File: results/youngs-modulus/2025-04-17/inconclusive-data/pf07lt03.csv
sep=
pf07lt03

System Information:
IntelliMESUR Version: 2.2.1
Test Frame Model: F505
Test Frame Serial Number: 4418651
Test Frame Capacity: 500 lbF / 2.2 kN
Test Frame Firmware Version: 1.00.14
Force Sensor Model: FS05-100
Force Sensor Capacity: 500 N
Force Sensor Resolution: 0.2 N
Force Sensor Serial Number: 4425350
Calibration Date: Apr 29, 2024
Calibration Due Date: Apr 29, 2025

Reading	Load [N]	Distance [mm]	Time [s]	Stress [MPa]	Strain [%]
1	0.0	0.00	0.000	0.0	0.0
4	0.0	0.00	0.012	0.0	0.0
7	0.0	0.00	0.024	0.0	0.0
10	0.0	0.00	0.036	0.0	0.0
13	0.2	0.00	0.048	0.1	0.0
16	0.2	0.00	0.060	0.1	0.0
19	-0.2	0.00	0.072	-0.1	0.0
22	-0.2	0.00	0.084	-0.1	0.0
25	0.0	0.00	0.096	0.0	0.0
28	0.0	0.00	0.108	0.0	0.0
31	0.0	0.00	0.120	0.0	0.0
34	0.0	0.00	0.132	0.0	0.0
37	-0.2	0.00	0.144	-0.1	0.0
40	0.0	0.00	0.156	0.0	0.0
43	0.0	0.00	0.168	0.0	0.0
46	0.0	0.00	0.180	0.0	0.0
49	-0.2	-0.01	0.192	-0.1	0.5
52	0.0	-0.03	0.204	0.0	1.5
55	0.2	-0.05	0.216	0.1	2.5
58	0.0	-0.07	0.228	0.0	3.5
61	-0.2	-0.09	0.240	-0.1	4.5
64	0.0	-0.11	0.252	0.0	5.5
67	0.2	-0.14	0.264	0.1	7.0
70	0.2	-0.16	0.276	0.1	8.0
73	-0.2	-0.18	0.288	-0.1	9.0
76	0.0	-0.19	0.300	0.0	9.5
79	0.2	-0.21	0.312	0.1	10.5
82	0.2	-0.23	0.324	0.1	11.5
85	0.2	-0.25	0.336	0.1	12.5
88	-0.2	-0.27	0.348	-0.1	13.5
91	0.0	-0.30	0.360	0.0	15.0
94	0.0	-0.32	0.372	0.0	16.0
97	0.0	-0.34	0.384	0.0	17.5
100	-0.2	-0.36	0.396	-0.1	18.5
103	0.0	-0.38	0.408	0.0	19.5
106	0.4	-0.40	0.420	0.2	20.5
109	0.0	-0.42	0.432	0.0	21.5
112	0.0	-0.44	0.444	0.0	22.5
115	0.0	-0.47	0.456	0.0	24.0
118	-0.2	-0.49	0.468	-0.1	25.0
121	0.0	-0.51	0.480	0.0	26.0
124	0.0	-0.53	0.492	0.0	27.0
127	0.0	-0.55	0.504	0.0	28.0
130	0.0	-0.57	0.516	0.0	29.0
133	-0.2	-0.59	0.528	-0.1	30.0
136	-0.2	-0.61	0.540	-0.1	31.0
139	0.0	-0.63	0.552	0.0	32.0
142	0.2	-0.65	0.564	0.1	33.0
145	0.0	-0.67	0.576	0.0	34.0
148	-0.2	-0.70	0.588	-0.1	35.5
151	0.0	-0.72	0.600	0.0	36.5
154	0.0	-0.74	0.612	0.0	37.5
157	0.2	-0.76	0.624	0.1	38.5
160	0.0	-0.78	0.636	0.0	39.5
163	0.0	-0.80	0.648	0.0	40.5
166	0.0	-0.82	0.660	0.0	41.5
169	0.0	-0.84	0.672	0.0	42.5
172	-0.2	-0.86	0.684	-0.1	43.5
175	0.0	-0.88	0.696	0.0	44.5
178	0.0	-0.90	0.708	0.0	45.5
181	0.0	-0.93	0.720	0.0	47.0
184	0.0	-0.95	0.732	0.0	48.0
187	0.0	-0.97	0.744	0.0	49.0
190	0.0	-0.99	0.756	0.0	50.5
193	-0.2	-1.01	0.768	-0.1	51.5
196	-0.2	-1.03	0.780	-0.1	52.5
199	0.2	-1.05	0.792	0.1	53.5
202	0.0	-1.07	0.804	0.0	54.5
205	-0.2	-1.09	0.816	-0.1	55.5
208	0.2	-1.11	0.828	0.1	56.5
211	0.2	-1.13	0.840	0.1	57.5
214	0.2	-1.15	0.852	0.1	58.5
217	0.0	-1.19	0.864	0.0	60.5
220	0.0	-1.21	0.876	0.0	61.5
223	-0.2	-1.23	0.888	-0.1	62.5
226	0.0	-1.25	0.900	0.0	63.5
229	0.0	-1.27	0.912	0.0	64.5
232	0.0	-1.29	0.924	0.0	65.5
235	0.0	-1.31	0.936	0.0	66.5
238	0.2	-1.33	0.948	0.1	67.5
241	0.2	-1.35	0.960	0.1	68.5
244	0.0	-1.38	0.972	0.0	70.0
247	-0.2	-1.40	0.984	-0.1	71.0
250	0.0	-1.42	0.996	0.0	72.0
253	0.0	-1.44	1.008	0.0	73.0
256	-0.2	-1.46	1.020	-0.1	74.0
259	0.0	-1.48	1.032	0.0	75.0
262	0.0	-1.50	1.044	0.0	76.0
265	0.0	-1.52	1.056	0.0	77.0
268	0.0	-1.54	1.068	0.0	78.0
271	0.0	-1.56	1.080	0.0	79.0
274	0.0	-1.58	1.092	0.0	80.0
277	0.0	-1.61	1.104	0.0	81.5
280	0.0	-1.63	1.116	0.0	82.5
283	0.0	-1.65	1.128	0.0	84.0
286	0.0	-1.67	1.140	0.0	85.0
289	0.6	-1.69	1.152	0.3	86.0
292	0.2	-1.71	1.164	0.1	87.0
295	0.0	-1.73	1.176	0.0	88.0
298	0.0	-1.75	1.188	0.0	89.0
301	0.0	-1.77	1.200	0.0	90.0
304	0.0	-1.79	1.212	0.0	91.0
307	0.0	-1.81	1.224	0.0	92.0
310	0.0	-1.83	1.236	0.0	93.0
313	0.2	-1.85	1.248	0.1	94.0
316	0.2	-1.88	1.260	0.1	95.5
319	0.0	-1.90	1.272	0.0	96.5
322	0.0	-1.92	1.284	0.0	97.5
325	0.0	-1.94	1.296	0.0	98.5
328	0.4	-1.96	1.308	0.2	99.5
331	0.2	-1.98	1.320	0.1	100.5
334	0.0	-2.00	1.332	0.0	101.5
337	0.0	-2.02	1.344	0.0	102.5
340	0.0	-2.04	1.356	0.0	103.5
343	0.0	-2.06	1.368	0.0	104.5
346	-0.2	-2.09	1.380	-0.1	106.0
349	0.0	-2.10	1.392	0.0	106.5
352	0.0	-2.13	1.404	0.0	108.0
355	0.2	-2.15	1.416	0.1	109.0
358	0.0	-2.17	1.428	0.0	110.0
361	-0.2	-2.18	1.440	-0.1	110.5
364	0.0	-2.20	1.452	0.0	111.5
367	0.0	-2.22	1.464	0.0	112.5
370	0.0	-2.24	1.476	0.0	113.5
373	0.4	-2.26	1.488	0.2	114.5
376	0.2	-2.28	1.500	0.1	115.5
379	0.0	-2.30	1.512	0.0	117.0
382	0.0	-2.32	1.524	0.0	118.0
385	0.0	-2.35	1.536	0.0	119.5
388	0.2	-2.37	1.548	0.1	120.5
391	-0.2	-2.39	1.560	-0.1	121.5
394	0.0	-2.41	1.572	0.0	122.5
397	0.2	-2.43	1.584	0.1	123.5
400	-0.2	-2.45	1.596	-0.1	124.5
403	-0.2	-2.47	1.608	-0.1	125.5
406	0.0	-2.49	1.620	0.0	126.5
409	0.0	-2.51	1.632	0.0	127.5
412	-0.2	-2.53	1.644	-0.1	128.5
415	0.0	-2.55	1.656	0.0	129.5
418	-0.2	-2.58	1.668	-0.1	131.0
421	0.0	-2.60	1.680	0.0	132.0
424	0.2	-2.62	1.692	0.1	133.0
427	0.0	-2.64	1.704	0.0	134.0
430	0.2	-2.66	1.716	0.1	135.0
433	0.0	-2.68	1.728	0.0	136.0
436	0.0	-2.70	1.740	0.0	137.0
439	0.0	-2.72	1.752	0.0	138.0
442	0.0	-2.74	1.764	0.0	139.0
445	-0.2	-2.76	1.776	-0.1	140.0
448	0.0	-2.79	1.788	0.0	141.5
451	0.2	-2.81	1.800	0.1	142.5
454	0.0	-2.83	1.812	0.0	143.5
457	0.2	-2.85	1.824	0.1	144.5
460	0.2	-2.87	1.836	0.1	145.5
463	0.0	-2.89	1.848	0.0	146.5
466	0.0	-2.91	1.860	0.0	147.5
469	0.0	-2.93	1.872	0.0	148.5
472	0.0	-2.95	1.884	0.0	149.5
475	0.0	-2.97	1.896	0.0	151.0
478	-0.2	-2.99	1.908	-0.1	152.0
481	0.0	-3.02	1.920	0.0	153.5
484	-0.2	-3.04	1.932	-0.1	154.5
487	0.0	-3.06	1.944	0.0	155.5
490	0.0	-3.08	1.956	0.0	156.5
493	0.0	-3.10	1.968	0.0	157.5
496	0.0	-3.12	1.980	0.0	158.5
499	0.0	-3.14	1.992	0.0	159.5
502	0.0	-3.16	2.004	0.0	160.5
505	0.0	-3.19	2.016	0.0	162.0
508	0.0	-3.21	2.028	0.0	163.0
511	0.0	-3.23	2.040	0.0	164.0
514	0.0	-3.26	2.052	0.0	165.5
517	-0.2	-3.28	2.064	-0.1	166.5
520	0.0	-3.30	2.076	0.0	167.5
523	0.0	-3.32	2.088	0.0	168.5
526	-0.2	-3.34	2.100	-0.1	169.5
529	-0.4	-3.36	2.112	-0.2	170.5
532	0.0	-3.38	2.124	0.0	171.5
535	0.0	-3.40	2.136	0.0	172.5
538	0.2	-3.42	2.148	0.1	173.5
541	0.2	-3.45	2.160	0.1	175.0
544	0.2	-3.47	2.172	0.1	176.0
547	0.0	-3.49	2.184	0.0	177.0
550	0.0	-3.51	2.196	0.0	178.0
553	0.0	-3.53	2.208	0.0	179.0
556	0.0	-3.55	2.220	0.0	180.0
559	0.0	-3.57	2.232	0.0	181.0
562	0.0	-3.59	2.244	0.0	182.0
565	0.0	-3.61	2.256	0.0	183.0
568	0.2	-3.64	2.268	0.1	185.0
571	0.0	-3.66	2.280	0.0	186.0
574	0.0	-3.68	2.292	0.0	187.0
577	0.0	-3.70	2.304	0.0	188.0
580	0.0	-3.72	2.316	0.0	189.0
583	0.0	-3.74	2.328	0.0	190.0
586	0.0	-3.76	2.340	0.0	191.0
589	0.0	-3.78	2.352	0.0	192.0
592	0.0	-3.80	2.364	0.0	193.0
595	0.0	-3.83	2.376	0.0	194.5
598	0.0	-3.85	2.388	0.0	195.5
601	0.4	-3.87	2.400	0.2	196.5
604	0.0	-3.89	2.412	0.0	197.5
607	0.2	-3.91	2.424	0.1	198.5
610	-0.2	-3.93	2.436	-0.1	199.5
613	0.0	-3.95	2.448	0.0	200.5
616	0.0	-3.97	2.460	0.0	201.5
619	0.0	-3.99	2.472	0.0	202.5
622	0.0	-4.02	2.484	0.0	204.0
625	0.0	-4.04	2.496	0.0	205.0
628	0.0	-4.06	2.508	0.0	206.0
631	0.0	-4.08	2.520	0.0	207.0
634	-0.2	-4.10	2.532	-0.1	208.0
637	-0.2	-4.12	2.544	-0.1	209.0
640	0.0	-4.14	2.556	0.0	210.0
643	0.0	-4.16	2.568	0.0	211.0
646	-0.2	-4.18	2.580	-0.1	212.0
649	0.0	-4.21	2.592	0.0	213.5
652	0.0	-4.23	2.604	0.0	214.5
655	0.0	-4.25	2.616	0.0	215.5
658	-0.2	-4.27	2.628	-0.1	217.0
661	-0.2	-4.29	2.640	-0.1	218.0
664	0.0	-4.31	2.652	0.0	219.0
667	0.2	-4.33	2.664	0.1	220.0
670	0.2	-4.35	2.676	0.1	221.0
673	0.0	-4.37	2.688	0.0	222.0
676	0.0	-4.40	2.700	0.0	223.5
679	0.0	-4.42	2.712	0.0	224.5
682	0.0	-4.44	2.724	0.0	225.5
685	0.0	-4.46	2.736	0.0	226.5
688	-0.2	-4.48	2.748	-0.1	227.5
691	0.0	-4.50	2.760	0.0	228.5
694	-0.2	-4.52	2.772	-0.1	229.5
697	0.0	-4.54	2.784	0.0	230.5
700	0.0	-4.56	2.796	0.0	231.5
703	0.0	-4.59	2.808	0.0	233.0
706	0.0	-4.61	2.820	0.0	234.0
709	0.0	-4.63	2.832	0.0	235.0
712	0.0	-4.65	2.844	0.0	236.0
715	0.2	-4.67	2.856	0.1	237.0
718	0.0	-4.69	2.868	0.0	238.0
721	0.0	-4.71	2.880	0.0	239.0
724	0.0	-4.74	2.892	0.0	240.5
727	0.2	-4.76	2.904	0.1	241.5
730	0.0	-4.78	2.916	0.0	242.5
733	0.0	-4.80	2.928	0.0	243.5
736	0.0	-4.82	2.940	0.0	244.5
739	-0.2	-4.84	2.952	-0.1	245.5
742	-0.2	-4.86	2.964	-0.1	246.5
745	0.0	-4.88	2.976	0.0	247.5
748	-0.2	-4.90	2.988	-0.1	248.5
751	0.0	-4.93	3.000	0.0	250.5
754	0.0	-4.95	3.012	0.0	251.5
757	0.0	-4.97	3.024	0.0	252.5
760	-0.2	-4.99	3.036	-0.1	253.5
763	0.0	-5.01	3.048	0.0	254.5
766	-0.2	-5.03	3.060	-0.1	255.5
769	0.2	-5.05	3.072	0.1	256.5
772	-0.2	-5.07	3.084	-0.1	257.5
775	0.4	-5.09	3.096	0.2	258.5
778	0.0	-5.12	3.108	0.0	260.0
781	-0.2	-5.14	3.120	-0.1	261.0
784	-0.2	-5.16	3.132	-0.1	262.0
787	0.2	-5.18	3.144	0.1	263.0
790	0.0	-5.20	3.156	0.0	264.0
793	0.4	-5.22	3.168	0.2	265.0
796	0.0	-5.24	3.180	0.0	266.0
799	0.2	-5.26	3.192	0.1	267.0
802	-0.2	-5.28	3.204	-0.1	268.0
805	0.0	-5.30	3.216	0.0	269.0
808	0.0	-5.32	3.228	0.0	270.0
811	0.0	-5.35	3.240	0.0	271.5
814	-0.2	-5.37	3.252	-0.1	272.5
817	0.2	-5.39	3.264	0.1	273.5
820	0.4	-5.41	3.276	0.2	274.5
823	0.0	-5.43	3.288	0.0	275.5
826	0.0	-5.45	3.300	0.0	276.5
829	0.0	-5.47	3.312	0.0	277.5
832	0.0	-5.49	3.324	0.0	278.5
835	0.0	-5.51	3.336	0.0	279.5
838	0.0	-5.54	3.348	0.0	281.0
841	0.0	-5.56	3.360	0.0	282.0
844	0.0	-5.58	3.372	0.0	283.0
847	0.2	-5.60	3.384	0.1	284.5
850	0.0	-5.62	3.396	0.0	285.5
853	0.0	-5.64	3.408	0.0	286.5
856	0.0	-5.66	3.420	0.0	287.5
859	0.0	-5.68	3.432	0.0	288.5
862	-0.2	-5.70	3.444	-0.1	289.5
865	0.0	-5.72	3.456	0.0	290.5
868	0.2	-5.75	3.468	0.1	292.0
871	0.0	-5.77	3.480	0.0	293.0
874	0.0	-5.79	3.492	0.0	294.0
877	-0.2	-5.81	3.504	-0.1	295.0
880	0.0	-5.83	3.516	0.0	296.0
883	0.0	-5.85	3.528	0.0	297.0
886	0.0	-5.87	3.540	0.0	298.0
889	0.0	-5.89	3.552	0.0	299.0
892	0.0	-5.91	3.564	0.0	300.0
895	0.0	-5.93	3.576	0.0	301.0
898	0.4	-5.95	3.588	0.2	302.0
901	0.0	-5.98	3.600	0.0	303.5
904	-0.4	-6.00	3.612	-0.2	304.5
907	0.0	-6.02	3.624	0.0	305.5
910	0.0	-6.04	3.636	0.0	306.5
913	0.4	-6.06	3.648	0.2	307.5
916	0.0	-6.08	3.660	0.0	308.5
919	-0.2	-6.10	3.672	-0.1	309.5
922	-0.2	-6.12	3.684	-0.1	310.5
925	0.0	-6.14	3.696	0.0	311.5
928	0.0	-6.16	3.708	0.0	312.5
931	0.0	-6.17	3.720	0.0	313.0
934	-0.2	-6.20	3.732	-0.1	314.5
937	-0.4	-6.22	3.744	-0.2	315.5
940	0.0	-6.24	3.756	0.0	317.0
943	0.2	-6.26	3.768	0.1	318.0
946	0.0	-6.28	3.780	0.0	319.0
949	0.0	-6.30	3.792	0.0	320.0
952	0.0	-6.32	3.804	0.0	321.0
955	-0.2	-6.34	3.816	-0.1	322.0
958	-0.2	-6.36	3.828	-0.1	323.0
961	0.0	-6.38	3.840	0.0	324.0
964	0.0	-6.40	3.852	0.0	325.0
967	0.0	-6.43	3.864	0.0	326.5
970	0.2	-6.45	3.876	0.1	327.5
973	0.2	-6.47	3.888	0.1	328.5
976	0.2	-6.49	3.900	0.1	329.5
979	0.0	-6.51	3.912	0.0	330.5
982	0.0	-6.53	3.924	0.0	331.5
985	0.2	-6.55	3.936	0.1	332.5
988	-0.4	-6.57	3.948	-0.2	333.5
991	0.0	-6.59	3.960	0.0	334.5
994	0.0	-6.61	3.972	0.0	335.5
997	0.2	-6.63	3.984	0.1	336.5
1000	0.0	-6.65	3.996	0.0	337.5
1003	0.0	-6.67	4.008	0.0	338.5
1006	0.2	-6.70	4.020	0.1	340.0
1009	0.0	-6.72	4.032	0.0	341.0
1012	0.0	-6.74	4.044	0.0	342.0
1015	0.0	-6.76	4.056	0.0	343.0
1018	0.0	-6.78	4.068	0.0	344.0
1021	0.2	-6.80	4.080	0.1	345.0
1024	0.0	-6.82	4.092	0.0	346.0
1027	0.2	-6.84	4.104	0.1	347.0
1030	0.2	-6.86	4.116	0.1	348.0
1033	0.2	-6.88	4.128	0.1	349.0
1036	0.0	-6.90	4.140	0.0	350.5
1039	0.0	-6.92	4.152	0.0	351.5
1042	-0.4	-6.95	4.164	-0.2	353.0
1045	0.0	-6.97	4.176	0.0	354.0
1048	0.2	-6.99	4.188	0.1	355.0
1051	0.0	-7.01	4.200	0.0	356.0
1054	0.2	-7.03	4.212	0.1	357.0
1057	0.0	-7.05	4.224	0.0	358.0
1060	0.0	-7.07	4.236	0.0	359.0
1063	0.0	-7.09	4.248	0.0	360.0
1066	0.2	-7.11	4.260	0.1	361.0
1069	0.2	-7.13	4.272	0.1	362.0
1072	0.0	-7.15	4.284	0.0	363.0
1075	0.0	-7.19	4.296	0.0	365.0
1078	0.0	-7.21	4.308	0.0	366.0
1081	0.0	-7.23	4.320	0.0	367.0
1084	0.0	-7.25	4.332	0.0	368.0
1087	0.4	-7.27	4.344	0.2	369.0
1090	0.0	-7.29	4.356	0.0	370.0
1093	0.2	-7.31	4.368	0.1	371.0
1096	0.0	-7.33	4.380	0.0	372.0
1099	0.2	-7.35	4.392	0.1	373.0
1102	0.0	-7.37	4.404	0.0	374.0
1105	0.0	-7.39	4.416	0.0	375.0
1108	0.0	-7.41	4.428	0.0	376.0
1111	0.0	-7.44	4.440	0.0	377.5
1114	0.2	-7.46	4.452	0.1	378.5
1117	0.0	-7.48	4.464	0.0	379.5
1120	-0.4	-7.50	4.476	-0.2	380.5
1123	0.2	-7.52	4.488	0.1	381.5
1126	0.0	-7.54	4.500	0.0	382.5
1129	0.0	-7.56	4.512	0.0	384.0
1132	0.2	-7.58	4.524	0.1	385.0
1135	-0.4	-7.60	4.536	-0.2	386.0
1138	0.2	-7.62	4.548	0.1	387.0
1141	0.0	-7.64	4.560	0.0	388.0
1144	0.0	-7.66	4.572	0.0	389.0
1147	0.0	-7.68	4.584	0.0	390.0
1150	0.0	-7.71	4.596	0.0	391.5
1153	0.0	-7.73	4.608	0.0	392.5
1156	0.0	-7.75	4.620	0.0	393.5
1159	0.0	-7.77	4.632	0.0	394.5
1162	-0.2	-7.79	4.644	-0.1	395.5
1165	0.0	-7.81	4.656	0.0	396.5
1168	0.2	-7.83	4.668	0.1	397.5
1171	0.0	-7.85	4.680	0.0	398.5
1174	0.0	-7.87	4.692	0.0	399.5
1177	-0.2	-7.89	4.704	-0.1	400.5
1180	0.0	-7.91	4.716	0.0	401.5
1183	0.0	-7.94	4.728	0.0	403.0
1186	0.0	-7.96	4.740	0.0	404.0
1189	0.6	-7.98	4.752	0.3	405.0
1192	0.0	-8.00	4.764	0.0	406.0
1195	0.0	-8.02	4.776	0.0	407.0
1198	0.0	-8.04	4.788	0.0	408.0
1201	0.0	-8.06	4.800	0.0	409.0
1204	0.0	-8.08	4.812	0.0	410.0
1207	0.0	-8.10	4.824	0.0	411.0
1210	0.0	-8.13	4.836	0.0	412.5
1213	0.0	-8.15	4.848	0.0	413.5
1216	-0.2	-8.17	4.860	-0.1	414.5
1219	0.2	-8.19	4.872	0.1	415.5
1222	0.0	-8.21	4.884	0.0	417.0
1225	0.0	-8.23	4.896	0.0	418.0
1228	0.2	-8.25	4.908	0.1	419.0
1231	0.2	-8.27	4.920	0.1	420.0
1234	0.0	-8.29	4.932	0.0	421.0
1237	0.0	-8.31	4.944	0.0	422.0
1240	0.0	-8.33	4.956	0.0	423.0
1243	-0.2	-8.36	4.968	-0.1	424.5
1246	-0.2	-8.38	4.980	-0.1	425.5
1249	0.2	-8.40	4.992	0.1	426.5
1252	0.0	-8.42	5.004	0.0	427.5
1255	0.0	-8.44	5.016	0.0	428.5
1258	0.2	-8.46	5.028	0.1	429.5
1261	0.2	-8.48	5.040	0.1	430.5
1264	0.2	-8.50	5.052	0.1	431.5
1267	0.2	-8.52	5.064	0.1	432.5
1270	0.0	-8.55	5.076	0.0	434.0
1273	-0.2	-8.57	5.088	-0.1	435.0
1276	0.4	-8.59	5.100	0.2	436.0
1279	-0.2	-8.61	5.112	-0.1	437.0
1282	0.0	-8.63	5.124	0.0	438.0
1285	0.2	-8.65	5.136	0.1	439.0
1288	-0.2	-8.67	5.148	-0.1	440.0
1291	0.0	-8.69	5.160	0.0	441.0
1294	0.0	-8.71	5.172	0.0	442.0
1297	0.0	-8.74	5.184	0.0	443.5
1300	0.0	-8.76	5.196	0.0	444.5
1303	0.0	-8.78	5.208	0.0	445.5
1306	0.0	-8.80	5.220	0.0	446.5
1309	-0.2	-8.82	5.232	-0.1	447.5
1312	0.0	-8.84	5.244	0.0	448.5
1315	0.0	-8.86	5.256	0.0	449.5
1318	0.0	-8.88	5.268	0.0	451.0
1321	0.0	-8.90	5.280	0.0	452.0
1324	0.0	-8.93	5.292	0.0	453.5
1327	0.0	-8.95	5.304	0.0	454.5
1330	0.0	-8.97	5.316	0.0	455.5
1333	0.0	-8.99	5.328	0.0	456.5
1336	0.0	-9.01	5.340	0.0	457.5
1339	-0.2	-9.03	5.352	-0.1	458.5
1342	0.0	-9.05	5.364	0.0	459.5
1345	0.0	-9.07	5.376	0.0	460.5
1348	0.2	-9.10	5.388	0.1	462.0
1351	0.0	-9.12	5.400	0.0	463.0
1354	0.0	-9.14	5.412	0.0	464.0
1357	0.0	-9.16	5.424	0.0	465.0
1360	-0.2	-9.18	5.436	-0.1	466.0
1363	-0.2	-9.20	5.448	-0.1	467.0
1366	0.2	-9.22	5.460	0.1	468.0
1369	0.4	-9.24	5.472	0.2	469.0
1372	0.0	-9.26	5.484	0.0	470.0
1375	-0.2	-9.29	5.496	-0.1	471.5
1378	-0.4	-9.31	5.508	-0.2	472.5
1381	0.0	-9.33	5.520	0.0	473.5
1384	0.0	-9.35	5.532	0.0	474.5
1387	-0.2	-9.37	5.544	-0.1	475.5
1390	0.0	-9.39	5.556	0.0	476.5
1393	0.2	-9.41	5.568	0.1	477.5
1396	0.0	-9.43	5.580	0.0	478.5
1399	0.2	-9.45	5.592	0.1	479.5
1402	0.0	-9.48	5.604	0.0	481.0
1405	-0.2	-9.50	5.616	-0.1	482.0
1408	0.2	-9.52	5.628	0.1	483.0
1411	0.0	-9.54	5.640	0.0	484.5
1414	0.0	-9.56	5.652	0.0	485.5
1417	-0.2	-9.58	5.664	-0.1	486.5
1420	0.0	-9.60	5.676	0.0	487.5
1423	0.0	-9.62	5.688	0.0	488.5
1426	0.2	-9.65	5.700	0.1	490.0
1429	-0.2	-9.67	5.712	-0.1	491.0
1432	-0.4	-9.69	5.724	-0.2	492.0
1435	-0.2	-9.71	5.736	-0.1	493.0
1438	0.0	-9.73	5.748	0.0	494.0
1441	0.0	-9.75	5.760	0.0	495.0
1444	0.0	-9.77	5.772	0.0	496.0
1447	0.0	-9.79	5.784	0.0	497.0
1450	0.0	-9.81	5.796	0.0	498.0
1453	0.0	-9.84	5.808	0.0	499.5
1456	0.0	-9.86	5.820	0.0	500.5
1459	0.0	-9.88	5.832	0.0	501.5
1462	0.2	-9.90	5.844	0.1	502.5
1465	0.0	-9.92	5.856	0.0	503.5
1468	-0.4	-9.94	5.868	-0.2	504.5
1471	0.0	-9.96	5.880	0.0	505.5
1474	0.0	-9.98	5.892	0.0	506.5
1477	0.2	-10.00	5.904	0.1	507.5
1480	0.0	-10.03	5.916	0.0	509.0
1483	0.0	-10.05	5.928	0.0	510.0
1486	0.2	-10.07	5.940	0.1	511.0
1489	0.0	-10.09	5.952	0.0	512.0
1492	0.0	-10.11	5.964	0.0	513.0
1495	0.2	-10.13	5.976	0.1	514.0
1498	-0.2	-10.15	5.988	-0.1	515.0
1501	0.0	-10.17	6.000	0.0	516.0
1504	0.0	-10.18	6.012	0.0	517.0
1507	0.0	-10.21	6.024	0.0	518.5
1510	0.0	-10.23	6.036	0.0	519.5
1513	0.0	-10.25	6.048	0.0	520.5
1516	0.0	-10.27	6.060	0.0	521.5
1519	0.0	-10.29	6.072	0.0	522.5
1522	-0.2	-10.31	6.084	-0.1	523.5
1525	-0.2	-10.33	6.096	-0.1	524.5
1528	-0.2	-10.35	6.108	-0.1	525.5
1531	0.0	-10.37	6.120	0.0	526.5
1534	0.0	-10.40	6.132	0.0	528.0
1537	0.2	-10.42	6.144	0.1	529.0
1540	-0.4	-10.44	6.156	-0.2	530.0
1543	-0.2	-10.46	6.168	-0.1	531.0
1546	0.2	-10.48	6.180	0.1	532.0
1549	-0.2	-10.50	6.192	-0.1	533.0
1552	0.0	-10.52	6.204	0.0	534.0
1555	0.2	-10.54	6.216	0.1	535.0
1558	0.0	-10.56	6.228	0.0	536.0
1561	0.2	-10.59	6.240	0.1	537.5
1564	0.0	-10.61	6.252	0.0	538.5
1567	0.0	-10.63	6.264	0.0	539.5
1570	0.0	-10.65	6.276	0.0	540.5
1573	0.4	-10.67	6.288	0.2	541.5
1576	0.2	-10.69	6.300	0.1	542.5
1579	-0.2	-10.71	6.312	-0.1	543.5
1582	0.2	-10.73	6.324	0.1	544.5
1585	0.0	-10.75	6.336	0.0	545.5
1588	0.0	-10.77	6.348	0.0	546.5
1591	0.0	-10.80	6.360	0.0	548.0
1594	0.0	-10.82	6.372	0.0	549.0
1597	0.2	-10.84	6.384	0.1	550.5
1600	0.2	-10.86	6.396	0.1	551.5
1603	0.0	-10.88	6.408	0.0	552.5
1606	0.0	-10.90	6.420	0.0	553.5
1609	0.0	-10.92	6.432	0.0	554.5
1612	0.0	-10.94	6.444	0.0	555.5
1615	0.0	-10.96	6.456	0.0	556.5
1618	-0.2	-10.98	6.468	-0.1	557.5
1621	0.0	-11.00	6.480	0.0	558.5
1624	0.0	-11.03	6.492	0.0	560.0
1627	0.0	-11.05	6.504	0.0	561.0
1630	0.0	-11.07	6.516	0.0	562.0
1633	0.0	-11.09	6.528	0.0	563.0
1636	0.0	-11.11	6.540	0.0	564.0
1639	0.0	-11.13	6.552	0.0	565.0
1642	-0.4	-11.15	6.564	-0.2	566.0
1645	-0.2	-11.17	6.576	-0.1	567.0
1648	0.0	-11.19	6.588	0.0	568.0
1651	-0.2	-11.21	6.600	-0.1	569.0
1654	0.2	-11.23	6.612	0.1	570.0
1657	0.0	-11.26	6.624	0.0	571.5
1660	0.0	-11.28	6.636	0.0	572.5
1663	0.2	-11.30	6.648	0.1	573.5
1666	-0.2	-11.32	6.660	-0.1	574.5
1669	0.0	-11.34	6.672	0.0	575.5
1672	-0.2	-11.36	6.684	-0.1	576.5
1675	0.0	-11.38	6.696	0.0	577.5
1678	0.2	-11.40	6.708	0.1	578.5
1681	0.0	-11.42	6.720	0.0	579.5
1684	0.0	-11.44	6.732	0.0	580.5
1687	-0.2	-11.46	6.744	-0.1	581.5
1690	-0.2	-11.49	6.756	-0.1	583.0
1693	-0.2	-11.51	6.768	-0.1	584.5
1696	0.0	-11.53	6.780	0.0	585.5
1699	0.0	-11.55	6.792	0.0	586.5
1702	0.0	-11.57	6.804	0.0	587.5
1705	0.0	-11.59	6.816	0.0	588.5
1708	0.0	-11.61	6.828	0.0	589.5
1711	0.2	-11.63	6.840	0.1	590.5
1714	0.0	-11.65	6.852	0.0	591.5
1717	-0.2	-11.67	6.864	-0.1	592.5
1720	-0.2	-11.69	6.876	-0.1	593.5
1723	0.2	-11.71	6.888	0.1	594.5
1726	0.0	-11.74	6.900	0.0	596.0
1729	0.2	-11.76	6.912	0.1	597.0
1732	0.0	-11.78	6.924	0.0	598.0
1735	0.2	-11.80	6.936	0.1	599.0
1738	0.0	-11.82	6.948	0.0	600.0
1741	0.0	-11.84	6.960	0.0	601.0
1744	0.0	-11.86	6.972	0.0	602.0
1747	0.2	-11.88	6.984	0.1	603.0
1750	0.0	-11.90	6.996	0.0	604.0
1753	0.0	-11.92	7.008	0.0	605.0
1756	0.0	-11.94	7.020	0.0	606.0
1759	0.0	-11.97	7.032	0.0	607.5
1762	-0.2	-11.98	7.044	-0.1	608.0
1765	0.0	-12.01	7.056	0.0	609.5
1768	0.0	-12.03	7.068	0.0	610.5
1771	0.0	-12.05	7.080	0.0	611.5
1774	0.0	-12.07	7.092	0.0	612.5
1777	0.2	-12.09	7.104	0.1	613.5
1780	0.0	-12.11	7.116	0.0	614.5
1783	-0.2	-12.13	7.128	-0.1	615.5
1786	0.0	-12.15	7.140	0.0	617.0
1789	-0.2	-12.18	7.152	-0.1	618.5
1792	0.0	-12.20	7.164	0.0	619.5
1795	0.0	-12.22	7.176	0.0	620.5
1798	0.0	-12.25	7.188	0.0	622.0
1801	-0.2	-12.27	7.200	-0.1	623.0
1804	0.0	-12.29	7.212	0.0	624.0
1807	0.0	-12.31	7.224	0.0	625.0
1810	0.2	-12.33	7.236	0.1	626.0
1813	0.0	-12.35	7.248	0.0	627.0
1816	0.0	-12.37	7.260	0.0	628.0
1819	0.0	-12.39	7.272	0.0	629.0
1822	0.0	-12.41	7.284	0.0	630.0
1825	0.0	-12.43	7.296	0.0	631.0
1828	-0.2	-12.46	7.308	-0.1	632.5
1831	0.2	-12.48	7.320	0.1	633.5
1834	0.0	-12.50	7.332	0.0	634.5
1837	0.0	-12.52	7.344	0.0	635.5
1840	0.0	-12.54	7.356	0.0	636.5
1843	0.2	-12.56	7.368	0.1	637.5
1846	0.0	-12.58	7.380	0.0	638.5
1849	-0.2	-12.60	7.392	-0.1	639.5
1852	0.2	-12.62	7.404	0.1	640.5
1855	0.2	-12.64	7.416	0.1	641.5
1858	0.0	-12.66	7.428	0.0	642.5
1861	0.0	-12.69	7.440	0.0	644.0
1864	-0.2	-12.71	7.452	-0.1	645.0
1867	-0.2	-12.73	7.464	-0.1	646.0
1870	0.2	-12.75	7.476	0.1	647.0
1873	0.4	-12.77	7.488	0.2	648.0
1876	0.2	-12.79	7.500	0.1	649.0
1879	0.2	-12.81	7.512	0.1	650.5
1882	-0.2	-12.83	7.524	-0.1	651.5
1885	0.0	-12.85	7.536	0.0	652.5
1888	0.0	-12.87	7.548	0.0	653.5
1891	0.0	-12.89	7.560	0.0	654.5
1894	0.0	-12.92	7.572	0.0	656.0
1897	0.0	-12.94	7.584	0.0	657.0
1900	0.0	-12.96	7.596	0.0	658.0
1903	-0.2	-12.98	7.608	-0.1	659.0
1906	0.0	-13.00	7.620	0.0	660.0
1909	0.0	-13.02	7.632	0.0	661.0
1912	0.0	-13.04	7.644	0.0	662.0
1915	0.0	-13.06	7.656	0.0	663.0
1918	0.0	-13.08	7.668	0.0	664.0
1921	0.0	-13.10	7.680	0.0	665.0
1924	-0.2	-13.12	7.692	-0.1	666.0
1927	-0.2	-13.15	7.704	-0.1	667.5
1930	0.0	-13.17	7.716	0.0	668.5
1933	0.0	-13.19	7.728	0.0	669.5
1936	0.0	-13.21	7.740	0.0	670.5
1939	0.2	-13.23	7.752	0.1	671.5
1942	-0.2	-13.25	7.764	-0.1	672.5
1945	0.0	-13.27	7.776	0.0	673.5
1948	0.0	-13.29	7.788	0.0	674.5
1951	0.2	-13.31	7.800	0.1	675.5
1954	0.0	-13.34	7.812	0.0	677.0
1957	0.0	-13.36	7.824	0.0	678.0
1960	0.0	-13.38	7.836	0.0	679.0
1963	0.2	-13.40	7.848	0.1	680.0
1966	0.2	-13.42	7.860	0.1	681.0
1969	-0.2	-13.44	7.872	-0.1	682.0
1972	0.0	-13.46	7.884	0.0	683.0
1975	0.4	-13.48	7.896	0.2	684.5
1978	0.4	-13.50	7.908	0.2	685.5
1981	0.0	-13.53	7.920	0.0	687.0
1984	-0.4	-13.55	7.932	-0.2	688.0
1987	0.2	-13.57	7.944	0.1	689.0
1990	0.0	-13.59	7.956	0.0	690.0
1993	0.0	-13.61	7.968	0.0	691.0
1996	-0.4	-13.63	7.980	-0.2	692.0
1999	0.0	-13.65	7.992	0.0	693.0
2002	0.0	-13.67	8.004	0.0	694.0
2005	0.0	-13.69	8.016	0.0	695.0
2008	0.2	-13.72	8.028	0.1	696.5
2011	-0.2	-13.74	8.040	-0.1	697.5
2014	0.2	-13.76	8.052	0.1	698.5
2017	0.0	-13.78	8.064	0.0	699.5
2020	0.0	-13.80	8.076	0.0	700.5
2023	0.0	-13.82	8.088	0.0	701.5
2026	0.0	-13.84	8.100	0.0	702.5
2029	0.0	-13.86	8.112	0.0	703.5
2032	0.4	-13.88	8.124	0.2	704.5
2035	0.0	-13.91	8.136	0.0	706.0
2038	0.0	-13.93	8.148	0.0	707.0
2041	0.0	-13.95	8.160	0.0	708.0
2044	0.0	-13.97	8.172	0.0	709.0
2047	0.0	-13.99	8.184	0.0	710.0
2050	0.0	-14.01	8.196	0.0	711.0
2053	0.0	-14.03	8.208	0.0	712.0
2056	0.0	-14.05	8.220	0.0	713.0
2059	0.0	-14.07	8.232	0.0	714.0
2062	-0.4	-14.10	8.244	-0.2	715.5
2065	0.0	-14.12	8.256	0.0	717.0
2068	0.0	-14.14	8.268	0.0	718.0
2071	0.0	-14.16	8.280	0.0	719.0
2074	-0.2	-14.18	8.292	-0.1	720.0
2077	0.4	-14.20	8.304	0.2	721.0
2080	0.0	-14.22	8.316	0.0	722.0
2083	-0.4	-14.24	8.328	-0.2	723.0
2086	0.0	-14.26	8.340	0.0	724.0
2089	0.2	-14.29	8.352	0.1	725.5
2092	0.2	-14.31	8.364	0.1	726.5
2095	0.0	-14.33	8.376	0.0	727.5
2098	-0.4	-14.35	8.388	-0.2	728.5
2101	-0.2	-14.37	8.400	-0.1	729.5
2104	-0.2	-14.39	8.412	-0.1	730.5
2107	0.2	-14.41	8.424	0.1	731.5
2110	0.2	-14.44	8.436	0.1	733.0
2113	-0.2	-14.46	8.448	-0.1	734.0
2116	-0.2	-14.48	8.460	-0.1	735.0
2119	0.4	-14.50	8.472	0.2	736.0
2122	0.4	-14.52	8.484	0.2	737.0
2125	0.0	-14.54	8.496	0.0	738.0
2128	0.0	-14.56	8.508	0.0	739.0
2131	0.4	-14.58	8.520	0.2	740.0
2134	0.4	-14.60	8.532	0.2	741.0
2137	0.0	-14.63	8.544	0.0	742.5
2140	0.0	-14.65	8.556	0.0	743.5
2143	0.0	-14.67	8.568	0.0	744.5
2146	0.0	-14.69	8.580	0.0	745.5
2149	0.0	-14.71	8.592	0.0	746.5
2152	0.0	-14.73	8.604	0.0	747.5
2155	0.0	-14.75	8.616	0.0	748.5
2158	-0.2	-14.77	8.628	-0.1	749.5
2161	0.0	-14.79	8.640	0.0	751.0
2164	0.0	-14.82	8.652	0.0	752.5
2167	0.0	-14.84	8.664	0.0	753.5
2170	0.0	-14.86	8.676	0.0	754.5
2173	0.4	-14.88	8.688	0.2	755.5
2176	0.2	-14.90	8.700	0.1	756.5
2179	0.2	-14.92	8.712	0.1	757.5
2182	0.0	-14.94	8.724	0.0	758.5
2185	0.0	-14.96	8.736	0.0	759.5
2188	-0.4	-14.98	8.748	-0.2	760.5
2191	0.0	-15.01	8.760	0.0	762.0
2194	0.2	-15.03	8.772	0.1	763.0
2197	-0.2	-15.05	8.784	-0.1	764.0
2200	0.0	-15.07	8.796	0.0	765.0
2203	0.0	-15.09	8.808	0.0	766.0
2206	0.0	-15.11	8.820	0.0	767.0
2209	0.0	-15.13	8.832	0.0	768.0
2212	0.2	-15.15	8.844	0.1	769.0
2215	-0.2	-15.17	8.856	-0.1	770.0
2218	0.0	-15.19	8.868	0.0	771.0
2221	0.0	-15.21	8.880	0.0	772.0
2224	0.0	-15.23	8.892	0.0	773.0
2227	0.0	-15.25	8.904	0.0	774.0
2230	0.0	-15.27	8.916	0.0	775.0
2233	0.0	-15.29	8.928	0.0	776.0
2236	0.0	-15.31	8.940	0.0	777.0
2239	0.0	-15.33	8.952	0.0	778.0
2242	0.0	-15.35	8.964	0.0	779.0
2245	-0.2	-15.38	8.976	-0.1	780.5
2248	-0.2	-15.40	8.988	-0.1	781.5
2251	0.0	-15.42	9.000	0.0	782.5
2254	-0.2	-15.44	9.012	-0.1	784.0
2257	0.2	-15.46	9.024	0.1	785.0
2260	0.0	-15.48	9.036	0.0	786.0
2263	0.0	-15.50	9.048	0.0	787.0
2266	0.0	-15.52	9.060	0.0	788.0
2269	0.0	-15.54	9.072	0.0	789.0
2272	0.0	-15.57	9.084	0.0	790.5
2275	0.0	-15.59	9.096	0.0	791.5
2278	0.0	-15.61	9.108	0.0	792.5
2281	0.0	-15.63	9.120	0.0	793.5
2284	-0.2	-15.65	9.132	-0.1	794.5
2287	0.0	-15.67	9.144	0.0	795.5
2290	0.0	-15.69	9.156	0.0	796.5
2293	0.4	-15.71	9.168	0.2	797.5
2296	0.0	-15.73	9.180	0.0	798.5
2299	0.2	-15.75	9.192	0.1	799.5
2302	0.2	-15.77	9.204	0.1	800.5
2305	0.0	-15.80	9.216	0.0	802.0
2308	0.0	-15.82	9.228	0.0	803.0
2311	0.0	-15.84	9.240	0.0	804.0
2314	0.0	-15.86	9.252	0.0	805.0
2317	-0.2	-15.88	9.264	-0.1	806.0
2320	0.0	-15.90	9.276	0.0	807.0
2323	0.2	-15.92	9.288	0.1	808.0
2326	0.0	-15.94	9.300	0.0	809.0
2329	0.0	-15.96	9.312	0.0	810.0
2332	0.0	-15.98	9.324	0.0	811.0
2335	-0.2	-16.00	9.336	-0.1	812.0
2338	0.0	-16.03	9.348	0.0	813.5
2341	-0.2	-16.05	9.360	-0.1	814.5
2344	0.0	-16.07	9.372	0.0	815.5
2347	0.0	-16.09	9.384	0.0	817.0
2350	0.4	-16.11	9.396	0.2	818.0
2353	0.0	-16.13	9.408	0.0	819.0
2356	0.0	-16.15	9.420	0.0	820.0
2359	0.0	-16.17	9.432	0.0	821.0
2362	0.0	-16.19	9.444	0.0	822.0
2365	-0.2	-16.21	9.456	-0.1	823.0
2368	0.0	-16.23	9.468	0.0	824.0
2371	0.0	-16.25	9.480	0.0	825.0
2374	0.2	-16.28	9.492	0.1	826.5
2377	-0.2	-16.30	9.504	-0.1	827.5
2380	0.0	-16.32	9.516	0.0	828.5
2383	-0.2	-16.34	9.528	-0.1	829.5
2386	0.0	-16.36	9.540	0.0	830.5
2389	0.0	-16.38	9.552	0.0	831.5
2392	0.0	-16.40	9.564	0.0	832.5
2395	0.0	-16.42	9.576	0.0	833.5
2398	0.0	-16.44	9.588	0.0	834.5
2401	0.0	-16.46	9.600	0.0	835.5
2404	0.0	-16.48	9.612	0.0	836.5
2407	0.0	-16.50	9.624	0.0	837.5
2410	-0.2	-16.53	9.636	-0.1	839.0
2413	0.2	-16.55	9.648	0.1	840.0
2416	0.0	-16.57	9.660	0.0	841.0
2419	0.0	-16.59	9.672	0.0	842.0
2422	0.0	-16.61	9.684	0.0	843.0
2425	0.0	-16.63	9.696	0.0	844.0
2428	0.0	-16.65	9.708	0.0	845.0
2431	0.0	-16.67	9.720	0.0	846.0
2434	0.2	-16.69	9.732	0.1	847.0
2437	0.0	-16.71	9.744	0.0	848.0
2440	0.0	-16.73	9.756	0.0	849.0
2443	0.0	-16.75	9.768	0.0	850.5
2446	0.0	-16.78	9.780	0.0	852.0
2449	-0.2	-16.80	9.792	-0.1	853.0
2452	0.0	-16.82	9.804	0.0	854.0
2455	0.0	-16.84	9.816	0.0	855.0
2458	0.0	-16.86	9.828	0.0	856.0
2461	0.2	-16.88	9.840	0.1	857.0
2464	-0.2	-16.90	9.852	-0.1	858.0
2467	0.0	-16.92	9.864	0.0	859.0
2470	0.0	-16.94	9.876	0.0	860.0
2473	0.0	-16.96	9.888	0.0	861.0
2476	0.0	-16.98	9.900	0.0	862.0
2479	0.0	-17.00	9.912	0.0	863.0
2482	0.0	-17.03	9.924	0.0	864.5
2485	0.0	-17.05	9.936	0.0	865.5
2488	0.0	-17.07	9.948	0.0	866.5
2491	0.0	-17.09	9.960	0.0	867.5
2494	-0.2	-17.11	9.972	-0.1	868.5
2497	-0.4	-17.13	9.984	-0.2	869.5
2500	0.2	-17.15	9.996	0.1	870.5
2503	0.0	-17.18	10.008	0.0	872.0
2506	0.0	-17.20	10.020	0.0	873.0
2509	0.0	-17.22	10.032	0.0	874.0
2512	0.0	-17.24	10.044	0.0	875.0
2515	0.2	-17.27	10.056	0.1	876.5
2518	0.0	-17.29	10.068	0.0	877.5
2521	-0.2	-17.31	10.080	-0.1	878.5
2524	0.0	-17.33	10.092	0.0	879.5
2527	0.0	-17.35	10.104	0.0	880.5
2530	0.0	-17.37	10.116	0.0	881.5
2533	0.0	-17.39	10.128	0.0	882.5
2536	0.0	-17.41	10.140	0.0	884.0
2539	-0.4	-17.43	10.152	-0.2	885.0
2542	0.2	-17.45	10.164	0.1	886.0
2545	0.0	-17.47	10.176	0.0	887.0
2548	0.0	-17.49	10.188	0.0	888.0
2551	0.2	-17.52	10.200	0.1	889.5
2554	-0.2	-17.54	10.212	-0.1	890.5
2557	0.0	-17.56	10.224	0.0	891.5
2560	0.0	-17.58	10.236	0.0	892.5
2563	0.2	-17.60	10.248	0.1	893.5
2566	0.0	-17.62	10.260	0.0	894.5
2569	0.0	-17.64	10.272	0.0	895.5
2572	0.0	-17.66	10.284	0.0	896.5
2575	0.0	-17.68	10.296	0.0	897.5
2578	-0.2	-17.70	10.308	-0.1	898.5
2581	0.0	-17.72	10.320	0.0	899.5
2584	0.0	-17.75	10.332	0.0	901.0
2587	0.0	-17.77	10.344	0.0	902.0
2590	0.0	-17.79	10.356	0.0	903.0
2593	0.2	-17.81	10.368	0.1	904.0
2596	0.4	-17.83	10.380	0.2	905.0
2599	0.0	-17.85	10.392	0.0	906.0
2602	0.2	-17.87	10.404	0.1	907.0
2605	0.2	-17.89	10.416	0.1	908.0
2608	0.2	-17.91	10.428	0.1	909.0
2611	-0.2	-17.93	10.440	-0.1	910.0
2614	0.4	-17.95	10.452	0.2	911.0
2617	0.0	-17.98	10.464	0.0	912.5
2620	0.0	-18.00	10.476	0.0	913.5
2623	0.0	-18.02	10.488	0.0	914.5
2626	0.0	-18.04	10.500	0.0	915.5
2629	-0.2	-18.06	10.512	-0.1	917.0
2632	0.0	-18.08	10.524	0.0	918.0
2635	0.2	-18.10	10.536	0.1	919.0
2638	-0.2	-18.12	10.548	-0.1	920.0
2641	0.0	-18.14	10.560	0.0	921.0
2644	0.0	-18.16	10.572	0.0	922.0
2647	-0.2	-18.18	10.584	-0.1	923.0
2650	0.0	-18.21	10.596	0.0	924.5
2653	0.0	-18.23	10.608	0.0	925.5
2656	0.2	-18.25	10.620	0.1	926.5
2659	0.2	-18.27	10.632	0.1	927.5
2662	0.0	-18.29	10.644	0.0	928.5
2665	-0.4	-18.31	10.656	-0.2	929.5
2668	0.0	-18.33	10.668	0.0	930.5
2671	0.2	-18.35	10.680	0.1	931.5
2674	0.0	-18.37	10.692	0.0	932.5
2677	0.0	-18.39	10.704	0.0	933.5
2680	0.0	-18.42	10.716	0.0	935.0
2683	0.0	-18.44	10.728	0.0	936.0
2686	0.2	-18.46	10.740	0.1	937.0
2689	0.2	-18.48	10.752	0.1	938.0
2692	0.0	-18.50	10.764	0.0	939.0
2695	-0.4	-18.52	10.776	-0.2	940.0
2698	0.0	-18.54	10.788	0.0	941.0
2701	-0.2	-18.56	10.800	-0.1	942.0
2704	0.2	-18.58	10.812	0.1	943.0
2707	0.0	-18.61	10.824	0.0	944.5
2710	0.2	-18.63	10.836	0.1	945.5
2713	0.0	-18.65	10.848	0.0	946.5
2716	-0.2	-18.67	10.860	-0.1	947.5
2719	0.0	-18.69	10.872	0.0	948.5
2722	0.4	-18.71	10.884	0.2	949.5
2725	0.2	-18.73	10.896	0.1	951.0
2728	0.0	-18.75	10.908	0.0	952.0
2731	0.0	-18.77	10.920	0.0	953.0
2734	0.0	-18.80	10.932	0.0	954.5
2737	0.0	-18.82	10.944	0.0	955.5
2740	0.2	-18.84	10.956	0.1	956.5
2743	0.0	-18.86	10.968	0.0	957.5
2746	0.0	-18.88	10.980	0.0	958.5
2749	0.0	-18.90	10.992	0.0	959.5
2752	0.0	-18.92	11.004	0.0	960.5
2755	0.0	-18.94	11.016	0.0	961.5
2758	0.0	-18.96	11.028	0.0	962.5
2761	0.0	-18.99	11.040	0.0	964.0
2764	0.0	-19.01	11.052	0.0	965.0
2767	0.2	-19.03	11.064	0.1	966.0
2770	-0.2	-19.05	11.076	-0.1	967.0
2773	0.0	-19.07	11.088	0.0	968.0
2776	0.0	-19.09	11.100	0.0	969.0
2779	0.0	-19.11	11.112	0.0	970.0
2782	0.0	-19.13	11.124	0.0	971.0
2785	0.2	-19.15	11.136	0.1	972.0
2788	0.0	-19.18	11.148	0.0	973.5
2791	-0.2	-19.19	11.160	-0.1	974.0
2794	0.0	-19.21	11.172	0.0	975.0
2797	-0.2	-19.23	11.184	-0.1	976.0
2800	0.2	-19.25	11.196	0.1	977.0
2803	-0.2	-19.27	11.208	-0.1	978.0
2806	0.0	-19.29	11.220	0.0	979.0
2809	-0.2	-19.31	11.232	-0.1	980.0
2812	-0.2	-19.34	11.244	-0.1	981.5
2815	0.0	-19.36	11.256	0.0	982.5
2818	0.0	-19.38	11.268	0.0	984.0
2821	0.0	-19.40	11.280	0.0	985.0
2824	0.0	-19.42	11.292	0.0	986.0
2827	0.0	-19.44	11.304	0.0	987.0
2830	0.2	-19.46	11.316	0.1	988.0
2833	0.2	-19.48	11.328	0.1	989.0
2836	-0.2	-19.50	11.340	-0.1	990.0
2839	0.2	-19.53	11.352	0.1	991.5
2842	0.0	-19.55	11.364	0.0	992.5
2845	0.2	-19.57	11.376	0.1	993.5
2848	0.0	-19.59	11.388	0.0	994.5
2851	0.2	-19.61	11.400	0.1	995.5
2854	0.0	-19.63	11.412	0.0	996.5
2857	-0.2	-19.65	11.424	-0.1	997.5
2860	-0.2	-19.67	11.436	-0.1	998.5
2863	0.0	-19.69	11.448	0.0	999.5
2866	0.0	-19.72	11.460	0.0	1001.0
2869	0.2	-19.74	11.472	0.1	1002.0
2872	0.0	-19.76	11.484	0.0	1003.0
2875	0.0	-19.78	11.496	0.0	1004.0
2878	-0.2	-19.80	11.508	-0.1	1005.0
2881	0.0	-19.82	11.520	0.0	1006.0
2884	-0.2	-19.84	11.532	-0.1	1007.0
2887	0.0	-19.86	11.544	0.0	1008.0
2890	0.0	-19.88	11.556	0.0	1009.0
2893	-0.2	-19.91	11.568	-0.1	1010.5
2896	0.0	-19.93	11.580	0.0	1011.5
2899	0.0	-19.95	11.592	0.0	1012.5
2902	0.0	-19.97	11.604	0.0	1013.5
2905	0.0	-19.99	11.616	0.0	1014.5
2908	0.0	-20.01	11.628	0.0	1015.5
2911	-0.2	-20.03	11.640	-0.1	1017.0
2914	0.0	-20.05	11.652	0.0	1018.0
2917	0.0	-20.07	11.664	0.0	1019.0
2920	0.0	-20.10	11.676	0.0	1020.5
2923	0.2	-20.12	11.688	0.1	1021.5
2926	0.2	-20.14	11.700	0.1	1022.5
2929	0.0	-20.16	11.712	0.0	1023.5
2932	-0.2	-20.18	11.724	-0.1	1024.5
2935	0.0	-20.20	11.736	0.0	1025.5
2938	0.0	-20.22	11.748	0.0	1026.5
2941	0.0	-20.24	11.760	0.0	1027.5
2944	-0.2	-20.26	11.772	-0.1	1028.5
2947	-0.2	-20.29	11.784	-0.1	1030.0
2950	-0.2	-20.31	11.796	-0.1	1031.0
2953	-0.2	-20.33	11.808	-0.1	1032.0
2956	0.0	-20.35	11.820	0.0	1033.0
2959	0.0	-20.37	11.832	0.0	1034.0
2962	0.0	-20.39	11.844	0.0	1035.0
2965	-0.4	-20.41	11.856	-0.2	1036.0
2968	0.0	-20.43	11.868	0.0	1037.0
2971	0.2	-20.45	11.880	0.1	1038.0
2974	-0.2	-20.48	11.892	-0.1	1039.5
2977	0.0	-20.50	11.904	0.0	1040.5
2980	0.2	-20.52	11.916	0.1	1041.5
2983	-0.2	-20.54	11.928	-0.1	1042.5
2986	0.0	-20.56	11.940	0.0	1043.5
2989	0.0	-20.58	11.952	0.0	1044.5
2992	0.4	-20.60	11.964	0.2	1045.5
2995	0.0	-20.62	11.976	0.0	1046.5
2998	-0.2	-20.64	11.988	-0.1	1047.5
3001	0.4	-20.66	12.000	0.2	1048.5
3004	0.6	-20.69	12.012	0.3	1050.5
3007	0.8	-20.71	12.024	0.4	1051.5
3010	2.0	-20.73	12.036	1.1	1052.5
3013	2.8	-20.75	12.048	1.5	1053.5
3016	3.6	-20.77	12.060	2.0	1054.5
3019	4.4	-20.79	12.072	2.4	1055.5
3022	5.8	-20.81	12.084	3.2	1056.5
3025	6.6	-20.83	12.096	3.6	1057.5
3028	6.6	-20.85	12.108	3.6	1058.5
3031	6.0	-20.87	12.120	3.3	1059.5
3034	5.4	-20.89	12.132	2.9	1060.5
3037	5.0	-20.92	12.144	2.7	1062.0
3040	5.0	-20.94	12.156	2.7	1063.0
3043	5.0	-20.96	12.168	2.7	1064.0
3046	4.4	-20.98	12.180	2.4	1065.0
3049	4.2	-21.00	12.192	2.3	1066.0
3052	4.0	-21.02	12.204	2.2	1067.0
3055	4.2	-21.04	12.216	2.3	1068.0
3058	4.2	-21.06	12.228	2.3	1069.0
3061	4.8	-21.08	12.240	2.6	1070.0
3064	5.8	-21.10	12.252	3.2	1071.0
3067	6.8	-21.12	12.264	3.7	1072.0
3070	8.8	-21.14	12.276	4.8	1073.0
3073	10.4	-21.16	12.288	5.7	1074.0
3076	12.0	-21.18	12.300	6.5	1075.0
3079	13.0	-21.20	12.312	7.1	1076.0
3082	13.4	-21.22	12.324	7.3	1077.0
3085	14.2	-21.24	12.336	7.7	1078.0
3088	14.8	-21.26	12.348	8.0	1079.0
3091	14.8	-21.28	12.360	8.0	1080.0
3094	15.8	-21.30	12.372	8.6	1081.0
3097	15.8	-21.32	12.384	8.6	1082.0
3100	16.0	-21.34	12.396	8.7	1083.0
3103	16.0	-21.37	12.408	8.7	1085.0
3106	16.0	-21.39	12.420	8.7	1086.0
3109	16.2	-21.41	12.432	8.8	1087.0
3112	17.2	-21.43	12.444	9.4	1088.0
3115	18.2	-21.44	12.456	9.9	1088.5
3118	19.0	-21.47	12.468	10.3	1090.0
3121	19.4	-21.48	12.480	10.6	1090.5
3124	20.2	-21.51	12.492	11.0	1092.0
3127	20.8	-21.53	12.504	11.3	1093.0
3130	19.4	-21.55	12.516	10.6	1094.0
3133	18.6	-21.56	12.528	10.1	1094.5
3136	16.0	-21.57	12.540	8.7	1095.0
3139	15.0	-21.57	12.552	8.2	1095.0
3142	14.6	-21.57	12.564	7.9	1095.0
3145	14.4	-21.57	12.576	7.8	1095.0
3148	13.8	-21.57	12.588	7.5	1095.0
3151	13.8	-21.57	12.600	7.5	1095.0
3154	13.6	-21.57	12.612	7.4	1095.0
3157	13.6	-21.57	12.624	7.4	1095.0
3160	13.4	-21.57	12.636	7.3	1095.0
3162	21.0	-21.53	12.644	7.2	1095.0