File: results/youngs-modulus/2025-04-17/inconclusive-data/pf16lt02.csv
sep=
pf16lt02

System Information:
IntelliMESUR Version: 2.2.1
Test Frame Model: F505
Test Frame Serial Number: 4418651
Test Frame Capacity: 500 lbF / 2.2 kN
Test Frame Firmware Version: 1.00.14
Force Sensor Model: FS05-100
Force Sensor Capacity: 500 N
Force Sensor Resolution: 0.2 N
Force Sensor Serial Number: 4425350
Calibration Date: Apr 29, 2024
Calibration Due Date: Apr 29, 2025

Reading	Load [N]	Distance [mm]	Time [s]	Stress [MPa]	Strain [%]
1	0.0	-0.02	0.000	0.00	0.6
4	0.0	-0.02	0.012	0.00	0.6
7	0.0	-0.02	0.024	0.00	0.6
10	0.0	-0.02	0.036	0.00	0.6
13	0.2	-0.02	0.048	0.02	0.6
16	0.0	-0.02	0.060	0.00	0.6
19	0.2	-0.02	0.072	0.02	0.6
22	0.0	-0.02	0.084	0.00	0.6
25	0.0	-0.02	0.096	0.00	0.6
28	0.0	-0.02	0.108	0.00	0.6
31	0.0	-0.02	0.120	0.00	0.6
34	0.2	-0.02	0.132	0.02	0.6
37	0.0	-0.02	0.144	0.00	0.6
40	0.0	-0.02	0.156	0.00	0.6
43	0.0	-0.02	0.168	0.00	0.6
46	0.0	-0.02	0.180	0.00	0.6
49	0.0	-0.03	0.192	0.00	1.0
52	0.0	-0.05	0.204	0.00	1.6
55	0.0	-0.08	0.216	0.00	2.4
58	0.0	-0.10	0.228	0.00	3.0
61	0.2	-0.12	0.240	0.02	3.6
64	-0.2	-0.14	0.252	-0.02	4.2
67	0.2	-0.16	0.264	0.02	4.8
70	0.0	-0.18	0.276	0.00	5.4
73	0.2	-0.20	0.288	0.02	6.0
76	0.4	-0.22	0.300	0.04	6.6
79	0.0	-0.25	0.312	0.00	7.6
82	0.0	-0.27	0.324	0.00	8.2
85	0.0	-0.29	0.336	0.00	8.8
88	0.0	-0.31	0.348	0.00	9.4
91	0.2	-0.33	0.360	0.02	10.0
94	0.0	-0.35	0.372	0.00	10.6
97	0.0	-0.37	0.384	0.00	11.2
100	0.0	-0.39	0.396	0.00	11.8
103	0.0	-0.40	0.408	0.00	12.0
106	0.0	-0.43	0.420	0.00	13.0
109	-0.2	-0.45	0.432	-0.02	13.6
112	-0.2	-0.47	0.444	-0.02	14.2
115	0.0	-0.49	0.456	0.00	14.8
118	-0.2	-0.51	0.468	-0.02	15.4
121	0.2	-0.53	0.480	0.02	16.0
124	0.0	-0.55	0.492	0.00	16.6
127	0.2	-0.57	0.504	0.02	17.2
130	0.0	-0.59	0.516	0.00	17.8
133	0.2	-0.61	0.528	0.02	18.4
136	-0.2	-0.64	0.540	-0.02	19.2
139	0.0	-0.66	0.552	0.00	19.8
142	-0.2	-0.68	0.564	-0.02	20.4
145	0.2	-0.70	0.576	0.02	21.0
148	0.0	-0.72	0.588	0.00	21.6
151	0.0	-0.74	0.600	0.00	22.2
154	0.0	-0.76	0.612	0.00	22.8
157	-0.2	-0.78	0.624	-0.02	23.4
160	0.0	-0.80	0.636	0.00	24.0
163	0.2	-0.83	0.648	0.02	25.0
166	0.0	-0.85	0.660	0.00	25.6
169	0.0	-0.87	0.672	0.00	26.2
172	0.0	-0.89	0.684	0.00	26.8
175	0.0	-0.91	0.696	0.00	27.4
178	0.0	-0.93	0.708	0.00	28.0
181	-0.2	-0.95	0.720	-0.02	28.6
184	0.0	-0.97	0.732	0.00	29.2
187	0.6	-0.99	0.744	0.06	29.8
190	0.0	-1.01	0.756	0.00	30.4
193	0.0	-1.03	0.768	0.00	31.0
196	0.2	-1.06	0.780	0.02	32.0
199	0.0	-1.08	0.792	0.00	32.6
202	0.2	-1.10	0.804	0.02	33.2
205	0.0	-1.12	0.816	0.00	33.8
208	0.0	-1.14	0.828	0.00	34.4
211	0.0	-1.16	0.840	0.00	35.0
214	0.0	-1.18	0.852	0.00	35.6
217	0.0	-1.20	0.864	0.00	36.2
220	-0.2	-1.22	0.876	-0.02	36.8
223	0.0	-1.24	0.888	0.00	37.4
226	0.2	-1.26	0.900	0.02	38.0
229	0.0	-1.29	0.912	0.00	38.8
232	0.0	-1.31	0.924	0.00	39.4
235	0.2	-1.33	0.936	0.02	40.0
238	0.0	-1.35	0.948	0.00	40.6
241	0.0	-1.37	0.960	0.00	41.2
244	0.0	-1.40	0.972	0.00	42.2
247	0.0	-1.42	0.984	0.00	42.8
250	0.0	-1.44	0.996	0.00	43.4
253	0.0	-1.46	1.008	0.00	44.0
256	0.0	-1.49	1.020	0.00	44.8
259	0.0	-1.51	1.032	0.00	45.4
262	0.0	-1.53	1.044	0.00	46.0
265	-0.2	-1.55	1.056	-0.02	46.6
268	0.2	-1.57	1.068	0.02	47.2
271	0.0	-1.59	1.080	0.00	47.8
274	0.2	-1.61	1.092	0.02	48.4
277	0.0	-1.63	1.104	0.00	49.0
280	-0.2	-1.65	1.116	-0.02	49.6
283	0.4	-1.67	1.128	0.04	50.4
286	0.0	-1.69	1.140	0.00	51.0
289	0.0	-1.71	1.152	0.00	51.6
292	0.0	-1.74	1.164	0.00	52.4
295	-0.2	-1.76	1.176	-0.02	53.0
298	0.0	-1.78	1.188	0.00	53.6
301	0.0	-1.80	1.200	0.00	54.2
304	0.0	-1.82	1.212	0.00	54.8
307	0.0	-1.84	1.224	0.00	55.4
310	-0.2	-1.86	1.236	-0.02	56.0
313	0.2	-1.88	1.248	0.02	56.6
316	0.0	-1.90	1.260	0.00	57.2
319	0.0	-1.92	1.272	0.00	57.8
322	0.0	-1.94	1.284	0.00	58.4
325	0.0	-1.97	1.296	0.00	59.4
328	0.0	-1.99	1.308	0.00	60.0
331	-0.2	-2.01	1.320	-0.02	60.6
334	0.0	-2.03	1.332	0.00	61.2
337	0.2	-2.05	1.344	0.02	61.8
340	0.0	-2.07	1.356	0.00	62.4
343	0.2	-2.09	1.368	0.02	63.0
346	-0.2	-2.11	1.380	-0.02	63.6
349	0.2	-2.13	1.392	0.02	64.2
352	0.0	-2.15	1.404	0.00	64.8
355	0.0	-2.17	1.416	0.00	65.4
358	0.0	-2.20	1.428	0.00	66.2
361	0.2	-2.21	1.440	0.02	66.6
364	0.0	-2.24	1.452	0.00	67.4
367	0.0	-2.26	1.464	0.00	68.0
370	0.0	-2.28	1.476	0.00	68.6
373	0.0	-2.30	1.488	0.00	69.2
376	0.0	-2.32	1.500	0.00	69.8
379	0.0	-2.34	1.512	0.00	70.4
382	-0.4	-2.36	1.524	-0.04	71.0
385	0.0	-2.38	1.536	0.00	71.6
388	0.0	-2.39	1.548	0.00	72.0
391	0.2	-2.41	1.560	0.02	72.6
394	0.0	-2.43	1.572	0.00	73.2
397	0.0	-2.46	1.584	0.00	74.0
400	-0.2	-2.48	1.596	-0.02	74.6
403	0.0	-2.50	1.608	0.00	75.4
406	0.0	-2.52	1.620	0.00	76.0
409	0.0	-2.54	1.632	0.00	76.6
412	0.0	-2.56	1.644	0.00	77.2
415	0.0	-2.58	1.656	0.00	77.8
418	0.0	-2.60	1.668	0.00	78.4
421	0.0	-2.62	1.680	0.00	79.0
424	0.0	-2.64	1.692	0.00	79.6
427	-0.2	-2.67	1.704	-0.02	80.4
430	-0.2	-2.68	1.716	-0.02	80.8
433	0.0	-2.71	1.728	0.00	81.6
436	0.0	-2.73	1.740	0.00	82.2
439	0.4	-2.75	1.752	0.04	82.8
442	0.0	-2.77	1.764	0.00	83.4
445	0.0	-2.79	1.776	0.00	84.0
448	0.0	-2.81	1.788	0.00	84.6
451	0.0	-2.83	1.800	0.00	85.2
454	-0.2	-2.85	1.812	-0.02	85.8
457	0.2	-2.87	1.824	0.02	86.4
460	0.0	-2.89	1.836	0.00	87.0
463	-0.4	-2.91	1.848	-0.04	87.6
466	0.0	-2.94	1.860	0.00	88.6
469	0.0	-2.96	1.872	0.00	89.2
472	0.2	-2.98	1.884	0.02	89.8
475	0.0	-3.00	1.896	0.00	90.4
478	0.0	-3.02	1.908	0.00	91.0
481	-0.2	-3.04	1.920	-0.02	91.6
484	0.0	-3.06	1.932	0.00	92.2
487	0.4	-3.08	1.944	0.04	92.8
490	0.0	-3.10	1.956	0.00	93.4
493	0.0	-3.13	1.968	0.00	94.2
496	0.0	-3.15	1.980	0.00	94.8
499	0.0	-3.17	1.992	0.00	95.4
502	0.0	-3.19	2.004	0.00	96.0
505	-0.2	-3.21	2.016	-0.02	96.6
508	-0.2	-3.23	2.028	-0.02	97.2
511	0.0	-3.25	2.040	0.00	97.8
514	0.0	-3.27	2.052	0.00	98.4
517	-0.2	-3.29	2.064	-0.02	99.0
520	0.0	-3.31	2.076	0.00	99.6
523	0.0	-3.33	2.088	0.00	100.4
526	0.2	-3.36	2.100	0.02	101.2
529	-0.4	-3.38	2.112	-0.04	101.8
532	0.0	-3.41	2.124	0.00	102.8
535	0.0	-3.43	2.136	0.00	103.4
538	0.2	-3.45	2.148	0.02	104.0
541	-0.2	-3.47	2.160	-0.02	104.6
544	0.0	-3.49	2.172	0.00	105.2
547	0.0	-3.51	2.184	0.00	105.8
550	-0.2	-3.53	2.196	-0.02	106.4
553	0.0	-3.56	2.208	0.00	107.2
556	-0.2	-3.58	2.220	-0.02	107.8
559	-0.2	-3.60	2.232	-0.02	108.4
562	0.2	-3.62	2.244	0.02	109.0
565	0.0	-3.64	2.256	0.00	109.6
568	0.0	-3.66	2.268	0.00	110.2
571	0.0	-3.68	2.280	0.00	110.8
574	0.0	-3.70	2.292	0.00	111.4
577	0.2	-3.72	2.304	0.02	112.0
580	0.0	-3.74	2.316	0.00	112.6
583	-0.4	-3.77	2.328	-0.04	113.6
586	-0.6	-3.79	2.340	-0.06	114.2
589	0.0	-3.81	2.352	0.00	114.8
592	0.2	-3.83	2.364	0.02	115.4
595	0.0	-3.85	2.376	0.00	116.0
598	0.0	-3.87	2.388	0.00	116.6
601	0.2	-3.89	2.400	0.02	117.2
604	0.0	-3.91	2.412	0.00	117.8
607	0.0	-3.93	2.424	0.00	118.4
610	0.0	-3.96	2.436	0.00	119.2
613	0.0	-3.98	2.448	0.00	119.8
616	0.0	-4.00	2.460	0.00	120.4
619	0.2	-4.02	2.472	0.02	121.0
622	-0.2	-4.04	2.484	-0.02	121.6
625	0.2	-4.06	2.496	0.02	122.2
628	0.0	-4.08	2.508	0.00	122.8
631	-0.2	-4.10	2.520	-0.02	123.4
634	0.4	-4.12	2.532	0.04	124.0
637	-0.2	-4.15	2.544	-0.02	125.0
640	-0.2	-4.17	2.556	-0.02	125.6
643	0.0	-4.19	2.568	0.00	126.2
646	0.0	-4.21	2.580	0.00	126.8
649	0.0	-4.23	2.592	0.00	127.4
652	-0.2	-4.25	2.604	-0.02	128.0
655	0.0	-4.27	2.616	0.00	128.6
658	0.0	-4.29	2.628	0.00	129.2
661	0.0	-4.31	2.640	0.00	129.8
664	-0.2	-4.34	2.652	-0.02	130.8
667	0.2	-4.36	2.664	0.02	131.4
670	0.2	-4.38	2.676	0.02	132.0
673	0.0	-4.40	2.688	0.00	132.6
676	0.0	-4.42	2.700	0.00	133.2
679	-0.2	-4.44	2.712	-0.02	133.8
682	0.4	-4.46	2.724	0.04	134.4
685	0.0	-4.48	2.736	0.00	135.0
688	0.0	-4.51	2.748	0.00	135.8
691	0.0	-4.53	2.760	0.00	136.4
694	0.0	-4.55	2.772	0.00	137.0
697	0.0	-4.57	2.784	0.00	137.6
700	0.0	-4.59	2.796	0.00	138.2
703	0.2	-4.61	2.808	0.02	138.8
706	0.0	-4.63	2.820	0.00	139.4
709	0.0	-4.65	2.832	0.00	140.0
712	0.0	-4.67	2.844	0.00	140.6
715	-0.6	-4.70	2.856	-0.06	141.6
718	0.0	-4.72	2.868	0.00	142.2
721	0.0	-4.74	2.880	0.00	142.8
724	-0.2	-4.76	2.892	-0.02	143.4
727	0.4	-4.78	2.904	0.04	144.0
730	0.0	-4.80	2.916	0.00	144.6
733	0.0	-4.82	2.928	0.00	145.2
736	0.2	-4.84	2.940	0.02	145.8
739	0.0	-4.86	2.952	0.00	146.4
742	0.4	-4.89	2.964	0.04	147.2
745	0.0	-4.91	2.976	0.00	147.8
748	0.0	-4.93	2.988	0.00	148.4
751	0.0	-4.95	3.000	0.00	149.0
754	0.0	-4.97	3.012	0.00	149.6
757	0.0	-4.99	3.024	0.00	150.4
760	0.0	-5.01	3.036	0.00	151.0
763	0.0	-5.03	3.048	0.00	151.6
766	0.0	-5.05	3.060	0.00	152.2
769	0.0	-5.08	3.072	0.00	153.0
772	0.0	-5.10	3.084	0.00	153.6
775	0.0	-5.12	3.096	0.00	154.2
778	0.0	-5.14	3.108	0.00	154.8
781	0.0	-5.16	3.120	0.00	155.4
784	0.0	-5.18	3.132	0.00	156.0
787	0.0	-5.20	3.144	0.00	156.6
790	0.2	-5.22	3.156	0.02	157.2
793	0.0	-5.24	3.168	0.00	157.8
796	0.0	-5.27	3.180	0.00	158.8
799	0.0	-5.29	3.192	0.00	159.4
802	0.4	-5.31	3.204	0.04	160.0
805	0.0	-5.33	3.216	0.00	160.6
808	0.0	-5.35	3.228	0.00	161.2
811	0.2	-5.37	3.240	0.02	161.8
814	-0.2	-5.39	3.252	-0.02	162.4
817	0.0	-5.41	3.264	0.00	163.0
820	-0.2	-5.43	3.276	-0.02	163.6
823	0.2	-5.46	3.288	0.02	164.4
826	0.0	-5.48	3.300	0.00	165.0
829	0.0	-5.50	3.312	0.00	165.6
832	0.0	-5.52	3.324	0.00	166.2
835	0.0	-5.54	3.336	0.00	166.8
838	0.0	-5.56	3.348	0.00	167.4
841	0.0	-5.58	3.360	0.00	168.0
844	0.0	-5.60	3.372	0.00	168.6
847	0.0	-5.62	3.384	0.00	169.2
850	0.2	-5.64	3.396	0.02	169.8
853	0.0	-5.67	3.408	0.00	170.8
856	0.0	-5.69	3.420	0.00	171.4
859	0.2	-5.71	3.432	0.02	172.0
862	0.0	-5.73	3.444	0.00	172.6
865	-0.2	-5.75	3.456	-0.02	173.2
868	-0.2	-5.77	3.468	-0.02	173.8
871	0.0	-5.79	3.480	0.00	174.4
874	-0.2	-5.81	3.492	-0.02	175.0
877	0.0	-5.83	3.504	0.00	175.6
880	0.0	-5.86	3.516	0.00	176.6
883	-0.2	-5.88	3.528	-0.02	177.2
886	0.0	-5.90	3.540	0.00	177.8
889	0.0	-5.92	3.552	0.00	178.4
892	0.2	-5.94	3.564	0.02	179.0
895	0.0	-5.96	3.576	0.00	179.6
898	0.2	-5.98	3.588	0.02	180.2
901	0.0	-6.00	3.600	0.00	180.8
904	0.2	-6.02	3.612	0.02	181.4
907	0.0	-6.04	3.624	0.00	182.0
910	0.0	-6.06	3.636	0.00	182.6
913	0.0	-6.09	3.648	0.00	183.4
916	-0.2	-6.11	3.660	-0.02	184.0
919	0.0	-6.13	3.672	0.00	184.6
922	0.2	-6.15	3.684	0.02	185.2
925	0.2	-6.17	3.696	0.02	185.8
928	0.0	-6.19	3.708	0.00	186.4
931	0.0	-6.21	3.720	0.00	187.0
934	0.0	-6.23	3.732	0.00	187.6
937	0.0	-6.25	3.744	0.00	188.2
940	0.0	-6.27	3.756	0.00	188.8
943	0.2	-6.29	3.768	0.02	189.4
946	0.2	-6.32	3.780	0.02	190.4
949	0.2	-6.34	3.792	0.02	191.0
952	0.0	-6.36	3.804	0.00	191.6
955	0.0	-6.38	3.816	0.00	192.2
958	0.2	-6.40	3.828	0.02	192.8
961	0.0	-6.41	3.840	0.00	193.0
964	0.2	-6.43	3.852	0.02	193.6
967	0.0	-6.45	3.864	0.00	194.2
970	-0.2	-6.47	3.876	-0.02	194.8
973	0.0	-6.49	3.888	0.00	195.4
976	0.0	-6.51	3.900	0.00	196.0
979	0.2	-6.53	3.912	0.02	196.6
982	0.0	-6.56	3.924	0.00	197.6
985	0.2	-6.58	3.936	0.02	198.2
988	-0.2	-6.60	3.948	-0.02	198.8
991	0.0	-6.62	3.960	0.00	199.4
994	0.0	-6.64	3.972	0.00	200.0
997	-0.2	-6.66	3.984	-0.02	200.6
1000	0.0	-6.68	3.996	0.00	201.2
1003	0.0	-6.70	4.008	0.00	201.8
1006	0.0	-6.72	4.020	0.00	202.4
1009	0.0	-6.74	4.032	0.00	203.0
1012	0.0	-6.76	4.044	0.00	203.6
1015	-0.2	-6.79	4.056	-0.02	204.6
1018	0.0	-6.80	4.068	0.00	204.8
1021	-0.2	-6.83	4.080	-0.02	205.8
1024	0.0	-6.85	4.092	0.00	206.4
1027	0.0	-6.87	4.104	0.00	207.0
1030	0.0	-6.89	4.116	0.00	207.6
1033	0.2	-6.91	4.128	0.02	208.2
1036	0.0	-6.93	4.140	0.00	208.8
1039	0.0	-6.95	4.152	0.00	209.4
1042	0.0	-6.97	4.164	0.00	210.0
1045	0.4	-6.99	4.176	0.04	210.6
1048	0.0	-7.01	4.188	0.00	211.2
1051	-0.2	-7.03	4.200	-0.02	211.8
1054	0.0	-7.06	4.212	0.00	212.6
1057	0.0	-7.08	4.224	0.00	213.2
1060	0.0	-7.10	4.236	0.00	213.8
1063	0.0	-7.12	4.248	0.00	214.4
1066	0.4	-7.14	4.260	0.04	215.0
1069	0.0	-7.16	4.272	0.00	215.6
1072	0.0	-7.18	4.284	0.00	216.2
1075	-0.2	-7.20	4.296	-0.02	216.8
1078	0.2	-7.22	4.308	0.02	217.4
1081	0.2	-7.24	4.320	0.02	218.0
1084	0.0	-7.26	4.332	0.00	218.6
1087	0.0	-7.29	4.344	0.00	219.6
1090	-0.2	-7.31	4.356	-0.02	220.2
1093	0.2	-7.33	4.368	0.02	220.8
1096	0.0	-7.35	4.380	0.00	221.4
1099	0.0	-7.37	4.392	0.00	222.0
1102	0.2	-7.39	4.404	0.02	222.6
1105	0.0	-7.42	4.416	0.00	223.4
1108	-0.2	-7.44	4.428	-0.02	224.0
1111	0.0	-7.46	4.440	0.00	224.6
1114	0.4	-7.48	4.452	0.04	225.4
1117	0.0	-7.50	4.464	0.00	226.0
1120	0.0	-7.52	4.476	0.00	226.6
1123	-0.2	-7.55	4.488	-0.02	227.4
1126	0.0	-7.57	4.500	0.00	228.0
1129	0.0	-7.59	4.512	0.00	228.6
1132	0.0	-7.61	4.524	0.00	229.2
1135	0.0	-7.63	4.536	0.00	229.8
1138	0.0	-7.65	4.548	0.00	230.4
1141	0.0	-7.67	4.560	0.00	231.0
1144	0.0	-7.69	4.572	0.00	231.6
1147	0.0	-7.71	4.584	0.00	232.2
1150	0.0	-7.73	4.596	0.00	232.8
1153	0.0	-7.75	4.608	0.00	233.4
1156	0.2	-7.78	4.620	0.02	234.4
1159	0.0	-7.80	4.632	0.00	235.0
1162	0.0	-7.82	4.644	0.00	235.6
1165	0.2	-7.84	4.656	0.02	236.2
1168	0.0	-7.86	4.668	0.00	236.8
1171	-0.2	-7.88	4.680	-0.02	237.4
1174	0.0	-7.90	4.692	0.00	238.0
1177	-0.2	-7.92	4.704	-0.02	238.6
1180	0.0	-7.94	4.716	0.00	239.2
1183	0.2	-7.96	4.728	0.02	239.8
1186	0.2	-7.98	4.740	0.02	240.4
1189	0.0	-8.00	4.752	0.00	241.0
1192	0.2	-8.03	4.764	0.02	241.8
1195	0.0	-8.05	4.776	0.00	242.4
1198	-0.2	-8.07	4.788	-0.02	243.0
1201	0.0	-8.09	4.800	0.00	243.6
1204	-0.2	-8.11	4.812	-0.02	244.2
1207	0.0	-8.13	4.824	0.00	244.8
1210	0.0	-8.15	4.836	0.00	245.4
1213	0.2	-8.17	4.848	0.02	246.0
1216	0.4	-8.19	4.860	0.04	246.6
1219	0.4	-8.21	4.872	0.04	247.2
1222	0.4	-8.23	4.884	0.04	247.8
1225	0.0	-8.26	4.896	0.00	248.8
1228	-0.4	-8.28	4.908	-0.04	249.4
1231	0.2	-8.30	4.920	0.02	250.0
1234	0.2	-8.32	4.932	0.02	250.6
1237	0.0	-8.34	4.944	0.00	251.2
1240	-0.2	-8.36	4.956	-0.02	251.8
1243	0.0	-8.38	4.968	0.00	252.4
1246	0.0	-8.40	4.980	0.00	253.0
1249	0.0	-8.42	4.992	0.00	253.6
1252	0.0	-8.45	5.004	0.00	254.6
1255	0.0	-8.47	5.016	0.00	255.2
1258	0.0	-8.49	5.028	0.00	255.8
1261	0.0	-8.51	5.040	0.00	256.4
1264	0.0	-8.53	5.052	0.00	257.0
1267	0.2	-8.55	5.064	0.02	257.6
1270	-0.2	-8.57	5.076	-0.02	258.2
1273	0.0	-8.59	5.088	0.00	258.8
1276	0.2	-8.61	5.100	0.02	259.4
1279	0.0	-8.63	5.112	0.00	260.0
1282	0.0	-8.65	5.124	0.00	260.6
1285	0.0	-8.68	5.136	0.00	261.4
1288	0.0	-8.70	5.148	0.00	262.0
1291	0.2	-8.72	5.160	0.02	262.6
1294	0.0	-8.74	5.172	0.00	263.2
1297	-0.4	-8.76	5.184	-0.04	263.8
1300	0.0	-8.78	5.196	0.00	264.4
1303	0.0	-8.80	5.208	0.00	265.0
1306	0.2	-8.82	5.220	0.02	265.6
1309	0.2	-8.84	5.232	0.02	266.2
1312	-0.2	-8.87	5.244	-0.02	267.2
1315	0.0	-8.89	5.256	0.00	267.8
1318	-0.2	-8.91	5.268	-0.02	268.4
1321	0.0	-8.93	5.280	0.00	269.0
1324	0.2	-8.95	5.292	0.02	269.6
1327	0.2	-8.97	5.304	0.02	270.2
1330	0.0	-8.99	5.316	0.00	270.8
1333	0.2	-9.01	5.328	0.02	271.4
1336	0.0	-9.03	5.340	0.00	272.0
1339	0.0	-9.06	5.352	0.00	272.8
1342	0.0	-9.08	5.364	0.00	273.4
1345	-0.2	-9.10	5.376	-0.02	274.0
1348	0.2	-9.12	5.388	0.02	274.6
1351	0.2	-9.14	5.400	0.02	275.4
1354	-0.2	-9.16	5.412	-0.02	276.0
1357	0.0	-9.18	5.424	0.00	276.6
1360	0.0	-9.20	5.436	0.00	277.2
1363	0.0	-9.22	5.448	0.00	277.8
1366	0.0	-9.25	5.460	0.00	278.6
1369	0.0	-9.27	5.472	0.00	279.2
1372	-0.2	-9.29	5.484	-0.02	279.8
1375	0.0	-9.31	5.496	0.00	280.4
1378	0.0	-9.33	5.508	0.00	281.0
1381	0.0	-9.35	5.520	0.00	281.6
1384	0.2	-9.37	5.532	0.02	282.2
1387	0.0	-9.39	5.544	0.00	282.8
1390	0.4	-9.41	5.556	0.04	283.4
1393	0.0	-9.44	5.568	0.00	284.4
1396	0.2	-9.46	5.580	0.02	285.0
1399	0.0	-9.48	5.592	0.00	285.6
1402	-0.2	-9.50	5.604	-0.02	286.2
1405	0.0	-9.52	5.616	0.00	286.8
1408	0.0	-9.54	5.628	0.00	287.4
1411	0.2	-9.56	5.640	0.02	288.0
1414	0.0	-9.59	5.652	0.00	288.8
1417	0.0	-9.60	5.664	0.00	289.2
1420	0.0	-9.63	5.676	0.00	290.0
1423	0.0	-9.65	5.688	0.00	290.6
1426	0.0	-9.67	5.700	0.00	291.2
1429	0.0	-9.69	5.712	0.00	291.8
1432	0.0	-9.71	5.724	0.00	292.4
1435	0.4	-9.73	5.736	0.04	293.0
1438	0.0	-9.75	5.748	0.00	293.6
1441	-0.2	-9.78	5.760	-0.02	294.6
1444	0.0	-9.80	5.772	0.00	295.2
1447	0.4	-9.82	5.784	0.04	295.8
1450	0.0	-9.84	5.796	0.00	296.4
1453	0.0	-9.86	5.808	0.00	297.0
1456	-0.2	-9.88	5.820	-0.02	297.6
1459	-0.4	-9.90	5.832	-0.04	298.2
1462	0.0	-9.92	5.844	0.00	298.8
1465	0.0	-9.94	5.856	0.00	299.4
1468	-0.2	-9.97	5.868	-0.02	300.4
1471	0.0	-9.99	5.880	0.00	301.0
1474	-0.2	-10.01	5.892	-0.02	301.6
1477	0.0	-10.03	5.904	0.00	302.2
1480	0.0	-10.05	5.916	0.00	302.8
1483	0.0	-10.07	5.928	0.00	303.4
1486	0.2	-10.09	5.940	0.02	304.0
1489	-0.2	-10.11	5.952	-0.02	304.6
1492	0.2	-10.13	5.964	0.02	305.2
1495	0.0	-10.16	5.976	0.00	306.0
1498	0.2	-10.18	5.988	0.02	306.6
1501	0.0	-10.20	6.000	0.00	307.2
1504	0.0	-10.22	6.012	0.00	307.8
1507	0.2	-10.24	6.024	0.02	308.4
1510	0.0	-10.26	6.036	0.00	309.0
1513	0.2	-10.28	6.048	0.02	309.6
1516	-0.2	-10.30	6.060	-0.02	310.2
1519	0.0	-10.32	6.072	0.00	310.8
1522	-0.2	-10.35	6.084	-0.02	311.8
1525	-0.2	-10.37	6.096	-0.02	312.4
1528	0.0	-10.39	6.108	0.00	313.0
1531	0.2	-10.40	6.120	0.02	313.2
1534	0.0	-10.42	6.132	0.00	313.8
1537	-0.4	-10.44	6.144	-0.04	314.4
1540	0.4	-10.46	6.156	0.04	315.0
1543	0.0	-10.48	6.168	0.00	315.6
1546	0.0	-10.50	6.180	0.00	316.2
1549	0.2	-10.53	6.192	0.02	317.2
1552	0.0	-10.55	6.204	0.00	317.8
1555	-0.2	-10.57	6.216	-0.02	318.4
1558	0.0	-10.59	6.228	0.00	319.0
1561	0.0	-10.61	6.240	0.00	319.6
1564	0.0	-10.63	6.252	0.00	320.2
1567	0.0	-10.65	6.264	0.00	320.8
1570	-0.2	-10.67	6.276	-0.02	321.4
1573	0.0	-10.69	6.288	0.00	322.0
1576	0.0	-10.72	6.300	0.00	322.8
1579	0.0	-10.74	6.312	0.00	323.4
1582	-0.2	-10.76	6.324	-0.02	324.0
1585	0.0	-10.78	6.336	0.00	324.6
1588	0.0	-10.80	6.348	0.00	325.4
1591	0.0	-10.82	6.360	0.00	326.0
1594	0.0	-10.84	6.372	0.00	326.6
1597	0.0	-10.86	6.384	0.00	327.2
1600	0.4	-10.88	6.396	0.04	327.8
1603	0.0	-10.90	6.408	0.00	328.4
1606	0.0	-10.92	6.420	0.00	329.0
1609	0.0	-10.95	6.432	0.00	329.8
1612	0.0	-10.97	6.444	0.00	330.4
1615	-0.2	-10.99	6.456	-0.02	331.0
1618	0.0	-11.01	6.468	0.00	331.6
1621	-0.2	-11.03	6.480	-0.02	332.2
1624	-0.2	-11.05	6.492	-0.02	332.8
1627	0.2	-11.07	6.504	0.02	333.4
1630	0.0	-11.09	6.516	0.00	334.0
1633	0.0	-11.11	6.528	0.00	334.6
1636	0.2	-11.14	6.540	0.02	335.6
1639	-0.2	-11.16	6.552	-0.02	336.2
1642	-0.2	-11.18	6.564	-0.02	336.8
1645	0.0	-11.20	6.576	0.00	337.4
1648	0.0	-11.22	6.588	0.00	338.0
1651	0.2	-11.24	6.600	0.02	338.6
1654	0.0	-11.26	6.612	0.00	339.2
1657	0.0	-11.28	6.624	0.00	339.8
1660	0.0	-11.30	6.636	0.00	340.4
1663	0.2	-11.32	6.648	0.02	341.0
1666	0.0	-11.34	6.660	0.00	341.6
1669	0.4	-11.37	6.672	0.04	342.4
1672	-0.2	-11.39	6.684	-0.02	343.0
1675	0.0	-11.41	6.696	0.00	343.6
1678	0.0	-11.43	6.708	0.00	344.2
1681	0.0	-11.45	6.720	0.00	344.8
1684	0.0	-11.47	6.732	0.00	345.4
1687	-0.2	-11.49	6.744	-0.02	346.0
1690	0.0	-11.51	6.756	0.00	346.6
1693	0.0	-11.53	6.768	0.00	347.2
1696	0.0	-11.55	6.780	0.00	347.8
1699	0.0	-11.57	6.792	0.00	348.4
1702	0.0	-11.59	6.804	0.00	349.0
1705	-0.2	-11.62	6.816	-0.02	350.0
1708	-0.4	-11.64	6.828	-0.04	350.6
1711	0.2	-11.66	6.840	0.02	351.2
1714	0.0	-11.68	6.852	0.00	351.8
1717	-0.2	-11.70	6.864	-0.02	352.4
1720	0.0	-11.72	6.876	0.00	353.0
1723	-0.6	-11.74	6.888	-0.06	353.6
1726	-0.2	-11.76	6.900	-0.02	354.2
1729	0.4	-11.78	6.912	0.04	354.8
1732	0.0	-11.80	6.924	0.00	355.4
1735	0.4	-11.82	6.936	0.04	356.0
1738	0.0	-11.85	6.948	0.00	357.0
1741	0.0	-11.87	6.960	0.00	357.6
1744	0.0	-11.89	6.972	0.00	358.2
1747	0.2	-11.91	6.984	0.02	358.8
1750	0.0	-11.93	6.996	0.00	359.4
1753	0.0	-11.95	7.008	0.00	360.0
1756	0.0	-11.97	7.020	0.00	360.6
1759	0.0	-11.99	7.032	0.00	361.2
1762	0.0	-12.01	7.044	0.00	361.8
1765	0.2	-12.03	7.056	0.02	362.4
1768	0.0	-12.05	7.068	0.00	363.0
1771	0.0	-12.08	7.080	0.00	363.8
1774	0.0	-12.10	7.092	0.00	364.4
1777	0.0	-12.12	7.104	0.00	365.0
1780	0.0	-12.14	7.116	0.00	365.6
1783	0.2	-12.16	7.128	0.02	366.2
1786	0.0	-12.18	7.140	0.00	366.8
1789	-0.2	-12.20	7.152	-0.02	367.4
1792	0.0	-12.22	7.164	0.00	368.0
1795	-0.4	-12.24	7.176	-0.04	368.6
1798	0.0	-12.26	7.188	0.00	369.2
1801	0.0	-12.28	7.200	0.00	369.8
1804	0.2	-12.30	7.212	0.02	370.4
1807	0.0	-12.33	7.224	0.00	371.4
1810	0.0	-12.35	7.236	0.00	372.0
1813	0.0	-12.37	7.248	0.00	372.6
1816	-0.4	-12.39	7.260	-0.04	373.2
1819	-0.2	-12.42	7.272	-0.02	374.0
1822	-0.2	-12.44	7.284	-0.02	374.6
1825	0.2	-12.46	7.296	0.02	375.4
1828	0.0	-12.48	7.308	0.00	376.0
1831	0.0	-12.50	7.320	0.00	376.6
1834	0.4	-12.52	7.332	0.04	377.2
1837	0.0	-12.54	7.344	0.00	377.8
1840	-0.2	-12.57	7.356	-0.02	378.6
1843	0.0	-12.59	7.368	0.00	379.2
1846	0.0	-12.61	7.380	0.00	379.8
1849	0.0	-12.63	7.392	0.00	380.4
1852	0.0	-12.65	7.404	0.00	381.0
1855	0.0	-12.67	7.416	0.00	381.6
1858	0.0	-12.69	7.428	0.00	382.2
1861	0.0	-12.71	7.440	0.00	382.8
1864	-0.2	-12.73	7.452	-0.02	383.4
1867	-0.2	-12.75	7.464	-0.02	384.0
1870	0.2	-12.77	7.476	0.02	384.6
1873	0.4	-12.80	7.488	0.04	385.6
1876	0.0	-12.82	7.500	0.00	386.2
1879	0.2	-12.84	7.512	0.02	386.8
1882	-0.2	-12.86	7.524	-0.02	387.4
1885	0.2	-12.88	7.536	0.02	388.0
1888	0.0	-12.90	7.548	0.00	388.6
1891	0.2	-12.92	7.560	0.02	389.2
1894	0.0	-12.94	7.572	0.00	389.8
1897	0.2	-12.96	7.584	0.02	390.4
1900	-0.2	-12.98	7.596	-0.02	391.0
1903	0.0	-13.00	7.608	0.00	391.6
1906	0.0	-13.03	7.620	0.00	392.4
1909	-0.4	-13.05	7.632	-0.04	393.0
1912	0.4	-13.07	7.644	0.04	393.6
1915	-0.2	-13.09	7.656	-0.02	394.2
1918	0.0	-13.11	7.668	0.00	394.8
1921	0.0	-13.13	7.680	0.00	395.4
1924	0.2	-13.15	7.692	0.02	396.0
1927	0.0	-13.17	7.704	0.00	396.6
1930	0.4	-13.19	7.716	0.04	397.2
1933	-0.2	-13.21	7.728	-0.02	397.8
1936	0.0	-13.23	7.740	0.00	398.4
1939	0.0	-13.26	7.752	0.00	399.4
1942	0.0	-13.28	7.764	0.00	400.0
1945	0.2	-13.30	7.776	0.02	400.6
1948	-0.2	-13.32	7.788	-0.02	401.2
1951	0.0	-13.34	7.800	0.00	401.8
1954	0.0	-13.36	7.812	0.00	402.4
1957	0.0	-13.38	7.824	0.00	403.0
1960	-0.2	-13.40	7.836	-0.02	403.6
1963	0.0	-13.42	7.848	0.00	404.2
1966	0.0	-13.44	7.860	0.00	404.8
1969	0.0	-13.47	7.872	0.00	405.8
1972	0.0	-13.49	7.884	0.00	406.4
1975	0.0	-13.51	7.896	0.00	407.0
1978	0.0	-13.53	7.908	0.00	407.6
1981	0.0	-13.55	7.920	0.00	408.2
1984	0.0	-13.57	7.932	0.00	408.8
1987	0.0	-13.59	7.944	0.00	409.4
1990	0.0	-13.61	7.956	0.00	410.0
1993	0.0	-13.63	7.968	0.00	410.6
1996	-0.2	-13.66	7.980	-0.02	411.4
1999	0.0	-13.68	7.992	0.00	412.0
2002	-0.2	-13.70	8.004	-0.02	412.6
2005	0.0	-13.72	8.016	0.00	413.2
2008	0.0	-13.74	8.028	0.00	413.8
2011	0.0	-13.76	8.040	0.00	414.4
2014	0.0	-13.78	8.052	0.00	415.0
2017	0.0	-13.80	8.064	0.00	415.6
2020	-0.2	-13.82	8.076	-0.02	416.2
2023	0.0	-13.84	8.088	0.00	416.8
2026	0.0	-13.87	8.100	0.00	417.8
2029	0.0	-13.89	8.112	0.00	418.4
2032	0.0	-13.91	8.124	0.00	419.0
2035	0.0	-13.93	8.136	0.00	419.6
2038	0.2	-13.95	8.148	0.02	420.2
2041	-0.2	-13.97	8.160	-0.02	420.8
2044	0.0	-13.99	8.172	0.00	421.4
2047	0.0	-14.01	8.184	0.00	422.0
2050	0.0	-14.04	8.196	0.00	422.8
2053	0.0	-14.06	8.208	0.00	423.4
2056	0.0	-14.08	8.220	0.00	424.0
2059	0.2	-14.10	8.232	0.02	424.6
2062	-0.4	-14.12	8.244	-0.04	425.4
2065	0.2	-14.14	8.256	0.02	426.0
2068	0.0	-14.16	8.268	0.00	426.6
2071	0.2	-14.18	8.280	0.02	427.2
2074	-0.2	-14.20	8.292	-0.02	427.8
2077	0.0	-14.23	8.304	0.00	428.6
2080	0.0	-14.25	8.316	0.00	429.2
2083	0.0	-14.27	8.328	0.00	429.8
2086	0.0	-14.29	8.340	0.00	430.4
2089	0.0	-14.31	8.352	0.00	431.0
2092	0.0	-14.33	8.364	0.00	431.6
2095	0.2	-14.35	8.376	0.02	432.2
2098	0.0	-14.37	8.388	0.00	432.8
2101	0.0	-14.40	8.400	0.00	433.8
2104	0.0	-14.42	8.412	0.00	434.4
2107	0.0	-14.44	8.424	0.00	435.0
2110	0.0	-14.46	8.436	0.00	435.6
2113	0.0	-14.48	8.448	0.00	436.2
2116	0.2	-14.50	8.460	0.02	436.8
2119	-0.2	-14.52	8.472	-0.02	437.4
2122	0.2	-14.54	8.484	0.02	438.0
2125	0.0	-14.56	8.496	0.00	438.6
2128	0.0	-14.59	8.508	0.00	439.4
2131	0.0	-14.61	8.520	0.00	440.0
2134	0.2	-14.63	8.532	0.02	440.6
2137	0.0	-14.65	8.544	0.00	441.2
2140	0.0	-14.67	8.556	0.00	441.8
2143	0.0	-14.69	8.568	0.00	442.4
2146	0.0	-14.71	8.580	0.00	443.0
2149	0.2	-14.73	8.592	0.02	443.6
2152	0.0	-14.75	8.604	0.00	444.2
2155	0.0	-14.78	8.616	0.00	445.2
2158	-0.4	-14.80	8.628	-0.04	445.8
2161	0.0	-14.82	8.640	0.00	446.4
2164	-0.4	-14.84	8.652	-0.04	447.0
2167	0.0	-14.86	8.664	0.00	447.6
2170	-0.2	-14.88	8.676	-0.02	448.2
2173	0.0	-14.90	8.688	0.00	448.8
2176	0.0	-14.92	8.700	0.00	449.4
2179	0.0	-14.94	8.712	0.00	450.0
2182	-0.2	-14.97	8.724	-0.02	451.0
2185	0.0	-14.99	8.736	0.00	451.6
2188	-0.4	-15.01	8.748	-0.04	452.2
2191	0.0	-15.03	8.760	0.00	452.8
2194	0.2	-15.05	8.772	0.02	453.4
2197	0.0	-15.07	8.784	0.00	454.0
2200	-0.2	-15.09	8.796	-0.02	454.6
2203	0.6	-15.11	8.808	0.06	455.2
2206	0.2	-15.13	8.820	0.02	455.8
2209	0.0	-15.16	8.832	0.00	456.6
2212	0.0	-15.18	8.844	0.00	457.2
2215	0.2	-15.20	8.856	0.02	457.8
2218	-0.2	-15.22	8.868	-0.02	458.4
2221	0.0	-15.24	8.880	0.00	459.0
2224	0.0	-15.26	8.892	0.00	459.6
2227	-0.2	-15.28	8.904	-0.02	460.2
2230	-0.2	-15.30	8.916	-0.02	460.8
2233	0.0	-15.32	8.928	0.00	461.4
2236	0.0	-15.35	8.940	0.00	462.4
2239	0.0	-15.37	8.952	0.00	463.0
2242	0.2	-15.39	8.964	0.02	463.6
2245	0.0	-15.40	8.976	0.00	463.8
2248	0.0	-15.42	8.988	0.00	464.4
2251	0.0	-15.44	9.000	0.00	465.0
2254	0.0	-15.46	9.012	0.00	465.6
2257	0.6	-15.48	9.024	0.06	466.2
2260	0.0	-15.51	9.036	0.00	467.2
2263	0.2	-15.53	9.048	0.02	467.8
2266	0.0	-15.55	9.060	0.00	468.4
2269	0.2	-15.57	9.072	0.02	469.0
2272	0.0	-15.59	9.084	0.00	469.6
2275	0.0	-15.61	9.096	0.00	470.2
2278	0.0	-15.63	9.108	0.00	470.8
2281	-0.2	-15.65	9.120	-0.02	471.4
2284	0.0	-15.67	9.132	0.00	472.0
2287	0.4	-15.69	9.144	0.04	472.6
2290	0.0	-15.72	9.156	0.00	473.4
2293	-0.2	-15.74	9.168	-0.02	474.0
2296	0.0	-15.76	9.180	0.00	474.6
2299	-0.2	-15.78	9.192	-0.02	475.4
2302	0.0	-15.80	9.204	0.00	476.0
2305	0.0	-15.82	9.216	0.00	476.6
2308	0.0	-15.84	9.228	0.00	477.2
2311	0.0	-15.86	9.240	0.00	477.8
2314	0.0	-15.88	9.252	0.00	478.4
2317	0.0	-15.90	9.264	0.00	479.0
2320	-0.2	-15.93	9.276	-0.02	479.8
2323	-0.4	-15.95	9.288	-0.04	480.4
2326	-0.4	-15.97	9.300	-0.04	481.0
2329	0.0	-15.99	9.312	0.00	481.6
2332	-0.2	-16.01	9.324	-0.02	482.2
2335	0.0	-16.03	9.336	0.00	482.8
2338	0.0	-16.05	9.348	0.00	483.4
2341	-0.2	-16.07	9.360	-0.02	484.0
2344	0.2	-16.09	9.372	0.02	484.6
2347	0.0	-16.11	9.384	0.00	485.2
2350	0.4	-16.13	9.396	0.04	485.8
2353	-0.2	-16.16	9.408	-0.02	486.8
2356	0.0	-16.18	9.420	0.00	487.4
2359	0.0	-16.20	9.432	0.00	488.0
2362	0.0	-16.22	9.444	0.00	488.6
2365	0.2	-16.24	9.456	0.02	489.2
2368	0.2	-16.26	9.468	0.02	489.8
2371	0.0	-16.28	9.480	0.00	490.4
2374	0.0	-16.30	9.492	0.00	491.0
2377	0.0	-16.32	9.504	0.00	491.6
2380	0.0	-16.34	9.516	0.00	492.2
2383	0.0	-16.36	9.528	0.00	492.8
2386	0.0	-16.39	9.540	0.00	493.6
2389	0.0	-16.41	9.552	0.00	494.2
2392	0.0	-16.43	9.564	0.00	494.8
2395	-0.2	-16.45	9.576	-0.02	495.4
2398	-0.2	-16.47	9.588	-0.02	496.0
2401	0.0	-16.49	9.600	0.00	496.6
2404	0.2	-16.51	9.612	0.02	497.2
2407	0.2	-16.53	9.624	0.02	497.8
2410	0.0	-16.55	9.636	0.00	498.4
2413	-0.2	-16.57	9.648	-0.02	499.0
2416	0.2	-16.59	9.660	0.02	499.6
2419	0.0	-16.61	9.672	0.00	500.4
2422	-0.2	-16.64	9.684	-0.02	501.2
2425	-0.4	-16.66	9.696	-0.04	501.8
2428	-0.2	-16.68	9.708	-0.02	502.4
2431	-0.2	-16.70	9.720	-0.02	503.0
2434	0.0	-16.72	9.732	0.00	503.6
2437	0.0	-16.74	9.744	0.00	504.2
2440	0.2	-16.76	9.756	0.02	504.8
2443	0.0	-16.78	9.768	0.00	505.4
2446	0.4	-16.80	9.780	0.04	506.0
2449	-0.2	-16.82	9.792	-0.02	506.6
2452	0.0	-16.84	9.804	0.00	507.2
2455	0.2	-16.87	9.816	0.02	508.2
2458	0.0	-16.89	9.828	0.00	508.8
2461	0.2	-16.91	9.840	0.02	509.4
2464	0.2	-16.93	9.852	0.02	510.0
2467	0.0	-16.95	9.864	0.00	510.6
2470	0.0	-16.97	9.876	0.00	511.2
2473	0.4	-16.99	9.888	0.04	511.8
2476	0.0	-17.01	9.900	0.00	512.4
2479	0.2	-17.03	9.912	0.02	513.0
2482	-0.2	-17.05	9.924	-0.02	513.6
2485	0.0	-17.07	9.936	0.00	514.2
2488	0.0	-17.09	9.948	0.00	514.8
2491	0.0	-17.11	9.960	0.00	515.4
2494	0.0	-17.14	9.972	0.00	516.2
2497	-0.2	-17.16	9.984	-0.02	516.8
2500	0.0	-17.18	9.996	0.00	517.4
2503	0.0	-17.20	10.008	0.00	518.0
2506	-0.2	-17.22	10.020	-0.02	518.6
2509	0.2	-17.24	10.032	0.02	519.2
2512	0.0	-17.26	10.044	0.00	519.8
2515	0.0	-17.28	10.056	0.00	520.4
2518	0.0	-17.30	10.068	0.00	521.0
2521	-0.2	-17.32	10.080	-0.02	521.6
2524	0.0	-17.34	10.092	0.00	522.2
2527	0.0	-17.37	10.104	0.00	523.2
2530	-0.2	-17.39	10.116	-0.02	523.8
2533	-0.2	-17.42	10.128	-0.02	524.6
2536	-0.2	-17.44	10.140	-0.02	525.4
2539	0.0	-17.46	10.152	0.00	526.0
2542	0.0	-17.48	10.164	0.00	526.6
2545	0.2	-17.50	10.176	0.02	527.2
2548	-0.2	-17.52	10.188	-0.02	527.8
2551	0.0	-17.54	10.200	0.00	528.4
2554	0.2	-17.56	10.212	0.02	529.0
2557	0.0	-17.58	10.224	0.00	529.6
2560	0.0	-17.60	10.236	0.00	530.2
2563	0.0	-17.63	10.248	0.00	531.0
2566	0.0	-17.65	10.260	0.00	531.6
2569	0.2	-17.67	10.272	0.02	532.2
2572	0.0	-17.69	10.284	0.00	532.8
2575	0.4	-17.71	10.296	0.04	533.4
2578	0.0	-17.73	10.308	0.00	534.0
2581	0.2	-17.75	10.320	0.02	534.6
2584	0.0	-17.77	10.332	0.00	535.2
2587	0.0	-17.79	10.344	0.00	535.8
2590	-0.2	-17.81	10.356	-0.02	536.4
2593	-0.2	-17.83	10.368	-0.02	537.0
2596	0.0	-17.86	10.380	0.00	538.0
2599	0.0	-17.88	10.392	0.00	538.6
2602	-0.2	-17.90	10.404	-0.02	539.2
2605	0.2	-17.92	10.416	0.02	539.8
2608	0.0	-17.94	10.428	0.00	540.4
2611	-0.2	-17.96	10.440	-0.02	541.0
2614	0.0	-17.98	10.452	0.00	541.6
2617	0.0	-18.00	10.464	0.00	542.2
2620	0.0	-18.02	10.476	0.00	542.8
2623	0.0	-18.04	10.488	0.00	543.4
2626	0.0	-18.06	10.500	0.00	544.0
2629	0.0	-18.09	10.512	0.00	544.8
2632	0.0	-18.11	10.524	0.00	545.4
2635	0.0	-18.13	10.536	0.00	546.0
2638	0.0	-18.15	10.548	0.00	546.6
2641	0.2	-18.17	10.560	0.02	547.2
2644	-0.2	-18.19	10.572	-0.02	547.8
2647	0.0	-18.21	10.584	0.00	548.4
2650	0.0	-18.23	10.596	0.00	549.0
2653	0.0	-18.25	10.608	0.00	549.6
2656	0.2	-18.27	10.620	0.02	550.4
2659	0.0	-18.29	10.632	0.00	551.0
2662	0.2	-18.31	10.644	0.02	551.6
2665	0.0	-18.34	10.656	0.00	552.4
2668	-0.2	-18.36	10.668	-0.02	553.0
2671	0.0	-18.38	10.680	0.00	553.6
2674	0.0	-18.40	10.692	0.00	554.2
2677	0.0	-18.42	10.704	0.00	554.8
2680	-0.2	-18.44	10.716	-0.02	555.4
2683	0.0	-18.46	10.728	0.00	556.0
2686	0.0	-18.48	10.740	0.00	556.6
2689	-0.2	-18.50	10.752	-0.02	557.2
2692	0.0	-18.53	10.764	0.00	558.2
2695	0.0	-18.55	10.776	0.00	558.8
2698	0.4	-18.57	10.788	0.04	559.4
2701	0.0	-18.59	10.800	0.00	560.0
2704	0.0	-18.61	10.812	0.00	560.6
2707	0.0	-18.63	10.824	0.00	561.2
2710	0.0	-18.65	10.836	0.00	561.8
2713	-0.2	-18.67	10.848	-0.02	562.4
2716	0.0	-18.69	10.860	0.00	563.0
2719	-0.4	-18.72	10.872	-0.04	563.8
2722	0.0	-18.74	10.884	0.00	564.4
2725	0.2	-18.76	10.896	0.02	565.0
2728	0.0	-18.78	10.908	0.00	565.6
2731	0.0	-18.80	10.920	0.00	566.2
2734	0.0	-18.82	10.932	0.00	566.8
2737	0.0	-18.84	10.944	0.00	567.4
2740	0.0	-18.86	10.956	0.00	568.0
2743	-0.2	-18.88	10.968	-0.02	568.6
2746	0.0	-18.90	10.980	0.00	569.2
2749	0.2	-18.92	10.992	0.02	569.8
2752	0.0	-18.95	11.004	0.00	570.8
2755	0.0	-18.97	11.016	0.00	571.4
2758	-0.2	-18.99	11.028	-0.02	572.0
2761	0.0	-19.01	11.040	0.00	572.6
2764	0.4	-19.03	11.052	0.04	573.2
2767	0.0	-19.05	11.064	0.00	573.8
2770	0.0	-19.07	11.076	0.00	574.4
2773	0.2	-19.09	11.088	0.02	575.0
2776	0.0	-19.11	11.100	0.00	575.6
2779	0.0	-19.14	11.112	0.00	576.6
2782	0.0	-19.16	11.124	0.00	577.2
2785	0.0	-19.18	11.136	0.00	577.8
2788	0.2	-19.20	11.148	0.02	578.4
2791	0.0	-19.22	11.160	0.00	579.0
2794	0.2	-19.24	11.172	0.02	579.6
2797	0.0	-19.26	11.184	0.00	580.2
2800	0.0	-19.29	11.196	0.00	581.0
2803	0.0	-19.30	11.208	0.00	581.4
2806	0.0	-19.33	11.220	0.00	582.2
2809	0.0	-19.35	11.232	0.00	582.8
2812	0.0	-19.37	11.244	0.00	583.4
2815	0.0	-19.39	11.256	0.00	584.0
2818	0.4	-19.40	11.268	0.04	584.4
2821	1.0	-19.42	11.280	0.12	585.0
2824	2.4	-19.44	11.292	0.28	585.6
2827	4.4	-19.46	11.304	0.52	586.2
2830	6.6	-19.48	11.316	0.76	586.8
2833	9.4	-19.50	11.328	1.10	587.4
2836	13.0	-19.52	11.340	1.52	588.0
2839	16.6	-19.54	11.352	1.92	588.6
2842	21.2	-19.56	11.364	2.46	589.2
2845	25.6	-19.57	11.376	2.98	589.4
2848	31.0	-19.59	11.388	3.60	590.0
2851	35.6	-19.60	11.400	4.14	590.4
2854	41.2	-19.62	11.412	4.78	591.0
2857	51.0	-19.63	11.424	5.92	591.2
2860	64.8	-19.65	11.436	7.54	591.8
2863	74.4	-19.66	11.448	8.64	592.2
2866	80.0	-19.67	11.460	9.30	592.4
2869	84.0	-19.69	11.472	9.76	593.0
2872	81.8	-19.71	11.484	9.50	593.6
2875	79.2	-19.74	11.496	9.20	594.6
2878	79.0	-19.76	11.508	9.18	595.2
2881	80.2	-19.78	11.520	9.32	595.8
2884	80.4	-19.80	11.532	9.34	596.4
2887	81.6	-19.82	11.544	9.48	597.0
2890	83.2	-19.84	11.556	9.66	597.6
2893	84.0	-19.86	11.568	9.76	598.2
2896	86.0	-19.88	11.580	10.00	598.8
2899	86.4	-19.90	11.592	10.04	599.4
2902	83.8	-19.92	11.604	9.74	600.0
2905	80.4	-19.95	11.616	9.34	601.0
2908	77.0	-19.97	11.628	8.94	601.6
2911	76.8	-19.99	11.640	8.92	602.2
2914	80.0	-20.01	11.652	9.30	602.8
2917	80.6	-20.03	11.664	9.36	603.4
2920	80.4	-20.05	11.676	9.34	604.0
2923	79.6	-20.07	11.688	9.26	604.6
2926	63.2	-20.11	11.700	7.34	605.8
2929	62.4	-20.13	11.712	7.26	606.4
2932	61.2	-20.15	11.724	7.12	607.0
2935	61.4	-20.17	11.736	7.14	607.6
2938	60.8	-20.19	11.748	7.06	608.2
2941	60.6	-20.22	11.760	7.04	609.0
2944	61.0	-20.24	11.772	7.08	609.6
2947	61.0	-20.26	11.784	7.08	610.2
2950	61.8	-20.28	11.796	7.18	610.8
2953	61.0	-20.30	11.808	7.08	611.4
2956	60.6	-20.32	11.820	7.04	612.0
2959	58.8	-20.34	11.832	6.84	612.6
2962	58.2	-20.37	11.844	6.76	613.6
2965	58.4	-20.39	11.856	6.78	614.2
2968	59.0	-20.41	11.868	6.86	614.8
2971	59.2	-20.43	11.880	6.88	615.4
2974	58.4	-20.45	11.892	6.78	616.0
2977	57.6	-20.47	11.904	6.70	616.6
2980	56.4	-20.50	11.916	6.56	617.4
2983	55.6	-20.52	11.928	6.46	618.0
2986	55.0	-20.54	11.940	6.40	618.6
2989	55.0	-20.56	11.952	6.40	619.2
2992	55.8	-20.58	11.964	6.48	619.8
2995	56.6	-20.60	11.976	6.58	620.4
2998	56.4	-20.62	11.988	6.56	621.0
3001	54.8	-20.64	12.000	6.36	621.6
3004	53.8	-20.67	12.012	6.26	622.6
3007	52.6	-20.69	12.024	6.12	623.2
3010	51.6	-20.71	12.036	6.00	623.8
3013	51.0	-20.73	12.048	5.92	624.4
3016	51.8	-20.75	12.060	6.02	625.0
3019	50.4	-20.77	12.072	5.86	625.6
3022	49.8	-20.80	12.084	5.78	626.6
3025	48.6	-20.82	12.096	5.64	627.2
3028	48.6	-20.84	12.108	5.64	627.8
3031	47.2	-20.86	12.120	5.48	628.4
3034	45.6	-20.88	12.132	5.30	629.0
3037	46.4	-20.90	12.144	5.40	629.6
3040	46.8	-20.92	12.156	5.44	630.2
3043	48.0	-20.94	12.168	5.58	630.8
3046	44.6	-20.95	12.180	5.18	631.0
3049	41.8	-20.96	12.192	4.86	631.4
3052	40.6	-20.96	12.204	4.72	631.4
3055	39.6	-20.96	12.216	4.60	631.4
3058	39.0	-20.96	12.228	4.54	631.4
3061	38.6	-20.96	12.240	4.48	631.4
3062	38.2	-20.96	12.244	4.44	631.4