File: results/youngs-modulus/2025-04-20/inconclusive-data/pf17cp03.csv
Axial Compression Test-Jun-21-2024-03-08-46-PM.log,,,,,
,,,,,
System Information:,,,,,
IntelliMESUR Version: 2.2.1,,,,,
Test Frame Model: F505,,,,,
Test Frame Serial Number: 4418651,,,,,
Test Frame Capacity: 500 lbF / 2.2 kN,,,,,
Test Frame Firmware Version: 1.00.14,,,,,
Force Sensor Model: FS05-100,,,,,
Force Sensor Capacity: 500 N,,,,,
Force Sensor Resolution: 0.2 N,,,,,
Force Sensor Serial Number: 4425350,,,,,
"Calibration Date: Apr 29, 2024",,,,,
"Calibration Due Date: Apr 29, 2025",,,,,
,,,,,
Reading,Load [N],Distance [mm],Time [s],Stress [MPa],Strain [%]
1,0,-0.01,0,0,0.5
4,0,-0.01,0.012,0,0.5
7,0.2,-0.01,0.024,0.1,0.5
10,0,-0.01,0.036,0,0.5
13,0,-0.01,0.048,0,0.5
16,0,-0.01,0.06,0,0.5
19,0,-0.01,0.072,0,0.5
22,0,-0.01,0.084,0,0.5
25,0,-0.01,0.096,0,0.5
28,0,-0.01,0.108,0,0.5
31,0.2,-0.01,0.12,0.1,0.5
34,0,-0.01,0.132,0,0.5
37,0,-0.01,0.144,0,0.5
40,0,-0.01,0.156,0,0.5
43,0,-0.01,0.168,0,0.5
46,0.2,-0.01,0.18,0.1,0.5
49,0,-0.02,0.192,0,1
52,0,-0.04,0.204,0,2
55,-0.2,-0.06,0.216,-0.1,3
58,-0.2,-0.08,0.228,-0.1,4.5
61,0,-0.1,0.24,0,5.5
64,0,-0.12,0.252,0,6.5
67,-0.2,-0.14,0.264,-0.1,7.5
70,0,-0.16,0.276,0,8.5
73,-0.2,-0.19,0.288,-0.1,10.5
76,0.2,-0.21,0.3,0.1,11.5
79,0,-0.22,0.312,0,12
82,0,-0.24,0.324,0,13
85,0,-0.26,0.336,0,14
88,0,-0.28,0.348,0,15
91,0,-0.3,0.36,0,16
94,0,-0.32,0.372,0,17.5
97,0,-0.35,0.384,0,19
100,0.2,-0.37,0.396,0.1,20
103,-0.2,-0.39,0.408,-0.1,21
106,0,-0.41,0.42,0,22
109,0,-0.43,0.432,0,23
112,0.2,-0.45,0.444,0.1,24.5
115,-0.2,-0.47,0.456,-0.1,25.5
118,0,-0.49,0.468,0,26.5
121,0,-0.51,0.48,0,27.5
124,0,-0.53,0.492,0,28.5
127,0,-0.55,0.504,0,29.5
130,0,-0.58,0.516,0,31.5
133,0,-0.6,0.528,0,32.5
136,0.2,-0.62,0.54,0.1,33.5
139,0,-0.64,0.552,0,34.5
142,0,-0.66,0.564,0,35.5
145,0,-0.68,0.576,0,37
148,0,-0.7,0.588,0,38
151,-0.2,-0.72,0.6,-0.1,39
154,0,-0.74,0.612,0,40
157,-0.2,-0.76,0.624,-0.1,41
160,0,-0.79,0.636,0,42.5
163,0.2,-0.81,0.648,0.1,44
166,0,-0.83,0.66,0,45
169,-0.2,-0.85,0.672,-0.1,46
172,0,-0.87,0.684,0,47
175,0,-0.89,0.696,0,48
178,0,-0.91,0.708,0,49
181,0,-0.93,0.72,0,50.5
184,-0.4,-0.95,0.732,-0.2,51.5
187,0,-0.97,0.744,0,52.5
190,0,-0.99,0.756,0,53.5
193,0,-1.02,0.768,0,55
196,0,-1.04,0.78,0,56
199,0.2,-1.06,0.792,0.1,57.5
202,0.2,-1.08,0.804,0.1,58.5
205,0.2,-1.1,0.816,0.1,59.5
208,0,-1.12,0.828,0,60.5
211,0,-1.14,0.84,0,61.5
214,0,-1.16,0.852,0,62.5
217,-0.4,-1.18,0.864,-0.2,64
220,0,-1.2,0.876,0,65
223,0,-1.23,0.888,0,66.5
226,0,-1.26,0.9,0,68
229,0.2,-1.28,0.912,0.1,69
232,0,-1.3,0.924,0,70.5
235,0,-1.32,0.936,0,71.5
238,0,-1.34,0.948,0,72.5
241,0,-1.36,0.96,0,73.5
244,0,-1.38,0.972,0,74.5
247,0,-1.4,0.984,0,75.5
250,-0.2,-1.42,0.996,-0.1,77
253,0,-1.45,1.008,0,78.5
256,0,-1.46,1.02,0,79
259,0.2,-1.49,1.032,0.1,80.5
262,0.2,-1.51,1.044,0.1,81.5
265,-0.2,-1.53,1.056,-0.1,82.5
268,0,-1.55,1.068,0,84
271,0,-1.57,1.08,0,85
274,0,-1.59,1.092,0,86
277,0,-1.61,1.104,0,87
280,0,-1.63,1.116,0,88
283,-0.2,-1.65,1.128,-0.1,89
286,0,-1.67,1.14,0,90.5
289,-0.2,-1.69,1.152,-0.1,91.5
292,0,-1.72,1.164,0,93
295,0,-1.74,1.176,0,94
298,0,-1.76,1.188,0,95
301,0.2,-1.78,1.2,0.1,96
304,0,-1.8,1.212,0,97.5
307,-0.2,-1.82,1.224,-0.1,98.5
310,0.2,-1.84,1.236,0.1,99.5
313,0,-1.86,1.248,0,100.5
316,0,-1.88,1.26,0,101.5
319,0,-1.9,1.272,0,102.5
322,0,-1.93,1.284,0,104.5
325,0,-1.94,1.296,0,105
328,0,-1.97,1.308,0,106.5
331,-0.2,-1.99,1.32,-0.1,107.5
334,0,-2.01,1.332,0,108.5
337,0,-2.03,1.344,0,109.5
340,0,-2.05,1.356,0,111
343,-0.4,-2.07,1.368,-0.2,112
346,0,-2.09,1.38,0,113
349,0,-2.11,1.392,0,114
352,0,-2.13,1.404,0,115
355,0,-2.15,1.416,0,116
358,0.2,-2.17,1.428,0.1,117.5
361,0.4,-2.2,1.44,0.2,119
364,0,-2.22,1.452,0,120
367,0,-2.23,1.464,0,120.5
370,0,-2.25,1.476,0,121.5
373,-0.2,-2.27,1.488,-0.1,122.5
376,0.2,-2.29,1.5,0.1,124
379,0,-2.31,1.512,0,125
382,0.2,-2.33,1.524,0.1,126
385,-0.2,-2.35,1.536,-0.1,127
388,-0.2,-2.37,1.548,-0.1,128
391,0,-2.39,1.56,0,129
394,0,-2.42,1.572,0,131
397,-0.2,-2.44,1.584,-0.1,132
400,0,-2.46,1.596,0,133
403,0,-2.48,1.608,0,134
406,0,-2.5,1.62,0,135
409,0,-2.52,1.632,0,136
412,-0.2,-2.54,1.644,-0.1,137.5
415,0,-2.56,1.656,0,138.5
418,-0.2,-2.58,1.668,-0.1,139.5
421,0,-2.6,1.68,0,140.5
424,0,-2.62,1.692,0,141.5
427,0,-2.64,1.704,0,142.5
430,0,-2.67,1.716,0,144.5
433,0,-2.69,1.728,0,145.5
436,-0.2,-2.71,1.74,-0.1,146.5
439,0,-2.73,1.752,0,147.5
442,0.2,-2.75,1.764,0.1,148.5
445,0,-2.77,1.776,0,149.5
448,0.4,-2.79,1.788,0.2,151
451,0,-2.81,1.8,0,152
454,-0.2,-2.83,1.812,-0.1,153
457,0,-2.85,1.824,0,154
460,0.2,-2.87,1.836,0.1,155
463,0,-2.9,1.848,0,157
466,0,-2.92,1.86,0,158
469,-0.2,-2.94,1.872,-0.1,159
472,-0.2,-2.96,1.884,-0.1,160
475,0.2,-2.98,1.896,0.1,161
478,-0.2,-3,1.908,-0.1,162
481,0.2,-3.02,1.92,0.1,163
484,0,-3.04,1.932,0,164.5
487,0,-3.06,1.944,0,165.5
490,-0.2,-3.09,1.956,-0.1,167
493,0.2,-3.11,1.968,0.1,168
496,0,-3.13,1.98,0,169
499,0,-3.15,1.992,0,170.5
502,0,-3.17,2.004,0,171.5
505,0,-3.19,2.016,0,172.5
508,0.2,-3.21,2.028,0.1,173.5
511,0,-3.24,2.04,0,175
514,0,-3.26,2.052,0,176
517,0,-3.28,2.064,0,177.5
520,0,-3.3,2.076,0,178.5
523,0,-3.33,2.088,0,180
526,0,-3.35,2.1,0,181
529,0,-3.37,2.112,0,182
532,-0.2,-3.39,2.124,-0.1,183
535,0,-3.41,2.136,0,184.5
538,0.2,-3.43,2.148,0.1,185.5
541,0,-3.45,2.16,0,186.5
544,0.2,-3.47,2.172,0.1,187.5
547,0,-3.49,2.184,0,188.5
550,0.2,-3.52,2.196,0.1,190.5
553,0,-3.54,2.208,0,191.5
556,-0.2,-3.56,2.22,-0.1,192.5
559,-0.2,-3.58,2.232,-0.1,193.5
562,0.2,-3.6,2.244,0.1,194.5
565,0.2,-3.62,2.256,0.1,195.5
568,-0.2,-3.64,2.268,-0.1,197
571,0,-3.66,2.28,0,198
574,0,-3.68,2.292,0,199
577,0,-3.71,2.304,0,200.5
580,0,-3.73,2.316,0,201.5
583,0,-3.75,2.328,0,202.5
586,-0.2,-3.77,2.34,-0.1,204
589,0,-3.79,2.352,0,205
592,0,-3.81,2.364,0,206
595,0,-3.83,2.376,0,207
598,-0.4,-3.85,2.388,-0.2,208
601,0,-3.87,2.4,0,209
604,0,-3.9,2.412,0,211
607,0,-3.92,2.424,0,212
610,0,-3.94,2.436,0,213
613,0,-3.96,2.448,0,214
616,0,-3.98,2.46,0,215
619,0,-4,2.472,0,216
622,0,-4.02,2.484,0,217.5
625,-0.2,-4.04,2.496,-0.1,218.5
628,0,-4.06,2.508,0,219.5
631,0,-4.09,2.52,0,221
634,0.2,-4.11,2.532,0.1,222
637,0.2,-4.13,2.544,0.1,223
640,0,-4.15,2.556,0,224.5
643,0,-4.17,2.568,0,225.5
646,-0.4,-4.19,2.58,-0.2,226.5
649,0,-4.21,2.592,0,227.5
652,-0.2,-4.23,2.604,-0.1,228.5
655,0.2,-4.25,2.616,0.1,229.5
658,0,-4.28,2.628,0,231.5
661,0,-4.3,2.64,0,232.5
664,-0.2,-4.32,2.652,-0.1,233.5
667,0,-4.34,2.664,0,234.5
670,0.2,-4.36,2.676,0.1,235.5
673,0,-4.38,2.688,0,237
676,0,-4.4,2.7,0,238
679,0.2,-4.42,2.712,0.1,239
682,0.2,-4.44,2.724,0.1,240
685,0,-4.47,2.736,0,241.5
688,-0.2,-4.49,2.748,-0.1,242.5
691,0,-4.51,2.76,0,244
694,-0.2,-4.53,2.772,-0.1,245
697,0.2,-4.55,2.784,0.1,246
700,0,-4.57,2.796,0,247
703,-0.2,-4.59,2.808,-0.1,248
706,0,-4.61,2.82,0,249
709,0,-4.64,2.832,0,251
712,0.2,-4.66,2.844,0.1,252
715,-0.2,-4.68,2.856,-0.1,253
718,0,-4.7,2.868,0,254
721,0,-4.72,2.88,0,255
724,0,-4.74,2.892,0,256
727,0.2,-4.76,2.904,0.1,257.5
730,0,-4.78,2.916,0,258.5
733,0,-4.81,2.928,0,260
736,0,-4.83,2.94,0,261
739,0,-4.85,2.952,0,262
742,0,-4.87,2.964,0,263
745,0,-4.89,2.976,0,264.5
748,0,-4.91,2.988,0,265.5
751,0.2,-4.93,3,0.1,266.5
754,0.2,-4.95,3.012,0.1,267.5
757,0.2,-4.97,3.024,0.1,268.5
760,0,-5,3.036,0,270.5
763,0,-5.02,3.048,0,271.5
766,0,-5.04,3.06,0,272.5
769,-0.2,-5.06,3.072,-0.1,273.5
772,0.2,-5.08,3.084,0.1,274.5
775,0.2,-5.1,3.096,0.1,275.5
778,0,-5.12,3.108,0,277
781,0.2,-5.14,3.12,0.1,278
784,-0.2,-5.16,3.132,-0.1,279
787,-0.4,-5.19,3.144,-0.2,280.5
790,0,-5.21,3.156,0,281.5
793,0,-5.23,3.168,0,282.5
796,-0.2,-5.25,3.18,-0.1,284
799,-0.2,-5.27,3.192,-0.1,285
802,0.2,-5.29,3.204,0.1,286
805,0,-5.31,3.216,0,287
808,-0.2,-5.33,3.228,-0.1,288
811,0,-5.35,3.24,0,289
814,0,-5.37,3.252,0,290.5
817,0,-5.39,3.264,0,291.5
820,0,-5.42,3.276,0,293
823,-0.2,-5.44,3.288,-0.1,294
826,0,-5.46,3.3,0,295
829,-0.6,-5.48,3.312,-0.3,296
832,-0.2,-5.5,3.324,-0.1,297.5
835,0,-5.52,3.336,0,298.5
838,-0.2,-5.54,3.348,-0.1,299.5
841,0,-5.56,3.36,0,300.5
844,0.2,-5.58,3.372,0.1,301.5
847,0,-5.61,3.384,0,303
850,0,-5.63,3.396,0,304.5
853,0,-5.65,3.408,0,305.5
856,0,-5.67,3.42,0,306.5
859,-0.2,-5.69,3.432,-0.1,307.5
862,-0.4,-5.71,3.444,-0.2,308.5
865,0,-5.73,3.456,0,309.5
868,-0.4,-5.75,3.468,-0.2,311
871,0,-5.77,3.48,0,312
874,0,-5.79,3.492,0,313
877,0,-5.82,3.504,0,314.5
880,0.2,-5.84,3.516,0.1,315.5
883,0,-5.86,3.528,0,317
886,0,-5.88,3.54,0,318
889,0,-5.9,3.552,0,319
892,0,-5.92,3.564,0,320
895,0,-5.94,3.576,0,321
898,0,-5.96,3.588,0,322
901,0,-5.98,3.6,0,323
904,0,-6,3.612,0,324.5
907,0,-6.02,3.624,0,325.5
910,-0.4,-6.05,3.636,-0.2,327
913,0,-6.07,3.648,0,328
916,0,-6.09,3.66,0,329
919,0,-6.11,3.672,0,330.5
922,0.2,-6.13,3.684,0.1,331.5
925,0,-6.15,3.696,0,332.5
928,0,-6.17,3.708,0,333.5
931,0,-6.19,3.72,0,334.5
934,0,-6.21,3.732,0,335.5
937,0.2,-6.22,3.744,0.1,336
940,0,-6.24,3.756,0,337.5
943,0,-6.27,3.768,0,339
946,0.2,-6.29,3.78,0.1,340
949,0,-6.31,3.792,0,341
952,0,-6.33,3.804,0,342
955,0,-6.35,3.816,0,343
958,-0.2,-6.37,3.828,-0.1,344.5
961,-0.2,-6.39,3.84,-0.1,345.5
964,0,-6.41,3.852,0,346.5
967,0,-6.43,3.864,0,347.5
970,0,-6.45,3.876,0,348.5
973,0,-6.47,3.888,0,349.5
976,0.4,-6.49,3.9,0.2,351
979,0,-6.51,3.912,0,352
982,-0.2,-6.54,3.924,-0.1,353.5
985,-0.2,-6.56,3.936,-0.1,354.5
988,0,-6.58,3.948,0,355.5
991,0,-6.6,3.96,0,357
994,0,-6.62,3.972,0,358
997,-0.2,-6.64,3.984,-0.1,359
1000,0.4,-6.66,3.996,0.2,360
1003,0,-6.68,4.008,0,361
1006,0,-6.7,4.02,0,362
1009,0,-6.72,4.032,0,363
1012,0,-6.74,4.044,0,364.5
1015,0,-6.76,4.056,0,365.5
1018,0.2,-6.79,4.068,0.1,367
1021,0.2,-6.81,4.08,0.1,368
1024,0.2,-6.83,4.092,0.1,369
1027,0.2,-6.85,4.104,0.1,370.5
1030,0,-6.87,4.116,0,371.5
1033,0,-6.89,4.128,0,372.5
1036,0.4,-6.91,4.14,0.2,373.5
1039,-0.2,-6.93,4.152,-0.1,374.5
1042,0,-6.95,4.164,0,375.5
1045,-0.2,-6.97,4.176,-0.1,377
1048,0,-6.99,4.188,0,378
1051,0,-7.02,4.2,0,379.5
1054,0,-7.04,4.212,0,380.5
1057,0,-7.06,4.224,0,381.5
1060,0.2,-7.08,4.236,0.1,382.5
1063,-0.2,-7.1,4.248,-0.1,384
1066,0,-7.12,4.26,0,385
1069,0,-7.14,4.272,0,386
1072,0,-7.16,4.284,0,387
1075,-0.2,-7.18,4.296,-0.1,388
1078,0,-7.2,4.308,0,389
1081,0,-7.23,4.32,0,391
1084,0,-7.25,4.332,0,392
1087,0,-7.28,4.344,0,393.5
1090,0.2,-7.3,4.356,0.1,394.5
1093,0,-7.32,4.368,0,395.5
1096,-0.2,-7.34,4.38,-0.1,397
1099,-0.2,-7.36,4.392,-0.1,398
1102,-0.2,-7.38,4.404,-0.1,399
1105,0.2,-7.4,4.416,0.1,400
1108,0,-7.42,4.428,0,401
1111,0,-7.44,4.44,0,402
1114,0,-7.46,4.452,0,403
1117,0,-7.48,4.464,0,404.5
1120,-0.2,-7.51,4.476,-0.1,406
1123,0,-7.53,4.488,0,407
1126,0,-7.55,4.5,0,408
1129,0.2,-7.57,4.512,0.1,409
1132,0,-7.59,4.524,0,410.5
1135,0,-7.61,4.536,0,411.5
1138,0,-7.63,4.548,0,412.5
1141,0,-7.65,4.56,0,413.5
1144,0,-7.67,4.572,0,414.5
1147,0,-7.69,4.584,0,415.5
1150,0,-7.71,4.596,0,417
1153,0,-7.73,4.608,0,418
1156,0.2,-7.75,4.62,0.1,419
1159,0,-7.78,4.632,0,420.5
1162,0,-7.8,4.644,0,421.5
1165,0,-7.82,4.656,0,422.5
1168,0,-7.84,4.668,0,424
1171,0.2,-7.86,4.68,0.1,425
1174,0,-7.88,4.692,0,426
1177,0,-7.9,4.704,0,427
1180,0,-7.92,4.716,0,428
1183,-0.2,-7.94,4.728,-0.1,429
1186,0.2,-7.96,4.74,0.1,430.5
1189,-0.2,-7.98,4.752,-0.1,431.5
1192,0.2,-8.01,4.764,0.1,433
1195,0,-8.03,4.776,0,434
1198,0.4,-8.05,4.788,0.2,435
1201,0,-8.07,4.8,0,436
1204,0,-8.09,4.812,0,437.5
1207,0,-8.11,4.824,0,438.5
1210,0,-8.13,4.836,0,439.5
1213,0,-8.15,4.848,0,440.5
1216,0,-8.17,4.86,0,441.5
1219,0.2,-8.19,4.872,0.1,442.5
1222,0,-8.22,4.884,0,444.5
1225,0.2,-8.24,4.896,0.1,445.5
1228,-0.6,-8.26,4.908,-0.3,446.5
1231,-0.2,-8.28,4.92,-0.1,447.5
1234,0,-8.3,4.932,0,448.5
1237,0,-8.32,4.944,0,449.5
1240,0,-8.34,4.956,0,451
1243,0.2,-8.36,4.968,0.1,452
1246,0,-8.38,4.98,0,453
1249,0,-8.41,4.992,0,454.5
1252,0,-8.43,5.004,0,455.5
1255,0,-8.45,5.016,0,457
1258,-0.2,-8.47,5.028,-0.1,458
1261,0,-8.49,5.04,0,459
1264,0,-8.51,5.052,0,460
1267,0.4,-8.53,5.064,0.2,461
1270,-0.2,-8.55,5.076,-0.1,462
1273,0,-8.57,5.088,0,463
1276,-0.2,-8.59,5.1,-0.1,464.5
1279,0,-8.62,5.112,0,466
1282,0,-8.64,5.124,0,467
1285,0,-8.66,5.136,0,468
1288,0,-8.68,5.148,0,469
1291,0,-8.7,5.16,0,470.5
1294,0,-8.72,5.172,0,471.5
1297,-0.2,-8.74,5.184,-0.1,472.5
1300,-0.6,-8.76,5.196,-0.3,473.5
1303,-0.2,-8.78,5.208,-0.1,474.5
1306,0,-8.81,5.22,0,476
1309,-0.2,-8.83,5.232,-0.1,477.5
1312,0.2,-8.85,5.244,0.1,478.5
1315,0,-8.87,5.256,0,479.5
1318,0,-8.89,5.268,0,480.5
1321,0,-8.91,5.28,0,481.5
1324,0,-8.93,5.292,0,482.5
1327,0.2,-8.95,5.304,0.1,484
1330,-0.4,-8.98,5.316,-0.2,485.5
1333,0,-9,5.328,0,486.5
1336,-0.2,-9.02,5.34,-0.1,487.5
1339,0,-9.04,5.352,0,488.5
1342,0,-9.06,5.364,0,489.5
1345,0.4,-9.08,5.376,0.2,491
1348,0.4,-9.1,5.388,0.2,492
1351,0.4,-9.12,5.4,0.2,493
1354,0,-9.14,5.412,0,494
1357,0.2,-9.17,5.424,0.1,495.5
1360,0,-9.19,5.436,0,497
1363,-0.2,-9.21,5.448,-0.1,498
1366,-0.2,-9.23,5.46,-0.1,499
1369,0.4,-9.25,5.472,0.2,500
1372,0,-9.27,5.484,0,501
1375,0,-9.29,5.496,0,502
1378,0.2,-9.31,5.508,0.1,503
1381,0,-9.33,5.52,0,504.5
1384,-0.2,-9.36,5.532,-0.1,506
1387,0.2,-9.38,5.544,0.1,507
1390,0,-9.4,5.556,0,508
1393,0,-9.42,5.568,0,509
1396,0,-9.44,5.58,0,510.5
1399,0,-9.46,5.592,0,511.5
1402,0,-9.48,5.604,0,512.5
1405,0.2,-9.5,5.616,0.1,513.5
1408,-0.2,-9.52,5.628,-0.1,514.5
1411,0.4,-9.55,5.64,0.2,516
1414,0,-9.57,5.652,0,517.5
1417,0,-9.59,5.664,0,518.5
1420,0,-9.61,5.676,0,519.5
1423,0,-9.63,5.688,0,520.5
1426,0.2,-9.65,5.7,0.1,521.5
1429,0.2,-9.67,5.712,0.1,522.5
1432,0.2,-9.69,5.724,0.1,524
1435,-0.2,-9.72,5.736,-0.1,525.5
1438,-0.2,-9.74,5.748,-0.1,526.5
1441,0,-9.76,5.76,0,527.5
1444,0,-9.78,5.772,0,528.5
1447,0,-9.8,5.784,0,529.5
1450,0,-9.82,5.796,0,531
1453,0,-9.84,5.808,0,532
1456,0,-9.86,5.82,0,533
1459,-0.2,-9.89,5.832,-0.1,534.5
1462,0.4,-9.91,5.844,0.2,535.5
1465,-0.4,-9.93,5.856,-0.2,537
1468,0,-9.95,5.868,0,538
1471,0,-9.97,5.88,0,539
1474,0,-9.99,5.892,0,540
1477,0,-10.01,5.904,0,541
1480,0,-10.03,5.916,0,542
1483,0,-10.05,5.928,0,543
1486,0,-10.07,5.94,0,544.5
1489,-0.2,-10.1,5.952,-0.1,546
1492,0,-10.12,5.964,0,547
1495,0,-10.14,5.976,0,548
1498,-0.2,-10.16,5.988,-0.1,549
1501,0.2,-10.18,6,0.1,550.5
1504,-0.2,-10.2,6.012,-0.1,551.5
1507,0.2,-10.21,6.024,0.1,552
1510,0.2,-10.23,6.036,0.1,553
1513,0,-10.25,6.048,0,554
1516,0,-10.28,6.06,0,555.5
1519,0,-10.3,6.072,0,557
1522,0,-10.32,6.084,0,558
1525,0,-10.34,6.096,0,559
1528,0,-10.36,6.108,0,560
1531,0,-10.38,6.12,0,561
1534,0,-10.4,6.132,0,562
1537,0,-10.42,6.144,0,563
1540,0,-10.44,6.156,0,564.5
1543,0,-10.47,6.168,0,566
1546,-0.2,-10.49,6.18,-0.1,567
1549,0,-10.51,6.192,0,568
1552,0,-10.53,6.204,0,569
1555,-0.2,-10.55,6.216,-0.1,570.5
1558,0,-10.57,6.228,0,571.5
1561,0,-10.59,6.24,0,572.5
1564,0.2,-10.61,6.252,0.1,573.5
1567,0,-10.63,6.264,0,574.5
1570,0.2,-10.65,6.276,0.1,575.5
1573,0.2,-10.68,6.288,0.1,577.5
1576,0,-10.7,6.3,0,578.5
1579,0,-10.72,6.312,0,579.5
1582,0,-10.74,6.324,0,580.5
1585,0,-10.76,6.336,0,581.5
1588,0,-10.78,6.348,0,582.5
1591,0,-10.8,6.36,0,584
1594,0,-10.82,6.372,0,585
1597,0,-10.84,6.384,0,586
1600,-0.4,-10.86,6.396,-0.2,587
1603,0,-10.88,6.408,0,588
1606,0,-10.91,6.42,0,589.5
1609,0.2,-10.93,6.432,0.1,591
1612,0.2,-10.95,6.444,0.1,592
1615,0,-10.97,6.456,0,593
1618,0,-10.99,6.468,0,594
1621,-0.2,-11.01,6.48,-0.1,595
1624,0,-11.03,6.492,0,596
1627,0.2,-11.05,6.504,0.1,597.5
1630,-0.2,-11.07,6.516,-0.1,598.5
1633,0.6,-11.1,6.528,0.3,600
1636,0,-11.11,6.54,0,600.5
1639,-0.2,-11.14,6.552,-0.1,602
1642,-0.2,-11.16,6.564,-0.1,603
1645,-0.2,-11.18,6.576,-0.1,604.5
1648,0,-11.2,6.588,0,605.5
1651,0,-11.22,6.6,0,606.5
1654,0,-11.24,6.612,0,607.5
1657,0,-11.26,6.624,0,608.5
1660,-0.2,-11.28,6.636,-0.1,609.5
1663,0,-11.3,6.648,0,611
1666,0.2,-11.32,6.66,0.1,612
1669,-0.2,-11.35,6.672,-0.1,613.5
1672,0,-11.37,6.684,0,614.5
1675,-0.2,-11.39,6.696,-0.1,615.5
1678,0.2,-11.41,6.708,0.1,617
1681,0,-11.43,6.72,0,618
1684,0,-11.45,6.732,0,619
1687,0,-11.47,6.744,0,620
1690,0,-11.49,6.756,0,621
1693,-0.2,-11.51,6.768,-0.1,622
1696,0,-11.53,6.78,0,623
1699,-0.4,-11.55,6.792,-0.2,624.5
1702,-0.2,-11.58,6.804,-0.1,626
1705,0,-11.6,6.816,0,627
1708,-0.2,-11.62,6.828,-0.1,628
1711,0,-11.64,6.84,0,629
1714,0.2,-11.66,6.852,0.1,630.5
1717,0,-11.68,6.864,0,631.5
1720,0.4,-11.7,6.876,0.2,632.5
1723,0,-11.72,6.888,0,633.5
1726,-0.2,-11.74,6.9,-0.1,634.5
1729,-0.2,-11.76,6.912,-0.1,635.5
1732,0,-11.78,6.924,0,637
1735,0,-11.81,6.936,0,638.5
1738,0,-11.83,6.948,0,639.5
1741,0,-11.85,6.96,0,640.5
1744,-0.4,-11.87,6.972,-0.2,641.5
1747,0.2,-11.89,6.984,0.1,642.5
1750,0,-11.91,6.996,0,644
1753,0,-11.93,7.008,0,645
1756,-0.2,-11.95,7.02,-0.1,646
1759,0.2,-11.97,7.032,0.1,647
1762,0.2,-11.99,7.044,0.1,648
1765,0,-12.01,7.056,0,649
1768,0.2,-12.03,7.068,0.1,650.5
1771,-0.2,-12.05,7.08,-0.1,651.5
1774,-0.2,-12.08,7.092,-0.1,653
1777,0,-12.1,7.104,0,654
1780,0.2,-12.12,7.116,0.1,655
1783,-0.4,-12.14,7.128,-0.2,656
1786,0,-12.16,7.14,0,657.5
1789,-0.2,-12.18,7.152,-0.1,658.5
1792,0,-12.2,7.164,0,659.5
1795,0.2,-12.23,7.176,0.1,661
1798,-0.2,-12.25,7.188,-0.1,662
1801,0,-12.27,7.2,0,663
1804,0.2,-12.29,7.212,0.1,664.5
1807,0,-12.32,7.224,0,666
1810,0.2,-12.34,7.236,0.1,667
1813,0,-12.36,7.248,0,668
1816,0,-12.38,7.26,0,669
1819,0,-12.4,7.272,0,670.5
1822,0,-12.42,7.284,0,671.5
1825,0,-12.44,7.296,0,672.5
1828,0,-12.46,7.308,0,673.5
1831,0,-12.48,7.32,0,674.5
1834,0,-12.5,7.332,0,675.5
1837,-0.2,-12.53,7.344,-0.1,677.5
1840,0.2,-12.55,7.356,0.1,678.5
1843,0,-12.57,7.368,0,679.5
1846,0,-12.59,7.38,0,680.5
1849,0,-12.61,7.392,0,681.5
1852,0,-12.63,7.404,0,682.5
1855,0.4,-12.65,7.416,0.2,684
1858,0,-12.67,7.428,0,685
1861,0,-12.69,7.44,0,686
1864,0.2,-12.71,7.452,0.1,687
1867,0.2,-12.73,7.464,0.1,688
1870,0,-12.76,7.476,0,689.5
1873,0,-12.78,7.488,0,691
1876,-0.2,-12.8,7.5,-0.1,692
1879,0,-12.82,7.512,0,693
1882,0,-12.84,7.524,0,694
1885,0.2,-12.86,7.536,0.1,695
1888,0,-12.88,7.548,0,696
1891,0,-12.9,7.56,0,697.5
1894,0,-12.92,7.572,0,698.5
1897,-0.2,-12.94,7.584,-0.1,699.5
1900,0,-12.96,7.596,0,700.5
1903,0,-12.98,7.608,0,701.5
1906,0.2,-13,7.62,0.1,702.5
1909,0.4,-13.03,7.632,0.2,704.5
1912,0,-13.05,7.644,0,705.5
1915,0.2,-13.07,7.656,0.1,706.5
1918,0,-13.09,7.668,0,707.5
1921,0,-13.11,7.68,0,708.5
1924,0,-13.13,7.692,0,709.5
1927,0.2,-13.15,7.704,0.1,711
1930,0,-13.17,7.716,0,712
1933,0,-13.19,7.728,0,713
1936,0.2,-13.22,7.74,0.1,714.5
1939,0,-13.24,7.752,0,715.5
1942,0,-13.26,7.764,0,717
1945,0,-13.28,7.776,0,718
1948,0,-13.3,7.788,0,719
1951,0,-13.32,7.8,0,720
1954,0.2,-13.34,7.812,0.1,721
1957,0,-13.36,7.824,0,722
1960,0,-13.38,7.836,0,723
1963,0.2,-13.41,7.848,0.1,725
1966,0,-13.43,7.86,0,726
1969,0,-13.45,7.872,0,727
1972,0,-13.47,7.884,0,728
1975,0,-13.49,7.896,0,729
1978,0,-13.51,7.908,0,730.5
1981,0,-13.53,7.92,0,731.5
1984,0,-13.55,7.932,0,732.5
1987,-0.2,-13.57,7.944,-0.1,733.5
1990,0,-13.59,7.956,0,734.5
1993,0,-13.62,7.968,0,736
1996,0,-13.64,7.98,0,737.5
1999,0,-13.66,7.992,0,738.5
2002,0,-13.68,8.004,0,739.5
2005,0,-13.7,8.016,0,740.5
2008,0.2,-13.72,8.028,0.1,741.5
2011,0,-13.74,8.04,0,742.5
2014,-0.2,-13.76,8.052,-0.1,744
2017,0.2,-13.79,8.064,0.1,745.5
2020,-0.2,-13.81,8.076,-0.1,746.5
2023,0,-13.83,8.088,0,747.5
2026,0,-13.85,8.1,0,748.5
2029,0,-13.87,8.112,0,749.5
2032,-0.2,-13.89,8.124,-0.1,751
2035,-0.2,-13.91,8.136,-0.1,752
2038,0.2,-13.93,8.148,0.1,753
2041,0,-13.95,8.16,0,754
2044,0,-13.98,8.172,0,755.5
2047,0,-14,8.184,0,757
2050,0,-14.02,8.196,0,758
2053,0,-14.04,8.208,0,759
2056,0,-14.06,8.22,0,760
2059,0,-14.08,8.232,0,761
2062,0,-14.1,8.244,0,762
2065,0.2,-14.12,8.256,0.1,763
2068,-0.2,-14.14,8.268,-0.1,764.5
2071,0,-14.17,8.28,0,766
2074,0,-14.19,8.292,0,767
2077,0,-14.21,8.304,0,768
2080,-0.2,-14.23,8.316,-0.1,769
2083,0,-14.25,8.328,0,770.5
2086,0.2,-14.27,8.34,0.1,771.5
2089,0,-14.29,8.352,0,772.5
2092,0.2,-14.31,8.364,0.1,773.5
2095,0,-14.34,8.376,0,775
2098,-0.2,-14.36,8.388,-0.1,776
2101,0,-14.38,8.4,0,777.5
2104,-0.2,-14.4,8.412,-0.1,778.5
2107,0.2,-14.42,8.424,0.1,779.5
2110,0,-14.44,8.436,0,780.5
2113,0,-14.46,8.448,0,781.5
2116,0,-14.48,8.46,0,782.5
2119,0,-14.5,8.472,0,784
2122,0,-14.53,8.484,0,785.5
2125,0,-14.55,8.496,0,786.5
2128,0,-14.57,8.508,0,787.5
2131,0,-14.59,8.52,0,788.5
2134,0.4,-14.61,8.532,0.2,789.5
2137,0,-14.63,8.544,0,791
2140,-0.2,-14.65,8.556,-0.1,792
2143,0,-14.67,8.568,0,793
2146,0,-14.7,8.58,0,794.5
2149,-0.2,-14.72,8.592,-0.1,795.5
2152,0,-14.74,8.604,0,797
2155,-0.2,-14.76,8.616,-0.1,798
2158,0.2,-14.78,8.628,0.1,799
2161,0,-14.8,8.64,0,800
2164,-0.2,-14.82,8.652,-0.1,801
2167,0,-14.84,8.664,0,802
2170,0,-14.86,8.676,0,803
2173,0,-14.89,8.688,0,805
2176,-0.2,-14.91,8.7,-0.1,806
2179,0.2,-14.93,8.712,0.1,807
2182,0.4,-14.95,8.724,0.2,808
2185,-0.2,-14.97,8.736,-0.1,809
2188,0,-14.99,8.748,0,810.5
2191,0,-15.01,8.76,0,811.5
2194,0.2,-15.03,8.772,0.1,812.5
2197,0,-15.05,8.784,0,813.5
2200,0,-15.08,8.796,0,815
2203,0,-15.1,8.808,0,816
2206,0.2,-15.12,8.82,0.1,817.5
2209,0.2,-15.14,8.832,0.1,818.5
2212,0.2,-15.16,8.844,0.1,819.5
2215,0,-15.18,8.856,0,820.5
2218,0,-15.2,8.868,0,821.5
2221,0,-15.21,8.88,0,822
2224,0,-15.23,8.892,0,823
2227,0,-15.26,8.904,0,825
2230,0,-15.28,8.916,0,826
2233,0.2,-15.3,8.928,0.1,827
2236,0,-15.32,8.94,0,828
2239,-0.2,-15.34,8.952,-0.1,829
2242,0.4,-15.36,8.964,0.2,830.5
2245,-0.2,-15.38,8.976,-0.1,831.5
2248,0,-15.4,8.988,0,832.5
2251,-0.4,-15.42,9,-0.2,833.5
2254,0,-15.45,9.012,0,835
2257,-0.2,-15.47,9.024,-0.1,836
2260,0,-15.49,9.036,0,837.5
2263,0,-15.51,9.048,0,838.5
2266,0,-15.53,9.06,0,839.5
2269,-0.2,-15.55,9.072,-0.1,840.5
2272,-0.2,-15.57,9.084,-0.1,841.5
2275,0,-15.59,9.096,0,842.5
2278,0.2,-15.61,9.108,0.1,844
2281,0.2,-15.63,9.12,0.1,845
2284,0,-15.66,9.132,0,846.5
2287,0.2,-15.68,9.144,0.1,847.5
2290,-0.2,-15.7,9.156,-0.1,848.5
2293,0,-15.72,9.168,0,849.5
2296,0,-15.74,9.18,0,851
2299,0,-15.76,9.192,0,852
2302,0,-15.78,9.204,0,853
2305,0.4,-15.8,9.216,0.2,854
2308,0,-15.82,9.228,0,855
2311,0,-15.84,9.24,0,856
2314,-0.2,-15.86,9.252,-0.1,857.5
2317,0,-15.89,9.264,0,859
2320,0,-15.91,9.276,0,860
2323,0,-15.93,9.288,0,861
2326,0,-15.95,9.3,0,862
2329,0,-15.97,9.312,0,863
2332,0,-15.99,9.324,0,864.5
2335,0,-16.01,9.336,0,865.5
2338,0,-16.03,9.348,0,866.5
2341,0,-16.05,9.36,0,867.5
2344,0,-16.07,9.372,0,868.5
2347,0,-16.09,9.384,0,869.5
2350,0,-16.12,9.396,0,871.5
2353,-0.2,-16.14,9.408,-0.1,872.5
2356,-0.2,-16.16,9.42,-0.1,873.5
2359,0,-16.18,9.432,0,874.5
2362,0,-16.2,9.444,0,875.5
2365,0.2,-16.22,9.456,0.1,877
2368,0,-16.24,9.468,0,878
2371,0,-16.26,9.48,0,879
2374,0,-16.28,9.492,0,880
2377,0,-16.3,9.504,0,881
2380,0,-16.32,9.516,0,882
2383,0,-16.35,9.528,0,884
2386,0,-16.37,9.54,0,885
2389,0.6,-16.39,9.552,0.3,886
2392,0,-16.41,9.564,0,887
2395,0,-16.43,9.576,0,888
2398,0.2,-16.45,9.588,0.1,889
2401,0,-16.47,9.6,0,890.5
2404,0,-16.49,9.612,0,891.5
2407,0.2,-16.51,9.624,0.1,892.5
2410,0,-16.53,9.636,0,893.5
2413,0,-16.55,9.648,0,894.5
2416,0.2,-16.57,9.66,0.1,895.5
2419,0,-16.6,9.672,0,897.5
2422,0.2,-16.62,9.684,0.1,898.5
2425,-0.2,-16.64,9.696,-0.1,899.5
2428,0.2,-16.66,9.708,0.1,900.5
2431,0,-16.68,9.72,0,901.5
2434,0,-16.7,9.732,0,902.5
2437,-0.2,-16.72,9.744,-0.1,904
2440,-0.2,-16.74,9.756,-0.1,905
2443,0,-16.76,9.768,0,906
2446,0.2,-16.78,9.78,0.1,907
2449,0,-16.8,9.792,0,908
2452,0,-16.82,9.804,0,909
2455,0,-16.84,9.816,0,910.5
2458,0,-16.87,9.828,0,912
2461,-0.2,-16.89,9.84,-0.1,913
2464,0,-16.91,9.852,0,914
2467,0,-16.93,9.864,0,915
2470,0,-16.95,9.876,0,916
2473,-0.2,-16.97,9.888,-0.1,917.5
2476,0.2,-16.99,9.9,0.1,918.5
2479,0,-17.01,9.912,0,919.5
2482,0,-17.03,9.924,0,920.5
2485,-0.2,-17.05,9.936,-0.1,921.5
2488,-0.2,-17.07,9.948,-0.1,922.5
2491,0,-17.1,9.96,0,924.5
2494,0.2,-17.12,9.972,0.1,925.5
2497,-0.2,-17.14,9.984,-0.1,926.5
2500,0,-17.16,9.996,0,927.5
2503,0,-17.18,10.008,0,928.5
2506,0,-17.2,10.02,0,929.5
2509,0,-17.23,10.032,0,931.5
2512,0.4,-17.25,10.044,0.2,932.5
2515,-0.2,-17.27,10.056,-0.1,933.5
2518,0,-17.29,10.068,0,934.5
2521,0,-17.31,10.08,0,935.5
2524,0,-17.33,10.092,0,937
2527,0,-17.36,10.104,0,938.5
2530,0,-17.38,10.116,0,939.5
2533,0,-17.4,10.128,0,940.5
2536,0,-17.42,10.14,0,941.5
2539,0,-17.44,10.152,0,942.5
2542,0,-17.46,10.164,0,944
2545,0,-17.48,10.176,0,945
2548,0,-17.5,10.188,0,946
2551,0.2,-17.52,10.2,0.1,947
2554,0,-17.54,10.212,0,948
2557,-0.2,-17.56,10.224,-0.1,949
2560,0,-17.59,10.236,0,951
2563,0.2,-17.61,10.248,0.1,952
2566,0,-17.63,10.26,0,953
2569,0,-17.65,10.272,0,954
2572,0.4,-17.67,10.284,0.2,955
2575,0,-17.69,10.296,0,956
2578,0,-17.71,10.308,0,957.5
2581,-0.2,-17.73,10.32,-0.1,958.5
2584,-0.2,-17.75,10.332,-0.1,959.5
2587,0,-17.77,10.344,0,960.5
2590,0,-17.79,10.356,0,961.5
2593,-0.2,-17.82,10.368,-0.1,963
2596,0,-17.84,10.38,0,964.5
2599,0.2,-17.86,10.392,0.1,965.5
2602,0,-17.88,10.404,0,966.5
2605,-0.2,-17.9,10.416,-0.1,967.5
2608,0,-17.92,10.428,0,968.5
2611,-0.2,-17.94,10.44,-0.1,969.5
2614,0.2,-17.96,10.452,0.1,971
2617,0.2,-17.98,10.464,0.1,972
2620,0.2,-18,10.476,0.1,973
2623,0,-18.02,10.488,0,974
2626,0,-18.04,10.5,0,975
2629,0,-18.07,10.512,0,977
2632,0,-18.09,10.524,0,978
2635,0,-18.11,10.536,0,979
2638,0,-18.13,10.548,0,980
2641,0,-18.15,10.56,0,981
2644,0,-18.17,10.572,0,982
2647,-0.2,-18.19,10.584,-0.1,983
2650,0.2,-18.21,10.596,0.1,984.5
2653,0,-18.23,10.608,0,985.5
2656,0,-18.25,10.62,0,986.5
2659,0,-18.27,10.632,0,987.5
2662,0,-18.3,10.644,0,989
2665,0,-18.32,10.656,0,990.5
2668,0.2,-18.34,10.668,0.1,991.5
2671,-0.2,-18.36,10.68,-0.1,992.5
2674,-0.2,-18.38,10.692,-0.1,993.5
2677,-0.4,-18.4,10.704,-0.2,994.5
2680,-0.2,-18.42,10.716,-0.1,995.5
2683,0,-18.44,10.728,0,997
2686,0,-18.46,10.74,0,998
2689,0,-18.49,10.752,0,999.5
2692,0.2,-18.51,10.764,0.1,1000.5
2695,-0.2,-18.53,10.776,-0.1,1001.5
2698,0.2,-18.55,10.788,0.1,1002.5
2701,0.2,-18.57,10.8,0.1,1004
2704,0,-18.59,10.812,0,1005
2707,-0.2,-18.61,10.824,-0.1,1006
2710,0,-18.63,10.836,0,1007
2713,0.2,-18.65,10.848,0.1,1008
2716,0,-18.68,10.86,0,1009.5
2719,0,-18.7,10.872,0,1011
2722,0,-18.72,10.884,0,1012
2725,-0.2,-18.74,10.896,-0.1,1013
2728,0,-18.76,10.908,0,1014
2731,0,-18.78,10.92,0,1015
2734,0.2,-18.8,10.932,0.1,1016
2737,0,-18.82,10.944,0,1017.5
2740,0,-18.84,10.956,0,1018.5
2743,-0.2,-18.87,10.968,-0.1,1020
2746,-0.2,-18.89,10.98,-0.1,1021
2749,-0.2,-18.91,10.992,-0.1,1022
2752,0,-18.93,11.004,0,1023
2755,0.2,-18.95,11.016,0.1,1024.5
2758,0,-18.97,11.028,0,1025.5
2761,0,-18.99,11.04,0,1026.5
2764,0,-19.01,11.052,0,1027.5
2767,0.2,-19.03,11.064,0.1,1028.5
2770,0.2,-19.06,11.076,0.1,1030.5
2773,0,-19.08,11.088,0,1031.5
2776,0.2,-19.1,11.1,0.1,1032.5
2779,0,-19.12,11.112,0,1033.5
2782,0,-19.14,11.124,0,1034.5
2785,0,-19.16,11.136,0,1035.5
2788,0.2,-19.18,11.148,0.1,1037
2791,-0.2,-19.2,11.16,-0.1,1038
2794,0,-19.21,11.172,0,1038.5
2797,0,-19.24,11.184,0,1040
2800,0,-19.26,11.196,0,1041
2803,-0.2,-19.28,11.208,-0.1,1042
2806,0.2,-19.3,11.22,0.1,1043
2809,0.2,-19.32,11.232,0.1,1044.5
2812,0.4,-19.34,11.244,0.2,1045.5
2815,0,-19.36,11.256,0,1046.5
2818,-0.2,-19.38,11.268,-0.1,1047.5
2821,0.6,-19.41,11.28,0.3,1049
2824,0,-19.43,11.292,0,1050.5
2827,0.2,-19.45,11.304,0.1,1051.5
2830,0,-19.47,11.316,0,1052.5
2833,0,-19.49,11.328,0,1053.5
2836,0.2,-19.51,11.34,0.1,1054.5
2839,0,-19.53,11.352,0,1055.5
2842,0.2,-19.55,11.364,0.1,1057
2845,0,-19.57,11.376,0,1058
2848,0,-19.6,11.388,0,1059.5
2851,0,-19.62,11.4,0,1060.5
2854,-0.2,-19.64,11.412,-0.1,1061.5
2857,0,-19.66,11.424,0,1062.5
2860,0,-19.68,11.436,0,1064
2863,-0.2,-19.7,11.448,-0.1,1065
2866,0,-19.72,11.46,0,1066
2869,0,-19.74,11.472,0,1067
2872,0,-19.76,11.484,0,1068
2875,0.2,-19.79,11.496,0.1,1069.5
2878,-0.2,-19.81,11.508,-0.1,1071
2881,-0.2,-19.83,11.52,-0.1,1072
2884,0,-19.85,11.532,0,1073
2887,0,-19.87,11.544,0,1074
2890,0,-19.89,11.556,0,1075
2893,-0.2,-19.91,11.568,-0.1,1076
2896,0,-19.93,11.58,0,1077.5
2899,0,-19.95,11.592,0,1078.5
2902,-0.2,-19.98,11.604,-0.1,1080
2905,0,-20,11.616,0,1081
2908,-0.6,-20.02,11.628,-0.3,1082
2911,0,-20.04,11.64,0,1083
2914,0,-20.06,11.652,0,1084.5
2917,0,-20.08,11.664,0,1085.5
2920,0.2,-20.1,11.676,0.1,1086.5
2923,0,-20.12,11.688,0,1087.5
2926,0,-20.15,11.7,0,1089
2929,0,-20.17,11.712,0,1090.5
2932,0,-20.19,11.724,0,1091.5
2935,0,-20.21,11.736,0,1092.5
2938,0,-20.23,11.748,0,1093.5
2941,0,-20.25,11.76,0,1094.5
2944,0.4,-20.27,11.772,0.2,1095.5
2947,-0.2,-20.29,11.784,-0.1,1097
2950,0,-20.31,11.796,0,1098
2953,0,-20.34,11.808,0,1099.5
2956,-0.2,-20.36,11.82,-0.1,1100.5
2959,-0.2,-20.38,11.832,-0.1,1101.5
2962,0,-20.4,11.844,0,1102.5
2965,0,-20.42,11.856,0,1104
2968,0,-20.44,11.868,0,1105
2971,0,-20.46,11.88,0,1106
2974,0,-20.48,11.892,0,1107
2977,0,-20.5,11.904,0,1108
2980,0,-20.52,11.916,0,1109
2983,0,-20.54,11.928,0,1110.5
2986,0.2,-20.57,11.94,0.1,1112
2989,-0.2,-20.59,11.952,-0.1,1113
2992,0,-20.61,11.964,0,1114
2995,0,-20.63,11.976,0,1115
2998,0,-20.65,11.988,0,1116
3001,0.2,-20.67,12,0.1,1117.5
3004,0.2,-20.69,12.012,0.1,1118.5
3007,-0.2,-20.71,12.024,-0.1,1119.5
3010,0,-20.73,12.036,0,1120.5
3013,0,-20.76,12.048,0,1122
3016,0.2,-20.78,12.06,0.1,1123
3019,0.6,-20.8,12.072,0.3,1124.5
3022,2.2,-20.82,12.084,1.1,1125.5
3025,4,-20.84,12.096,2,1126.5
3028,7.2,-20.86,12.108,3.7,1127.5
3031,10.8,-20.87,12.12,5.5,1128
3034,15.2,-20.89,12.132,7.8,1129
3037,21.4,-20.91,12.144,10.9,1130.5
3040,27.6,-20.92,12.156,14.1,1131
3043,33.2,-20.94,12.168,16.9,1132
3046,35.8,-20.96,12.18,18.3,1133
3049,36.4,-20.98,12.192,18.6,1134
3052,24,-21.01,12.204,12.2,1135.5
3055,24.4,-21.03,12.216,12.4,1137
3058,27.8,-21.05,12.228,14.2,1138
3061,34.4,-21.06,12.24,17.5,1138.5
3064,30.6,-21.09,12.252,15.6,1140
3067,31.2,-21.11,12.264,15.9,1141
3070,33.6,-21.13,12.276,17.1,1142
3073,35.4,-21.15,12.288,18.1,1143
3076,37,-21.16,12.3,18.9,1144
3079,36.6,-21.19,12.312,18.7,1145.5
3082,19.8,-21.22,12.324,10.1,1147
3085,18.4,-21.24,12.336,9.4,1148
3088,18.8,-21.27,12.348,9.6,1149.5
3091,19,-21.28,12.36,9.7,1150.5
3094,19.8,-21.31,12.372,10.1,1152
3097,21,-21.33,12.384,10.7,1153
3100,23,-21.35,12.396,11.7,1154
3103,24,-21.36,12.408,12.2,1154.5
3106,26.8,-21.38,12.42,13.7,1155.5
3109,30.4,-21.4,12.432,15.5,1157
3112,31.8,-21.42,12.444,16.2,1158
3115,28.6,-21.44,12.456,14.6,1159
3118,27.8,-21.46,12.468,14.2,1160
3121,28.8,-21.49,12.48,14.7,1161.5
3124,29.8,-21.51,12.492,15.2,1162.5
3127,30.6,-21.53,12.504,15.6,1164
3130,28,-21.55,12.516,14.3,1165
3133,27.4,-21.57,12.528,14,1166
3136,27.2,-21.59,12.54,13.9,1167
3139,24,-21.59,12.552,12.2,1167
3142,22.6,-21.59,12.564,11.5,1167
3145,21.8,-21.59,12.576,11.1,1167
3148,21.4,-21.59,12.588,10.9,1167
3151,20.8,-21.59,12.6,10.6,1167
3154,20.6,-21.59,12.612,10.5,1167
3157,20.4,-21.59,12.624,10.4,1167
3160,20,-21.59,12.636,10.2,1167
3163,20,-21.59,12.648,10.2,1167
3166,19.8,-21.59,12.66,10.1,1167
3169,19.8,-21.59,12.672,10.1,1167
3172,19.6,-21.59,12.684,10,1167
3174,19.2,-21.59,12.692,9.8,1167