File: results/youngs-modulus/2025-04-20/inconclusive-data/pf18lt03.csv
sep=
pf18lt03

System Information:
IntelliMESUR Version: 2.2.1
Test Frame Model: F505
Test Frame Serial Number: 4418651
Test Frame Capacity: 500 lbF / 2.2 kN
Test Frame Firmware Version: 1.00.14
Force Sensor Model: FS05-100
Force Sensor Capacity: 500 N
Force Sensor Resolution: 0.2 N
Force Sensor Serial Number: 4425350
Calibration Date: Apr 29, 2024
Calibration Due Date: Apr 29, 2025

Reading	Load [N]	Distance [mm]	Time [s]	Stress [MPa]	Strain [%]
1	0.0	0.01	0.000	0.00	-0.4
4	0.0	0.01	0.012	0.00	-0.4
7	0.0	0.01	0.024	0.00	-0.4
10	-0.2	0.01	0.036	-0.02	-0.4
13	0.0	0.01	0.048	0.00	-0.4
16	0.2	0.01	0.060	0.02	-0.4
19	0.0	0.01	0.072	0.00	-0.4
22	-0.2	0.01	0.084	-0.02	-0.4
25	0.0	0.01	0.096	0.00	-0.4
28	0.0	0.01	0.108	0.00	-0.4
31	0.2	0.01	0.120	0.02	-0.4
34	0.0	0.01	0.132	0.00	-0.4
37	0.0	0.01	0.144	0.00	-0.4
40	0.2	0.01	0.156	0.02	-0.4
43	0.0	0.01	0.168	0.00	-0.4
46	0.0	0.01	0.180	0.00	-0.4
49	0.0	0.00	0.192	0.00	0.0
52	0.0	-0.02	0.204	0.00	0.6
55	0.0	-0.05	0.216	0.00	1.6
58	0.0	-0.06	0.228	0.00	2.0
61	-0.4	-0.08	0.240	-0.06	2.8
64	0.0	-0.10	0.252	0.00	3.4
67	-0.2	-0.12	0.264	-0.02	4.0
70	-0.2	-0.14	0.276	-0.02	4.8
73	0.0	-0.16	0.288	0.00	5.4
76	0.0	-0.19	0.300	0.00	6.4
79	0.0	-0.21	0.312	0.00	7.0
82	0.2	-0.23	0.324	0.02	7.8
85	0.0	-0.25	0.336	0.00	8.4
88	0.2	-0.27	0.348	0.02	9.2
91	0.2	-0.29	0.360	0.02	9.8
94	0.2	-0.31	0.372	0.02	10.4
97	0.0	-0.33	0.384	0.00	11.2
100	0.2	-0.35	0.396	0.02	11.8
103	0.0	-0.37	0.408	0.00	12.4
106	0.0	-0.39	0.420	0.00	13.2
109	0.0	-0.42	0.432	0.00	14.2
112	0.0	-0.44	0.444	0.00	14.8
115	-0.2	-0.46	0.456	-0.02	15.6
118	-0.2	-0.48	0.468	-0.02	16.2
121	0.2	-0.50	0.480	0.02	16.8
124	-0.2	-0.52	0.492	-0.02	17.6
127	0.0	-0.54	0.504	0.00	18.2
130	0.2	-0.56	0.516	0.02	19.0
133	-0.2	-0.58	0.528	-0.02	19.6
136	0.0	-0.61	0.540	0.00	20.6
139	0.0	-0.63	0.552	0.00	21.2
142	0.2	-0.65	0.564	0.02	22.0
145	0.0	-0.67	0.576	0.00	22.6
148	0.2	-0.69	0.588	0.02	23.4
151	-0.2	-0.71	0.600	-0.02	24.0
154	0.0	-0.73	0.612	0.00	24.6
157	-0.2	-0.75	0.624	-0.02	25.4
160	0.0	-0.77	0.636	0.00	26.0
163	0.0	-0.79	0.648	0.00	26.6
166	0.0	-0.81	0.660	0.00	27.4
169	0.4	-0.84	0.672	0.06	28.4
172	0.0	-0.86	0.684	0.00	29.0
175	0.0	-0.88	0.696	0.00	29.8
178	0.0	-0.90	0.708	0.00	30.4
181	0.0	-0.92	0.720	0.00	31.0
184	0.0	-0.94	0.732	0.00	31.8
187	0.0	-0.96	0.744	0.00	32.4
190	0.2	-0.98	0.756	0.02	33.2
193	0.0	-1.00	0.768	0.00	33.8
196	0.0	-1.02	0.780	0.00	34.4
199	0.0	-1.05	0.792	0.00	35.4
202	0.2	-1.08	0.804	0.02	36.4
205	0.0	-1.10	0.816	0.00	37.2
208	0.0	-1.12	0.828	0.00	37.8
211	0.2	-1.14	0.840	0.02	38.6
214	0.0	-1.16	0.852	0.00	39.2
217	0.0	-1.18	0.864	0.00	39.8
220	0.4	-1.20	0.876	0.06	40.6
223	-0.2	-1.22	0.888	-0.02	41.2
226	-0.2	-1.24	0.900	-0.02	41.8
229	-0.2	-1.26	0.912	-0.02	42.6
232	-0.2	-1.29	0.924	-0.02	43.6
235	-0.2	-1.30	0.936	-0.02	44.0
238	0.0	-1.33	0.948	0.00	45.0
241	0.0	-1.35	0.960	0.00	45.6
244	0.0	-1.37	0.972	0.00	46.2
247	0.0	-1.39	0.984	0.00	47.0
250	0.2	-1.41	0.996	0.02	47.6
253	-0.2	-1.43	1.008	-0.02	48.4
256	0.0	-1.45	1.020	0.00	49.0
259	0.0	-1.47	1.032	0.00	49.6
262	0.2	-1.49	1.044	0.02	50.4
265	0.0	-1.51	1.056	0.00	51.0
268	0.0	-1.53	1.068	0.00	51.6
271	0.2	-1.56	1.080	0.02	52.8
274	0.0	-1.58	1.092	0.00	53.4
277	0.0	-1.60	1.104	0.00	54.0
280	-0.4	-1.62	1.116	-0.06	54.8
283	0.0	-1.64	1.128	0.00	55.4
286	0.2	-1.66	1.140	0.02	56.0
289	0.0	-1.68	1.152	0.00	56.8
292	-0.2	-1.70	1.164	-0.02	57.4
295	0.0	-1.72	1.176	0.00	58.2
298	0.0	-1.74	1.188	0.00	58.8
301	-0.4	-1.76	1.200	-0.06	59.4
304	0.2	-1.79	1.212	0.02	60.4
307	-0.2	-1.81	1.224	-0.02	61.2
310	0.0	-1.83	1.236	0.00	61.8
313	0.0	-1.85	1.248	0.00	62.6
316	0.2	-1.87	1.260	0.02	63.2
319	0.0	-1.89	1.272	0.00	63.8
322	0.2	-1.91	1.284	0.02	64.6
325	0.0	-1.93	1.296	0.00	65.2
328	-0.2	-1.95	1.308	-0.02	65.8
331	0.2	-1.97	1.320	0.02	66.6
334	0.0	-1.99	1.332	0.00	67.2
337	0.0	-2.01	1.344	0.00	68.0
340	0.0	-2.04	1.356	0.00	69.0
343	0.0	-2.05	1.368	0.00	69.2
346	0.0	-2.07	1.380	0.00	70.0
349	0.0	-2.09	1.392	0.00	70.6
352	0.0	-2.11	1.404	0.00	71.2
355	0.0	-2.13	1.416	0.00	72.0
358	0.0	-2.15	1.428	0.00	72.6
361	0.0	-2.17	1.440	0.00	73.4
364	0.0	-2.19	1.452	0.00	74.0
367	-0.4	-2.21	1.464	-0.06	74.6
370	0.0	-2.23	1.476	0.00	75.4
373	0.0	-2.26	1.488	0.00	76.4
376	0.0	-2.28	1.500	0.00	77.0
379	0.0	-2.30	1.512	0.00	77.8
382	-0.2	-2.32	1.524	-0.02	78.4
385	-0.4	-2.34	1.536	-0.06	79.0
388	0.2	-2.36	1.548	0.02	79.8
391	0.0	-2.38	1.560	0.00	80.4
394	0.4	-2.40	1.572	0.06	81.0
397	0.0	-2.42	1.584	0.00	81.8
400	-0.2	-2.44	1.596	-0.02	82.4
403	0.2	-2.46	1.608	0.02	83.2
406	-0.2	-2.49	1.620	-0.02	84.2
409	-0.2	-2.51	1.632	-0.02	84.8
412	0.0	-2.53	1.644	0.00	85.4
415	-0.2	-2.55	1.656	-0.02	86.2
418	0.0	-2.57	1.668	0.00	86.8
421	0.0	-2.59	1.680	0.00	87.6
424	0.0	-2.61	1.692	0.00	88.2
427	0.0	-2.63	1.704	0.00	88.8
430	0.0	-2.65	1.716	0.00	89.6
433	0.4	-2.67	1.728	0.06	90.2
436	0.0	-2.69	1.740	0.00	90.8
439	0.0	-2.72	1.752	0.00	91.8
442	0.2	-2.74	1.764	0.02	92.6
445	0.2	-2.76	1.776	0.02	93.2
448	0.2	-2.78	1.788	0.02	94.0
451	0.0	-2.80	1.800	0.00	94.6
454	0.2	-2.82	1.812	0.02	95.2
457	-0.2	-2.84	1.824	-0.02	96.0
460	0.0	-2.86	1.836	0.00	96.6
463	0.2	-2.88	1.848	0.02	97.2
466	-0.2	-2.90	1.860	-0.02	98.0
469	-0.2	-2.93	1.872	-0.02	99.0
472	0.2	-2.95	1.884	0.02	99.6
475	-0.2	-2.97	1.896	-0.02	100.4
478	0.0	-2.99	1.908	0.00	101.0
481	0.0	-3.01	1.920	0.00	101.6
484	-0.2	-3.03	1.932	-0.02	102.4
487	0.0	-3.06	1.944	0.00	103.4
490	0.0	-3.08	1.956	0.00	104.0
493	0.0	-3.10	1.968	0.00	104.8
496	0.0	-3.12	1.980	0.00	105.4
499	0.0	-3.14	1.992	0.00	106.0
502	0.0	-3.17	2.004	0.00	107.0
505	0.0	-3.19	2.016	0.00	107.8
508	0.0	-3.21	2.028	0.00	108.4
511	0.0	-3.23	2.040	0.00	109.2
514	0.0	-3.25	2.052	0.00	109.8
517	0.0	-3.27	2.064	0.00	110.4
520	0.0	-3.29	2.076	0.00	111.2
523	0.0	-3.31	2.088	0.00	111.8
526	0.0	-3.33	2.100	0.00	112.6
529	-0.2	-3.36	2.112	-0.02	113.6
532	0.0	-3.38	2.124	0.00	114.2
535	-0.2	-3.40	2.136	-0.02	114.8
538	0.0	-3.42	2.148	0.00	115.6
541	0.0	-3.44	2.160	0.00	116.2
544	0.0	-3.46	2.172	0.00	116.8
547	0.4	-3.48	2.184	0.06	117.6
550	0.0	-3.50	2.196	0.00	118.2
553	0.2	-3.52	2.208	0.02	119.0
556	-0.2	-3.55	2.220	-0.02	120.0
559	0.0	-3.57	2.232	0.00	120.6
562	0.0	-3.59	2.244	0.00	121.2
565	0.0	-3.61	2.256	0.00	122.0
568	0.0	-3.63	2.268	0.00	122.6
571	-0.2	-3.65	2.280	-0.02	123.4
574	-0.2	-3.67	2.292	-0.02	124.0
577	0.4	-3.69	2.304	0.06	124.6
580	-0.2	-3.71	2.316	-0.02	125.4
583	-0.4	-3.74	2.328	-0.06	126.4
586	0.0	-3.76	2.340	0.00	127.0
589	-0.2	-3.78	2.352	-0.02	127.8
592	0.2	-3.80	2.364	0.02	128.4
595	0.2	-3.82	2.376	0.02	129.0
598	0.2	-3.84	2.388	0.02	129.8
601	0.0	-3.86	2.400	0.00	130.4
604	0.0	-3.88	2.412	0.00	131.0
607	-0.2	-3.90	2.424	-0.02	131.8
610	0.2	-3.93	2.436	0.02	132.8
613	0.0	-3.95	2.448	0.00	133.4
616	0.0	-3.97	2.460	0.00	134.2
619	0.0	-3.99	2.472	0.00	134.8
622	0.0	-4.01	2.484	0.00	135.4
625	-0.2	-4.03	2.496	-0.02	136.2
628	-0.2	-4.05	2.508	-0.02	136.8
631	0.2	-4.08	2.520	0.02	137.8
634	0.0	-4.10	2.532	0.00	138.6
637	-0.2	-4.12	2.544	-0.02	139.2
640	0.0	-4.14	2.556	0.00	139.8
643	0.2	-4.16	2.568	0.02	140.6
646	-0.2	-4.18	2.580	-0.02	141.2
649	0.4	-4.20	2.592	0.06	141.8
652	0.0	-4.22	2.604	0.00	142.6
655	-0.2	-4.24	2.616	-0.02	143.2
658	0.2	-4.26	2.628	0.02	144.0
661	0.0	-4.28	2.640	0.00	144.6
664	0.2	-4.31	2.652	0.02	145.6
667	0.4	-4.33	2.664	0.06	146.2
670	0.0	-4.35	2.676	0.00	147.0
673	0.0	-4.37	2.688	0.00	147.6
676	0.0	-4.39	2.700	0.00	148.4
679	0.0	-4.41	2.712	0.00	149.0
682	0.0	-4.43	2.724	0.00	149.6
685	-0.4	-4.46	2.736	-0.06	150.6
688	0.0	-4.48	2.748	0.00	151.4
691	-0.2	-4.50	2.760	-0.02	152.0
694	0.0	-4.52	2.772	0.00	152.8
697	0.0	-4.54	2.784	0.00	153.4
700	0.2	-4.56	2.796	0.02	154.0
703	0.2	-4.58	2.808	0.02	154.8
706	0.0	-4.60	2.820	0.00	155.4
709	0.0	-4.62	2.832	0.00	156.0
712	-0.2	-4.65	2.844	-0.02	157.0
715	0.0	-4.67	2.856	0.00	157.8
718	-0.2	-4.69	2.868	-0.02	158.4
721	0.0	-4.71	2.880	0.00	159.2
724	-0.2	-4.73	2.892	-0.02	159.8
727	0.6	-4.75	2.904	0.08	160.4
730	0.0	-4.77	2.916	0.00	161.2
733	0.0	-4.79	2.928	0.00	161.8
736	0.0	-4.81	2.940	0.00	162.6
739	-0.2	-4.84	2.952	-0.02	163.6
742	0.0	-4.86	2.964	0.00	164.2
745	0.0	-4.88	2.976	0.00	164.8
748	-0.4	-4.90	2.988	-0.06	165.6
751	0.0	-4.92	3.000	0.00	166.2
754	0.0	-4.94	3.012	0.00	166.8
757	0.0	-4.96	3.024	0.00	167.6
760	-0.2	-4.98	3.036	-0.02	168.2
763	-0.2	-5.00	3.048	-0.02	169.0
766	0.0	-5.03	3.060	0.00	170.0
769	0.2	-5.05	3.072	0.02	170.6
772	0.0	-5.07	3.084	0.00	171.2
775	0.0	-5.09	3.096	0.00	172.0
778	0.0	-5.11	3.108	0.00	172.6
781	0.0	-5.13	3.120	0.00	173.4
784	0.0	-5.15	3.132	0.00	174.0
787	0.0	-5.17	3.144	0.00	174.6
790	-0.2	-5.19	3.156	-0.02	175.4
793	0.0	-5.22	3.168	0.00	176.4
796	0.0	-5.23	3.180	0.00	176.6
799	-0.4	-5.26	3.192	-0.06	177.8
802	-0.2	-5.28	3.204	-0.02	178.4
805	0.0	-5.30	3.216	0.00	179.0
808	0.0	-5.32	3.228	0.00	179.8
811	0.2	-5.34	3.240	0.02	180.4
814	0.0	-5.36	3.252	0.00	181.0
817	-0.4	-5.38	3.264	-0.06	181.8
820	0.0	-5.40	3.276	0.00	182.4
823	0.0	-5.42	3.288	0.00	183.2
826	0.0	-5.45	3.300	0.00	184.2
829	0.0	-5.47	3.312	0.00	184.8
832	-0.4	-5.49	3.324	-0.06	185.4
835	0.0	-5.51	3.336	0.00	186.2
838	0.0	-5.53	3.348	0.00	186.8
841	0.0	-5.55	3.360	0.00	187.6
844	0.0	-5.57	3.372	0.00	188.2
847	0.0	-5.59	3.384	0.00	188.8
850	0.0	-5.61	3.396	0.00	189.6
853	0.0	-5.64	3.408	0.00	190.6
856	0.0	-5.66	3.420	0.00	191.2
859	0.0	-5.68	3.432	0.00	191.8
862	0.0	-5.70	3.444	0.00	192.6
865	-0.2	-5.72	3.456	-0.02	193.2
868	-0.2	-5.74	3.468	-0.02	194.0
871	0.2	-5.76	3.480	0.02	194.6
874	0.0	-5.78	3.492	0.00	195.2
877	0.0	-5.80	3.504	0.00	196.0
880	-0.4	-5.82	3.516	-0.06	196.6
883	0.0	-5.84	3.528	0.00	197.2
886	0.2	-5.86	3.540	0.02	198.0
889	0.0	-5.89	3.552	0.00	199.0
892	0.2	-5.91	3.564	0.02	199.6
895	0.0	-5.93	3.576	0.00	200.4
898	0.0	-5.95	3.588	0.00	201.0
901	0.0	-5.97	3.600	0.00	201.6
904	0.2	-5.99	3.612	0.02	202.4
907	0.0	-6.01	3.624	0.00	203.0
910	0.0	-6.03	3.636	0.00	203.8
913	0.0	-6.04	3.648	0.00	204.0
916	0.0	-6.06	3.660	0.00	204.8
919	-0.4	-6.08	3.672	-0.06	205.4
922	0.0	-6.11	3.684	0.00	206.4
925	0.0	-6.13	3.696	0.00	207.0
928	-0.2	-6.15	3.708	-0.02	207.8
931	0.0	-6.17	3.720	0.00	208.4
934	0.2	-6.19	3.732	0.02	209.2
937	0.0	-6.21	3.744	0.00	209.8
940	0.0	-6.23	3.756	0.00	210.4
943	0.0	-6.25	3.768	0.00	211.2
946	0.0	-6.27	3.780	0.00	211.8
949	0.0	-6.29	3.792	0.00	212.4
952	0.0	-6.31	3.804	0.00	213.2
955	0.0	-6.33	3.816	0.00	213.8
958	-0.2	-6.35	3.828	-0.02	214.6
961	0.0	-6.38	3.840	0.00	215.6
964	0.0	-6.40	3.852	0.00	216.2
967	0.0	-6.42	3.864	0.00	216.8
970	-0.2	-6.44	3.876	-0.02	217.6
973	0.0	-6.46	3.888	0.00	218.2
976	0.0	-6.48	3.900	0.00	219.0
979	0.2	-6.50	3.912	0.02	219.6
982	0.0	-6.52	3.924	0.00	220.2
985	0.0	-6.54	3.936	0.00	221.0
988	0.0	-6.56	3.948	0.00	221.6
991	0.2	-6.58	3.960	0.02	222.2
994	0.0	-6.61	3.972	0.00	223.4
997	-0.2	-6.63	3.984	-0.02	224.0
1000	0.2	-6.65	3.996	0.02	224.6
1003	-0.2	-6.67	4.008	-0.02	225.4
1006	0.0	-6.69	4.020	0.00	226.0
1009	-0.2	-6.71	4.032	-0.02	226.6
1012	-0.2	-6.73	4.044	-0.02	227.4
1015	0.0	-6.75	4.056	0.00	228.0
1018	-0.4	-6.77	4.068	-0.06	228.8
1021	0.2	-6.79	4.080	0.02	229.4
1024	0.0	-6.81	4.092	0.00	230.0
1027	-0.2	-6.83	4.104	-0.02	230.8
1030	0.2	-6.86	4.116	0.02	231.8
1033	0.0	-6.88	4.128	0.00	232.4
1036	0.0	-6.90	4.140	0.00	233.2
1039	0.0	-6.92	4.152	0.00	233.8
1042	0.0	-6.94	4.164	0.00	234.4
1045	0.0	-6.96	4.176	0.00	235.2
1048	0.0	-6.98	4.188	0.00	235.8
1051	0.0	-7.00	4.200	0.00	236.4
1054	0.0	-7.02	4.212	0.00	237.2
1057	-0.2	-7.05	4.224	-0.02	238.2
1060	0.0	-7.07	4.236	0.00	238.8
1063	-0.2	-7.10	4.248	-0.02	239.8
1066	-0.2	-7.11	4.260	-0.02	240.2
1069	0.0	-7.14	4.272	0.00	241.2
1072	0.0	-7.16	4.284	0.00	241.8
1075	0.0	-7.18	4.296	0.00	242.6
1078	-0.2	-7.20	4.308	-0.02	243.2
1081	-0.2	-7.22	4.320	-0.02	244.0
1084	0.0	-7.24	4.332	0.00	244.6
1087	0.2	-7.26	4.344	0.02	245.2
1090	0.0	-7.28	4.356	0.00	246.0
1093	0.0	-7.30	4.368	0.00	246.6
1096	-0.2	-7.32	4.380	-0.02	247.2
1099	0.2	-7.35	4.392	0.02	248.4
1102	0.0	-7.37	4.404	0.00	249.0
1105	0.2	-7.39	4.416	0.02	249.6
1108	0.2	-7.41	4.428	0.02	250.4
1111	0.0	-7.43	4.440	0.00	251.0
1114	0.0	-7.45	4.452	0.00	251.6
1117	0.0	-7.47	4.464	0.00	252.4
1120	0.0	-7.49	4.476	0.00	253.0
1123	0.0	-7.51	4.488	0.00	253.8
1126	0.0	-7.53	4.500	0.00	254.4
1129	0.0	-7.55	4.512	0.00	255.0
1132	0.0	-7.57	4.524	0.00	255.8
1135	-0.2	-7.59	4.536	-0.02	256.4
1138	0.0	-7.62	4.548	0.00	257.4
1141	0.0	-7.64	4.560	0.00	258.2
1144	0.0	-7.66	4.572	0.00	258.8
1147	0.0	-7.68	4.584	0.00	259.4
1150	0.2	-7.70	4.596	0.02	260.2
1153	-0.2	-7.72	4.608	-0.02	260.8
1156	0.0	-7.74	4.620	0.00	261.4
1159	0.0	-7.76	4.632	0.00	262.2
1162	0.2	-7.78	4.644	0.02	262.8
1165	0.0	-7.80	4.656	0.00	263.6
1168	0.0	-7.82	4.668	0.00	264.2
1171	-0.2	-7.85	4.680	-0.02	265.2
1174	0.0	-7.87	4.692	0.00	265.8
1177	0.0	-7.89	4.704	0.00	266.6
1180	-0.2	-7.91	4.716	-0.02	267.2
1183	0.0	-7.93	4.728	0.00	268.0
1186	0.0	-7.95	4.740	0.00	268.6
1189	-0.2	-7.97	4.752	-0.02	269.2
1192	-0.2	-7.99	4.764	-0.02	270.0
1195	0.0	-8.01	4.776	0.00	270.6
1198	0.0	-8.04	4.788	0.00	271.6
1201	0.0	-8.06	4.800	0.00	272.2
1204	0.0	-8.08	4.812	0.00	273.0
1207	0.0	-8.10	4.824	0.00	273.6
1210	-0.4	-8.12	4.836	-0.06	274.4
1213	0.2	-8.14	4.848	0.02	275.0
1216	0.2	-8.16	4.860	0.02	275.6
1219	0.0	-8.18	4.872	0.00	276.4
1222	-0.2	-8.20	4.884	-0.02	277.0
1225	0.0	-8.22	4.896	0.00	277.8
1228	0.2	-8.24	4.908	0.02	278.4
1231	-0.4	-8.27	4.920	-0.06	279.4
1234	0.0	-8.29	4.932	0.00	280.0
1237	-0.2	-8.31	4.944	-0.02	280.8
1240	-0.2	-8.33	4.956	-0.02	281.4
1243	0.0	-8.35	4.968	0.00	282.0
1246	0.2	-8.37	4.980	0.02	282.8
1249	0.0	-8.39	4.992	0.00	283.4
1252	0.0	-8.41	5.004	0.00	284.2
1255	0.0	-8.43	5.016	0.00	284.8
1258	0.0	-8.46	5.028	0.00	285.8
1261	0.0	-8.48	5.040	0.00	286.4
1264	-0.2	-8.50	5.052	-0.02	287.2
1267	0.0	-8.52	5.064	0.00	287.8
1270	0.2	-8.54	5.076	0.02	288.6
1273	0.0	-8.56	5.088	0.00	289.2
1276	0.4	-8.58	5.100	0.06	289.8
1279	-0.2	-8.60	5.112	-0.02	290.6
1282	0.0	-8.62	5.124	0.00	291.2
1285	0.2	-8.65	5.136	0.02	292.2
1288	-0.2	-8.67	5.148	-0.02	293.0
1291	0.0	-8.69	5.160	0.00	293.6
1294	-0.2	-8.71	5.172	-0.02	294.2
1297	0.0	-8.73	5.184	0.00	295.0
1300	-0.2	-8.75	5.196	-0.02	295.6
1303	0.0	-8.77	5.208	0.00	296.2
1306	-0.2	-8.79	5.220	-0.02	297.0
1309	-0.4	-8.81	5.232	-0.06	297.6
1312	0.2	-8.84	5.244	0.02	298.6
1315	-0.2	-8.86	5.256	-0.02	299.4
1318	0.0	-8.88	5.268	0.00	300.0
1321	0.2	-8.90	5.280	0.02	300.6
1324	0.0	-8.92	5.292	0.00	301.4
1327	0.0	-8.94	5.304	0.00	302.0
1330	0.2	-8.96	5.316	0.02	302.8
1333	0.0	-8.98	5.328	0.00	303.4
1336	0.0	-9.01	5.340	0.00	304.4
1339	0.2	-9.03	5.352	0.02	305.0
1342	0.0	-9.05	5.364	0.00	305.8
1345	-0.2	-9.07	5.376	-0.02	306.4
1348	-0.2	-9.09	5.388	-0.02	307.0
1351	0.0	-9.11	5.400	0.00	307.8
1354	0.0	-9.13	5.412	0.00	308.4
1357	0.0	-9.15	5.424	0.00	309.2
1360	0.2	-9.18	5.436	0.02	310.2
1363	0.2	-9.20	5.448	0.02	310.8
1366	0.0	-9.22	5.460	0.00	311.4
1369	0.0	-9.24	5.472	0.00	312.2
1372	0.0	-9.26	5.484	0.00	312.8
1375	0.0	-9.28	5.496	0.00	313.6
1378	0.2	-9.30	5.508	0.02	314.2
1381	0.2	-9.32	5.520	0.02	314.8
1384	0.0	-9.34	5.532	0.00	315.6
1387	0.4	-9.37	5.544	0.06	316.6
1390	0.0	-9.39	5.556	0.00	317.2
1393	-0.2	-9.41	5.568	-0.02	318.0
1396	0.2	-9.43	5.580	0.02	318.6
1399	0.0	-9.45	5.592	0.00	319.2
1402	0.2	-9.47	5.604	0.02	320.0
1405	-0.2	-9.49	5.616	-0.02	320.6
1408	0.0	-9.51	5.628	0.00	321.2
1411	0.0	-9.53	5.640	0.00	322.0
1414	0.0	-9.56	5.652	0.00	323.0
1417	0.0	-9.58	5.664	0.00	323.6
1420	0.0	-9.60	5.676	0.00	324.4
1423	0.0	-9.62	5.688	0.00	325.0
1426	0.0	-9.64	5.700	0.00	325.6
1429	0.0	-9.66	5.712	0.00	326.4
1432	0.2	-9.68	5.724	0.02	327.0
1435	0.0	-9.70	5.736	0.00	327.8
1438	0.0	-9.72	5.748	0.00	328.4
1441	-0.2	-9.75	5.760	-0.02	329.4
1444	0.0	-9.77	5.772	0.00	330.0
1447	-0.2	-9.79	5.784	-0.02	330.8
1450	0.0	-9.81	5.796	0.00	331.4
1453	-0.2	-9.83	5.808	-0.02	332.0
1456	0.0	-9.85	5.820	0.00	332.8
1459	0.0	-9.87	5.832	0.00	333.4
1462	0.0	-9.89	5.844	0.00	334.2
1465	0.0	-9.91	5.856	0.00	334.8
1468	0.0	-9.94	5.868	0.00	335.8
1471	0.0	-9.96	5.880	0.00	336.4
1474	-0.2	-9.98	5.892	-0.02	337.2
1477	0.0	-10.00	5.904	0.00	337.8
1480	0.0	-10.02	5.916	0.00	338.6
1483	0.0	-10.04	5.928	0.00	339.2
1486	0.2	-10.05	5.940	0.02	339.6
1489	0.0	-10.07	5.952	0.00	340.2
1492	0.0	-10.09	5.964	0.00	340.8
1495	-0.2	-10.12	5.976	-0.02	341.8
1498	0.0	-10.14	5.988	0.00	342.6
1501	0.0	-10.16	6.000	0.00	343.2
1504	-0.2	-10.18	6.012	-0.02	344.0
1507	0.0	-10.20	6.024	0.00	344.6
1510	0.0	-10.22	6.036	0.00	345.2
1513	-0.2	-10.24	6.048	-0.02	346.0
1516	0.0	-10.26	6.060	0.00	346.6
1519	0.0	-10.28	6.072	0.00	347.2
1522	0.0	-10.31	6.084	0.00	348.4
1525	0.0	-10.33	6.096	0.00	349.0
1528	0.0	-10.35	6.108	0.00	349.6
1531	-0.2	-10.37	6.120	-0.02	350.4
1534	-0.4	-10.39	6.132	-0.06	351.0
1537	0.2	-10.41	6.144	0.02	351.6
1540	0.0	-10.43	6.156	0.00	352.4
1543	0.0	-10.45	6.168	0.00	353.0
1546	0.2	-10.47	6.180	0.02	353.8
1549	0.0	-10.50	6.192	0.00	354.8
1552	-0.2	-10.52	6.204	-0.02	355.4
1555	0.0	-10.54	6.216	0.00	356.0
1558	-0.4	-10.56	6.228	-0.06	356.8
1561	0.2	-10.58	6.240	0.02	357.4
1564	0.4	-10.60	6.252	0.06	358.2
1567	0.0	-10.62	6.264	0.00	358.8
1570	0.0	-10.64	6.276	0.00	359.4
1573	0.0	-10.66	6.288	0.00	360.2
1576	-0.2	-10.68	6.300	-0.02	360.8
1579	-0.2	-10.70	6.312	-0.02	361.4
1582	0.2	-10.73	6.324	0.02	362.4
1585	0.0	-10.75	6.336	0.00	363.2
1588	0.0	-10.77	6.348	0.00	363.8
1591	0.0	-10.79	6.360	0.00	364.6
1594	0.2	-10.81	6.372	0.02	365.2
1597	0.4	-10.83	6.384	0.06	365.8
1600	0.0	-10.85	6.396	0.00	366.6
1603	-0.2	-10.87	6.408	-0.02	367.2
1606	0.0	-10.89	6.420	0.00	368.0
1609	0.0	-10.91	6.432	0.00	368.6
1612	0.0	-10.94	6.444	0.00	369.6
1615	0.0	-10.96	6.456	0.00	370.2
1618	0.0	-10.98	6.468	0.00	371.0
1621	0.0	-11.00	6.480	0.00	371.6
1624	-0.2	-11.02	6.492	-0.02	372.2
1627	0.2	-11.04	6.504	0.02	373.0
1630	0.0	-11.06	6.516	0.00	373.6
1633	-0.2	-11.08	6.528	-0.02	374.4
1636	0.2	-11.10	6.540	0.02	375.0
1639	-0.2	-11.12	6.552	-0.02	375.6
1642	0.0	-11.14	6.564	0.00	376.4
1645	0.8	-11.17	6.576	0.10	377.4
1648	0.0	-11.18	6.588	0.00	377.8
1651	-0.2	-11.21	6.600	-0.02	378.8
1654	0.0	-11.23	6.612	0.00	379.4
1657	0.0	-11.25	6.624	0.00	380.0
1660	0.0	-11.27	6.636	0.00	380.8
1663	0.2	-11.29	6.648	0.02	381.4
1666	0.0	-11.31	6.660	0.00	382.0
1669	0.0	-11.33	6.672	0.00	382.8
1672	0.0	-11.35	6.684	0.00	383.4
1675	0.0	-11.37	6.696	0.00	384.2
1678	0.0	-11.40	6.708	0.00	385.2
1681	0.2	-11.42	6.720	0.02	385.8
1684	0.2	-11.44	6.732	0.02	386.4
1687	-0.2	-11.46	6.744	-0.02	387.2
1690	0.0	-11.48	6.756	0.00	387.8
1693	0.0	-11.50	6.768	0.00	388.6
1696	-0.2	-11.52	6.780	-0.02	389.2
1699	-0.2	-11.54	6.792	-0.02	389.8
1702	0.0	-11.56	6.804	0.00	390.6
1705	-0.6	-11.58	6.816	-0.08	391.2
1708	-0.6	-11.60	6.828	-0.08	391.8
1711	-0.2	-11.62	6.840	-0.02	392.6
1714	0.0	-11.65	6.852	0.00	393.6
1717	0.0	-11.67	6.864	0.00	394.2
1720	-0.2	-11.69	6.876	-0.02	395.0
1723	0.4	-11.71	6.888	0.06	395.6
1726	0.0	-11.73	6.900	0.00	396.2
1729	0.0	-11.75	6.912	0.00	397.0
1732	0.0	-11.77	6.924	0.00	397.6
1735	0.0	-11.79	6.936	0.00	398.4
1738	0.6	-11.81	6.948	0.08	399.0
1741	0.0	-11.83	6.960	0.00	399.6
1744	0.0	-11.85	6.972	0.00	400.4
1747	-0.2	-11.87	6.984	-0.02	401.0
1750	0.0	-11.89	6.996	0.00	401.6
1753	0.0	-11.92	7.008	0.00	402.8
1756	0.0	-11.94	7.020	0.00	403.4
1759	0.0	-11.96	7.032	0.00	404.0
1762	-0.2	-11.98	7.044	-0.02	404.8
1765	0.2	-12.00	7.056	0.02	405.4
1768	0.0	-12.02	7.068	0.00	406.0
1771	0.4	-12.05	7.080	0.06	407.0
1774	0.0	-12.07	7.092	0.00	407.8
1777	-0.2	-12.09	7.104	-0.02	408.4
1780	0.0	-12.11	7.116	0.00	409.2
1783	0.0	-12.13	7.128	0.00	409.8
1786	0.0	-12.16	7.140	0.00	410.8
1789	0.0	-12.18	7.152	0.00	411.4
1792	0.0	-12.20	7.164	0.00	412.2
1795	0.0	-12.22	7.176	0.00	412.8
1798	0.0	-12.24	7.188	0.00	413.6
1801	0.0	-12.26	7.200	0.00	414.2
1804	0.0	-12.28	7.212	0.00	414.8
1807	0.0	-12.30	7.224	0.00	415.6
1810	0.0	-12.32	7.236	0.00	416.2
1813	0.0	-12.34	7.248	0.00	416.8
1816	-0.2	-12.36	7.260	-0.02	417.6
1819	0.0	-12.39	7.272	0.00	418.6
1822	0.0	-12.41	7.284	0.00	419.2
1825	0.4	-12.43	7.296	0.06	420.0
1828	0.0	-12.45	7.308	0.00	420.6
1831	0.2	-12.47	7.320	0.02	421.2
1834	0.0	-12.49	7.332	0.00	422.0
1837	0.0	-12.51	7.344	0.00	422.6
1840	0.0	-12.53	7.356	0.00	423.4
1843	0.0	-12.55	7.368	0.00	424.0
1846	0.0	-12.57	7.380	0.00	424.6
1849	0.2	-12.60	7.392	0.02	425.6
1852	0.0	-12.62	7.404	0.00	426.4
1855	-0.2	-12.64	7.416	-0.02	427.0
1858	0.2	-12.66	7.428	0.02	427.8
1861	0.0	-12.68	7.440	0.00	428.4
1864	0.0	-12.70	7.452	0.00	429.0
1867	0.2	-12.72	7.464	0.02	429.8
1870	-0.2	-12.74	7.476	-0.02	430.4
1873	0.0	-12.76	7.488	0.00	431.0
1876	0.0	-12.78	7.500	0.00	431.8
1879	0.0	-12.80	7.512	0.00	432.4
1882	0.0	-12.83	7.524	0.00	433.4
1885	0.0	-12.84	7.536	0.00	433.8
1888	0.0	-12.87	7.548	0.00	434.8
1891	-0.2	-12.89	7.560	-0.02	435.4
1894	0.0	-12.91	7.572	0.00	436.2
1897	0.0	-12.93	7.584	0.00	436.8
1900	0.0	-12.95	7.596	0.00	437.6
1903	0.0	-12.97	7.608	0.00	438.2
1906	0.0	-12.99	7.620	0.00	438.8
1909	-0.2	-13.01	7.632	-0.02	439.6
1912	0.0	-13.03	7.644	0.00	440.2
1915	0.2	-13.06	7.656	0.02	441.2
1918	-0.2	-13.08	7.668	-0.02	441.8
1921	0.2	-13.10	7.680	0.02	442.6
1924	0.0	-13.12	7.692	0.00	443.2
1927	0.0	-13.14	7.704	0.00	444.0
1930	0.0	-13.16	7.716	0.00	444.6
1933	0.0	-13.18	7.728	0.00	445.2
1936	-0.4	-13.20	7.740	-0.06	446.0
1939	0.0	-13.22	7.752	0.00	446.6
1942	0.2	-13.25	7.764	0.02	447.6
1945	0.0	-13.27	7.776	0.00	448.4
1948	0.2	-13.29	7.788	0.02	449.0
1951	-0.2	-13.31	7.800	-0.02	449.6
1954	0.2	-13.33	7.812	0.02	450.4
1957	0.0	-13.35	7.824	0.00	451.0
1960	0.0	-13.37	7.836	0.00	451.6
1963	0.4	-13.39	7.848	0.06	452.4
1966	-0.2	-13.41	7.860	-0.02	453.0
1969	0.0	-13.44	7.872	0.00	454.0
1972	0.0	-13.46	7.884	0.00	454.8
1975	0.0	-13.48	7.896	0.00	455.4
1978	0.0	-13.50	7.908	0.00	456.0
1981	0.0	-13.52	7.920	0.00	456.8
1984	-0.2	-13.54	7.932	-0.02	457.4
1987	0.0	-13.56	7.944	0.00	458.2
1990	0.2	-13.58	7.956	0.02	458.8
1993	0.2	-13.60	7.968	0.02	459.4
1996	0.0	-13.63	7.980	0.00	460.4
1999	0.0	-13.65	7.992	0.00	461.2
2002	-0.2	-13.67	8.004	-0.02	461.8
2005	-0.2	-13.69	8.016	-0.02	462.6
2008	0.0	-13.71	8.028	0.00	463.2
2011	0.2	-13.73	8.040	0.02	463.8
2014	0.0	-13.75	8.052	0.00	464.6
2017	0.0	-13.77	8.064	0.00	465.2
2020	-0.4	-13.79	8.076	-0.06	465.8
2023	0.0	-13.82	8.088	0.00	466.8
2026	0.0	-13.84	8.100	0.00	467.6
2029	-0.2	-13.86	8.112	-0.02	468.2
2032	0.0	-13.88	8.124	0.00	469.0
2035	0.2	-13.90	8.136	0.02	469.6
2038	0.2	-13.92	8.148	0.02	470.2
2041	0.0	-13.94	8.160	0.00	471.0
2044	0.0	-13.96	8.172	0.00	471.6
2047	0.0	-13.98	8.184	0.00	472.2
2050	-0.2	-14.01	8.196	-0.02	473.4
2053	0.0	-14.03	8.208	0.00	474.0
2056	0.0	-14.05	8.220	0.00	474.6
2059	-0.2	-14.07	8.232	-0.02	475.4
2062	0.0	-14.09	8.244	0.00	476.0
2065	0.0	-14.11	8.256	0.00	476.6
2068	0.0	-14.13	8.268	0.00	477.4
2071	0.0	-14.16	8.280	0.00	478.4
2074	0.0	-14.18	8.292	0.00	479.0
2077	0.0	-14.20	8.304	0.00	479.8
2080	0.0	-14.22	8.316	0.00	480.4
2083	0.0	-14.24	8.328	0.00	481.0
2086	0.2	-14.26	8.340	0.02	481.8
2089	0.0	-14.28	8.352	0.00	482.4
2092	0.2	-14.30	8.364	0.02	483.2
2095	-0.2	-14.32	8.376	-0.02	483.8
2098	-0.2	-14.35	8.388	-0.02	484.8
2101	0.0	-14.37	8.400	0.00	485.4
2104	0.2	-14.39	8.412	0.02	486.2
2107	0.0	-14.41	8.424	0.00	486.8
2110	0.0	-14.43	8.436	0.00	487.6
2113	0.0	-14.45	8.448	0.00	488.2
2116	0.0	-14.47	8.460	0.00	488.8
2119	-0.2	-14.49	8.472	-0.02	489.6
2122	0.0	-14.51	8.484	0.00	490.2
2125	0.0	-14.54	8.496	0.00	491.2
2128	0.0	-14.56	8.508	0.00	491.8
2131	0.0	-14.58	8.520	0.00	492.6
2134	0.0	-14.60	8.532	0.00	493.2
2137	0.0	-14.62	8.544	0.00	494.0
2140	0.0	-14.64	8.556	0.00	494.6
2143	0.0	-14.66	8.568	0.00	495.2
2146	0.0	-14.68	8.580	0.00	496.0
2149	-0.2	-14.70	8.592	-0.02	496.6
2152	0.0	-14.73	8.604	0.00	497.6
2155	-0.2	-14.75	8.616	-0.02	498.4
2158	0.0	-14.77	8.628	0.00	499.0
2161	0.2	-14.79	8.640	0.02	499.6
2164	-0.2	-14.81	8.652	-0.02	500.4
2167	0.0	-14.83	8.664	0.00	501.0
2170	0.0	-14.85	8.676	0.00	501.6
2173	0.0	-14.87	8.688	0.00	502.4
2176	0.2	-14.89	8.700	0.02	503.0
2179	0.2	-14.92	8.712	0.02	504.0
2182	0.2	-14.94	8.724	0.02	504.8
2185	0.0	-14.96	8.736	0.00	505.4
2188	-0.2	-14.98	8.748	-0.02	506.0
2191	0.0	-15.00	8.760	0.00	506.8
2194	0.0	-15.02	8.772	0.00	507.4
2197	0.2	-15.04	8.784	0.02	508.2
2200	0.0	-15.05	8.796	0.00	508.4
2203	0.0	-15.07	8.808	0.00	509.2
2206	-0.2	-15.10	8.820	-0.02	510.2
2209	0.0	-15.12	8.832	0.00	510.8
2212	0.2	-15.14	8.844	0.02	511.4
2215	0.0	-15.16	8.856	0.00	512.2
2218	0.0	-15.18	8.868	0.00	512.8
2221	0.0	-15.20	8.880	0.00	513.6
2224	0.0	-15.22	8.892	0.00	514.2
2227	0.0	-15.24	8.904	0.00	514.8
2230	0.0	-15.26	8.916	0.00	515.6
2233	0.2	-15.29	8.928	0.02	516.6
2236	0.0	-15.31	8.940	0.00	517.2
2239	-0.2	-15.33	8.952	-0.02	518.0
2242	-0.4	-15.35	8.964	-0.06	518.6
2245	0.0	-15.37	8.976	0.00	519.2
2248	0.0	-15.39	8.988	0.00	520.0
2251	0.4	-15.41	9.000	0.06	520.6
2254	-0.2	-15.43	9.012	-0.02	521.2
2257	0.2	-15.45	9.024	0.02	522.0
2260	0.0	-15.48	9.036	0.00	523.0
2263	0.0	-15.50	9.048	0.00	523.6
2266	-0.2	-15.52	9.060	-0.02	524.4
2269	0.0	-15.54	9.072	0.00	525.0
2272	-0.2	-15.56	9.084	-0.02	525.6
2275	0.0	-15.58	9.096	0.00	526.4
2278	0.0	-15.60	9.108	0.00	527.0
2281	0.0	-15.62	9.120	0.00	527.8
2284	0.0	-15.64	9.132	0.00	528.4
2287	0.0	-15.66	9.144	0.00	529.0
2290	0.0	-15.68	9.156	0.00	529.8
2293	0.0	-15.71	9.168	0.00	530.8
2296	0.0	-15.73	9.180	0.00	531.4
2299	0.0	-15.75	9.192	0.00	532.0
2302	0.0	-15.77	9.204	0.00	532.8
2305	0.0	-15.79	9.216	0.00	533.4
2308	0.0	-15.81	9.228	0.00	534.2
2311	0.0	-15.83	9.240	0.00	534.8
2314	0.0	-15.85	9.252	0.00	535.4
2317	0.2	-15.87	9.264	0.02	536.2
2320	0.0	-15.89	9.276	0.00	536.8
2323	0.2	-15.91	9.288	0.02	537.6
2326	0.2	-15.94	9.300	0.02	538.6
2329	-0.2	-15.96	9.312	-0.02	539.2
2332	0.0	-15.98	9.324	0.00	539.8
2335	-0.2	-16.00	9.336	-0.02	540.6
2338	0.0	-16.02	9.348	0.00	541.2
2341	-0.4	-16.04	9.360	-0.06	541.8
2344	0.0	-16.06	9.372	0.00	542.6
2347	0.0	-16.08	9.384	0.00	543.2
2350	0.0	-16.10	9.396	0.00	544.0
2353	0.0	-16.12	9.408	0.00	544.6
2356	-0.4	-16.14	9.420	-0.06	545.2
2359	-0.2	-16.16	9.432	-0.02	546.0
2362	0.0	-16.19	9.444	0.00	547.0
2365	0.4	-16.21	9.456	0.06	547.6
2368	-0.4	-16.23	9.468	-0.06	548.4
2371	0.0	-16.25	9.480	0.00	549.0
2374	0.0	-16.27	9.492	0.00	549.6
2377	0.0	-16.29	9.504	0.00	550.4
2380	-0.2	-16.31	9.516	-0.02	551.0
2383	0.0	-16.33	9.528	0.00	551.6
2386	0.2	-16.35	9.540	0.02	552.4
2389	0.0	-16.37	9.552	0.00	553.0
2392	0.0	-16.39	9.564	0.00	553.8
2395	0.0	-16.41	9.576	0.00	554.4
2398	-0.2	-16.43	9.588	-0.02	555.0
2401	0.0	-16.46	9.600	0.00	556.0
2404	0.2	-16.48	9.612	0.02	556.8
2407	0.4	-16.50	9.624	0.06	557.4
2410	0.0	-16.52	9.636	0.00	558.2
2413	0.0	-16.54	9.648	0.00	558.8
2416	0.0	-16.56	9.660	0.00	559.4
2419	0.2	-16.58	9.672	0.02	560.2
2422	0.2	-16.60	9.684	0.02	560.8
2425	-0.2	-16.62	9.696	-0.02	561.4
2428	0.0	-16.64	9.708	0.00	562.2
2431	0.0	-16.66	9.720	0.00	562.8
2434	0.0	-16.69	9.732	0.00	563.8
2437	0.0	-16.71	9.744	0.00	564.6
2440	-0.2	-16.73	9.756	-0.02	565.2
2443	0.0	-16.75	9.768	0.00	565.8
2446	0.0	-16.77	9.780	0.00	566.6
2449	0.0	-16.79	9.792	0.00	567.2
2452	0.2	-16.81	9.804	0.02	568.0
2455	-0.2	-16.83	9.816	-0.02	568.6
2458	0.4	-16.85	9.828	0.06	569.2
2461	0.0	-16.87	9.840	0.00	570.0
2464	0.0	-16.89	9.852	0.00	570.6
2467	0.2	-16.91	9.864	0.02	571.2
2470	0.0	-16.94	9.876	0.00	572.2
2473	0.2	-16.96	9.888	0.02	573.0
2476	-0.4	-16.98	9.900	-0.06	573.6
2479	0.0	-17.00	9.912	0.00	574.4
2482	0.0	-17.02	9.924	0.00	575.0
2485	-0.2	-17.04	9.936	-0.02	575.6
2488	0.2	-17.07	9.948	0.02	576.6
2491	0.0	-17.09	9.960	0.00	577.4
2494	0.0	-17.11	9.972	0.00	578.0
2497	0.0	-17.13	9.984	0.00	578.8
2500	0.0	-17.15	9.996	0.00	579.4
2503	-0.2	-17.18	10.008	-0.02	580.4
2506	0.0	-17.20	10.020	0.00	581.0
2509	0.0	-17.22	10.032	0.00	581.8
2512	0.0	-17.24	10.044	0.00	582.4
2515	0.2	-17.26	10.056	0.02	583.2
2518	0.2	-17.28	10.068	0.02	583.8
2521	0.0	-17.30	10.080	0.00	584.4
2524	0.0	-17.32	10.092	0.00	585.2
2527	0.0	-17.34	10.104	0.00	585.8
2530	0.0	-17.36	10.116	0.00	586.4
2533	-0.2	-17.38	10.128	-0.02	587.2
2536	0.0	-17.40	10.140	0.00	587.8
2539	0.0	-17.43	10.152	0.00	588.8
2542	0.2	-17.45	10.164	0.02	589.6
2545	0.0	-17.47	10.176	0.00	590.2
2548	0.2	-17.49	10.188	0.02	590.8
2551	-0.2	-17.51	10.200	-0.02	591.6
2554	0.0	-17.53	10.212	0.00	592.2
2557	0.0	-17.55	10.224	0.00	593.0
2560	0.2	-17.57	10.236	0.02	593.6
2563	0.0	-17.59	10.248	0.00	594.2
2566	0.0	-17.61	10.260	0.00	595.0
2569	0.0	-17.63	10.272	0.00	595.6
2572	0.0	-17.66	10.284	0.00	596.6
2575	0.4	-17.68	10.296	0.06	597.2
2578	0.0	-17.70	10.308	0.00	598.0
2581	0.0	-17.72	10.320	0.00	598.6
2584	0.0	-17.74	10.332	0.00	599.4
2587	0.0	-17.76	10.344	0.00	600.0
2590	0.0	-17.78	10.356	0.00	600.6
2593	-0.2	-17.80	10.368	-0.02	601.4
2596	0.0	-17.82	10.380	0.00	602.0
2599	-0.4	-17.84	10.392	-0.06	602.8
2602	0.0	-17.86	10.404	0.00	603.4
2605	-0.4	-17.89	10.416	-0.06	604.4
2608	0.2	-17.91	10.428	0.02	605.0
2611	-0.2	-17.93	10.440	-0.02	605.8
2614	-0.2	-17.95	10.452	-0.02	606.4
2617	0.2	-17.97	10.464	0.02	607.0
2620	0.0	-17.99	10.476	0.00	607.8
2623	0.0	-18.01	10.488	0.00	608.4
2626	0.0	-18.03	10.500	0.00	609.2
2629	0.0	-18.05	10.512	0.00	609.8
2632	0.0	-18.07	10.524	0.00	610.4
2635	0.0	-18.09	10.536	0.00	611.2
2638	0.0	-18.12	10.548	0.00	612.2
2641	0.0	-18.14	10.560	0.00	612.8
2644	0.0	-18.16	10.572	0.00	613.6
2647	0.0	-18.18	10.584	0.00	614.2
2650	0.0	-18.20	10.596	0.00	614.8
2653	0.2	-18.22	10.608	0.02	615.6
2656	0.0	-18.24	10.620	0.00	616.2
2659	-0.4	-18.26	10.632	-0.06	616.8
2662	0.0	-18.28	10.644	0.00	617.6
2665	0.4	-18.31	10.656	0.06	618.6
2668	0.2	-18.33	10.668	0.02	619.2
2671	0.0	-18.35	10.680	0.00	620.0
2674	0.0	-18.37	10.692	0.00	620.6
2677	-0.4	-18.39	10.704	-0.06	621.2
2680	0.4	-18.41	10.716	0.06	622.0
2683	0.0	-18.43	10.728	0.00	622.6
2686	0.0	-18.45	10.740	0.00	623.4
2689	0.0	-18.47	10.752	0.00	624.0
2692	0.2	-18.49	10.764	0.02	624.6
2695	0.0	-18.52	10.776	0.00	625.6
2698	0.0	-18.54	10.788	0.00	626.4
2701	0.0	-18.56	10.800	0.00	627.0
2704	0.0	-18.58	10.812	0.00	627.8
2707	0.0	-18.60	10.824	0.00	628.4
2710	0.2	-18.62	10.836	0.02	629.0
2713	-0.2	-18.64	10.848	-0.02	629.8
2716	0.0	-18.66	10.860	0.00	630.4
2719	0.0	-18.68	10.872	0.00	631.0
2722	0.0	-18.71	10.884	0.00	632.0
2725	0.0	-18.73	10.896	0.00	632.8
2728	0.0	-18.75	10.908	0.00	633.4
2731	-0.2	-18.77	10.920	-0.02	634.2
2734	-0.2	-18.79	10.932	-0.02	634.8
2737	0.0	-18.81	10.944	0.00	635.4
2740	-0.2	-18.83	10.956	-0.02	636.2
2743	-0.2	-18.85	10.968	-0.02	636.8
2746	0.0	-18.87	10.980	0.00	637.6
2749	0.2	-18.90	10.992	0.02	638.6
2752	0.2	-18.92	11.004	0.02	639.2
2755	-0.2	-18.94	11.016	-0.02	639.8
2758	0.0	-18.96	11.028	0.00	640.6
2761	-0.2	-18.98	11.040	-0.02	641.2
2764	0.0	-19.00	11.052	0.00	641.8
2767	-0.4	-19.02	11.064	-0.06	642.6
2770	0.2	-19.04	11.076	0.02	643.2
2773	0.6	-19.06	11.088	0.08	644.0
2776	0.0	-19.08	11.100	0.00	644.6
2779	0.0	-19.10	11.112	0.00	645.2
2782	0.0	-19.12	11.124	0.00	646.0
2785	0.2	-19.14	11.136	0.02	646.6
2788	0.0	-19.16	11.148	0.00	647.2
2791	0.0	-19.18	11.160	0.00	648.0
2794	0.4	-19.20	11.172	0.06	648.6
2797	0.0	-19.22	11.184	0.00	649.4
2800	0.2	-19.25	11.196	0.02	650.4
2803	0.0	-19.27	11.208	0.00	651.0
2806	0.0	-19.29	11.220	0.00	651.6
2809	-0.2	-19.31	11.232	-0.02	652.4
2812	-0.2	-19.33	11.244	-0.02	653.0
2815	0.0	-19.35	11.256	0.00	653.8
2818	-0.2	-19.37	11.268	-0.02	654.4
2821	0.0	-19.39	11.280	0.00	655.0
2824	0.0	-19.41	11.292	0.00	655.8
2827	0.0	-19.44	11.304	0.00	656.8
2830	0.2	-19.46	11.316	0.02	657.4
2833	0.6	-19.48	11.328	0.08	658.2
2836	0.8	-19.50	11.340	0.10	658.8
2839	1.8	-19.52	11.352	0.24	659.4
2842	3.4	-19.54	11.364	0.44	660.2
2845	5.2	-19.56	11.376	0.68	660.8
2848	7.8	-19.58	11.388	1.02	661.4
2851	10.8	-19.60	11.400	1.42	662.2
2854	14.8	-19.62	11.412	1.94	662.8
2857	19.6	-19.63	11.424	2.56	663.2
2860	24.6	-19.65	11.436	3.22	663.8
2863	30.0	-19.67	11.448	3.92	664.6
2866	38.2	-19.68	11.460	5.00	664.8
2869	48.2	-19.69	11.472	6.30	665.2
2872	58.4	-19.71	11.484	7.64	665.8
2875	64.4	-19.72	11.496	8.42	666.2
2878	64.4	-19.74	11.508	8.42	666.8
2881	64.0	-19.76	11.520	8.38	667.6
2884	64.2	-19.78	11.532	8.40	668.2
2887	63.2	-19.81	11.544	8.26	669.2
2890	63.8	-19.83	11.556	8.34	670.0
2893	64.4	-19.85	11.568	8.42	670.6
2896	64.8	-19.87	11.580	8.48	671.2
2899	64.8	-19.89	11.592	8.48	672.0
2902	62.6	-19.91	11.604	8.18	672.6
2905	60.6	-19.93	11.616	7.92	673.4
2908	59.2	-19.96	11.628	7.74	674.4
2911	58.6	-19.98	11.640	7.66	675.0
2914	57.2	-20.00	11.652	7.48	675.6
2917	57.6	-20.02	11.664	7.54	676.4
2920	60.4	-20.04	11.676	7.90	677.0
2923	60.8	-20.06	11.688	7.96	677.8
2926	59.0	-20.08	11.700	7.72	678.4
2929	58.2	-20.11	11.712	7.62	679.4
2932	57.8	-20.13	11.724	7.56	680.0
2935	55.4	-20.15	11.736	7.24	680.8
2938	53.4	-20.17	11.748	6.98	681.4
2941	50.8	-20.19	11.760	6.64	682.0
2944	51.6	-20.22	11.772	6.74	683.2
2947	50.6	-20.24	11.784	6.62	683.8
2950	49.8	-20.26	11.796	6.52	684.4
2953	49.6	-20.28	11.808	6.48	685.2
2956	49.6	-20.30	11.820	6.48	685.8
2959	49.8	-20.32	11.832	6.52	686.4
2962	50.4	-20.34	11.844	6.60	687.2
2965	51.4	-20.36	11.856	6.72	687.8
2968	51.4	-20.38	11.868	6.72	688.6
2971	52.0	-20.40	11.880	6.80	689.2
2974	52.2	-20.42	11.892	6.82	689.8
2977	52.6	-20.45	11.904	6.88	690.8
2980	53.0	-20.47	11.916	6.94	691.6
2983	53.6	-20.49	11.928	7.02	692.2
2986	54.2	-20.51	11.940	7.08	693.0
2989	54.4	-20.53	11.952	7.12	693.6
2992	54.0	-20.55	11.964	7.06	694.2
2995	53.0	-20.57	11.976	6.94	695.0
2998	52.6	-20.59	11.988	6.88	695.6
3001	51.0	-20.61	12.000	6.68	696.2
3004	49.6	-20.64	12.012	6.48	697.2
3007	47.8	-20.66	12.024	6.26	698.0
3010	46.4	-20.68	12.036	6.06	698.6
3013	44.8	-20.70	12.048	5.86	699.4
3016	44.2	-20.73	12.060	5.78	700.4
3019	43.8	-20.75	12.072	5.72	701.0
3022	43.8	-20.77	12.084	5.72	701.6
3025	45.2	-20.79	12.096	5.92	702.4
3028	46.0	-20.81	12.108	6.02	703.0
3031	48.2	-20.83	12.120	6.30	703.8
3034	48.8	-20.85	12.132	6.38	704.4
3037	51.2	-20.87	12.144	6.70	705.0
3040	53.0	-20.89	12.156	6.94	705.8
3043	53.4	-20.91	12.168	6.98	706.4
3046	54.2	-20.93	12.180	7.08	707.0
3049	54.8	-20.95	12.192	7.16	707.8
3052	56.2	-20.97	12.204	7.36	708.4
3055	57.2	-20.99	12.216	7.48	709.2
3058	58.4	-21.01	12.228	7.64	709.8
3061	59.6	-21.03	12.240	7.80	710.4
3064	61.6	-21.05	12.252	8.06	711.2
3067	61.0	-21.07	12.264	7.98	711.8
3070	60.0	-21.09	12.276	7.84	712.4
3073	61.8	-21.11	12.288	8.08	713.2
3076	62.8	-21.13	12.300	8.22	713.8
3079	64.4	-21.15	12.312	8.42	714.6
3082	68.2	-21.16	12.324	8.92	714.8
3085	70.4	-21.18	12.336	9.20	715.6
3088	71.2	-21.20	12.348	9.32	716.2
3091	71.0	-21.23	12.360	9.28	717.2
3094	71.8	-21.25	12.372	9.40	718.0
3097	72.2	-21.27	12.384	9.44	718.6
3100	73.0	-21.29	12.396	9.54	719.2
3103	72.6	-21.31	12.408	9.50	720.0
3106	73.2	-21.33	12.420	9.58	720.6
3109	73.6	-21.35	12.432	9.62	721.2
3112	75.2	-21.37	12.444	9.84	722.0
3115	72.0	-21.38	12.456	9.42	722.2
3118	66.6	-21.38	12.468	8.72	722.2
3121	64.0	-21.39	12.480	8.38	722.6
3124	62.6	-21.39	12.492	8.18	722.6
3127	61.4	-21.39	12.504	8.04	722.6
3130	60.4	-21.39	12.516	7.90	722.6
3133	59.6	-21.39	12.528	7.80	722.6
3136	58.8	-21.39	12.540	7.70	722.6
3139	58.4	-21.39	12.552	7.64	722.6
3142	57.8	-21.39	12.564	7.56	722.6
3145	57.2	-21.39	12.576	7.48	722.6
3148	56.8	-21.39	12.588	7.42	722.6
3151	56.4	-21.39	12.600	7.38	722.6
3154	56.2	-21.39	12.612	7.36	722.6
3157	55.8	-21.39	12.624	7.30	722.6
3159	55.6	-21.39	12.632	7.28	722.6