File: results/youngs-modulus/2025-04-15/inconclusives/pf10lt01.csv
sep=
pf10lt01

System Information:
IntelliMESUR Version: 2.2.1
Test Frame Model: F505
Test Frame Serial Number: 4418651
Test Frame Capacity: 500 lbF / 2.2 kN
Test Frame Firmware Version: 1.00.14
Force Sensor Model: FS05-100
Force Sensor Capacity: 500 N
Force Sensor Resolution: 0.2 N
Force Sensor Serial Number: 4425350
Calibration Date: Apr 29, 2024
Calibration Due Date: Apr 29, 2025

Reading	Load [N]	Distance [mm]	Time [s]	Stress [MPa]	Strain [%]
1	0.0	0.00	0.000	0.00	0.0
4	0.0	0.00	0.012	0.00	0.0
7	0.0	0.00	0.024	0.00	0.0
10	-0.2	0.00	0.036	-0.05	0.0
13	0.0	0.00	0.048	0.00	0.0
16	0.0	0.00	0.060	0.00	0.0
19	0.0	0.00	0.072	0.00	0.0
22	-0.2	0.00	0.084	-0.05	0.0
25	0.2	0.00	0.096	0.05	0.0
28	0.0	0.00	0.108	0.00	0.0
31	0.0	0.00	0.120	0.00	0.0
34	0.0	0.00	0.132	0.00	0.0
37	-0.2	0.00	0.144	-0.05	0.0
40	0.0	0.00	0.156	0.00	0.0
43	0.0	0.00	0.168	0.00	0.0
46	0.0	0.00	0.180	0.00	0.0
49	0.0	0.00	0.192	0.00	0.0
52	0.0	-0.02	0.204	0.00	1.0
55	0.0	-0.04	0.216	0.00	2.0
58	0.0	-0.06	0.228	0.00	3.0
61	0.0	-0.08	0.240	0.00	4.0
64	0.0	-0.10	0.252	0.00	5.0
67	0.2	-0.12	0.264	0.05	6.0
70	0.0	-0.15	0.276	0.00	7.5
73	-0.2	-0.17	0.288	-0.05	8.5
76	0.0	-0.19	0.300	0.00	9.5
79	0.2	-0.21	0.312	0.05	10.5
82	0.0	-0.23	0.324	0.00	11.5
85	0.0	-0.25	0.336	0.00	12.5
88	0.0	-0.27	0.348	0.00	13.5
91	0.0	-0.29	0.360	0.00	14.5
94	-0.2	-0.31	0.372	-0.05	15.5
97	0.0	-0.34	0.384	0.00	17.0
100	0.0	-0.36	0.396	0.00	18.0
103	0.0	-0.38	0.408	0.00	19.0
106	0.2	-0.40	0.420	0.05	20.0
109	0.0	-0.42	0.432	0.00	21.0
112	-0.2	-0.44	0.444	-0.05	22.0
115	0.0	-0.46	0.456	0.00	23.0
118	0.0	-0.48	0.468	0.00	24.0
121	0.0	-0.50	0.480	0.00	25.0
124	0.0	-0.52	0.492	0.00	26.0
127	0.0	-0.54	0.504	0.00	27.0
130	0.0	-0.57	0.516	0.00	28.5
133	0.0	-0.59	0.528	0.00	29.5
136	-0.2	-0.61	0.540	-0.05	30.5
139	0.2	-0.63	0.552	0.05	31.5
142	0.0	-0.65	0.564	0.00	32.5
145	0.0	-0.67	0.576	0.00	33.5
148	0.0	-0.69	0.588	0.00	34.5
151	-0.2	-0.71	0.600	-0.05	35.5
154	0.0	-0.73	0.612	0.00	36.5
157	0.2	-0.75	0.624	0.05	37.5
160	0.0	-0.78	0.636	0.00	39.0
163	0.0	-0.80	0.648	0.00	40.0
166	0.4	-0.82	0.660	0.10	41.0
169	0.2	-0.84	0.672	0.05	42.0
172	-0.2	-0.86	0.684	-0.05	43.0
175	-0.2	-0.88	0.696	-0.05	44.0
178	0.2	-0.90	0.708	0.05	45.0
181	0.2	-0.92	0.720	0.05	46.0
184	0.0	-0.94	0.732	0.00	47.0
187	-0.2	-0.96	0.744	-0.05	48.0
190	0.2	-0.98	0.756	0.05	49.0
193	0.0	-1.02	0.768	0.00	51.0
196	0.0	-1.04	0.780	0.00	52.0
199	0.2	-1.06	0.792	0.05	53.0
202	0.0	-1.08	0.804	0.00	54.0
205	0.2	-1.10	0.816	0.05	55.0
208	0.0	-1.12	0.828	0.00	56.0
211	0.0	-1.14	0.840	0.00	57.0
214	0.0	-1.16	0.852	0.00	58.0
217	0.0	-1.18	0.864	0.00	59.0
220	0.2	-1.20	0.876	0.05	60.0
223	0.2	-1.22	0.888	0.05	61.0
226	0.2	-1.25	0.900	0.05	62.5
229	0.0	-1.27	0.912	0.00	63.5
232	0.0	-1.29	0.924	0.00	64.5
235	-0.2	-1.31	0.936	-0.05	65.5
238	-0.2	-1.33	0.948	-0.05	66.5
241	0.0	-1.35	0.960	0.00	67.5
244	0.0	-1.37	0.972	0.00	68.5
247	0.0	-1.39	0.984	0.00	69.5
250	0.2	-1.41	0.996	0.05	70.5
253	-0.2	-1.43	1.008	-0.05	71.5
256	0.0	-1.45	1.020	0.00	72.5
259	0.0	-1.48	1.032	0.00	74.0
262	0.0	-1.50	1.044	0.00	75.0
265	0.0	-1.52	1.056	0.00	76.0
268	-0.4	-1.54	1.068	-0.10	77.0
271	0.0	-1.56	1.080	0.00	78.0
274	0.0	-1.58	1.092	0.00	79.0
277	0.0	-1.60	1.104	0.00	80.0
280	-0.2	-1.62	1.116	-0.05	81.0
283	0.0	-1.64	1.128	0.00	82.0
286	0.0	-1.66	1.140	0.00	83.0
289	0.0	-1.68	1.152	0.00	84.0
292	0.0	-1.70	1.164	0.00	85.0
295	0.0	-1.73	1.176	0.00	86.5
298	0.2	-1.75	1.188	0.05	87.5
301	0.0	-1.77	1.200	0.00	88.5
304	0.4	-1.79	1.212	0.10	89.5
307	0.0	-1.81	1.224	0.00	90.5
310	0.2	-1.83	1.236	0.05	91.5
313	0.0	-1.85	1.248	0.00	92.5
316	0.0	-1.87	1.260	0.00	93.5
319	0.0	-1.89	1.272	0.00	94.5
322	0.0	-1.91	1.284	0.00	95.5
325	0.2	-1.93	1.296	0.05	96.5
328	0.0	-1.96	1.308	0.00	98.0
331	0.2	-1.98	1.320	0.05	99.0
334	0.0	-2.00	1.332	0.00	100.0
337	0.0	-2.01	1.344	0.00	100.5
340	0.0	-2.03	1.356	0.00	101.5
343	0.0	-2.05	1.368	0.00	102.5
346	0.0	-2.07	1.380	0.00	103.5
349	0.0	-2.09	1.392	0.00	104.5
352	0.2	-2.11	1.404	0.05	105.5
355	0.0	-2.13	1.416	0.00	106.5
358	0.0	-2.15	1.428	0.00	107.5
361	0.2	-2.18	1.440	0.05	109.0
364	0.0	-2.20	1.452	0.00	110.0
367	0.0	-2.22	1.464	0.00	111.0
370	-0.2	-2.24	1.476	-0.05	112.0
373	0.0	-2.26	1.488	0.00	113.0
376	0.0	-2.28	1.500	0.00	114.0
379	0.0	-2.30	1.512	0.00	115.0
382	0.0	-2.32	1.524	0.00	116.0
385	0.0	-2.34	1.536	0.00	117.0
388	-0.2	-2.36	1.548	-0.05	118.0
391	0.4	-2.38	1.560	0.10	119.0
394	0.0	-2.40	1.572	0.00	120.0
397	-0.2	-2.43	1.584	-0.05	121.5
400	0.0	-2.45	1.596	0.00	122.5
403	-0.2	-2.47	1.608	-0.05	123.5
406	-0.2	-2.49	1.620	-0.05	124.5
409	0.0	-2.51	1.632	0.00	125.5
412	0.2	-2.53	1.644	0.05	126.5
415	0.0	-2.55	1.656	0.00	127.5
418	0.0	-2.57	1.668	0.00	128.5
421	0.0	-2.59	1.680	0.00	129.5
424	0.0	-2.61	1.692	0.00	130.5
427	0.0	-2.63	1.704	0.00	131.5
430	-0.2	-2.66	1.716	-0.05	133.0
433	0.0	-2.68	1.728	0.00	134.0
436	0.2	-2.70	1.740	0.05	135.0
439	0.2	-2.72	1.752	0.05	136.0
442	0.2	-2.74	1.764	0.05	137.0
445	0.2	-2.76	1.776	0.05	138.0
448	0.0	-2.78	1.788	0.00	139.0
451	-0.2	-2.80	1.800	-0.05	140.0
454	0.0	-2.82	1.812	0.00	141.0
457	0.0	-2.84	1.824	0.00	142.0
460	-0.2	-2.86	1.836	-0.05	143.0
463	0.0	-2.89	1.848	0.00	144.5
466	-0.2	-2.91	1.860	-0.05	145.5
469	0.0	-2.93	1.872	0.00	146.5
472	-0.2	-2.95	1.884	-0.05	147.5
475	0.2	-2.97	1.896	0.05	148.5
478	0.0	-3.00	1.908	0.00	150.0
481	0.0	-3.02	1.920	0.00	151.0
484	0.0	-3.04	1.932	0.00	152.0
487	0.0	-3.06	1.944	0.00	153.0
490	0.2	-3.09	1.956	0.05	154.5
493	0.2	-3.11	1.968	0.05	155.5
496	0.0	-3.13	1.980	0.00	156.5
499	-0.2	-3.15	1.992	-0.05	157.5
502	-0.2	-3.17	2.004	-0.05	158.5
505	0.0	-3.19	2.016	0.00	159.5
508	0.0	-3.21	2.028	0.00	160.5
511	0.0	-3.23	2.040	0.00	161.5
514	0.0	-3.25	2.052	0.00	162.5
517	0.0	-3.28	2.064	0.00	164.0
520	0.0	-3.29	2.076	0.00	164.5
523	0.0	-3.32	2.088	0.00	166.0
526	0.0	-3.34	2.100	0.00	167.0
529	-0.2	-3.36	2.112	-0.05	168.0
532	0.0	-3.38	2.124	0.00	169.0
535	0.0	-3.40	2.136	0.00	170.0
538	-0.2	-3.42	2.148	-0.05	171.0
541	0.0	-3.44	2.160	0.00	172.0
544	0.0	-3.46	2.172	0.00	173.0
547	0.0	-3.48	2.184	0.00	174.0
550	0.0	-3.51	2.196	0.00	175.5
553	0.0	-3.53	2.208	0.00	176.5
556	0.2	-3.55	2.220	0.05	177.5
559	0.0	-3.57	2.232	0.00	178.5
562	0.0	-3.59	2.244	0.00	179.5
565	0.0	-3.61	2.256	0.00	180.5
568	0.0	-3.63	2.268	0.00	181.5
571	0.0	-3.65	2.280	0.00	182.5
574	0.0	-3.68	2.292	0.00	184.0
577	0.0	-3.70	2.304	0.00	185.0
580	0.0	-3.72	2.316	0.00	186.0
583	0.0	-3.74	2.328	0.00	187.0
586	-0.4	-3.76	2.340	-0.10	188.0
589	0.0	-3.78	2.352	0.00	189.0
592	0.0	-3.80	2.364	0.00	190.0
595	0.0	-3.82	2.376	0.00	191.0
598	0.0	-3.85	2.388	0.00	192.5
601	0.0	-3.87	2.400	0.00	193.5
604	0.0	-3.89	2.412	0.00	194.5
607	0.2	-3.91	2.424	0.05	195.5
610	0.0	-3.93	2.436	0.00	196.5
613	-0.2	-3.95	2.448	-0.05	197.5
616	0.0	-3.97	2.460	0.00	198.5
619	0.0	-3.99	2.472	0.00	199.5
622	0.0	-4.01	2.484	0.00	200.5
625	0.0	-4.04	2.496	0.00	202.0
628	0.0	-4.06	2.508	0.00	203.0
631	0.2	-4.08	2.520	0.05	204.0
634	0.0	-4.10	2.532	0.00	205.0
637	0.2	-4.12	2.544	0.05	206.0
640	0.0	-4.14	2.556	0.00	207.0
643	0.0	-4.16	2.568	0.00	208.0
646	0.0	-4.18	2.580	0.00	209.0
649	0.2	-4.20	2.592	0.05	210.0
652	0.2	-4.23	2.604	0.05	211.5
655	0.2	-4.25	2.616	0.05	212.5
658	0.4	-4.27	2.628	0.10	213.5
661	-0.2	-4.29	2.640	-0.05	214.5
664	0.2	-4.31	2.652	0.05	215.5
667	0.0	-4.33	2.664	0.00	216.5
670	0.0	-4.35	2.676	0.00	217.5
673	0.0	-4.37	2.688	0.00	218.5
676	-0.2	-4.39	2.700	-0.05	219.5
679	0.0	-4.42	2.712	0.00	221.0
682	-0.2	-4.44	2.724	-0.05	222.0
685	0.0	-4.46	2.736	0.00	223.0
688	-0.2	-4.48	2.748	-0.05	224.0
691	0.0	-4.50	2.760	0.00	225.0
694	0.0	-4.52	2.772	0.00	226.0
697	-0.2	-4.54	2.784	-0.05	227.0
700	-0.2	-4.56	2.796	-0.05	228.0
703	0.0	-4.58	2.808	0.00	229.0
706	-0.2	-4.61	2.820	-0.05	230.5
709	-0.2	-4.63	2.832	-0.05	231.5
712	0.2	-4.65	2.844	0.05	232.5
715	0.2	-4.67	2.856	0.05	233.5
718	-0.2	-4.69	2.868	-0.05	234.5
721	0.0	-4.71	2.880	0.00	235.5
724	0.2	-4.73	2.892	0.05	236.5
727	-0.2	-4.75	2.904	-0.05	237.5
730	0.0	-4.77	2.916	0.00	238.5
733	0.0	-4.80	2.928	0.00	240.0
736	0.0	-4.82	2.940	0.00	241.0
739	0.2	-4.84	2.952	0.05	242.0
742	0.0	-4.86	2.964	0.00	243.0
745	0.2	-4.88	2.976	0.05	244.0
748	0.0	-4.90	2.988	0.00	245.0
751	-0.2	-4.92	3.000	-0.05	246.0
754	-0.2	-4.94	3.012	-0.05	247.0
757	0.0	-4.96	3.024	0.00	248.0
760	0.2	-4.99	3.036	0.05	249.5
763	0.0	-5.01	3.048	0.00	250.5
766	0.0	-5.03	3.060	0.00	251.5
769	0.0	-5.05	3.072	0.00	252.5
772	0.0	-5.07	3.084	0.00	253.5
775	0.0	-5.09	3.096	0.00	254.5
778	-0.2	-5.11	3.108	-0.05	255.5
781	0.0	-5.13	3.120	0.00	256.5
784	0.0	-5.15	3.132	0.00	257.5
787	0.0	-5.18	3.144	0.00	259.0
790	0.0	-5.20	3.156	0.00	260.0
793	0.2	-5.22	3.168	0.05	261.0
796	0.0	-5.24	3.180	0.00	262.0
799	0.2	-5.26	3.192	0.05	263.0
802	0.0	-5.28	3.204	0.00	264.0
805	0.2	-5.30	3.216	0.05	265.0
808	0.0	-5.32	3.228	0.00	266.0
811	-0.2	-5.34	3.240	-0.05	267.0
814	0.2	-5.36	3.252	0.05	268.0
817	0.0	-5.39	3.264	0.00	269.5
820	0.0	-5.41	3.276	0.00	270.5
823	0.0	-5.43	3.288	0.00	271.5
826	0.2	-5.45	3.300	0.05	272.5
829	0.0	-5.47	3.312	0.00	273.5
832	0.0	-5.49	3.324	0.00	274.5
835	0.0	-5.51	3.336	0.00	275.5
838	0.0	-5.53	3.348	0.00	276.5
841	-0.2	-5.55	3.360	-0.05	277.5
844	0.0	-5.57	3.372	0.00	278.5
847	0.0	-5.60	3.384	0.00	280.0
850	0.0	-5.62	3.396	0.00	281.0
853	0.0	-5.64	3.408	0.00	282.0
856	0.0	-5.66	3.420	0.00	283.0
859	0.0	-5.68	3.432	0.00	284.0
862	0.0	-5.70	3.444	0.00	285.0
865	-0.4	-5.72	3.456	-0.10	286.0
868	-0.2	-5.74	3.468	-0.05	287.0
871	-0.2	-5.76	3.480	-0.05	288.0
874	0.0	-5.78	3.492	0.00	289.0
877	0.0	-5.80	3.504	0.00	290.0
880	0.0	-5.82	3.516	0.00	291.0
883	0.0	-5.85	3.528	0.00	292.5
886	0.0	-5.87	3.540	0.00	293.5
889	0.2	-5.89	3.552	0.05	294.5
892	0.0	-5.91	3.564	0.00	295.5
895	0.0	-5.93	3.576	0.00	296.5
898	0.0	-5.95	3.588	0.00	297.5
901	0.0	-5.97	3.600	0.00	298.5
904	0.0	-5.99	3.612	0.00	299.5
907	-0.2	-6.00	3.624	-0.05	300.0
910	0.0	-6.02	3.636	0.00	301.0
913	0.2	-6.04	3.648	0.05	302.0
916	-0.4	-6.07	3.660	-0.10	303.5
919	0.0	-6.09	3.672	0.00	304.5
922	0.0	-6.11	3.684	0.00	305.5
925	-0.2	-6.13	3.696	-0.05	306.5
928	0.0	-6.15	3.708	0.00	307.5
931	0.0	-6.17	3.720	0.00	308.5
934	0.0	-6.19	3.732	0.00	309.5
937	0.2	-6.21	3.744	0.05	310.5
940	0.0	-6.23	3.756	0.00	311.5
943	0.2	-6.25	3.768	0.05	312.5
946	-0.2	-6.27	3.780	-0.05	313.5
949	0.2	-6.30	3.792	0.05	315.0
952	0.0	-6.32	3.804	0.00	316.0
955	0.2	-6.34	3.816	0.05	317.0
958	0.0	-6.36	3.828	0.00	318.0
961	0.4	-6.38	3.840	0.10	319.0
964	0.0	-6.40	3.852	0.00	320.0
967	0.0	-6.42	3.864	0.00	321.0
970	-0.4	-6.44	3.876	-0.10	322.0
973	0.0	-6.46	3.888	0.00	323.0
976	0.0	-6.48	3.900	0.00	324.0
979	0.0	-6.50	3.912	0.00	325.0
982	0.0	-6.52	3.924	0.00	326.0
985	0.0	-6.55	3.936	0.00	327.5
988	0.0	-6.57	3.948	0.00	328.5
991	0.0	-6.59	3.960	0.00	329.5
994	0.0	-6.61	3.972	0.00	330.5
997	-0.4	-6.63	3.984	-0.10	331.5
1000	0.0	-6.65	3.996	0.00	332.5
1003	0.0	-6.67	4.008	0.00	333.5
1006	0.0	-6.69	4.020	0.00	334.5
1009	0.0	-6.71	4.032	0.00	335.5
1012	0.0	-6.73	4.044	0.00	336.5
1015	0.0	-6.75	4.056	0.00	337.5
1018	0.0	-6.77	4.068	0.00	338.5
1021	0.2	-6.79	4.080	0.05	339.5
1024	0.0	-6.82	4.092	0.00	341.0
1027	0.2	-6.84	4.104	0.05	342.0
1030	0.2	-6.86	4.116	0.05	343.0
1033	-0.2	-6.88	4.128	-0.05	344.0
1036	0.0	-6.90	4.140	0.00	345.0
1039	-0.2	-6.92	4.152	-0.05	346.0
1042	0.0	-6.94	4.164	0.00	347.0
1045	0.2	-6.96	4.176	0.05	348.0
1048	0.0	-6.98	4.188	0.00	349.0
1051	0.0	-7.01	4.200	0.00	350.5
1054	0.0	-7.03	4.212	0.00	351.5
1057	0.0	-7.06	4.224	0.00	353.0
1060	0.2	-7.08	4.236	0.05	354.0
1063	0.0	-7.10	4.248	0.00	355.0
1066	0.0	-7.12	4.260	0.00	356.0
1069	0.0	-7.14	4.272	0.00	357.0
1072	-0.2	-7.16	4.284	-0.05	358.0
1075	-0.4	-7.18	4.296	-0.10	359.0
1078	0.0	-7.20	4.308	0.00	360.0
1081	0.0	-7.22	4.320	0.00	361.0
1084	0.2	-7.24	4.332	0.05	362.0
1087	0.0	-7.26	4.344	0.00	363.0
1090	0.0	-7.28	4.356	0.00	364.0
1093	0.0	-7.31	4.368	0.00	365.5
1096	0.0	-7.33	4.380	0.00	366.5
1099	-0.2	-7.35	4.392	-0.05	367.5
1102	0.2	-7.37	4.404	0.05	368.5
1105	0.0	-7.39	4.416	0.00	369.5
1108	0.0	-7.41	4.428	0.00	370.5
1111	-0.2	-7.43	4.440	-0.05	371.5
1114	-0.2	-7.45	4.452	-0.05	372.5
1117	0.0	-7.47	4.464	0.00	373.5
1120	0.0	-7.49	4.476	0.00	374.5
1123	0.0	-7.51	4.488	0.00	375.5
1126	0.0	-7.54	4.500	0.00	377.0
1129	0.0	-7.56	4.512	0.00	378.0
1132	0.2	-7.58	4.524	0.05	379.0
1135	0.2	-7.60	4.536	0.05	380.0
1138	0.4	-7.62	4.548	0.10	381.0
1141	-0.2	-7.64	4.560	-0.05	382.0
1144	0.0	-7.66	4.572	0.00	383.0
1147	-0.2	-7.68	4.584	-0.05	384.0
1150	0.0	-7.70	4.596	0.00	385.0
1153	-0.4	-7.72	4.608	-0.10	386.0
1156	-0.2	-7.74	4.620	-0.05	387.0
1159	0.2	-7.77	4.632	0.05	388.5
1162	0.0	-7.79	4.644	0.00	389.5
1165	0.0	-7.81	4.656	0.00	390.5
1168	-0.2	-7.83	4.668	-0.05	391.5
1171	0.0	-7.85	4.680	0.00	392.5
1174	0.0	-7.87	4.692	0.00	393.5
1177	0.0	-7.89	4.704	0.00	394.5
1180	0.2	-7.91	4.716	0.05	395.5
1183	0.0	-7.93	4.728	0.00	396.5
1186	0.0	-7.95	4.740	0.00	397.5
1189	-0.2	-7.97	4.752	-0.05	398.5
1192	0.0	-8.00	4.764	0.00	400.0
1195	-0.2	-8.02	4.776	-0.05	401.0
1198	0.2	-8.04	4.788	0.05	402.0
1201	-0.2	-8.06	4.800	-0.05	403.0
1204	0.0	-8.08	4.812	0.00	404.0
1207	0.0	-8.10	4.824	0.00	405.0
1210	0.0	-8.12	4.836	0.00	406.0
1213	0.0	-8.14	4.848	0.00	407.0
1216	0.0	-8.16	4.860	0.00	408.0
1219	0.2	-8.19	4.872	0.05	409.5
1222	-0.2	-8.21	4.884	-0.05	410.5
1225	0.0	-8.23	4.896	0.00	411.5
1228	0.2	-8.25	4.908	0.05	412.5
1231	0.0	-8.27	4.920	0.00	413.5
1234	0.0	-8.29	4.932	0.00	414.5
1237	0.0	-8.31	4.944	0.00	415.5
1240	0.0	-8.33	4.956	0.00	416.5
1243	0.2	-8.35	4.968	0.05	417.5
1246	0.0	-8.37	4.980	0.00	418.5
1249	0.0	-8.40	4.992	0.00	420.0
1252	0.2	-8.42	5.004	0.05	421.0
1255	0.2	-8.44	5.016	0.05	422.0
1258	0.2	-8.46	5.028	0.05	423.0
1261	0.0	-8.48	5.040	0.00	424.0
1264	-0.2	-8.50	5.052	-0.05	425.0
1267	0.0	-8.52	5.064	0.00	426.0
1270	0.2	-8.54	5.076	0.05	427.0
1273	0.0	-8.56	5.088	0.00	428.0
1276	-0.4	-8.59	5.100	-0.10	429.5
1279	0.0	-8.61	5.112	0.00	430.5
1282	0.2	-8.63	5.124	0.05	431.5
1285	0.0	-8.65	5.136	0.00	432.5
1288	-0.2	-8.67	5.148	-0.05	433.5
1291	0.0	-8.69	5.160	0.00	434.5
1294	-0.4	-8.71	5.172	-0.10	435.5
1297	0.0	-8.73	5.184	0.00	436.5
1300	-0.2	-8.75	5.196	-0.05	437.5
1303	0.2	-8.78	5.208	0.05	439.0
1306	0.0	-8.80	5.220	0.00	440.0
1309	0.0	-8.82	5.232	0.00	441.0
1312	0.0	-8.84	5.244	0.00	442.0
1315	0.0	-8.86	5.256	0.00	443.0
1318	0.0	-8.88	5.268	0.00	444.0
1321	0.2	-8.90	5.280	0.05	445.0
1324	0.0	-8.92	5.292	0.00	446.0
1327	0.0	-8.95	5.304	0.00	447.5
1330	0.0	-8.97	5.316	0.00	448.5
1333	0.0	-8.99	5.328	0.00	449.5
1336	-0.2	-9.01	5.340	-0.05	450.5
1339	0.0	-9.03	5.352	0.00	451.5
1342	0.0	-9.05	5.364	0.00	452.5
1345	0.2	-9.07	5.376	0.05	453.5
1348	0.2	-9.09	5.388	0.05	454.5
1351	0.0	-9.11	5.400	0.00	455.5
1354	0.0	-9.14	5.412	0.00	457.0
1357	-0.2	-9.16	5.424	-0.05	458.0
1360	0.0	-9.18	5.436	0.00	459.0
1363	-0.2	-9.20	5.448	-0.05	460.0
1366	0.0	-9.22	5.460	0.00	461.0
1369	0.0	-9.24	5.472	0.00	462.0
1372	-0.2	-9.26	5.484	-0.05	463.0
1375	-0.2	-9.28	5.496	-0.05	464.0
1378	0.0	-9.30	5.508	0.00	465.0
1381	0.2	-9.33	5.520	0.05	466.5
1384	0.0	-9.35	5.532	0.00	467.5
1387	0.0	-9.37	5.544	0.00	468.5
1390	-0.4	-9.39	5.556	-0.10	469.5
1393	-0.2	-9.41	5.568	-0.05	470.5
1396	0.2	-9.43	5.580	0.05	471.5
1399	0.0	-9.45	5.592	0.00	472.5
1402	0.0	-9.47	5.604	0.00	473.5
1405	-0.2	-9.50	5.616	-0.05	475.0
1408	0.0	-9.52	5.628	0.00	476.0
1411	-0.2	-9.54	5.640	-0.05	477.0
1414	0.2	-9.56	5.652	0.05	478.0
1417	-0.2	-9.58	5.664	-0.05	479.0
1420	-0.2	-9.60	5.676	-0.05	480.0
1423	0.0	-9.62	5.688	0.00	481.0
1426	0.0	-9.64	5.700	0.00	482.0
1429	0.2	-9.67	5.712	0.05	483.5
1432	0.0	-9.69	5.724	0.00	484.5
1435	0.0	-9.71	5.736	0.00	485.5
1438	0.0	-9.73	5.748	0.00	486.5
1441	0.0	-9.75	5.760	0.00	487.5
1444	0.0	-9.77	5.772	0.00	488.5
1447	0.2	-9.79	5.784	0.05	489.5
1450	0.0	-9.81	5.796	0.00	490.5
1453	0.0	-9.83	5.808	0.00	491.5
1456	0.2	-9.86	5.820	0.05	493.0
1459	0.0	-9.88	5.832	0.00	494.0
1462	0.2	-9.90	5.844	0.05	495.0
1465	0.2	-9.92	5.856	0.05	496.0
1468	0.2	-9.94	5.868	0.05	497.0
1471	0.0	-9.96	5.880	0.00	498.0
1474	0.0	-9.98	5.892	0.00	499.0
1477	0.0	-9.99	5.904	0.00	499.5
1480	0.0	-10.01	5.916	0.00	500.5
1483	0.2	-10.03	5.928	0.05	501.5
1486	0.0	-10.06	5.940	0.00	503.0
1489	0.2	-10.08	5.952	0.05	504.0
1492	0.0	-10.10	5.964	0.00	505.0
1495	0.0	-10.12	5.976	0.00	506.0
1498	-0.2	-10.14	5.988	-0.05	507.0
1501	0.0	-10.16	6.000	0.00	508.0
1504	-0.2	-10.18	6.012	-0.05	509.0
1507	0.2	-10.20	6.024	0.05	510.0
1510	0.0	-10.22	6.036	0.00	511.0
1513	-0.4	-10.25	6.048	-0.10	512.5
1516	0.0	-10.27	6.060	0.00	513.5
1519	0.0	-10.29	6.072	0.00	514.5
1522	0.2	-10.31	6.084	0.05	515.5
1525	0.0	-10.33	6.096	0.00	516.5
1528	0.0	-10.35	6.108	0.00	517.5
1531	0.0	-10.37	6.120	0.00	518.5
1534	0.2	-10.39	6.132	0.05	519.5
1537	-0.2	-10.41	6.144	-0.05	520.5
1540	0.0	-10.44	6.156	0.00	522.0
1543	-0.2	-10.46	6.168	-0.05	523.0
1546	0.0	-10.48	6.180	0.00	524.0
1549	0.0	-10.50	6.192	0.00	525.0
1552	0.0	-10.52	6.204	0.00	526.0
1555	0.0	-10.54	6.216	0.00	527.0
1558	-0.2	-10.56	6.228	-0.05	528.0
1561	0.0	-10.58	6.240	0.00	529.0
1564	0.0	-10.60	6.252	0.00	530.0
1567	0.0	-10.62	6.264	0.00	531.0
1570	-0.2	-10.64	6.276	-0.05	532.0
1573	-0.2	-10.67	6.288	-0.05	533.5
1576	-0.2	-10.69	6.300	-0.05	534.5
1579	0.0	-10.71	6.312	0.00	535.5
1582	0.2	-10.73	6.324	0.05	536.5
1585	0.4	-10.75	6.336	0.10	537.5
1588	0.2	-10.77	6.348	0.05	538.5
1591	0.0	-10.79	6.360	0.00	539.5
1594	0.0	-10.81	6.372	0.00	540.5
1597	0.0	-10.83	6.384	0.00	541.5
1600	0.0	-10.85	6.396	0.00	542.5
1603	0.0	-10.87	6.408	0.00	543.5
1606	0.0	-10.90	6.420	0.00	545.0
1609	0.0	-10.92	6.432	0.00	546.0
1612	-0.2	-10.94	6.444	-0.05	547.0
1615	0.0	-10.96	6.456	0.00	548.0
1618	-0.2	-10.98	6.468	-0.05	549.0
1621	0.2	-11.00	6.480	0.05	550.0
1624	0.0	-11.02	6.492	0.00	551.0
1627	0.2	-11.04	6.504	0.05	552.0
1630	0.0	-11.06	6.516	0.00	553.0
1633	0.0	-11.08	6.528	0.00	554.0
1636	-0.2	-11.10	6.540	-0.05	555.0
1639	0.0	-11.13	6.552	0.00	556.5
1642	-0.2	-11.15	6.564	-0.05	557.5
1645	-0.2	-11.17	6.576	-0.05	558.5
1648	-0.2	-11.19	6.588	-0.05	559.5
1651	0.0	-11.21	6.600	0.00	560.5
1654	0.2	-11.23	6.612	0.05	561.5
1657	-0.4	-11.25	6.624	-0.10	562.5
1660	-0.2	-11.27	6.636	-0.05	563.5
1663	0.0	-11.29	6.648	0.00	564.5
1666	0.4	-11.31	6.660	0.10	565.5
1669	0.0	-11.33	6.672	0.00	566.5
1672	0.0	-11.36	6.684	0.00	568.0
1675	0.0	-11.38	6.696	0.00	569.0
1678	0.2	-11.40	6.708	0.05	570.0
1681	-0.2	-11.42	6.720	-0.05	571.0
1684	0.0	-11.44	6.732	0.00	572.0
1687	0.0	-11.46	6.744	0.00	573.0
1690	0.0	-11.48	6.756	0.00	574.0
1693	0.2	-11.50	6.768	0.05	575.0
1696	-0.2	-11.52	6.780	-0.05	576.0
1699	0.2	-11.54	6.792	0.05	577.0
1702	0.0	-11.56	6.804	0.00	578.0
1705	0.2	-11.58	6.816	0.05	579.0
1708	0.0	-11.61	6.828	0.00	580.5
1711	-0.2	-11.63	6.840	-0.05	581.5
1714	0.0	-11.65	6.852	0.00	582.5
1717	0.0	-11.67	6.864	0.00	583.5
1720	0.0	-11.69	6.876	0.00	584.5
1723	-0.2	-11.71	6.888	-0.05	585.5
1726	-0.4	-11.73	6.900	-0.10	586.5
1729	-0.2	-11.75	6.912	-0.05	587.5
1732	0.0	-11.77	6.924	0.00	588.5
1735	-0.2	-11.79	6.936	-0.05	589.5
1738	0.0	-11.81	6.948	0.00	590.5
1741	0.2	-11.84	6.960	0.05	592.0
1744	0.0	-11.86	6.972	0.00	593.0
1747	0.2	-11.88	6.984	0.05	594.0
1750	0.0	-11.90	6.996	0.00	595.0
1753	0.2	-11.92	7.008	0.05	596.0
1756	0.0	-11.94	7.020	0.00	597.0
1759	0.0	-11.96	7.032	0.00	598.0
1762	0.0	-11.98	7.044	0.00	599.0
1765	0.0	-12.01	7.056	0.00	600.5
1768	-0.2	-12.03	7.068	-0.05	601.5
1771	0.0	-12.05	7.080	0.00	602.5
1774	0.0	-12.08	7.092	0.00	604.0
1777	0.0	-12.10	7.104	0.00	605.0
1780	0.0	-12.12	7.116	0.00	606.0
1783	-0.2	-12.14	7.128	-0.05	607.0
1786	0.0	-12.16	7.140	0.00	608.0
1789	-0.2	-12.18	7.152	-0.05	609.0
1792	0.0	-12.20	7.164	0.00	610.0
1795	0.0	-12.22	7.176	0.00	611.0
1798	0.0	-12.24	7.188	0.00	612.0
1801	0.0	-12.26	7.200	0.00	613.0
1804	0.0	-12.28	7.212	0.00	614.0
1807	0.0	-12.30	7.224	0.00	615.0
1810	0.2	-12.33	7.236	0.05	616.5
1813	0.2	-12.35	7.248	0.05	617.5
1816	0.0	-12.37	7.260	0.00	618.5
1819	0.0	-12.39	7.272	0.00	619.5
1822	0.0	-12.41	7.284	0.00	620.5
1825	-0.2	-12.43	7.296	-0.05	621.5
1828	0.0	-12.45	7.308	0.00	622.5
1831	0.0	-12.47	7.320	0.00	623.5
1834	0.0	-12.49	7.332	0.00	624.5
1837	0.0	-12.51	7.344	0.00	625.5
1840	-0.2	-12.53	7.356	-0.05	626.5
1843	0.0	-12.56	7.368	0.00	628.0
1846	0.0	-12.58	7.380	0.00	629.0
1849	0.0	-12.60	7.392	0.00	630.0
1852	0.0	-12.62	7.404	0.00	631.0
1855	0.2	-12.64	7.416	0.05	632.0
1858	0.0	-12.66	7.428	0.00	633.0
1861	0.2	-12.68	7.440	0.05	634.0
1864	0.0	-12.70	7.452	0.00	635.0
1867	0.0	-12.72	7.464	0.00	636.0
1870	-0.2	-12.74	7.476	-0.05	637.0
1873	0.2	-12.76	7.488	0.05	638.0
1876	0.0	-12.79	7.500	0.00	639.5
1879	0.0	-12.81	7.512	0.00	640.5
1882	0.0	-12.83	7.524	0.00	641.5
1885	-0.2	-12.85	7.536	-0.05	642.5
1888	0.0	-12.87	7.548	0.00	643.5
1891	-0.2	-12.89	7.560	-0.05	644.5
1894	0.0	-12.91	7.572	0.00	645.5
1897	-0.2	-12.93	7.584	-0.05	646.5
1900	0.0	-12.95	7.596	0.00	647.5
1903	0.0	-12.98	7.608	0.00	649.0
1906	-0.2	-13.00	7.620	-0.05	650.0
1909	0.0	-13.02	7.632	0.00	651.0
1912	0.0	-13.04	7.644	0.00	652.0
1915	0.0	-13.06	7.656	0.00	653.0
1918	-0.2	-13.08	7.668	-0.05	654.0
1921	0.0	-13.10	7.680	0.00	655.0
1924	0.2	-13.12	7.692	0.05	656.0
1927	0.0	-13.14	7.704	0.00	657.0
1930	-0.2	-13.16	7.716	-0.05	658.0
1933	0.0	-13.19	7.728	0.00	659.5
1936	-0.2	-13.21	7.740	-0.05	660.5
1939	0.0	-13.23	7.752	0.00	661.5
1942	-0.2	-13.25	7.764	-0.05	662.5
1945	0.0	-13.27	7.776	0.00	663.5
1948	0.2	-13.29	7.788	0.05	664.5
1951	-0.2	-13.31	7.800	-0.05	665.5
1954	0.0	-13.33	7.812	0.00	666.5
1957	0.0	-13.35	7.824	0.00	667.5
1960	0.0	-13.37	7.836	0.00	668.5
1963	0.0	-13.40	7.848	0.00	670.0
1966	0.4	-13.42	7.860	0.10	671.0
1969	0.0	-13.44	7.872	0.00	672.0
1972	-0.2	-13.46	7.884	-0.05	673.0
1975	0.0	-13.48	7.896	0.00	674.0
1978	0.2	-13.50	7.908	0.05	675.0
1981	-0.2	-13.52	7.920	-0.05	676.0
1984	0.0	-13.54	7.932	0.00	677.0
1987	0.0	-13.56	7.944	0.00	678.0
1990	-0.4	-13.59	7.956	-0.10	679.5
1993	0.0	-13.61	7.968	0.00	680.5
1996	0.0	-13.63	7.980	0.00	681.5
1999	-0.4	-13.65	7.992	-0.10	682.5
2002	0.0	-13.67	8.004	0.00	683.5
2005	0.0	-13.69	8.016	0.00	684.5
2008	-0.2	-13.71	8.028	-0.05	685.5
2011	-0.2	-13.74	8.040	-0.05	687.0
2014	0.0	-13.76	8.052	0.00	688.0
2017	0.2	-13.78	8.064	0.05	689.0
2020	0.0	-13.80	8.076	0.00	690.0
2023	0.2	-13.82	8.088	0.05	691.0
2026	-0.2	-13.84	8.100	-0.05	692.0
2029	0.2	-13.86	8.112	0.05	693.0
2032	0.0	-13.88	8.124	0.00	694.0
2035	0.2	-13.90	8.136	0.05	695.0
2038	-0.2	-13.93	8.148	-0.05	696.5
2041	0.0	-13.95	8.160	0.00	697.5
2044	0.0	-13.97	8.172	0.00	698.5
2047	0.0	-13.99	8.184	0.00	699.5
2050	0.0	-14.01	8.196	0.00	700.5
2053	0.0	-14.03	8.208	0.00	701.5
2056	0.0	-14.05	8.220	0.00	702.5
2059	0.2	-14.07	8.232	0.05	703.5
2062	0.0	-14.09	8.244	0.00	704.5
2065	0.0	-14.12	8.256	0.00	706.0
2068	0.0	-14.14	8.268	0.00	707.0
2071	0.0	-14.16	8.280	0.00	708.0
2074	0.0	-14.18	8.292	0.00	709.0
2077	0.4	-14.20	8.304	0.10	710.0
2080	0.2	-14.22	8.316	0.05	711.0
2083	0.0	-14.24	8.328	0.00	712.0
2086	0.0	-14.26	8.340	0.00	713.0
2089	0.0	-14.28	8.352	0.00	714.0
2092	0.0	-14.31	8.364	0.00	715.5
2095	-0.2	-14.33	8.376	-0.05	716.5
2098	0.2	-14.35	8.388	0.05	717.5
2101	0.0	-14.37	8.400	0.00	718.5
2104	0.0	-14.39	8.412	0.00	719.5
2107	0.0	-14.41	8.424	0.00	720.5
2110	0.0	-14.43	8.436	0.00	721.5
2113	0.0	-14.45	8.448	0.00	722.5
2116	0.0	-14.47	8.460	0.00	723.5
2119	-0.2	-14.50	8.472	-0.05	725.0
2122	0.0	-14.52	8.484	0.00	726.0
2125	0.0	-14.54	8.496	0.00	727.0
2128	0.2	-14.56	8.508	0.05	728.0
2131	0.0	-14.58	8.520	0.00	729.0
2134	0.0	-14.60	8.532	0.00	730.0
2137	0.2	-14.62	8.544	0.05	731.0
2140	-0.2	-14.64	8.556	-0.05	732.0
2143	0.0	-14.66	8.568	0.00	733.0
2146	0.0	-14.69	8.580	0.00	734.5
2149	-0.4	-14.71	8.592	-0.10	735.5
2152	0.2	-14.73	8.604	0.05	736.5
2155	0.2	-14.75	8.616	0.05	737.5
2158	0.0	-14.77	8.628	0.00	738.5
2161	0.0	-14.79	8.640	0.00	739.5
2164	0.0	-14.81	8.652	0.00	740.5
2167	0.0	-14.84	8.664	0.00	742.0
2170	0.0	-14.86	8.676	0.00	743.0
2173	0.2	-14.88	8.688	0.05	744.0
2176	0.0	-14.90	8.700	0.00	745.0
2179	0.2	-14.92	8.712	0.05	746.0
2182	0.2	-14.94	8.724	0.05	747.0
2185	0.2	-14.96	8.736	0.05	748.0
2188	0.0	-14.98	8.748	0.00	749.0
2191	0.0	-14.99	8.760	0.00	749.5
2194	-0.2	-15.01	8.772	-0.05	750.5
2197	0.0	-15.03	8.784	0.00	751.5
2200	-0.2	-15.06	8.796	-0.05	753.0
2203	0.0	-15.08	8.808	0.00	754.0
2206	0.0	-15.10	8.820	0.00	755.0
2209	0.2	-15.12	8.832	0.05	756.0
2212	0.0	-15.14	8.844	0.00	757.0
2215	-0.2	-15.16	8.856	-0.05	758.0
2218	0.0	-15.18	8.868	0.00	759.0
2221	0.0	-15.20	8.880	0.00	760.0
2224	0.0	-15.22	8.892	0.00	761.0
2227	0.0	-15.25	8.904	0.00	762.5
2230	0.4	-15.27	8.916	0.10	763.5
2233	0.0	-15.29	8.928	0.00	764.5
2236	0.0	-15.31	8.940	0.00	765.5
2239	-0.2	-15.33	8.952	-0.05	766.5
2242	0.0	-15.35	8.964	0.00	767.5
2245	-0.2	-15.37	8.976	-0.05	768.5
2248	0.0	-15.39	8.988	0.00	769.5
2251	0.0	-15.41	9.000	0.00	770.5
2254	0.0	-15.44	9.012	0.00	772.0
2257	0.0	-15.46	9.024	0.00	773.0
2260	-0.2	-15.48	9.036	-0.05	774.0
2263	0.0	-15.50	9.048	0.00	775.0
2266	0.4	-15.52	9.060	0.10	776.0
2269	0.0	-15.54	9.072	0.00	777.0
2272	0.0	-15.56	9.084	0.00	778.0
2275	0.0	-15.58	9.096	0.00	779.0
2278	0.0	-15.60	9.108	0.00	780.0
2281	0.0	-15.62	9.120	0.00	781.0
2284	-0.6	-15.65	9.132	-0.15	782.5
2287	0.0	-15.67	9.144	0.00	783.5
2290	0.0	-15.69	9.156	0.00	784.5
2293	0.0	-15.71	9.168	0.00	785.5
2296	0.0	-15.73	9.180	0.00	786.5
2299	0.0	-15.75	9.192	0.00	787.5
2302	0.2	-15.77	9.204	0.05	788.5
2305	0.0	-15.79	9.216	0.00	789.5
2308	0.0	-15.81	9.228	0.00	790.5
2311	0.0	-15.83	9.240	0.00	791.5
2314	0.2	-15.85	9.252	0.05	792.5
2317	-0.2	-15.88	9.264	-0.05	794.0
2320	0.0	-15.90	9.276	0.00	795.0
2323	0.0	-15.92	9.288	0.00	796.0
2326	0.0	-15.94	9.300	0.00	797.0
2329	-0.2	-15.96	9.312	-0.05	798.0
2332	0.0	-15.98	9.324	0.00	799.0
2335	0.2	-16.00	9.336	0.05	800.0
2338	0.0	-16.02	9.348	0.00	801.0
2341	0.0	-16.04	9.360	0.00	802.0
2344	0.0	-16.06	9.372	0.00	803.0
2347	0.0	-16.08	9.384	0.00	804.0
2350	0.0	-16.10	9.396	0.00	805.0
2353	0.0	-16.12	9.408	0.00	806.0
2356	0.0	-16.15	9.420	0.00	807.5
2359	0.0	-16.17	9.432	0.00	808.5
2362	0.0	-16.19	9.444	0.00	809.5
2365	0.0	-16.21	9.456	0.00	810.5
2368	0.0	-16.23	9.468	0.00	811.5
2371	-0.2	-16.25	9.480	-0.05	812.5
2374	-0.4	-16.27	9.492	-0.10	813.5
2377	0.0	-16.29	9.504	0.00	814.5
2380	0.0	-16.31	9.516	0.00	815.5
2383	0.0	-16.33	9.528	0.00	816.5
2386	0.0	-16.35	9.540	0.00	817.5
2389	0.0	-16.38	9.552	0.00	819.0
2392	-0.6	-16.40	9.564	-0.15	820.0
2395	0.0	-16.42	9.576	0.00	821.0
2398	0.0	-16.44	9.588	0.00	822.0
2401	0.0	-16.46	9.600	0.00	823.0
2404	-0.4	-16.48	9.612	-0.10	824.0
2407	0.0	-16.50	9.624	0.00	825.0
2410	0.0	-16.52	9.636	0.00	826.0
2413	0.0	-16.54	9.648	0.00	827.0
2416	0.0	-16.56	9.660	0.00	828.0
2419	0.2	-16.58	9.672	0.05	829.0
2422	-0.4	-16.60	9.684	-0.10	830.0
2425	0.0	-16.63	9.696	0.00	831.5
2428	-0.6	-16.65	9.708	-0.15	832.5
2431	0.2	-16.67	9.720	0.05	833.5
2434	0.0	-16.69	9.732	0.00	834.5
2437	0.0	-16.71	9.744	0.00	835.5
2440	0.0	-16.73	9.756	0.00	836.5
2443	0.0	-16.75	9.768	0.00	837.5
2446	0.0	-16.77	9.780	0.00	838.5
2449	-0.4	-16.79	9.792	-0.10	839.5
2452	0.0	-16.81	9.804	0.00	840.5
2455	0.0	-16.83	9.816	0.00	841.5
2458	0.0	-16.86	9.828	0.00	843.0
2461	-0.2	-16.87	9.840	-0.05	843.5
2464	0.0	-16.90	9.852	0.00	845.0
2467	0.2	-16.92	9.864	0.05	846.0
2470	0.4	-16.94	9.876	0.10	847.0
2473	0.0	-16.96	9.888	0.00	848.0
2476	0.0	-16.98	9.900	0.00	849.0
2479	0.0	-17.01	9.912	0.00	850.5
2482	0.0	-17.03	9.924	0.00	851.5
2485	0.2	-17.05	9.936	0.05	852.5
2488	0.0	-17.07	9.948	0.00	853.5
2491	0.0	-17.09	9.960	0.00	854.5
2494	0.2	-17.11	9.972	0.05	855.5
2497	0.2	-17.14	9.984	0.05	857.0
2500	-0.2	-17.16	9.996	-0.05	858.0
2503	-0.4	-17.18	10.008	-0.10	859.0
2506	-0.2	-17.20	10.020	-0.05	860.0
2509	0.2	-17.22	10.032	0.05	861.0
2512	0.0	-17.24	10.044	0.00	862.0
2515	0.2	-17.26	10.056	0.05	863.0
2518	0.0	-17.28	10.068	0.00	864.0
2521	0.0	-17.30	10.080	0.00	865.0
2524	0.0	-17.32	10.092	0.00	866.0
2527	0.0	-17.35	10.104	0.00	867.5
2530	0.0	-17.36	10.116	0.00	868.0
2533	0.0	-17.39	10.128	0.00	869.5
2536	-0.2	-17.41	10.140	-0.05	870.5
2539	0.0	-17.43	10.152	0.00	871.5
2542	0.0	-17.45	10.164	0.00	872.5
2545	-0.2	-17.47	10.176	-0.05	873.5
2548	0.0	-17.49	10.188	0.00	874.5
2551	0.0	-17.51	10.200	0.00	875.5
2554	0.0	-17.53	10.212	0.00	876.5
2557	-0.2	-17.55	10.224	-0.05	877.5
2560	0.2	-17.57	10.236	0.05	878.5
2563	0.0	-17.59	10.248	0.00	879.5
2566	-0.4	-17.62	10.260	-0.10	881.0
2569	0.0	-17.64	10.272	0.00	882.0
2572	0.2	-17.66	10.284	0.05	883.0
2575	-0.2	-17.68	10.296	-0.05	884.0
2578	0.0	-17.70	10.308	0.00	885.0
2581	0.0	-17.72	10.320	0.00	886.0
2584	0.0	-17.74	10.332	0.00	887.0
2587	-0.2	-17.76	10.344	-0.05	888.0
2590	0.0	-17.78	10.356	0.00	889.0
2593	0.4	-17.80	10.368	0.10	890.0
2596	0.2	-17.82	10.380	0.05	891.0
2599	0.0	-17.85	10.392	0.00	892.5
2602	0.0	-17.87	10.404	0.00	893.5
2605	0.0	-17.89	10.416	0.00	894.5
2608	0.0	-17.91	10.428	0.00	895.5
2611	0.0	-17.93	10.440	0.00	896.5
2614	0.0	-17.95	10.452	0.00	897.5
2617	-0.2	-17.97	10.464	-0.05	898.5
2620	0.2	-17.99	10.476	0.05	899.5
2623	0.0	-18.01	10.488	0.00	900.5
2626	0.2	-18.03	10.500	0.05	901.5
2629	-0.2	-18.06	10.512	-0.05	903.0
2632	0.0	-18.08	10.524	0.00	904.0
2635	0.0	-18.10	10.536	0.00	905.0
2638	0.2	-18.12	10.548	0.05	906.0
2641	0.0	-18.14	10.560	0.00	907.0
2644	0.0	-18.16	10.572	0.00	908.0
2647	-0.4	-18.18	10.584	-0.10	909.0
2650	0.0	-18.20	10.596	0.00	910.0
2653	0.0	-18.22	10.608	0.00	911.0
2656	-0.8	-18.25	10.620	-0.20	912.5
2659	0.0	-18.27	10.632	0.00	913.5
2662	-0.2	-18.29	10.644	-0.05	914.5
2665	0.0	-18.31	10.656	0.00	915.5
2668	0.0	-18.33	10.668	0.00	916.5
2671	0.2	-18.35	10.680	0.05	917.5
2674	-0.4	-18.37	10.692	-0.10	918.5
2677	0.0	-18.39	10.704	0.00	919.5
2680	0.2	-18.41	10.716	0.05	920.5
2683	0.0	-18.43	10.728	0.00	921.5
2686	0.2	-18.46	10.740	0.05	923.0
2689	0.0	-18.48	10.752	0.00	924.0
2692	0.0	-18.50	10.764	0.00	925.0
2695	0.0	-18.52	10.776	0.00	926.0
2698	-0.2	-18.54	10.788	-0.05	927.0
2701	0.2	-18.56	10.800	0.05	928.0
2704	0.0	-18.58	10.812	0.00	929.0
2707	0.0	-18.60	10.824	0.00	930.0
2710	0.4	-18.62	10.836	0.10	931.0
2713	0.0	-18.65	10.848	0.00	932.5
2716	0.0	-18.67	10.860	0.00	933.5
2719	0.0	-18.69	10.872	0.00	934.5
2722	0.0	-18.71	10.884	0.00	935.5
2725	0.0	-18.73	10.896	0.00	936.5
2728	0.0	-18.75	10.908	0.00	937.5
2731	0.0	-18.77	10.920	0.00	938.5
2734	0.0	-18.79	10.932	0.00	939.5
2737	0.0	-18.81	10.944	0.00	940.5
2740	0.0	-18.84	10.956	0.00	942.0
2743	0.0	-18.86	10.968	0.00	943.0
2746	-0.2	-18.88	10.980	-0.05	944.0
2749	0.0	-18.90	10.992	0.00	945.0
2752	0.0	-18.92	11.004	0.00	946.0
2755	0.4	-18.94	11.016	0.10	947.0
2758	0.0	-18.96	11.028	0.00	948.0
2761	0.0	-18.98	11.040	0.00	949.0
2764	0.0	-19.00	11.052	0.00	950.0
2767	0.0	-19.02	11.064	0.00	951.0
2770	0.0	-19.04	11.076	0.00	952.0
2773	-0.2	-19.06	11.088	-0.05	953.0
2776	0.2	-19.08	11.100	0.05	954.0
2779	0.0	-19.10	11.112	0.00	955.0
2782	-0.2	-19.12	11.124	-0.05	956.0
2785	0.0	-19.14	11.136	0.00	957.0
2788	0.0	-19.16	11.148	0.00	958.0
2791	0.0	-19.19	11.160	0.00	959.5
2794	0.0	-19.21	11.172	0.00	960.5
2797	0.0	-19.23	11.184	0.00	961.5
2800	0.0	-19.25	11.196	0.00	962.5
2803	-0.2	-19.27	11.208	-0.05	963.5
2806	0.0	-19.29	11.220	0.00	964.5
2809	0.0	-19.31	11.232	0.00	965.5
2812	0.0	-19.33	11.244	0.00	966.5
2815	0.0	-19.35	11.256	0.00	967.5
2818	0.0	-19.38	11.268	0.00	969.0
2821	0.0	-19.40	11.280	0.00	970.0
2824	0.0	-19.42	11.292	0.00	971.0
2827	0.0	-19.44	11.304	0.00	972.0
2830	0.0	-19.46	11.316	0.00	973.0
2833	0.0	-19.48	11.328	0.00	974.0
2836	0.0	-19.50	11.340	0.00	975.0
2839	0.2	-19.52	11.352	0.05	976.0
2842	0.0	-19.54	11.364	0.00	977.0
2845	0.2	-19.57	11.376	0.05	978.5
2848	0.0	-19.59	11.388	0.00	979.5
2851	-0.2	-19.61	11.400	-0.05	980.5
2854	0.0	-19.63	11.412	0.00	981.5
2857	0.0	-19.65	11.424	0.00	982.5
2860	-0.4	-19.67	11.436	-0.10	983.5
2863	0.2	-19.69	11.448	0.05	984.5
2866	-0.2	-19.71	11.460	-0.05	985.5
2869	0.0	-19.73	11.472	0.00	986.5
2872	0.0	-19.76	11.484	0.00	988.0
2875	0.2	-19.78	11.496	0.05	989.0
2878	0.2	-19.80	11.508	0.05	990.0
2881	-0.2	-19.82	11.520	-0.05	991.0
2884	0.2	-19.84	11.532	0.05	992.0
2887	0.0	-19.86	11.544	0.00	993.0
2890	0.0	-19.88	11.556	0.00	994.0
2893	0.2	-19.90	11.568	0.05	995.0
2896	0.4	-19.92	11.580	0.10	996.0
2899	0.0	-19.95	11.592	0.00	997.5
2902	0.0	-19.97	11.604	0.00	998.5
2905	0.4	-19.99	11.616	0.10	999.5
2908	0.2	-20.01	11.628	0.05	1000.5
2911	0.0	-20.03	11.640	0.00	1001.5
2914	-0.2	-20.05	11.652	-0.05	1002.5
2917	0.0	-20.07	11.664	0.00	1003.5
2920	-0.2	-20.09	11.676	-0.05	1004.5
2923	0.2	-20.11	11.688	0.05	1005.5
2926	-0.2	-20.14	11.700	-0.05	1007.0
2929	0.0	-20.16	11.712	0.00	1008.0
2932	-0.2	-20.18	11.724	-0.05	1009.0
2935	-0.4	-20.20	11.736	-0.10	1010.0
2938	0.0	-20.22	11.748	0.00	1011.0
2941	0.0	-20.24	11.760	0.00	1012.0
2944	0.2	-20.26	11.772	0.05	1013.0
2947	0.0	-20.28	11.784	0.00	1014.0
2950	0.2	-20.30	11.796	0.05	1015.0
2953	0.0	-20.33	11.808	0.00	1016.5
2956	0.0	-20.35	11.820	0.00	1017.5
2959	0.2	-20.37	11.832	0.05	1018.5
2962	0.6	-20.39	11.844	0.15	1019.5
2965	1.0	-20.41	11.856	0.25	1020.5
2968	2.0	-20.43	11.868	0.55	1021.5
2971	2.6	-20.45	11.880	0.70	1022.5
2974	3.4	-20.47	11.892	0.90	1023.5
2977	4.0	-20.49	11.904	1.10	1024.5
2980	4.4	-20.51	11.916	1.20	1025.5
2983	4.6	-20.53	11.928	1.25	1026.5
2986	4.6	-20.56	11.940	1.25	1028.0
2989	4.6	-20.58	11.952	1.25	1029.0
2992	4.4	-20.60	11.964	1.20	1030.0
2995	4.2	-20.62	11.976	1.15	1031.0
2998	4.0	-20.64	11.988	1.10	1032.0
3001	3.8	-20.66	12.000	1.05	1033.0
3004	3.6	-20.68	12.012	0.95	1034.0
3007	4.2	-20.70	12.024	1.15	1035.0
3010	3.8	-20.72	12.036	1.05	1036.0
3013	4.0	-20.74	12.048	1.10	1037.0
3016	5.0	-20.76	12.060	1.35	1038.0
3019	6.6	-20.78	12.072	1.80	1039.0
3022	8.8	-20.80	12.084	2.40	1040.0
3025	11.4	-20.82	12.096	3.10	1041.0
3028	14.2	-20.84	12.108	3.85	1042.0
3031	16.6	-20.86	12.120	4.50	1043.0
3034	18.8	-20.88	12.132	5.10	1044.0
3037	19.8	-20.90	12.144	5.35	1045.0
3040	20.2	-20.92	12.156	5.45	1046.0
3043	20.4	-20.94	12.168	5.50	1047.0
3046	18.4	-20.96	12.180	5.00	1048.0
3049	18.4	-20.98	12.192	5.00	1049.0
3052	18.6	-21.00	12.204	5.05	1050.0
3055	18.4	-21.02	12.216	5.00	1051.0
3058	18.6	-21.04	12.228	5.05	1052.0
3061	19.8	-21.06	12.240	5.35	1053.0
3064	21.0	-21.08	12.252	5.70	1054.0
3067	22.4	-21.11	12.264	6.05	1055.5
3070	23.2	-21.12	12.276	6.25	1056.0
3073	24.2	-21.15	12.288	6.55	1057.5
3076	24.4	-21.17	12.300	6.60	1058.5
3079	24.6	-21.19	12.312	6.65	1059.5
3082	25.0	-21.21	12.324	6.75	1060.5
3085	25.2	-21.23	12.336	6.80	1061.5
3088	26.0	-21.25	12.348	7.05	1062.5
3091	26.4	-21.27	12.360	7.15	1063.5
3094	26.4	-21.29	12.372	7.15	1064.5
3097	27.0	-21.31	12.384	7.30	1065.5
3100	27.4	-21.33	12.396	7.40	1066.5
3103	27.6	-21.35	12.408	7.45	1067.5
3106	27.4	-21.37	12.420	7.40	1068.5
3109	26.4	-21.38	12.432	7.15	1069.0
3112	23.8	-21.39	12.444	6.45	1069.5
3115	22.4	-21.39	12.456	6.05	1069.5
3118	22.0	-21.39	12.468	5.95	1069.5
3121	21.8	-21.39	12.480	5.90	1069.5
3124	21.0	-21.39	12.492	5.70	1069.5
3127	20.8	-21.39	12.504	5.60	1069.5
3130	20.6	-21.39	12.516	5.55	1069.5
3133	20.4	-21.39	12.528	5.50	1069.5
3136	20.4	-21.39	12.540	5.50	1069.5
3137	20.2	-21.39	12.544	5.45	1069.5