File: results/youngs-modulus/2025-04-15/inconclusives/pf11lt02.csv
sep=
pf11lt02

System Information:
IntelliMESUR Version: 2.2.1
Test Frame Model: F505
Test Frame Serial Number: 4418651
Test Frame Capacity: 500 lbF / 2.2 kN
Test Frame Firmware Version: 1.00.14
Force Sensor Model: FS05-100
Force Sensor Capacity: 500 N
Force Sensor Resolution: 0.2 N
Force Sensor Serial Number: 4425350
Calibration Date: Apr 29, 2024
Calibration Due Date: Apr 29, 2025

Reading	Load [N]	Distance [mm]	Time [s]	Stress [MPa]	Strain [%]
1	0.0	-0.01	0.000	0.00	0.4
4	0.2	-0.01	0.012	0.04	0.4
7	0.2	-0.01	0.024	0.04	0.4
10	0.0	-0.01	0.036	0.00	0.4
13	0.0	-0.01	0.048	0.00	0.4
16	0.0	-0.01	0.060	0.00	0.4
19	0.0	-0.01	0.072	0.00	0.4
22	0.0	-0.01	0.084	0.00	0.4
25	0.2	-0.01	0.096	0.04	0.4
28	-0.2	-0.01	0.108	-0.04	0.4
31	-0.2	-0.01	0.120	-0.04	0.4
34	0.2	-0.01	0.132	0.04	0.4
37	0.2	-0.01	0.144	0.04	0.4
40	0.0	-0.01	0.156	0.00	0.4
43	-0.2	-0.01	0.168	-0.04	0.4
46	0.0	-0.01	0.180	0.00	0.4
49	0.0	-0.02	0.192	0.00	0.6
52	0.0	-0.04	0.204	0.00	1.4
55	0.0	-0.06	0.216	0.00	2.0
58	0.0	-0.08	0.228	0.00	2.6
61	-0.2	-0.10	0.240	-0.04	3.2
64	0.0	-0.12	0.252	0.00	4.0
67	0.0	-0.14	0.264	0.00	4.6
70	-0.2	-0.17	0.276	-0.04	5.6
73	0.0	-0.19	0.288	0.00	6.2
76	0.0	-0.21	0.300	0.00	6.8
79	0.0	-0.22	0.312	0.00	7.2
82	-0.2	-0.24	0.324	-0.04	7.8
85	0.0	-0.26	0.336	0.00	8.6
88	0.0	-0.28	0.348	0.00	9.2
91	0.0	-0.30	0.360	0.00	9.8
94	0.0	-0.32	0.372	0.00	10.4
97	-0.2	-0.35	0.384	-0.04	11.4
100	0.4	-0.37	0.396	0.08	12.2
103	-0.2	-0.39	0.408	-0.04	12.8
106	0.0	-0.41	0.420	0.00	13.4
109	0.2	-0.43	0.432	0.04	14.0
112	-0.2	-0.45	0.444	-0.04	14.8
115	0.0	-0.47	0.456	0.00	15.4
118	-0.2	-0.49	0.468	-0.04	16.0
121	0.2	-0.51	0.480	0.04	16.8
124	-0.4	-0.54	0.492	-0.08	17.8
127	0.0	-0.56	0.504	0.00	18.4
130	0.2	-0.58	0.516	0.04	19.0
133	0.0	-0.60	0.528	0.00	19.6
136	0.0	-0.62	0.540	0.00	20.4
139	0.0	-0.64	0.552	0.00	21.0
142	0.0	-0.66	0.564	0.00	21.6
145	0.0	-0.68	0.576	0.00	22.2
148	0.0	-0.70	0.588	0.00	23.0
151	-0.2	-0.72	0.600	-0.04	23.6
154	0.0	-0.74	0.612	0.00	24.2
157	0.0	-0.77	0.624	0.00	25.2
160	0.2	-0.79	0.636	0.04	26.0
163	-0.2	-0.81	0.648	-0.04	26.6
166	0.0	-0.83	0.660	0.00	27.2
169	0.0	-0.85	0.672	0.00	27.8
172	0.0	-0.87	0.684	0.00	28.6
175	0.0	-0.89	0.696	0.00	29.2
178	0.0	-0.91	0.708	0.00	29.8
181	0.0	-0.93	0.720	0.00	30.4
184	0.0	-0.95	0.732	0.00	31.2
187	0.0	-0.97	0.744	0.00	31.8
190	0.0	-1.00	0.756	0.00	32.8
193	-0.2	-1.02	0.768	-0.04	33.4
196	0.0	-1.04	0.780	0.00	34.0
199	0.0	-1.06	0.792	0.00	34.8
202	0.2	-1.08	0.804	0.04	35.4
205	0.2	-1.10	0.816	0.04	36.0
208	0.2	-1.12	0.828	0.04	36.8
211	-0.2	-1.14	0.840	-0.04	37.4
214	0.0	-1.16	0.852	0.00	38.0
217	0.0	-1.18	0.864	0.00	38.6
220	-0.2	-1.22	0.876	-0.04	40.0
223	0.0	-1.24	0.888	0.00	40.6
226	0.0	-1.26	0.900	0.00	41.4
229	0.0	-1.28	0.912	0.00	42.0
232	-0.2	-1.30	0.924	-0.04	42.6
235	0.0	-1.32	0.936	0.00	43.2
238	0.0	-1.34	0.948	0.00	44.0
241	0.0	-1.36	0.960	0.00	44.6
244	0.0	-1.38	0.972	0.00	45.2
247	0.0	-1.40	0.984	0.00	46.0
250	0.0	-1.43	0.996	0.00	46.8
253	0.0	-1.45	1.008	0.00	47.6
256	0.0	-1.47	1.020	0.00	48.2
259	-0.2	-1.49	1.032	-0.04	48.8
262	0.0	-1.51	1.044	0.00	49.6
265	-0.4	-1.53	1.056	-0.08	50.2
268	0.0	-1.55	1.068	0.00	50.8
271	0.0	-1.57	1.080	0.00	51.4
274	0.0	-1.59	1.092	0.00	52.2
277	0.0	-1.61	1.104	0.00	52.8
280	-0.2	-1.63	1.116	-0.04	53.4
283	-0.4	-1.65	1.128	-0.08	54.0
286	0.4	-1.68	1.140	0.08	55.0
289	0.4	-1.70	1.152	0.08	55.8
292	0.0	-1.72	1.164	0.00	56.4
295	0.0	-1.74	1.176	0.00	57.0
298	0.0	-1.76	1.188	0.00	57.8
301	0.0	-1.78	1.200	0.00	58.4
304	0.2	-1.80	1.212	0.04	59.0
307	0.0	-1.82	1.224	0.00	59.6
310	0.0	-1.84	1.236	0.00	60.4
313	0.0	-1.86	1.248	0.00	61.0
316	0.2	-1.88	1.260	0.04	61.6
319	0.0	-1.91	1.272	0.00	62.6
322	0.2	-1.93	1.284	0.04	63.2
325	0.0	-1.95	1.296	0.00	64.0
328	0.4	-1.97	1.308	0.08	64.6
331	0.2	-1.99	1.320	0.04	65.2
334	0.0	-2.01	1.332	0.00	66.0
337	0.0	-2.03	1.344	0.00	66.6
340	0.0	-2.05	1.356	0.00	67.2
343	-0.2	-2.07	1.368	-0.04	67.8
346	0.0	-2.09	1.380	0.00	68.6
349	0.2	-2.11	1.392	0.04	69.2
352	0.0	-2.13	1.404	0.00	69.8
355	0.0	-2.16	1.416	0.00	70.8
358	0.0	-2.18	1.428	0.00	71.4
361	-0.2	-2.20	1.440	-0.04	72.2
364	0.0	-2.21	1.452	0.00	72.4
367	0.0	-2.23	1.464	0.00	73.2
370	0.0	-2.25	1.476	0.00	73.8
373	0.0	-2.27	1.488	0.00	74.4
376	0.0	-2.29	1.500	0.00	75.0
379	0.0	-2.31	1.512	0.00	75.8
382	-0.2	-2.33	1.524	-0.04	76.4
385	0.2	-2.35	1.536	0.04	77.0
388	0.0	-2.37	1.548	0.00	77.8
391	-0.4	-2.39	1.560	-0.08	78.4
394	0.0	-2.42	1.572	0.00	79.4
397	0.0	-2.44	1.584	0.00	80.0
400	0.0	-2.46	1.596	0.00	80.6
403	0.0	-2.48	1.608	0.00	81.4
406	0.2	-2.50	1.620	0.04	82.0
409	0.0	-2.52	1.632	0.00	82.6
412	0.2	-2.54	1.644	0.04	83.2
415	0.0	-2.56	1.656	0.00	84.0
418	0.0	-2.58	1.668	0.00	84.6
421	-0.2	-2.60	1.680	-0.04	85.2
424	0.0	-2.62	1.692	0.00	86.0
427	0.0	-2.65	1.704	0.00	86.8
430	0.0	-2.67	1.716	0.00	87.6
433	0.0	-2.69	1.728	0.00	88.2
436	0.2	-2.71	1.740	0.04	88.8
439	0.0	-2.73	1.752	0.00	89.6
442	0.0	-2.75	1.764	0.00	90.2
445	0.2	-2.77	1.776	0.04	90.8
448	0.0	-2.79	1.788	0.00	91.4
451	-0.4	-2.81	1.800	-0.08	92.2
454	0.0	-2.84	1.812	0.00	93.2
457	0.2	-2.85	1.824	0.04	93.4
460	0.0	-2.88	1.836	0.00	94.4
463	0.0	-2.90	1.848	0.00	95.0
466	0.0	-2.92	1.860	0.00	95.8
469	-0.2	-2.94	1.872	-0.04	96.4
472	0.0	-2.96	1.884	0.00	97.0
475	0.0	-2.98	1.896	0.00	97.8
478	0.0	-3.00	1.908	0.00	98.4
481	0.0	-3.02	1.920	0.00	99.0
484	0.0	-3.04	1.932	0.00	99.6
487	0.2	-3.07	1.944	0.04	100.6
490	0.0	-3.09	1.956	0.00	101.4
493	0.0	-3.11	1.968	0.00	102.0
496	0.2	-3.13	1.980	0.04	102.6
499	0.0	-3.15	1.992	0.00	103.2
502	0.2	-3.17	2.004	0.04	104.0
505	0.0	-3.19	2.016	0.00	104.6
508	-0.2	-3.22	2.028	-0.04	105.6
511	0.0	-3.24	2.040	0.00	106.2
514	0.2	-3.26	2.052	0.04	106.8
517	0.2	-3.29	2.064	0.04	107.8
520	0.2	-3.31	2.076	0.04	108.6
523	0.0	-3.33	2.088	0.00	109.2
526	-0.4	-3.35	2.100	-0.08	109.8
529	0.0	-3.37	2.112	0.00	110.4
532	0.0	-3.39	2.124	0.00	111.2
535	0.0	-3.41	2.136	0.00	111.8
538	0.0	-3.43	2.148	0.00	112.4
541	0.0	-3.45	2.160	0.00	113.2
544	-0.2	-3.47	2.172	-0.04	113.8
547	0.2	-3.50	2.184	0.04	114.8
550	0.2	-3.52	2.196	0.04	115.4
553	0.0	-3.54	2.208	0.00	116.0
556	0.2	-3.56	2.220	0.04	116.8
559	-0.2	-3.58	2.232	-0.04	117.4
562	0.0	-3.60	2.244	0.00	118.0
565	0.0	-3.62	2.256	0.00	118.6
568	0.0	-3.64	2.268	0.00	119.4
571	-0.4	-3.66	2.280	-0.08	120.0
574	0.0	-3.69	2.292	0.00	121.0
577	0.2	-3.71	2.304	0.04	121.6
580	0.0	-3.73	2.316	0.00	122.2
583	-0.4	-3.75	2.328	-0.08	123.0
586	-0.2	-3.77	2.340	-0.04	123.6
589	0.0	-3.79	2.352	0.00	124.2
592	0.0	-3.81	2.364	0.00	125.0
595	0.0	-3.83	2.376	0.00	125.6
598	0.0	-3.85	2.388	0.00	126.2
601	0.0	-3.88	2.400	0.00	127.2
604	0.0	-3.90	2.412	0.00	127.8
607	-0.2	-3.92	2.424	-0.04	128.6
610	0.0	-3.94	2.436	0.00	129.2
613	0.0	-3.96	2.448	0.00	129.8
616	0.0	-3.98	2.460	0.00	130.4
619	0.0	-4.00	2.472	0.00	131.2
622	0.0	-4.02	2.484	0.00	131.8
625	0.0	-4.05	2.496	0.00	132.8
628	0.2	-4.07	2.508	0.04	133.4
631	-0.2	-4.09	2.520	-0.04	134.0
634	0.0	-4.11	2.532	0.00	134.8
637	0.0	-4.13	2.544	0.00	135.4
640	0.0	-4.15	2.556	0.00	136.0
643	0.0	-4.17	2.568	0.00	136.8
646	0.2	-4.19	2.580	0.04	137.4
649	0.2	-4.21	2.592	0.04	138.0
652	0.0	-4.24	2.604	0.00	139.0
655	0.0	-4.26	2.616	0.00	139.6
658	0.2	-4.28	2.628	0.04	140.4
661	0.0	-4.30	2.640	0.00	141.0
664	0.0	-4.32	2.652	0.00	141.6
667	0.0	-4.34	2.664	0.00	142.2
670	-0.2	-4.36	2.676	-0.04	143.0
673	0.0	-4.38	2.688	0.00	143.6
676	0.0	-4.40	2.700	0.00	144.2
679	0.0	-4.43	2.712	0.00	145.2
682	0.0	-4.45	2.724	0.00	146.0
685	0.0	-4.47	2.736	0.00	146.6
688	0.0	-4.49	2.748	0.00	147.2
691	0.0	-4.51	2.760	0.00	147.8
694	0.0	-4.53	2.772	0.00	148.6
697	0.0	-4.55	2.784	0.00	149.2
700	0.0	-4.57	2.796	0.00	149.8
703	0.2	-4.59	2.808	0.04	150.4
706	0.0	-4.62	2.820	0.00	151.4
709	0.2	-4.64	2.832	0.04	152.2
712	-0.2	-4.66	2.844	-0.04	152.8
715	0.0	-4.68	2.856	0.00	153.4
718	0.0	-4.70	2.868	0.00	154.0
721	0.0	-4.72	2.880	0.00	154.8
724	0.0	-4.74	2.892	0.00	155.4
727	-0.2	-4.76	2.904	-0.04	156.0
730	0.0	-4.78	2.916	0.00	156.8
733	0.0	-4.81	2.928	0.00	157.8
736	0.2	-4.83	2.940	0.04	158.4
739	-0.2	-4.85	2.952	-0.04	159.0
742	0.0	-4.87	2.964	0.00	159.6
745	-0.4	-4.89	2.976	-0.08	160.4
748	0.0	-4.91	2.988	0.00	161.0
751	0.0	-4.93	3.000	0.00	161.6
754	0.2	-4.95	3.012	0.04	162.2
757	0.2	-4.97	3.024	0.04	163.0
760	0.0	-5.00	3.036	0.00	164.0
763	0.0	-5.02	3.048	0.00	164.6
766	-0.2	-5.04	3.060	-0.04	165.2
769	0.0	-5.06	3.072	0.00	166.0
772	0.2	-5.08	3.084	0.04	166.6
775	0.0	-5.10	3.096	0.00	167.2
778	0.0	-5.12	3.108	0.00	167.8
781	0.0	-5.14	3.120	0.00	168.6
784	0.0	-5.16	3.132	0.00	169.2
787	-0.2	-5.19	3.144	-0.04	170.2
790	-0.2	-5.21	3.156	-0.04	170.8
793	-0.2	-5.23	3.168	-0.04	171.4
796	-0.2	-5.25	3.180	-0.04	172.2
799	0.0	-5.27	3.192	0.00	172.8
802	0.0	-5.29	3.204	0.00	173.4
805	0.0	-5.31	3.216	0.00	174.0
808	0.0	-5.33	3.228	0.00	174.8
811	0.0	-5.35	3.240	0.00	175.4
814	0.0	-5.38	3.252	0.00	176.4
817	0.0	-5.40	3.264	0.00	177.0
820	0.0	-5.42	3.276	0.00	177.8
823	0.0	-5.44	3.288	0.00	178.4
826	0.0	-5.46	3.300	0.00	179.0
829	0.0	-5.48	3.312	0.00	179.6
832	0.0	-5.50	3.324	0.00	180.4
835	0.0	-5.52	3.336	0.00	181.0
838	0.0	-5.54	3.348	0.00	181.6
841	-0.2	-5.57	3.360	-0.04	182.6
844	-0.2	-5.59	3.372	-0.04	183.2
847	0.0	-5.61	3.384	0.00	184.0
850	0.0	-5.63	3.396	0.00	184.6
853	0.0	-5.65	3.408	0.00	185.2
856	0.0	-5.67	3.420	0.00	186.0
859	0.0	-5.69	3.432	0.00	186.6
862	0.2	-5.71	3.444	0.04	187.2
865	0.4	-5.73	3.456	0.08	187.8
868	0.0	-5.75	3.468	0.00	188.6
871	0.2	-5.77	3.480	0.04	189.2
874	0.0	-5.80	3.492	0.00	190.2
877	0.2	-5.82	3.504	0.04	190.8
880	-0.2	-5.84	3.516	-0.04	191.4
883	0.0	-5.86	3.528	0.00	192.2
886	0.0	-5.88	3.540	0.00	192.8
889	0.0	-5.90	3.552	0.00	193.4
892	0.0	-5.92	3.564	0.00	194.0
895	0.0	-5.94	3.576	0.00	194.8
898	0.0	-5.96	3.588	0.00	195.4
901	0.0	-5.98	3.600	0.00	196.0
904	0.0	-6.00	3.612	0.00	196.8
907	0.0	-6.03	3.624	0.00	197.8
910	0.0	-6.05	3.636	0.00	198.4
913	-0.2	-6.07	3.648	-0.04	199.0
916	0.0	-6.09	3.660	0.00	199.6
919	0.2	-6.11	3.672	0.04	200.4
922	0.0	-6.13	3.684	0.00	201.0
925	-0.2	-6.15	3.696	-0.04	201.6
928	0.4	-6.17	3.708	0.08	202.2
931	0.0	-6.19	3.720	0.00	203.0
934	0.0	-6.20	3.732	0.00	203.2
937	0.0	-6.22	3.744	0.00	204.0
940	0.4	-6.25	3.756	0.08	205.0
943	0.0	-6.27	3.768	0.00	205.6
946	0.0	-6.29	3.780	0.00	206.2
949	-0.2	-6.31	3.792	-0.04	206.8
952	0.0	-6.33	3.804	0.00	207.6
955	0.0	-6.35	3.816	0.00	208.2
958	0.0	-6.37	3.828	0.00	208.8
961	-0.2	-6.39	3.840	-0.04	209.6
964	0.0	-6.41	3.852	0.00	210.2
967	0.0	-6.43	3.864	0.00	210.8
970	0.2	-6.45	3.876	0.04	211.4
973	0.0	-6.47	3.888	0.00	212.2
976	-0.2	-6.50	3.900	-0.04	213.2
979	0.0	-6.52	3.912	0.00	213.8
982	-0.2	-6.54	3.924	-0.04	214.4
985	0.0	-6.56	3.936	0.00	215.0
988	0.0	-6.58	3.948	0.00	215.8
991	-0.2	-6.60	3.960	-0.04	216.4
994	0.0	-6.62	3.972	0.00	217.0
997	0.2	-6.64	3.984	0.04	217.8
1000	0.0	-6.66	3.996	0.00	218.4
1003	0.0	-6.68	4.008	0.00	219.0
1006	0.0	-6.70	4.020	0.00	219.6
1009	0.0	-6.73	4.032	0.00	220.6
1012	0.0	-6.74	4.044	0.00	221.0
1015	0.0	-6.77	4.056	0.00	222.0
1018	0.2	-6.79	4.068	0.04	222.6
1021	0.0	-6.81	4.080	0.00	223.2
1024	0.2	-6.83	4.092	0.04	224.0
1027	0.2	-6.85	4.104	0.04	224.6
1030	0.0	-6.87	4.116	0.00	225.2
1033	0.0	-6.89	4.128	0.00	226.0
1036	0.0	-6.91	4.140	0.00	226.6
1039	0.0	-6.93	4.152	0.00	227.2
1042	0.0	-6.95	4.164	0.00	227.8
1045	0.2	-6.97	4.176	0.04	228.6
1048	0.0	-7.00	4.188	0.00	229.6
1051	0.0	-7.02	4.200	0.00	230.2
1054	0.0	-7.04	4.212	0.00	230.8
1057	0.0	-7.06	4.224	0.00	231.4
1060	0.0	-7.08	4.236	0.00	232.2
1063	-0.2	-7.10	4.248	-0.04	232.8
1066	0.0	-7.12	4.260	0.00	233.4
1069	0.0	-7.14	4.272	0.00	234.0
1072	0.0	-7.16	4.284	0.00	234.8
1075	0.0	-7.18	4.296	0.00	235.4
1078	0.0	-7.21	4.308	0.00	236.4
1081	0.0	-7.23	4.320	0.00	237.0
1084	0.0	-7.26	4.332	0.00	238.0
1087	-0.2	-7.28	4.344	-0.04	238.6
1090	0.2	-7.30	4.356	0.04	239.4
1093	0.0	-7.32	4.368	0.00	240.0
1096	0.0	-7.34	4.380	0.00	240.6
1099	0.0	-7.36	4.392	0.00	241.4
1102	0.0	-7.38	4.404	0.00	242.0
1105	0.0	-7.40	4.416	0.00	242.6
1108	0.0	-7.42	4.428	0.00	243.2
1111	-0.2	-7.44	4.440	-0.04	244.0
1114	0.0	-7.46	4.452	0.00	244.6
1117	0.2	-7.49	4.464	0.04	245.6
1120	0.0	-7.51	4.476	0.00	246.2
1123	0.0	-7.53	4.488	0.00	246.8
1126	-0.2	-7.55	4.500	-0.04	247.6
1129	0.0	-7.57	4.512	0.00	248.2
1132	0.2	-7.59	4.524	0.04	248.8
1135	0.0	-7.61	4.536	0.00	249.6
1138	0.0	-7.63	4.548	0.00	250.2
1141	-0.2	-7.65	4.560	-0.04	250.8
1144	-0.2	-7.67	4.572	-0.04	251.4
1147	0.0	-7.69	4.584	0.00	252.2
1150	0.0	-7.71	4.596	0.00	252.8
1153	0.0	-7.73	4.608	0.00	253.4
1156	0.2	-7.76	4.620	0.04	254.4
1159	0.0	-7.78	4.632	0.00	255.0
1162	0.0	-7.80	4.644	0.00	255.8
1165	0.0	-7.82	4.656	0.00	256.4
1168	0.0	-7.84	4.668	0.00	257.0
1171	0.0	-7.86	4.680	0.00	257.8
1174	-0.2	-7.88	4.692	-0.04	258.4
1177	-0.2	-7.90	4.704	-0.04	259.0
1180	0.0	-7.92	4.716	0.00	259.6
1183	-0.2	-7.94	4.728	-0.04	260.4
1186	0.0	-7.97	4.740	0.00	261.4
1189	0.0	-7.99	4.752	0.00	262.0
1192	0.0	-8.01	4.764	0.00	262.6
1195	0.0	-8.03	4.776	0.00	263.2
1198	0.0	-8.05	4.788	0.00	264.0
1201	0.0	-8.07	4.800	0.00	264.6
1204	-0.2	-8.09	4.812	-0.04	265.2
1207	0.0	-8.11	4.824	0.00	266.0
1210	0.0	-8.13	4.836	0.00	266.6
1213	0.0	-8.15	4.848	0.00	267.2
1216	0.2	-8.17	4.860	0.04	267.8
1219	0.0	-8.20	4.872	0.00	268.8
1222	0.0	-8.22	4.884	0.00	269.6
1225	0.0	-8.24	4.896	0.00	270.2
1228	0.0	-8.26	4.908	0.00	270.8
1231	-0.2	-8.28	4.920	-0.04	271.4
1234	0.0	-8.30	4.932	0.00	272.2
1237	0.0	-8.32	4.944	0.00	272.8
1240	0.2	-8.34	4.956	0.04	273.4
1243	0.0	-8.36	4.968	0.00	274.0
1246	0.0	-8.39	4.980	0.00	275.0
1249	0.0	-8.41	4.992	0.00	275.8
1252	-0.4	-8.43	5.004	-0.08	276.4
1255	0.0	-8.45	5.016	0.00	277.0
1258	0.0	-8.47	5.028	0.00	277.8
1261	0.0	-8.49	5.040	0.00	278.4
1264	0.2	-8.51	5.052	0.04	279.0
1267	-0.4	-8.53	5.064	-0.08	279.6
1270	0.0	-8.55	5.076	0.00	280.4
1273	0.0	-8.58	5.088	0.00	281.4
1276	-0.2	-8.60	5.100	-0.04	282.0
1279	-0.2	-8.62	5.112	-0.04	282.6
1282	0.0	-8.64	5.124	0.00	283.2
1285	-0.2	-8.66	5.136	-0.04	284.0
1288	0.0	-8.68	5.148	0.00	284.6
1291	0.0	-8.70	5.160	0.00	285.2
1294	0.0	-8.72	5.172	0.00	286.0
1297	0.0	-8.74	5.184	0.00	286.6
1300	0.2	-8.77	5.196	0.04	287.6
1303	0.0	-8.79	5.208	0.00	288.2
1306	0.0	-8.81	5.220	0.00	288.8
1309	0.0	-8.83	5.232	0.00	289.6
1312	0.0	-8.85	5.244	0.00	290.2
1315	-0.2	-8.87	5.256	-0.04	290.8
1318	-0.2	-8.89	5.268	-0.04	291.4
1321	0.0	-8.91	5.280	0.00	292.2
1324	0.2	-8.93	5.292	0.04	292.8
1327	0.2	-8.96	5.304	0.04	293.8
1330	0.2	-8.98	5.316	0.04	294.4
1333	0.0	-9.00	5.328	0.00	295.0
1336	0.0	-9.02	5.340	0.00	295.8
1339	0.2	-9.04	5.352	0.04	296.4
1342	-0.2	-9.06	5.364	-0.04	297.0
1345	0.0	-9.08	5.376	0.00	297.8
1348	0.0	-9.10	5.388	0.00	298.4
1351	0.0	-9.12	5.400	0.00	299.0
1354	0.0	-9.15	5.412	0.00	300.0
1357	0.0	-9.17	5.424	0.00	300.6
1360	0.0	-9.19	5.436	0.00	301.4
1363	-0.2	-9.21	5.448	-0.04	302.0
1366	-0.2	-9.23	5.460	-0.04	302.6
1369	0.2	-9.25	5.472	0.04	303.2
1372	0.0	-9.27	5.484	0.00	304.0
1375	-0.2	-9.29	5.496	-0.04	304.6
1378	0.0	-9.31	5.508	0.00	305.2
1381	0.0	-9.34	5.520	0.00	306.2
1384	0.0	-9.36	5.532	0.00	306.8
1387	0.0	-9.38	5.544	0.00	307.6
1390	0.0	-9.40	5.556	0.00	308.2
1393	-0.4	-9.42	5.568	-0.08	308.8
1396	0.0	-9.44	5.580	0.00	309.6
1399	0.0	-9.46	5.592	0.00	310.2
1402	0.0	-9.48	5.604	0.00	310.8
1405	0.0	-9.50	5.616	0.00	311.4
1408	0.0	-9.53	5.628	0.00	312.4
1411	0.0	-9.55	5.640	0.00	313.2
1414	0.0	-9.57	5.652	0.00	313.8
1417	0.0	-9.59	5.664	0.00	314.4
1420	0.0	-9.61	5.676	0.00	315.0
1423	0.0	-9.63	5.688	0.00	315.8
1426	0.0	-9.65	5.700	0.00	316.4
1429	0.0	-9.67	5.712	0.00	317.0
1432	0.0	-9.69	5.724	0.00	317.8
1435	0.2	-9.72	5.736	0.04	318.6
1438	0.0	-9.74	5.748	0.00	319.4
1441	-0.4	-9.76	5.760	-0.08	320.0
1444	0.0	-9.78	5.772	0.00	320.6
1447	0.0	-9.80	5.784	0.00	321.4
1450	0.0	-9.82	5.796	0.00	322.0
1453	0.2	-9.84	5.808	0.04	322.6
1456	0.0	-9.87	5.820	0.00	323.6
1459	0.2	-9.89	5.832	0.04	324.2
1462	0.2	-9.91	5.844	0.04	325.0
1465	-0.2	-9.93	5.856	-0.04	325.6
1468	0.0	-9.95	5.868	0.00	326.2
1471	0.0	-9.97	5.880	0.00	326.8
1474	0.0	-9.99	5.892	0.00	327.6
1477	-0.2	-10.01	5.904	-0.04	328.2
1480	0.0	-10.03	5.916	0.00	328.8
1483	0.2	-10.06	5.928	0.04	329.8
1486	-0.4	-10.08	5.940	-0.08	330.4
1489	0.0	-10.10	5.952	0.00	331.2
1492	0.0	-10.12	5.964	0.00	331.8
1495	-0.4	-10.14	5.976	-0.08	332.4
1498	0.2	-10.16	5.988	0.04	333.2
1501	0.2	-10.18	6.000	0.04	333.8
1504	0.0	-10.20	6.012	0.00	334.4
1507	-0.2	-10.21	6.024	-0.04	334.8
1510	-0.2	-10.24	6.036	-0.04	335.8
1513	0.6	-10.26	6.048	0.12	336.4
1516	-0.2	-10.28	6.060	-0.04	337.0
1519	0.0	-10.30	6.072	0.00	337.8
1522	-0.2	-10.32	6.084	-0.04	338.4
1525	0.0	-10.34	6.096	0.00	339.0
1528	0.0	-10.36	6.108	0.00	339.6
1531	0.0	-10.38	6.120	0.00	340.4
1534	-0.4	-10.40	6.132	-0.08	341.0
1537	-0.2	-10.42	6.144	-0.04	341.6
1540	0.0	-10.45	6.156	0.00	342.6
1543	0.0	-10.47	6.168	0.00	343.2
1546	0.0	-10.49	6.180	0.00	344.0
1549	0.4	-10.51	6.192	0.08	344.6
1552	0.2	-10.53	6.204	0.04	345.2
1555	0.0	-10.55	6.216	0.00	346.0
1558	0.2	-10.57	6.228	0.04	346.6
1561	0.0	-10.59	6.240	0.00	347.2
1564	-0.4	-10.61	6.252	-0.08	347.8
1567	0.0	-10.63	6.264	0.00	348.6
1570	0.0	-10.66	6.276	0.00	349.6
1573	0.2	-10.68	6.288	0.04	350.2
1576	0.0	-10.70	6.300	0.00	350.8
1579	0.0	-10.72	6.312	0.00	351.4
1582	0.0	-10.74	6.324	0.00	352.2
1585	-0.2	-10.76	6.336	-0.04	352.8
1588	0.2	-10.78	6.348	0.04	353.4
1591	0.0	-10.80	6.360	0.00	354.0
1594	0.0	-10.82	6.372	0.00	354.8
1597	0.0	-10.84	6.384	0.00	355.4
1600	-0.2	-10.86	6.396	-0.04	356.0
1603	0.0	-10.89	6.408	0.00	357.0
1606	0.0	-10.91	6.420	0.00	357.8
1609	-0.4	-10.93	6.432	-0.08	358.4
1612	0.2	-10.95	6.444	0.04	359.0
1615	0.2	-10.97	6.456	0.04	359.6
1618	-0.2	-10.99	6.468	-0.04	360.4
1621	0.2	-11.01	6.480	0.04	361.0
1624	0.0	-11.03	6.492	0.00	361.6
1627	-0.2	-11.05	6.504	-0.04	362.2
1630	-0.2	-11.08	6.516	-0.04	363.2
1633	-0.2	-11.10	6.528	-0.04	364.0
1636	0.0	-11.12	6.540	0.00	364.6
1639	-0.2	-11.14	6.552	-0.04	365.2
1642	0.0	-11.16	6.564	0.00	366.0
1645	0.0	-11.18	6.576	0.00	366.6
1648	0.0	-11.20	6.588	0.00	367.2
1651	0.0	-11.22	6.600	0.00	367.8
1654	0.0	-11.24	6.612	0.00	368.6
1657	0.0	-11.26	6.624	0.00	369.2
1660	0.0	-11.28	6.636	0.00	369.8
1663	0.0	-11.30	6.648	0.00	370.4
1666	0.0	-11.33	6.660	0.00	371.4
1669	0.2	-11.35	6.672	0.04	372.2
1672	0.0	-11.37	6.684	0.00	372.8
1675	-0.2	-11.39	6.696	-0.04	373.4
1678	0.0	-11.41	6.708	0.00	374.0
1681	0.0	-11.43	6.720	0.00	374.8
1684	-0.2	-11.45	6.732	-0.04	375.4
1687	0.0	-11.47	6.744	0.00	376.0
1690	-0.2	-11.49	6.756	-0.04	376.8
1693	0.0	-11.51	6.768	0.00	377.4
1696	0.0	-11.53	6.780	0.00	378.0
1699	0.0	-11.56	6.792	0.00	379.0
1702	0.4	-11.58	6.804	0.08	379.6
1705	0.2	-11.60	6.816	0.04	380.4
1708	-0.2	-11.62	6.828	-0.04	381.0
1711	0.0	-11.64	6.840	0.00	381.6
1714	-0.2	-11.66	6.852	-0.04	382.2
1717	0.0	-11.68	6.864	0.00	383.0
1720	0.0	-11.70	6.876	0.00	383.6
1723	0.0	-11.72	6.888	0.00	384.2
1726	0.0	-11.74	6.900	0.00	385.0
1729	0.0	-11.76	6.912	0.00	385.6
1732	0.0	-11.79	6.924	0.00	386.6
1735	0.0	-11.81	6.936	0.00	387.2
1738	0.0	-11.83	6.948	0.00	387.8
1741	0.2	-11.85	6.960	0.04	388.6
1744	-0.2	-11.87	6.972	-0.04	389.2
1747	-0.4	-11.89	6.984	-0.08	389.8
1750	0.0	-11.91	6.996	0.00	390.4
1753	0.0	-11.93	7.008	0.00	391.2
1756	0.0	-11.95	7.020	0.00	391.8
1759	-0.2	-11.97	7.032	-0.04	392.4
1762	-0.4	-11.99	7.044	-0.08	393.2
1765	0.0	-12.01	7.056	0.00	393.8
1768	0.2	-12.04	7.068	0.04	394.8
1771	0.2	-12.06	7.080	0.04	395.4
1774	0.0	-12.08	7.092	0.00	396.0
1777	0.0	-12.10	7.104	0.00	396.8
1780	0.2	-12.12	7.116	0.04	397.4
1783	0.2	-12.14	7.128	0.04	398.0
1786	0.0	-12.16	7.140	0.00	398.6
1789	0.0	-12.18	7.152	0.00	399.4
1792	0.0	-12.21	7.164	0.00	400.4
1795	-0.2	-12.23	7.176	-0.04	401.0
1798	-0.2	-12.25	7.188	-0.04	401.6
1801	0.2	-12.28	7.200	0.04	402.6
1804	0.0	-12.30	7.212	0.00	403.2
1807	-0.2	-12.32	7.224	-0.04	404.0
1810	0.2	-12.34	7.236	0.04	404.6
1813	0.0	-12.36	7.248	0.00	405.2
1816	0.0	-12.38	7.260	0.00	406.0
1819	0.2	-12.40	7.272	0.04	406.6
1822	0.0	-12.42	7.284	0.00	407.2
1825	0.0	-12.44	7.296	0.00	407.8
1828	0.2	-12.46	7.308	0.04	408.6
1831	-0.2	-12.48	7.320	-0.04	409.2
1834	0.0	-12.51	7.332	0.00	410.2
1837	0.0	-12.53	7.344	0.00	410.8
1840	-0.2	-12.55	7.356	-0.04	411.4
1843	-0.2	-12.57	7.368	-0.04	412.2
1846	0.0	-12.59	7.380	0.00	412.8
1849	0.0	-12.61	7.392	0.00	413.4
1852	0.0	-12.63	7.404	0.00	414.0
1855	-0.4	-12.65	7.416	-0.08	414.8
1858	0.0	-12.67	7.428	0.00	415.4
1861	0.0	-12.69	7.440	0.00	416.0
1864	-0.2	-12.71	7.452	-0.04	416.8
1867	0.0	-12.74	7.464	0.00	417.8
1870	0.0	-12.76	7.476	0.00	418.4
1873	0.0	-12.78	7.488	0.00	419.0
1876	0.0	-12.80	7.500	0.00	419.6
1879	0.0	-12.82	7.512	0.00	420.4
1882	-0.2	-12.84	7.524	-0.04	421.0
1885	0.0	-12.86	7.536	0.00	421.6
1888	-0.2	-12.88	7.548	-0.04	422.2
1891	0.0	-12.90	7.560	0.00	423.0
1894	-0.4	-12.92	7.572	-0.08	423.6
1897	0.0	-12.94	7.584	0.00	424.2
1900	0.0	-12.97	7.596	0.00	425.2
1903	0.0	-12.99	7.608	0.00	426.0
1906	-0.2	-13.01	7.620	-0.04	426.6
1909	0.0	-13.03	7.632	0.00	427.2
1912	0.0	-13.05	7.644	0.00	427.8
1915	0.0	-13.07	7.656	0.00	428.6
1918	0.0	-13.09	7.668	0.00	429.2
1921	0.4	-13.11	7.680	0.08	429.8
1924	0.0	-13.13	7.692	0.00	430.4
1927	0.0	-13.15	7.704	0.00	431.2
1930	0.0	-13.17	7.716	0.00	431.8
1933	0.0	-13.20	7.728	0.00	432.8
1936	-0.2	-13.22	7.740	-0.04	433.4
1939	0.0	-13.24	7.752	0.00	434.0
1942	0.0	-13.26	7.764	0.00	434.8
1945	0.0	-13.28	7.776	0.00	435.4
1948	0.2	-13.30	7.788	0.04	436.0
1951	0.2	-13.32	7.800	0.04	436.8
1954	0.0	-13.34	7.812	0.00	437.4
1957	0.0	-13.36	7.824	0.00	438.0
1960	0.2	-13.39	7.836	0.04	439.0
1963	0.0	-13.41	7.848	0.00	439.6
1966	0.0	-13.43	7.860	0.00	440.4
1969	0.0	-13.45	7.872	0.00	441.0
1972	0.0	-13.47	7.884	0.00	441.6
1975	0.0	-13.49	7.896	0.00	442.2
1978	0.0	-13.51	7.908	0.00	443.0
1981	0.0	-13.53	7.920	0.00	443.6
1984	0.2	-13.55	7.932	0.04	444.2
1987	0.2	-13.57	7.944	0.04	445.0
1990	0.0	-13.60	7.956	0.00	446.0
1993	0.0	-13.62	7.968	0.00	446.6
1996	-0.2	-13.64	7.980	-0.04	447.2
1999	0.0	-13.66	7.992	0.00	447.8
2002	0.2	-13.68	8.004	0.04	448.6
2005	0.0	-13.70	8.016	0.00	449.2
2008	0.0	-13.72	8.028	0.00	449.8
2011	0.0	-13.74	8.040	0.00	450.4
2014	0.0	-13.76	8.052	0.00	451.2
2017	-0.2	-13.79	8.064	-0.04	452.2
2020	0.0	-13.81	8.076	0.00	452.8
2023	0.0	-13.83	8.088	0.00	453.4
2026	0.0	-13.85	8.100	0.00	454.0
2029	0.2	-13.87	8.112	0.04	454.8
2032	-0.2	-13.89	8.124	-0.04	455.4
2035	-0.2	-13.91	8.136	-0.04	456.0
2038	0.0	-13.93	8.148	0.00	456.8
2041	0.4	-13.96	8.160	0.08	457.8
2044	0.2	-13.98	8.172	0.04	458.4
2047	0.0	-14.00	8.184	0.00	459.0
2050	0.0	-14.02	8.196	0.00	459.6
2053	0.0	-14.04	8.208	0.00	460.4
2056	0.2	-14.06	8.220	0.04	461.0
2059	-0.4	-14.08	8.232	-0.08	461.6
2062	0.0	-14.10	8.244	0.00	462.2
2065	0.2	-14.13	8.256	0.04	463.2
2068	0.0	-14.15	8.268	0.00	464.0
2071	-0.4	-14.17	8.280	-0.08	464.6
2074	-0.2	-14.19	8.292	-0.04	465.2
2077	-0.2	-14.21	8.304	-0.04	466.0
2080	0.0	-14.23	8.316	0.00	466.6
2083	0.0	-14.25	8.328	0.00	467.2
2086	0.2	-14.27	8.340	0.04	467.8
2089	0.0	-14.29	8.352	0.00	468.6
2092	0.0	-14.32	8.364	0.00	469.6
2095	0.0	-14.34	8.376	0.00	470.2
2098	0.0	-14.36	8.388	0.00	470.8
2101	0.4	-14.38	8.400	0.08	471.4
2104	0.0	-14.40	8.412	0.00	472.2
2107	-0.2	-14.42	8.424	-0.04	472.8
2110	-0.2	-14.44	8.436	-0.04	473.4
2113	0.0	-14.46	8.448	0.00	474.0
2116	0.2	-14.48	8.460	0.04	474.8
2119	0.0	-14.51	8.472	0.00	475.8
2122	0.0	-14.53	8.484	0.00	476.4
2125	-0.2	-14.55	8.496	-0.04	477.0
2128	0.0	-14.57	8.508	0.00	477.8
2131	0.0	-14.59	8.520	0.00	478.4
2134	0.2	-14.61	8.532	0.04	479.0
2137	0.0	-14.63	8.544	0.00	479.6
2140	0.0	-14.65	8.556	0.00	480.4
2143	0.0	-14.68	8.568	0.00	481.4
2146	0.0	-14.70	8.580	0.00	482.0
2149	0.0	-14.72	8.592	0.00	482.6
2152	0.0	-14.74	8.604	0.00	483.2
2155	0.0	-14.76	8.616	0.00	484.0
2158	0.0	-14.78	8.628	0.00	484.6
2161	0.2	-14.80	8.640	0.04	485.2
2164	0.0	-14.82	8.652	0.00	486.0
2167	-0.4	-14.84	8.664	-0.08	486.6
2170	0.0	-14.87	8.676	0.00	487.6
2173	0.0	-14.89	8.688	0.00	488.2
2176	0.2	-14.91	8.700	0.04	488.8
2179	0.0	-14.93	8.712	0.00	489.6
2182	0.0	-14.95	8.724	0.00	490.2
2185	0.2	-14.97	8.736	0.04	490.8
2188	0.2	-14.99	8.748	0.04	491.4
2191	0.0	-15.01	8.760	0.00	492.2
2194	0.0	-15.03	8.772	0.00	492.8
2197	0.0	-15.06	8.784	0.00	493.8
2200	0.0	-15.08	8.796	0.00	494.4
2203	0.0	-15.10	8.808	0.00	495.0
2206	0.0	-15.12	8.820	0.00	495.8
2209	-0.2	-15.14	8.832	-0.04	496.4
2212	0.2	-15.16	8.844	0.04	497.0
2215	0.0	-15.18	8.856	0.00	497.8
2218	0.2	-15.20	8.868	0.04	498.4
2221	0.2	-15.21	8.880	0.04	498.6
2224	0.0	-15.24	8.892	0.00	499.6
2227	0.0	-15.26	8.904	0.00	500.4
2230	0.0	-15.28	8.916	0.00	501.0
2233	0.0	-15.30	8.928	0.00	501.6
2236	0.0	-15.32	8.940	0.00	502.2
2239	0.0	-15.34	8.952	0.00	503.0
2242	0.4	-15.36	8.964	0.08	503.6
2245	0.0	-15.38	8.976	0.00	504.2
2248	0.0	-15.40	8.988	0.00	505.0
2251	0.2	-15.43	9.000	0.04	506.0
2254	-0.2	-15.45	9.012	-0.04	506.6
2257	0.0	-15.47	9.024	0.00	507.2
2260	0.0	-15.49	9.036	0.00	507.8
2263	0.0	-15.51	9.048	0.00	508.6
2266	0.0	-15.53	9.060	0.00	509.2
2269	0.0	-15.55	9.072	0.00	509.8
2272	-0.4	-15.57	9.084	-0.08	510.4
2275	0.0	-15.59	9.096	0.00	511.2
2278	0.0	-15.61	9.108	0.00	511.8
2281	0.2	-15.64	9.120	0.04	512.8
2284	0.2	-15.66	9.132	0.04	513.4
2287	0.0	-15.68	9.144	0.00	514.0
2290	0.0	-15.70	9.156	0.00	514.8
2293	0.0	-15.72	9.168	0.00	515.4
2296	-0.2	-15.74	9.180	-0.04	516.0
2299	0.0	-15.76	9.192	0.00	516.8
2302	0.0	-15.78	9.204	0.00	517.4
2305	-0.4	-15.80	9.216	-0.08	518.0
2308	0.0	-15.82	9.228	0.00	518.6
2311	0.0	-15.84	9.240	0.00	519.4
2314	0.0	-15.87	9.252	0.00	520.4
2317	-0.2	-15.89	9.264	-0.04	521.0
2320	0.0	-15.91	9.276	0.00	521.6
2323	-0.2	-15.93	9.288	-0.04	522.2
2326	0.0	-15.95	9.300	0.00	523.0
2329	0.0	-15.97	9.312	0.00	523.6
2332	0.2	-15.99	9.324	0.04	524.2
2335	0.0	-16.01	9.336	0.00	525.0
2338	0.0	-16.03	9.348	0.00	525.6
2341	0.2	-16.05	9.360	0.04	526.2
2344	0.0	-16.07	9.372	0.00	526.8
2347	0.0	-16.10	9.384	0.00	527.8
2350	0.0	-16.12	9.396	0.00	528.6
2353	0.2	-16.14	9.408	0.04	529.2
2356	0.0	-16.16	9.420	0.00	529.8
2359	0.4	-16.18	9.432	0.08	530.4
2362	0.2	-16.20	9.444	0.04	531.2
2365	-0.2	-16.22	9.456	-0.04	531.8
2368	0.0	-16.24	9.468	0.00	532.4
2371	0.0	-16.26	9.480	0.00	533.2
2374	0.0	-16.28	9.492	0.00	533.8
2377	0.0	-16.30	9.504	0.00	534.4
2380	0.0	-16.32	9.516	0.00	535.0
2383	0.0	-16.35	9.528	0.00	536.0
2386	0.0	-16.37	9.540	0.00	536.8
2389	0.0	-16.39	9.552	0.00	537.4
2392	0.2	-16.41	9.564	0.04	538.0
2395	0.0	-16.43	9.576	0.00	538.6
2398	0.0	-16.45	9.588	0.00	539.4
2401	0.2	-16.47	9.600	0.04	540.0
2404	0.0	-16.49	9.612	0.00	540.6
2407	0.0	-16.51	9.624	0.00	541.4
2410	0.0	-16.53	9.636	0.00	542.0
2413	0.0	-16.55	9.648	0.00	542.6
2416	0.0	-16.58	9.660	0.00	543.6
2419	0.0	-16.60	9.672	0.00	544.2
2422	0.0	-16.62	9.684	0.00	545.0
2425	0.0	-16.64	9.696	0.00	545.6
2428	0.2	-16.66	9.708	0.04	546.2
2431	0.0	-16.68	9.720	0.00	546.8
2434	0.0	-16.70	9.732	0.00	547.6
2437	0.0	-16.72	9.744	0.00	548.2
2440	0.0	-16.74	9.756	0.00	548.8
2443	0.0	-16.76	9.768	0.00	549.6
2446	0.0	-16.78	9.780	0.00	550.2
2449	0.0	-16.81	9.792	0.00	551.2
2452	0.0	-16.83	9.804	0.00	551.8
2455	0.0	-16.85	9.816	0.00	552.4
2458	0.0	-16.87	9.828	0.00	553.2
2461	0.4	-16.89	9.840	0.08	553.8
2464	-0.2	-16.91	9.852	-0.04	554.4
2467	0.0	-16.93	9.864	0.00	555.0
2470	0.0	-16.95	9.876	0.00	555.8
2473	-0.2	-16.97	9.888	-0.04	556.4
2476	0.0	-16.99	9.900	0.00	557.0
2479	0.0	-17.01	9.912	0.00	557.8
2482	0.0	-17.03	9.924	0.00	558.4
2485	-0.2	-17.05	9.936	-0.04	559.0
2488	0.0	-17.08	9.948	0.00	560.0
2491	0.0	-17.10	9.960	0.00	560.6
2494	0.0	-17.12	9.972	0.00	561.4
2497	-0.4	-17.14	9.984	-0.08	562.0
2500	0.0	-17.16	9.996	0.00	562.6
2503	0.0	-17.18	10.008	0.00	563.2
2506	0.2	-17.20	10.020	0.04	564.0
2509	0.4	-17.23	10.032	0.08	565.0
2512	0.0	-17.25	10.044	0.00	565.6
2515	0.2	-17.27	10.056	0.04	566.2
2518	0.0	-17.29	10.068	0.00	566.8
2521	0.0	-17.31	10.080	0.00	567.6
2524	0.0	-17.34	10.092	0.00	568.6
2527	0.2	-17.36	10.104	0.04	569.2
2530	0.0	-17.38	10.116	0.00	569.8
2533	-0.6	-17.40	10.128	-0.12	570.4
2536	0.0	-17.42	10.140	0.00	571.2
2539	0.0	-17.44	10.152	0.00	571.8
2542	0.2	-17.46	10.164	0.04	572.4
2545	0.2	-17.48	10.176	0.04	573.2
2548	0.0	-17.50	10.188	0.00	573.8
2551	-0.2	-17.52	10.200	-0.04	574.4
2554	0.0	-17.54	10.212	0.00	575.0
2557	0.0	-17.57	10.224	0.00	576.0
2560	-0.2	-17.59	10.236	-0.04	576.8
2563	0.0	-17.61	10.248	0.00	577.4
2566	-0.4	-17.63	10.260	-0.08	578.0
2569	-0.2	-17.65	10.272	-0.04	578.6
2572	0.0	-17.67	10.284	0.00	579.4
2575	0.0	-17.69	10.296	0.00	580.0
2578	0.0	-17.71	10.308	0.00	580.6
2581	0.0	-17.73	10.320	0.00	581.4
2584	0.0	-17.75	10.332	0.00	582.0
2587	0.0	-17.77	10.344	0.00	582.6
2590	0.0	-17.80	10.356	0.00	583.6
2593	-0.2	-17.82	10.368	-0.04	584.2
2596	0.0	-17.84	10.380	0.00	585.0
2599	0.0	-17.86	10.392	0.00	585.6
2602	0.0	-17.88	10.404	0.00	586.2
2605	0.0	-17.90	10.416	0.00	586.8
2608	0.0	-17.92	10.428	0.00	587.6
2611	0.0	-17.94	10.440	0.00	588.2
2614	0.0	-17.96	10.452	0.00	588.8
2617	0.4	-17.98	10.464	0.08	589.6
2620	0.0	-18.00	10.476	0.00	590.2
2623	0.0	-18.02	10.488	0.00	590.8
2626	0.0	-18.05	10.500	0.00	591.8
2629	0.2	-18.07	10.512	0.04	592.4
2632	0.0	-18.09	10.524	0.00	593.2
2635	0.0	-18.11	10.536	0.00	593.8
2638	0.0	-18.13	10.548	0.00	594.4
2641	0.2	-18.15	10.560	0.04	595.0
2644	0.0	-18.17	10.572	0.00	595.8
2647	0.0	-18.19	10.584	0.00	596.4
2650	0.0	-18.21	10.596	0.00	597.0
2653	0.0	-18.23	10.608	0.00	597.8
2656	0.2	-18.25	10.620	0.04	598.4
2659	0.0	-18.28	10.632	0.00	599.4
2662	-0.2	-18.30	10.644	-0.04	600.0
2665	0.0	-18.32	10.656	0.00	600.6
2668	0.0	-18.34	10.668	0.00	601.4
2671	0.2	-18.36	10.680	0.04	602.0
2674	0.0	-18.38	10.692	0.00	602.6
2677	0.0	-18.40	10.704	0.00	603.2
2680	0.0	-18.42	10.716	0.00	604.0
2683	0.2	-18.44	10.728	0.04	604.6
2686	-0.2	-18.47	10.740	-0.04	605.6
2689	0.0	-18.49	10.752	0.00	606.2
2692	-0.2	-18.51	10.764	-0.04	606.8
2695	-0.4	-18.53	10.776	-0.08	607.6
2698	0.0	-18.55	10.788	0.00	608.2
2701	-0.2	-18.57	10.800	-0.04	608.8
2704	0.0	-18.59	10.812	0.00	609.6
2707	0.0	-18.61	10.824	0.00	610.2
2710	0.0	-18.63	10.836	0.00	610.8
2713	0.0	-18.66	10.848	0.00	611.8
2716	0.2	-18.68	10.860	0.04	612.4
2719	0.0	-18.70	10.872	0.00	613.2
2722	0.0	-18.72	10.884	0.00	613.8
2725	0.0	-18.74	10.896	0.00	614.4
2728	0.2	-18.76	10.908	0.04	615.0
2731	0.0	-18.78	10.920	0.00	615.8
2734	0.2	-18.80	10.932	0.04	616.4
2737	0.0	-18.82	10.944	0.00	617.0
2740	-0.2	-18.85	10.956	-0.04	618.0
2743	-0.2	-18.87	10.968	-0.04	618.6
2746	0.2	-18.89	10.980	0.04	619.4
2749	0.0	-18.91	10.992	0.00	620.0
2752	0.0	-18.93	11.004	0.00	620.6
2755	0.0	-18.95	11.016	0.00	621.4
2758	-0.2	-18.97	11.028	-0.04	622.0
2761	-0.2	-18.99	11.040	-0.04	622.6
2764	0.0	-19.01	11.052	0.00	623.2
2767	0.0	-19.04	11.064	0.00	624.2
2770	0.0	-19.06	11.076	0.00	625.0
2773	0.2	-19.08	11.088	0.04	625.6
2776	0.0	-19.10	11.100	0.00	626.2
2779	-0.2	-19.12	11.112	-0.04	626.8
2782	-0.2	-19.14	11.124	-0.04	627.6
2785	0.0	-19.16	11.136	0.00	628.2
2788	-0.2	-19.18	11.148	-0.04	628.8
2791	0.0	-19.20	11.160	0.00	629.6
2794	-0.2	-19.22	11.172	-0.04	630.2
2797	0.0	-19.24	11.184	0.00	630.8
2800	-0.2	-19.26	11.196	-0.04	631.4
2803	0.0	-19.28	11.208	0.00	632.2
2806	0.0	-19.30	11.220	0.00	632.8
2809	0.0	-19.32	11.232	0.00	633.4
2812	0.2	-19.34	11.244	0.04	634.0
2815	0.0	-19.36	11.256	0.00	634.8
2818	0.0	-19.38	11.268	0.00	635.4
2821	0.0	-19.41	11.280	0.00	636.4
2824	0.4	-19.43	11.292	0.08	637.0
2827	0.4	-19.45	11.304	0.08	637.8
2830	0.8	-19.47	11.316	0.16	638.4
2833	1.0	-19.49	11.328	0.20	639.0
2836	1.6	-19.51	11.340	0.34	639.6
2839	2.8	-19.53	11.352	0.58	640.4
2842	3.8	-19.55	11.364	0.80	641.0
2845	5.4	-19.57	11.376	1.12	641.6
2848	7.8	-19.59	11.388	1.62	642.2
2851	11.0	-19.61	11.400	2.30	643.0
2854	15.6	-19.63	11.412	3.26	643.6
2857	24.2	-19.64	11.424	5.06	644.0
2860	33.2	-19.66	11.436	6.92	644.6
2863	42.4	-19.67	11.448	8.84	645.0
2866	51.6	-19.68	11.460	10.76	645.2
2869	59.8	-19.69	11.472	12.48	645.6
2872	63.4	-19.71	11.484	13.24	646.2
2875	68.2	-19.73	11.496	14.24	646.8
2878	72.6	-19.75	11.508	15.16	647.6
2881	74.0	-19.77	11.520	15.44	648.2
2884	64.6	-19.80	11.532	13.48	649.2
2887	60.6	-19.82	11.544	12.64	649.8
2890	64.4	-19.84	11.556	13.44	650.4
2893	67.0	-19.86	11.568	13.98	651.2
2896	68.6	-19.88	11.580	14.32	651.8
2899	68.8	-19.90	11.592	14.36	652.4
2902	68.4	-19.92	11.604	14.28	653.2
2905	67.6	-19.94	11.616	14.10	653.8
2908	67.2	-19.96	11.628	14.02	654.4
2911	67.2	-19.98	11.640	14.02	655.0
2914	65.8	-20.01	11.652	13.74	656.0
2917	49.4	-20.04	11.664	10.30	657.0
2920	22.8	-20.09	11.676	4.76	658.6
2923	23.6	-20.11	11.688	4.92	659.4
2926	22.2	-20.13	11.700	4.64	660.0
2929	21.2	-20.15	11.712	4.42	660.6
2932	20.4	-20.17	11.724	4.26	661.4
2935	20.2	-20.19	11.736	4.22	662.0
2938	20.4	-20.22	11.748	4.26	663.0
2941	19.6	-20.24	11.760	4.10	663.6
2944	18.6	-20.26	11.772	3.88	664.2
2947	17.4	-20.28	11.784	3.64	665.0
2950	17.8	-20.30	11.796	3.72	665.6
2953	19.4	-20.32	11.808	4.04	666.2
2956	21.0	-20.34	11.820	4.38	666.8
2959	22.0	-20.36	11.832	4.60	667.6
2962	23.0	-20.38	11.844	4.80	668.2
2965	24.6	-20.40	11.856	5.14	668.8
2968	27.0	-20.42	11.868	5.64	669.6
2971	31.6	-20.44	11.880	6.60	670.2
2974	32.0	-20.46	11.892	6.68	670.8
2977	34.8	-20.48	11.904	7.26	671.4
2980	36.8	-20.49	11.916	7.68	671.8
2983	39.0	-20.51	11.928	8.14	672.4
2986	39.0	-20.53	11.940	8.14	673.2
2989	39.2	-20.56	11.952	8.18	674.0
2992	38.0	-20.58	11.964	7.94	674.8
2995	38.6	-20.60	11.976	8.06	675.4
2998	36.8	-20.62	11.988	7.68	676.0
3001	37.2	-20.64	12.000	7.76	676.8
3004	38.6	-20.66	12.012	8.06	677.4
3007	39.2	-20.68	12.024	8.18	678.0
3010	39.4	-20.70	12.036	8.22	678.6
3013	39.8	-20.72	12.048	8.30	679.4
3016	40.4	-20.75	12.060	8.44	680.4
3019	41.2	-20.77	12.072	8.60	681.0
3022	41.2	-20.79	12.084	8.60	681.6
3025	42.8	-20.81	12.096	8.94	682.2
3028	43.8	-20.82	12.108	9.14	682.6
3031	44.6	-20.85	12.120	9.30	683.6
3034	45.6	-20.86	12.132	9.52	684.0
3037	48.0	-20.89	12.144	10.02	685.0
3040	48.8	-20.91	12.156	10.18	685.6
3043	46.8	-20.93	12.168	9.76	686.2
3046	46.4	-20.95	12.180	9.68	686.8
3049	46.6	-20.97	12.192	9.72	687.6
3052	47.8	-20.99	12.204	9.98	688.2
3055	49.0	-21.01	12.216	10.22	688.8
3058	50.2	-21.03	12.228	10.48	689.6
3061	51.4	-21.05	12.240	10.72	690.2
3064	52.2	-21.07	12.252	10.90	690.8
3067	52.8	-21.09	12.264	11.02	691.4
3070	53.2	-21.11	12.276	11.10	692.2
3073	53.4	-21.13	12.288	11.14	692.8
3076	54.0	-21.15	12.300	11.26	693.4
3079	55.8	-21.17	12.312	11.64	694.0
3082	57.2	-21.19	12.324	11.94	694.8
3085	58.0	-21.21	12.336	12.10	695.4
3088	59.0	-21.23	12.348	12.32	696.0
3091	59.8	-21.25	12.360	12.48	696.8
3094	61.4	-21.27	12.372	12.82	697.4
3097	60.6	-21.29	12.384	12.64	698.0
3100	62.0	-21.31	12.396	12.94	698.6
3103	62.6	-21.33	12.408	13.06	699.4
3106	63.4	-21.35	12.420	13.24	700.0
3109	64.0	-21.37	12.432	13.36	700.6
3112	65.2	-21.39	12.444	13.60	701.4
3115	63.2	-21.41	12.456	13.18	702.0
3118	57.8	-21.44	12.468	12.06	703.0
3121	56.8	-21.46	12.480	11.86	703.6
3124	57.8	-21.48	12.492	12.06	704.2
3127	58.6	-21.50	12.504	12.22	705.0
3130	59.6	-21.52	12.516	12.44	705.6
3133	60.0	-21.54	12.528	12.52	706.2
3136	54.4	-21.54	12.540	11.36	706.2
3139	51.6	-21.55	12.552	10.76	706.6
3142	50.2	-21.55	12.564	10.48	706.6
3145	48.6	-21.55	12.576	10.14	706.6
3148	48.0	-21.55	12.588	10.02	706.6
3151	47.2	-21.55	12.600	9.86	706.6
3154	46.6	-21.55	12.612	9.72	706.6
3157	46.4	-21.55	12.624	9.68	706.6
3160	45.8	-21.55	12.636	9.56	706.6
3163	45.4	-21.55	12.648	9.48	706.6
3166	45.2	-21.55	12.660	9.44	706.6
3169	44.8	-21.55	12.672	9.34	706.6
3170	74.6	-19.76	12.676	9.30	706.6