File: results/youngs-modulus/2025-04-25/inconclusive-data/pf02ut03.csv
sep=
pf02ut03

System Information:
IntelliMESUR Version: 2.2.1
Test Frame Model: F505
Test Frame Serial Number: 4418651
Test Frame Capacity: 500 lbF / 2.2 kN
Test Frame Firmware Version: 1.00.14
Force Sensor Model: FS05-100
Force Sensor Capacity: 500 N
Force Sensor Resolution: 0.2 N
Force Sensor Serial Number: 4425350
Calibration Date: Apr 29, 2024
Calibration Due Date: Apr 29, 2025

Reading	Load [N]	Distance [mm]	Time [s]	Stress [MPa]	Strain [%]
1	0.0	-0.01	0.000	0.00	0.4
4	0.0	-0.01	0.012	0.00	0.4
7	0.0	-0.01	0.024	0.00	0.4
10	0.0	-0.01	0.036	0.00	0.4
13	0.0	-0.01	0.048	0.00	0.4
16	0.0	-0.01	0.060	0.00	0.4
19	0.2	-0.01	0.072	0.04	0.4
22	0.0	-0.01	0.084	0.00	0.4
25	0.0	-0.01	0.096	0.00	0.4
28	0.0	-0.01	0.108	0.00	0.4
31	0.0	-0.01	0.120	0.00	0.4
34	0.0	-0.01	0.132	0.00	0.4
37	0.0	-0.01	0.144	0.00	0.4
40	0.0	-0.01	0.156	0.00	0.4
43	-0.2	-0.01	0.168	-0.04	0.4
46	-0.2	-0.01	0.180	-0.04	0.4
49	0.0	-0.02	0.192	0.00	0.6
52	0.2	-0.04	0.204	0.04	1.4
55	0.2	-0.05	0.216	0.04	1.8
58	0.2	-0.07	0.228	0.04	2.4
61	-0.2	-0.09	0.240	-0.04	3.2
64	-0.2	-0.12	0.252	-0.04	4.2
67	0.0	-0.14	0.264	0.00	4.8
70	0.0	-0.16	0.276	0.00	5.6
73	0.0	-0.18	0.288	0.00	6.2
76	0.0	-0.20	0.300	0.00	7.0
79	0.0	-0.22	0.312	0.00	7.6
82	0.0	-0.24	0.324	0.00	8.4
85	0.0	-0.26	0.336	0.00	9.0
88	0.0	-0.28	0.348	0.00	9.8
91	0.0	-0.31	0.360	0.00	10.8
94	-0.2	-0.32	0.372	-0.04	11.2
97	0.2	-0.35	0.384	0.04	12.2
100	0.0	-0.37	0.396	0.00	12.8
103	-0.2	-0.39	0.408	-0.04	13.6
106	0.0	-0.41	0.420	0.00	14.2
109	0.0	-0.43	0.432	0.00	15.0
112	0.0	-0.45	0.444	0.00	15.6
115	0.0	-0.47	0.456	0.00	16.4
118	-0.2	-0.49	0.468	-0.04	17.0
121	0.0	-0.51	0.480	0.00	17.8
124	0.0	-0.54	0.492	0.00	18.8
127	0.2	-0.56	0.504	0.04	19.6
130	0.0	-0.58	0.516	0.00	20.2
133	0.2	-0.60	0.528	0.04	21.0
136	0.0	-0.62	0.540	0.00	21.6
139	0.0	-0.64	0.552	0.00	22.2
142	0.2	-0.66	0.564	0.04	23.0
145	0.2	-0.68	0.576	0.04	23.6
148	0.0	-0.70	0.588	0.00	24.4
151	0.0	-0.72	0.600	0.00	25.0
154	-0.2	-0.74	0.612	-0.04	25.8
157	0.2	-0.77	0.624	0.04	26.8
160	-0.2	-0.79	0.636	-0.04	27.6
163	0.0	-0.81	0.648	0.00	28.2
166	0.0	-0.83	0.660	0.00	29.0
169	-0.4	-0.85	0.672	-0.06	29.6
172	0.0	-0.87	0.684	0.00	30.4
175	0.0	-0.89	0.696	0.00	31.0
178	0.2	-0.91	0.708	0.04	31.8
181	0.0	-0.93	0.720	0.00	32.4
184	0.0	-0.95	0.732	0.00	33.2
187	-0.2	-0.97	0.744	-0.04	33.8
190	0.2	-1.00	0.756	0.04	34.8
193	-0.2	-1.02	0.768	-0.04	35.6
196	0.0	-1.05	0.780	0.00	36.6
199	-0.2	-1.07	0.792	-0.04	37.2
202	0.0	-1.09	0.804	0.00	38.0
205	-0.2	-1.11	0.816	-0.04	38.6
208	0.0	-1.13	0.828	0.00	39.4
211	-0.2	-1.15	0.840	-0.04	40.0
214	0.0	-1.17	0.852	0.00	40.8
217	0.0	-1.19	0.864	0.00	41.4
220	-0.2	-1.22	0.876	-0.04	42.6
223	0.2	-1.24	0.888	0.04	43.2
226	0.0	-1.26	0.900	0.00	44.0
229	0.0	-1.28	0.912	0.00	44.6
232	0.0	-1.30	0.924	0.00	45.2
235	0.0	-1.32	0.936	0.00	46.0
238	0.0	-1.34	0.948	0.00	46.6
241	0.0	-1.36	0.960	0.00	47.4
244	0.0	-1.38	0.972	0.00	48.0
247	0.0	-1.40	0.984	0.00	48.8
250	0.0	-1.42	0.996	0.00	49.4
253	0.0	-1.45	1.008	0.00	50.6
256	0.2	-1.46	1.020	0.04	50.8
259	0.0	-1.49	1.032	0.00	52.0
262	0.0	-1.51	1.044	0.00	52.6
265	0.2	-1.53	1.056	0.04	53.4
268	0.0	-1.55	1.068	0.00	54.0
271	0.0	-1.57	1.080	0.00	54.8
274	0.0	-1.59	1.092	0.00	55.4
277	0.0	-1.61	1.104	0.00	56.0
280	0.0	-1.63	1.116	0.00	56.8
283	0.2	-1.65	1.128	0.04	57.4
286	0.2	-1.67	1.140	0.04	58.2
289	0.0	-1.69	1.152	0.00	58.8
292	0.0	-1.72	1.164	0.00	60.0
295	0.2	-1.74	1.176	0.04	60.6
298	0.2	-1.76	1.188	0.04	61.4
301	0.0	-1.78	1.200	0.00	62.0
304	0.0	-1.80	1.212	0.00	62.8
307	-0.2	-1.82	1.224	-0.04	63.4
310	0.0	-1.84	1.236	0.00	64.2
313	-0.2	-1.86	1.248	-0.04	64.8
316	0.0	-1.88	1.260	0.00	65.6
319	-0.4	-1.90	1.272	-0.06	66.2
322	0.0	-1.92	1.284	0.00	66.8
325	0.0	-1.95	1.296	0.00	68.0
328	0.0	-1.97	1.308	0.00	68.6
331	0.0	-1.99	1.320	0.00	69.4
334	0.0	-2.01	1.332	0.00	70.0
337	-0.2	-2.03	1.344	-0.04	70.8
340	-0.2	-2.04	1.356	-0.04	71.0
343	0.0	-2.06	1.368	0.00	71.8
346	-0.2	-2.08	1.380	-0.04	72.4
349	0.0	-2.10	1.392	0.00	73.2
352	0.0	-2.12	1.404	0.00	73.8
355	-0.2	-2.14	1.416	-0.04	74.6
358	0.0	-2.16	1.428	0.00	75.2
361	-0.2	-2.19	1.440	-0.04	76.4
364	0.0	-2.21	1.452	0.00	77.0
367	-0.4	-2.23	1.464	-0.06	77.8
370	-0.2	-2.25	1.476	-0.04	78.4
373	-0.2	-2.27	1.488	-0.04	79.0
376	0.0	-2.29	1.500	0.00	79.8
379	0.0	-2.31	1.512	0.00	80.4
382	0.0	-2.33	1.524	0.00	81.2
385	-0.2	-2.35	1.536	-0.04	81.8
388	0.0	-2.37	1.548	0.00	82.6
391	0.0	-2.39	1.560	0.00	83.2
394	0.0	-2.42	1.572	0.00	84.4
397	0.0	-2.44	1.584	0.00	85.0
400	0.0	-2.46	1.596	0.00	85.8
403	0.0	-2.48	1.608	0.00	86.4
406	0.0	-2.50	1.620	0.00	87.2
409	0.2	-2.52	1.632	0.04	87.8
412	0.0	-2.54	1.644	0.00	88.6
415	0.0	-2.56	1.656	0.00	89.2
418	0.2	-2.58	1.668	0.04	89.8
421	0.2	-2.60	1.680	0.04	90.6
424	0.0	-2.62	1.692	0.00	91.2
427	0.2	-2.65	1.704	0.04	92.4
430	-0.2	-2.67	1.716	-0.04	93.0
433	0.0	-2.69	1.728	0.00	93.8
436	0.0	-2.71	1.740	0.00	94.4
439	-0.2	-2.73	1.752	-0.04	95.2
442	0.0	-2.75	1.764	0.00	95.8
445	0.0	-2.77	1.776	0.00	96.6
448	0.2	-2.79	1.788	0.04	97.2
451	0.0	-2.81	1.800	0.00	98.0
454	0.0	-2.83	1.812	0.00	98.6
457	0.0	-2.86	1.824	0.00	99.6
460	0.0	-2.88	1.836	0.00	100.4
463	0.0	-2.90	1.848	0.00	101.0
466	0.0	-2.92	1.860	0.00	101.8
469	0.0	-2.94	1.872	0.00	102.4
472	0.0	-2.96	1.884	0.00	103.2
475	0.0	-2.98	1.896	0.00	103.8
478	0.0	-3.00	1.908	0.00	104.6
481	-0.4	-3.02	1.920	-0.06	105.2
484	-0.2	-3.05	1.932	-0.04	106.2
487	0.0	-3.07	1.944	0.00	107.0
490	0.0	-3.10	1.956	0.00	108.0
493	0.0	-3.12	1.968	0.00	108.8
496	-0.4	-3.14	1.980	-0.06	109.4
499	0.0	-3.16	1.992	0.00	110.2
502	0.2	-3.18	2.004	0.04	110.8
505	0.0	-3.20	2.016	0.00	111.4
508	0.0	-3.22	2.028	0.00	112.2
511	-0.2	-3.24	2.040	-0.04	112.8
514	0.0	-3.26	2.052	0.00	113.6
517	0.0	-3.29	2.064	0.00	114.6
520	0.0	-3.31	2.076	0.00	115.4
523	0.0	-3.33	2.088	0.00	116.0
526	0.0	-3.35	2.100	0.00	116.8
529	0.2	-3.37	2.112	0.04	117.4
532	0.0	-3.39	2.124	0.00	118.2
535	0.0	-3.41	2.136	0.00	118.8
538	0.0	-3.43	2.148	0.00	119.6
541	0.0	-3.45	2.160	0.00	120.2
544	0.0	-3.48	2.172	0.00	121.2
547	0.2	-3.50	2.184	0.04	122.0
550	-0.4	-3.52	2.196	-0.06	122.6
553	0.0	-3.54	2.208	0.00	123.4
556	0.0	-3.56	2.220	0.00	124.0
559	0.0	-3.58	2.232	0.00	124.8
562	0.0	-3.60	2.244	0.00	125.4
565	0.0	-3.62	2.256	0.00	126.2
568	0.0	-3.64	2.268	0.00	126.8
571	0.0	-3.67	2.280	0.00	127.8
574	0.0	-3.69	2.292	0.00	128.6
577	0.0	-3.71	2.304	0.00	129.2
580	0.0	-3.73	2.316	0.00	130.0
583	0.0	-3.75	2.328	0.00	130.6
586	-0.2	-3.77	2.340	-0.04	131.4
589	0.0	-3.79	2.352	0.00	132.0
592	0.0	-3.81	2.364	0.00	132.8
595	0.0	-3.83	2.376	0.00	133.4
598	0.0	-3.86	2.388	0.00	134.4
601	0.4	-3.88	2.400	0.06	135.2
604	0.2	-3.90	2.412	0.04	135.8
607	0.0	-3.92	2.424	0.00	136.6
610	0.0	-3.94	2.436	0.00	137.2
613	-0.2	-3.96	2.448	-0.04	138.0
616	0.0	-3.98	2.460	0.00	138.6
619	0.0	-4.00	2.472	0.00	139.4
622	-0.2	-4.02	2.484	-0.04	140.0
625	-0.2	-4.05	2.496	-0.04	141.2
628	0.2	-4.07	2.508	0.04	141.8
631	0.0	-4.09	2.520	0.00	142.6
634	0.0	-4.11	2.532	0.00	143.2
637	0.0	-4.13	2.544	0.00	144.0
640	0.0	-4.15	2.556	0.00	144.6
643	0.2	-4.17	2.568	0.04	145.2
646	-0.2	-4.19	2.580	-0.04	146.0
649	0.0	-4.21	2.592	0.00	146.6
652	0.0	-4.24	2.604	0.00	147.8
655	0.0	-4.26	2.616	0.00	148.4
658	0.2	-4.28	2.628	0.04	149.2
661	-0.2	-4.30	2.640	-0.04	149.8
664	0.2	-4.32	2.652	0.04	150.6
667	0.0	-4.34	2.664	0.00	151.2
670	0.0	-4.36	2.676	0.00	152.0
673	0.0	-4.38	2.688	0.00	152.6
676	-0.2	-4.41	2.700	-0.04	153.6
679	0.0	-4.43	2.712	0.00	154.4
682	0.0	-4.45	2.724	0.00	155.0
685	0.0	-4.47	2.736	0.00	155.8
688	-0.2	-4.49	2.748	-0.04	156.4
691	0.0	-4.51	2.760	0.00	157.2
694	0.0	-4.53	2.772	0.00	157.8
697	0.0	-4.55	2.784	0.00	158.6
700	0.0	-4.58	2.796	0.00	159.6
703	-0.2	-4.60	2.808	-0.04	160.2
706	0.0	-4.62	2.820	0.00	161.0
709	0.0	-4.64	2.832	0.00	161.6
712	0.0	-4.66	2.844	0.00	162.4
715	0.0	-4.68	2.856	0.00	163.0
718	-0.2	-4.70	2.868	-0.04	163.8
721	0.0	-4.72	2.880	0.00	164.4
724	-0.4	-4.74	2.892	-0.06	165.2
727	-0.2	-4.77	2.904	-0.04	166.2
730	0.2	-4.79	2.916	0.04	166.8
733	0.4	-4.81	2.928	0.06	167.6
736	0.2	-4.83	2.940	0.04	168.2
739	-0.2	-4.85	2.952	-0.04	169.0
742	0.0	-4.87	2.964	0.00	169.6
745	0.0	-4.89	2.976	0.00	170.4
748	-0.4	-4.91	2.988	-0.06	171.0
751	0.0	-4.93	3.000	0.00	171.8
754	0.0	-4.96	3.012	0.00	172.8
757	0.0	-4.98	3.024	0.00	173.6
760	0.2	-5.00	3.036	0.04	174.2
763	0.0	-5.02	3.048	0.00	175.0
766	0.0	-5.04	3.060	0.00	175.6
769	-0.4	-5.06	3.072	-0.06	176.4
772	0.0	-5.08	3.084	0.00	177.0
775	0.0	-5.10	3.096	0.00	177.8
778	0.0	-5.12	3.108	0.00	178.4
781	-0.4	-5.15	3.120	-0.06	179.4
784	0.0	-5.17	3.132	0.00	180.2
787	0.0	-5.19	3.144	0.00	180.8
790	0.2	-5.21	3.156	0.04	181.6
793	0.0	-5.23	3.168	0.00	182.2
796	-0.2	-5.25	3.180	-0.04	183.0
799	0.0	-5.27	3.192	0.00	183.6
802	0.0	-5.29	3.204	0.00	184.4
805	0.0	-5.31	3.216	0.00	185.0
808	-0.2	-5.33	3.228	-0.04	185.8
811	0.0	-5.35	3.240	0.00	186.4
814	0.0	-5.38	3.252	0.00	187.4
817	0.0	-5.40	3.264	0.00	188.2
820	-0.2	-5.42	3.276	-0.04	188.8
823	0.0	-5.44	3.288	0.00	189.6
826	0.2	-5.46	3.300	0.04	190.2
829	0.0	-5.48	3.312	0.00	191.0
832	0.0	-5.50	3.324	0.00	191.6
835	0.0	-5.52	3.336	0.00	192.4
838	0.0	-5.54	3.348	0.00	193.0
841	0.4	-5.57	3.360	0.06	194.0
844	0.0	-5.59	3.372	0.00	194.8
847	0.0	-5.61	3.384	0.00	195.4
850	0.0	-5.63	3.396	0.00	196.2
853	0.0	-5.65	3.408	0.00	196.8
856	0.0	-5.67	3.420	0.00	197.6
859	0.0	-5.69	3.432	0.00	198.2
862	0.0	-5.71	3.444	0.00	199.0
865	0.0	-5.73	3.456	0.00	199.6
868	0.0	-5.75	3.468	0.00	200.4
871	0.2	-5.77	3.480	0.04	201.0
874	0.0	-5.80	3.492	0.00	202.0
877	-0.2	-5.82	3.504	-0.04	202.8
880	0.0	-5.84	3.516	0.00	203.4
883	0.0	-5.86	3.528	0.00	204.2
886	0.0	-5.88	3.540	0.00	204.8
889	0.2	-5.90	3.552	0.04	205.6
892	0.0	-5.92	3.564	0.00	206.2
895	0.0	-5.94	3.576	0.00	207.0
898	0.0	-5.96	3.588	0.00	207.6
901	0.0	-5.98	3.600	0.00	208.4
904	0.0	-6.00	3.612	0.00	209.0
907	0.0	-6.02	3.624	0.00	209.8
910	-0.2	-6.04	3.636	-0.04	210.4
913	0.0	-6.06	3.648	0.00	211.2
916	0.0	-6.08	3.660	0.00	211.8
919	0.0	-6.10	3.672	0.00	212.6
922	0.0	-6.12	3.684	0.00	213.2
925	-0.2	-6.14	3.696	-0.04	214.0
928	0.2	-6.16	3.708	0.04	214.6
931	-0.2	-6.18	3.720	-0.04	215.4
934	0.0	-6.20	3.732	0.00	216.0
937	-0.2	-6.22	3.744	-0.04	216.8
940	0.2	-6.24	3.756	0.04	217.4
943	0.0	-6.27	3.768	0.00	218.4
946	0.0	-6.29	3.780	0.00	219.2
949	0.2	-6.31	3.792	0.04	219.8
952	0.0	-6.33	3.804	0.00	220.6
955	0.0	-6.35	3.816	0.00	221.2
958	-0.2	-6.37	3.828	-0.04	222.0
961	0.0	-6.39	3.840	0.00	222.6
964	0.0	-6.41	3.852	0.00	223.4
967	0.0	-6.43	3.864	0.00	224.0
970	0.0	-6.45	3.876	0.00	224.8
973	0.0	-6.47	3.888	0.00	225.4
976	0.2	-6.49	3.900	0.04	226.2
979	0.0	-6.51	3.912	0.00	226.8
982	0.0	-6.54	3.924	0.00	227.8
985	0.0	-6.56	3.936	0.00	228.6
988	0.0	-6.58	3.948	0.00	229.2
991	0.0	-6.60	3.960	0.00	230.0
994	0.0	-6.62	3.972	0.00	230.6
997	0.0	-6.64	3.984	0.00	231.4
1000	0.2	-6.66	3.996	0.04	232.0
1003	0.0	-6.68	4.008	0.00	232.8
1006	0.0	-6.70	4.020	0.00	233.4
1009	-0.4	-6.72	4.032	-0.06	234.2
1012	0.0	-6.74	4.044	0.00	234.8
1015	0.0	-6.76	4.056	0.00	235.6
1018	0.0	-6.79	4.068	0.00	236.6
1021	0.0	-6.81	4.080	0.00	237.2
1024	0.2	-6.83	4.092	0.04	238.0
1027	0.0	-6.85	4.104	0.00	238.6
1030	0.4	-6.87	4.116	0.06	239.4
1033	-0.2	-6.89	4.128	-0.04	240.0
1036	0.0	-6.91	4.140	0.00	240.8
1039	-0.2	-6.93	4.152	-0.04	241.4
1042	0.0	-6.95	4.164	0.00	242.2
1045	0.0	-6.97	4.176	0.00	242.8
1048	0.0	-6.99	4.188	0.00	243.6
1051	0.2	-7.02	4.200	0.04	244.6
1054	0.0	-7.05	4.212	0.00	245.6
1057	0.0	-7.07	4.224	0.00	246.4
1060	0.0	-7.09	4.236	0.00	247.0
1063	0.2	-7.11	4.248	0.04	247.8
1066	0.0	-7.13	4.260	0.00	248.4
1069	0.4	-7.15	4.272	0.06	249.2
1072	-0.2	-7.17	4.284	-0.04	249.8
1075	0.0	-7.19	4.296	0.00	250.6
1078	-0.4	-7.21	4.308	-0.06	251.2
1081	-0.4	-7.23	4.320	-0.06	252.0
1084	0.0	-7.25	4.332	0.00	252.6
1087	0.0	-7.28	4.344	0.00	253.6
1090	0.0	-7.30	4.356	0.00	254.4
1093	-0.2	-7.32	4.368	-0.04	255.0
1096	0.0	-7.34	4.380	0.00	255.8
1099	0.2	-7.36	4.392	0.04	256.4
1102	-0.2	-7.38	4.404	-0.04	257.2
1105	0.2	-7.40	4.416	0.04	257.8
1108	0.0	-7.42	4.428	0.00	258.6
1111	0.0	-7.44	4.440	0.00	259.2
1114	0.0	-7.46	4.452	0.00	260.0
1117	0.0	-7.48	4.464	0.00	260.6
1120	0.0	-7.50	4.476	0.00	261.4
1123	0.0	-7.53	4.488	0.00	262.4
1126	0.0	-7.55	4.500	0.00	263.0
1129	0.2	-7.57	4.512	0.04	263.8
1132	0.0	-7.59	4.524	0.00	264.4
1135	0.0	-7.61	4.536	0.00	265.2
1138	0.0	-7.63	4.548	0.00	265.8
1141	-0.2	-7.65	4.560	-0.04	266.6
1144	0.0	-7.67	4.572	0.00	267.2
1147	0.0	-7.69	4.584	0.00	268.0
1150	0.2	-7.71	4.596	0.04	268.6
1153	0.0	-7.73	4.608	0.00	269.4
1156	0.0	-7.75	4.620	0.00	270.0
1159	0.2	-7.78	4.632	0.04	271.0
1162	0.0	-7.80	4.644	0.00	271.8
1165	0.0	-7.82	4.656	0.00	272.4
1168	-0.4	-7.84	4.668	-0.06	273.2
1171	0.0	-7.86	4.680	0.00	273.8
1174	0.0	-7.88	4.692	0.00	274.6
1177	0.0	-7.90	4.704	0.00	275.2
1180	-0.2	-7.92	4.716	-0.04	276.0
1183	0.2	-7.94	4.728	0.04	276.6
1186	0.0	-7.97	4.740	0.00	277.8
1189	0.0	-7.99	4.752	0.00	278.4
1192	-0.2	-8.01	4.764	-0.04	279.0
1195	0.0	-8.03	4.776	0.00	279.8
1198	0.0	-8.05	4.788	0.00	280.4
1201	0.0	-8.07	4.800	0.00	281.2
1204	0.0	-8.09	4.812	0.00	281.8
1207	0.0	-8.11	4.824	0.00	282.6
1210	-0.2	-8.13	4.836	-0.04	283.2
1213	0.0	-8.16	4.848	0.00	284.4
1216	0.0	-8.17	4.860	0.00	284.6
1219	0.0	-8.20	4.872	0.00	285.8
1222	0.0	-8.22	4.884	0.00	286.4
1225	0.0	-8.24	4.896	0.00	287.2
1228	0.2	-8.26	4.908	0.04	287.8
1231	-0.2	-8.28	4.920	-0.04	288.6
1234	-0.2	-8.30	4.932	-0.04	289.2
1237	-0.2	-8.32	4.944	-0.04	289.8
1240	-0.2	-8.34	4.956	-0.04	290.6
1243	0.0	-8.36	4.968	0.00	291.2
1246	0.0	-8.39	4.980	0.00	292.4
1249	0.0	-8.41	4.992	0.00	293.0
1252	-0.2	-8.43	5.004	-0.04	293.8
1255	0.0	-8.45	5.016	0.00	294.4
1258	0.0	-8.47	5.028	0.00	295.2
1261	0.2	-8.49	5.040	0.04	295.8
1264	0.0	-8.51	5.052	0.00	296.6
1267	0.0	-8.53	5.064	0.00	297.2
1270	-0.4	-8.55	5.076	-0.06	298.0
1273	0.0	-8.58	5.088	0.00	299.0
1276	0.0	-8.60	5.100	0.00	299.6
1279	0.0	-8.62	5.112	0.00	300.4
1282	0.0	-8.64	5.124	0.00	301.0
1285	0.0	-8.66	5.136	0.00	301.8
1288	0.0	-8.68	5.148	0.00	302.4
1291	0.0	-8.70	5.160	0.00	303.2
1294	0.0	-8.72	5.172	0.00	303.8
1297	0.0	-8.74	5.184	0.00	304.6
1300	-0.2	-8.77	5.196	-0.04	305.6
1303	0.0	-8.79	5.208	0.00	306.2
1306	0.0	-8.81	5.220	0.00	307.0
1309	0.0	-8.83	5.232	0.00	307.6
1312	0.0	-8.85	5.244	0.00	308.4
1315	0.0	-8.87	5.256	0.00	309.0
1318	-0.2	-8.89	5.268	-0.04	309.8
1321	0.0	-8.92	5.280	0.00	310.8
1324	-0.2	-8.93	5.292	-0.04	311.2
1327	0.0	-8.96	5.304	0.00	312.2
1330	0.0	-8.98	5.316	0.00	312.8
1333	0.2	-9.00	5.328	0.04	313.6
1336	0.0	-9.02	5.340	0.00	314.2
1339	0.0	-9.04	5.352	0.00	315.0
1342	0.0	-9.06	5.364	0.00	315.6
1345	0.0	-9.08	5.376	0.00	316.4
1348	0.0	-9.10	5.388	0.00	317.0
1351	0.0	-9.12	5.400	0.00	317.8
1354	0.0	-9.15	5.412	0.00	318.8
1357	0.0	-9.17	5.424	0.00	319.6
1360	0.2	-9.19	5.436	0.04	320.2
1363	0.0	-9.21	5.448	0.00	321.0
1366	0.0	-9.23	5.460	0.00	321.6
1369	-0.2	-9.25	5.472	-0.04	322.2
1372	-0.2	-9.27	5.484	-0.04	323.0
1375	0.0	-9.30	5.496	0.00	324.0
1378	0.0	-9.32	5.508	0.00	324.8
1381	-0.2	-9.34	5.520	-0.04	325.4
1384	0.0	-9.36	5.532	0.00	326.2
1387	0.0	-9.38	5.544	0.00	326.8
1390	0.0	-9.40	5.556	0.00	327.6
1393	0.0	-9.42	5.568	0.00	328.2
1396	0.0	-9.44	5.580	0.00	329.0
1399	0.2	-9.46	5.592	0.04	329.6
1402	0.0	-9.49	5.604	0.00	330.6
1405	0.0	-9.51	5.616	0.00	331.4
1408	0.2	-9.53	5.628	0.04	332.0
1411	0.0	-9.55	5.640	0.00	332.8
1414	0.0	-9.57	5.652	0.00	333.4
1417	-0.2	-9.59	5.664	-0.04	334.2
1420	0.0	-9.61	5.676	0.00	334.8
1423	0.0	-9.63	5.688	0.00	335.6
1426	-0.2	-9.65	5.700	-0.04	336.2
1429	0.0	-9.68	5.712	0.00	337.2
1432	0.2	-9.70	5.724	0.04	338.0
1435	-0.2	-9.72	5.736	-0.04	338.6
1438	0.0	-9.74	5.748	0.00	339.4
1441	0.0	-9.76	5.760	0.00	340.0
1444	0.0	-9.78	5.772	0.00	340.8
1447	0.0	-9.80	5.784	0.00	341.4
1450	0.0	-9.82	5.796	0.00	342.2
1453	0.2	-9.84	5.808	0.04	342.8
1456	0.2	-9.87	5.820	0.04	344.0
1459	0.0	-9.89	5.832	0.00	344.6
1462	0.0	-9.91	5.844	0.00	345.2
1465	0.0	-9.93	5.856	0.00	346.0
1468	0.0	-9.95	5.868	0.00	346.6
1471	0.0	-9.97	5.880	0.00	347.4
1474	-0.2	-9.99	5.892	-0.04	348.0
1477	-0.4	-10.01	5.904	-0.06	348.8
1480	0.0	-10.03	5.916	0.00	349.4
1483	0.0	-10.05	5.928	0.00	350.2
1486	-0.2	-10.07	5.940	-0.04	350.8
1489	0.4	-10.09	5.952	0.06	351.6
1492	0.0	-10.11	5.964	0.00	352.2
1495	0.0	-10.13	5.976	0.00	353.0
1498	-0.2	-10.15	5.988	-0.04	353.6
1501	0.0	-10.17	6.000	0.00	354.4
1504	0.0	-10.19	6.012	0.00	355.0
1507	-0.2	-10.21	6.024	-0.04	355.8
1510	0.0	-10.24	6.036	0.00	356.8
1513	0.0	-10.26	6.048	0.00	357.4
1516	0.0	-10.28	6.060	0.00	358.2
1519	0.0	-10.30	6.072	0.00	358.8
1522	0.2	-10.32	6.084	0.04	359.6
1525	0.0	-10.34	6.096	0.00	360.2
1528	0.0	-10.36	6.108	0.00	361.0
1531	0.0	-10.38	6.120	0.00	361.6
1534	0.0	-10.40	6.132	0.00	362.4
1537	0.0	-10.43	6.144	0.00	363.4
1540	0.0	-10.45	6.156	0.00	364.2
1543	0.0	-10.47	6.168	0.00	364.8
1546	0.0	-10.49	6.180	0.00	365.6
1549	0.0	-10.51	6.192	0.00	366.2
1552	0.0	-10.53	6.204	0.00	366.8
1555	0.0	-10.55	6.216	0.00	367.6
1558	0.0	-10.57	6.228	0.00	368.2
1561	-0.6	-10.59	6.240	-0.10	369.0
1564	0.0	-10.61	6.252	0.00	369.6
1567	0.0	-10.63	6.264	0.00	370.4
1570	0.0	-10.66	6.276	0.00	371.4
1573	0.0	-10.68	6.288	0.00	372.2
1576	0.0	-10.70	6.300	0.00	372.8
1579	0.0	-10.72	6.312	0.00	373.6
1582	0.0	-10.74	6.324	0.00	374.2
1585	0.0	-10.76	6.336	0.00	375.0
1588	0.0	-10.78	6.348	0.00	375.6
1591	0.0	-10.80	6.360	0.00	376.4
1594	0.0	-10.82	6.372	0.00	377.0
1597	0.0	-10.84	6.384	0.00	377.8
1600	0.2	-10.87	6.396	0.04	378.8
1603	0.2	-10.89	6.408	0.04	379.4
1606	0.0	-10.91	6.420	0.00	380.2
1609	0.0	-10.93	6.432	0.00	380.8
1612	0.0	-10.95	6.444	0.00	381.6
1615	0.0	-10.97	6.456	0.00	382.2
1618	0.0	-10.99	6.468	0.00	383.0
1621	0.0	-11.01	6.480	0.00	383.6
1624	0.2	-11.03	6.492	0.04	384.4
1627	0.0	-11.05	6.504	0.00	385.0
1630	-0.2	-11.07	6.516	-0.04	385.8
1633	0.0	-11.10	6.528	0.00	386.8
1636	0.0	-11.12	6.540	0.00	387.4
1639	0.0	-11.14	6.552	0.00	388.2
1642	0.0	-11.16	6.564	0.00	388.8
1645	0.0	-11.18	6.576	0.00	389.6
1648	0.0	-11.20	6.588	0.00	390.2
1651	0.2	-11.22	6.600	0.04	391.0
1654	0.0	-11.24	6.612	0.00	391.6
1657	0.0	-11.26	6.624	0.00	392.4
1660	0.0	-11.28	6.636	0.00	393.0
1663	0.0	-11.30	6.648	0.00	393.8
1666	0.0	-11.33	6.660	0.00	394.8
1669	0.0	-11.35	6.672	0.00	395.4
1672	0.0	-11.37	6.684	0.00	396.2
1675	-0.2	-11.39	6.696	-0.04	396.8
1678	0.0	-11.41	6.708	0.00	397.6
1681	0.0	-11.43	6.720	0.00	398.2
1684	0.2	-11.45	6.732	0.04	399.0
1687	0.0	-11.47	6.744	0.00	399.6
1690	0.0	-11.49	6.756	0.00	400.4
1693	-0.2	-11.51	6.768	-0.04	401.0
1696	0.0	-11.53	6.780	0.00	401.8
1699	0.0	-11.56	6.792	0.00	402.8
1702	0.0	-11.58	6.804	0.00	403.4
1705	0.0	-11.60	6.816	0.00	404.2
1708	-0.4	-11.62	6.828	-0.06	404.8
1711	0.0	-11.64	6.840	0.00	405.6
1714	0.0	-11.66	6.852	0.00	406.2
1717	0.0	-11.68	6.864	0.00	407.0
1720	0.0	-11.70	6.876	0.00	407.6
1723	0.0	-11.72	6.888	0.00	408.4
1726	0.0	-11.74	6.900	0.00	409.0
1729	0.0	-11.76	6.912	0.00	409.8
1732	0.0	-11.78	6.924	0.00	410.4
1735	0.0	-11.81	6.936	0.00	411.4
1738	0.2	-11.83	6.948	0.04	412.2
1741	0.0	-11.85	6.960	0.00	412.8
1744	-0.2	-11.87	6.972	-0.04	413.6
1747	0.0	-11.89	6.984	0.00	414.2
1750	-0.2	-11.91	6.996	-0.04	415.0
1753	0.4	-11.93	7.008	0.06	415.6
1756	-0.2	-11.95	7.020	-0.04	416.4
1759	0.0	-11.97	7.032	0.00	417.0
1762	0.0	-11.99	7.044	0.00	417.8
1765	0.0	-12.01	7.056	0.00	418.4
1768	0.2	-12.05	7.068	0.04	419.8
1771	0.0	-12.06	7.080	0.00	420.2
1774	0.2	-12.09	7.092	0.04	421.2
1777	-0.2	-12.11	7.104	-0.04	422.0
1780	0.0	-12.13	7.116	0.00	422.6
1783	0.0	-12.15	7.128	0.00	423.4
1786	0.0	-12.17	7.140	0.00	424.0
1789	0.0	-12.19	7.152	0.00	424.8
1792	0.0	-12.21	7.164	0.00	425.4
1795	0.0	-12.23	7.176	0.00	426.2
1798	0.0	-12.25	7.188	0.00	426.8
1801	0.0	-12.28	7.200	0.00	427.8
1804	0.0	-12.30	7.212	0.00	428.6
1807	0.0	-12.32	7.224	0.00	429.2
1810	-0.2	-12.34	7.236	-0.04	430.0
1813	0.2	-12.36	7.248	0.04	430.6
1816	0.0	-12.38	7.260	0.00	431.4
1819	0.0	-12.40	7.272	0.00	432.0
1822	0.2	-12.42	7.284	0.04	432.8
1825	0.0	-12.44	7.296	0.00	433.4
1828	0.0	-12.46	7.308	0.00	434.2
1831	-0.2	-12.48	7.320	-0.04	434.8
1834	0.0	-12.50	7.332	0.00	435.6
1837	0.2	-12.53	7.344	0.04	436.6
1840	0.2	-12.55	7.356	0.04	437.2
1843	-0.2	-12.57	7.368	-0.04	438.0
1846	0.0	-12.59	7.380	0.00	438.6
1849	0.0	-12.61	7.392	0.00	439.4
1852	0.0	-12.63	7.404	0.00	440.0
1855	0.0	-12.65	7.416	0.00	440.8
1858	0.0	-12.67	7.428	0.00	441.4
1861	-0.6	-12.69	7.440	-0.10	442.2
1864	0.0	-12.71	7.452	0.00	442.8
1867	0.0	-12.73	7.464	0.00	443.6
1870	0.0	-12.76	7.476	0.00	444.6
1873	0.0	-12.78	7.488	0.00	445.2
1876	0.2	-12.80	7.500	0.04	446.0
1879	-0.2	-12.82	7.512	-0.04	446.6
1882	0.0	-12.84	7.524	0.00	447.4
1885	0.0	-12.86	7.536	0.00	448.0
1888	0.0	-12.88	7.548	0.00	448.8
1891	0.0	-12.90	7.560	0.00	449.4
1894	0.0	-12.92	7.572	0.00	450.2
1897	0.0	-12.94	7.584	0.00	450.8
1900	0.0	-12.96	7.596	0.00	451.6
1903	0.0	-12.99	7.608	0.00	452.6
1906	0.0	-13.01	7.620	0.00	453.4
1909	0.0	-13.03	7.632	0.00	454.0
1912	0.0	-13.05	7.644	0.00	454.8
1915	0.0	-13.07	7.656	0.00	455.4
1918	0.2	-13.09	7.668	0.04	456.0
1921	0.0	-13.11	7.680	0.00	456.8
1924	-0.6	-13.13	7.692	-0.10	457.4
1927	-0.2	-13.15	7.704	-0.04	458.2
1930	0.0	-13.18	7.716	0.00	459.2
1933	0.0	-13.20	7.728	0.00	460.0
1936	-0.2	-13.22	7.740	-0.04	460.6
1939	0.0	-13.24	7.752	0.00	461.4
1942	0.0	-13.26	7.764	0.00	462.0
1945	0.0	-13.28	7.776	0.00	462.8
1948	0.0	-13.30	7.788	0.00	463.4
1951	-0.2	-13.32	7.800	-0.04	464.2
1954	0.0	-13.34	7.812	0.00	464.8
1957	0.2	-13.37	7.824	0.04	465.8
1960	-0.2	-13.39	7.836	-0.04	466.6
1963	0.0	-13.41	7.848	0.00	467.2
1966	0.0	-13.43	7.860	0.00	468.0
1969	0.0	-13.45	7.872	0.00	468.6
1972	0.2	-13.47	7.884	0.04	469.4
1975	0.2	-13.49	7.896	0.04	470.0
1978	0.0	-13.51	7.908	0.00	470.8
1981	-0.2	-13.53	7.920	-0.04	471.4
1984	0.0	-13.56	7.932	0.00	472.4
1987	0.0	-13.58	7.944	0.00	473.2
1990	-0.2	-13.60	7.956	-0.04	473.8
1993	0.0	-13.62	7.968	0.00	474.6
1996	0.0	-13.64	7.980	0.00	475.2
1999	0.2	-13.66	7.992	0.04	476.0
2002	0.2	-13.68	8.004	0.04	476.6
2005	0.0	-13.70	8.016	0.00	477.4
2008	0.0	-13.72	8.028	0.00	478.0
2011	-0.2	-13.75	8.040	-0.04	479.0
2014	-0.2	-13.77	8.052	-0.04	479.8
2017	0.0	-13.79	8.064	0.00	480.4
2020	0.0	-13.81	8.076	0.00	481.2
2023	0.2	-13.83	8.088	0.04	481.8
2026	0.0	-13.85	8.100	0.00	482.6
2029	0.0	-13.87	8.112	0.00	483.2
2032	0.0	-13.89	8.124	0.00	484.0
2035	0.0	-13.91	8.136	0.00	484.6
2038	0.0	-13.94	8.148	0.00	485.8
2041	0.0	-13.96	8.160	0.00	486.4
2044	0.0	-13.98	8.172	0.00	487.2
2047	0.0	-14.00	8.184	0.00	487.8
2050	0.0	-14.02	8.196	0.00	488.6
2053	0.2	-14.04	8.208	0.04	489.2
2056	0.0	-14.06	8.220	0.00	489.8
2059	0.0	-14.09	8.232	0.00	491.0
2062	0.0	-14.10	8.244	0.00	491.2
2065	-0.2	-14.13	8.256	-0.04	492.4
2068	0.0	-14.15	8.268	0.00	493.0
2071	0.2	-14.17	8.280	0.04	493.8
2074	0.2	-14.19	8.292	0.04	494.4
2077	0.0	-14.21	8.304	0.00	495.2
2080	0.0	-14.23	8.316	0.00	495.8
2083	-0.2	-14.25	8.328	-0.04	496.6
2086	0.0	-14.28	8.340	0.00	497.6
2089	-0.2	-14.30	8.352	-0.04	498.2
2092	-0.2	-14.32	8.364	-0.04	499.0
2095	0.2	-14.34	8.376	0.04	499.6
2098	0.2	-14.36	8.388	0.04	500.4
2101	-0.2	-14.38	8.400	-0.04	501.0
2104	0.0	-14.40	8.412	0.00	501.8
2107	-0.2	-14.42	8.424	-0.04	502.4
2110	-0.4	-14.44	8.436	-0.06	503.2
2113	0.2	-14.47	8.448	0.04	504.2
2116	0.2	-14.49	8.460	0.04	504.8
2119	0.0	-14.51	8.472	0.00	505.6
2122	0.0	-14.53	8.484	0.00	506.2
2125	-0.2	-14.55	8.496	-0.04	507.0
2128	0.0	-14.57	8.508	0.00	507.6
2131	0.0	-14.59	8.520	0.00	508.4
2134	0.0	-14.61	8.532	0.00	509.0
2137	0.2	-14.63	8.544	0.04	509.8
2140	-0.2	-14.66	8.556	-0.04	510.8
2143	0.4	-14.68	8.568	0.06	511.4
2146	-0.2	-14.70	8.580	-0.04	512.2
2149	0.0	-14.72	8.592	0.00	512.8
2152	-0.2	-14.74	8.604	-0.04	513.6
2155	0.0	-14.76	8.616	0.00	514.2
2158	0.0	-14.78	8.628	0.00	515.0
2161	-0.2	-14.80	8.640	-0.04	515.6
2164	0.0	-14.82	8.652	0.00	516.4
2167	0.2	-14.85	8.664	0.04	517.4
2170	0.0	-14.87	8.676	0.00	518.2
2173	0.0	-14.89	8.688	0.00	518.8
2176	-0.4	-14.91	8.700	-0.06	519.6
2179	0.0	-14.93	8.712	0.00	520.2
2182	0.0	-14.95	8.724	0.00	521.0
2185	0.0	-14.97	8.736	0.00	521.6
2188	-0.2	-14.99	8.748	-0.04	522.2
2191	0.2	-15.01	8.760	0.04	523.0
2194	-0.2	-15.04	8.772	-0.04	524.0
2197	-0.2	-15.05	8.784	-0.04	524.4
2200	-0.4	-15.07	8.796	-0.06	525.0
2203	-0.4	-15.09	8.808	-0.06	525.8
2206	0.0	-15.11	8.820	0.00	526.4
2209	0.2	-15.13	8.832	0.04	527.2
2212	0.0	-15.15	8.844	0.00	527.8
2215	0.0	-15.17	8.856	0.00	528.6
2218	0.0	-15.19	8.868	0.00	529.2
2221	0.4	-15.22	8.880	0.06	530.4
2224	0.0	-15.24	8.892	0.00	531.0
2227	-0.2	-15.26	8.904	-0.04	531.8
2230	0.0	-15.28	8.916	0.00	532.4
2233	0.0	-15.30	8.928	0.00	533.2
2236	0.2	-15.32	8.940	0.04	533.8
2239	0.0	-15.34	8.952	0.00	534.4
2242	-0.2	-15.36	8.964	-0.04	535.2
2245	0.0	-15.38	8.976	0.00	535.8
2248	-0.2	-15.41	8.988	-0.04	537.0
2251	-0.2	-15.43	9.000	-0.04	537.6
2254	0.0	-15.45	9.012	0.00	538.4
2257	0.0	-15.47	9.024	0.00	539.0
2260	0.0	-15.49	9.036	0.00	539.8
2263	0.0	-15.51	9.048	0.00	540.4
2266	0.4	-15.53	9.060	0.06	541.2
2269	0.0	-15.55	9.072	0.00	541.8
2272	-0.2	-15.57	9.084	-0.04	542.6
2275	0.0	-15.59	9.096	0.00	543.2
2278	0.0	-15.61	9.108	0.00	544.0
2281	0.0	-15.64	9.120	0.00	545.0
2284	0.0	-15.66	9.132	0.00	545.6
2287	0.0	-15.68	9.144	0.00	546.4
2290	0.0	-15.70	9.156	0.00	547.0
2293	0.0	-15.72	9.168	0.00	547.8
2296	-0.2	-15.74	9.180	-0.04	548.4
2299	0.0	-15.76	9.192	0.00	549.2
2302	0.0	-15.78	9.204	0.00	549.8
2305	0.0	-15.80	9.216	0.00	550.6
2308	0.2	-15.82	9.228	0.04	551.2
2311	-0.2	-15.84	9.240	-0.04	552.0
2314	0.0	-15.87	9.252	0.00	553.0
2317	0.0	-15.89	9.264	0.00	553.6
2320	0.0	-15.91	9.276	0.00	554.4
2323	0.0	-15.93	9.288	0.00	555.0
2326	0.0	-15.95	9.300	0.00	555.8
2329	0.0	-15.97	9.312	0.00	556.4
2332	-0.2	-15.99	9.324	-0.04	557.2
2335	-0.2	-16.01	9.336	-0.04	557.8
2338	0.0	-16.03	9.348	0.00	558.6
2341	0.0	-16.05	9.360	0.00	559.2
2344	0.0	-16.07	9.372	0.00	560.0
2347	0.0	-16.09	9.384	0.00	560.6
2350	0.0	-16.12	9.396	0.00	561.6
2353	0.0	-16.14	9.408	0.00	562.4
2356	0.0	-16.16	9.420	0.00	563.0
2359	0.0	-16.18	9.432	0.00	563.8
2362	0.2	-16.20	9.444	0.04	564.4
2365	0.0	-16.22	9.456	0.00	565.2
2368	-0.4	-16.24	9.468	-0.06	565.8
2371	-0.2	-16.26	9.480	-0.04	566.6
2374	0.2	-16.28	9.492	0.04	567.2
2377	-0.4	-16.30	9.504	-0.06	568.0
2380	-0.2	-16.32	9.516	-0.04	568.6
2383	0.4	-16.35	9.528	0.06	569.6
2386	0.0	-16.37	9.540	0.00	570.4
2389	0.0	-16.39	9.552	0.00	571.0
2392	0.0	-16.41	9.564	0.00	571.8
2395	0.2	-16.43	9.576	0.04	572.4
2398	0.0	-16.45	9.588	0.00	573.2
2401	0.0	-16.47	9.600	0.00	573.8
2404	0.2	-16.49	9.612	0.04	574.6
2407	0.0	-16.51	9.624	0.00	575.2
2410	-0.2	-16.53	9.636	-0.04	576.0
2413	0.0	-16.55	9.648	0.00	576.6
2416	0.2	-16.57	9.660	0.04	577.4
2419	-0.2	-16.59	9.672	-0.04	578.0
2422	0.2	-16.62	9.684	0.04	579.0
2425	0.0	-16.64	9.696	0.00	579.8
2428	0.0	-16.66	9.708	0.00	580.4
2431	-0.4	-16.68	9.720	-0.06	581.2
2434	0.0	-16.70	9.732	0.00	581.8
2437	0.0	-16.72	9.744	0.00	582.6
2440	-0.2	-16.74	9.756	-0.04	583.2
2443	0.0	-16.76	9.768	0.00	584.0
2446	0.0	-16.78	9.780	0.00	584.6
2449	0.0	-16.80	9.792	0.00	585.4
2452	-0.2	-16.82	9.804	-0.04	586.0
2455	0.0	-16.84	9.816	0.00	586.8
2458	0.0	-16.87	9.828	0.00	587.8
2461	0.2	-16.89	9.840	0.04	588.6
2464	0.0	-16.91	9.852	0.00	589.2
2467	0.0	-16.93	9.864	0.00	589.8
2470	0.0	-16.95	9.876	0.00	590.6
2473	0.0	-16.97	9.888	0.00	591.2
2476	0.0	-16.99	9.900	0.00	592.0
2479	0.0	-17.01	9.912	0.00	592.6
2482	0.0	-17.04	9.924	0.00	593.8
2485	0.0	-17.06	9.936	0.00	594.4
2488	0.0	-17.08	9.948	0.00	595.2
2491	0.0	-17.11	9.960	0.00	596.2
2494	0.0	-17.13	9.972	0.00	596.8
2497	0.0	-17.15	9.984	0.00	597.6
2500	0.2	-17.17	9.996	0.04	598.2
2503	0.0	-17.19	10.008	0.00	599.0
2506	-0.4	-17.21	10.020	-0.06	599.6
2509	-0.2	-17.23	10.032	-0.04	600.4
2512	0.0	-17.25	10.044	0.00	601.0
2515	0.0	-17.27	10.056	0.00	601.8
2518	-0.2	-17.29	10.068	-0.04	602.4
2521	0.0	-17.31	10.080	0.00	603.2
2524	-0.2	-17.34	10.092	-0.04	604.2
2527	0.0	-17.36	10.104	0.00	604.8
2530	0.0	-17.38	10.116	0.00	605.6
2533	-0.6	-17.40	10.128	-0.10	606.2
2536	0.0	-17.42	10.140	0.00	607.0
2539	0.2	-17.44	10.152	0.04	607.6
2542	0.0	-17.46	10.164	0.00	608.4
2545	0.0	-17.48	10.176	0.00	609.0
2548	0.0	-17.50	10.188	0.00	609.8
2551	0.0	-17.52	10.200	0.00	610.4
2554	-0.4	-17.54	10.212	-0.06	611.2
2557	0.0	-17.56	10.224	0.00	611.8
2560	-0.2	-17.59	10.236	-0.04	612.8
2563	0.0	-17.61	10.248	0.00	613.6
2566	0.2	-17.63	10.260	0.04	614.2
2569	0.0	-17.65	10.272	0.00	615.0
2572	-0.4	-17.67	10.284	-0.06	615.6
2575	-0.4	-17.69	10.296	-0.06	616.4
2578	0.0	-17.71	10.308	0.00	617.0
2581	0.0	-17.73	10.320	0.00	617.8
2584	0.0	-17.75	10.332	0.00	618.4
2587	0.0	-17.77	10.344	0.00	619.2
2590	0.0	-17.79	10.356	0.00	619.8
2593	-0.2	-17.82	10.368	-0.04	621.0
2596	0.0	-17.84	10.380	0.00	621.6
2599	0.0	-17.86	10.392	0.00	622.2
2602	0.0	-17.88	10.404	0.00	623.0
2605	0.2	-17.90	10.416	0.04	623.6
2608	0.0	-17.92	10.428	0.00	624.4
2611	0.0	-17.94	10.440	0.00	625.0
2614	0.0	-17.96	10.452	0.00	625.8
2617	0.0	-17.98	10.464	0.00	626.4
2620	-0.6	-18.00	10.476	-0.10	627.2
2623	-0.2	-18.02	10.488	-0.04	627.8
2626	0.0	-18.05	10.500	0.00	629.0
2629	0.0	-18.07	10.512	0.00	629.6
2632	-0.2	-18.09	10.524	-0.04	630.4
2635	0.0	-18.11	10.536	0.00	631.0
2638	0.0	-18.13	10.548	0.00	631.8
2641	0.0	-18.15	10.560	0.00	632.4
2644	0.0	-18.17	10.572	0.00	633.2
2647	0.0	-18.19	10.584	0.00	633.8
2650	0.0	-18.21	10.596	0.00	634.4
2653	-0.4	-18.24	10.608	-0.06	635.6
2656	0.0	-18.26	10.620	0.00	636.2
2659	0.0	-18.28	10.632	0.00	637.0
2662	0.0	-18.30	10.644	0.00	637.6
2665	0.2	-18.32	10.656	0.04	638.4
2668	-0.2	-18.34	10.668	-0.04	639.0
2671	0.0	-18.36	10.680	0.00	639.8
2674	0.0	-18.38	10.692	0.00	640.4
2677	0.0	-18.40	10.704	0.00	641.2
2680	0.0	-18.42	10.716	0.00	641.8
2683	0.4	-18.45	10.728	0.06	642.8
2686	0.0	-18.47	10.740	0.00	643.6
2689	0.2	-18.49	10.752	0.04	644.2
2692	0.0	-18.51	10.764	0.00	645.0
2695	0.2	-18.53	10.776	0.04	645.6
2698	0.0	-18.55	10.788	0.00	646.4
2701	-0.2	-18.57	10.800	-0.04	647.0
2704	0.0	-18.59	10.812	0.00	647.8
2707	0.0	-18.61	10.824	0.00	648.4
2710	0.0	-18.63	10.836	0.00	649.2
2713	0.0	-18.66	10.848	0.00	650.2
2716	0.2	-18.68	10.860	0.04	650.8
2719	-0.2	-18.70	10.872	-0.04	651.6
2722	-0.2	-18.72	10.884	-0.04	652.2
2725	0.0	-18.74	10.896	0.00	653.0
2728	0.0	-18.76	10.908	0.00	653.6
2731	0.0	-18.78	10.920	0.00	654.4
2734	0.0	-18.80	10.932	0.00	655.0
2737	-0.2	-18.82	10.944	-0.04	655.8
2740	0.0	-18.85	10.956	0.00	656.8
2743	0.0	-18.87	10.968	0.00	657.4
2746	0.0	-18.89	10.980	0.00	658.2
2749	0.0	-18.91	10.992	0.00	658.8
2752	0.0	-18.93	11.004	0.00	659.6
2755	0.0	-18.95	11.016	0.00	660.2
2758	-0.4	-18.97	11.028	-0.06	661.0
2761	0.0	-18.99	11.040	0.00	661.6
2764	0.2	-19.02	11.052	0.04	662.8
2767	-0.2	-19.04	11.064	-0.04	663.4
2770	0.0	-19.05	11.076	0.00	663.8
2773	0.0	-19.07	11.088	0.00	664.4
2776	-0.2	-19.09	11.100	-0.04	665.2
2779	0.0	-19.11	11.112	0.00	665.8
2782	-0.4	-19.13	11.124	-0.06	666.6
2785	-0.2	-19.15	11.136	-0.04	667.2
2788	0.0	-19.18	11.148	0.00	668.2
2791	-0.2	-19.20	11.160	-0.04	669.0
2794	0.0	-19.22	11.172	0.00	669.6
2797	0.0	-19.24	11.184	0.00	670.4
2800	0.2	-19.26	11.196	0.04	671.0
2803	0.4	-19.28	11.208	0.06	671.8
2806	0.6	-19.30	11.220	0.10	672.4
2809	0.8	-19.32	11.232	0.12	673.2
2812	1.0	-19.34	11.244	0.16	673.8
2815	1.4	-19.37	11.256	0.22	675.0
2818	1.8	-19.39	11.268	0.28	675.6
2821	2.0	-19.41	11.280	0.30	676.4
2824	2.2	-19.43	11.292	0.34	677.0
2827	2.4	-19.45	11.304	0.36	677.8
2830	3.0	-19.47	11.316	0.46	678.4
2833	3.2	-19.49	11.328	0.50	679.0
2836	3.2	-19.51	11.340	0.50	679.8
2839	3.8	-19.53	11.352	0.58	680.4
2842	5.0	-19.55	11.364	0.76	681.2
2845	6.6	-19.57	11.376	1.02	681.8
2848	8.6	-19.59	11.388	1.32	682.6
2851	11.8	-19.61	11.400	1.82	683.2
2854	14.4	-19.63	11.412	2.22	684.0
2857	18.6	-19.65	11.424	2.86	684.6
2860	22.6	-19.67	11.436	3.46	685.4
2863	27.2	-19.68	11.448	4.18	685.8
2866	31.8	-19.70	11.460	4.88	686.4
2869	37.0	-19.72	11.472	5.68	687.2
2872	41.8	-19.73	11.484	6.42	687.4
2875	46.8	-19.75	11.496	7.18	688.2
2878	52.2	-19.77	11.508	8.02	688.8
2881	63.2	-19.78	11.520	9.70	689.2
2884	72.4	-19.79	11.532	11.12	689.6
2887	80.0	-19.81	11.544	12.28	690.2
2890	94.6	-19.81	11.556	14.52	690.2
2893	107.8	-19.82	11.568	16.54	690.6
2896	119.0	-19.83	11.580	18.26	691.0
2899	126.4	-19.85	11.592	19.40	691.6
2902	108.2	-19.89	11.604	16.60	693.0
2905	109.6	-19.91	11.616	16.82	693.8
2908	113.8	-19.92	11.628	17.46	694.0
2911	115.2	-19.94	11.640	17.68	694.8
2914	113.0	-19.97	11.652	17.34	695.8
2917	113.4	-19.99	11.664	17.40	696.6
2920	113.8	-20.01	11.676	17.46	697.2
2923	114.4	-20.03	11.688	17.56	698.0
2926	114.0	-20.05	11.700	17.50	698.6
2929	113.0	-20.07	11.712	17.34	699.4
2932	98.4	-20.11	11.724	15.10	700.6
2935	102.2	-20.12	11.736	15.68	701.0
2938	105.2	-20.14	11.748	16.14	701.8
2941	104.6	-20.16	11.760	16.06	702.4
2944	102.6	-20.19	11.772	15.74	703.4
2947	101.4	-20.21	11.784	15.56	704.2
2950	101.0	-20.23	11.796	15.50	704.8
2953	101.0	-20.25	11.808	15.50	705.6
2956	100.6	-20.27	11.820	15.44	706.2
2959	101.2	-20.29	11.832	15.54	707.0
2962	101.6	-20.31	11.844	15.60	707.6
2965	104.0	-20.33	11.856	15.96	708.4
2968	106.2	-20.35	11.868	16.30	709.0
2971	106.4	-20.37	11.880	16.34	709.8
2974	107.6	-20.39	11.892	16.52	710.4
2977	108.8	-20.41	11.904	16.70	711.2
2980	108.2	-20.43	11.916	16.60	711.8
2983	104.8	-20.46	11.928	16.08	712.8
2986	99.0	-20.48	11.940	15.20	713.6
2989	92.2	-20.50	11.952	14.16	714.2
2992	87.0	-20.51	11.964	13.36	714.6
2995	82.6	-20.52	11.976	12.68	715.0
2998	80.4	-20.52	11.988	12.34	715.0
3001	78.8	-20.52	12.000	12.10	715.0
3004	77.6	-20.52	12.012	11.92	715.0
3007	76.4	-20.52	12.024	11.72	715.0
3010	75.4	-20.52	12.036	11.58	715.0