File: results/youngs-modulus/2025-04-25/inconclusive-data/pf13mt01.csv
sep=
pf13mt01

System Information:
IntelliMESUR Version: 2.2.1
Test Frame Model: F505
Test Frame Serial Number: 4418651
Test Frame Capacity: 500 lbF / 2.2 kN
Test Frame Firmware Version: 1.00.14
Force Sensor Model: FS05-100
Force Sensor Capacity: 500 N
Force Sensor Resolution: 0.2 N
Force Sensor Serial Number: 4425350
Calibration Date: Apr 29, 2024
Calibration Due Date: Apr 29, 2025

Reading	Load [N]	Distance [mm]	Time [s]	Stress [MPa]	Strain [%]
1	0.2	0.00	0.000	0.10	0.0
4	0.2	0.00	0.012	0.10	0.0
7	0.2	0.00	0.024	0.10	0.0
10	0.0	0.00	0.036	0.00	0.0
13	0.2	0.00	0.048	0.10	0.0
16	0.4	0.00	0.060	0.15	0.0
19	0.2	0.00	0.072	0.10	0.0
22	0.2	0.00	0.084	0.10	0.0
25	0.2	0.00	0.096	0.10	0.0
28	0.2	0.00	0.108	0.10	0.0
31	0.2	0.00	0.120	0.10	0.0
34	0.2	0.00	0.132	0.10	0.0
37	0.2	0.00	0.144	0.10	0.0
40	0.2	0.00	0.156	0.10	0.0
43	0.2	0.00	0.168	0.10	0.0
46	0.2	0.00	0.180	0.10	0.0
49	0.2	-0.01	0.192	0.10	0.5
52	0.4	-0.03	0.204	0.15	1.5
55	0.2	-0.05	0.216	0.10	3.0
58	0.2	-0.07	0.228	0.10	4.0
61	0.2	-0.09	0.240	0.10	5.0
64	0.4	-0.12	0.252	0.15	6.5
67	0.2	-0.14	0.264	0.10	7.5
70	0.0	-0.16	0.276	0.00	9.0
73	0.2	-0.18	0.288	0.10	10.0
76	0.0	-0.20	0.300	0.00	11.0
79	0.0	-0.22	0.312	0.00	12.0
82	0.2	-0.24	0.324	0.10	13.5
85	0.2	-0.26	0.336	0.10	14.5
88	0.2	-0.29	0.348	0.10	16.0
91	0.2	-0.31	0.360	0.10	17.0
94	0.2	-0.33	0.372	0.10	18.0
97	0.2	-0.35	0.384	0.10	19.5
100	0.2	-0.36	0.396	0.10	20.0
103	-0.2	-0.38	0.408	-0.10	21.0
106	0.0	-0.40	0.420	0.00	22.0
109	0.2	-0.42	0.432	0.10	23.0
112	0.2	-0.44	0.444	0.10	24.5
115	0.2	-0.47	0.456	0.10	26.0
118	0.2	-0.49	0.468	0.10	27.0
121	0.2	-0.51	0.480	0.10	28.0
124	0.4	-0.53	0.492	0.15	29.5
127	0.2	-0.55	0.504	0.10	30.5
130	0.2	-0.57	0.516	0.10	31.5
133	0.0	-0.59	0.528	0.00	32.5
136	0.2	-0.61	0.540	0.10	33.5
139	0.2	-0.63	0.552	0.10	35.0
142	0.2	-0.66	0.564	0.10	36.5
145	0.2	-0.68	0.576	0.10	37.5
148	0.2	-0.70	0.588	0.10	38.5
151	0.2	-0.72	0.600	0.10	40.0
154	0.2	-0.74	0.612	0.10	41.0
157	0.2	-0.76	0.624	0.10	42.0
160	0.4	-0.78	0.636	0.15	43.0
163	0.6	-0.80	0.648	0.25	44.0
166	0.0	-0.82	0.660	0.00	45.5
169	0.2	-0.84	0.672	0.10	46.5
172	0.2	-0.86	0.684	0.10	47.5
175	0.2	-0.89	0.696	0.10	49.0
178	0.0	-0.91	0.708	0.00	50.5
181	0.6	-0.93	0.720	0.25	51.5
184	0.0	-0.95	0.732	0.00	52.5
187	0.4	-0.97	0.744	0.15	53.5
190	0.2	-0.99	0.756	0.10	54.5
193	0.2	-1.01	0.768	0.10	56.0
196	0.2	-1.03	0.780	0.10	57.0
199	0.4	-1.05	0.792	0.15	58.0
202	0.2	-1.07	0.804	0.10	59.0
205	0.2	-1.10	0.816	0.10	61.0
208	0.2	-1.12	0.828	0.10	62.0
211	0.2	-1.14	0.840	0.10	63.0
214	0.2	-1.16	0.852	0.10	64.0
217	0.2	-1.18	0.864	0.10	65.0
220	0.2	-1.20	0.876	0.10	66.5
223	0.4	-1.22	0.888	0.15	67.5
226	0.2	-1.24	0.900	0.10	68.5
229	0.4	-1.26	0.912	0.15	69.5
232	0.2	-1.28	0.924	0.10	70.5
235	0.2	-1.30	0.936	0.10	72.0
238	0.2	-1.33	0.948	0.10	73.5
241	0.2	-1.35	0.960	0.10	74.5
244	0.0	-1.38	0.972	0.00	76.0
247	0.2	-1.40	0.984	0.10	77.5
250	0.4	-1.42	0.996	0.15	78.5
253	0.2	-1.44	1.008	0.10	79.5
256	0.4	-1.46	1.020	0.15	80.5
259	0.4	-1.48	1.032	0.15	82.0
262	0.2	-1.50	1.044	0.10	83.0
265	0.2	-1.52	1.056	0.10	84.0
268	0.4	-1.54	1.068	0.15	85.0
271	0.4	-1.57	1.080	0.15	86.5
274	0.2	-1.59	1.092	0.10	88.0
277	0.2	-1.61	1.104	0.10	89.0
280	0.2	-1.63	1.116	0.10	90.0
283	0.0	-1.65	1.128	0.00	91.0
286	0.2	-1.67	1.140	0.10	92.5
289	0.2	-1.69	1.152	0.10	93.5
292	0.2	-1.71	1.164	0.10	94.5
295	0.4	-1.73	1.176	0.15	95.5
298	0.2	-1.75	1.188	0.10	96.5
301	0.2	-1.77	1.200	0.10	98.0
304	0.2	-1.80	1.212	0.10	99.5
307	0.0	-1.82	1.224	0.00	100.5
310	0.2	-1.84	1.236	0.10	101.5
313	0.2	-1.86	1.248	0.10	103.0
316	0.4	-1.88	1.260	0.15	104.0
319	0.2	-1.90	1.272	0.10	105.0
322	0.2	-1.92	1.284	0.10	106.0
325	0.2	-1.94	1.296	0.10	107.0
328	0.2	-1.96	1.308	0.10	108.5
331	0.2	-1.98	1.320	0.10	109.5
334	0.2	-2.00	1.332	0.10	110.5
337	0.2	-2.02	1.344	0.10	111.5
340	0.2	-2.05	1.356	0.10	113.5
343	0.0	-2.07	1.368	0.00	114.5
346	0.2	-2.09	1.380	0.10	115.5
349	0.2	-2.11	1.392	0.10	116.5
352	0.2	-2.13	1.404	0.10	117.5
355	0.2	-2.15	1.416	0.10	119.0
358	0.4	-2.17	1.428	0.15	120.0
361	0.2	-2.19	1.440	0.10	121.0
364	0.0	-2.21	1.452	0.00	122.0
367	0.6	-2.23	1.464	0.25	123.0
370	0.4	-2.25	1.476	0.15	124.5
373	0.2	-2.28	1.488	0.10	126.0
376	0.2	-2.30	1.500	0.10	127.0
379	0.4	-2.32	1.512	0.15	128.0
382	0.2	-2.34	1.524	0.10	129.5
385	0.2	-2.36	1.536	0.10	130.5
388	0.2	-2.37	1.548	0.10	131.0
391	0.2	-2.39	1.560	0.10	132.0
394	0.2	-2.41	1.572	0.10	133.0
397	0.0	-2.43	1.584	0.00	134.5
400	0.2	-2.45	1.596	0.10	135.5
403	0.4	-2.47	1.608	0.15	136.5
406	0.4	-2.49	1.620	0.15	137.5
409	0.2	-2.51	1.632	0.10	138.5
412	0.2	-2.54	1.644	0.10	140.5
415	0.0	-2.56	1.656	0.00	141.5
418	0.0	-2.58	1.668	0.00	142.5
421	0.2	-2.60	1.680	0.10	143.5
424	0.2	-2.62	1.692	0.10	145.0
427	0.2	-2.64	1.704	0.10	146.0
430	0.0	-2.66	1.716	0.00	147.0
433	0.2	-2.68	1.728	0.10	148.0
436	0.0	-2.70	1.740	0.00	149.0
439	0.4	-2.72	1.752	0.15	150.5
442	0.4	-2.74	1.764	0.15	151.5
445	0.6	-2.77	1.776	0.25	153.0
448	0.2	-2.79	1.788	0.10	154.0
451	0.2	-2.81	1.800	0.10	155.0
454	0.4	-2.83	1.812	0.15	156.5
457	0.4	-2.85	1.824	0.15	157.5
460	0.2	-2.87	1.836	0.10	158.5
463	0.2	-2.89	1.848	0.10	159.5
466	0.0	-2.91	1.860	0.00	161.0
469	0.2	-2.93	1.872	0.10	162.0
472	0.2	-2.95	1.884	0.10	163.0
475	0.2	-2.98	1.896	0.10	164.5
478	0.4	-3.00	1.908	0.15	165.5
481	0.2	-3.02	1.920	0.10	167.0
484	0.0	-3.04	1.932	0.00	168.0
487	0.0	-3.06	1.944	0.00	169.0
490	0.0	-3.08	1.956	0.00	170.0
493	0.2	-3.10	1.968	0.10	171.5
496	0.0	-3.12	1.980	0.00	172.5
499	0.4	-3.14	1.992	0.15	173.5
502	0.4	-3.16	2.004	0.15	174.5
505	0.4	-3.18	2.016	0.15	175.5
508	0.2	-3.21	2.028	0.10	177.5
511	0.2	-3.23	2.040	0.10	178.5
514	0.2	-3.25	2.052	0.10	179.5
517	0.2	-3.27	2.064	0.10	180.5
520	0.0	-3.29	2.076	0.00	182.0
523	0.2	-3.31	2.088	0.10	183.0
526	0.2	-3.33	2.100	0.10	184.0
529	0.4	-3.36	2.112	0.15	185.5
532	0.2	-3.38	2.124	0.10	186.5
535	0.2	-3.41	2.136	0.10	188.5
538	0.2	-3.43	2.148	0.10	189.5
541	0.0	-3.45	2.160	0.00	190.5
544	0.2	-3.47	2.172	0.10	191.5
547	0.6	-3.49	2.184	0.25	193.0
550	0.2	-3.51	2.196	0.10	194.0
553	0.2	-3.53	2.208	0.10	195.0
556	0.2	-3.55	2.220	0.10	196.0
559	0.4	-3.57	2.232	0.15	197.0
562	0.2	-3.60	2.244	0.10	199.0
565	0.6	-3.61	2.256	0.25	199.5
568	0.2	-3.64	2.268	0.10	201.0
571	0.0	-3.66	2.280	0.00	202.0
574	0.4	-3.68	2.292	0.15	203.5
577	0.2	-3.70	2.304	0.10	204.5
580	0.2	-3.72	2.316	0.10	205.5
583	0.2	-3.74	2.328	0.10	206.5
586	0.0	-3.76	2.340	0.00	207.5
589	0.2	-3.78	2.352	0.10	209.0
592	0.4	-3.80	2.364	0.15	210.0
595	0.4	-3.83	2.376	0.15	211.5
598	0.0	-3.85	2.388	0.00	212.5
601	0.2	-3.87	2.400	0.10	214.0
604	0.0	-3.89	2.412	0.00	215.0
607	0.2	-3.91	2.424	0.10	216.0
610	0.2	-3.93	2.436	0.10	217.0
613	0.2	-3.95	2.448	0.10	218.0
616	0.2	-3.97	2.460	0.10	219.5
619	0.0	-3.99	2.472	0.00	220.5
622	0.2	-4.02	2.484	0.10	222.0
625	0.2	-4.04	2.496	0.10	223.0
628	0.4	-4.06	2.508	0.15	224.5
631	0.2	-4.08	2.520	0.10	225.5
634	0.2	-4.10	2.532	0.10	226.5
637	0.4	-4.12	2.544	0.15	227.5
640	0.2	-4.14	2.556	0.10	228.5
643	0.0	-4.16	2.568	0.00	230.0
646	0.4	-4.18	2.580	0.15	231.0
649	0.2	-4.21	2.592	0.10	232.5
652	0.2	-4.23	2.604	0.10	233.5
655	0.2	-4.25	2.616	0.10	235.0
658	0.2	-4.27	2.628	0.10	236.0
661	0.2	-4.29	2.640	0.10	237.0
664	0.2	-4.31	2.652	0.10	238.0
667	0.2	-4.33	2.664	0.10	239.0
670	0.6	-4.36	2.676	0.25	241.0
673	0.2	-4.38	2.688	0.10	242.0
676	0.2	-4.40	2.700	0.10	243.0
679	0.2	-4.42	2.712	0.10	244.0
682	0.2	-4.44	2.724	0.10	245.5
685	0.2	-4.46	2.736	0.10	246.5
688	0.2	-4.48	2.748	0.10	247.5
691	0.4	-4.50	2.760	0.15	248.5
694	0.2	-4.52	2.772	0.10	249.5
697	0.2	-4.55	2.784	0.10	251.5
700	0.2	-4.57	2.796	0.10	252.5
703	0.4	-4.59	2.808	0.15	253.5
706	0.2	-4.61	2.820	0.10	254.5
709	0.6	-4.63	2.832	0.25	256.0
712	0.2	-4.65	2.844	0.10	257.0
715	0.2	-4.67	2.856	0.10	258.0
718	0.2	-4.69	2.868	0.10	259.0
721	0.2	-4.71	2.880	0.10	260.0
724	0.4	-4.74	2.892	0.15	262.0
727	0.0	-4.76	2.904	0.00	263.0
730	0.2	-4.78	2.916	0.10	264.0
733	0.2	-4.80	2.928	0.10	265.0
736	0.4	-4.82	2.940	0.15	266.5
739	0.0	-4.84	2.952	0.00	267.5
742	0.4	-4.86	2.964	0.15	268.5
745	0.4	-4.88	2.976	0.15	269.5
748	0.2	-4.90	2.988	0.10	270.5
751	0.2	-4.93	3.000	0.10	272.5
754	0.2	-4.95	3.012	0.10	273.5
757	0.2	-4.97	3.024	0.10	274.5
760	0.2	-4.99	3.036	0.10	275.5
763	0.6	-5.01	3.048	0.25	277.0
766	0.2	-5.03	3.060	0.10	278.0
769	0.2	-5.05	3.072	0.10	279.0
772	0.2	-5.07	3.084	0.10	280.0
775	0.6	-5.09	3.096	0.25	281.0
778	0.2	-5.12	3.108	0.10	283.0
781	0.2	-5.14	3.120	0.10	284.0
784	0.4	-5.16	3.132	0.15	285.0
787	0.2	-5.18	3.144	0.10	286.0
790	0.0	-5.20	3.156	0.00	287.5
793	0.2	-5.22	3.168	0.10	288.5
796	0.2	-5.24	3.180	0.10	289.5
799	0.0	-5.26	3.192	0.00	290.5
802	0.4	-5.28	3.204	0.15	291.5
805	0.2	-5.31	3.216	0.10	293.5
808	0.2	-5.33	3.228	0.10	294.5
811	0.2	-5.35	3.240	0.10	295.5
814	0.2	-5.37	3.252	0.10	296.5
817	0.6	-5.39	3.264	0.25	298.0
820	0.2	-5.41	3.276	0.10	299.0
823	0.2	-5.43	3.288	0.10	300.0
826	0.2	-5.45	3.300	0.10	301.0
829	0.2	-5.47	3.312	0.10	302.0
832	-0.2	-5.50	3.324	-0.10	304.0
835	0.2	-5.52	3.336	0.10	305.0
838	0.2	-5.54	3.348	0.10	306.0
841	0.4	-5.56	3.360	0.15	307.0
844	0.2	-5.58	3.372	0.10	308.5
847	0.2	-5.60	3.384	0.10	309.5
850	0.2	-5.62	3.396	0.10	310.5
853	0.2	-5.64	3.408	0.10	311.5
856	0.0	-5.66	3.420	0.00	312.5
859	-0.2	-5.69	3.432	-0.10	314.5
862	0.2	-5.70	3.444	0.10	315.0
865	0.2	-5.73	3.456	0.10	316.5
868	0.2	-5.75	3.468	0.10	317.5
871	0.2	-5.77	3.480	0.10	319.0
874	0.2	-5.79	3.492	0.10	320.0
877	0.2	-5.81	3.504	0.10	321.0
880	0.2	-5.83	3.516	0.10	322.0
883	0.2	-5.85	3.528	0.10	323.0
886	0.0	-5.87	3.540	0.00	324.5
889	0.2	-5.89	3.552	0.10	325.5
892	0.0	-5.92	3.564	0.00	327.0
895	0.2	-5.94	3.576	0.10	328.0
898	0.4	-5.96	3.588	0.15	329.5
901	0.4	-5.98	3.600	0.15	330.5
904	0.4	-6.00	3.612	0.15	331.5
907	0.2	-6.02	3.624	0.10	332.5
910	0.0	-6.04	3.636	0.00	333.5
913	0.0	-6.06	3.648	0.00	335.0
916	0.2	-6.08	3.660	0.10	336.0
919	0.2	-6.10	3.672	0.10	337.0
922	0.2	-6.12	3.684	0.10	338.0
925	0.0	-6.14	3.696	0.00	339.0
928	0.2	-6.17	3.708	0.10	341.0
931	0.2	-6.19	3.720	0.10	342.0
934	0.0	-6.21	3.732	0.00	343.0
937	0.4	-6.23	3.744	0.15	344.0
940	0.2	-6.25	3.756	0.10	345.5
943	0.0	-6.27	3.768	0.00	346.5
946	0.4	-6.29	3.780	0.15	347.5
949	0.2	-6.31	3.792	0.10	348.5
952	0.4	-6.33	3.804	0.15	349.5
955	0.2	-6.35	3.816	0.10	351.0
958	0.2	-6.36	3.828	0.10	351.5
961	0.2	-6.39	3.840	0.10	353.0
964	0.0	-6.41	3.852	0.00	354.0
967	0.2	-6.43	3.864	0.10	355.0
970	0.0	-6.45	3.876	0.00	356.5
973	0.2	-6.47	3.888	0.10	357.5
976	0.2	-6.49	3.900	0.10	358.5
979	0.2	-6.51	3.912	0.10	359.5
982	0.0	-6.53	3.924	0.00	361.0
985	0.2	-6.55	3.936	0.10	362.0
988	0.4	-6.57	3.948	0.15	363.0
991	0.2	-6.59	3.960	0.10	364.0
994	0.2	-6.62	3.972	0.10	365.5
997	0.2	-6.64	3.984	0.10	367.0
1000	0.2	-6.66	3.996	0.10	368.0
1003	0.2	-6.68	4.008	0.10	369.0
1006	0.6	-6.70	4.020	0.25	370.0
1009	0.0	-6.72	4.032	0.00	371.5
1012	0.0	-6.74	4.044	0.00	372.5
1015	0.4	-6.76	4.056	0.15	373.5
1018	0.2	-6.78	4.068	0.10	374.5
1021	0.2	-6.80	4.080	0.10	375.5
1024	0.2	-6.82	4.092	0.10	377.0
1027	0.2	-6.84	4.104	0.10	378.0
1030	0.2	-6.87	4.116	0.10	379.5
1033	0.2	-6.89	4.128	0.10	380.5
1036	0.2	-6.91	4.140	0.10	382.0
1039	0.2	-6.93	4.152	0.10	383.0
1042	0.0	-6.95	4.164	0.00	384.0
1045	0.2	-6.97	4.176	0.10	385.0
1048	-0.2	-6.99	4.188	-0.10	386.0
1051	0.0	-7.01	4.200	0.00	387.5
1054	0.2	-7.03	4.212	0.10	388.5
1057	0.2	-7.05	4.224	0.10	389.5
1060	0.6	-7.07	4.236	0.25	390.5
1063	0.2	-7.09	4.248	0.10	391.5
1066	0.2	-7.11	4.260	0.10	393.0
1069	0.2	-7.14	4.272	0.10	394.5
1072	0.0	-7.16	4.284	0.00	395.5
1075	0.4	-7.18	4.296	0.15	396.5
1078	0.2	-7.20	4.308	0.10	398.0
1081	0.2	-7.22	4.320	0.10	399.0
1084	0.2	-7.24	4.332	0.10	400.0
1087	-0.2	-7.26	4.344	-0.10	401.0
1090	0.2	-7.28	4.356	0.10	402.0
1093	0.2	-7.30	4.368	0.10	403.5
1096	0.2	-7.32	4.380	0.10	404.5
1099	0.2	-7.34	4.392	0.10	405.5
1102	0.2	-7.38	4.404	0.10	407.5
1105	0.2	-7.40	4.416	0.10	409.0
1108	0.2	-7.42	4.428	0.10	410.0
1111	0.2	-7.44	4.440	0.10	411.0
1114	0.2	-7.46	4.452	0.10	412.0
1117	0.2	-7.48	4.464	0.10	413.5
1120	0.0	-7.50	4.476	0.00	414.5
1123	0.2	-7.52	4.488	0.10	415.5
1126	0.2	-7.54	4.500	0.10	416.5
1129	0.2	-7.56	4.512	0.10	417.5
1132	0.2	-7.58	4.524	0.10	419.0
1135	0.4	-7.61	4.536	0.15	420.5
1138	0.0	-7.63	4.548	0.00	421.5
1141	0.2	-7.65	4.560	0.10	422.5
1144	0.2	-7.67	4.572	0.10	424.0
1147	0.4	-7.69	4.584	0.15	425.0
1150	0.0	-7.71	4.596	0.00	426.0
1153	0.2	-7.73	4.608	0.10	427.0
1156	0.6	-7.75	4.620	0.25	428.0
1159	0.4	-7.77	4.632	0.15	429.5
1162	0.4	-7.79	4.644	0.15	430.5
1165	0.4	-7.81	4.656	0.15	431.5
1168	0.2	-7.83	4.668	0.10	432.5
1171	0.2	-7.86	4.680	0.10	434.5
1174	0.0	-7.88	4.692	0.00	435.5
1177	0.4	-7.90	4.704	0.15	436.5
1180	0.0	-7.92	4.716	0.00	437.5
1183	0.2	-7.94	4.728	0.10	438.5
1186	0.2	-7.96	4.740	0.10	440.0
1189	0.2	-7.98	4.752	0.10	441.0
1192	0.0	-8.00	4.764	0.00	442.0
1195	0.4	-8.02	4.776	0.15	443.0
1198	0.2	-8.04	4.788	0.10	444.0
1201	0.2	-8.06	4.800	0.10	445.5
1204	0.2	-8.09	4.812	0.10	447.0
1207	0.2	-8.11	4.824	0.10	448.0
1210	0.2	-8.13	4.836	0.10	449.0
1213	0.2	-8.15	4.848	0.10	450.5
1216	0.4	-8.17	4.860	0.15	451.5
1219	0.2	-8.19	4.872	0.10	452.5
1222	0.4	-8.21	4.884	0.15	453.5
1225	0.2	-8.23	4.896	0.10	454.5
1228	0.2	-8.25	4.908	0.10	456.0
1231	0.4	-8.27	4.920	0.15	457.0
1234	0.2	-8.29	4.932	0.10	458.0
1237	0.4	-8.32	4.944	0.15	459.5
1240	0.2	-8.34	4.956	0.10	461.0
1243	0.2	-8.36	4.968	0.10	462.0
1246	0.0	-8.38	4.980	0.00	463.0
1249	0.2	-8.40	4.992	0.10	464.0
1252	0.0	-8.42	5.004	0.00	465.0
1255	0.4	-8.44	5.016	0.15	466.5
1258	0.2	-8.46	5.028	0.10	467.5
1261	0.2	-8.48	5.040	0.10	468.5
1264	0.0	-8.51	5.052	0.00	470.0
1267	0.2	-8.53	5.064	0.10	471.5
1270	0.2	-8.55	5.076	0.10	472.5
1273	0.2	-8.57	5.088	0.10	473.5
1276	0.2	-8.59	5.100	0.10	474.5
1279	0.0	-8.61	5.112	0.00	475.5
1282	0.4	-8.63	5.124	0.15	477.0
1285	0.2	-8.65	5.136	0.10	478.0
1288	0.2	-8.67	5.148	0.10	479.0
1291	0.2	-8.69	5.160	0.10	480.0
1294	0.2	-8.72	5.172	0.10	482.0
1297	0.2	-8.74	5.184	0.10	483.0
1300	0.2	-8.76	5.196	0.10	484.0
1303	0.2	-8.78	5.208	0.10	485.0
1306	0.4	-8.80	5.220	0.15	486.0
1309	0.4	-8.82	5.232	0.15	487.5
1312	-0.2	-8.84	5.244	-0.10	488.5
1315	0.2	-8.86	5.256	0.10	489.5
1318	0.4	-8.88	5.268	0.15	490.5
1321	0.2	-8.91	5.280	0.10	492.5
1324	0.4	-8.93	5.292	0.15	493.5
1327	0.0	-8.95	5.304	0.00	494.5
1330	0.2	-8.97	5.316	0.10	495.5
1333	0.2	-8.99	5.328	0.10	496.5
1336	0.2	-9.01	5.340	0.10	498.0
1339	0.2	-9.03	5.352	0.10	499.0
1342	0.2	-9.05	5.364	0.10	500.0
1345	0.2	-9.07	5.376	0.10	501.0
1348	0.0	-9.10	5.388	0.00	503.0
1351	0.0	-9.12	5.400	0.00	504.0
1354	0.0	-9.14	5.412	0.00	505.0
1357	0.2	-9.16	5.424	0.10	506.0
1360	0.2	-9.18	5.436	0.10	507.0
1363	0.4	-9.20	5.448	0.15	508.5
1366	0.4	-9.22	5.460	0.15	509.5
1369	0.2	-9.24	5.472	0.10	510.5
1372	0.2	-9.27	5.484	0.10	512.0
1375	0.2	-9.29	5.496	0.10	513.5
1378	0.2	-9.31	5.508	0.10	514.5
1381	0.2	-9.33	5.520	0.10	515.5
1384	0.2	-9.35	5.532	0.10	516.5
1387	0.2	-9.37	5.544	0.10	517.5
1390	0.2	-9.39	5.556	0.10	519.0
1393	0.2	-9.41	5.568	0.10	520.0
1396	0.2	-9.43	5.580	0.10	521.0
1399	0.2	-9.46	5.592	0.10	522.5
1402	0.2	-9.48	5.604	0.10	524.0
1405	0.0	-9.50	5.616	0.00	525.0
1408	0.2	-9.52	5.628	0.10	526.0
1411	0.0	-9.54	5.640	0.00	527.0
1414	0.4	-9.56	5.652	0.15	528.0
1417	0.2	-9.58	5.664	0.10	529.5
1420	0.4	-9.60	5.676	0.15	530.5
1423	0.2	-9.62	5.688	0.10	531.5
1426	0.2	-9.65	5.700	0.10	533.0
1429	0.2	-9.67	5.712	0.10	534.5
1432	0.2	-9.69	5.724	0.10	535.5
1435	0.2	-9.71	5.736	0.10	536.5
1438	0.2	-9.73	5.748	0.10	537.5
1441	0.2	-9.75	5.760	0.10	538.5
1444	0.6	-9.77	5.772	0.25	540.0
1447	0.4	-9.79	5.784	0.15	541.0
1450	0.2	-9.81	5.796	0.10	542.0
1453	0.2	-9.84	5.808	0.10	543.5
1456	0.4	-9.86	5.820	0.15	545.0
1459	0.2	-9.88	5.832	0.10	546.0
1462	0.2	-9.90	5.844	0.10	547.0
1465	0.4	-9.92	5.856	0.15	548.0
1468	0.2	-9.94	5.868	0.10	549.0
1471	0.2	-9.96	5.880	0.10	550.5
1474	0.2	-9.98	5.892	0.10	551.5
1477	0.2	-10.01	5.904	0.10	553.0
1480	0.4	-10.03	5.916	0.15	554.0
1483	0.2	-10.05	5.928	0.10	555.0
1486	0.2	-10.07	5.940	0.10	556.5
1489	0.2	-10.09	5.952	0.10	557.5
1492	0.0	-10.11	5.964	0.00	558.5
1495	0.2	-10.13	5.976	0.10	559.5
1498	0.2	-10.15	5.988	0.10	561.0
1501	0.2	-10.18	6.000	0.10	562.5
1504	0.2	-10.20	6.012	0.10	563.5
1507	0.2	-10.22	6.024	0.10	564.5
1510	0.2	-10.24	6.036	0.10	565.5
1513	0.2	-10.26	6.048	0.10	567.0
1516	-0.2	-10.28	6.060	-0.10	568.0
1519	0.2	-10.30	6.072	0.10	569.0
1522	0.4	-10.32	6.084	0.15	570.0
1525	0.2	-10.34	6.096	0.10	571.5
1528	0.2	-10.35	6.108	0.10	572.0
1531	0.2	-10.38	6.120	0.10	573.5
1534	0.0	-10.40	6.132	0.00	574.5
1537	0.2	-10.42	6.144	0.10	575.5
1540	0.4	-10.44	6.156	0.15	577.0
1543	0.2	-10.46	6.168	0.10	578.0
1546	0.0	-10.48	6.180	0.00	579.0
1549	0.2	-10.50	6.192	0.10	580.0
1552	0.2	-10.52	6.204	0.10	581.0
1555	0.2	-10.54	6.216	0.10	582.5
1558	0.4	-10.56	6.228	0.15	583.5
1561	0.4	-10.59	6.240	0.15	585.0
1564	0.2	-10.61	6.252	0.10	586.0
1567	0.0	-10.63	6.264	0.00	587.5
1570	0.2	-10.65	6.276	0.10	588.5
1573	0.2	-10.67	6.288	0.10	589.5
1576	0.2	-10.69	6.300	0.10	590.5
1579	0.2	-10.71	6.312	0.10	591.5
1582	0.4	-10.73	6.324	0.15	593.0
1585	0.2	-10.75	6.336	0.10	594.0
1588	0.4	-10.78	6.348	0.15	595.5
1591	0.4	-10.80	6.360	0.15	596.5
1594	0.2	-10.82	6.372	0.10	598.0
1597	0.2	-10.84	6.384	0.10	599.0
1600	0.2	-10.86	6.396	0.10	600.0
1603	0.0	-10.88	6.408	0.00	601.0
1606	0.2	-10.90	6.420	0.10	602.0
1609	0.2	-10.92	6.432	0.10	603.5
1612	0.2	-10.94	6.444	0.10	604.5
1615	0.4	-10.96	6.456	0.15	605.5
1618	0.2	-10.99	6.468	0.10	607.0
1621	0.2	-11.01	6.480	0.10	608.5
1624	0.2	-11.03	6.492	0.10	609.5
1627	0.2	-11.05	6.504	0.10	610.5
1630	0.2	-11.07	6.516	0.10	611.5
1633	0.4	-11.09	6.528	0.15	612.5
1636	0.2	-11.11	6.540	0.10	614.0
1639	0.2	-11.13	6.552	0.10	615.0
1642	0.2	-11.15	6.564	0.10	616.0
1645	0.0	-11.17	6.576	0.00	617.0
1648	0.0	-11.19	6.588	0.00	618.0
1651	-0.2	-11.22	6.600	-0.10	620.0
1654	0.2	-11.24	6.612	0.10	621.0
1657	0.2	-11.26	6.624	0.10	622.0
1660	0.4	-11.28	6.636	0.15	623.0
1663	0.2	-11.30	6.648	0.10	624.5
1666	0.6	-11.32	6.660	0.25	625.5
1669	0.0	-11.34	6.672	0.00	626.5
1672	0.2	-11.36	6.684	0.10	627.5
1675	0.2	-11.38	6.696	0.10	628.5
1678	0.2	-11.40	6.708	0.10	630.0
1681	0.2	-11.42	6.720	0.10	631.0
1684	0.2	-11.45	6.732	0.10	632.5
1687	0.2	-11.47	6.744	0.10	633.5
1690	0.2	-11.49	6.756	0.10	635.0
1693	0.2	-11.51	6.768	0.10	636.0
1696	0.2	-11.53	6.780	0.10	637.0
1699	0.2	-11.55	6.792	0.10	638.0
1702	0.2	-11.57	6.804	0.10	639.0
1705	0.0	-11.59	6.816	0.00	640.5
1708	0.2	-11.61	6.828	0.10	641.5
1711	0.0	-11.63	6.840	0.00	642.5
1714	0.0	-11.65	6.852	0.00	643.5
1717	0.2	-11.68	6.864	0.10	645.5
1720	0.4	-11.70	6.876	0.15	646.5
1723	0.4	-11.72	6.888	0.15	647.5
1726	0.2	-11.74	6.900	0.10	648.5
1729	0.8	-11.76	6.912	0.35	649.5
1732	0.2	-11.78	6.924	0.10	651.0
1735	0.2	-11.80	6.936	0.10	652.0
1738	0.2	-11.82	6.948	0.10	653.0
1741	0.2	-11.84	6.960	0.10	654.0
1744	0.4	-11.86	6.972	0.15	655.0
1747	0.2	-11.88	6.984	0.10	656.5
1750	0.2	-11.90	6.996	0.10	657.5
1753	0.0	-11.93	7.008	0.00	659.0
1756	0.4	-11.95	7.020	0.15	660.0
1759	0.2	-11.97	7.032	0.10	661.5
1762	0.4	-11.99	7.044	0.15	662.5
1765	0.0	-12.01	7.056	0.00	663.5
1768	0.2	-12.03	7.068	0.10	664.5
1771	0.0	-12.05	7.080	0.00	665.5
1774	0.0	-12.07	7.092	0.00	667.0
1777	0.2	-12.09	7.104	0.10	668.0
1780	0.2	-12.11	7.116	0.10	669.0
1783	0.2	-12.13	7.128	0.10	670.0
1786	0.2	-12.16	7.140	0.10	672.0
1789	0.2	-12.18	7.152	0.10	673.0
1792	0.4	-12.20	7.164	0.15	674.0
1795	0.2	-12.22	7.176	0.10	675.0
1798	0.4	-12.24	7.188	0.15	676.0
1801	0.2	-12.26	7.200	0.10	677.5
1804	0.2	-12.28	7.212	0.10	678.5
1807	0.0	-12.30	7.224	0.00	679.5
1810	0.0	-12.32	7.236	0.00	680.5
1813	0.4	-12.34	7.248	0.15	682.0
1816	0.4	-12.37	7.260	0.15	683.5
1819	0.2	-12.40	7.272	0.10	685.0
1822	0.2	-12.42	7.284	0.10	686.0
1825	0.2	-12.44	7.296	0.10	687.5
1828	0.0	-12.46	7.308	0.00	688.5
1831	0.2	-12.48	7.320	0.10	689.5
1834	0.0	-12.50	7.332	0.00	690.5
1837	0.2	-12.52	7.344	0.10	691.5
1840	0.0	-12.54	7.356	0.00	693.0
1843	0.2	-12.56	7.368	0.10	694.0
1846	0.4	-12.58	7.380	0.15	695.0
1849	0.2	-12.60	7.392	0.10	696.0
1852	0.0	-12.62	7.404	0.00	697.0
1855	0.2	-12.65	7.416	0.10	699.0
1858	0.0	-12.67	7.428	0.00	700.0
1861	0.2	-12.69	7.440	0.10	701.0
1864	0.4	-12.71	7.452	0.15	702.0
1867	0.4	-12.73	7.464	0.15	703.5
1870	0.2	-12.75	7.476	0.10	704.5
1873	0.4	-12.77	7.488	0.15	705.5
1876	0.2	-12.79	7.500	0.10	706.5
1879	0.6	-12.81	7.512	0.25	707.5
1882	0.2	-12.83	7.524	0.10	709.0
1885	0.2	-12.85	7.536	0.10	710.0
1888	0.2	-12.88	7.548	0.10	711.5
1891	0.4	-12.90	7.560	0.15	712.5
1894	0.2	-12.92	7.572	0.10	714.0
1897	0.2	-12.94	7.584	0.10	715.0
1900	0.2	-12.96	7.596	0.10	716.0
1903	0.2	-12.98	7.608	0.10	717.0
1906	0.2	-13.00	7.620	0.10	718.0
1909	0.2	-13.02	7.632	0.10	719.5
1912	0.0	-13.04	7.644	0.00	720.5
1915	0.0	-13.06	7.656	0.00	721.5
1918	0.4	-13.08	7.668	0.15	722.5
1921	0.2	-13.11	7.680	0.10	724.5
1924	0.2	-13.13	7.692	0.10	725.5
1927	0.2	-13.15	7.704	0.10	726.5
1930	0.2	-13.17	7.716	0.10	727.5
1933	0.0	-13.19	7.728	0.00	728.5
1936	0.4	-13.21	7.740	0.15	730.0
1939	0.2	-13.23	7.752	0.10	731.0
1942	0.2	-13.25	7.764	0.10	732.0
1945	0.6	-13.27	7.776	0.25	733.0
1948	0.4	-13.29	7.788	0.15	734.5
1951	0.4	-13.31	7.800	0.15	735.5
1954	0.2	-13.34	7.812	0.10	737.0
1957	0.2	-13.36	7.824	0.10	738.0
1960	0.2	-13.38	7.836	0.10	739.0
1963	0.2	-13.40	7.848	0.10	740.5
1966	0.2	-13.42	7.860	0.10	741.5
1969	0.2	-13.44	7.872	0.10	742.5
1972	0.2	-13.46	7.884	0.10	743.5
1975	0.4	-13.48	7.896	0.15	745.0
1978	0.2	-13.50	7.908	0.10	746.0
1981	0.2	-13.53	7.920	0.10	747.5
1984	0.0	-13.55	7.932	0.00	748.5
1987	0.2	-13.57	7.944	0.10	749.5
1990	0.4	-13.59	7.956	0.15	751.0
1993	0.2	-13.61	7.968	0.10	752.0
1996	0.2	-13.63	7.980	0.10	753.0
1999	0.2	-13.65	7.992	0.10	754.0
2002	0.4	-13.67	8.004	0.15	755.0
2005	0.2	-13.69	8.016	0.10	756.5
2008	0.2	-13.72	8.028	0.10	758.0
2011	0.4	-13.74	8.040	0.15	759.0
2014	0.4	-13.76	8.052	0.15	760.0
2017	0.2	-13.78	8.064	0.10	761.5
2020	0.2	-13.80	8.076	0.10	762.5
2023	-0.4	-13.82	8.088	-0.15	763.5
2026	0.0	-13.84	8.100	0.00	764.5
2029	-0.2	-13.86	8.112	-0.10	765.5
2032	0.2	-13.88	8.124	0.10	767.0
2035	0.0	-13.91	8.136	0.00	768.5
2038	0.0	-13.93	8.148	0.00	769.5
2041	0.4	-13.95	8.160	0.15	770.5
2044	0.0	-13.97	8.172	0.00	772.0
2047	0.2	-13.99	8.184	0.10	773.0
2050	0.2	-14.01	8.196	0.10	774.0
2053	0.4	-14.03	8.208	0.15	775.0
2056	0.4	-14.05	8.220	0.15	776.0
2059	0.2	-14.07	8.232	0.10	777.5
2062	0.2	-14.10	8.244	0.10	779.0
2065	0.4	-14.12	8.256	0.15	780.0
2068	0.2	-14.14	8.268	0.10	781.0
2071	0.2	-14.16	8.280	0.10	782.5
2074	0.2	-14.18	8.292	0.10	783.5
2077	0.0	-14.20	8.304	0.00	784.5
2080	0.2	-14.22	8.316	0.10	785.5
2083	0.2	-14.25	8.328	0.10	787.5
2086	0.0	-14.27	8.340	0.00	788.5
2089	0.2	-14.29	8.352	0.10	789.5
2092	0.2	-14.31	8.364	0.10	790.5
2095	0.4	-14.33	8.376	0.15	791.5
2098	0.2	-14.35	8.388	0.10	793.0
2101	0.2	-14.37	8.400	0.10	794.0
2104	0.2	-14.39	8.412	0.10	795.0
2107	0.2	-14.41	8.424	0.10	796.0
2110	0.2	-14.44	8.436	0.10	798.0
2113	0.2	-14.46	8.448	0.10	799.0
2116	0.6	-14.48	8.460	0.25	800.0
2119	0.2	-14.50	8.472	0.10	801.0
2122	0.2	-14.52	8.484	0.10	802.0
2125	0.2	-14.54	8.496	0.10	803.5
2128	0.2	-14.56	8.508	0.10	804.5
2131	0.2	-14.58	8.520	0.10	805.5
2134	0.0	-14.60	8.532	0.00	806.5
2137	0.6	-14.63	8.544	0.25	808.5
2140	0.2	-14.65	8.556	0.10	809.5
2143	0.2	-14.67	8.568	0.10	810.5
2146	0.0	-14.69	8.580	0.00	811.5
2149	0.2	-14.71	8.592	0.10	812.5
2152	0.2	-14.73	8.604	0.10	814.0
2155	0.2	-14.75	8.616	0.10	815.0
2158	0.8	-14.77	8.628	0.35	816.0
2161	0.4	-14.79	8.640	0.15	817.0
2164	0.4	-14.82	8.652	0.15	819.0
2167	0.2	-14.84	8.664	0.10	820.0
2170	0.8	-14.86	8.676	0.35	821.0
2173	0.2	-14.88	8.688	0.10	822.0
2176	0.4	-14.90	8.700	0.15	823.0
2179	0.4	-14.92	8.712	0.15	824.5
2182	0.0	-14.94	8.724	0.00	825.5
2185	0.2	-14.96	8.736	0.10	826.5
2188	0.2	-14.98	8.748	0.10	827.5
2191	0.2	-15.01	8.760	0.10	829.5
2194	0.2	-15.03	8.772	0.10	830.5
2197	0.2	-15.05	8.784	0.10	831.5
2200	0.2	-15.07	8.796	0.10	832.5
2203	0.2	-15.09	8.808	0.10	833.5
2206	-0.2	-15.11	8.820	-0.10	835.0
2209	0.2	-15.13	8.832	0.10	836.0
2212	0.2	-15.15	8.844	0.10	837.0
2215	0.2	-15.17	8.856	0.10	838.0
2218	0.2	-15.20	8.868	0.10	840.0
2221	0.0	-15.22	8.880	0.00	841.0
2224	0.2	-15.24	8.892	0.10	842.0
2227	0.2	-15.26	8.904	0.10	843.0
2230	0.0	-15.28	8.916	0.00	844.0
2233	0.2	-15.30	8.928	0.10	845.5
2236	0.0	-15.32	8.940	0.00	846.5
2239	0.2	-15.34	8.952	0.10	847.5
2242	0.2	-15.35	8.964	0.10	848.0
2245	0.2	-15.38	8.976	0.10	849.5
2248	0.0	-15.40	8.988	0.00	851.0
2251	0.4	-15.42	9.000	0.15	852.0
2254	0.2	-15.44	9.012	0.10	853.0
2257	0.4	-15.46	9.024	0.15	854.0
2260	0.2	-15.48	9.036	0.10	855.0
2263	0.4	-15.50	9.048	0.15	856.5
2266	0.0	-15.52	9.060	0.00	857.5
2269	0.2	-15.54	9.072	0.10	858.5
2272	0.2	-15.57	9.084	0.10	860.0
2275	0.2	-15.59	9.096	0.10	861.5
2278	0.2	-15.61	9.108	0.10	862.5
2281	0.4	-15.63	9.120	0.15	863.5
2284	0.2	-15.65	9.132	0.10	864.5
2287	0.2	-15.67	9.144	0.10	865.5
2290	0.2	-15.69	9.156	0.10	867.0
2293	0.2	-15.71	9.168	0.10	868.0
2296	0.0	-15.73	9.180	0.00	869.0
2299	0.0	-15.76	9.192	0.00	870.5
2302	0.0	-15.78	9.204	0.00	872.0
2305	0.2	-15.80	9.216	0.10	873.0
2308	0.4	-15.82	9.228	0.15	874.0
2311	0.2	-15.84	9.240	0.10	875.0
2314	0.0	-15.86	9.252	0.00	876.0
2317	0.4	-15.88	9.264	0.15	877.5
2320	0.2	-15.90	9.276	0.10	878.5
2323	0.2	-15.92	9.288	0.10	879.5
2326	0.2	-15.94	9.300	0.10	880.5
2329	0.0	-15.96	9.312	0.00	882.0
2332	0.2	-15.99	9.324	0.10	883.5
2335	0.2	-16.01	9.336	0.10	884.5
2338	0.4	-16.03	9.348	0.15	885.5
2341	0.2	-16.05	9.360	0.10	886.5
2344	0.2	-16.07	9.372	0.10	888.0
2347	0.2	-16.09	9.384	0.10	889.0
2350	0.0	-16.11	9.396	0.00	890.0
2353	0.2	-16.13	9.408	0.10	891.0
2356	0.4	-16.15	9.420	0.15	892.5
2359	0.0	-16.17	9.432	0.00	893.5
2362	0.0	-16.19	9.444	0.00	894.5
2365	0.2	-16.22	9.456	0.10	896.0
2368	-0.2	-16.24	9.468	-0.10	897.0
2371	0.2	-16.26	9.480	0.10	898.5
2374	0.2	-16.28	9.492	0.10	899.5
2377	0.4	-16.30	9.504	0.15	900.5
2380	0.0	-16.32	9.516	0.00	901.5
2383	0.2	-16.34	9.528	0.10	903.0
2386	0.2	-16.36	9.540	0.10	904.0
2389	0.2	-16.38	9.552	0.10	905.0
2392	0.4	-16.40	9.564	0.15	906.0
2395	0.2	-16.42	9.576	0.10	907.0
2398	0.0	-16.44	9.588	0.00	908.5
2401	0.4	-16.47	9.600	0.15	910.0
2404	0.2	-16.49	9.612	0.10	911.0
2407	0.2	-16.51	9.624	0.10	912.0
2410	0.6	-16.53	9.636	0.25	913.5
2413	0.4	-16.55	9.648	0.15	914.5
2416	0.2	-16.57	9.660	0.10	915.5
2419	0.2	-16.59	9.672	0.10	916.5
2422	0.0	-16.61	9.684	0.00	917.5
2425	0.2	-16.63	9.696	0.10	919.0
2428	0.6	-16.65	9.708	0.25	920.0
2431	0.2	-16.67	9.720	0.10	921.0
2434	0.2	-16.70	9.732	0.10	922.5
2437	0.0	-16.72	9.744	0.00	924.0
2440	0.2	-16.74	9.756	0.10	925.0
2443	0.6	-16.76	9.768	0.25	926.0
2446	0.6	-16.78	9.780	0.25	927.0
2449	0.2	-16.80	9.792	0.10	928.0
2452	0.2	-16.82	9.804	0.10	929.5
2455	0.2	-16.84	9.816	0.10	930.5
2458	0.2	-16.86	9.828	0.10	931.5
2461	0.2	-16.88	9.840	0.10	932.5
2464	-0.2	-16.90	9.852	-0.10	933.5
2467	0.2	-16.92	9.864	0.10	935.0
2470	0.4	-16.95	9.876	0.15	936.5
2473	0.2	-16.97	9.888	0.10	937.5
2476	0.4	-16.99	9.900	0.15	938.5
2479	0.2	-17.01	9.912	0.10	940.0
2482	0.2	-17.03	9.924	0.10	941.0
2485	0.2	-17.05	9.936	0.10	942.0
2488	-0.2	-17.07	9.948	-0.10	943.0
2491	0.2	-17.09	9.960	0.10	944.0
2494	0.2	-17.11	9.972	0.10	945.5
2497	0.2	-17.13	9.984	0.10	946.5
2500	0.2	-17.15	9.996	0.10	947.5
2503	0.4	-17.18	10.008	0.15	949.0
2506	0.4	-17.19	10.020	0.15	949.5
2509	0.2	-17.22	10.032	0.10	951.5
2512	0.2	-17.24	10.044	0.10	952.5
2515	0.2	-17.26	10.056	0.10	953.5
2518	0.2	-17.28	10.068	0.10	954.5
2521	0.4	-17.30	10.080	0.15	956.0
2524	0.2	-17.32	10.092	0.10	957.0
2527	0.2	-17.34	10.104	0.10	958.0
2530	0.2	-17.37	10.116	0.10	959.5
2533	0.2	-17.39	10.128	0.10	961.0
2536	0.2	-17.41	10.140	0.10	962.0
2539	0.2	-17.43	10.152	0.10	963.0
2542	0.2	-17.46	10.164	0.10	964.5
2545	0.2	-17.48	10.176	0.10	965.5
2548	0.2	-17.50	10.188	0.10	967.0
2551	0.2	-17.52	10.200	0.10	968.0
2554	0.2	-17.54	10.212	0.10	969.0
2557	0.2	-17.56	10.224	0.10	970.0
2560	0.2	-17.58	10.236	0.10	971.5
2563	0.2	-17.60	10.248	0.10	972.5
2566	0.4	-17.62	10.260	0.15	973.5
2569	0.2	-17.64	10.272	0.10	974.5
2572	0.2	-17.66	10.284	0.10	975.5
2575	0.4	-17.69	10.296	0.15	977.5
2578	0.6	-17.71	10.308	0.25	978.5
2581	0.2	-17.73	10.320	0.10	979.5
2584	0.0	-17.75	10.332	0.00	980.5
2587	0.2	-17.77	10.344	0.10	982.0
2590	0.2	-17.79	10.356	0.10	983.0
2593	0.2	-17.81	10.368	0.10	984.0
2596	0.2	-17.83	10.380	0.10	985.0
2599	0.6	-17.85	10.392	0.25	986.0
2602	0.2	-17.87	10.404	0.10	987.5
2605	0.2	-17.89	10.416	0.10	988.5
2608	0.2	-17.91	10.428	0.10	989.5
2611	0.0	-17.94	10.440	0.00	991.0
2614	0.2	-17.96	10.452	0.10	992.5
2617	0.4	-17.98	10.464	0.15	993.5
2620	0.6	-18.00	10.476	0.25	994.5
2623	0.0	-18.02	10.488	0.00	995.5
2626	0.0	-18.04	10.500	0.00	996.5
2629	0.2	-18.06	10.512	0.10	998.0
2632	0.0	-18.08	10.524	0.00	999.0
2635	0.2	-18.10	10.536	0.10	1000.0
2638	0.2	-18.12	10.548	0.10	1001.0
2641	0.2	-18.14	10.560	0.10	1002.0
2644	0.4	-18.17	10.572	0.15	1004.0
2647	0.2	-18.19	10.584	0.10	1005.0
2650	0.4	-18.21	10.596	0.15	1006.0
2653	0.2	-18.23	10.608	0.10	1007.0
2656	0.4	-18.25	10.620	0.15	1008.5
2659	0.4	-18.27	10.632	0.15	1009.5
2662	0.2	-18.29	10.644	0.10	1010.5
2665	0.2	-18.31	10.656	0.10	1011.5
2668	0.2	-18.33	10.668	0.10	1012.5
2671	0.2	-18.35	10.680	0.10	1014.0
2674	0.0	-18.37	10.692	0.00	1015.0
2677	0.2	-18.40	10.704	0.10	1016.5
2680	0.2	-18.42	10.716	0.10	1017.5
2683	0.6	-18.44	10.728	0.25	1019.0
2686	0.6	-18.46	10.740	0.25	1020.0
2689	0.2	-18.48	10.752	0.10	1021.0
2692	0.0	-18.50	10.764	0.00	1022.0
2695	0.2	-18.52	10.776	0.10	1023.0
2698	0.4	-18.54	10.788	0.15	1024.5
2701	0.4	-18.56	10.800	0.15	1025.5
2704	0.2	-18.59	10.812	0.10	1027.0
2707	-0.2	-18.61	10.824	-0.10	1028.0
2710	0.0	-18.63	10.836	0.00	1029.5
2713	0.4	-18.65	10.848	0.15	1030.5
2716	0.2	-18.67	10.860	0.10	1031.5
2719	0.2	-18.69	10.872	0.10	1032.5
2722	0.2	-18.71	10.884	0.10	1033.5
2725	0.4	-18.73	10.896	0.15	1035.0
2728	0.0	-18.75	10.908	0.00	1036.0
2731	0.0	-18.78	10.920	0.00	1037.5
2734	0.4	-18.80	10.932	0.15	1038.5
2737	0.2	-18.82	10.944	0.10	1040.0
2740	-0.2	-18.84	10.956	-0.10	1041.0
2743	0.2	-18.86	10.968	0.10	1042.0
2746	0.6	-18.88	10.980	0.25	1043.0
2749	0.2	-18.90	10.992	0.10	1044.0
2752	0.2	-18.92	11.004	0.10	1045.5
2755	0.4	-18.94	11.016	0.15	1046.5
2758	0.4	-18.96	11.028	0.15	1047.5
2761	0.2	-18.99	11.040	0.10	1049.0
2764	0.0	-19.01	11.052	0.00	1050.5
2767	0.0	-19.03	11.064	0.00	1051.5
2770	0.2	-19.05	11.076	0.10	1052.5
2773	0.4	-19.07	11.088	0.15	1053.5
2776	0.2	-19.09	11.100	0.10	1054.5
2779	0.2	-19.11	11.112	0.10	1056.0
2782	0.2	-19.13	11.124	0.10	1057.0
2785	0.2	-19.15	11.136	0.10	1058.0
2788	0.2	-19.18	11.148	0.10	1059.5
2791	0.2	-19.20	11.160	0.10	1061.0
2794	0.2	-19.22	11.172	0.10	1062.0
2797	0.2	-19.24	11.184	0.10	1063.0
2800	0.4	-19.26	11.196	0.15	1064.0
2803	0.4	-19.28	11.208	0.15	1065.0
2806	0.2	-19.30	11.220	0.10	1066.5
2809	0.2	-19.32	11.232	0.10	1067.5
2812	0.2	-19.35	11.244	0.10	1069.0
2815	0.2	-19.36	11.256	0.10	1069.5
2818	0.2	-19.38	11.268	0.10	1070.5
2821	0.0	-19.40	11.280	0.00	1072.0
2824	0.2	-19.42	11.292	0.10	1073.0
2827	0.2	-19.44	11.304	0.10	1074.0
2830	0.4	-19.46	11.316	0.15	1075.0
2833	0.2	-19.48	11.328	0.10	1076.0
2836	0.2	-19.50	11.340	0.10	1077.5
2839	0.0	-19.53	11.352	0.00	1079.0
2842	0.6	-19.55	11.364	0.25	1080.0
2845	0.4	-19.57	11.376	0.15	1081.0
2848	0.6	-19.59	11.388	0.25	1082.5
2851	0.8	-19.61	11.400	0.35	1083.5
2854	0.4	-19.63	11.412	0.15	1084.5
2857	0.0	-19.65	11.424	0.00	1085.5
2860	0.0	-19.67	11.436	0.00	1086.5
2863	0.0	-19.70	11.448	0.00	1088.5
2866	0.6	-19.72	11.460	0.25	1089.5
2869	0.2	-19.74	11.472	0.10	1090.5
2872	0.4	-19.76	11.484	0.15	1091.5
2875	0.6	-19.78	11.496	0.25	1093.0
2878	1.0	-19.80	11.508	0.40	1094.0
2881	1.0	-19.82	11.520	0.40	1095.0
2884	1.2	-19.84	11.532	0.50	1096.0
2887	1.4	-19.86	11.544	0.60	1097.0
2890	1.4	-19.89	11.556	0.60	1099.0
2893	1.6	-19.91	11.568	0.65	1100.0
2896	2.0	-19.93	11.580	0.85	1101.0
2899	2.0	-19.95	11.592	0.85	1102.0
2902	2.4	-19.97	11.604	1.00	1103.5
2905	2.4	-19.99	11.616	1.00	1104.5
2908	2.2	-20.01	11.628	0.95	1105.5
2911	2.4	-20.03	11.640	1.00	1106.5
2914	2.4	-20.05	11.652	1.00	1107.5
2917	2.4	-20.08	11.664	1.00	1109.5
2920	2.6	-20.10	11.676	1.10	1110.5
2923	2.2	-20.12	11.688	0.95	1111.5
2926	2.6	-20.14	11.700	1.10	1112.5
2929	2.4	-20.16	11.712	1.00	1114.0
2932	2.2	-20.18	11.724	0.95	1115.0
2935	2.6	-20.20	11.736	1.10	1116.0
2938	2.6	-20.22	11.748	1.10	1117.0
2941	2.6	-20.24	11.760	1.10	1118.0
2944	3.0	-20.27	11.772	1.25	1120.0
2947	2.8	-20.29	11.784	1.20	1121.0
2950	3.4	-20.31	11.796	1.45	1122.0
2953	3.2	-20.33	11.808	1.35	1123.0
2956	3.4	-20.35	11.820	1.45	1124.5
2959	3.6	-20.37	11.832	1.50	1125.5
2962	3.4	-20.39	11.844	1.45	1126.5
2965	3.6	-20.41	11.856	1.50	1127.5
2968	4.0	-20.43	11.868	1.70	1128.5
2971	4.0	-20.45	11.880	1.70	1130.0
2974	4.2	-20.48	11.892	1.75	1131.5
2977	4.4	-20.50	11.904	1.85	1132.5
2980	3.8	-20.52	11.916	1.60	1133.5
2983	4.0	-20.54	11.928	1.70	1135.0
2986	3.6	-20.56	11.940	1.50	1136.0
2989	3.6	-20.58	11.952	1.50	1137.0
2992	3.4	-20.60	11.964	1.45	1138.0
2995	3.0	-20.62	11.976	1.25	1139.0
2998	0.6	-20.64	11.988	0.25	1140.5
3001	0.4	-20.67	12.000	0.15	1142.0
3004	0.4	-20.69	12.012	0.15	1143.0
3007	0.4	-20.71	12.024	0.15	1144.0
3010	0.4	-20.73	12.036	0.15	1145.5
3013	0.8	-20.75	12.048	0.35	1146.5
3016	1.4	-20.77	12.060	0.60	1147.5
3019	1.6	-20.79	12.072	0.65	1148.5
3022	2.2	-20.81	12.084	0.95	1149.5
3025	2.2	-20.83	12.096	0.95	1151.0
3028	2.4	-20.85	12.108	1.00	1152.0
3031	1.8	-20.88	12.120	0.75	1153.5
3034	1.4	-20.90	12.132	0.60	1154.5
3037	1.2	-20.92	12.144	0.50	1156.0
3040	1.0	-20.94	12.156	0.40	1157.0
3043	0.6	-20.96	12.168	0.25	1158.0
3046	0.4	-20.98	12.180	0.15	1159.0
3049	0.2	-21.00	12.192	0.10	1160.0
3052	0.4	-21.02	12.204	0.15	1161.5
3055	0.4	-21.04	12.216	0.15	1162.5
3058	0.6	-21.07	12.228	0.25	1164.0
3061	0.4	-21.09	12.240	0.15	1165.0
3064	0.8	-21.11	12.252	0.35	1166.5
3067	1.6	-21.13	12.264	0.65	1167.5
3070	2.4	-21.15	12.276	1.00	1168.5
3073	3.4	-21.17	12.288	1.45	1169.5
3076	3.6	-21.19	12.300	1.50	1170.5
3079	4.8	-21.21	12.312	2.00	1172.0
3082	5.0	-21.23	12.324	2.10	1173.0
3085	5.2	-21.25	12.336	2.20	1174.0
3088	5.2	-21.27	12.348	2.20	1175.0
3091	5.4	-21.29	12.360	2.25	1176.0
3094	5.6	-21.31	12.372	2.35	1177.5
3097	6.0	-21.34	12.384	2.50	1179.0
3100	5.8	-21.36	12.396	2.45	1180.0
3103	6.6	-21.38	12.408	2.80	1181.0
3106	6.8	-21.40	12.420	2.85	1182.5
3109	7.0	-21.42	12.432	2.95	1183.5
3112	7.2	-21.44	12.444	3.05	1184.5
3115	7.6	-21.46	12.456	3.20	1185.5
3118	8.2	-21.48	12.468	3.45	1186.5
3121	9.0	-21.50	12.480	3.80	1188.0
3124	10.2	-21.52	12.492	4.30	1189.0
3127	10.8	-21.54	12.504	4.55	1190.0
3130	12.4	-21.56	12.516	5.20	1191.0
3133	13.8	-21.58	12.528	5.80	1192.5
3136	15.0	-21.60	12.540	6.30	1193.5
3139	17.0	-21.62	12.552	7.15	1194.5
3142	19.2	-21.63	12.564	8.05	1195.0
3145	21.6	-21.65	12.576	9.10	1196.0
3148	24.2	-21.67	12.588	10.20	1197.0
3151	26.6	-21.69	12.600	11.20	1198.5
3154	27.0	-21.70	12.612	11.35	1199.0
3157	25.0	-21.70	12.624	10.50	1199.0
3160	24.0	-21.70	12.636	10.10	1199.0
3163	23.4	-21.71	12.648	9.85	1199.5
3166	22.8	-21.71	12.660	9.60	1199.5
3169	22.6	-21.71	12.672	9.50	1199.5
3172	22.4	-21.71	12.684	9.40	1199.5
3175	22.0	-21.71	12.696	9.25	1199.5
3178	22.0	-21.71	12.708	9.25	1199.5
3181	21.6	-21.71	12.720	9.10	1199.5
3184	21.6	-21.71	12.732	9.10	1199.5
3187	21.4	-21.71	12.744	9.00	1199.5
3190	21.2	-21.71	12.756	8.90	1199.5
3193	21.0	-21.71	12.768	8.85	1199.5
3196	27.6	-21.70	12.780	8.85	1199.5