File: results/youngs-modulus/2025-04-25/inconclusive-data/pf16cp02.csv
sep=
pf16cp02

System Information:
IntelliMESUR Version: 2.2.1
Test Frame Model: F505
Test Frame Serial Number: 4418651
Test Frame Capacity: 500 lbF / 2.2 kN
Test Frame Firmware Version: 1.00.14
Force Sensor Model: FS05-100
Force Sensor Capacity: 500 N
Force Sensor Resolution: 0.2 N
Force Sensor Serial Number: 4425350
Calibration Date: Apr 29, 2024
Calibration Due Date: Apr 29, 2025

Reading	Load [N]	Distance [mm]	Time [s]	Stress [MPa]	Strain [%]
1	-0.2	-0.01	0.000	-0.04	0.4
4	0.0	-0.01	0.012	0.00	0.4
7	-0.4	-0.01	0.024	-0.08	0.4
10	-0.2	-0.01	0.036	-0.04	0.4
13	0.0	-0.01	0.048	0.00	0.4
16	0.0	-0.01	0.060	0.00	0.4
19	-0.2	-0.01	0.072	-0.04	0.4
22	-0.2	-0.01	0.084	-0.04	0.4
25	-0.2	-0.01	0.096	-0.04	0.4
28	-0.2	-0.01	0.108	-0.04	0.4
31	-0.2	-0.01	0.120	-0.04	0.4
34	-0.2	-0.01	0.132	-0.04	0.4
37	-0.4	-0.01	0.144	-0.08	0.4
40	-0.2	-0.01	0.156	-0.04	0.4
43	-0.2	-0.01	0.168	-0.04	0.4
46	-0.2	-0.01	0.180	-0.04	0.4
49	-0.2	-0.03	0.192	-0.04	1.2
52	-0.2	-0.05	0.204	-0.04	2.0
55	-0.2	-0.07	0.216	-0.04	2.8
58	-0.2	-0.09	0.228	-0.04	3.6
61	-0.2	-0.11	0.240	-0.04	4.4
64	-0.2	-0.14	0.252	-0.04	5.6
67	-0.2	-0.16	0.264	-0.04	6.4
70	0.0	-0.18	0.276	0.00	7.2
73	-0.2	-0.20	0.288	-0.04	8.0
76	0.0	-0.22	0.300	0.00	8.8
79	-0.2	-0.24	0.312	-0.04	9.6
82	-0.2	-0.26	0.324	-0.04	10.4
85	-0.4	-0.28	0.336	-0.08	11.2
88	-0.2	-0.31	0.348	-0.04	12.4
91	-0.2	-0.33	0.360	-0.04	13.2
94	-0.4	-0.35	0.372	-0.08	14.0
97	-0.2	-0.37	0.384	-0.04	14.8
100	-0.2	-0.39	0.396	-0.04	15.6
103	-0.4	-0.40	0.408	-0.08	16.0
106	-0.2	-0.42	0.420	-0.04	16.8
109	-0.2	-0.44	0.432	-0.04	17.6
112	-0.2	-0.46	0.444	-0.04	18.4
115	0.0	-0.49	0.456	0.00	19.6
118	-0.2	-0.51	0.468	-0.04	20.4
121	-0.2	-0.53	0.480	-0.04	21.2
124	-0.2	-0.55	0.492	-0.04	22.0
127	-0.4	-0.57	0.504	-0.08	22.8
130	-0.2	-0.59	0.516	-0.04	23.6
133	-0.2	-0.61	0.528	-0.04	24.4
136	-0.2	-0.63	0.540	-0.04	25.2
139	0.0	-0.65	0.552	0.00	26.0
142	-0.2	-0.67	0.564	-0.04	26.8
145	-0.2	-0.70	0.576	-0.04	28.0
148	0.0	-0.72	0.588	0.00	28.8
151	-0.2	-0.74	0.600	-0.04	29.6
154	-0.2	-0.76	0.612	-0.04	30.4
157	0.0	-0.78	0.624	0.00	31.2
160	-0.2	-0.80	0.636	-0.04	32.0
163	-0.2	-0.82	0.648	-0.04	32.8
166	-0.2	-0.84	0.660	-0.04	33.6
169	-0.2	-0.86	0.672	-0.04	34.4
172	-0.2	-0.89	0.684	-0.04	35.6
175	0.0	-0.91	0.696	0.00	36.4
178	-0.2	-0.93	0.708	-0.04	37.2
181	-0.2	-0.95	0.720	-0.04	38.0
184	-0.2	-0.97	0.732	-0.04	38.8
187	-0.2	-0.99	0.744	-0.04	39.6
190	0.2	-1.01	0.756	0.04	40.4
193	-0.2	-1.03	0.768	-0.04	41.2
196	-0.2	-1.05	0.780	-0.04	42.0
199	-0.2	-1.07	0.792	-0.04	42.8
202	0.0	-1.09	0.804	0.00	43.6
205	-0.2	-1.12	0.816	-0.04	44.8
208	0.0	-1.14	0.828	0.00	45.6
211	-0.2	-1.16	0.840	-0.04	46.4
214	-0.2	-1.18	0.852	-0.04	47.2
217	-0.2	-1.20	0.864	-0.04	48.0
220	0.0	-1.22	0.876	0.00	48.8
223	0.0	-1.24	0.888	0.00	49.6
226	-0.4	-1.26	0.900	-0.08	50.4
229	-0.2	-1.28	0.912	-0.04	51.2
232	0.0	-1.30	0.924	0.00	52.0
235	-0.2	-1.32	0.936	-0.04	52.8
238	0.2	-1.35	0.948	0.04	54.0
241	0.0	-1.37	0.960	0.00	54.8
244	0.0	-1.39	0.972	0.00	55.6
247	-0.4	-1.42	0.984	-0.08	56.8
250	0.2	-1.44	0.996	0.04	57.6
253	0.0	-1.46	1.008	0.00	58.4
256	0.0	-1.48	1.020	0.00	59.2
259	-0.2	-1.50	1.032	-0.04	60.0
262	-0.2	-1.52	1.044	-0.04	60.8
265	-0.2	-1.54	1.056	-0.04	61.6
268	-0.2	-1.57	1.068	-0.04	62.8
271	-0.2	-1.59	1.080	-0.04	63.6
274	-0.2	-1.61	1.092	-0.04	64.4
277	-0.2	-1.63	1.104	-0.04	65.2
280	-0.2	-1.65	1.116	-0.04	66.0
283	-0.4	-1.67	1.128	-0.08	66.8
286	-0.2	-1.69	1.140	-0.04	67.6
289	-0.2	-1.71	1.152	-0.04	68.4
292	-0.2	-1.73	1.164	-0.04	69.2
295	-0.2	-1.75	1.176	-0.04	70.0
298	-0.2	-1.77	1.188	-0.04	70.8
301	0.0	-1.80	1.200	0.00	72.0
304	-0.2	-1.82	1.212	-0.04	72.8
307	-0.2	-1.84	1.224	-0.04	73.6
310	-0.2	-1.86	1.236	-0.04	74.4
313	-0.2	-1.88	1.248	-0.04	75.2
316	-0.2	-1.90	1.260	-0.04	76.0
319	0.0	-1.92	1.272	0.00	76.8
322	-0.2	-1.94	1.284	-0.04	77.6
325	0.0	-1.96	1.296	0.00	78.4
328	0.0	-1.98	1.308	0.00	79.2
331	-0.2	-2.00	1.320	-0.04	80.0
334	-0.4	-2.03	1.332	-0.08	81.2
337	-0.2	-2.04	1.344	-0.04	81.6
340	-0.2	-2.07	1.356	-0.04	82.8
343	-0.2	-2.09	1.368	-0.04	83.6
346	-0.2	-2.11	1.380	-0.04	84.4
349	-0.2	-2.13	1.392	-0.04	85.2
352	-0.2	-2.15	1.404	-0.04	86.0
355	-0.2	-2.17	1.416	-0.04	86.8
358	-0.2	-2.19	1.428	-0.04	87.6
361	-0.2	-2.21	1.440	-0.04	88.4
364	-0.2	-2.23	1.452	-0.04	89.2
367	-0.2	-2.25	1.464	-0.04	90.0
370	-0.2	-2.27	1.476	-0.04	90.8
373	-0.2	-2.30	1.488	-0.04	92.0
376	-0.2	-2.32	1.500	-0.04	92.8
379	0.0	-2.34	1.512	0.00	93.6
382	-0.2	-2.36	1.524	-0.04	94.4
385	-0.2	-2.38	1.536	-0.04	95.2
388	-0.2	-2.40	1.548	-0.04	96.0
391	-0.2	-2.41	1.560	-0.04	96.4
394	-0.4	-2.43	1.572	-0.08	97.2
397	-0.2	-2.45	1.584	-0.04	98.0
400	-0.2	-2.47	1.596	-0.04	98.8
403	-0.2	-2.49	1.608	-0.04	99.6
406	-0.2	-2.51	1.620	-0.04	100.4
409	-0.2	-2.54	1.632	-0.04	101.6
412	-0.2	-2.56	1.644	-0.04	102.4
415	-0.2	-2.58	1.656	-0.04	103.2
418	0.2	-2.60	1.668	0.04	104.0
421	-0.4	-2.62	1.680	-0.08	104.8
424	-0.2	-2.64	1.692	-0.04	105.6
427	-0.2	-2.66	1.704	-0.04	106.4
430	-0.2	-2.68	1.716	-0.04	107.2
433	0.0	-2.70	1.728	0.00	108.0
436	-0.4	-2.72	1.740	-0.08	108.8
439	-0.2	-2.74	1.752	-0.04	109.6
442	-0.2	-2.77	1.764	-0.04	110.8
445	-0.2	-2.79	1.776	-0.04	111.6
448	-0.2	-2.81	1.788	-0.04	112.4
451	-0.2	-2.83	1.800	-0.04	113.2
454	-0.2	-2.85	1.812	-0.04	114.0
457	-0.2	-2.87	1.824	-0.04	114.8
460	-0.2	-2.89	1.836	-0.04	115.6
463	0.0	-2.91	1.848	0.00	116.4
466	0.0	-2.93	1.860	0.00	117.2
469	-0.2	-2.95	1.872	-0.04	118.0
472	-0.2	-2.97	1.884	-0.04	118.8
475	0.2	-3.00	1.896	0.04	120.0
478	-0.2	-3.02	1.908	-0.04	120.8
481	0.0	-3.04	1.920	0.00	121.6
484	-0.2	-3.06	1.932	-0.04	122.4
487	-0.2	-3.08	1.944	-0.04	123.2
490	-0.2	-3.10	1.956	-0.04	124.0
493	-0.2	-3.12	1.968	-0.04	124.8
496	0.0	-3.14	1.980	0.00	125.6
499	-0.2	-3.16	1.992	-0.04	126.4
502	-0.2	-3.19	2.004	-0.04	127.6
505	-0.2	-3.21	2.016	-0.04	128.4
508	-0.2	-3.23	2.028	-0.04	129.2
511	-0.4	-3.25	2.040	-0.08	130.0
514	0.2	-3.27	2.052	0.04	130.8
517	-0.2	-3.29	2.064	-0.04	131.6
520	0.0	-3.31	2.076	0.00	132.4
523	0.0	-3.33	2.088	0.00	133.2
526	-0.2	-3.35	2.100	-0.04	134.0
529	-0.2	-3.37	2.112	-0.04	134.8
532	-0.4	-3.40	2.124	-0.08	136.0
535	-0.2	-3.43	2.136	-0.04	137.2
538	-0.2	-3.45	2.148	-0.04	138.0
541	-0.4	-3.47	2.160	-0.08	138.8
544	-0.2	-3.49	2.172	-0.04	139.6
547	-0.2	-3.51	2.184	-0.04	140.4
550	-0.2	-3.53	2.196	-0.04	141.2
553	-0.4	-3.55	2.208	-0.08	142.0
556	-0.2	-3.57	2.220	-0.04	142.8
559	-0.2	-3.59	2.232	-0.04	143.6
562	0.2	-3.61	2.244	0.04	144.4
565	-0.2	-3.64	2.256	-0.04	145.6
568	0.0	-3.66	2.268	0.00	146.4
571	-0.2	-3.68	2.280	-0.04	147.2
574	-0.2	-3.70	2.292	-0.04	148.0
577	-0.2	-3.72	2.304	-0.04	148.8
580	-0.2	-3.74	2.316	-0.04	149.6
583	-0.2	-3.76	2.328	-0.04	150.4
586	0.0	-3.78	2.340	0.00	151.2
589	0.2	-3.80	2.352	0.04	152.0
592	-0.2	-3.83	2.364	-0.04	153.2
595	-0.2	-3.85	2.376	-0.04	154.0
598	-0.2	-3.87	2.388	-0.04	154.8
601	-0.2	-3.89	2.400	-0.04	155.6
604	-0.2	-3.91	2.412	-0.04	156.4
607	-0.2	-3.93	2.424	-0.04	157.2
610	-0.4	-3.95	2.436	-0.08	158.0
613	-0.2	-3.97	2.448	-0.04	158.8
616	-0.2	-3.99	2.460	-0.04	159.6
619	-0.2	-4.02	2.472	-0.04	160.8
622	-0.2	-4.04	2.484	-0.04	161.6
625	-0.2	-4.06	2.496	-0.04	162.4
628	-0.2	-4.08	2.508	-0.04	163.2
631	-0.2	-4.10	2.520	-0.04	164.0
634	-0.4	-4.12	2.532	-0.08	164.8
637	0.0	-4.14	2.544	0.00	165.6
640	-0.2	-4.16	2.556	-0.04	166.4
643	0.0	-4.18	2.568	0.00	167.2
646	-0.2	-4.21	2.580	-0.04	168.4
649	-0.2	-4.23	2.592	-0.04	169.2
652	-0.2	-4.25	2.604	-0.04	170.0
655	-0.4	-4.27	2.616	-0.08	170.8
658	-0.2	-4.29	2.628	-0.04	171.6
661	-0.2	-4.31	2.640	-0.04	172.4
664	-0.2	-4.33	2.652	-0.04	173.2
667	-0.2	-4.35	2.664	-0.04	174.0
670	0.2	-4.38	2.676	0.04	175.2
673	-0.4	-4.40	2.688	-0.08	176.0
676	0.0	-4.42	2.700	0.00	176.8
679	0.0	-4.44	2.712	0.00	177.6
682	-0.2	-4.46	2.724	-0.04	178.4
685	-0.4	-4.48	2.736	-0.08	179.2
688	-0.2	-4.50	2.748	-0.04	180.0
691	-0.4	-4.52	2.760	-0.08	180.8
694	-0.4	-4.54	2.772	-0.08	181.6
697	-0.2	-4.57	2.784	-0.04	182.8
700	-0.2	-4.59	2.796	-0.04	183.6
703	-0.2	-4.61	2.808	-0.04	184.4
706	-0.4	-4.63	2.820	-0.08	185.2
709	0.0	-4.65	2.832	0.00	186.0
712	-0.2	-4.67	2.844	-0.04	186.8
715	-0.2	-4.69	2.856	-0.04	187.6
718	-0.4	-4.71	2.868	-0.08	188.4
721	-0.2	-4.73	2.880	-0.04	189.2
724	0.2	-4.76	2.892	0.04	190.4
727	-0.2	-4.78	2.904	-0.04	191.2
730	-0.2	-4.80	2.916	-0.04	192.0
733	-0.2	-4.82	2.928	-0.04	192.8
736	-0.2	-4.84	2.940	-0.04	193.6
739	-0.2	-4.86	2.952	-0.04	194.4
742	-0.4	-4.88	2.964	-0.08	195.2
745	-0.2	-4.90	2.976	-0.04	196.0
748	-0.2	-4.92	2.988	-0.04	196.8
751	-0.2	-4.95	3.000	-0.04	198.0
754	-0.2	-4.97	3.012	-0.04	198.8
757	0.0	-4.99	3.024	0.00	199.6
760	-0.2	-5.01	3.036	-0.04	200.4
763	0.0	-5.03	3.048	0.00	201.2
766	-0.2	-5.05	3.060	-0.04	202.0
769	-0.2	-5.07	3.072	-0.04	202.8
772	-0.2	-5.09	3.084	-0.04	203.6
775	-0.2	-5.11	3.096	-0.04	204.4
778	-0.4	-5.14	3.108	-0.08	205.6
781	-0.4	-5.16	3.120	-0.08	206.4
784	-0.4	-5.18	3.132	-0.08	207.2
787	-0.2	-5.20	3.144	-0.04	208.0
790	-0.4	-5.22	3.156	-0.08	208.8
793	-0.4	-5.24	3.168	-0.08	209.6
796	-0.2	-5.26	3.180	-0.04	210.4
799	-0.2	-5.28	3.192	-0.04	211.2
802	0.0	-5.30	3.204	0.00	212.0
805	-0.2	-5.33	3.216	-0.04	213.2
808	-0.2	-5.35	3.228	-0.04	214.0
811	-0.2	-5.37	3.240	-0.04	214.8
814	-0.2	-5.39	3.252	-0.04	215.6
817	-0.4	-5.41	3.264	-0.08	216.4
820	0.0	-5.43	3.276	0.00	217.2
823	0.0	-5.45	3.288	0.00	218.0
826	0.0	-5.47	3.300	0.00	218.8
829	-0.2	-5.49	3.312	-0.04	219.6
832	-0.2	-5.52	3.324	-0.04	220.8
835	-0.4	-5.54	3.336	-0.08	221.6
838	-0.2	-5.56	3.348	-0.04	222.4
841	-0.2	-5.58	3.360	-0.04	223.2
844	-0.2	-5.60	3.372	-0.04	224.0
847	-0.2	-5.62	3.384	-0.04	224.8
850	-0.2	-5.64	3.396	-0.04	225.6
853	-0.2	-5.66	3.408	-0.04	226.4
856	-0.2	-5.68	3.420	-0.04	227.2
859	0.0	-5.70	3.432	0.00	228.0
862	-0.2	-5.73	3.444	-0.04	229.2
865	-0.2	-5.75	3.456	-0.04	230.0
868	-0.4	-5.77	3.468	-0.08	230.8
871	-0.4	-5.79	3.480	-0.08	231.6
874	-0.6	-5.81	3.492	-0.12	232.4
877	-0.2	-5.83	3.504	-0.04	233.2
880	-0.2	-5.85	3.516	-0.04	234.0
883	-0.2	-5.87	3.528	-0.04	234.8
886	-0.2	-5.89	3.540	-0.04	235.6
889	-0.2	-5.92	3.552	-0.04	236.8
892	-0.2	-5.93	3.564	-0.04	237.2
895	-0.4	-5.96	3.576	-0.08	238.4
898	-0.4	-5.98	3.588	-0.08	239.2
901	0.0	-6.00	3.600	0.00	240.0
904	-0.2	-6.02	3.612	-0.04	240.8
907	-0.2	-6.04	3.624	-0.04	241.6
910	-0.2	-6.06	3.636	-0.04	242.4
913	0.0	-6.08	3.648	0.00	243.2
916	-0.4	-6.10	3.660	-0.08	244.0
919	-0.2	-6.12	3.672	-0.04	244.8
922	-0.2	-6.15	3.684	-0.04	246.0
925	-0.2	-6.16	3.696	-0.04	246.4
928	-0.2	-6.19	3.708	-0.04	247.6
931	-0.2	-6.21	3.720	-0.04	248.4
934	-0.2	-6.23	3.732	-0.04	249.2
937	-0.2	-6.25	3.744	-0.04	250.0
940	-0.2	-6.27	3.756	-0.04	250.8
943	-0.2	-6.29	3.768	-0.04	251.6
946	-0.2	-6.31	3.780	-0.04	252.4
949	0.0	-6.33	3.792	0.00	253.2
952	-0.2	-6.35	3.804	-0.04	254.0
955	0.0	-6.37	3.816	0.00	254.8
958	0.0	-6.39	3.828	0.00	255.6
961	-0.2	-6.41	3.840	-0.04	256.4
964	-0.2	-6.43	3.852	-0.04	257.2
967	0.0	-6.45	3.864	0.00	258.0
970	-0.2	-6.47	3.876	-0.04	258.8
973	-0.2	-6.49	3.888	-0.04	259.6
976	-0.2	-6.51	3.900	-0.04	260.4
979	-0.2	-6.53	3.912	-0.04	261.2
982	-0.2	-6.55	3.924	-0.04	262.0
985	-0.2	-6.57	3.936	-0.04	262.8
988	0.4	-6.59	3.948	0.08	263.6
991	-0.2	-6.62	3.960	-0.04	264.8
994	-0.2	-6.64	3.972	-0.04	265.6
997	-0.2	-6.66	3.984	-0.04	266.4
1000	-0.2	-6.68	3.996	-0.04	267.2
1003	-0.2	-6.70	4.008	-0.04	268.0
1006	-0.2	-6.72	4.020	-0.04	268.8
1009	0.0	-6.74	4.032	0.00	269.6
1012	-0.2	-6.76	4.044	-0.04	270.4
1015	-0.2	-6.78	4.056	-0.04	271.2
1018	0.2	-6.80	4.068	0.04	272.0
1021	0.0	-6.82	4.080	0.00	272.8
1024	-0.4	-6.84	4.092	-0.08	273.6
1027	-0.2	-6.86	4.104	-0.04	274.4
1030	-0.2	-6.89	4.116	-0.04	275.6
1033	-0.2	-6.91	4.128	-0.04	276.4
1036	-0.2	-6.93	4.140	-0.04	277.2
1039	-0.2	-6.95	4.152	-0.04	278.0
1042	-0.2	-6.97	4.164	-0.04	278.8
1045	-0.2	-6.99	4.176	-0.04	279.6
1048	-0.2	-7.01	4.188	-0.04	280.4
1051	-0.2	-7.03	4.200	-0.04	281.2
1054	0.0	-7.05	4.212	0.00	282.0
1057	-0.2	-7.07	4.224	-0.04	282.8
1060	-0.2	-7.09	4.236	-0.04	283.6
1063	-0.2	-7.12	4.248	-0.04	284.8
1066	-0.4	-7.14	4.260	-0.08	285.6
1069	0.0	-7.16	4.272	0.00	286.4
1072	-0.2	-7.18	4.284	-0.04	287.2
1075	-0.2	-7.20	4.296	-0.04	288.0
1078	-0.2	-7.22	4.308	-0.04	288.8
1081	0.0	-7.24	4.320	0.00	289.6
1084	-0.2	-7.26	4.332	-0.04	290.4
1087	-0.2	-7.28	4.344	-0.04	291.2
1090	0.2	-7.30	4.356	0.04	292.0
1093	0.0	-7.32	4.368	0.00	292.8
1096	-0.2	-7.34	4.380	-0.04	293.6
1099	-0.2	-7.37	4.392	-0.04	294.8
1102	-0.4	-7.39	4.404	-0.08	295.6
1105	-0.2	-7.42	4.416	-0.04	296.8
1108	-0.2	-7.44	4.428	-0.04	297.6
1111	-0.2	-7.46	4.440	-0.04	298.4
1114	-0.2	-7.48	4.452	-0.04	299.2
1117	-0.2	-7.50	4.464	-0.04	300.0
1120	-0.2	-7.52	4.476	-0.04	300.8
1123	0.0	-7.54	4.488	0.00	301.6
1126	-0.2	-7.56	4.500	-0.04	302.4
1129	0.0	-7.58	4.512	0.00	303.2
1132	-0.2	-7.61	4.524	-0.04	304.4
1135	-0.2	-7.62	4.536	-0.04	304.8
1138	-0.4	-7.65	4.548	-0.08	306.0
1141	-0.2	-7.67	4.560	-0.04	306.8
1144	0.2	-7.69	4.572	0.04	307.6
1147	-0.2	-7.71	4.584	-0.04	308.4
1150	-0.2	-7.73	4.596	-0.04	309.2
1153	-0.2	-7.75	4.608	-0.04	310.0
1156	-0.2	-7.77	4.620	-0.04	310.8
1159	0.4	-7.79	4.632	0.08	311.6
1162	-0.2	-7.81	4.644	-0.04	312.4
1165	-0.2	-7.84	4.656	-0.04	313.6
1168	-0.2	-7.85	4.668	-0.04	314.0
1171	-0.2	-7.88	4.680	-0.04	315.2
1174	-0.2	-7.90	4.692	-0.04	316.0
1177	-0.2	-7.92	4.704	-0.04	316.8
1180	-0.2	-7.94	4.716	-0.04	317.6
1183	0.0	-7.96	4.728	0.00	318.4
1186	-0.4	-7.98	4.740	-0.08	319.2
1189	0.0	-8.00	4.752	0.00	320.0
1192	0.2	-8.02	4.764	0.04	320.8
1195	0.0	-8.04	4.776	0.00	321.6
1198	0.2	-8.06	4.788	0.04	322.4
1201	0.0	-8.08	4.800	0.00	323.2
1204	0.0	-8.11	4.812	0.00	324.4
1207	0.0	-8.13	4.824	0.00	325.2
1210	0.0	-8.15	4.836	0.00	326.0
1213	0.0	-8.17	4.848	0.00	326.8
1216	0.0	-8.19	4.860	0.00	327.6
1219	0.0	-8.21	4.872	0.00	328.4
1222	-0.2	-8.23	4.884	-0.04	329.2
1225	0.0	-8.25	4.896	0.00	330.0
1228	-0.2	-8.27	4.908	-0.04	330.8
1231	0.0	-8.29	4.920	0.00	331.6
1234	-0.2	-8.32	4.932	-0.04	332.8
1237	0.0	-8.34	4.944	0.00	333.6
1240	0.2	-8.36	4.956	0.04	334.4
1243	-0.2	-8.38	4.968	-0.04	335.2
1246	-0.4	-8.40	4.980	-0.08	336.0
1249	0.0	-8.42	4.992	0.00	336.8
1252	0.0	-8.44	5.004	0.00	337.6
1255	0.2	-8.46	5.016	0.04	338.4
1258	0.0	-8.48	5.028	0.00	339.2
1261	-0.2	-8.51	5.040	-0.04	340.4
1264	0.0	-8.52	5.052	0.00	340.8
1267	0.0	-8.55	5.064	0.00	342.0
1270	0.0	-8.57	5.076	0.00	342.8
1273	-0.2	-8.59	5.088	-0.04	343.6
1276	0.0	-8.61	5.100	0.00	344.4
1279	-0.2	-8.63	5.112	-0.04	345.2
1282	-0.4	-8.65	5.124	-0.08	346.0
1285	-0.2	-8.67	5.136	-0.04	346.8
1288	-0.2	-8.69	5.148	-0.04	347.6
1291	0.0	-8.71	5.160	0.00	348.4
1294	-0.2	-8.74	5.172	-0.04	349.6
1297	-0.2	-8.76	5.184	-0.04	350.4
1300	-0.2	-8.78	5.196	-0.04	351.2
1303	-0.4	-8.80	5.208	-0.08	352.0
1306	0.0	-8.82	5.220	0.00	352.8
1309	-0.2	-8.84	5.232	-0.04	353.6
1312	-0.2	-8.86	5.244	-0.04	354.4
1315	0.0	-8.88	5.256	0.00	355.2
1318	-0.2	-8.90	5.268	-0.04	356.0
1321	0.2	-8.93	5.280	0.04	357.2
1324	-0.2	-8.95	5.292	-0.04	358.0
1327	-0.2	-8.97	5.304	-0.04	358.8
1330	0.2	-8.99	5.316	0.04	359.6
1333	-0.2	-9.01	5.328	-0.04	360.4
1336	-0.2	-9.03	5.340	-0.04	361.2
1339	-0.2	-9.05	5.352	-0.04	362.0
1342	-0.2	-9.07	5.364	-0.04	362.8
1345	-0.2	-9.09	5.376	-0.04	363.6
1348	-0.2	-9.12	5.388	-0.04	364.8
1351	0.0	-9.14	5.400	0.00	365.6
1354	-0.2	-9.16	5.412	-0.04	366.4
1357	-0.2	-9.18	5.424	-0.04	367.2
1360	-0.2	-9.20	5.436	-0.04	368.0
1363	-0.2	-9.22	5.448	-0.04	368.8
1366	-0.2	-9.24	5.460	-0.04	369.6
1369	-0.2	-9.27	5.472	-0.04	370.8
1372	-0.2	-9.28	5.484	-0.04	371.2
1375	-0.2	-9.31	5.496	-0.04	372.4
1378	-0.2	-9.33	5.508	-0.04	373.2
1381	-0.2	-9.35	5.520	-0.04	374.0
1384	-0.2	-9.37	5.532	-0.04	374.8
1387	-0.2	-9.39	5.544	-0.04	375.6
1390	-0.2	-9.41	5.556	-0.04	376.4
1393	-0.4	-9.43	5.568	-0.08	377.2
1396	-0.2	-9.45	5.580	-0.04	378.0
1399	-0.2	-9.47	5.592	-0.04	378.8
1402	-0.2	-9.50	5.604	-0.04	380.0
1405	-0.2	-9.52	5.616	-0.04	380.8
1408	-0.2	-9.54	5.628	-0.04	381.6
1411	0.0	-9.56	5.640	0.00	382.4
1414	0.0	-9.58	5.652	0.00	383.2
1417	-0.2	-9.60	5.664	-0.04	384.0
1420	0.0	-9.62	5.676	0.00	384.8
1423	-0.2	-9.65	5.688	-0.04	386.0
1426	-0.2	-9.66	5.700	-0.04	386.4
1429	-0.2	-9.69	5.712	-0.04	387.6
1432	-0.2	-9.71	5.724	-0.04	388.4
1435	-0.2	-9.73	5.736	-0.04	389.2
1438	-0.4	-9.75	5.748	-0.08	390.0
1441	-0.2	-9.77	5.760	-0.04	390.8
1444	-0.2	-9.79	5.772	-0.04	391.6
1447	-0.4	-9.81	5.784	-0.08	392.4
1450	-0.4	-9.84	5.796	-0.08	393.6
1453	-0.4	-9.86	5.808	-0.08	394.4
1456	0.2	-9.88	5.820	0.04	395.2
1459	0.2	-9.90	5.832	0.04	396.0
1462	0.0	-9.92	5.844	0.00	396.8
1465	-0.4	-9.94	5.856	-0.08	397.6
1468	0.0	-9.96	5.868	0.00	398.4
1471	-0.2	-9.98	5.880	-0.04	399.2
1474	-0.2	-10.00	5.892	-0.04	400.0
1477	-0.2	-10.03	5.904	-0.04	401.2
1480	-0.2	-10.05	5.916	-0.04	402.0
1483	-0.2	-10.07	5.928	-0.04	402.8
1486	-0.2	-10.09	5.940	-0.04	403.6
1489	-0.2	-10.11	5.952	-0.04	404.4
1492	-0.2	-10.13	5.964	-0.04	405.2
1495	0.0	-10.15	5.976	0.00	406.0
1498	-0.2	-10.17	5.988	-0.04	406.8
1501	0.0	-10.19	6.000	0.00	407.6
1504	-0.2	-10.22	6.012	-0.04	408.8
1507	-0.2	-10.24	6.024	-0.04	409.6
1510	-0.2	-10.26	6.036	-0.04	410.4
1513	-0.2	-10.28	6.048	-0.04	411.2
1516	-0.2	-10.30	6.060	-0.04	412.0
1519	-0.2	-10.32	6.072	-0.04	412.8
1522	-0.4	-10.34	6.084	-0.08	413.6
1525	-0.2	-10.36	6.096	-0.04	414.4
1528	0.0	-10.38	6.108	0.00	415.2
1531	-0.2	-10.40	6.120	-0.04	416.0
1534	-0.2	-10.42	6.132	-0.04	416.8
1537	-0.2	-10.44	6.144	-0.04	417.6
1540	-0.2	-10.46	6.156	-0.04	418.4
1543	-0.2	-10.48	6.168	-0.04	419.2
1546	-0.2	-10.50	6.180	-0.04	420.0
1549	-0.2	-10.52	6.192	-0.04	420.8
1552	0.2	-10.54	6.204	0.04	421.6
1555	0.4	-10.56	6.216	0.08	422.4
1558	0.0	-10.59	6.228	0.00	423.6
1561	0.0	-10.61	6.240	0.00	424.4
1564	0.0	-10.63	6.252	0.00	425.2
1567	0.0	-10.65	6.264	0.00	426.0
1570	0.0	-10.67	6.276	0.00	426.8
1573	0.0	-10.69	6.288	0.00	427.6
1576	0.2	-10.71	6.300	0.04	428.4
1579	0.0	-10.73	6.312	0.00	429.2
1582	0.0	-10.75	6.324	0.00	430.0
1585	-0.2	-10.78	6.336	-0.04	431.2
1588	-0.6	-10.80	6.348	-0.12	432.0
1591	0.0	-10.82	6.360	0.00	432.8
1594	0.0	-10.84	6.372	0.00	433.6
1597	0.0	-10.86	6.384	0.00	434.4
1600	-0.4	-10.88	6.396	-0.08	435.2
1603	-0.2	-10.90	6.408	-0.04	436.0
1606	-0.2	-10.92	6.420	-0.04	436.8
1609	0.0	-10.94	6.432	0.00	437.6
1612	-0.2	-10.96	6.444	-0.04	438.4
1615	-0.2	-10.98	6.456	-0.04	439.2
1618	-0.2	-11.01	6.468	-0.04	440.4
1621	0.0	-11.03	6.480	0.00	441.2
1624	-0.2	-11.05	6.492	-0.04	442.0
1627	-0.2	-11.07	6.504	-0.04	442.8
1630	0.0	-11.09	6.516	0.00	443.6
1633	0.0	-11.11	6.528	0.00	444.4
1636	0.0	-11.13	6.540	0.00	445.2
1639	0.0	-11.15	6.552	0.00	446.0
1642	-0.2	-11.17	6.564	-0.04	446.8
1645	-0.4	-11.19	6.576	-0.08	447.6
1648	-0.2	-11.21	6.588	-0.04	448.4
1651	-0.2	-11.24	6.600	-0.04	449.6
1654	-0.2	-11.26	6.612	-0.04	450.4
1657	-0.2	-11.28	6.624	-0.04	451.2
1660	-0.2	-11.30	6.636	-0.04	452.0
1663	-0.4	-11.32	6.648	-0.08	452.8
1666	-0.2	-11.34	6.660	-0.04	453.6
1669	-0.2	-11.36	6.672	-0.04	454.4
1672	0.0	-11.38	6.684	0.00	455.2
1675	-0.2	-11.40	6.696	-0.04	456.0
1678	-0.2	-11.42	6.708	-0.04	456.8
1681	-0.2	-11.45	6.720	-0.04	458.0
1684	-0.4	-11.47	6.732	-0.08	458.8
1687	-0.2	-11.49	6.744	-0.04	459.6
1690	-0.2	-11.51	6.756	-0.04	460.4
1693	-0.2	-11.53	6.768	-0.04	461.2
1696	-0.2	-11.55	6.780	-0.04	462.0
1699	-0.2	-11.57	6.792	-0.04	462.8
1702	-0.2	-11.59	6.804	-0.04	463.6
1705	0.2	-11.61	6.816	0.04	464.4
1708	-0.2	-11.63	6.828	-0.04	465.2
1711	-0.2	-11.65	6.840	-0.04	466.0
1714	0.0	-11.68	6.852	0.00	467.2
1717	-0.4	-11.70	6.864	-0.08	468.0
1720	-0.2	-11.72	6.876	-0.04	468.8
1723	-0.4	-11.74	6.888	-0.08	469.6
1726	-0.2	-11.76	6.900	-0.04	470.4
1729	-0.2	-11.78	6.912	-0.04	471.2
1732	-0.2	-11.80	6.924	-0.04	472.0
1735	-0.6	-11.82	6.936	-0.12	472.8
1738	-0.2	-11.84	6.948	-0.04	473.6
1741	-0.2	-11.86	6.960	-0.04	474.4
1744	0.0	-11.88	6.972	0.00	475.2
1747	-0.2	-11.91	6.984	-0.04	476.4
1750	-0.2	-11.92	6.996	-0.04	476.8
1753	-0.2	-11.95	7.008	-0.04	478.0
1756	-0.2	-11.97	7.020	-0.04	478.8
1759	-0.4	-11.99	7.032	-0.08	479.6
1762	-0.2	-12.01	7.044	-0.04	480.4
1765	0.2	-12.03	7.056	0.04	481.2
1768	-0.2	-12.05	7.068	-0.04	482.0
1771	0.0	-12.07	7.080	0.00	482.8
1774	-0.2	-12.09	7.092	-0.04	483.6
1777	-0.2	-12.11	7.104	-0.04	484.4
1780	-0.2	-12.13	7.116	-0.04	485.2
1783	-0.2	-12.15	7.128	-0.04	486.0
1786	-0.2	-12.18	7.140	-0.04	487.2
1789	-0.2	-12.20	7.152	-0.04	488.0
1792	-0.2	-12.22	7.164	-0.04	488.8
1795	0.0	-12.24	7.176	0.00	489.6
1798	-0.2	-12.26	7.188	-0.04	490.4
1801	-0.2	-12.28	7.200	-0.04	491.2
1804	-0.2	-12.30	7.212	-0.04	492.0
1807	-0.2	-12.32	7.224	-0.04	492.8
1810	-0.2	-12.34	7.236	-0.04	493.6
1813	-0.2	-12.36	7.248	-0.04	494.4
1816	-0.2	-12.39	7.260	-0.04	495.6
1819	-0.4	-12.42	7.272	-0.08	496.8
1822	0.0	-12.44	7.284	0.00	497.6
1825	-0.2	-12.46	7.296	-0.04	498.4
1828	-0.2	-12.48	7.308	-0.04	499.2
1831	-0.2	-12.50	7.320	-0.04	500.0
1834	-0.6	-12.52	7.332	-0.12	500.8
1837	-0.2	-12.54	7.344	-0.04	501.6
1840	-0.2	-12.56	7.356	-0.04	502.4
1843	0.0	-12.58	7.368	0.00	503.2
1846	-0.2	-12.60	7.380	-0.04	504.0
1849	-0.2	-12.63	7.392	-0.04	505.2
1852	-0.2	-12.64	7.404	-0.04	505.6
1855	-0.2	-12.67	7.416	-0.04	506.8
1858	0.0	-12.69	7.428	0.00	507.6
1861	0.0	-12.71	7.440	0.00	508.4
1864	-0.4	-12.73	7.452	-0.08	509.2
1867	0.0	-12.75	7.464	0.00	510.0
1870	-0.2	-12.77	7.476	-0.04	510.8
1873	-0.2	-12.79	7.488	-0.04	511.6
1876	-0.2	-12.81	7.500	-0.04	512.4
1879	-0.4	-12.83	7.512	-0.08	513.2
1882	-0.2	-12.86	7.524	-0.04	514.4
1885	-0.2	-12.88	7.536	-0.04	515.2
1888	-0.4	-12.90	7.548	-0.08	516.0
1891	-0.2	-12.92	7.560	-0.04	516.8
1894	0.2	-12.94	7.572	0.04	517.6
1897	-0.2	-12.96	7.584	-0.04	518.4
1900	-0.2	-12.98	7.596	-0.04	519.2
1903	-0.2	-13.00	7.608	-0.04	520.0
1906	-0.2	-13.02	7.620	-0.04	520.8
1909	-0.2	-13.04	7.632	-0.04	521.6
1912	0.0	-13.06	7.644	0.00	522.4
1915	-0.2	-13.09	7.656	-0.04	523.6
1918	-0.2	-13.11	7.668	-0.04	524.4
1921	-0.2	-13.13	7.680	-0.04	525.2
1924	0.0	-13.15	7.692	0.00	526.0
1927	0.0	-13.17	7.704	0.00	526.8
1930	-0.2	-13.19	7.716	-0.04	527.6
1933	-0.2	-13.21	7.728	-0.04	528.4
1936	-0.2	-13.23	7.740	-0.04	529.2
1939	-0.2	-13.25	7.752	-0.04	530.0
1942	-0.2	-13.27	7.764	-0.04	530.8
1945	-0.4	-13.29	7.776	-0.08	531.6
1948	-0.2	-13.31	7.788	-0.04	532.4
1951	0.0	-13.34	7.800	0.00	533.6
1954	-0.2	-13.36	7.812	-0.04	534.4
1957	-0.2	-13.38	7.824	-0.04	535.2
1960	-0.2	-13.40	7.836	-0.04	536.0
1963	-0.2	-13.42	7.848	-0.04	536.8
1966	-0.2	-13.44	7.860	-0.04	537.6
1969	-0.2	-13.46	7.872	-0.04	538.4
1972	0.0	-13.48	7.884	0.00	539.2
1975	-0.2	-13.50	7.896	-0.04	540.0
1978	-0.2	-13.53	7.908	-0.04	541.2
1981	-0.4	-13.55	7.920	-0.08	542.0
1984	-0.4	-13.57	7.932	-0.08	542.8
1987	-0.2	-13.59	7.944	-0.04	543.6
1990	-0.2	-13.61	7.956	-0.04	544.4
1993	-0.2	-13.63	7.968	-0.04	545.2
1996	-0.2	-13.65	7.980	-0.04	546.0
1999	0.0	-13.67	7.992	0.00	546.8
2002	0.0	-13.69	8.004	0.00	547.6
2005	-0.2	-13.72	8.016	-0.04	548.8
2008	0.0	-13.74	8.028	0.00	549.6
2011	0.0	-13.76	8.040	0.00	550.4
2014	-0.2	-13.78	8.052	-0.04	551.2
2017	-0.2	-13.80	8.064	-0.04	552.0
2020	-0.2	-13.82	8.076	-0.04	552.8
2023	-0.2	-13.84	8.088	-0.04	553.6
2026	0.0	-13.86	8.100	0.00	554.4
2029	0.2	-13.88	8.112	0.04	555.2
2032	-0.2	-13.91	8.124	-0.04	556.4
2035	-0.2	-13.93	8.136	-0.04	557.2
2038	-0.4	-13.95	8.148	-0.08	558.0
2041	-0.2	-13.97	8.160	-0.04	558.8
2044	-0.2	-13.99	8.172	-0.04	559.6
2047	-0.4	-14.01	8.184	-0.08	560.4
2050	-0.2	-14.03	8.196	-0.04	561.2
2053	-0.2	-14.05	8.208	-0.04	562.0
2056	-0.2	-14.07	8.220	-0.04	562.8
2059	-0.2	-14.10	8.232	-0.04	564.0
2062	-0.4	-14.12	8.244	-0.08	564.8
2065	-0.2	-14.14	8.256	-0.04	565.6
2068	0.0	-14.16	8.268	0.00	566.4
2071	-0.4	-14.18	8.280	-0.08	567.2
2074	-0.2	-14.20	8.292	-0.04	568.0
2077	-0.2	-14.22	8.304	-0.04	568.8
2080	-0.2	-14.24	8.316	-0.04	569.6
2083	0.2	-14.26	8.328	0.04	570.4
2086	-0.2	-14.29	8.340	-0.04	571.6
2089	-0.2	-14.31	8.352	-0.04	572.4
2092	-0.2	-14.33	8.364	-0.04	573.2
2095	-0.2	-14.35	8.376	-0.04	574.0
2098	-0.2	-14.37	8.388	-0.04	574.8
2101	-0.2	-14.39	8.400	-0.04	575.6
2104	-0.2	-14.41	8.412	-0.04	576.4
2107	-0.2	-14.43	8.424	-0.04	577.2
2110	-0.2	-14.46	8.436	-0.04	578.4
2113	-0.2	-14.48	8.448	-0.04	579.2
2116	-0.2	-14.50	8.460	-0.04	580.0
2119	0.0	-14.52	8.472	0.00	580.8
2122	-0.2	-14.54	8.484	-0.04	581.6
2125	-0.2	-14.56	8.496	-0.04	582.4
2128	-0.2	-14.58	8.508	-0.04	583.2
2131	-0.2	-14.60	8.520	-0.04	584.0
2134	-0.4	-14.62	8.532	-0.08	584.8
2137	-0.2	-14.64	8.544	-0.04	585.6
2140	-0.2	-14.67	8.556	-0.04	586.8
2143	-0.2	-14.69	8.568	-0.04	587.6
2146	-0.2	-14.71	8.580	-0.04	588.4
2149	-0.2	-14.73	8.592	-0.04	589.2
2152	0.0	-14.75	8.604	0.00	590.0
2155	-0.2	-14.77	8.616	-0.04	590.8
2158	-0.2	-14.79	8.628	-0.04	591.6
2161	-0.2	-14.81	8.640	-0.04	592.4
2164	0.0	-14.84	8.652	0.00	593.6
2167	0.0	-14.86	8.664	0.00	594.4
2170	-0.2	-14.88	8.676	-0.04	595.2
2173	0.2	-14.90	8.688	0.04	596.0
2176	-0.2	-14.92	8.700	-0.04	596.8
2179	-0.2	-14.94	8.712	-0.04	597.6
2182	-0.2	-14.96	8.724	-0.04	598.4
2185	0.0	-14.98	8.736	0.00	599.2
2188	0.0	-15.01	8.748	0.00	600.4
2191	-0.2	-15.03	8.760	-0.04	601.2
2194	-0.2	-15.05	8.772	-0.04	602.0
2197	-0.2	-15.07	8.784	-0.04	602.8
2200	-0.2	-15.09	8.796	-0.04	603.6
2203	-0.2	-15.11	8.808	-0.04	604.4
2206	0.0	-15.13	8.820	0.00	605.2
2209	-0.2	-15.15	8.832	-0.04	606.0
2212	0.0	-15.17	8.844	0.00	606.8
2215	-0.2	-15.20	8.856	-0.04	608.0
2218	-0.2	-15.22	8.868	-0.04	608.8
2221	-0.2	-15.24	8.880	-0.04	609.6
2224	-0.4	-15.26	8.892	-0.08	610.4
2227	-0.2	-15.28	8.904	-0.04	611.2
2230	-0.2	-15.30	8.916	-0.04	612.0
2233	0.0	-15.32	8.928	0.00	612.8
2236	-0.2	-15.34	8.940	-0.04	613.6
2239	-0.2	-15.36	8.952	-0.04	614.4
2242	0.0	-15.39	8.964	0.00	615.6
2245	-0.2	-15.40	8.976	-0.04	616.0
2248	-0.2	-15.42	8.988	-0.04	616.8
2251	-0.2	-15.44	9.000	-0.04	617.6
2254	-0.2	-15.46	9.012	-0.04	618.4
2257	-0.2	-15.48	9.024	-0.04	619.2
2260	-0.4	-15.50	9.036	-0.08	620.0
2263	-0.2	-15.52	9.048	-0.04	620.8
2266	-0.2	-15.54	9.060	-0.04	621.6
2269	-0.2	-15.57	9.072	-0.04	622.8
2272	-0.2	-15.59	9.084	-0.04	623.6
2275	-0.2	-15.61	9.096	-0.04	624.4
2278	-0.2	-15.63	9.108	-0.04	625.2
2281	0.0	-15.65	9.120	0.00	626.0
2284	0.0	-15.67	9.132	0.00	626.8
2287	-0.2	-15.69	9.144	-0.04	627.6
2290	-0.2	-15.71	9.156	-0.04	628.4
2293	-0.2	-15.73	9.168	-0.04	629.2
2296	-0.2	-15.75	9.180	-0.04	630.0
2299	-0.2	-15.77	9.192	-0.04	630.8
2302	0.2	-15.80	9.204	0.04	632.0
2305	-0.2	-15.82	9.216	-0.04	632.8
2308	-0.2	-15.84	9.228	-0.04	633.6
2311	-0.2	-15.86	9.240	-0.04	634.4
2314	0.0	-15.88	9.252	0.00	635.2
2317	-0.4	-15.90	9.264	-0.08	636.0
2320	-0.2	-15.92	9.276	-0.04	636.8
2323	-0.2	-15.94	9.288	-0.04	637.6
2326	0.2	-15.96	9.300	0.04	638.4
2329	-0.2	-15.99	9.312	-0.04	639.6
2332	-0.2	-16.01	9.324	-0.04	640.4
2335	-0.2	-16.03	9.336	-0.04	641.2
2338	-0.2	-16.05	9.348	-0.04	642.0
2341	-0.2	-16.07	9.360	-0.04	642.8
2344	-0.2	-16.09	9.372	-0.04	643.6
2347	-0.4	-16.11	9.384	-0.08	644.4
2350	-0.2	-16.13	9.396	-0.04	645.2
2353	-0.4	-16.15	9.408	-0.08	646.0
2356	0.2	-16.17	9.420	0.04	646.8
2359	0.2	-16.19	9.432	0.04	647.6
2362	-0.4	-16.22	9.444	-0.08	648.8
2365	-0.2	-16.24	9.456	-0.04	649.6
2368	-0.2	-16.26	9.468	-0.04	650.4
2371	0.0	-16.28	9.480	0.00	651.2
2374	0.0	-16.30	9.492	0.00	652.0
2377	-0.2	-16.32	9.504	-0.04	652.8
2380	-0.2	-16.34	9.516	-0.04	653.6
2383	-0.2	-16.36	9.528	-0.04	654.4
2386	-0.2	-16.38	9.540	-0.04	655.2
2389	-0.2	-16.40	9.552	-0.04	656.0
2392	-0.4	-16.42	9.564	-0.08	656.8
2395	-0.2	-16.45	9.576	-0.04	658.0
2398	-0.2	-16.47	9.588	-0.04	658.8
2401	-0.2	-16.49	9.600	-0.04	659.6
2404	-0.2	-16.51	9.612	-0.04	660.4
2407	-0.2	-16.53	9.624	-0.04	661.2
2410	-0.2	-16.55	9.636	-0.04	662.0
2413	-0.2	-16.57	9.648	-0.04	662.8
2416	-0.2	-16.59	9.660	-0.04	663.6
2419	-0.2	-16.61	9.672	-0.04	664.4
2422	-0.2	-16.63	9.684	-0.04	665.2
2425	-0.2	-16.65	9.696	-0.04	666.0
2428	0.0	-16.67	9.708	0.00	666.8
2431	-0.2	-16.70	9.720	-0.04	668.0
2434	0.0	-16.72	9.732	0.00	668.8
2437	-0.2	-16.74	9.744	-0.04	669.6
2440	-0.2	-16.76	9.756	-0.04	670.4
2443	0.0	-16.78	9.768	0.00	671.2
2446	-0.2	-16.80	9.780	-0.04	672.0
2449	0.2	-16.82	9.792	0.04	672.8
2452	-0.2	-16.84	9.804	-0.04	673.6
2455	-0.2	-16.86	9.816	-0.04	674.4
2458	0.0	-16.88	9.828	0.00	675.2
2461	-0.2	-16.90	9.840	-0.04	676.0
2464	-0.2	-16.93	9.852	-0.04	677.2
2467	0.0	-16.94	9.864	0.00	677.6
2470	-0.4	-16.97	9.876	-0.08	678.8
2473	-0.2	-16.99	9.888	-0.04	679.6
2476	-0.2	-17.01	9.900	-0.04	680.4
2479	-0.2	-17.03	9.912	-0.04	681.2
2482	-0.2	-17.05	9.924	-0.04	682.0
2485	-0.4	-17.07	9.936	-0.08	682.8
2488	-0.2	-17.09	9.948	-0.04	683.6
2491	0.0	-17.11	9.960	0.00	684.4
2494	0.0	-17.13	9.972	0.00	685.2
2497	-0.2	-17.15	9.984	-0.04	686.0
2500	-0.2	-17.17	9.996	-0.04	686.8
2503	-0.2	-17.20	10.008	-0.04	688.0
2506	-0.2	-17.22	10.020	-0.04	688.8
2509	0.2	-17.24	10.032	0.04	689.6
2512	0.0	-17.26	10.044	0.00	690.4
2515	-0.2	-17.28	10.056	-0.04	691.2
2518	-0.4	-17.30	10.068	-0.08	692.0
2521	0.0	-17.32	10.080	0.00	692.8
2524	0.0	-17.34	10.092	0.00	693.6
2527	-0.2	-17.36	10.104	-0.04	694.4
2530	-0.2	-17.38	10.116	-0.04	695.2
2533	0.2	-17.41	10.128	0.04	696.4
2536	0.0	-17.43	10.140	0.00	697.2
2539	-0.2	-17.46	10.152	-0.04	698.4
2542	-0.2	-17.48	10.164	-0.04	699.2
2545	-0.2	-17.50	10.176	-0.04	700.0
2548	-0.4	-17.52	10.188	-0.08	700.8
2551	0.4	-17.54	10.200	0.08	701.6
2554	-0.2	-17.56	10.212	-0.04	702.4
2557	-0.2	-17.58	10.224	-0.04	703.2
2560	-0.2	-17.60	10.236	-0.04	704.0
2563	-0.2	-17.62	10.248	-0.04	704.8
2566	0.0	-17.64	10.260	0.00	705.6
2569	-0.2	-17.66	10.272	-0.04	706.4
2572	0.0	-17.69	10.284	0.00	707.6
2575	-0.2	-17.71	10.296	-0.04	708.4
2578	-0.2	-17.73	10.308	-0.04	709.2
2581	-0.2	-17.75	10.320	-0.04	710.0
2584	0.0	-17.77	10.332	0.00	710.8
2587	-0.2	-17.79	10.344	-0.04	711.6
2590	-0.4	-17.81	10.356	-0.08	712.4
2593	-0.2	-17.83	10.368	-0.04	713.2
2596	-0.2	-17.85	10.380	-0.04	714.0
2599	0.0	-17.87	10.392	0.00	714.8
2602	-0.2	-17.89	10.404	-0.04	715.6
2605	-0.2	-17.92	10.416	-0.04	716.8
2608	-0.2	-17.94	10.428	-0.04	717.6
2611	-0.2	-17.96	10.440	-0.04	718.4
2614	-0.2	-17.98	10.452	-0.04	719.2
2617	0.0	-18.00	10.464	0.00	720.0
2620	-0.4	-18.02	10.476	-0.08	720.8
2623	0.0	-18.04	10.488	0.00	721.6
2626	-0.2	-18.06	10.500	-0.04	722.4
2629	-0.2	-18.08	10.512	-0.04	723.2
2632	0.2	-18.10	10.524	0.04	724.0
2635	-0.2	-18.12	10.536	-0.04	724.8
2638	-0.2	-18.14	10.548	-0.04	725.6
2641	-0.2	-18.17	10.560	-0.04	726.8
2644	-0.2	-18.19	10.572	-0.04	727.6
2647	-0.2	-18.21	10.584	-0.04	728.4
2650	0.0	-18.23	10.596	0.00	729.2
2653	0.0	-18.25	10.608	0.00	730.0
2656	-0.2	-18.27	10.620	-0.04	730.8
2659	-0.2	-18.29	10.632	-0.04	731.6
2662	-0.2	-18.31	10.644	-0.04	732.4
2665	-0.2	-18.33	10.656	-0.04	733.2
2668	-0.4	-18.35	10.668	-0.08	734.0
2671	-0.2	-18.37	10.680	-0.04	734.8
2674	-0.2	-18.40	10.692	-0.04	736.0
2677	-0.2	-18.42	10.704	-0.04	736.8
2680	-0.2	-18.44	10.716	-0.04	737.6
2683	-0.2	-18.46	10.728	-0.04	738.4
2686	-0.2	-18.48	10.740	-0.04	739.2
2689	-0.2	-18.50	10.752	-0.04	740.0
2692	-0.2	-18.52	10.764	-0.04	740.8
2695	-0.2	-18.54	10.776	-0.04	741.6
2698	0.0	-18.56	10.788	0.00	742.4
2701	-0.2	-18.59	10.800	-0.04	743.6
2704	-0.2	-18.61	10.812	-0.04	744.4
2707	-0.2	-18.63	10.824	-0.04	745.2
2710	-0.2	-18.65	10.836	-0.04	746.0
2713	-0.2	-18.67	10.848	-0.04	746.8
2716	-0.2	-18.69	10.860	-0.04	747.6
2719	-0.4	-18.71	10.872	-0.08	748.4
2722	-0.2	-18.73	10.884	-0.04	749.2
2725	-0.2	-18.75	10.896	-0.04	750.0
2728	-0.2	-18.78	10.908	-0.04	751.2
2731	-0.2	-18.80	10.920	-0.04	752.0
2734	-0.2	-18.82	10.932	-0.04	752.8
2737	0.0	-18.84	10.944	0.00	753.6
2740	-0.2	-18.86	10.956	-0.04	754.4
2743	-0.2	-18.88	10.968	-0.04	755.2
2746	-0.2	-18.90	10.980	-0.04	756.0
2749	-0.2	-18.92	10.992	-0.04	756.8
2752	-0.2	-18.94	11.004	-0.04	757.6
2755	-0.2	-18.97	11.016	-0.04	758.8
2758	-0.2	-18.98	11.028	-0.04	759.2
2761	0.0	-19.01	11.040	0.00	760.4
2764	-0.4	-19.03	11.052	-0.08	761.2
2767	-0.2	-19.05	11.064	-0.04	762.0
2770	-0.2	-19.07	11.076	-0.04	762.8
2773	-0.2	-19.09	11.088	-0.04	763.6
2776	0.0	-19.11	11.100	0.00	764.4
2779	-0.2	-19.13	11.112	-0.04	765.2
2782	0.0	-19.16	11.124	0.00	766.4
2785	-0.2	-19.17	11.136	-0.04	766.8
2788	0.0	-19.20	11.148	0.00	768.0
2791	0.0	-19.22	11.160	0.00	768.8
2794	-0.2	-19.24	11.172	-0.04	769.6
2797	-0.2	-19.26	11.184	-0.04	770.4
2800	-0.2	-19.28	11.196	-0.04	771.2
2803	-0.2	-19.30	11.208	-0.04	772.0
2806	-0.2	-19.32	11.220	-0.04	772.8
2809	-0.2	-19.35	11.232	-0.04	774.0
2812	0.0	-19.36	11.244	0.00	774.4
2815	-0.2	-19.39	11.256	-0.04	775.6
2818	-0.2	-19.40	11.268	-0.04	776.0
2821	-0.2	-19.42	11.280	-0.04	776.8
2824	-0.2	-19.44	11.292	-0.04	777.6
2827	-0.2	-19.46	11.304	-0.04	778.4
2830	-0.2	-19.48	11.316	-0.04	779.2
2833	-0.2	-19.50	11.328	-0.04	780.0
2836	0.0	-19.53	11.340	0.00	781.2
2839	-0.4	-19.55	11.352	-0.08	782.0
2842	-0.2	-19.57	11.364	-0.04	782.8
2845	0.2	-19.59	11.376	0.04	783.6
2848	0.0	-19.61	11.388	0.00	784.4
2851	-0.2	-19.63	11.400	-0.04	785.2
2854	-0.2	-19.65	11.412	-0.04	786.0
2857	-0.2	-19.67	11.424	-0.04	786.8
2860	0.0	-19.69	11.436	0.00	787.6
2863	0.0	-19.72	11.448	0.00	788.8
2866	-0.2	-19.74	11.460	-0.04	789.6
2869	-0.4	-19.76	11.472	-0.08	790.4
2872	-0.2	-19.78	11.484	-0.04	791.2
2875	-0.2	-19.80	11.496	-0.04	792.0
2878	-0.4	-19.82	11.508	-0.08	792.8
2881	-0.2	-19.84	11.520	-0.04	793.6
2884	-0.2	-19.86	11.532	-0.04	794.4
2887	0.2	-19.88	11.544	0.04	795.2
2890	-0.2	-19.91	11.556	-0.04	796.4
2893	-0.2	-19.93	11.568	-0.04	797.2
2896	-0.2	-19.95	11.580	-0.04	798.0
2899	-0.2	-19.97	11.592	-0.04	798.8
2902	0.2	-19.99	11.604	0.04	799.6
2905	-0.2	-20.01	11.616	-0.04	800.4
2908	0.2	-20.03	11.628	0.04	801.2
2911	-0.2	-20.05	11.640	-0.04	802.0
2914	-0.2	-20.07	11.652	-0.04	802.8
2917	-0.2	-20.10	11.664	-0.04	804.0
2920	-0.4	-20.12	11.676	-0.08	804.8
2923	0.4	-20.14	11.688	0.08	805.6
2926	-0.2	-20.16	11.700	-0.04	806.4
2929	0.2	-20.18	11.712	0.04	807.2
2932	2.2	-20.20	11.724	0.42	808.0
2935	5.2	-20.22	11.736	1.00	808.8
2938	8.8	-20.24	11.748	1.68	809.6
2941	13.0	-20.26	11.760	2.48	810.4
2944	18.6	-20.27	11.772	3.56	810.8
2947	24.4	-20.29	11.784	4.66	811.6
2950	31.2	-20.30	11.796	5.96	812.0
2953	39.6	-20.32	11.808	7.58	812.8
2956	46.8	-20.33	11.820	8.96	813.2
2959	58.4	-20.35	11.832	11.18	814.0
2962	68.8	-20.35	11.844	13.16	814.0
2965	81.4	-20.37	11.856	15.58	814.8
2968	92.2	-20.37	11.868	17.64	814.8
2971	97.2	-20.39	11.880	18.60	815.6
2974	95.4	-20.42	11.892	18.24	816.8
2977	95.6	-20.44	11.904	18.28	817.6
2980	96.0	-20.46	11.916	18.36	818.4
2983	95.8	-20.48	11.928	18.32	819.2
2986	96.2	-20.50	11.940	18.40	820.0
2989	95.2	-20.52	11.952	18.20	820.8
2992	95.4	-20.54	11.964	18.24	821.6
2995	93.4	-20.56	11.976	17.86	822.4
2998	92.4	-20.59	11.988	17.68	823.6
3001	90.8	-20.61	12.000	17.36	824.4
3004	89.2	-20.63	12.012	17.06	825.2
3007	87.4	-20.65	12.024	16.72	826.0
3010	85.8	-20.68	12.036	16.42	827.2
3013	84.2	-20.70	12.048	16.10	828.0
3016	82.8	-20.72	12.060	15.84	828.8
3019	81.4	-20.74	12.072	15.58	829.6
3022	81.2	-20.76	12.084	15.54	830.4
3025	80.0	-20.79	12.096	15.30	831.6
3028	75.8	-20.81	12.108	14.50	832.4
3031	72.8	-20.84	12.120	13.92	833.6
3034	54.4	-20.87	12.132	10.40	834.8
3037	55.4	-20.89	12.144	10.60	835.6
3040	56.2	-20.91	12.156	10.74	836.4
3043	55.8	-20.93	12.168	10.68	837.2
3046	53.0	-20.95	12.180	10.14	838.0
3049	48.8	-20.95	12.192	9.34	838.0
3052	47.0	-20.95	12.204	9.00	838.0
3055	45.8	-20.95	12.216	8.76	838.0
3058	44.8	-20.95	12.228	8.56	838.0
3061	44.4	-20.95	12.240	8.50	838.0
3064	43.6	-20.95	12.252	8.34	838.0
3067	43.2	-20.95	12.264	8.26	838.0
3070	42.8	-20.95	12.276	8.18	838.0