File: results/youngs-modulus/2025-04-25/inconclusive-data/pf18mt01.csv
sep=
pf18mt01

System Information:
IntelliMESUR Version: 2.2.1
Test Frame Model: F505
Test Frame Serial Number: 4418651
Test Frame Capacity: 500 lbF / 2.2 kN
Test Frame Firmware Version: 1.00.14
Force Sensor Model: FS05-100
Force Sensor Capacity: 500 N
Force Sensor Resolution: 0.2 N
Force Sensor Serial Number: 4425350
Calibration Date: Apr 29, 2024
Calibration Due Date: Apr 29, 2025

Reading	Load [N]	Distance [mm]	Time [s]	Stress [MPa]	Strain [%]
1	0.0	0.00	0.000	0.00	0.0
4	0.0	0.00	0.012	0.00	0.0
7	0.0	0.00	0.024	0.00	0.0
10	-0.2	0.00	0.036	-0.04	0.0
13	0.0	0.00	0.048	0.00	0.0
16	0.0	0.00	0.060	0.00	0.0
19	0.0	0.00	0.072	0.00	0.0
22	0.2	0.00	0.084	0.04	0.0
25	0.0	0.00	0.096	0.00	0.0
28	-0.2	0.00	0.108	-0.04	0.0
31	0.0	0.00	0.120	0.00	0.0
34	0.0	0.00	0.132	0.00	0.0
37	0.2	0.00	0.144	0.04	0.0
40	0.0	0.00	0.156	0.00	0.0
43	0.0	0.00	0.168	0.00	0.0
46	0.0	0.00	0.180	0.00	0.0
49	0.0	-0.01	0.192	0.00	0.4
52	0.0	-0.03	0.204	0.00	1.0
55	-0.2	-0.05	0.216	-0.04	1.6
58	0.2	-0.06	0.228	0.04	2.0
61	-0.2	-0.08	0.240	-0.04	2.6
64	0.0	-0.10	0.252	0.00	3.4
67	0.0	-0.12	0.264	0.00	4.0
70	0.0	-0.14	0.276	0.00	4.6
73	0.0	-0.17	0.288	0.00	5.8
76	0.0	-0.19	0.300	0.00	6.4
79	0.0	-0.21	0.312	0.00	7.0
82	0.0	-0.23	0.324	0.00	7.8
85	0.0	-0.25	0.336	0.00	8.4
88	0.0	-0.27	0.348	0.00	9.0
91	0.0	-0.29	0.360	0.00	9.8
94	0.0	-0.31	0.372	0.00	10.4
97	0.0	-0.33	0.384	0.00	11.0
100	0.2	-0.36	0.396	0.04	12.0
103	0.0	-0.38	0.408	0.00	12.8
106	0.0	-0.40	0.420	0.00	13.4
109	-0.4	-0.42	0.432	-0.06	14.0
112	0.0	-0.44	0.444	0.00	14.8
115	0.0	-0.46	0.456	0.00	15.4
118	0.0	-0.48	0.468	0.00	16.2
121	-0.2	-0.50	0.480	-0.04	16.8
124	0.0	-0.52	0.492	0.00	17.4
127	0.2	-0.54	0.504	0.04	18.2
130	0.0	-0.56	0.516	0.00	18.8
133	0.2	-0.59	0.528	0.04	19.8
136	0.0	-0.61	0.540	0.00	20.4
139	0.0	-0.63	0.552	0.00	21.2
142	0.0	-0.65	0.564	0.00	21.8
145	0.0	-0.67	0.576	0.00	22.4
148	0.4	-0.69	0.588	0.06	23.2
151	0.0	-0.71	0.600	0.00	23.8
154	0.2	-0.73	0.612	0.04	24.4
157	0.0	-0.75	0.624	0.00	25.2
160	0.0	-0.77	0.636	0.00	25.8
163	-0.2	-0.80	0.648	-0.04	26.8
166	0.0	-0.82	0.660	0.00	27.6
169	0.0	-0.84	0.672	0.00	28.2
172	0.0	-0.86	0.684	0.00	28.8
175	-0.2	-0.88	0.696	-0.04	29.6
178	0.0	-0.90	0.708	0.00	30.2
181	0.2	-0.92	0.720	0.04	30.8
184	0.2	-0.94	0.732	0.04	31.6
187	0.0	-0.96	0.744	0.00	32.2
190	0.0	-0.98	0.756	0.00	32.8
193	0.0	-1.00	0.768	0.00	33.6
196	0.0	-1.03	0.780	0.00	34.6
199	0.0	-1.06	0.792	0.00	35.6
202	0.2	-1.08	0.804	0.04	36.2
205	0.0	-1.10	0.816	0.00	37.0
208	0.0	-1.12	0.828	0.00	37.6
211	0.0	-1.14	0.840	0.00	38.2
214	0.0	-1.16	0.852	0.00	39.0
217	0.0	-1.18	0.864	0.00	39.6
220	0.0	-1.20	0.876	0.00	40.2
223	0.0	-1.22	0.888	0.00	41.0
226	0.0	-1.24	0.900	0.00	41.6
229	0.2	-1.27	0.912	0.04	42.6
232	0.0	-1.29	0.924	0.00	43.2
235	0.2	-1.31	0.936	0.04	44.0
238	0.0	-1.33	0.948	0.00	44.6
241	0.0	-1.35	0.960	0.00	45.4
244	0.0	-1.37	0.972	0.00	46.0
247	0.0	-1.39	0.984	0.00	46.6
250	0.0	-1.41	0.996	0.00	47.4
253	0.0	-1.43	1.008	0.00	48.0
256	0.0	-1.45	1.020	0.00	48.6
259	0.0	-1.47	1.032	0.00	49.4
262	0.0	-1.50	1.044	0.00	50.4
265	-0.2	-1.52	1.056	-0.04	51.0
268	0.0	-1.54	1.068	0.00	51.6
271	0.0	-1.56	1.080	0.00	52.4
274	0.0	-1.58	1.092	0.00	53.0
277	0.0	-1.60	1.104	0.00	53.6
280	0.0	-1.62	1.116	0.00	54.4
283	0.0	-1.64	1.128	0.00	55.0
286	0.0	-1.66	1.140	0.00	55.8
289	0.0	-1.68	1.152	0.00	56.4
292	-0.2	-1.70	1.164	-0.04	57.0
295	-0.2	-1.72	1.176	-0.04	57.8
298	0.0	-1.75	1.188	0.00	58.8
301	0.0	-1.77	1.200	0.00	59.4
304	0.0	-1.79	1.212	0.00	60.0
307	0.0	-1.81	1.224	0.00	60.8
310	0.0	-1.83	1.236	0.00	61.4
313	-0.2	-1.85	1.248	-0.04	62.0
316	0.0	-1.87	1.260	0.00	62.8
319	0.0	-1.89	1.272	0.00	63.4
322	0.0	-1.91	1.284	0.00	64.0
325	0.0	-1.93	1.296	0.00	64.8
328	0.0	-1.95	1.308	0.00	65.4
331	0.0	-1.98	1.320	0.00	66.4
334	-0.2	-2.00	1.332	-0.04	67.2
337	0.0	-2.02	1.344	0.00	67.8
340	0.2	-2.04	1.356	0.04	68.4
343	0.2	-2.05	1.368	0.04	68.8
346	-0.2	-2.07	1.380	-0.04	69.4
349	0.2	-2.09	1.392	0.04	70.2
352	0.0	-2.11	1.404	0.00	70.8
355	0.0	-2.13	1.416	0.00	71.4
358	0.0	-2.15	1.428	0.00	72.2
361	0.0	-2.17	1.440	0.00	72.8
364	0.0	-2.19	1.452	0.00	73.4
367	0.0	-2.22	1.464	0.00	74.4
370	-0.2	-2.24	1.476	-0.04	75.2
373	0.0	-2.26	1.488	0.00	75.8
376	-0.2	-2.28	1.500	-0.04	76.6
379	-0.2	-2.30	1.512	-0.04	77.2
382	0.0	-2.32	1.524	0.00	77.8
385	0.2	-2.34	1.536	0.04	78.6
388	0.0	-2.36	1.548	0.00	79.2
391	0.0	-2.38	1.560	0.00	79.8
394	0.2	-2.40	1.572	0.04	80.6
397	0.0	-2.42	1.584	0.00	81.2
400	0.0	-2.45	1.596	0.00	82.2
403	0.0	-2.47	1.608	0.00	82.8
406	-0.2	-2.49	1.620	-0.04	83.6
409	-0.2	-2.51	1.632	-0.04	84.2
412	0.0	-2.53	1.644	0.00	84.8
415	0.0	-2.55	1.656	0.00	85.6
418	0.0	-2.57	1.668	0.00	86.2
421	0.0	-2.59	1.680	0.00	87.0
424	0.0	-2.61	1.692	0.00	87.6
427	0.0	-2.63	1.704	0.00	88.2
430	0.0	-2.65	1.716	0.00	89.0
433	-0.2	-2.68	1.728	-0.04	90.0
436	0.0	-2.70	1.740	0.00	90.6
439	0.0	-2.72	1.752	0.00	91.2
442	0.0	-2.74	1.764	0.00	92.0
445	-0.2	-2.76	1.776	-0.04	92.6
448	-0.2	-2.78	1.788	-0.04	93.2
451	0.0	-2.80	1.800	0.00	94.0
454	0.0	-2.82	1.812	0.00	94.6
457	0.0	-2.84	1.824	0.00	95.4
460	0.0	-2.86	1.836	0.00	96.0
463	-0.2	-2.88	1.848	-0.04	96.6
466	0.0	-2.91	1.860	0.00	97.6
469	-0.2	-2.93	1.872	-0.04	98.4
472	0.0	-2.95	1.884	0.00	99.0
475	-0.2	-2.97	1.896	-0.04	99.6
478	0.0	-2.99	1.908	0.00	100.4
481	0.2	-3.01	1.920	0.04	101.0
484	0.2	-3.03	1.932	0.04	101.6
487	-0.2	-3.06	1.944	-0.04	102.6
490	0.0	-3.08	1.956	0.00	103.4
493	0.2	-3.11	1.968	0.04	104.4
496	0.0	-3.13	1.980	0.00	105.0
499	0.0	-3.15	1.992	0.00	105.8
502	-0.2	-3.17	2.004	-0.04	106.4
505	-0.2	-3.19	2.016	-0.04	107.0
508	0.4	-3.21	2.028	0.06	107.8
511	0.0	-3.23	2.040	0.00	108.4
514	-0.2	-3.25	2.052	-0.04	109.0
517	0.0	-3.27	2.064	0.00	109.8
520	-0.2	-3.29	2.076	-0.04	110.4
523	0.0	-3.32	2.088	0.00	111.4
526	0.4	-3.34	2.100	0.06	112.0
529	0.0	-3.36	2.112	0.00	112.8
532	0.0	-3.38	2.124	0.00	113.4
535	0.2	-3.40	2.136	0.04	114.0
538	0.0	-3.42	2.148	0.00	114.8
541	-0.2	-3.44	2.160	-0.04	115.4
544	0.0	-3.46	2.172	0.00	116.2
547	0.0	-3.48	2.184	0.00	116.8
550	0.0	-3.50	2.196	0.00	117.4
553	0.0	-3.53	2.208	0.00	118.4
556	0.0	-3.55	2.220	0.00	119.2
559	0.2	-3.57	2.232	0.04	119.8
562	0.2	-3.59	2.244	0.04	120.4
565	0.0	-3.61	2.256	0.00	121.2
568	0.0	-3.63	2.268	0.00	121.8
571	0.0	-3.65	2.280	0.00	122.4
574	0.4	-3.67	2.292	0.06	123.2
577	0.0	-3.69	2.304	0.00	123.8
580	0.4	-3.72	2.316	0.06	124.8
583	0.4	-3.74	2.328	0.06	125.6
586	0.0	-3.76	2.340	0.00	126.2
589	0.0	-3.78	2.352	0.00	126.8
592	0.0	-3.80	2.364	0.00	127.6
595	0.0	-3.82	2.376	0.00	128.2
598	0.0	-3.84	2.388	0.00	128.8
601	-0.2	-3.86	2.400	-0.04	129.6
604	0.0	-3.89	2.412	0.00	130.6
607	0.0	-3.91	2.424	0.00	131.2
610	0.0	-3.93	2.436	0.00	131.8
613	-0.2	-3.95	2.448	-0.04	132.6
616	0.0	-3.97	2.460	0.00	133.2
619	0.0	-3.99	2.472	0.00	133.8
622	0.0	-4.01	2.484	0.00	134.6
625	0.0	-4.03	2.496	0.00	135.2
628	-0.2	-4.06	2.508	-0.04	136.2
631	0.0	-4.08	2.520	0.00	137.0
634	0.0	-4.10	2.532	0.00	137.6
637	0.0	-4.12	2.544	0.00	138.2
640	-0.2	-4.14	2.556	-0.04	139.0
643	0.0	-4.16	2.568	0.00	139.6
646	0.0	-4.18	2.580	0.00	140.2
649	-0.2	-4.20	2.592	-0.04	141.0
652	0.0	-4.22	2.604	0.00	141.6
655	0.0	-4.25	2.616	0.00	142.6
658	0.0	-4.27	2.628	0.00	143.2
661	0.0	-4.29	2.640	0.00	144.0
664	-0.2	-4.31	2.652	-0.04	144.6
667	0.0	-4.33	2.664	0.00	145.4
670	0.2	-4.35	2.676	0.04	146.0
673	0.2	-4.37	2.688	0.04	146.6
676	0.0	-4.39	2.700	0.00	147.4
679	-0.2	-4.41	2.712	-0.04	148.0
682	0.2	-4.44	2.724	0.04	149.0
685	0.0	-4.46	2.736	0.00	149.6
688	-0.2	-4.48	2.748	-0.04	150.4
691	0.0	-4.50	2.760	0.00	151.0
694	0.0	-4.52	2.772	0.00	151.6
697	0.2	-4.54	2.784	0.04	152.4
700	0.0	-4.56	2.796	0.00	153.0
703	0.2	-4.58	2.808	0.04	153.6
706	0.0	-4.60	2.820	0.00	154.4
709	0.0	-4.63	2.832	0.00	155.4
712	0.2	-4.65	2.844	0.04	156.0
715	0.0	-4.67	2.856	0.00	156.8
718	-0.2	-4.69	2.868	-0.04	157.4
721	0.0	-4.71	2.880	0.00	158.0
724	0.0	-4.73	2.892	0.00	158.8
727	-0.2	-4.75	2.904	-0.04	159.4
730	0.0	-4.77	2.916	0.00	160.0
733	0.0	-4.79	2.928	0.00	160.8
736	0.0	-4.82	2.940	0.00	161.8
739	0.0	-4.84	2.952	0.00	162.4
742	0.0	-4.86	2.964	0.00	163.0
745	0.0	-4.88	2.976	0.00	163.8
748	0.2	-4.90	2.988	0.04	164.4
751	-0.2	-4.92	3.000	-0.04	165.2
754	0.0	-4.94	3.012	0.00	165.8
757	0.0	-4.96	3.024	0.00	166.4
760	0.0	-4.98	3.036	0.00	167.2
763	0.0	-5.01	3.048	0.00	168.2
766	0.0	-5.03	3.060	0.00	168.8
769	0.2	-5.05	3.072	0.04	169.4
772	0.2	-5.07	3.084	0.04	170.2
775	0.0	-5.09	3.096	0.00	170.8
778	0.0	-5.11	3.108	0.00	171.4
781	0.0	-5.13	3.120	0.00	172.2
784	0.0	-5.15	3.132	0.00	172.8
787	0.0	-5.17	3.144	0.00	173.4
790	0.4	-5.20	3.156	0.06	174.4
793	0.0	-5.22	3.168	0.00	175.2
796	0.2	-5.24	3.180	0.04	175.8
799	0.0	-5.26	3.192	0.00	176.6
802	0.0	-5.28	3.204	0.00	177.2
805	-0.2	-5.30	3.216	-0.04	177.8
808	-0.2	-5.32	3.228	-0.04	178.6
811	0.0	-5.34	3.240	0.00	179.2
814	0.0	-5.36	3.252	0.00	179.8
817	-0.2	-5.39	3.264	-0.04	180.8
820	0.0	-5.41	3.276	0.00	181.6
823	0.0	-5.43	3.288	0.00	182.2
826	-0.2	-5.45	3.300	-0.04	182.8
829	-0.2	-5.47	3.312	-0.04	183.6
832	0.2	-5.49	3.324	0.04	184.2
835	0.0	-5.51	3.336	0.00	184.8
838	0.2	-5.53	3.348	0.04	185.6
841	0.2	-5.55	3.360	0.04	186.2
844	0.0	-5.57	3.372	0.00	187.0
847	0.0	-5.59	3.384	0.00	187.6
850	0.2	-5.62	3.396	0.04	188.6
853	0.2	-5.64	3.408	0.04	189.2
856	0.0	-5.66	3.420	0.00	190.0
859	0.0	-5.68	3.432	0.00	190.6
862	-0.2	-5.70	3.444	-0.04	191.2
865	0.2	-5.72	3.456	0.04	192.0
868	0.0	-5.74	3.468	0.00	192.6
871	0.2	-5.76	3.480	0.04	193.2
874	0.2	-5.78	3.492	0.04	194.0
877	-0.2	-5.80	3.504	-0.04	194.6
880	0.2	-5.82	3.516	0.04	195.4
883	-0.2	-5.84	3.528	-0.04	196.0
886	0.0	-5.87	3.540	0.00	197.0
889	0.0	-5.89	3.552	0.00	197.6
892	0.0	-5.91	3.564	0.00	198.4
895	0.2	-5.93	3.576	0.04	199.0
898	0.0	-5.95	3.588	0.00	199.6
901	0.0	-5.97	3.600	0.00	200.4
904	0.0	-5.99	3.612	0.00	201.0
907	0.0	-6.01	3.624	0.00	201.6
910	0.2	-6.03	3.636	0.04	202.4
913	0.0	-6.04	3.648	0.00	202.6
916	-0.2	-6.06	3.660	-0.04	203.4
919	0.0	-6.09	3.672	0.00	204.4
922	0.0	-6.11	3.684	0.00	205.0
925	0.2	-6.13	3.696	0.04	205.8
928	0.0	-6.15	3.708	0.00	206.4
931	0.4	-6.17	3.720	0.06	207.0
934	0.0	-6.19	3.732	0.00	207.8
937	0.0	-6.21	3.744	0.00	208.4
940	-0.2	-6.23	3.756	-0.04	209.0
943	0.2	-6.25	3.768	0.04	209.8
946	0.0	-6.27	3.780	0.00	210.4
949	0.2	-6.29	3.792	0.04	211.0
952	0.0	-6.32	3.804	0.00	212.0
955	0.0	-6.34	3.816	0.00	212.8
958	-0.2	-6.36	3.828	-0.04	213.4
961	0.2	-6.38	3.840	0.04	214.0
964	0.0	-6.40	3.852	0.00	214.8
967	0.0	-6.42	3.864	0.00	215.4
970	0.0	-6.44	3.876	0.00	216.2
973	0.2	-6.46	3.888	0.04	216.8
976	0.4	-6.48	3.900	0.06	217.4
979	0.0	-6.50	3.912	0.00	218.2
982	0.0	-6.52	3.924	0.00	218.8
985	0.0	-6.54	3.936	0.00	219.4
988	0.0	-6.57	3.948	0.00	220.4
991	0.0	-6.59	3.960	0.00	221.2
994	0.0	-6.61	3.972	0.00	221.8
997	0.0	-6.63	3.984	0.00	222.4
1000	-0.4	-6.65	3.996	-0.06	223.2
1003	0.0	-6.67	4.008	0.00	223.8
1006	0.0	-6.69	4.020	0.00	224.4
1009	0.0	-6.71	4.032	0.00	225.2
1012	-0.2	-6.73	4.044	-0.04	225.8
1015	-0.2	-6.75	4.056	-0.04	226.6
1018	0.0	-6.77	4.068	0.00	227.2
1021	0.2	-6.79	4.080	0.04	227.8
1024	0.0	-6.81	4.092	0.00	228.6
1027	0.0	-6.84	4.104	0.00	229.6
1030	0.0	-6.86	4.116	0.00	230.2
1033	0.0	-6.88	4.128	0.00	230.8
1036	-0.6	-6.90	4.140	-0.10	231.6
1039	0.0	-6.92	4.152	0.00	232.2
1042	0.0	-6.94	4.164	0.00	232.8
1045	0.0	-6.96	4.176	0.00	233.6
1048	0.0	-6.98	4.188	0.00	234.2
1051	0.0	-7.00	4.200	0.00	234.8
1054	0.0	-7.02	4.212	0.00	235.6
1057	0.2	-7.05	4.224	0.04	236.6
1060	0.0	-7.08	4.236	0.00	237.6
1063	-0.4	-7.10	4.248	-0.06	238.2
1066	0.2	-7.12	4.260	0.04	239.0
1069	0.0	-7.14	4.272	0.00	239.6
1072	0.0	-7.16	4.284	0.00	240.2
1075	0.0	-7.18	4.296	0.00	241.0
1078	0.0	-7.20	4.308	0.00	241.6
1081	0.0	-7.22	4.320	0.00	242.2
1084	0.0	-7.24	4.332	0.00	243.0
1087	0.2	-7.26	4.344	0.04	243.6
1090	0.0	-7.28	4.356	0.00	244.2
1093	0.0	-7.30	4.368	0.00	245.0
1096	0.0	-7.33	4.380	0.00	246.0
1099	0.2	-7.35	4.392	0.04	246.6
1102	0.0	-7.37	4.404	0.00	247.4
1105	0.0	-7.39	4.416	0.00	248.0
1108	0.0	-7.41	4.428	0.00	248.6
1111	0.2	-7.43	4.440	0.04	249.4
1114	-0.2	-7.45	4.452	-0.04	250.0
1117	0.0	-7.47	4.464	0.00	250.6
1120	-0.4	-7.49	4.476	-0.06	251.4
1123	-0.2	-7.51	4.488	-0.04	252.0
1126	0.0	-7.53	4.500	0.00	252.6
1129	0.0	-7.56	4.512	0.00	253.6
1132	0.0	-7.58	4.524	0.00	254.4
1135	0.0	-7.60	4.536	0.00	255.0
1138	-0.2	-7.62	4.548	-0.04	255.8
1141	0.0	-7.64	4.560	0.00	256.4
1144	0.0	-7.66	4.572	0.00	257.0
1147	0.2	-7.68	4.584	0.04	257.8
1150	0.0	-7.70	4.596	0.00	258.4
1153	0.0	-7.72	4.608	0.00	259.0
1156	0.2	-7.74	4.620	0.04	259.8
1159	-0.2	-7.76	4.632	-0.04	260.4
1162	0.0	-7.79	4.644	0.00	261.4
1165	0.0	-7.81	4.656	0.00	262.0
1168	0.0	-7.83	4.668	0.00	262.8
1171	0.0	-7.85	4.680	0.00	263.4
1174	0.0	-7.87	4.692	0.00	264.0
1177	0.0	-7.89	4.704	0.00	264.8
1180	0.0	-7.91	4.716	0.00	265.4
1183	0.2	-7.93	4.728	0.04	266.2
1186	0.0	-7.95	4.740	0.00	266.8
1189	0.0	-7.97	4.752	0.00	267.4
1192	0.0	-7.99	4.764	0.00	268.2
1195	0.0	-8.02	4.776	0.00	269.2
1198	0.2	-8.04	4.788	0.04	269.8
1201	0.0	-8.06	4.800	0.00	270.4
1204	-0.2	-8.08	4.812	-0.04	271.2
1207	0.0	-8.10	4.824	0.00	271.8
1210	0.0	-8.12	4.836	0.00	272.4
1213	0.0	-8.14	4.848	0.00	273.2
1216	0.0	-8.16	4.860	0.00	273.8
1219	-0.2	-8.18	4.872	-0.04	274.4
1222	0.0	-8.20	4.884	0.00	275.2
1225	0.0	-8.23	4.896	0.00	276.2
1228	0.0	-8.25	4.908	0.00	276.8
1231	0.0	-8.27	4.920	0.00	277.6
1234	0.0	-8.29	4.932	0.00	278.2
1237	0.0	-8.31	4.944	0.00	278.8
1240	0.0	-8.33	4.956	0.00	279.6
1243	0.0	-8.35	4.968	0.00	280.2
1246	0.0	-8.37	4.980	0.00	280.8
1249	0.2	-8.39	4.992	0.04	281.6
1252	0.2	-8.42	5.004	0.04	282.6
1255	0.4	-8.44	5.016	0.06	283.2
1258	0.0	-8.46	5.028	0.00	283.8
1261	-0.2	-8.48	5.040	-0.04	284.6
1264	0.2	-8.50	5.052	0.04	285.2
1267	0.0	-8.52	5.064	0.00	286.0
1270	0.2	-8.54	5.076	0.04	286.6
1273	0.0	-8.56	5.088	0.00	287.2
1276	0.0	-8.58	5.100	0.00	288.0
1279	0.0	-8.61	5.112	0.00	289.0
1282	0.2	-8.63	5.124	0.04	289.6
1285	0.0	-8.65	5.136	0.00	290.2
1288	-0.2	-8.67	5.148	-0.04	291.0
1291	0.0	-8.69	5.160	0.00	291.6
1294	-0.2	-8.71	5.172	-0.04	292.2
1297	0.0	-8.73	5.184	0.00	293.0
1300	0.0	-8.75	5.196	0.00	293.6
1303	0.0	-8.77	5.208	0.00	294.2
1306	0.0	-8.80	5.220	0.00	295.4
1309	0.0	-8.82	5.232	0.00	296.0
1312	0.0	-8.84	5.244	0.00	296.6
1315	0.0	-8.86	5.256	0.00	297.4
1318	0.0	-8.88	5.268	0.00	298.0
1321	0.2	-8.90	5.280	0.04	298.6
1324	0.2	-8.92	5.292	0.04	299.4
1327	0.0	-8.94	5.304	0.00	300.0
1330	-0.2	-8.96	5.316	-0.04	300.6
1333	0.0	-8.99	5.328	0.00	301.6
1336	0.2	-9.01	5.340	0.04	302.4
1339	0.0	-9.03	5.352	0.00	303.0
1342	0.0	-9.05	5.364	0.00	303.6
1345	0.0	-9.07	5.376	0.00	304.4
1348	-0.2	-9.09	5.388	-0.04	305.0
1351	0.0	-9.11	5.400	0.00	305.8
1354	0.0	-9.13	5.412	0.00	306.4
1357	0.0	-9.16	5.424	0.00	307.4
1360	0.0	-9.18	5.436	0.00	308.0
1363	0.0	-9.20	5.448	0.00	308.8
1366	0.0	-9.22	5.460	0.00	309.4
1369	0.0	-9.24	5.472	0.00	310.0
1372	0.2	-9.26	5.484	0.04	310.8
1375	0.0	-9.28	5.496	0.00	311.4
1378	0.2	-9.30	5.508	0.04	312.0
1381	0.0	-9.32	5.520	0.00	312.8
1384	0.4	-9.35	5.532	0.06	313.8
1387	-0.2	-9.37	5.544	-0.04	314.4
1390	0.0	-9.39	5.556	0.00	315.2
1393	-0.2	-9.41	5.568	-0.04	315.8
1396	-0.2	-9.43	5.580	-0.04	316.4
1399	0.2	-9.45	5.592	0.04	317.2
1402	0.0	-9.47	5.604	0.00	317.8
1405	0.0	-9.49	5.616	0.00	318.4
1408	0.0	-9.52	5.628	0.00	319.4
1411	0.0	-9.54	5.640	0.00	320.2
1414	0.0	-9.56	5.652	0.00	320.8
1417	0.0	-9.58	5.664	0.00	321.4
1420	0.0	-9.60	5.676	0.00	322.2
1423	0.0	-9.62	5.688	0.00	322.8
1426	0.0	-9.64	5.700	0.00	323.4
1429	0.0	-9.66	5.712	0.00	324.2
1432	0.0	-9.68	5.724	0.00	324.8
1435	-0.2	-9.71	5.736	-0.04	325.8
1438	0.2	-9.73	5.748	0.04	326.6
1441	0.0	-9.75	5.760	0.00	327.2
1444	0.2	-9.77	5.772	0.04	327.8
1447	-0.2	-9.79	5.784	-0.04	328.6
1450	0.2	-9.81	5.796	0.04	329.2
1453	0.2	-9.83	5.808	0.04	329.8
1456	0.0	-9.85	5.820	0.00	330.6
1459	0.2	-9.88	5.832	0.04	331.6
1462	0.2	-9.90	5.844	0.04	332.2
1465	0.0	-9.92	5.856	0.00	332.8
1468	-0.2	-9.94	5.868	-0.04	333.6
1471	0.0	-9.96	5.880	0.00	334.2
1474	0.2	-9.98	5.892	0.04	334.8
1477	0.0	-10.00	5.904	0.00	335.6
1480	-0.2	-10.02	5.916	-0.04	336.2
1483	0.0	-10.04	5.928	0.00	337.0
1486	0.0	-10.05	5.940	0.00	337.2
1489	0.0	-10.08	5.952	0.00	338.2
1492	-0.2	-10.10	5.964	-0.04	339.0
1495	-0.2	-10.12	5.976	-0.04	339.6
1498	0.0	-10.14	5.988	0.00	340.2
1501	0.0	-10.16	6.000	0.00	341.0
1504	0.0	-10.18	6.012	0.00	341.6
1507	0.0	-10.20	6.024	0.00	342.2
1510	0.0	-10.22	6.036	0.00	343.0
1513	0.0	-10.24	6.048	0.00	343.6
1516	0.2	-10.27	6.060	0.04	344.6
1519	-0.2	-10.29	6.072	-0.04	345.4
1522	0.0	-10.31	6.084	0.00	346.0
1525	0.0	-10.33	6.096	0.00	346.6
1528	0.0	-10.35	6.108	0.00	347.4
1531	-0.2	-10.37	6.120	-0.04	348.0
1534	0.0	-10.39	6.132	0.00	348.6
1537	0.0	-10.41	6.144	0.00	349.4
1540	0.2	-10.43	6.156	0.04	350.0
1543	0.0	-10.46	6.168	0.00	351.0
1546	0.2	-10.48	6.180	0.04	351.6
1549	-0.2	-10.50	6.192	-0.04	352.4
1552	0.0	-10.52	6.204	0.00	353.0
1555	0.0	-10.54	6.216	0.00	353.6
1558	0.0	-10.56	6.228	0.00	354.4
1561	0.0	-10.58	6.240	0.00	355.0
1564	0.0	-10.60	6.252	0.00	355.8
1567	-0.2	-10.62	6.264	-0.04	356.4
1570	-0.2	-10.64	6.276	-0.04	357.0
1573	-0.2	-10.66	6.288	-0.04	357.8
1576	0.2	-10.69	6.300	0.04	358.8
1579	0.0	-10.71	6.312	0.00	359.4
1582	0.0	-10.73	6.324	0.00	360.0
1585	0.0	-10.75	6.336	0.00	360.8
1588	0.0	-10.77	6.348	0.00	361.4
1591	0.0	-10.79	6.360	0.00	362.0
1594	-0.2	-10.81	6.372	-0.04	362.8
1597	0.2	-10.83	6.384	0.04	363.4
1600	0.2	-10.85	6.396	0.04	364.0
1603	0.0	-10.87	6.408	0.00	364.8
1606	0.0	-10.89	6.420	0.00	365.4
1609	0.0	-10.92	6.432	0.00	366.4
1612	-0.2	-10.94	6.444	-0.04	367.2
1615	0.0	-10.96	6.456	0.00	367.8
1618	0.0	-10.98	6.468	0.00	368.4
1621	0.0	-11.00	6.480	0.00	369.2
1624	0.0	-11.02	6.492	0.00	369.8
1627	0.0	-11.04	6.504	0.00	370.4
1630	0.0	-11.06	6.516	0.00	371.2
1633	0.0	-11.08	6.528	0.00	371.8
1636	0.0	-11.10	6.540	0.00	372.4
1639	0.0	-11.12	6.552	0.00	373.2
1642	-0.2	-11.15	6.564	-0.04	374.2
1645	0.0	-11.17	6.576	0.00	374.8
1648	0.2	-11.19	6.588	0.04	375.6
1651	-0.4	-11.21	6.600	-0.06	376.2
1654	0.0	-11.23	6.612	0.00	376.8
1657	-0.2	-11.25	6.624	-0.04	377.6
1660	0.0	-11.27	6.636	0.00	378.2
1663	0.0	-11.29	6.648	0.00	378.8
1666	0.0	-11.31	6.660	0.00	379.6
1669	0.2	-11.33	6.672	0.04	380.2
1672	-0.2	-11.35	6.684	-0.04	380.8
1675	0.0	-11.38	6.696	0.00	381.8
1678	0.0	-11.40	6.708	0.00	382.6
1681	0.2	-11.42	6.720	0.04	383.2
1684	0.0	-11.44	6.732	0.00	383.8
1687	0.0	-11.46	6.744	0.00	384.6
1690	0.4	-11.48	6.756	0.06	385.2
1693	-0.2	-11.50	6.768	-0.04	386.0
1696	0.0	-11.52	6.780	0.00	386.6
1699	-0.2	-11.54	6.792	-0.04	387.2
1702	0.0	-11.56	6.804	0.00	388.0
1705	0.0	-11.58	6.816	0.00	388.6
1708	0.0	-11.60	6.828	0.00	389.2
1711	0.0	-11.63	6.840	0.00	390.2
1714	0.0	-11.65	6.852	0.00	391.0
1717	-0.2	-11.67	6.864	-0.04	391.6
1720	0.0	-11.69	6.876	0.00	392.2
1723	-0.2	-11.71	6.888	-0.04	393.0
1726	0.0	-11.73	6.900	0.00	393.6
1729	0.0	-11.75	6.912	0.00	394.2
1732	0.0	-11.77	6.924	0.00	395.0
1735	-0.2	-11.79	6.936	-0.04	395.6
1738	0.0	-11.81	6.948	0.00	396.4
1741	0.0	-11.83	6.960	0.00	397.0
1744	0.0	-11.86	6.972	0.00	398.0
1747	0.0	-11.88	6.984	0.00	398.6
1750	0.0	-11.90	6.996	0.00	399.4
1753	0.0	-11.92	7.008	0.00	400.0
1756	0.0	-11.94	7.020	0.00	400.6
1759	0.0	-11.96	7.032	0.00	401.4
1762	0.0	-11.98	7.044	0.00	402.0
1765	0.0	-12.00	7.056	0.00	402.6
1768	0.2	-12.02	7.068	0.04	403.4
1771	0.0	-12.05	7.080	0.00	404.4
1774	0.0	-12.07	7.092	0.00	405.0
1777	0.0	-12.10	7.104	0.00	406.0
1780	0.2	-12.12	7.116	0.04	406.8
1783	0.0	-12.14	7.128	0.00	407.4
1786	0.0	-12.16	7.140	0.00	408.0
1789	0.0	-12.18	7.152	0.00	408.8
1792	0.2	-12.20	7.164	0.04	409.4
1795	-0.2	-12.22	7.176	-0.04	410.0
1798	0.0	-12.24	7.188	0.00	410.8
1801	0.0	-12.26	7.200	0.00	411.4
1804	0.2	-12.28	7.212	0.04	412.0
1807	-0.2	-12.30	7.224	-0.04	412.8
1810	-0.2	-12.32	7.236	-0.04	413.4
1813	0.0	-12.35	7.248	0.00	414.4
1816	0.2	-12.37	7.260	0.04	415.2
1819	-0.2	-12.39	7.272	-0.04	415.8
1822	-0.2	-12.41	7.284	-0.04	416.4
1825	0.0	-12.43	7.296	0.00	417.2
1828	0.2	-12.45	7.308	0.04	417.8
1831	0.0	-12.47	7.320	0.00	418.4
1834	0.0	-12.49	7.332	0.00	419.2
1837	0.0	-12.51	7.344	0.00	419.8
1840	0.0	-12.53	7.356	0.00	420.4
1843	0.0	-12.55	7.368	0.00	421.2
1846	0.0	-12.58	7.380	0.00	422.2
1849	0.0	-12.60	7.392	0.00	422.8
1852	0.2	-12.62	7.404	0.04	423.4
1855	0.0	-12.64	7.416	0.00	424.2
1858	0.2	-12.66	7.428	0.04	424.8
1861	0.2	-12.68	7.440	0.04	425.6
1864	0.0	-12.70	7.452	0.00	426.2
1867	0.0	-12.72	7.464	0.00	426.8
1870	0.0	-12.74	7.476	0.00	427.6
1873	-0.2	-12.76	7.488	-0.04	428.2
1876	0.2	-12.78	7.500	0.04	428.8
1879	0.0	-12.81	7.512	0.00	429.8
1882	0.0	-12.83	7.524	0.00	430.6
1885	0.0	-12.85	7.536	0.00	431.2
1888	0.0	-12.87	7.548	0.00	431.8
1891	0.2	-12.89	7.560	0.04	432.6
1894	0.0	-12.91	7.572	0.00	433.2
1897	0.2	-12.93	7.584	0.04	433.8
1900	0.4	-12.95	7.596	0.06	434.6
1903	-0.2	-12.97	7.608	-0.04	435.2
1906	0.0	-12.99	7.620	0.00	436.0
1909	0.0	-13.02	7.632	0.00	437.0
1912	0.0	-13.04	7.644	0.00	437.6
1915	0.0	-13.06	7.656	0.00	438.2
1918	0.0	-13.08	7.668	0.00	439.0
1921	0.0	-13.10	7.680	0.00	439.6
1924	0.0	-13.12	7.692	0.00	440.2
1927	0.0	-13.14	7.704	0.00	441.0
1930	0.0	-13.16	7.716	0.00	441.6
1933	0.4	-13.18	7.728	0.06	442.2
1936	0.0	-13.21	7.740	0.00	443.2
1939	0.0	-13.23	7.752	0.00	444.0
1942	-0.4	-13.25	7.764	-0.06	444.6
1945	0.0	-13.27	7.776	0.00	445.4
1948	0.0	-13.29	7.788	0.00	446.0
1951	0.0	-13.31	7.800	0.00	446.6
1954	0.2	-13.33	7.812	0.04	447.4
1957	0.0	-13.35	7.824	0.00	448.0
1960	0.0	-13.37	7.836	0.00	448.6
1963	0.0	-13.39	7.848	0.00	449.4
1966	0.0	-13.42	7.860	0.00	450.4
1969	0.0	-13.44	7.872	0.00	451.0
1972	0.2	-13.46	7.884	0.04	451.6
1975	0.0	-13.48	7.896	0.00	452.4
1978	0.0	-13.50	7.908	0.00	453.0
1981	0.2	-13.52	7.920	0.04	453.6
1984	0.0	-13.54	7.932	0.00	454.4
1987	-0.2	-13.56	7.944	-0.04	455.0
1990	0.2	-13.58	7.956	0.04	455.8
1993	0.2	-13.61	7.968	0.04	456.8
1996	0.0	-13.63	7.980	0.00	457.4
1999	0.0	-13.65	7.992	0.00	458.0
2002	0.0	-13.67	8.004	0.00	458.8
2005	0.0	-13.69	8.016	0.00	459.4
2008	0.0	-13.71	8.028	0.00	460.0
2011	0.0	-13.73	8.040	0.00	460.8
2014	0.0	-13.75	8.052	0.00	461.4
2017	0.0	-13.78	8.064	0.00	462.4
2020	0.0	-13.80	8.076	0.00	463.0
2023	0.0	-13.82	8.088	0.00	463.8
2026	0.0	-13.84	8.100	0.00	464.4
2029	-0.4	-13.86	8.112	-0.06	465.2
2032	0.0	-13.88	8.124	0.00	465.8
2035	-0.2	-13.90	8.136	-0.04	466.4
2038	0.0	-13.92	8.148	0.00	467.2
2041	0.2	-13.95	8.160	0.04	468.2
2044	0.0	-13.97	8.172	0.00	468.8
2047	0.0	-13.99	8.184	0.00	469.4
2050	0.2	-14.01	8.196	0.04	470.2
2053	0.0	-14.03	8.208	0.00	470.8
2056	0.0	-14.05	8.220	0.00	471.4
2059	0.0	-14.07	8.232	0.00	472.2
2062	0.2	-14.09	8.244	0.04	472.8
2065	0.2	-14.11	8.256	0.04	473.4
2068	0.0	-14.14	8.268	0.00	474.4
2071	-0.2	-14.16	8.280	-0.04	475.2
2074	-0.4	-14.18	8.292	-0.06	475.8
2077	-0.2	-14.20	8.304	-0.04	476.6
2080	0.2	-14.22	8.316	0.04	477.2
2083	0.0	-14.24	8.328	0.00	477.8
2086	0.0	-14.26	8.340	0.00	478.6
2089	0.2	-14.28	8.352	0.04	479.2
2092	0.0	-14.30	8.364	0.00	479.8
2095	0.0	-14.33	8.376	0.00	480.8
2098	0.0	-14.35	8.388	0.00	481.6
2101	0.2	-14.37	8.400	0.04	482.2
2104	0.0	-14.39	8.412	0.00	482.8
2107	-0.2	-14.41	8.424	-0.04	483.6
2110	0.0	-14.43	8.436	0.00	484.2
2113	0.0	-14.45	8.448	0.00	484.8
2116	0.0	-14.47	8.460	0.00	485.6
2119	0.4	-14.49	8.472	0.06	486.2
2122	0.6	-14.52	8.484	0.10	487.2
2125	0.0	-14.54	8.496	0.00	488.0
2128	0.0	-14.56	8.508	0.00	488.6
2131	0.0	-14.58	8.520	0.00	489.2
2134	0.0	-14.60	8.532	0.00	490.0
2137	0.4	-14.62	8.544	0.06	490.6
2140	0.0	-14.64	8.556	0.00	491.2
2143	0.0	-14.66	8.568	0.00	492.0
2146	0.0	-14.68	8.580	0.00	492.6
2149	0.0	-14.71	8.592	0.00	493.6
2152	0.0	-14.73	8.604	0.00	494.2
2155	0.2	-14.75	8.616	0.04	495.0
2158	0.0	-14.77	8.628	0.00	495.6
2161	0.2	-14.79	8.640	0.04	496.4
2164	0.0	-14.81	8.652	0.00	497.0
2167	0.0	-14.83	8.664	0.00	497.6
2170	-0.2	-14.85	8.676	-0.04	498.4
2173	0.0	-14.88	8.688	0.00	499.4
2176	0.2	-14.90	8.700	0.04	500.0
2179	0.0	-14.92	8.712	0.00	500.6
2182	0.0	-14.94	8.724	0.00	501.4
2185	0.2	-14.96	8.736	0.04	502.0
2188	0.0	-14.98	8.748	0.00	502.6
2191	0.0	-15.00	8.760	0.00	503.4
2194	0.0	-15.02	8.772	0.00	504.0
2197	-0.2	-15.04	8.784	-0.04	504.6
2200	0.0	-15.05	8.796	0.00	505.0
2203	0.2	-15.08	8.808	0.04	506.0
2206	-0.2	-15.10	8.820	-0.04	506.8
2209	0.0	-15.12	8.832	0.00	507.4
2212	-0.2	-15.14	8.844	-0.04	508.0
2215	0.0	-15.16	8.856	0.00	508.8
2218	0.0	-15.18	8.868	0.00	509.4
2221	0.0	-15.20	8.880	0.00	510.0
2224	0.4	-15.22	8.892	0.06	510.8
2227	0.0	-15.24	8.904	0.00	511.4
2230	0.4	-15.27	8.916	0.06	512.4
2233	0.0	-15.29	8.928	0.00	513.0
2236	0.0	-15.31	8.940	0.00	513.8
2239	-0.2	-15.33	8.952	-0.04	514.4
2242	0.0	-15.35	8.964	0.00	515.2
2245	0.0	-15.37	8.976	0.00	515.8
2248	0.0	-15.39	8.988	0.00	516.4
2251	0.0	-15.41	9.000	0.00	517.2
2254	0.0	-15.43	9.012	0.00	517.8
2257	0.0	-15.46	9.024	0.00	518.8
2260	0.2	-15.48	9.036	0.04	519.4
2263	0.0	-15.50	9.048	0.00	520.2
2266	0.0	-15.52	9.060	0.00	520.8
2269	0.0	-15.54	9.072	0.00	521.4
2272	0.2	-15.56	9.084	0.04	522.2
2275	0.0	-15.58	9.096	0.00	522.8
2278	-0.2	-15.60	9.108	-0.04	523.4
2281	-0.2	-15.62	9.120	-0.04	524.2
2284	0.0	-15.64	9.132	0.00	524.8
2287	0.0	-15.67	9.144	0.00	525.8
2290	0.2	-15.69	9.156	0.04	526.6
2293	-0.2	-15.71	9.168	-0.04	527.2
2296	0.2	-15.73	9.180	0.04	527.8
2299	0.0	-15.75	9.192	0.00	528.6
2302	0.0	-15.77	9.204	0.00	529.2
2305	0.0	-15.79	9.216	0.00	529.8
2308	0.0	-15.81	9.228	0.00	530.6
2311	0.0	-15.83	9.240	0.00	531.2
2314	0.2	-15.85	9.252	0.04	531.8
2317	0.0	-15.87	9.264	0.00	532.6
2320	0.0	-15.90	9.276	0.00	533.6
2323	0.0	-15.92	9.288	0.00	534.2
2326	0.2	-15.94	9.300	0.04	534.8
2329	-0.2	-15.96	9.312	-0.04	535.6
2332	0.0	-15.98	9.324	0.00	536.2
2335	0.0	-16.00	9.336	0.00	537.0
2338	0.0	-16.02	9.348	0.00	537.6
2341	0.4	-16.04	9.360	0.06	538.2
2344	0.0	-16.06	9.372	0.00	539.0
2347	0.0	-16.08	9.384	0.00	539.6
2350	0.0	-16.10	9.396	0.00	540.2
2353	0.0	-16.12	9.408	0.00	541.0
2356	0.0	-16.14	9.420	0.00	541.6
2359	0.0	-16.17	9.432	0.00	542.6
2362	0.0	-16.19	9.444	0.00	543.2
2365	0.0	-16.21	9.456	0.00	544.0
2368	0.2	-16.23	9.468	0.04	544.6
2371	0.0	-16.25	9.480	0.00	545.4
2374	0.0	-16.27	9.492	0.00	546.0
2377	0.0	-16.29	9.504	0.00	546.6
2380	0.0	-16.31	9.516	0.00	547.4
2383	0.0	-16.33	9.528	0.00	548.0
2386	-0.2	-16.35	9.540	-0.04	548.6
2389	0.0	-16.37	9.552	0.00	549.4
2392	-0.2	-16.40	9.564	-0.04	550.4
2395	0.0	-16.42	9.576	0.00	551.0
2398	0.4	-16.44	9.588	0.06	551.6
2401	0.0	-16.46	9.600	0.00	552.4
2404	0.0	-16.48	9.612	0.00	553.0
2407	0.0	-16.50	9.624	0.00	553.6
2410	-0.2	-16.52	9.636	-0.04	554.4
2413	0.0	-16.54	9.648	0.00	555.0
2416	0.0	-16.56	9.660	0.00	555.8
2419	0.0	-16.58	9.672	0.00	556.4
2422	-0.2	-16.60	9.684	-0.04	557.0
2425	0.0	-16.62	9.696	0.00	557.8
2428	-0.2	-16.65	9.708	-0.04	558.8
2431	0.0	-16.67	9.720	0.00	559.4
2434	0.0	-16.69	9.732	0.00	560.0
2437	0.0	-16.71	9.744	0.00	560.8
2440	0.0	-16.73	9.756	0.00	561.4
2443	0.2	-16.75	9.768	0.04	562.0
2446	0.0	-16.77	9.780	0.00	562.8
2449	-0.2	-16.79	9.792	-0.04	563.4
2452	0.2	-16.81	9.804	0.04	564.0
2455	0.0	-16.83	9.816	0.00	564.8
2458	0.0	-16.85	9.828	0.00	565.4
2461	0.2	-16.88	9.840	0.04	566.4
2464	0.0	-16.89	9.852	0.00	566.8
2467	0.0	-16.92	9.864	0.00	567.8
2470	0.2	-16.94	9.876	0.04	568.4
2473	0.0	-16.96	9.888	0.00	569.2
2476	0.0	-16.98	9.900	0.00	569.8
2479	-0.2	-17.00	9.912	-0.04	570.4
2482	0.0	-17.02	9.924	0.00	571.2
2485	0.0	-17.04	9.936	0.00	571.8
2488	0.0	-17.07	9.948	0.00	572.8
2491	0.0	-17.09	9.960	0.00	573.4
2494	0.0	-17.11	9.972	0.00	574.2
2497	0.0	-17.13	9.984	0.00	574.8
2500	0.2	-17.16	9.996	0.04	575.8
2503	-0.4	-17.18	10.008	-0.06	576.6
2506	0.2	-17.20	10.020	0.04	577.2
2509	0.0	-17.22	10.032	0.00	577.8
2512	0.0	-17.24	10.044	0.00	578.6
2515	0.2	-17.26	10.056	0.04	579.2
2518	0.2	-17.28	10.068	0.04	579.8
2521	0.0	-17.30	10.080	0.00	580.6
2524	0.0	-17.32	10.092	0.00	581.2
2527	0.0	-17.34	10.104	0.00	581.8
2530	0.0	-17.37	10.116	0.00	582.8
2533	0.0	-17.38	10.128	0.00	583.2
2536	0.0	-17.41	10.140	0.00	584.2
2539	0.0	-17.43	10.152	0.00	584.8
2542	0.0	-17.45	10.164	0.00	585.6
2545	-0.2	-17.47	10.176	-0.04	586.2
2548	0.0	-17.49	10.188	0.00	587.0
2551	-0.2	-17.51	10.200	-0.04	587.6
2554	0.0	-17.53	10.212	0.00	588.2
2557	0.0	-17.55	10.224	0.00	589.0
2560	0.2	-17.57	10.236	0.04	589.6
2563	0.0	-17.59	10.248	0.00	590.2
2566	0.2	-17.61	10.260	0.04	591.0
2569	0.0	-17.64	10.272	0.00	592.0
2572	0.0	-17.66	10.284	0.00	592.6
2575	0.0	-17.68	10.296	0.00	593.2
2578	0.0	-17.70	10.308	0.00	594.0
2581	0.4	-17.72	10.320	0.06	594.6
2584	0.0	-17.74	10.332	0.00	595.4
2587	0.0	-17.76	10.344	0.00	596.0
2590	-0.6	-17.78	10.356	-0.10	596.6
2593	0.0	-17.80	10.368	0.00	597.4
2596	0.0	-17.82	10.380	0.00	598.0
2599	-0.4	-17.84	10.392	-0.06	598.6
2602	0.0	-17.87	10.404	0.00	599.6
2605	0.0	-17.89	10.416	0.00	600.4
2608	0.0	-17.91	10.428	0.00	601.0
2611	0.0	-17.93	10.440	0.00	601.6
2614	0.0	-17.95	10.452	0.00	602.4
2617	0.0	-17.97	10.464	0.00	603.0
2620	0.0	-17.99	10.476	0.00	603.6
2623	0.0	-18.01	10.488	0.00	604.4
2626	-0.2	-18.03	10.500	-0.04	605.0
2629	0.0	-18.05	10.512	0.00	605.8
2632	0.0	-18.08	10.524	0.00	606.8
2635	0.0	-18.10	10.536	0.00	607.4
2638	0.0	-18.12	10.548	0.00	608.0
2641	0.0	-18.14	10.560	0.00	608.8
2644	0.2	-18.16	10.572	0.04	609.4
2647	0.2	-18.18	10.584	0.04	610.0
2650	0.0	-18.20	10.596	0.00	610.8
2653	0.0	-18.22	10.608	0.00	611.4
2656	0.0	-18.24	10.620	0.00	612.0
2659	-0.2	-18.26	10.632	-0.04	612.8
2662	0.0	-18.29	10.644	0.00	613.8
2665	-0.4	-18.31	10.656	-0.06	614.4
2668	0.0	-18.33	10.668	0.00	615.2
2671	0.2	-18.35	10.680	0.04	615.8
2674	0.0	-18.37	10.692	0.00	616.4
2677	-0.2	-18.39	10.704	-0.04	617.2
2680	0.0	-18.41	10.716	0.00	617.8
2683	0.2	-18.43	10.728	0.04	618.4
2686	0.0	-18.45	10.740	0.00	619.2
2689	0.0	-18.47	10.752	0.00	619.8
2692	0.2	-18.50	10.764	0.04	620.8
2695	0.0	-18.52	10.776	0.00	621.4
2698	0.0	-18.54	10.788	0.00	622.2
2701	0.0	-18.56	10.800	0.00	622.8
2704	0.2	-18.58	10.812	0.04	623.4
2707	0.2	-18.60	10.824	0.04	624.2
2710	0.2	-18.62	10.836	0.04	624.8
2713	0.2	-18.64	10.848	0.04	625.6
2716	0.0	-18.66	10.860	0.00	626.2
2719	0.2	-18.69	10.872	0.04	627.2
2722	0.4	-18.71	10.884	0.06	627.8
2725	0.0	-18.73	10.896	0.00	628.6
2728	0.0	-18.75	10.908	0.00	629.2
2731	0.2	-18.77	10.920	0.04	629.8
2734	-0.2	-18.79	10.932	-0.04	630.6
2737	0.0	-18.81	10.944	0.00	631.2
2740	0.0	-18.83	10.956	0.00	631.8
2743	-0.2	-18.85	10.968	-0.04	632.6
2746	0.0	-18.88	10.980	0.00	633.6
2749	0.0	-18.90	10.992	0.00	634.2
2752	0.0	-18.92	11.004	0.00	634.8
2755	-0.2	-18.94	11.016	-0.04	635.6
2758	0.4	-18.96	11.028	0.06	636.2
2761	-0.2	-18.98	11.040	-0.04	637.0
2764	-0.2	-19.00	11.052	-0.04	637.6
2767	0.0	-19.02	11.064	0.00	638.2
2770	0.2	-19.05	11.076	0.04	639.2
2773	0.0	-19.06	11.088	0.00	639.6
2776	-0.2	-19.08	11.100	-0.04	640.2
2779	0.2	-19.10	11.112	0.04	641.0
2782	0.0	-19.12	11.124	0.00	641.6
2785	0.0	-19.14	11.136	0.00	642.2
2788	0.2	-19.16	11.148	0.04	643.0
2791	0.0	-19.18	11.160	0.00	643.6
2794	0.0	-19.21	11.172	0.00	644.6
2797	0.0	-19.23	11.184	0.00	645.4
2800	0.2	-19.25	11.196	0.04	646.0
2803	0.0	-19.27	11.208	0.00	646.6
2806	-0.2	-19.29	11.220	-0.04	647.4
2809	-0.2	-19.31	11.232	-0.04	648.0
2812	0.0	-19.33	11.244	0.00	648.6
2815	0.0	-19.35	11.256	0.00	649.4
2818	0.0	-19.37	11.268	0.00	650.0
2821	0.0	-19.40	11.280	0.00	651.0
2824	0.2	-19.42	11.292	0.04	651.6
2827	0.0	-19.44	11.304	0.00	652.4
2830	0.4	-19.46	11.316	0.06	653.0
2833	1.0	-19.48	11.328	0.16	653.6
2836	1.0	-19.50	11.340	0.16	654.4
2839	1.6	-19.52	11.352	0.26	655.0
2842	2.6	-19.54	11.364	0.44	655.8
2845	4.4	-19.56	11.376	0.74	656.4
2848	7.0	-19.58	11.388	1.18	657.0
2851	10.4	-19.60	11.400	1.76	657.8
2854	14.4	-19.62	11.412	2.42	658.4
2857	18.8	-19.63	11.424	3.16	658.8
2860	23.8	-19.65	11.436	4.00	659.4
2863	29.2	-19.67	11.448	4.92	660.0
2866	34.6	-19.68	11.460	5.82	660.4
2869	43.6	-19.70	11.472	7.34	661.0
2872	56.6	-19.71	11.484	9.52	661.4
2875	68.2	-19.72	11.496	11.48	661.8
2878	73.2	-19.74	11.508	12.32	662.4
2881	75.0	-19.75	11.520	12.62	662.8
2884	76.4	-19.77	11.532	12.86	663.4
2887	77.0	-19.80	11.544	12.96	664.4
2890	77.0	-19.82	11.556	12.96	665.2
2893	76.4	-19.84	11.568	12.86	665.8
2896	75.6	-19.86	11.580	12.72	666.4
2899	74.2	-19.88	11.592	12.50	667.2
2902	75.4	-19.90	11.604	12.70	667.8
2905	76.2	-19.92	11.616	12.82	668.4
2908	73.4	-19.95	11.628	12.36	669.4
2911	72.4	-19.97	11.640	12.18	670.2
2914	72.4	-19.99	11.652	12.18	670.8
2917	69.4	-20.01	11.664	11.68	671.4
2920	69.6	-20.03	11.676	11.72	672.2
2923	69.2	-20.06	11.688	11.66	673.2
2926	68.0	-20.08	11.700	11.44	673.8
2929	67.6	-20.10	11.712	11.38	674.4
2932	67.0	-20.12	11.724	11.28	675.2
2935	25.2	-20.18	11.736	4.24	677.2
2938	21.8	-20.20	11.748	3.68	677.8
2941	23.2	-20.22	11.760	3.90	678.6
2944	23.4	-20.24	11.772	3.94	679.2
2947	23.2	-20.27	11.784	3.90	680.2
2950	23.2	-20.29	11.796	3.90	680.8
2953	22.6	-20.31	11.808	3.80	681.6
2956	22.6	-20.33	11.820	3.80	682.2
2959	22.0	-20.35	11.832	3.70	682.8
2962	21.8	-20.37	11.844	3.68	683.6
2965	21.4	-20.39	11.856	3.60	684.2
2968	20.6	-20.41	11.868	3.46	684.8
2971	20.4	-20.43	11.880	3.44	685.6
2974	20.8	-20.46	11.892	3.50	686.6
2977	21.8	-20.48	11.904	3.68	687.2
2980	21.6	-20.50	11.916	3.64	688.0
2983	22.8	-20.52	11.928	3.84	688.6
2986	24.0	-20.54	11.940	4.04	689.2
2989	25.8	-20.56	11.952	4.34	690.0
2992	26.8	-20.57	11.964	4.52	690.2
2995	27.4	-20.60	11.976	4.62	691.2
2998	28.0	-20.62	11.988	4.72	692.0
3001	28.4	-20.64	12.000	4.78	692.6
3004	29.0	-20.66	12.012	4.88	693.2
3007	29.6	-20.68	12.024	4.98	694.0
3010	31.2	-20.70	12.036	5.26	694.6
3013	32.4	-20.72	12.048	5.46	695.4
3016	33.8	-20.74	12.060	5.70	696.0
3019	34.8	-20.76	12.072	5.86	696.6
3022	36.6	-20.78	12.084	6.16	697.4
3025	38.4	-20.80	12.096	6.46	698.0
3028	40.0	-20.82	12.108	6.74	698.6
3031	41.4	-20.84	12.120	6.98	699.4
3034	42.8	-20.85	12.132	7.20	699.6
3037	44.2	-20.88	12.144	7.44	700.6
3040	44.6	-20.90	12.156	7.50	701.4
3043	46.2	-20.92	12.168	7.78	702.0
3046	46.6	-20.94	12.180	7.84	702.6
3049	47.4	-20.96	12.192	7.98	703.4
3052	48.4	-20.98	12.204	8.14	704.0
3055	48.6	-21.00	12.216	8.18	704.6
3058	49.4	-21.02	12.228	8.32	705.4
3061	50.4	-21.04	12.240	8.48	706.0
3064	51.6	-21.06	12.252	8.68	706.8
3067	52.6	-21.08	12.264	8.86	707.4
3070	53.8	-21.10	12.276	9.06	708.0
3073	55.0	-21.12	12.288	9.26	708.8
3076	56.4	-21.14	12.300	9.50	709.4
3079	57.6	-21.16	12.312	9.70	710.0
3082	58.8	-21.17	12.324	9.90	710.4
3085	60.6	-21.20	12.336	10.20	711.4
3088	62.4	-21.21	12.348	10.50	711.8
3091	64.4	-21.23	12.360	10.84	712.4
3094	66.4	-21.25	12.372	11.18	713.0
3097	68.6	-21.27	12.384	11.54	713.8
3100	70.4	-21.29	12.396	11.86	714.4
3103	72.4	-21.31	12.408	12.18	715.2
3106	73.2	-21.33	12.420	12.32	715.8
3109	73.4	-21.35	12.432	12.36	716.4
3112	75.8	-21.37	12.444	12.76	717.2
3115	71.2	-21.38	12.456	11.98	717.4
3118	64.4	-21.39	12.468	10.84	717.8
3121	61.0	-21.39	12.480	10.28	717.8
3124	59.0	-21.39	12.492	9.94	717.8
3127	57.6	-21.39	12.504	9.70	717.8
3130	56.4	-21.39	12.516	9.50	717.8
3133	55.8	-21.39	12.528	9.40	717.8
3136	55.0	-21.39	12.540	9.26	717.8
3139	54.4	-21.39	12.552	9.16	717.8
3142	54.0	-21.39	12.564	9.10	717.8
3144	53.4	-21.39	12.572	9.00	717.8