File: results/youngs-modulus/2025-04-25/inconclusive-data/pf20cp04.csv
sep=
pf20cp04

System Information:
IntelliMESUR Version: 2.2.1
Test Frame Model: F505
Test Frame Serial Number: 4418651
Test Frame Capacity: 500 lbF / 2.2 kN
Test Frame Firmware Version: 1.00.14
Force Sensor Model: FS05-100
Force Sensor Capacity: 500 N
Force Sensor Resolution: 0.2 N
Force Sensor Serial Number: 4425350
Calibration Date: Apr 29, 2024
Calibration Due Date: Apr 29, 2025

Reading	Load [N]	Distance [mm]	Time [s]	Stress [MPa]	Strain [%]
1	0.2	0.00	0.000	0.00001	0.0
4	0.2	0.00	0.012	0.00001	0.0
7	0.2	0.00	0.024	0.00001	0.0
10	0.2	0.00	0.036	0.00001	0.0
13	0.0	0.00	0.048	0.00000	0.0
16	0.0	0.00	0.060	0.00000	0.0
19	0.2	0.00	0.072	0.00001	0.0
22	0.2	0.00	0.084	0.00001	0.0
25	0.2	0.00	0.096	0.00001	0.0
28	0.2	0.00	0.108	0.00001	0.0
31	0.2	0.00	0.120	0.00001	0.0
34	0.2	0.00	0.132	0.00001	0.0
37	0.2	0.00	0.144	0.00001	0.0
40	0.2	0.00	0.156	0.00001	0.0
43	0.2	0.00	0.168	0.00001	0.0
46	0.2	0.00	0.180	0.00001	0.0
49	0.2	-0.01	0.192	0.00001	0.5
52	0.4	-0.03	0.204	0.00002	2.0
55	0.2	-0.06	0.216	0.00001	4.0
58	0.2	-0.08	0.228	0.00001	5.0
61	0.2	-0.10	0.240	0.00001	6.5
64	0.2	-0.12	0.252	0.00001	7.5
67	0.2	-0.14	0.264	0.00001	9.0
70	0.2	-0.16	0.276	0.00001	10.0
73	-0.2	-0.18	0.288	-0.00001	11.5
76	0.4	-0.20	0.300	0.00002	12.5
79	0.2	-0.22	0.312	0.00001	14.0
82	0.2	-0.25	0.324	0.00001	16.0
85	0.0	-0.27	0.336	0.00000	17.0
88	-0.2	-0.29	0.348	-0.00001	18.5
91	0.2	-0.31	0.360	0.00001	19.5
94	0.2	-0.33	0.372	0.00001	21.0
97	0.2	-0.35	0.384	0.00001	22.5
100	0.2	-0.37	0.396	0.00001	23.5
103	0.2	-0.39	0.408	0.00001	25.0
106	0.2	-0.41	0.420	0.00001	26.0
109	0.2	-0.43	0.432	0.00001	27.5
112	0.2	-0.45	0.444	0.00001	28.5
115	0.2	-0.48	0.456	0.00001	30.5
118	0.0	-0.50	0.468	0.00000	32.0
121	0.2	-0.52	0.480	0.00001	33.0
124	0.2	-0.54	0.492	0.00001	34.5
127	0.0	-0.56	0.504	0.00000	35.5
130	0.2	-0.58	0.516	0.00001	37.0
133	0.6	-0.60	0.528	0.00004	38.0
136	0.4	-0.62	0.540	0.00002	39.5
139	0.2	-0.64	0.552	0.00001	41.0
142	0.4	-0.66	0.564	0.00002	42.0
145	0.4	-0.68	0.576	0.00002	43.5
148	0.2	-0.71	0.588	0.00001	45.0
151	0.2	-0.73	0.600	0.00001	46.5
154	0.4	-0.75	0.612	0.00002	48.0
157	0.2	-0.77	0.624	0.00001	49.0
160	0.2	-0.79	0.636	0.00001	50.5
163	0.2	-0.81	0.648	0.00001	51.5
166	0.2	-0.83	0.660	0.00001	53.0
169	0.2	-0.85	0.672	0.00001	54.0
172	0.0	-0.87	0.684	0.00000	55.5
175	0.2	-0.89	0.696	0.00001	56.5
178	0.2	-0.91	0.708	0.00001	58.0
181	0.0	-0.94	0.720	0.00000	60.0
184	0.2	-0.96	0.732	0.00001	61.0
187	0.2	-0.99	0.744	0.00001	63.0
190	0.0	-1.01	0.756	0.00000	64.5
193	0.2	-1.03	0.768	0.00001	65.5
196	0.2	-1.05	0.780	0.00001	67.0
199	0.2	-1.07	0.792	0.00001	68.0
202	0.2	-1.09	0.804	0.00001	69.5
205	0.0	-1.11	0.816	0.00000	70.5
208	0.2	-1.13	0.828	0.00001	72.0
211	0.2	-1.16	0.840	0.00001	74.0
214	0.2	-1.18	0.852	0.00001	75.0
217	0.2	-1.20	0.864	0.00001	76.5
220	0.2	-1.22	0.876	0.00001	77.5
223	0.4	-1.24	0.888	0.00002	79.0
226	0.0	-1.26	0.900	0.00000	80.5
229	0.2	-1.28	0.912	0.00001	81.5
232	0.4	-1.30	0.924	0.00002	83.0
235	0.2	-1.32	0.936	0.00001	84.0
238	0.0	-1.34	0.948	0.00000	85.5
241	0.2	-1.36	0.960	0.00001	86.5
244	0.2	-1.39	0.972	0.00001	88.5
247	0.2	-1.41	0.984	0.00001	90.0
250	0.0	-1.43	0.996	0.00000	91.0
253	0.4	-1.45	1.008	0.00002	92.5
256	0.2	-1.47	1.020	0.00001	93.5
259	0.2	-1.49	1.032	0.00001	95.0
262	0.4	-1.51	1.044	0.00002	96.0
265	0.2	-1.53	1.056	0.00001	97.5
268	0.2	-1.55	1.068	0.00001	98.5
271	0.2	-1.57	1.080	0.00001	100.0
274	0.0	-1.59	1.092	0.00000	101.5
277	0.2	-1.62	1.104	0.00001	103.0
280	0.2	-1.63	1.116	0.00001	104.0
283	0.2	-1.66	1.128	0.00001	105.5
286	-0.2	-1.68	1.140	-0.00001	107.0
289	0.0	-1.70	1.152	0.00000	108.5
292	0.2	-1.72	1.164	0.00001	109.5
295	-0.2	-1.74	1.176	-0.00001	111.0
298	0.0	-1.76	1.188	0.00000	112.0
301	0.2	-1.78	1.200	0.00001	113.5
304	0.2	-1.80	1.212	0.00001	114.5
307	0.2	-1.82	1.224	0.00001	116.0
310	0.0	-1.84	1.236	0.00000	117.0
313	0.2	-1.87	1.248	0.00001	119.0
316	0.2	-1.89	1.260	0.00001	120.5
319	0.2	-1.91	1.272	0.00001	121.5
322	0.2	-1.93	1.284	0.00001	123.0
325	0.2	-1.95	1.296	0.00001	124.0
328	0.2	-1.97	1.308	0.00001	125.5
331	0.2	-1.98	1.320	0.00001	126.0
334	0.2	-2.00	1.332	0.00001	127.5
337	0.2	-2.02	1.344	0.00001	128.5
340	0.2	-2.04	1.356	0.00001	130.0
343	0.2	-2.06	1.368	0.00001	131.0
346	0.2	-2.09	1.380	0.00001	133.0
349	0.2	-2.11	1.392	0.00001	134.5
352	0.2	-2.13	1.404	0.00001	135.5
355	0.2	-2.15	1.416	0.00001	137.0
358	0.4	-2.17	1.428	0.00002	138.0
361	0.2	-2.19	1.440	0.00001	139.5
364	0.2	-2.21	1.452	0.00001	141.0
367	0.2	-2.23	1.464	0.00001	142.0
370	0.0	-2.25	1.476	0.00000	143.5
373	0.2	-2.27	1.488	0.00001	144.5
376	0.2	-2.29	1.500	0.00001	146.0
379	0.4	-2.31	1.512	0.00002	147.0
382	0.2	-2.33	1.524	0.00001	148.5
385	0.2	-2.36	1.536	0.00001	150.5
388	0.2	-2.38	1.548	0.00001	151.5
391	0.2	-2.40	1.560	0.00001	153.0
394	0.0	-2.42	1.572	0.00000	154.0
397	0.2	-2.44	1.584	0.00001	155.5
400	0.2	-2.46	1.596	0.00001	156.5
403	0.2	-2.48	1.608	0.00001	158.0
406	-0.2	-2.50	1.620	-0.00001	159.0
409	0.2	-2.52	1.632	0.00001	160.5
412	0.2	-2.54	1.644	0.00001	162.0
415	0.2	-2.57	1.656	0.00001	163.5
418	0.4	-2.59	1.668	0.00002	165.0
421	0.2	-2.61	1.680	0.00001	166.0
424	0.0	-2.63	1.692	0.00000	167.5
427	0.0	-2.65	1.704	0.00000	169.0
430	0.0	-2.67	1.716	0.00000	170.0
433	0.0	-2.69	1.728	0.00000	171.5
436	0.2	-2.71	1.740	0.00001	172.5
439	0.0	-2.73	1.752	0.00000	174.0
442	0.2	-2.75	1.764	0.00001	175.0
445	0.2	-2.78	1.776	0.00001	177.0
448	0.0	-2.80	1.788	0.00000	178.5
451	0.2	-2.82	1.800	0.00001	179.5
454	0.4	-2.84	1.812	0.00002	181.0
457	0.2	-2.86	1.824	0.00001	182.0
460	0.2	-2.88	1.836	0.00001	183.5
463	0.0	-2.90	1.848	0.00000	184.5
466	0.4	-2.92	1.860	0.00002	186.0
469	0.2	-2.94	1.872	0.00001	187.5
472	0.2	-2.96	1.884	0.00001	188.5
475	0.2	-2.99	1.896	0.00001	190.5
478	0.4	-3.02	1.908	0.00002	192.5
481	0.2	-3.04	1.920	0.00001	193.5
484	0.2	-3.06	1.932	0.00001	195.0
487	0.2	-3.08	1.944	0.00001	196.0
490	0.2	-3.10	1.956	0.00001	197.5
493	0.2	-3.12	1.968	0.00001	198.5
496	0.2	-3.14	1.980	0.00001	200.0
499	0.6	-3.16	1.992	0.00004	201.5
502	-0.2	-3.18	2.004	-0.00001	202.5
505	0.2	-3.21	2.016	0.00001	204.5
508	0.2	-3.23	2.028	0.00001	205.5
511	0.2	-3.25	2.040	0.00001	207.0
514	0.0	-3.27	2.052	0.00000	208.5
517	0.2	-3.29	2.064	0.00001	209.5
520	0.2	-3.31	2.076	0.00001	211.0
523	0.2	-3.33	2.088	0.00001	212.0
526	0.0	-3.35	2.100	0.00000	213.5
529	0.2	-3.37	2.112	0.00001	214.5
532	0.0	-3.39	2.124	0.00000	216.0
535	0.2	-3.42	2.136	0.00001	218.0
538	0.2	-3.44	2.148	0.00001	219.0
541	0.2	-3.46	2.160	0.00001	220.5
544	0.2	-3.48	2.172	0.00001	221.5
547	0.2	-3.50	2.184	0.00001	223.0
550	0.4	-3.52	2.196	0.00002	224.0
553	0.2	-3.54	2.208	0.00001	225.5
556	0.2	-3.56	2.220	0.00001	227.0
559	0.2	-3.58	2.232	0.00001	228.0
562	-0.2	-3.61	2.244	-0.00001	230.0
565	0.2	-3.63	2.256	0.00001	231.0
568	0.2	-3.65	2.268	0.00001	232.5
571	0.2	-3.67	2.280	0.00001	234.0
574	0.2	-3.69	2.292	0.00001	235.0
577	0.0	-3.71	2.304	0.00000	236.5
580	0.0	-3.73	2.316	0.00000	237.5
583	0.2	-3.75	2.328	0.00001	239.0
586	0.2	-3.77	2.340	0.00001	240.0
589	0.2	-3.80	2.352	0.00001	242.0
592	0.2	-3.82	2.364	0.00001	243.5
595	0.2	-3.84	2.376	0.00001	244.5
598	0.2	-3.86	2.388	0.00001	246.0
601	0.2	-3.88	2.400	0.00001	247.0
604	0.2	-3.90	2.412	0.00001	248.5
607	0.4	-3.92	2.424	0.00002	249.5
610	0.2	-3.94	2.436	0.00001	251.0
613	0.2	-3.97	2.448	0.00001	253.0
616	0.2	-3.99	2.460	0.00001	254.0
619	0.2	-4.01	2.472	0.00001	255.5
622	0.0	-4.03	2.484	0.00000	256.5
625	0.2	-4.05	2.496	0.00001	258.0
628	0.2	-4.07	2.508	0.00001	259.0
631	0.2	-4.09	2.520	0.00001	260.5
634	0.2	-4.11	2.532	0.00001	262.0
637	0.6	-4.14	2.544	0.00004	263.5
640	0.2	-4.16	2.556	0.00001	265.0
643	0.2	-4.18	2.568	0.00001	266.0
646	0.2	-4.20	2.580	0.00001	267.5
649	0.2	-4.22	2.592	0.00001	269.0
652	0.2	-4.24	2.604	0.00001	270.0
655	0.4	-4.26	2.616	0.00002	271.5
658	0.2	-4.28	2.628	0.00001	272.5
661	0.4	-4.30	2.640	0.00002	274.0
664	0.2	-4.33	2.652	0.00001	276.0
667	0.4	-4.35	2.664	0.00002	277.0
670	0.2	-4.37	2.676	0.00001	278.5
673	-0.2	-4.39	2.688	-0.00001	279.5
676	0.2	-4.41	2.700	0.00001	281.0
679	0.2	-4.43	2.712	0.00001	282.0
682	0.2	-4.45	2.724	0.00001	283.5
685	0.0	-4.47	2.736	0.00000	284.5
688	0.4	-4.49	2.748	0.00002	286.0
691	0.2	-4.52	2.760	0.00001	288.0
694	0.2	-4.54	2.772	0.00001	289.0
697	0.0	-4.56	2.784	0.00000	290.5
700	0.2	-4.58	2.796	0.00001	291.5
703	0.2	-4.60	2.808	0.00001	293.0
706	0.2	-4.62	2.820	0.00001	294.5
709	0.2	-4.64	2.832	0.00001	295.5
712	-0.2	-4.66	2.844	-0.00001	297.0
715	0.2	-4.68	2.856	0.00001	298.0
718	0.4	-4.71	2.868	0.00002	300.0
721	0.2	-4.73	2.880	0.00001	301.5
724	0.2	-4.75	2.892	0.00001	302.5
727	0.2	-4.77	2.904	0.00001	304.0
730	0.2	-4.79	2.916	0.00001	305.0
733	0.2	-4.81	2.928	0.00001	306.5
736	0.2	-4.83	2.940	0.00001	307.5
739	-0.2	-4.85	2.952	-0.00001	309.0
742	0.2	-4.87	2.964	0.00001	310.0
745	0.4	-4.90	2.976	0.00002	312.0
748	0.2	-4.92	2.988	0.00001	313.5
751	0.2	-4.94	3.000	0.00001	314.5
754	0.2	-4.96	3.012	0.00001	316.0
757	0.2	-4.98	3.024	0.00001	317.0
760	0.2	-5.00	3.036	0.00001	318.5
763	0.2	-5.02	3.048	0.00001	319.5
766	0.2	-5.04	3.060	0.00001	321.0
769	0.0	-5.06	3.072	0.00000	322.5
772	0.2	-5.09	3.084	0.00001	324.0
775	0.4	-5.11	3.096	0.00002	325.5
778	0.2	-5.13	3.108	0.00001	327.0
781	0.2	-5.15	3.120	0.00001	328.0
784	0.2	-5.17	3.132	0.00001	329.5
787	0.0	-5.19	3.144	0.00000	330.5
790	0.2	-5.21	3.156	0.00001	332.0
793	0.0	-5.23	3.168	0.00000	333.0
796	0.2	-5.25	3.180	0.00001	334.5
799	0.4	-5.28	3.192	0.00002	336.5
802	0.4	-5.30	3.204	0.00002	337.5
805	0.4	-5.32	3.216	0.00002	339.0
808	0.2	-5.34	3.228	0.00001	340.0
811	0.4	-5.36	3.240	0.00002	341.5
814	0.0	-5.38	3.252	0.00000	342.5
817	0.2	-5.40	3.264	0.00001	344.0
820	0.2	-5.42	3.276	0.00001	345.0
823	0.2	-5.44	3.288	0.00001	346.5
826	0.2	-5.46	3.300	0.00001	348.0
829	0.2	-5.48	3.312	0.00001	349.0
832	0.2	-5.51	3.324	0.00001	351.0
835	0.2	-5.53	3.336	0.00001	352.0
838	0.2	-5.55	3.348	0.00001	353.5
841	0.2	-5.57	3.360	0.00001	355.0
844	0.2	-5.59	3.372	0.00001	356.0
847	0.2	-5.61	3.384	0.00001	357.5
850	0.2	-5.63	3.396	0.00001	358.5
853	-0.2	-5.65	3.408	-0.00001	360.0
856	0.2	-5.67	3.420	0.00001	361.0
859	0.0	-5.69	3.432	0.00000	362.5
862	0.2	-5.71	3.444	0.00001	363.5
865	0.2	-5.74	3.456	0.00001	365.5
868	0.2	-5.76	3.468	0.00001	367.0
871	0.2	-5.78	3.480	0.00001	368.0
874	0.2	-5.80	3.492	0.00001	369.5
877	0.0	-5.82	3.504	0.00000	370.5
880	0.2	-5.84	3.516	0.00001	372.0
883	0.4	-5.86	3.528	0.00002	373.0
886	0.2	-5.88	3.540	0.00001	374.5
889	0.2	-5.90	3.552	0.00001	376.0
892	0.2	-5.92	3.564	0.00001	377.0
895	0.2	-5.94	3.576	0.00001	378.5
898	0.2	-5.96	3.588	0.00001	379.5
901	0.2	-5.98	3.600	0.00001	381.0
904	0.2	-6.00	3.612	0.00001	382.0
907	-0.2	-6.02	3.624	-0.00001	383.5
910	0.2	-6.04	3.636	0.00001	384.5
913	-0.2	-6.06	3.648	-0.00001	386.0
916	0.0	-6.08	3.660	0.00000	387.5
919	0.2	-6.10	3.672	0.00001	388.5
922	0.2	-6.12	3.684	0.00001	390.0
925	0.0	-6.14	3.696	0.00000	391.0
928	0.2	-6.16	3.708	0.00001	392.5
931	0.2	-6.18	3.720	0.00001	393.5
934	0.4	-6.21	3.732	0.00002	395.5
937	0.2	-6.23	3.744	0.00001	397.0
940	0.4	-6.25	3.756	0.00002	398.0
943	0.2	-6.27	3.768	0.00001	399.5
946	0.2	-6.29	3.780	0.00001	400.5
949	0.2	-6.31	3.792	0.00001	402.0
952	0.0	-6.33	3.804	0.00000	403.0
955	0.0	-6.35	3.816	0.00000	404.5
958	0.2	-6.37	3.828	0.00001	405.5
961	0.0	-6.39	3.840	0.00000	407.0
964	0.2	-6.41	3.852	0.00001	408.5
967	0.4	-6.44	3.864	0.00002	410.0
970	0.4	-6.45	3.876	0.00002	411.0
973	0.2	-6.48	3.888	0.00001	412.5
976	0.2	-6.50	3.900	0.00001	414.0
979	0.2	-6.52	3.912	0.00001	415.5
982	0.2	-6.54	3.924	0.00001	416.5
985	0.2	-6.56	3.936	0.00001	418.0
988	0.2	-6.58	3.948	0.00001	419.0
991	0.0	-6.60	3.960	0.00000	420.5
994	0.2	-6.62	3.972	0.00001	421.5
997	0.0	-6.64	3.984	0.00000	423.0
1000	0.2	-6.66	3.996	0.00001	424.0
1003	0.0	-6.68	4.008	0.00000	425.5
1006	0.2	-6.71	4.020	0.00001	427.5
1009	0.2	-6.73	4.032	0.00001	428.5
1012	0.2	-6.75	4.044	0.00001	430.0
1015	0.2	-6.77	4.056	0.00001	431.0
1018	0.2	-6.79	4.068	0.00001	432.5
1021	0.2	-6.81	4.080	0.00001	434.0
1024	0.2	-6.83	4.092	0.00001	435.0
1027	0.2	-6.85	4.104	0.00001	436.5
1030	0.2	-6.87	4.116	0.00001	437.5
1033	0.2	-6.89	4.128	0.00001	439.0
1036	0.0	-6.91	4.140	0.00000	440.0
1039	0.2	-6.93	4.152	0.00001	441.5
1042	0.2	-6.96	4.164	0.00001	443.5
1045	0.2	-6.99	4.176	0.00001	445.0
1048	0.2	-7.01	4.188	0.00001	446.5
1051	0.2	-7.03	4.200	0.00001	448.0
1054	-0.2	-7.05	4.212	-0.00001	449.0
1057	0.2	-7.07	4.224	0.00001	450.5
1060	0.2	-7.09	4.236	0.00001	451.5
1063	0.4	-7.11	4.248	0.00002	453.0
1066	0.2	-7.13	4.260	0.00001	454.0
1069	0.2	-7.15	4.272	0.00001	455.5
1072	0.2	-7.17	4.284	0.00001	456.5
1075	0.2	-7.20	4.296	0.00001	458.5
1078	0.2	-7.22	4.308	0.00001	460.0
1081	0.2	-7.24	4.320	0.00001	461.0
1084	0.2	-7.26	4.332	0.00001	462.5
1087	0.4	-7.28	4.344	0.00002	463.5
1090	0.2	-7.30	4.356	0.00001	465.0
1093	0.2	-7.32	4.368	0.00001	466.0
1096	0.2	-7.34	4.380	0.00001	467.5
1099	0.2	-7.36	4.392	0.00001	469.0
1102	0.2	-7.38	4.404	0.00001	470.0
1105	0.2	-7.40	4.416	0.00001	471.5
1108	0.4	-7.43	4.428	0.00002	473.0
1111	0.2	-7.45	4.440	0.00001	474.5
1114	0.2	-7.47	4.452	0.00001	476.0
1117	0.2	-7.49	4.464	0.00001	477.0
1120	0.0	-7.51	4.476	0.00000	478.5
1123	0.2	-7.53	4.488	0.00001	479.5
1126	0.2	-7.55	4.500	0.00001	481.0
1129	0.0	-7.57	4.512	0.00000	482.0
1132	0.2	-7.59	4.524	0.00001	483.5
1135	0.2	-7.61	4.536	0.00001	484.5
1138	0.2	-7.63	4.548	0.00001	486.0
1141	0.2	-7.65	4.560	0.00001	487.5
1144	0.2	-7.67	4.572	0.00001	488.5
1147	0.2	-7.70	4.584	0.00001	490.5
1150	0.2	-7.72	4.596	0.00001	491.5
1153	0.2	-7.74	4.608	0.00001	493.0
1156	0.2	-7.76	4.620	0.00001	494.5
1159	0.2	-7.78	4.632	0.00001	495.5
1162	0.2	-7.80	4.644	0.00001	497.0
1165	0.2	-7.82	4.656	0.00001	498.0
1168	0.2	-7.84	4.668	0.00001	499.5
1171	0.2	-7.86	4.680	0.00001	500.5
1174	0.2	-7.88	4.692	0.00001	502.0
1177	0.2	-7.91	4.704	0.00001	504.0
1180	0.2	-7.93	4.716	0.00001	505.0
1183	0.4	-7.95	4.728	0.00002	506.5
1186	0.2	-7.97	4.740	0.00001	507.5
1189	0.4	-7.99	4.752	0.00002	509.0
1192	0.2	-8.01	4.764	0.00001	510.0
1195	0.2	-8.03	4.776	0.00001	511.5
1198	0.2	-8.05	4.788	0.00001	512.5
1201	-0.2	-8.07	4.800	-0.00001	514.0
1204	0.2	-8.10	4.812	0.00001	516.0
1207	0.6	-8.12	4.824	0.00004	517.0
1210	0.4	-8.14	4.836	0.00002	518.5
1213	0.4	-8.16	4.848	0.00002	519.5
1216	0.2	-8.18	4.860	0.00001	521.0
1219	0.2	-8.20	4.872	0.00001	522.5
1222	0.2	-8.22	4.884	0.00001	523.5
1225	0.2	-8.24	4.896	0.00001	525.0
1228	0.2	-8.26	4.908	0.00001	526.0
1231	0.2	-8.28	4.920	0.00001	527.5
1234	0.2	-8.30	4.932	0.00001	528.5
1237	0.2	-8.33	4.944	0.00001	530.5
1240	0.2	-8.35	4.956	0.00001	532.0
1243	0.2	-8.37	4.968	0.00001	533.0
1246	0.0	-8.39	4.980	0.00000	534.5
1249	0.2	-8.41	4.992	0.00001	535.5
1252	0.4	-8.43	5.004	0.00002	537.0
1255	0.2	-8.45	5.016	0.00001	538.0
1258	0.2	-8.47	5.028	0.00001	539.5
1261	0.2	-8.49	5.040	0.00001	541.0
1264	0.4	-8.52	5.052	0.00002	542.5
1267	0.2	-8.54	5.064	0.00001	544.0
1270	0.2	-8.56	5.076	0.00001	545.0
1273	0.2	-8.58	5.088	0.00001	546.5
1276	0.4	-8.60	5.100	0.00002	548.0
1279	0.2	-8.62	5.112	0.00001	549.0
1282	0.4	-8.64	5.124	0.00002	550.5
1285	-0.2	-8.66	5.136	-0.00001	551.5
1288	0.2	-8.68	5.148	0.00001	553.0
1291	0.2	-8.71	5.160	0.00001	555.0
1294	0.2	-8.73	5.172	0.00001	556.0
1297	0.2	-8.75	5.184	0.00001	557.5
1300	0.2	-8.77	5.196	0.00001	558.5
1303	0.2	-8.79	5.208	0.00001	560.0
1306	0.0	-8.81	5.220	0.00000	561.0
1309	0.2	-8.83	5.232	0.00001	562.5
1312	0.4	-8.86	5.244	0.00002	564.5
1315	0.2	-8.88	5.256	0.00001	565.5
1318	0.0	-8.90	5.268	0.00000	567.0
1321	0.2	-8.92	5.280	0.00001	568.0
1324	0.2	-8.94	5.292	0.00001	569.5
1327	0.4	-8.96	5.304	0.00002	570.5
1330	-0.2	-8.98	5.316	-0.00001	572.0
1333	0.2	-9.00	5.328	0.00001	573.0
1336	-0.2	-9.02	5.340	-0.00001	574.5
1339	0.2	-9.05	5.352	0.00001	576.5
1342	0.4	-9.07	5.364	0.00002	577.5
1345	0.2	-9.09	5.376	0.00001	579.0
1348	0.2	-9.11	5.388	0.00001	580.5
1351	0.2	-9.13	5.400	0.00001	581.5
1354	0.2	-9.15	5.412	0.00001	583.0
1357	0.2	-9.17	5.424	0.00001	584.0
1360	-0.2	-9.19	5.436	-0.00001	585.5
1363	0.2	-9.21	5.448	0.00001	586.5
1366	0.2	-9.24	5.460	0.00001	588.5
1369	0.2	-9.26	5.472	0.00001	590.0
1372	-0.2	-9.28	5.484	-0.00001	591.0
1375	-0.2	-9.30	5.496	-0.00001	592.5
1378	0.4	-9.32	5.508	0.00002	593.5
1381	0.2	-9.34	5.520	0.00001	595.0
1384	0.2	-9.36	5.532	0.00001	596.0
1387	-0.4	-9.38	5.544	-0.00002	597.5
1390	0.2	-9.40	5.556	0.00001	598.5
1393	0.2	-9.43	5.568	0.00001	600.5
1396	0.2	-9.45	5.580	0.00001	602.0
1399	0.2	-9.47	5.592	0.00001	603.0
1402	0.4	-9.49	5.604	0.00002	604.5
1405	0.4	-9.51	5.616	0.00002	605.5
1408	0.2	-9.53	5.628	0.00001	607.0
1411	0.2	-9.55	5.640	0.00001	608.5
1414	0.0	-9.57	5.652	0.00000	609.5
1417	0.0	-9.59	5.664	0.00000	611.0
1420	0.2	-9.62	5.676	0.00001	612.5
1423	0.2	-9.64	5.688	0.00001	614.0
1426	-0.2	-9.66	5.700	-0.00001	615.5
1429	0.2	-9.68	5.712	0.00001	616.5
1432	0.4	-9.70	5.724	0.00002	618.0
1435	0.2	-9.72	5.736	0.00001	619.0
1438	0.2	-9.74	5.748	0.00001	620.5
1441	0.2	-9.77	5.760	0.00001	622.5
1444	0.2	-9.79	5.772	0.00001	623.5
1447	0.2	-9.81	5.784	0.00001	625.0
1450	0.2	-9.83	5.796	0.00001	626.0
1453	0.2	-9.85	5.808	0.00001	627.5
1456	0.2	-9.87	5.820	0.00001	628.5
1459	0.2	-9.89	5.832	0.00001	630.0
1462	0.0	-9.91	5.844	0.00000	631.0
1465	0.2	-9.93	5.856	0.00001	632.5
1468	0.2	-9.96	5.868	0.00001	634.5
1471	0.4	-9.98	5.880	0.00002	635.5
1474	0.0	-9.99	5.892	0.00000	636.5
1477	0.4	-10.01	5.904	0.00002	637.5
1480	0.4	-10.03	5.916	0.00002	639.0
1483	0.2	-10.05	5.928	0.00001	640.0
1486	0.2	-10.07	5.940	0.00001	641.5
1489	0.2	-10.09	5.952	0.00001	642.5
1492	0.2	-10.11	5.964	0.00001	644.0
1495	0.2	-10.13	5.976	0.00001	645.0
1498	0.2	-10.15	5.988	0.00001	646.5
1501	0.2	-10.18	6.000	0.00001	648.5
1504	0.0	-10.20	6.012	0.00000	649.5
1507	0.2	-10.22	6.024	0.00001	651.0
1510	0.4	-10.24	6.036	0.00002	652.0
1513	0.4	-10.26	6.048	0.00002	653.5
1516	0.2	-10.28	6.060	0.00001	655.0
1519	0.0	-10.30	6.072	0.00000	656.0
1522	0.4	-10.32	6.084	0.00002	657.5
1525	0.0	-10.34	6.096	0.00000	658.5
1528	0.2	-10.37	6.108	0.00001	660.5
1531	0.2	-10.39	6.120	0.00001	662.0
1534	0.2	-10.41	6.132	0.00001	663.0
1537	0.0	-10.43	6.144	0.00000	664.5
1540	0.2	-10.45	6.156	0.00001	665.5
1543	0.0	-10.47	6.168	0.00000	667.0
1546	0.2	-10.49	6.180	0.00001	668.0
1549	0.2	-10.51	6.192	0.00001	669.5
1552	0.2	-10.53	6.204	0.00001	670.5
1555	0.0	-10.56	6.216	0.00000	672.5
1558	0.4	-10.58	6.228	0.00002	674.0
1561	0.2	-10.60	6.240	0.00001	675.0
1564	0.2	-10.62	6.252	0.00001	676.5
1567	0.2	-10.64	6.264	0.00001	677.5
1570	0.2	-10.66	6.276	0.00001	679.0
1573	0.2	-10.68	6.288	0.00001	680.5
1576	0.2	-10.70	6.300	0.00001	681.5
1579	0.0	-10.72	6.312	0.00000	683.0
1582	0.4	-10.74	6.324	0.00002	684.0
1585	0.2	-10.76	6.336	0.00001	685.5
1588	0.2	-10.78	6.348	0.00001	686.5
1591	0.2	-10.81	6.360	0.00001	688.5
1594	0.4	-10.83	6.372	0.00002	690.0
1597	0.2	-10.85	6.384	0.00001	691.0
1600	0.2	-10.87	6.396	0.00001	692.5
1603	0.2	-10.89	6.408	0.00001	693.5
1606	0.2	-10.91	6.420	0.00001	695.0
1609	0.2	-10.93	6.432	0.00001	696.0
1612	0.4	-10.95	6.444	0.00002	697.5
1615	0.2	-10.97	6.456	0.00001	698.5
1618	0.2	-10.99	6.468	0.00001	700.0
1621	0.4	-11.01	6.480	0.00002	701.5
1624	0.0	-11.04	6.492	0.00000	703.0
1627	0.2	-11.06	6.504	0.00001	704.5
1630	0.0	-11.08	6.516	0.00000	705.5
1633	0.0	-11.10	6.528	0.00000	707.0
1636	0.2	-11.12	6.540	0.00001	708.5
1639	0.2	-11.14	6.552	0.00001	709.5
1642	0.2	-11.16	6.564	0.00001	711.0
1645	0.0	-11.18	6.576	0.00000	712.0
1648	0.0	-11.20	6.588	0.00000	713.5
1651	0.2	-11.22	6.600	0.00001	714.5
1654	0.2	-11.24	6.612	0.00001	716.0
1657	0.2	-11.27	6.624	0.00001	718.0
1660	0.0	-11.29	6.636	0.00000	719.0
1663	0.0	-11.31	6.648	0.00000	720.5
1666	0.2	-11.33	6.660	0.00001	721.5
1669	0.2	-11.35	6.672	0.00001	723.0
1672	0.2	-11.37	6.684	0.00001	724.0
1675	0.2	-11.39	6.696	0.00001	725.5
1678	0.0	-11.41	6.708	0.00000	727.0
1681	0.2	-11.43	6.720	0.00001	728.0
1684	-0.2	-11.45	6.732	-0.00001	729.5
1687	0.2	-11.47	6.744	0.00001	730.5
1690	0.2	-11.50	6.756	0.00001	732.5
1693	0.2	-11.52	6.768	0.00001	734.0
1696	0.2	-11.54	6.780	0.00001	735.0
1699	0.0	-11.56	6.792	0.00000	736.5
1702	0.4	-11.58	6.804	0.00002	737.5
1705	0.2	-11.60	6.816	0.00001	739.0
1708	0.4	-11.62	6.828	0.00002	740.0
1711	0.2	-11.64	6.840	0.00001	741.5
1714	0.2	-11.66	6.852	0.00001	742.5
1717	0.2	-11.68	6.864	0.00001	744.0
1720	0.2	-11.70	6.876	0.00001	745.0
1723	0.2	-11.72	6.888	0.00001	746.5
1726	0.2	-11.75	6.900	0.00001	748.5
1729	0.2	-11.77	6.912	0.00001	749.5
1732	0.2	-11.79	6.924	0.00001	751.0
1735	0.2	-11.81	6.936	0.00001	752.0
1738	-0.2	-11.83	6.948	-0.00001	753.5
1741	0.2	-11.85	6.960	0.00001	755.0
1744	0.4	-11.87	6.972	0.00002	756.0
1747	0.2	-11.89	6.984	0.00001	757.5
1750	0.0	-11.91	6.996	0.00000	758.5
1753	0.0	-11.93	7.008	0.00000	760.0
1756	0.4	-11.95	7.020	0.00002	761.0
1759	0.2	-11.99	7.032	0.00001	763.5
1762	0.4	-12.01	7.044	0.00002	765.0
1765	0.0	-12.03	7.056	0.00000	766.0
1768	0.2	-12.05	7.068	0.00001	767.5
1771	0.2	-12.07	7.080	0.00001	769.0
1774	0.2	-12.09	7.092	0.00001	770.0
1777	0.2	-12.11	7.104	0.00001	771.5
1780	0.2	-12.13	7.116	0.00001	772.5
1783	0.2	-12.15	7.128	0.00001	774.0
1786	-0.2	-12.17	7.140	-0.00001	775.0
1789	0.2	-12.19	7.152	0.00001	776.5
1792	0.2	-12.22	7.164	0.00001	778.5
1795	0.2	-12.24	7.176	0.00001	779.5
1798	0.4	-12.26	7.188	0.00002	781.0
1801	0.2	-12.28	7.200	0.00001	782.0
1804	0.2	-12.30	7.212	0.00001	783.5
1807	0.4	-12.32	7.224	0.00002	784.5
1810	0.2	-12.34	7.236	0.00001	786.0
1813	0.2	-12.36	7.248	0.00001	787.5
1816	0.4	-12.38	7.260	0.00002	788.5
1819	0.4	-12.40	7.272	0.00002	790.0
1822	0.0	-12.42	7.284	0.00000	791.0
1825	0.4	-12.45	7.296	0.00002	793.0
1828	0.2	-12.47	7.308	0.00001	794.5
1831	0.2	-12.49	7.320	0.00001	795.5
1834	0.2	-12.51	7.332	0.00001	797.0
1837	0.2	-12.53	7.344	0.00001	798.0
1840	0.0	-12.55	7.356	0.00000	799.5
1843	0.2	-12.57	7.368	0.00001	800.5
1846	0.0	-12.59	7.380	0.00000	802.0
1849	0.2	-12.61	7.392	0.00001	803.0
1852	0.2	-12.63	7.404	0.00001	804.5
1855	0.0	-12.65	7.416	0.00000	805.5
1858	0.2	-12.67	7.428	0.00001	807.0
1861	0.2	-12.70	7.440	0.00001	809.0
1864	0.2	-12.72	7.452	0.00001	810.0
1867	0.2	-12.74	7.464	0.00001	811.5
1870	0.2	-12.76	7.476	0.00001	812.5
1873	0.2	-12.78	7.488	0.00001	814.0
1876	-0.2	-12.80	7.500	-0.00001	815.5
1879	0.0	-12.82	7.512	0.00000	816.5
1882	0.2	-12.84	7.524	0.00001	818.0
1885	0.4	-12.86	7.536	0.00002	819.0
1888	-0.2	-12.88	7.548	-0.00001	820.5
1891	0.2	-12.91	7.560	0.00001	822.5
1894	0.2	-12.93	7.572	0.00001	823.5
1897	0.2	-12.95	7.584	0.00001	825.0
1900	0.2	-12.97	7.596	0.00001	826.0
1903	0.2	-12.99	7.608	0.00001	827.5
1906	0.2	-13.01	7.620	0.00001	828.5
1909	0.2	-13.03	7.632	0.00001	830.0
1912	0.0	-13.05	7.644	0.00000	831.0
1915	0.2	-13.07	7.656	0.00001	832.5
1918	-0.2	-13.09	7.668	-0.00001	834.0
1921	0.2	-13.12	7.680	0.00001	835.5
1924	0.2	-13.14	7.692	0.00001	837.0
1927	0.2	-13.16	7.704	0.00001	838.0
1930	0.2	-13.18	7.716	0.00001	839.5
1933	0.2	-13.20	7.728	0.00001	841.0
1936	0.2	-13.22	7.740	0.00001	842.0
1939	0.2	-13.24	7.752	0.00001	843.5
1942	0.2	-13.26	7.764	0.00001	844.5
1945	0.2	-13.28	7.776	0.00001	846.0
1948	0.2	-13.31	7.788	0.00001	848.0
1951	0.2	-13.33	7.800	0.00001	849.0
1954	0.2	-13.35	7.812	0.00001	850.5
1957	0.2	-13.37	7.824	0.00001	851.5
1960	0.2	-13.39	7.836	0.00001	853.0
1963	0.2	-13.41	7.848	0.00001	854.0
1966	0.0	-13.43	7.860	0.00000	855.5
1969	0.2	-13.45	7.872	0.00001	856.5
1972	0.2	-13.47	7.884	0.00001	858.0
1975	0.2	-13.50	7.896	0.00001	860.0
1978	0.2	-13.52	7.908	0.00001	861.0
1981	0.2	-13.54	7.920	0.00001	862.5
1984	0.2	-13.56	7.932	0.00001	863.5
1987	0.4	-13.58	7.944	0.00002	865.0
1990	0.2	-13.60	7.956	0.00001	866.0
1993	0.4	-13.62	7.968	0.00002	867.5
1996	0.2	-13.64	7.980	0.00001	869.0
1999	-0.2	-13.66	7.992	-0.00001	870.0
2002	0.4	-13.69	8.004	0.00002	872.0
2005	0.2	-13.71	8.016	0.00001	873.0
2008	0.2	-13.73	8.028	0.00001	874.5
2011	0.2	-13.75	8.040	0.00001	876.0
2014	0.2	-13.77	8.052	0.00001	877.0
2017	0.2	-13.79	8.064	0.00001	878.5
2020	0.4	-13.81	8.076	0.00002	879.5
2023	0.0	-13.83	8.088	0.00000	881.0
2026	0.4	-13.86	8.100	0.00002	883.0
2029	0.2	-13.88	8.112	0.00001	884.0
2032	0.4	-13.90	8.124	0.00002	885.5
2035	0.2	-13.92	8.136	0.00001	886.5
2038	-0.2	-13.94	8.148	-0.00001	888.0
2041	0.2	-13.96	8.160	0.00001	889.0
2044	0.2	-13.98	8.172	0.00001	890.5
2047	0.0	-14.00	8.184	0.00000	891.5
2050	0.4	-14.03	8.196	0.00002	893.5
2053	0.2	-14.05	8.208	0.00001	895.0
2056	0.2	-14.07	8.220	0.00001	896.0
2059	0.4	-14.09	8.232	0.00002	897.5
2062	0.6	-14.11	8.244	0.00004	898.5
2065	0.4	-14.13	8.256	0.00002	900.0
2068	0.2	-14.15	8.268	0.00001	901.5
2071	0.2	-14.17	8.280	0.00001	902.5
2074	0.4	-14.19	8.292	0.00002	904.0
2077	0.0	-14.22	8.304	0.00000	905.5
2080	0.2	-14.24	8.316	0.00001	907.0
2083	0.4	-14.26	8.328	0.00002	908.5
2086	0.2	-14.28	8.340	0.00001	909.5
2089	0.2	-14.30	8.352	0.00001	911.0
2092	0.0	-14.32	8.364	0.00000	912.0
2095	0.2	-14.34	8.376	0.00001	913.5
2098	0.2	-14.36	8.388	0.00001	914.5
2101	0.2	-14.38	8.400	0.00001	916.0
2104	0.2	-14.41	8.412	0.00001	918.0
2107	-0.2	-14.43	8.424	-0.00001	919.0
2110	0.2	-14.45	8.436	0.00001	920.5
2113	0.2	-14.47	8.448	0.00001	921.5
2116	0.0	-14.49	8.460	0.00000	923.0
2119	0.0	-14.51	8.472	0.00000	924.0
2122	0.2	-14.53	8.484	0.00001	925.5
2125	0.4	-14.55	8.496	0.00002	927.0
2128	0.0	-14.57	8.508	0.00000	928.0
2131	0.0	-14.60	8.520	0.00000	930.0
2134	0.2	-14.62	8.532	0.00001	931.0
2137	-0.4	-14.64	8.544	-0.00002	932.5
2140	0.2	-14.66	8.556	0.00001	934.0
2143	0.2	-14.68	8.568	0.00001	935.0
2146	0.2	-14.70	8.580	0.00001	936.5
2149	0.2	-14.72	8.592	0.00001	937.5
2152	0.2	-14.74	8.604	0.00001	939.0
2155	0.0	-14.76	8.616	0.00000	940.0
2158	0.4	-14.79	8.628	0.00002	942.0
2161	0.2	-14.81	8.640	0.00001	943.5
2164	0.2	-14.83	8.652	0.00001	944.5
2167	-0.4	-14.85	8.664	-0.00002	946.0
2170	-0.2	-14.87	8.676	-0.00001	947.0
2173	0.2	-14.89	8.688	0.00001	948.5
2176	0.2	-14.91	8.700	0.00001	949.5
2179	-0.2	-14.93	8.712	-0.00001	951.0
2182	0.2	-14.95	8.724	0.00001	952.0
2185	0.2	-14.98	8.736	0.00001	954.0
2188	0.2	-14.99	8.748	0.00001	955.0
2191	0.2	-15.01	8.760	0.00001	956.0
2194	0.0	-15.03	8.772	0.00000	957.5
2197	0.2	-15.05	8.784	0.00001	958.5
2200	0.2	-15.07	8.796	0.00001	960.0
2203	0.2	-15.09	8.808	0.00001	961.0
2206	0.2	-15.11	8.820	0.00001	962.5
2209	0.2	-15.13	8.832	0.00001	963.5
2212	0.0	-15.16	8.844	0.00000	965.5
2215	0.2	-15.18	8.856	0.00001	967.0
2218	0.2	-15.20	8.868	0.00001	968.0
2221	0.2	-15.22	8.880	0.00001	969.5
2224	0.4	-15.24	8.892	0.00002	970.5
2227	0.2	-15.26	8.904	0.00001	972.0
2230	0.2	-15.28	8.916	0.00001	973.0
2233	0.2	-15.30	8.928	0.00001	974.5
2236	0.2	-15.32	8.940	0.00001	976.0
2239	0.2	-15.35	8.952	0.00001	977.5
2242	0.2	-15.37	8.964	0.00001	979.0
2245	0.2	-15.39	8.976	0.00001	980.5
2248	0.2	-15.41	8.988	0.00001	981.5
2251	0.2	-15.43	9.000	0.00001	983.0
2254	0.2	-15.45	9.012	0.00001	984.0
2257	0.2	-15.47	9.024	0.00001	985.5
2260	0.2	-15.49	9.036	0.00001	986.5
2263	0.0	-15.51	9.048	0.00000	988.0
2266	0.0	-15.53	9.060	0.00000	989.0
2269	0.2	-15.55	9.072	0.00001	990.5
2272	0.0	-15.58	9.084	0.00000	992.5
2275	0.2	-15.60	9.096	0.00001	993.5
2278	0.4	-15.62	9.108	0.00002	995.0
2281	0.2	-15.64	9.120	0.00001	996.0
2284	0.2	-15.66	9.132	0.00001	997.5
2287	0.2	-15.68	9.144	0.00001	998.5
2290	0.2	-15.70	9.156	0.00001	1000.0
2293	0.2	-15.72	9.168	0.00001	1001.5
2296	0.2	-15.74	9.180	0.00001	1002.5
2299	0.2	-15.76	9.192	0.00001	1004.0
2302	0.4	-15.78	9.204	0.00002	1005.0
2305	0.2	-15.81	9.216	0.00001	1007.0
2308	0.4	-15.83	9.228	0.00002	1008.5
2311	0.2	-15.85	9.240	0.00001	1009.5
2314	0.2	-15.87	9.252	0.00001	1011.0
2317	0.2	-15.89	9.264	0.00001	1012.0
2320	0.4	-15.91	9.276	0.00002	1013.5
2323	0.2	-15.93	9.288	0.00001	1014.5
2326	0.2	-15.95	9.300	0.00001	1016.0
2329	0.2	-15.97	9.312	0.00001	1017.0
2332	-0.2	-15.99	9.324	-0.00001	1018.5
2335	0.2	-16.01	9.336	0.00001	1019.5
2338	0.2	-16.04	9.348	0.00001	1021.5
2341	0.0	-16.06	9.360	0.00000	1023.0
2344	0.4	-16.08	9.372	0.00002	1024.0
2347	0.2	-16.10	9.384	0.00001	1025.5
2350	0.2	-16.12	9.396	0.00001	1027.0
2353	0.4	-16.14	9.408	0.00002	1028.0
2356	0.0	-16.16	9.420	0.00000	1029.5
2359	0.2	-16.18	9.432	0.00001	1030.5
2362	0.2	-16.20	9.444	0.00001	1032.0
2365	0.0	-16.22	9.456	0.00000	1033.0
2368	0.2	-16.24	9.468	0.00001	1034.5
2371	0.4	-16.26	9.480	0.00002	1035.5
2374	0.2	-16.29	9.492	0.00001	1037.5
2377	0.2	-16.31	9.504	0.00001	1039.0
2380	0.2	-16.33	9.516	0.00001	1040.0
2383	0.2	-16.35	9.528	0.00001	1041.5
2386	0.2	-16.37	9.540	0.00001	1042.5
2389	0.2	-16.39	9.552	0.00001	1044.0
2392	0.2	-16.41	9.564	0.00001	1045.0
2395	0.4	-16.43	9.576	0.00002	1046.5
2398	0.4	-16.45	9.588	0.00002	1048.0
2401	0.2	-16.47	9.600	0.00001	1049.0
2404	0.4	-16.49	9.612	0.00002	1050.5
2407	0.2	-16.52	9.624	0.00001	1052.0
2410	0.4	-16.54	9.636	0.00002	1053.5
2413	0.2	-16.56	9.648	0.00001	1055.0
2416	0.0	-16.58	9.660	0.00000	1056.0
2419	0.2	-16.60	9.672	0.00001	1057.5
2422	0.2	-16.62	9.684	0.00001	1058.5
2425	0.2	-16.64	9.696	0.00001	1060.0
2428	0.0	-16.66	9.708	0.00000	1061.0
2431	0.4	-16.68	9.720	0.00002	1062.5
2434	0.2	-16.70	9.732	0.00001	1063.5
2437	-0.2	-16.72	9.744	-0.00001	1065.0
2440	0.0	-16.74	9.756	0.00000	1066.0
2443	0.2	-16.76	9.768	0.00001	1067.5
2446	0.2	-16.79	9.780	0.00001	1069.5
2449	0.2	-16.81	9.792	0.00001	1070.5
2452	0.2	-16.83	9.804	0.00001	1072.0
2455	0.2	-16.85	9.816	0.00001	1073.0
2458	0.2	-16.87	9.828	0.00001	1074.5
2461	0.4	-16.89	9.840	0.00002	1076.0
2464	0.0	-16.91	9.852	0.00000	1077.0
2467	0.2	-16.93	9.864	0.00001	1078.5
2470	0.0	-16.95	9.876	0.00000	1079.5
2473	0.0	-16.98	9.888	0.00000	1081.5
2476	0.2	-17.00	9.900	0.00001	1083.0
2479	0.2	-17.02	9.912	0.00001	1084.0
2482	0.2	-17.05	9.924	0.00001	1086.0
2485	0.2	-17.07	9.936	0.00001	1087.5
2488	0.0	-17.09	9.948	0.00000	1088.5
2491	0.2	-17.11	9.960	0.00001	1090.0
2494	0.4	-17.13	9.972	0.00002	1091.0
2497	0.4	-17.15	9.984	0.00002	1092.5
2500	0.0	-17.17	9.996	0.00000	1093.5
2503	0.2	-17.19	10.008	0.00001	1095.0
2506	0.0	-17.21	10.020	0.00000	1096.0
2509	0.2	-17.23	10.032	0.00001	1097.5
2512	0.2	-17.25	10.044	0.00001	1098.5
2515	0.4	-17.28	10.056	0.00002	1100.5
2518	0.0	-17.30	10.068	0.00000	1102.0
2521	0.2	-17.32	10.080	0.00001	1103.0
2524	0.2	-17.34	10.092	0.00001	1104.5
2527	0.2	-17.36	10.104	0.00001	1105.5
2530	0.0	-17.38	10.116	0.00000	1107.0
2533	0.4	-17.40	10.128	0.00002	1108.5
2536	-0.2	-17.42	10.140	-0.00001	1109.5
2539	0.2	-17.44	10.152	0.00001	1111.0
2542	0.2	-17.46	10.164	0.00001	1112.0
2545	0.2	-17.48	10.176	0.00001	1113.5
2548	0.2	-17.51	10.188	0.00001	1115.5
2551	0.2	-17.53	10.200	0.00001	1116.5
2554	0.4	-17.55	10.212	0.00002	1118.0
2557	0.2	-17.57	10.224	0.00001	1119.0
2560	0.0	-17.59	10.236	0.00000	1120.5
2563	0.2	-17.61	10.248	0.00001	1121.5
2566	0.2	-17.63	10.260	0.00001	1123.0
2569	0.2	-17.65	10.272	0.00001	1124.0
2572	0.4	-17.67	10.284	0.00002	1125.5
2575	0.2	-17.69	10.296	0.00001	1127.0
2578	0.2	-17.71	10.308	0.00001	1128.0
2581	0.4	-17.73	10.320	0.00002	1129.5
2584	0.2	-17.76	10.332	0.00001	1131.0
2587	0.2	-17.78	10.344	0.00001	1132.5
2590	-0.2	-17.80	10.356	-0.00001	1134.0
2593	0.2	-17.82	10.368	0.00001	1135.0
2596	0.2	-17.84	10.380	0.00001	1136.5
2599	0.2	-17.86	10.392	0.00001	1137.5
2602	0.0	-17.88	10.404	0.00000	1139.0
2605	0.4	-17.90	10.416	0.00002	1140.0
2608	0.2	-17.92	10.428	0.00001	1141.5
2611	0.0	-17.94	10.440	0.00000	1142.5
2614	0.2	-17.96	10.452	0.00001	1144.0
2617	0.2	-17.99	10.464	0.00001	1146.0
2620	0.0	-18.01	10.476	0.00000	1147.0
2623	0.2	-18.03	10.488	0.00001	1148.5
2626	0.2	-18.05	10.500	0.00001	1149.5
2629	0.2	-18.07	10.512	0.00001	1151.0
2632	0.6	-18.09	10.524	0.00004	1152.0
2635	0.2	-18.11	10.536	0.00001	1153.5
2638	0.0	-18.13	10.548	0.00000	1155.0
2641	0.2	-18.15	10.560	0.00001	1156.0
2644	0.8	-18.18	10.572	0.00005	1158.0
2647	0.2	-18.20	10.584	0.00001	1159.0
2650	0.2	-18.22	10.596	0.00001	1160.5
2653	0.0	-18.24	10.608	0.00000	1162.0
2656	0.2	-18.26	10.620	0.00001	1163.0
2659	0.6	-18.28	10.632	0.00004	1164.5
2662	0.0	-18.30	10.644	0.00000	1165.5
2665	0.0	-18.32	10.656	0.00000	1167.0
2668	0.2	-18.34	10.668	0.00001	1168.0
2671	0.2	-18.37	10.680	0.00001	1170.0
2674	0.2	-18.39	10.692	0.00001	1171.5
2677	0.0	-18.41	10.704	0.00000	1172.5
2680	0.2	-18.43	10.716	0.00001	1174.0
2683	0.2	-18.45	10.728	0.00001	1175.0
2686	0.2	-18.47	10.740	0.00001	1176.5
2689	0.2	-18.49	10.752	0.00001	1177.5
2692	0.2	-18.51	10.764	0.00001	1179.0
2695	0.2	-18.53	10.776	0.00001	1180.5
2698	0.2	-18.56	10.788	0.00001	1182.0
2701	-0.2	-18.58	10.800	-0.00001	1183.5
2704	0.2	-18.60	10.812	0.00001	1184.5
2707	0.2	-18.62	10.824	0.00001	1186.0
2710	0.2	-18.64	10.836	0.00001	1187.5
2713	0.2	-18.66	10.848	0.00001	1188.5
2716	0.2	-18.68	10.860	0.00001	1190.0
2719	0.4	-18.70	10.872	0.00002	1191.0
2722	0.2	-18.72	10.884	0.00001	1192.5
2725	0.2	-18.75	10.896	0.00001	1194.5
2728	0.4	-18.77	10.908	0.00002	1195.5
2731	0.4	-18.79	10.920	0.00002	1197.0
2734	0.2	-18.81	10.932	0.00001	1198.0
2737	0.2	-18.83	10.944	0.00001	1199.5
2740	0.2	-18.85	10.956	0.00001	1200.5
2743	0.4	-18.87	10.968	0.00002	1202.0
2746	0.0	-18.89	10.980	0.00000	1203.0
2749	0.2	-18.91	10.992	0.00001	1204.5
2752	0.2	-18.94	11.004	0.00001	1206.5
2755	0.0	-18.96	11.016	0.00000	1207.5
2758	0.2	-18.98	11.028	0.00001	1209.0
2761	0.2	-18.99	11.040	0.00001	1209.5
2764	0.2	-19.01	11.052	0.00001	1211.0
2767	0.0	-19.03	11.064	0.00000	1212.0
2770	0.6	-19.05	11.076	0.00004	1213.5
2773	0.2	-19.07	11.088	0.00001	1214.5
2776	0.2	-19.09	11.100	0.00001	1216.0
2779	-0.2	-19.12	11.112	-0.00001	1218.0
2782	0.2	-19.14	11.124	0.00001	1219.0
2785	0.2	-19.16	11.136	0.00001	1220.5
2788	0.0	-19.18	11.148	0.00000	1221.5
2791	0.4	-19.20	11.160	0.00002	1223.0
2794	0.2	-19.22	11.172	0.00001	1224.0
2797	0.2	-19.24	11.184	0.00001	1225.5
2800	0.0	-19.26	11.196	0.00000	1227.0
2803	0.2	-19.28	11.208	0.00001	1228.0
2806	0.2	-19.31	11.220	0.00001	1230.0
2809	0.0	-19.33	11.232	0.00000	1231.0
2812	0.2	-19.35	11.244	0.00001	1232.5
2815	0.0	-19.37	11.256	0.00000	1234.0
2818	0.4	-19.39	11.268	0.00002	1235.0
2821	0.2	-19.41	11.280	0.00001	1236.5
2824	0.2	-19.43	11.292	0.00001	1237.5
2827	0.2	-19.46	11.304	0.00001	1239.5
2830	0.2	-19.47	11.316	0.00001	1240.0
2833	0.2	-19.50	11.328	0.00001	1242.0
2836	0.4	-19.52	11.340	0.00002	1243.5
2839	0.2	-19.54	11.352	0.00001	1244.5
2842	0.0	-19.56	11.364	0.00000	1246.0
2845	0.2	-19.58	11.376	0.00001	1247.0
2848	0.2	-19.60	11.388	0.00001	1248.5
2851	0.0	-19.62	11.400	0.00000	1249.5
2854	0.2	-19.65	11.412	0.00001	1251.5
2857	0.2	-19.66	11.424	0.00001	1252.0
2860	0.0	-19.69	11.436	0.00000	1254.0
2863	0.2	-19.71	11.448	0.00001	1255.5
2866	0.4	-19.73	11.460	0.00002	1256.5
2869	0.4	-19.75	11.472	0.00002	1258.0
2872	0.2	-19.77	11.484	0.00001	1259.0
2875	0.2	-19.79	11.496	0.00001	1260.5
2878	0.0	-19.81	11.508	0.00000	1262.0
2881	0.4	-19.83	11.520	0.00002	1263.0
2884	0.2	-19.85	11.532	0.00001	1264.5
2887	0.2	-19.88	11.544	0.00001	1266.0
2890	0.2	-19.90	11.556	0.00001	1267.5
2893	0.2	-19.92	11.568	0.00001	1269.0
2896	0.4	-19.94	11.580	0.00002	1270.0
2899	0.4	-19.96	11.592	0.00002	1271.5
2902	0.2	-19.98	11.604	0.00001	1272.5
2905	0.0	-20.00	11.616	0.00000	1274.0
2908	0.8	-20.03	11.628	0.00005	1276.0
2911	0.2	-20.04	11.640	0.00001	1276.5
2914	0.2	-20.07	11.652	0.00001	1278.5
2917	0.4	-20.09	11.664	0.00002	1279.5
2920	0.2	-20.11	11.676	0.00001	1281.0
2923	0.2	-20.13	11.688	0.00001	1282.0
2926	0.2	-20.15	11.700	0.00001	1283.5
2929	0.2	-20.17	11.712	0.00001	1284.5
2932	0.2	-20.19	11.724	0.00001	1286.0
2935	0.4	-20.21	11.736	0.00002	1287.5
2938	0.2	-20.23	11.748	0.00001	1288.5
2941	0.2	-20.26	11.760	0.00001	1290.5
2944	0.2	-20.28	11.772	0.00001	1291.5
2947	0.0	-20.30	11.784	0.00000	1293.0
2950	0.2	-20.32	11.796	0.00001	1294.5
2953	0.4	-20.34	11.808	0.00002	1295.5
2956	0.2	-20.36	11.820	0.00001	1297.0
2959	0.2	-20.38	11.832	0.00001	1298.0
2962	0.0	-20.40	11.844	0.00000	1299.5
2965	0.2	-20.42	11.856	0.00001	1300.5
2968	0.2	-20.45	11.868	0.00001	1302.5
2971	0.0	-20.47	11.880	0.00000	1304.0
2974	0.0	-20.49	11.892	0.00000	1305.0
2977	0.0	-20.51	11.904	0.00000	1306.5
2980	0.2	-20.53	11.916	0.00001	1307.5
2983	0.2	-20.55	11.928	0.00001	1309.0
2986	0.2	-20.57	11.940	0.00001	1310.0
2989	0.2	-20.59	11.952	0.00001	1311.5
2992	0.2	-20.61	11.964	0.00001	1312.5
2995	0.4	-20.63	11.976	0.00002	1314.0
2998	0.0	-20.65	11.988	0.00000	1315.5
3001	0.2	-20.68	12.000	0.00001	1317.0
3004	0.2	-20.70	12.012	0.00001	1318.5
3007	-0.4	-20.72	12.024	-0.00002	1319.5
3010	0.2	-20.74	12.036	0.00001	1321.0
3013	0.2	-20.76	12.048	0.00001	1322.5
3016	0.2	-20.78	12.060	0.00001	1323.5
3019	0.4	-20.80	12.072	0.00002	1325.0
3022	0.2	-20.82	12.084	0.00001	1326.0
3025	0.4	-20.84	12.096	0.00002	1327.5
3028	1.2	-20.86	12.108	0.00007	1328.5
3031	2.4	-20.89	12.120	0.00015	1330.5
3034	4.6	-20.90	12.132	0.00028	1331.0
3037	7.8	-20.92	12.144	0.00048	1332.5
3040	11.6	-20.94	12.156	0.00071	1334.0
3043	15.4	-20.96	12.168	0.00095	1335.0
3046	19.8	-20.97	12.180	0.00122	1335.5
3049	29.0	-20.99	12.192	0.00178	1337.0
3052	33.4	-21.01	12.204	0.00205	1338.0
3055	34.6	-21.02	12.216	0.00212	1339.0
3058	35.8	-21.04	12.228	0.00220	1340.0
3061	35.6	-21.06	12.240	0.00219	1341.5
3064	36.6	-21.09	12.252	0.00225	1343.5
3067	35.4	-21.11	12.264	0.00217	1344.5
3070	35.4	-21.13	12.276	0.00217	1346.0
3073	34.6	-21.15	12.288	0.00212	1347.0
3076	33.6	-21.17	12.300	0.00206	1348.5
3079	33.2	-21.19	12.312	0.00204	1349.5
3082	32.8	-21.21	12.324	0.00201	1351.0
3085	32.8	-21.24	12.336	0.00201	1353.0
3088	31.2	-21.26	12.348	0.00192	1354.0
3091	31.2	-21.28	12.360	0.00192	1355.5
3094	32.0	-21.30	12.372	0.00196	1356.5
3097	31.4	-21.32	12.384	0.00193	1358.0
3100	31.6	-21.34	12.396	0.00194	1359.0
3103	28.6	-21.35	12.408	0.00176	1360.0
3106	26.4	-21.35	12.420	0.00162	1360.0
3109	25.2	-21.35	12.432	0.00155	1360.0
3112	24.6	-21.35	12.444	0.00151	1360.0
3115	24.4	-21.35	12.456	0.00150	1360.0
3118	24.0	-21.35	12.468	0.00147	1360.0
3121	23.4	-21.35	12.480	0.00144	1360.0
3124	23.2	-21.35	12.492	0.00142	1360.0
3127	23.0	-21.35	12.504	0.00141	1360.0
3130	22.8	-21.35	12.516	0.00140	1360.0
3133	22.8	-21.35	12.528	0.00140	1360.0
3136	22.4	-21.35	12.540	0.00138	1360.0
3139	22.4	-21.35	12.552	0.00138	1360.0
3142	22.0	-21.35	12.564	0.00135	1360.0
3145	22.0	-21.35	12.576	0.00135	1360.0
3148	22.2	-21.35	12.588	0.00136	1360.0
3151	21.8	-21.35	12.600	0.00134	1360.0