File: results/youngs-modulus/2025-04-19/inconclusive-data/pf18lt01.csv
sep=
pf18lt01

System Information:
IntelliMESUR Version: 2.2.1
Test Frame Model: F505
Test Frame Serial Number: 4418651
Test Frame Capacity: 500 lbF / 2.2 kN
Test Frame Firmware Version: 1.00.14
Force Sensor Model: FS05-100
Force Sensor Capacity: 500 N
Force Sensor Resolution: 0.2 N
Force Sensor Serial Number: 4425350
Calibration Date: Apr 29, 2024
Calibration Due Date: Apr 29, 2025

Reading	Load [N]	Distance [mm]	Time [s]	Stress [MPa]	Strain [%]
1	0.0	0.01	0.000	0.00	-0.4
4	0.0	0.01	0.012	0.00	-0.4
7	0.0	0.01	0.024	0.00	-0.4
10	0.0	0.01	0.036	0.00	-0.4
13	0.0	0.01	0.048	0.00	-0.4
16	0.0	0.01	0.060	0.00	-0.4
19	0.0	0.01	0.072	0.00	-0.4
22	0.2	0.01	0.084	0.02	-0.4
25	0.0	0.01	0.096	0.00	-0.4
28	-0.2	0.01	0.108	-0.02	-0.4
31	0.0	0.01	0.120	0.00	-0.4
34	0.0	0.01	0.132	0.00	-0.4
37	0.0	0.01	0.144	0.00	-0.4
40	-0.2	0.01	0.156	-0.02	-0.4
43	0.0	0.01	0.168	0.00	-0.4
46	0.0	0.01	0.180	0.00	-0.4
49	0.0	0.00	0.192	0.00	0.0
52	0.0	-0.02	0.204	0.00	0.6
55	-0.2	-0.05	0.216	-0.02	1.6
58	0.0	-0.06	0.228	0.00	2.0
61	0.0	-0.08	0.240	0.00	2.6
64	0.0	-0.10	0.252	0.00	3.4
67	0.0	-0.12	0.264	0.00	4.0
70	0.0	-0.14	0.276	0.00	4.6
73	0.0	-0.16	0.288	0.00	5.4
76	0.2	-0.19	0.300	0.02	6.4
79	0.0	-0.21	0.312	0.00	7.0
82	-0.2	-0.23	0.324	-0.02	7.6
85	-0.2	-0.25	0.336	-0.02	8.4
88	0.2	-0.27	0.348	0.02	9.0
91	0.0	-0.29	0.360	0.00	9.6
94	0.2	-0.31	0.372	0.02	10.4
97	-0.2	-0.33	0.384	-0.02	11.0
100	0.0	-0.35	0.396	0.00	11.8
103	0.0	-0.37	0.408	0.00	12.4
106	0.0	-0.39	0.420	0.00	13.0
109	0.0	-0.42	0.432	0.00	14.0
112	0.0	-0.44	0.444	0.00	14.8
115	0.0	-0.46	0.456	0.00	15.4
118	0.0	-0.48	0.468	0.00	16.0
121	0.0	-0.50	0.480	0.00	16.8
124	0.0	-0.52	0.492	0.00	17.4
127	0.0	-0.54	0.504	0.00	18.0
130	0.0	-0.56	0.516	0.00	18.8
133	0.0	-0.58	0.528	0.00	19.4
136	0.0	-0.61	0.540	0.00	20.4
139	0.0	-0.63	0.552	0.00	21.0
142	0.4	-0.65	0.564	0.04	21.8
145	0.0	-0.67	0.576	0.00	22.4
148	0.0	-0.69	0.588	0.00	23.0
151	-0.2	-0.71	0.600	-0.02	23.8
154	0.0	-0.73	0.612	0.00	24.4
157	-0.2	-0.75	0.624	-0.02	25.0
160	0.0	-0.77	0.636	0.00	25.8
163	-0.4	-0.79	0.648	-0.04	26.4
166	-0.2	-0.81	0.660	-0.02	27.0
169	0.0	-0.84	0.672	0.00	28.0
172	0.0	-0.86	0.684	0.00	28.8
175	0.0	-0.88	0.696	0.00	29.4
178	0.0	-0.90	0.708	0.00	30.2
181	-0.4	-0.92	0.720	-0.04	30.8
184	0.0	-0.94	0.732	0.00	31.4
187	0.0	-0.96	0.744	0.00	32.2
190	0.2	-0.98	0.756	0.02	32.8
193	0.0	-1.00	0.768	0.00	33.4
196	0.0	-1.02	0.780	0.00	34.2
199	-0.4	-1.05	0.792	-0.04	35.2
202	0.0	-1.08	0.804	0.00	36.2
205	-0.2	-1.10	0.816	-0.02	36.8
208	0.0	-1.12	0.828	0.00	37.4
211	0.2	-1.14	0.840	0.02	38.2
214	0.0	-1.16	0.852	0.00	38.8
217	-0.2	-1.18	0.864	-0.02	39.4
220	0.0	-1.20	0.876	0.00	40.2
223	0.2	-1.22	0.888	0.02	40.8
226	0.0	-1.24	0.900	0.00	41.4
229	0.0	-1.26	0.912	0.00	42.2
232	-0.2	-1.29	0.924	-0.02	43.2
235	0.0	-1.31	0.936	0.00	43.8
238	0.4	-1.33	0.948	0.04	44.4
241	0.2	-1.35	0.960	0.02	45.2
244	0.0	-1.37	0.972	0.00	45.8
247	0.0	-1.39	0.984	0.00	46.4
250	0.0	-1.41	0.996	0.00	47.2
253	-0.4	-1.43	1.008	-0.04	47.8
256	0.0	-1.45	1.020	0.00	48.4
259	0.2	-1.47	1.032	0.02	49.2
262	0.0	-1.49	1.044	0.00	49.8
265	-0.2	-1.51	1.056	-0.02	50.6
268	0.0	-1.53	1.068	0.00	51.2
271	0.0	-1.56	1.080	0.00	52.2
274	0.0	-1.58	1.092	0.00	52.8
277	0.0	-1.60	1.104	0.00	53.6
280	0.0	-1.62	1.116	0.00	54.2
283	-0.2	-1.64	1.128	-0.02	54.8
286	0.0	-1.66	1.140	0.00	55.6
289	0.0	-1.68	1.152	0.00	56.2
292	0.0	-1.70	1.164	0.00	56.8
295	0.0	-1.72	1.176	0.00	57.6
298	-0.2	-1.74	1.188	-0.02	58.2
301	0.0	-1.76	1.200	0.00	58.8
304	-0.2	-1.79	1.212	-0.02	59.8
307	0.0	-1.81	1.224	0.00	60.6
310	0.2	-1.83	1.236	0.02	61.2
313	0.2	-1.85	1.248	0.02	61.8
316	-0.2	-1.87	1.260	-0.02	62.6
319	0.2	-1.89	1.272	0.02	63.2
322	0.0	-1.91	1.284	0.00	63.8
325	0.0	-1.93	1.296	0.00	64.6
328	-0.2	-1.95	1.308	-0.02	65.2
331	0.0	-1.97	1.320	0.00	65.8
334	-0.4	-1.99	1.332	-0.04	66.6
337	-0.2	-2.01	1.344	-0.02	67.2
340	0.0	-2.04	1.356	0.00	68.2
343	0.0	-2.05	1.368	0.00	68.6
346	0.0	-2.07	1.380	0.00	69.2
349	0.0	-2.09	1.392	0.00	69.8
352	0.0	-2.11	1.404	0.00	70.6
355	-0.2	-2.13	1.416	-0.02	71.2
358	0.2	-2.15	1.428	0.02	72.0
361	0.0	-2.17	1.440	0.00	72.6
364	-0.2	-2.19	1.452	-0.02	73.2
367	0.0	-2.21	1.464	0.00	74.0
370	0.0	-2.23	1.476	0.00	74.6
373	0.2	-2.26	1.488	0.02	75.6
376	0.0	-2.28	1.500	0.00	76.2
379	0.2	-2.30	1.512	0.02	77.0
382	0.0	-2.32	1.524	0.00	77.6
385	0.0	-2.34	1.536	0.00	78.2
388	0.2	-2.36	1.548	0.02	79.0
391	0.0	-2.38	1.560	0.00	79.6
394	0.0	-2.40	1.572	0.00	80.2
397	0.0	-2.42	1.584	0.00	81.0
400	0.2	-2.44	1.596	0.02	81.6
403	0.0	-2.46	1.608	0.00	82.2
406	0.2	-2.49	1.620	0.02	83.2
409	0.0	-2.51	1.632	0.00	84.0
412	0.2	-2.53	1.644	0.02	84.6
415	-0.2	-2.55	1.656	-0.02	85.2
418	0.0	-2.57	1.668	0.00	86.0
421	0.0	-2.59	1.680	0.00	86.6
424	0.2	-2.61	1.692	0.02	87.2
427	0.0	-2.63	1.704	0.00	88.0
430	0.0	-2.65	1.716	0.00	88.6
433	-0.2	-2.67	1.728	-0.02	89.2
436	0.0	-2.69	1.740	0.00	90.0
439	0.0	-2.72	1.752	0.00	91.0
442	0.0	-2.74	1.764	0.00	91.6
445	0.0	-2.76	1.776	0.00	92.4
448	0.0	-2.78	1.788	0.00	93.0
451	0.0	-2.80	1.800	0.00	93.6
454	-0.2	-2.82	1.812	-0.02	94.4
457	0.0	-2.84	1.824	0.00	95.0
460	0.2	-2.86	1.836	0.02	95.6
463	0.0	-2.88	1.848	0.00	96.4
466	0.0	-2.90	1.860	0.00	97.0
469	0.0	-2.93	1.872	0.00	98.0
472	0.0	-2.95	1.884	0.00	98.6
475	-0.2	-2.97	1.896	-0.02	99.4
478	0.0	-2.99	1.908	0.00	100.0
481	-0.2	-3.01	1.920	-0.02	100.6
484	0.0	-3.03	1.932	0.00	101.4
487	0.0	-3.06	1.944	0.00	102.4
490	0.0	-3.08	1.956	0.00	103.0
493	0.2	-3.10	1.968	0.02	103.6
496	0.0	-3.12	1.980	0.00	104.4
499	0.0	-3.14	1.992	0.00	105.0
502	-0.2	-3.17	2.004	-0.02	106.0
505	0.0	-3.19	2.016	0.00	106.6
508	0.0	-3.21	2.028	0.00	107.4
511	0.0	-3.23	2.040	0.00	108.0
514	0.2	-3.25	2.052	0.02	108.6
517	0.0	-3.27	2.064	0.00	109.4
520	0.2	-3.29	2.076	0.02	110.0
523	0.0	-3.31	2.088	0.00	110.8
526	0.0	-3.33	2.100	0.00	111.4
529	-0.2	-3.36	2.112	-0.02	112.4
532	-0.4	-3.38	2.124	-0.04	113.0
535	0.0	-3.40	2.136	0.00	113.8
538	0.0	-3.42	2.148	0.00	114.4
541	0.2	-3.44	2.160	0.02	115.0
544	0.0	-3.46	2.172	0.00	115.8
547	0.0	-3.48	2.184	0.00	116.4
550	0.0	-3.50	2.196	0.00	117.0
553	0.0	-3.52	2.208	0.00	117.8
556	0.0	-3.55	2.220	0.00	118.8
559	0.0	-3.57	2.232	0.00	119.4
562	-0.2	-3.59	2.244	-0.02	120.0
565	-0.4	-3.61	2.256	-0.04	120.8
568	0.0	-3.63	2.268	0.00	121.4
571	0.0	-3.65	2.280	0.00	122.0
574	0.0	-3.67	2.292	0.00	122.8
577	0.0	-3.69	2.304	0.00	123.4
580	0.0	-3.71	2.316	0.00	124.0
583	0.4	-3.74	2.328	0.04	125.0
586	0.0	-3.76	2.340	0.00	125.8
589	-0.4	-3.78	2.352	-0.04	126.4
592	0.0	-3.80	2.364	0.00	127.0
595	0.0	-3.82	2.376	0.00	127.8
598	0.0	-3.84	2.388	0.00	128.4
601	0.0	-3.86	2.400	0.00	129.0
604	0.0	-3.88	2.412	0.00	129.8
607	0.0	-3.90	2.424	0.00	130.4
610	-0.2	-3.93	2.436	-0.02	131.4
613	0.0	-3.95	2.448	0.00	132.2
616	0.0	-3.97	2.460	0.00	132.8
619	0.0	-3.99	2.472	0.00	133.4
622	0.0	-4.01	2.484	0.00	134.2
625	-0.2	-4.03	2.496	-0.02	134.8
628	0.0	-4.05	2.508	0.00	135.4
631	0.0	-4.08	2.520	0.00	136.4
634	0.0	-4.10	2.532	0.00	137.2
637	0.0	-4.12	2.544	0.00	137.8
640	0.0	-4.14	2.556	0.00	138.4
643	0.2	-4.16	2.568	0.02	139.2
646	0.0	-4.18	2.580	0.00	139.8
649	0.0	-4.20	2.592	0.00	140.4
652	0.0	-4.22	2.604	0.00	141.2
655	0.2	-4.24	2.616	0.02	141.8
658	0.0	-4.27	2.628	0.00	142.8
661	0.0	-4.29	2.640	0.00	143.4
664	0.2	-4.31	2.652	0.02	144.2
667	0.0	-4.33	2.664	0.00	144.8
670	0.0	-4.35	2.676	0.00	145.4
673	0.0	-4.37	2.688	0.00	146.2
676	0.0	-4.39	2.700	0.00	146.8
679	-0.4	-4.41	2.712	-0.04	147.4
682	-0.4	-4.43	2.724	-0.04	148.2
685	0.0	-4.46	2.736	0.00	149.2
688	0.0	-4.48	2.748	0.00	149.8
691	-0.4	-4.50	2.760	-0.04	150.6
694	0.0	-4.52	2.772	0.00	151.2
697	0.0	-4.54	2.784	0.00	151.8
700	0.2	-4.56	2.796	0.02	152.6
703	0.0	-4.58	2.808	0.00	153.2
706	-0.2	-4.60	2.820	-0.02	153.8
709	0.0	-4.62	2.832	0.00	154.6
712	0.0	-4.65	2.844	0.00	155.6
715	0.0	-4.67	2.856	0.00	156.2
718	0.0	-4.69	2.868	0.00	156.8
721	0.0	-4.71	2.880	0.00	157.6
724	0.0	-4.73	2.892	0.00	158.2
727	0.0	-4.75	2.904	0.00	158.8
730	0.2	-4.77	2.916	0.02	159.6
733	-0.2	-4.79	2.928	-0.02	160.2
736	-0.2	-4.81	2.940	-0.02	160.8
739	0.0	-4.84	2.952	0.00	161.8
742	0.0	-4.86	2.964	0.00	162.6
745	0.0	-4.88	2.976	0.00	163.2
748	0.0	-4.90	2.988	0.00	163.8
751	-0.2	-4.92	3.000	-0.02	164.6
754	0.0	-4.94	3.012	0.00	165.2
757	0.0	-4.96	3.024	0.00	165.8
760	0.0	-4.98	3.036	0.00	166.6
763	0.0	-5.00	3.048	0.00	167.2
766	-0.2	-5.03	3.060	-0.02	168.2
769	0.2	-5.05	3.072	0.02	168.8
772	0.0	-5.07	3.084	0.00	169.6
775	0.2	-5.09	3.096	0.02	170.2
778	0.0	-5.11	3.108	0.00	171.0
781	-0.2	-5.13	3.120	-0.02	171.6
784	-0.2	-5.15	3.132	-0.02	172.2
787	0.0	-5.17	3.144	0.00	173.0
790	0.0	-5.19	3.156	0.00	173.6
793	-0.2	-5.22	3.168	-0.02	174.6
796	0.0	-5.24	3.180	0.00	175.2
799	0.0	-5.26	3.192	0.00	176.0
802	0.0	-5.28	3.204	0.00	176.6
805	0.0	-5.30	3.216	0.00	177.2
808	0.0	-5.32	3.228	0.00	178.0
811	0.2	-5.34	3.240	0.02	178.6
814	0.0	-5.36	3.252	0.00	179.2
817	0.0	-5.38	3.264	0.00	180.0
820	0.0	-5.40	3.276	0.00	180.6
823	0.0	-5.42	3.288	0.00	181.2
826	0.0	-5.45	3.300	0.00	182.2
829	-0.2	-5.47	3.312	-0.02	183.0
832	0.2	-5.49	3.324	0.02	183.6
835	0.0	-5.51	3.336	0.00	184.2
838	0.0	-5.53	3.348	0.00	185.0
841	-0.2	-5.55	3.360	-0.02	185.6
844	0.0	-5.57	3.372	0.00	186.2
847	0.2	-5.59	3.384	0.02	187.0
850	0.0	-5.61	3.396	0.00	187.6
853	0.0	-5.64	3.408	0.00	188.6
856	0.0	-5.66	3.420	0.00	189.2
859	0.0	-5.68	3.432	0.00	190.0
862	0.0	-5.70	3.444	0.00	190.6
865	-0.2	-5.72	3.456	-0.02	191.4
868	0.2	-5.74	3.468	0.02	192.0
871	0.0	-5.76	3.480	0.00	192.6
874	0.0	-5.78	3.492	0.00	193.4
877	0.0	-5.80	3.504	0.00	194.0
880	0.2	-5.82	3.516	0.02	194.6
883	0.0	-5.84	3.528	0.00	195.4
886	0.0	-5.86	3.540	0.00	196.0
889	0.0	-5.89	3.552	0.00	197.0
892	0.0	-5.91	3.564	0.00	197.6
895	0.0	-5.93	3.576	0.00	198.4
898	0.0	-5.95	3.588	0.00	199.0
901	0.0	-5.97	3.600	0.00	199.6
904	0.0	-5.99	3.612	0.00	200.4
907	-0.2	-6.01	3.624	-0.02	201.0
910	0.0	-6.03	3.636	0.00	201.6
913	0.0	-6.04	3.648	0.00	202.0
916	0.0	-6.06	3.660	0.00	202.6
919	0.0	-6.08	3.672	0.00	203.4
922	-0.2	-6.11	3.684	-0.02	204.4
925	0.2	-6.13	3.696	0.02	205.0
928	0.0	-6.15	3.708	0.00	205.6
931	0.0	-6.17	3.720	0.00	206.4
934	0.0	-6.19	3.732	0.00	207.0
937	0.0	-6.21	3.744	0.00	207.6
940	0.2	-6.23	3.756	0.02	208.4
943	-0.2	-6.25	3.768	-0.02	209.0
946	0.0	-6.27	3.780	0.00	209.6
949	0.0	-6.29	3.792	0.00	210.4
952	0.2	-6.31	3.804	0.02	211.0
955	0.0	-6.34	3.816	0.00	212.0
958	-0.2	-6.35	3.828	-0.02	212.4
961	0.0	-6.38	3.840	0.00	213.4
964	0.0	-6.40	3.852	0.00	214.0
967	0.0	-6.42	3.864	0.00	214.8
970	0.0	-6.44	3.876	0.00	215.4
973	0.0	-6.46	3.888	0.00	216.0
976	0.0	-6.48	3.900	0.00	216.8
979	-0.2	-6.50	3.912	-0.02	217.4
982	0.0	-6.52	3.924	0.00	218.0
985	0.0	-6.54	3.936	0.00	218.8
988	-0.2	-6.56	3.948	-0.02	219.4
991	0.0	-6.58	3.960	0.00	220.0
994	0.0	-6.61	3.972	0.00	221.0
997	0.0	-6.63	3.984	0.00	221.8
1000	0.2	-6.65	3.996	0.02	222.4
1003	-0.2	-6.67	4.008	-0.02	223.0
1006	0.0	-6.69	4.020	0.00	223.8
1009	0.0	-6.71	4.032	0.00	224.4
1012	0.0	-6.73	4.044	0.00	225.0
1015	-0.2	-6.75	4.056	-0.02	225.8
1018	0.0	-6.77	4.068	0.00	226.4
1021	0.0	-6.79	4.080	0.00	227.0
1024	0.0	-6.81	4.092	0.00	227.8
1027	-0.2	-6.83	4.104	-0.02	228.4
1030	0.0	-6.86	4.116	0.00	229.4
1033	0.0	-6.88	4.128	0.00	230.2
1036	0.0	-6.90	4.140	0.00	230.8
1039	0.0	-6.92	4.152	0.00	231.4
1042	-0.2	-6.94	4.164	-0.02	232.2
1045	0.0	-6.96	4.176	0.00	232.8
1048	0.0	-6.98	4.188	0.00	233.4
1051	0.0	-7.00	4.200	0.00	234.2
1054	0.0	-7.02	4.212	0.00	234.8
1057	0.0	-7.05	4.224	0.00	235.8
1060	-0.2	-7.07	4.236	-0.02	236.4
1063	0.0	-7.10	4.248	0.00	237.4
1066	0.0	-7.12	4.260	0.00	238.2
1069	-0.2	-7.14	4.272	-0.02	238.8
1072	0.2	-7.16	4.284	0.02	239.4
1075	0.2	-7.18	4.296	0.02	240.2
1078	0.0	-7.20	4.308	0.00	240.8
1081	0.0	-7.22	4.320	0.00	241.4
1084	0.0	-7.24	4.332	0.00	242.2
1087	-0.2	-7.26	4.344	-0.02	242.8
1090	0.0	-7.28	4.356	0.00	243.4
1093	0.0	-7.30	4.368	0.00	244.2
1096	0.0	-7.32	4.380	0.00	244.8
1099	0.2	-7.34	4.392	0.02	245.4
1102	0.0	-7.37	4.404	0.00	246.4
1105	0.0	-7.39	4.416	0.00	247.2
1108	0.0	-7.41	4.428	0.00	247.8
1111	0.0	-7.43	4.440	0.00	248.4
1114	0.0	-7.45	4.452	0.00	249.2
1117	-0.2	-7.47	4.464	-0.02	249.8
1120	0.0	-7.49	4.476	0.00	250.6
1123	0.0	-7.51	4.488	0.00	251.2
1126	0.0	-7.53	4.500	0.00	251.8
1129	0.0	-7.55	4.512	0.00	252.6
1132	0.0	-7.57	4.524	0.00	253.2
1135	0.4	-7.59	4.536	0.04	253.8
1138	0.0	-7.62	4.548	0.00	254.8
1141	0.0	-7.64	4.560	0.00	255.6
1144	0.0	-7.66	4.572	0.00	256.2
1147	0.0	-7.68	4.584	0.00	256.8
1150	0.0	-7.70	4.596	0.00	257.6
1153	0.0	-7.72	4.608	0.00	258.2
1156	0.0	-7.74	4.620	0.00	258.8
1159	0.0	-7.76	4.632	0.00	259.6
1162	0.0	-7.78	4.644	0.00	260.2
1165	-0.4	-7.81	4.656	-0.04	261.2
1168	0.0	-7.82	4.668	0.00	261.6
1171	0.0	-7.85	4.680	0.00	262.6
1174	-0.2	-7.87	4.692	-0.02	263.2
1177	0.0	-7.89	4.704	0.00	263.8
1180	0.0	-7.91	4.716	0.00	264.6
1183	0.0	-7.93	4.728	0.00	265.2
1186	0.0	-7.95	4.740	0.00	265.8
1189	0.0	-7.97	4.752	0.00	266.6
1192	-0.6	-7.99	4.764	-0.08	267.2
1195	0.0	-8.01	4.776	0.00	267.8
1198	0.4	-8.04	4.788	0.04	268.8
1201	0.0	-8.06	4.800	0.00	269.6
1204	0.0	-8.08	4.812	0.00	270.2
1207	-0.2	-8.10	4.824	-0.02	271.0
1210	0.0	-8.12	4.836	0.00	271.6
1213	0.0	-8.14	4.848	0.00	272.2
1216	-0.2	-8.16	4.860	-0.02	273.0
1219	-0.4	-8.18	4.872	-0.04	273.6
1222	0.0	-8.20	4.884	0.00	274.2
1225	0.0	-8.22	4.896	0.00	275.0
1228	0.0	-8.24	4.908	0.00	275.6
1231	0.0	-8.27	4.920	0.00	276.6
1234	-0.2	-8.29	4.932	-0.02	277.2
1237	0.0	-8.31	4.944	0.00	278.0
1240	0.0	-8.33	4.956	0.00	278.6
1243	0.0	-8.35	4.968	0.00	279.2
1246	0.0	-8.37	4.980	0.00	280.0
1249	0.0	-8.39	4.992	0.00	280.6
1252	0.0	-8.41	5.004	0.00	281.2
1255	-0.2	-8.43	5.016	-0.02	282.0
1258	0.0	-8.46	5.028	0.00	283.0
1261	0.0	-8.48	5.040	0.00	283.6
1264	0.2	-8.50	5.052	0.02	284.2
1267	0.0	-8.52	5.064	0.00	285.0
1270	0.0	-8.54	5.076	0.00	285.6
1273	0.2	-8.56	5.088	0.02	286.2
1276	0.0	-8.58	5.100	0.00	287.0
1279	0.0	-8.60	5.112	0.00	287.6
1282	0.0	-8.62	5.124	0.00	288.2
1285	0.0	-8.65	5.136	0.00	289.2
1288	0.0	-8.67	5.148	0.00	290.0
1291	-0.2	-8.69	5.160	-0.02	290.6
1294	0.0	-8.71	5.172	0.00	291.4
1297	0.0	-8.73	5.184	0.00	292.0
1300	0.0	-8.75	5.196	0.00	292.6
1303	0.0	-8.77	5.208	0.00	293.4
1306	0.2	-8.79	5.220	0.02	294.0
1309	0.0	-8.81	5.232	0.00	294.6
1312	0.0	-8.84	5.244	0.00	295.6
1315	0.0	-8.86	5.256	0.00	296.4
1318	0.2	-8.88	5.268	0.02	297.0
1321	-0.2	-8.90	5.280	-0.02	297.6
1324	0.0	-8.92	5.292	0.00	298.4
1327	0.0	-8.94	5.304	0.00	299.0
1330	0.0	-8.96	5.316	0.00	299.6
1333	0.0	-8.98	5.328	0.00	300.4
1336	0.0	-9.01	5.340	0.00	301.4
1339	0.0	-9.03	5.352	0.00	302.0
1342	0.0	-9.05	5.364	0.00	302.6
1345	0.0	-9.07	5.376	0.00	303.4
1348	-0.2	-9.09	5.388	-0.02	304.0
1351	0.0	-9.11	5.400	0.00	304.6
1354	0.0	-9.13	5.412	0.00	305.4
1357	0.0	-9.15	5.424	0.00	306.0
1360	0.0	-9.18	5.436	0.00	307.0
1363	0.0	-9.20	5.448	0.00	307.6
1366	0.0	-9.22	5.460	0.00	308.4
1369	0.2	-9.24	5.472	0.02	309.0
1372	0.2	-9.26	5.484	0.02	309.6
1375	0.2	-9.28	5.496	0.02	310.4
1378	0.0	-9.30	5.508	0.00	311.0
1381	-0.2	-9.32	5.520	-0.02	311.8
1384	0.0	-9.34	5.532	0.00	312.4
1387	0.0	-9.37	5.544	0.00	313.4
1390	0.0	-9.39	5.556	0.00	314.0
1393	0.2	-9.41	5.568	0.02	314.8
1396	-0.2	-9.43	5.580	-0.02	315.4
1399	0.0	-9.45	5.592	0.00	316.0
1402	-0.2	-9.47	5.604	-0.02	316.8
1405	0.0	-9.49	5.616	0.00	317.4
1408	0.0	-9.51	5.628	0.00	318.0
1411	-0.2	-9.53	5.640	-0.02	318.8
1414	0.2	-9.56	5.652	0.02	319.8
1417	-0.2	-9.58	5.664	-0.02	320.4
1420	0.0	-9.60	5.676	0.00	321.0
1423	0.2	-9.62	5.688	0.02	321.8
1426	0.0	-9.64	5.700	0.00	322.4
1429	0.0	-9.66	5.712	0.00	323.0
1432	0.0	-9.68	5.724	0.00	323.8
1435	-0.2	-9.70	5.736	-0.02	324.4
1438	0.2	-9.72	5.748	0.02	325.0
1441	0.0	-9.75	5.760	0.00	326.0
1444	0.0	-9.77	5.772	0.00	326.8
1447	0.0	-9.79	5.784	0.00	327.4
1450	0.0	-9.81	5.796	0.00	328.0
1453	0.0	-9.83	5.808	0.00	328.8
1456	0.0	-9.85	5.820	0.00	329.4
1459	0.2	-9.87	5.832	0.02	330.2
1462	-0.6	-9.89	5.844	-0.08	330.8
1465	-0.2	-9.91	5.856	-0.02	331.4
1468	0.0	-9.94	5.868	0.00	332.4
1471	0.0	-9.96	5.880	0.00	333.2
1474	0.0	-9.98	5.892	0.00	333.8
1477	0.0	-10.00	5.904	0.00	334.4
1480	0.2	-10.02	5.916	0.02	335.2
1483	0.0	-10.04	5.928	0.00	335.8
1486	0.0	-10.05	5.940	0.00	336.2
1489	0.0	-10.07	5.952	0.00	336.8
1492	0.0	-10.09	5.964	0.00	337.4
1495	-0.2	-10.12	5.976	-0.02	338.4
1498	0.0	-10.14	5.988	0.00	339.2
1501	-0.4	-10.16	6.000	-0.04	339.8
1504	0.0	-10.18	6.012	0.00	340.4
1507	0.0	-10.20	6.024	0.00	341.2
1510	0.0	-10.22	6.036	0.00	341.8
1513	-0.2	-10.24	6.048	-0.02	342.4
1516	-0.4	-10.26	6.060	-0.04	343.2
1519	0.0	-10.28	6.072	0.00	343.8
1522	0.2	-10.31	6.084	0.02	344.8
1525	0.0	-10.33	6.096	0.00	345.4
1528	0.0	-10.35	6.108	0.00	346.2
1531	-0.4	-10.37	6.120	-0.04	346.8
1534	0.0	-10.39	6.132	0.00	347.4
1537	-0.2	-10.41	6.144	-0.02	348.2
1540	-0.2	-10.43	6.156	-0.02	348.8
1543	-0.2	-10.45	6.168	-0.02	349.4
1546	0.0	-10.47	6.180	0.00	350.2
1549	0.0	-10.50	6.192	0.00	351.2
1552	0.0	-10.52	6.204	0.00	351.8
1555	0.4	-10.54	6.216	0.04	352.6
1558	0.0	-10.56	6.228	0.00	353.2
1561	0.0	-10.58	6.240	0.00	353.8
1564	-0.2	-10.60	6.252	-0.02	354.6
1567	0.0	-10.62	6.264	0.00	355.2
1570	0.0	-10.64	6.276	0.00	355.8
1573	0.0	-10.66	6.288	0.00	356.6
1576	-0.4	-10.68	6.300	-0.04	357.2
1579	-0.2	-10.70	6.312	-0.02	357.8
1582	0.2	-10.73	6.324	0.02	358.8
1585	0.0	-10.75	6.336	0.00	359.6
1588	0.0	-10.77	6.348	0.00	360.2
1591	0.0	-10.79	6.360	0.00	360.8
1594	0.0	-10.81	6.372	0.00	361.6
1597	0.0	-10.83	6.384	0.00	362.2
1600	0.2	-10.85	6.396	0.02	362.8
1603	0.0	-10.87	6.408	0.00	363.6
1606	0.0	-10.89	6.420	0.00	364.2
1609	0.0	-10.91	6.432	0.00	364.8
1612	0.0	-10.94	6.444	0.00	365.8
1615	0.0	-10.96	6.456	0.00	366.6
1618	-0.2	-10.98	6.468	-0.02	367.2
1621	0.0	-11.00	6.480	0.00	367.8
1624	0.0	-11.02	6.492	0.00	368.6
1627	0.0	-11.04	6.504	0.00	369.2
1630	0.2	-11.06	6.516	0.02	369.8
1633	0.0	-11.08	6.528	0.00	370.6
1636	-0.2	-11.10	6.540	-0.02	371.2
1639	0.0	-11.12	6.552	0.00	372.0
1642	0.0	-11.14	6.564	0.00	372.6
1645	0.2	-11.17	6.576	0.02	373.6
1648	-0.2	-11.18	6.588	-0.02	374.0
1651	0.0	-11.21	6.600	0.00	375.0
1654	0.0	-11.23	6.612	0.00	375.6
1657	0.0	-11.25	6.624	0.00	376.2
1660	0.0	-11.27	6.636	0.00	377.0
1663	0.0	-11.29	6.648	0.00	377.6
1666	-0.2	-11.31	6.660	-0.02	378.2
1669	0.0	-11.33	6.672	0.00	379.0
1672	0.0	-11.35	6.684	0.00	379.6
1675	0.0	-11.37	6.696	0.00	380.2
1678	0.0	-11.40	6.708	0.00	381.2
1681	0.0	-11.42	6.720	0.00	382.0
1684	0.0	-11.44	6.732	0.00	382.6
1687	0.0	-11.46	6.744	0.00	383.2
1690	0.0	-11.48	6.756	0.00	384.0
1693	0.0	-11.50	6.768	0.00	384.6
1696	0.0	-11.52	6.780	0.00	385.2
1699	0.0	-11.54	6.792	0.00	386.0
1702	0.0	-11.56	6.804	0.00	386.6
1705	0.0	-11.58	6.816	0.00	387.2
1708	0.0	-11.60	6.828	0.00	388.0
1711	0.0	-11.62	6.840	0.00	388.6
1714	-0.2	-11.65	6.852	-0.02	389.6
1717	0.2	-11.67	6.864	0.02	390.4
1720	0.0	-11.69	6.876	0.00	391.0
1723	0.2	-11.71	6.888	0.02	391.6
1726	0.0	-11.73	6.900	0.00	392.4
1729	0.0	-11.75	6.912	0.00	393.0
1732	-0.2	-11.77	6.924	-0.02	393.6
1735	-0.2	-11.79	6.936	-0.02	394.4
1738	0.0	-11.81	6.948	0.00	395.0
1741	0.0	-11.83	6.960	0.00	395.6
1744	-0.4	-11.85	6.972	-0.04	396.4
1747	0.0	-11.87	6.984	0.00	397.0
1750	0.0	-11.89	6.996	0.00	397.6
1753	0.0	-11.92	7.008	0.00	398.6
1756	0.0	-11.94	7.020	0.00	399.4
1759	0.0	-11.96	7.032	0.00	400.0
1762	0.0	-11.98	7.044	0.00	400.6
1765	0.0	-12.00	7.056	0.00	401.4
1768	-0.2	-12.02	7.068	-0.02	402.0
1771	-0.2	-12.05	7.080	-0.02	403.0
1774	-0.2	-12.07	7.092	-0.02	403.6
1777	0.0	-12.09	7.104	0.00	404.4
1780	0.0	-12.11	7.116	0.00	405.0
1783	0.0	-12.13	7.128	0.00	405.6
1786	0.0	-12.16	7.140	0.00	406.6
1789	0.0	-12.18	7.152	0.00	407.4
1792	0.0	-12.20	7.164	0.00	408.0
1795	0.0	-12.22	7.176	0.00	408.6
1798	0.0	-12.24	7.188	0.00	409.4
1801	0.0	-12.26	7.200	0.00	410.0
1804	0.2	-12.28	7.212	0.02	410.8
1807	0.2	-12.30	7.224	0.02	411.4
1810	-0.2	-12.32	7.236	-0.02	412.0
1813	0.2	-12.34	7.248	0.02	412.8
1816	0.0	-12.36	7.260	0.00	413.4
1819	0.0	-12.39	7.272	0.00	414.4
1822	0.2	-12.41	7.284	0.02	415.0
1825	0.0	-12.43	7.296	0.00	415.8
1828	0.0	-12.45	7.308	0.00	416.4
1831	0.0	-12.47	7.320	0.00	417.0
1834	0.4	-12.49	7.332	0.04	417.8
1837	-0.2	-12.51	7.344	-0.02	418.4
1840	-0.4	-12.53	7.356	-0.04	419.0
1843	-0.2	-12.55	7.368	-0.02	419.8
1846	0.0	-12.57	7.380	0.00	420.4
1849	0.2	-12.60	7.392	0.02	421.4
1852	0.2	-12.62	7.404	0.02	422.0
1855	0.2	-12.64	7.416	0.02	422.8
1858	0.0	-12.66	7.428	0.00	423.4
1861	0.0	-12.68	7.440	0.00	424.0
1864	-0.2	-12.70	7.452	-0.02	424.8
1867	0.0	-12.72	7.464	0.00	425.4
1870	0.0	-12.74	7.476	0.00	426.0
1873	0.2	-12.76	7.488	0.02	426.8
1876	0.0	-12.78	7.500	0.00	427.4
1879	0.2	-12.80	7.512	0.02	428.0
1882	0.0	-12.83	7.524	0.00	429.0
1885	-0.2	-12.85	7.536	-0.02	429.8
1888	0.0	-12.87	7.548	0.00	430.4
1891	0.0	-12.89	7.560	0.00	431.2
1894	-0.2	-12.91	7.572	-0.02	431.8
1897	0.0	-12.93	7.584	0.00	432.4
1900	0.0	-12.95	7.596	0.00	433.2
1903	-0.2	-12.97	7.608	-0.02	433.8
1906	0.2	-12.99	7.620	0.02	434.4
1909	-0.2	-13.01	7.632	-0.02	435.2
1912	0.0	-13.03	7.644	0.00	435.8
1915	0.0	-13.06	7.656	0.00	436.8
1918	0.2	-13.08	7.668	0.02	437.4
1921	0.0	-13.10	7.680	0.00	438.2
1924	0.0	-13.12	7.692	0.00	438.8
1927	-0.4	-13.14	7.704	-0.04	439.4
1930	0.0	-13.16	7.716	0.00	440.2
1933	0.0	-13.18	7.728	0.00	440.8
1936	0.0	-13.20	7.740	0.00	441.4
1939	0.0	-13.22	7.752	0.00	442.2
1942	0.0	-13.25	7.764	0.00	443.2
1945	0.2	-13.27	7.776	0.02	443.8
1948	0.0	-13.29	7.788	0.00	444.4
1951	0.0	-13.31	7.800	0.00	445.2
1954	0.0	-13.33	7.812	0.00	445.8
1957	-0.2	-13.35	7.824	-0.02	446.4
1960	0.4	-13.37	7.836	0.04	447.2
1963	-0.2	-13.39	7.848	-0.02	447.8
1966	-0.2	-13.41	7.860	-0.02	448.4
1969	0.0	-13.44	7.872	0.00	449.4
1972	0.0	-13.46	7.884	0.00	450.2
1975	0.0	-13.48	7.896	0.00	450.8
1978	0.0	-13.50	7.908	0.00	451.6
1981	0.0	-13.52	7.920	0.00	452.2
1984	0.0	-13.54	7.932	0.00	452.8
1987	0.4	-13.56	7.944	0.04	453.6
1990	0.0	-13.58	7.956	0.00	454.2
1993	-0.2	-13.60	7.968	-0.02	454.8
1996	-0.2	-13.63	7.980	-0.02	455.8
1999	0.0	-13.65	7.992	0.00	456.6
2002	0.0	-13.67	8.004	0.00	457.2
2005	-0.2	-13.69	8.016	-0.02	457.8
2008	0.0	-13.71	8.028	0.00	458.6
2011	-0.4	-13.73	8.040	-0.04	459.2
2014	0.0	-13.75	8.052	0.00	459.8
2017	0.0	-13.77	8.064	0.00	460.6
2020	0.0	-13.79	8.076	0.00	461.2
2023	0.0	-13.82	8.088	0.00	462.2
2026	0.0	-13.84	8.100	0.00	462.8
2029	0.0	-13.86	8.112	0.00	463.6
2032	-0.4	-13.88	8.124	-0.04	464.2
2035	0.6	-13.90	8.136	0.08	464.8
2038	0.0	-13.92	8.148	0.00	465.6
2041	0.0	-13.94	8.160	0.00	466.2
2044	0.0	-13.96	8.172	0.00	466.8
2047	0.0	-13.98	8.184	0.00	467.6
2050	0.0	-14.01	8.196	0.00	468.6
2053	0.2	-14.03	8.208	0.02	469.2
2056	0.0	-14.05	8.220	0.00	469.8
2059	0.0	-14.07	8.232	0.00	470.6
2062	0.0	-14.09	8.244	0.00	471.2
2065	0.0	-14.11	8.256	0.00	472.0
2068	-0.4	-14.13	8.268	-0.04	472.6
2071	0.0	-14.16	8.280	0.00	473.6
2074	0.2	-14.18	8.292	0.02	474.2
2077	0.4	-14.20	8.304	0.04	475.0
2080	0.0	-14.22	8.316	0.00	475.6
2083	0.0	-14.24	8.328	0.00	476.2
2086	0.0	-14.26	8.340	0.00	477.0
2089	0.0	-14.28	8.352	0.00	477.6
2092	-0.2	-14.30	8.364	-0.02	478.2
2095	0.0	-14.32	8.376	0.00	479.0
2098	0.0	-14.35	8.388	0.00	480.0
2101	0.0	-14.37	8.400	0.00	480.6
2104	0.0	-14.39	8.412	0.00	481.2
2107	0.0	-14.41	8.424	0.00	482.0
2110	0.0	-14.43	8.436	0.00	482.6
2113	-0.2	-14.45	8.448	-0.02	483.2
2116	-0.2	-14.47	8.460	-0.02	484.0
2119	0.0	-14.49	8.472	0.00	484.6
2122	0.2	-14.51	8.484	0.02	485.2
2125	-0.2	-14.54	8.496	-0.02	486.2
2128	0.0	-14.56	8.508	0.00	487.0
2131	0.0	-14.58	8.520	0.00	487.6
2134	0.0	-14.60	8.532	0.00	488.2
2137	0.0	-14.62	8.544	0.00	489.0
2140	0.2	-14.64	8.556	0.02	489.6
2143	0.0	-14.66	8.568	0.00	490.4
2146	-0.2	-14.68	8.580	-0.02	491.0
2149	0.0	-14.70	8.592	0.00	491.6
2152	0.0	-14.73	8.604	0.00	492.6
2155	-0.2	-14.75	8.616	-0.02	493.4
2158	-0.2	-14.77	8.628	-0.02	494.0
2161	0.2	-14.79	8.640	0.02	494.6
2164	0.0	-14.81	8.652	0.00	495.4
2167	0.0	-14.83	8.664	0.00	496.0
2170	0.2	-14.85	8.676	0.02	496.6
2173	0.0	-14.87	8.688	0.00	497.4
2176	-0.2	-14.89	8.700	-0.02	498.0
2179	0.0	-14.92	8.712	0.00	499.0
2182	0.0	-14.94	8.724	0.00	499.6
2185	0.0	-14.96	8.736	0.00	500.4
2188	0.0	-14.98	8.748	0.00	501.0
2191	-0.2	-15.00	8.760	-0.02	501.6
2194	-0.2	-15.02	8.772	-0.02	502.4
2197	0.0	-15.04	8.784	0.00	503.0
2200	-0.2	-15.05	8.796	-0.02	503.4
2203	0.0	-15.07	8.808	0.00	504.0
2206	-0.4	-15.10	8.820	-0.04	505.0
2209	0.0	-15.12	8.832	0.00	505.6
2212	0.0	-15.14	8.844	0.00	506.4
2215	0.0	-15.16	8.856	0.00	507.0
2218	0.0	-15.18	8.868	0.00	507.6
2221	0.0	-15.20	8.880	0.00	508.4
2224	0.0	-15.22	8.892	0.00	509.0
2227	0.0	-15.24	8.904	0.00	509.6
2230	0.0	-15.26	8.916	0.00	510.4
2233	0.0	-15.29	8.928	0.00	511.4
2236	0.2	-15.31	8.940	0.02	512.0
2239	0.0	-15.33	8.952	0.00	512.8
2242	0.0	-15.35	8.964	0.00	513.4
2245	0.0	-15.37	8.976	0.00	514.0
2248	0.2	-15.39	8.988	0.02	514.8
2251	0.2	-15.41	9.000	0.02	515.4
2254	0.0	-15.43	9.012	0.00	516.0
2257	0.0	-15.45	9.024	0.00	516.8
2260	0.0	-15.48	9.036	0.00	517.8
2263	0.2	-15.50	9.048	0.02	518.4
2266	-0.2	-15.52	9.060	-0.02	519.0
2269	0.0	-15.54	9.072	0.00	519.8
2272	0.0	-15.56	9.084	0.00	520.4
2275	0.0	-15.58	9.096	0.00	521.0
2278	0.2	-15.60	9.108	0.02	521.8
2281	0.0	-15.62	9.120	0.00	522.4
2284	0.0	-15.64	9.132	0.00	523.0
2287	0.4	-15.66	9.144	0.04	523.8
2290	-0.2	-15.68	9.156	-0.02	524.4
2293	0.0	-15.71	9.168	0.00	525.4
2296	0.2	-15.73	9.180	0.02	526.0
2299	0.2	-15.75	9.192	0.02	526.8
2302	-0.2	-15.77	9.204	-0.02	527.4
2305	-0.2	-15.79	9.216	-0.02	528.0
2308	0.0	-15.81	9.228	0.00	528.8
2311	-0.2	-15.83	9.240	-0.02	529.4
2314	0.0	-15.85	9.252	0.00	530.2
2317	0.0	-15.87	9.264	0.00	530.8
2320	0.0	-15.89	9.276	0.00	531.4
2323	0.2	-15.91	9.288	0.02	532.2
2326	-0.2	-15.94	9.300	-0.02	533.2
2329	-0.4	-15.96	9.312	-0.04	533.8
2332	0.2	-15.98	9.324	0.02	534.4
2335	-0.2	-16.00	9.336	-0.02	535.2
2338	-0.2	-16.02	9.348	-0.02	535.8
2341	0.2	-16.04	9.360	0.02	536.4
2344	0.0	-16.06	9.372	0.00	537.2
2347	-0.2	-16.08	9.384	-0.02	537.8
2350	0.0	-16.10	9.396	0.00	538.4
2353	-0.2	-16.12	9.408	-0.02	539.2
2356	0.2	-16.14	9.420	0.02	539.8
2359	0.0	-16.16	9.432	0.00	540.4
2362	-0.4	-16.19	9.444	-0.04	541.4
2365	0.2	-16.21	9.456	0.02	542.2
2368	0.0	-16.23	9.468	0.00	542.8
2371	0.0	-16.25	9.480	0.00	543.4
2374	0.4	-16.27	9.492	0.04	544.2
2377	0.0	-16.29	9.504	0.00	544.8
2380	0.0	-16.31	9.516	0.00	545.4
2383	0.0	-16.33	9.528	0.00	546.2
2386	0.0	-16.35	9.540	0.00	546.8
2389	0.0	-16.37	9.552	0.00	547.4
2392	0.0	-16.39	9.564	0.00	548.2
2395	0.0	-16.42	9.576	0.00	549.2
2398	0.0	-16.43	9.588	0.00	549.4
2401	0.2	-16.46	9.600	0.02	550.6
2404	0.0	-16.48	9.612	0.00	551.2
2407	0.0	-16.50	9.624	0.00	551.8
2410	-0.2	-16.52	9.636	-0.02	552.6
2413	0.0	-16.54	9.648	0.00	553.2
2416	0.2	-16.56	9.660	0.02	553.8
2419	0.0	-16.58	9.672	0.00	554.6
2422	0.0	-16.60	9.684	0.00	555.2
2425	-0.2	-16.62	9.696	-0.02	555.8
2428	0.0	-16.64	9.708	0.00	556.6
2431	-0.2	-16.66	9.720	-0.02	557.2
2434	0.0	-16.69	9.732	0.00	558.2
2437	0.0	-16.71	9.744	0.00	558.8
2440	0.0	-16.73	9.756	0.00	559.6
2443	0.0	-16.75	9.768	0.00	560.2
2446	0.0	-16.77	9.780	0.00	560.8
2449	0.0	-16.79	9.792	0.00	561.6
2452	0.0	-16.81	9.804	0.00	562.2
2455	-0.2	-16.83	9.816	-0.02	562.8
2458	0.0	-16.85	9.828	0.00	563.6
2461	-0.2	-16.87	9.840	-0.02	564.2
2464	0.0	-16.89	9.852	0.00	564.8
2467	0.0	-16.91	9.864	0.00	565.6
2470	-0.2	-16.94	9.876	-0.02	566.6
2473	-0.2	-16.96	9.888	-0.02	567.2
2476	0.0	-16.98	9.900	0.00	567.8
2479	0.2	-17.00	9.912	0.02	568.6
2482	-0.2	-17.02	9.924	-0.02	569.2
2485	0.0	-17.04	9.936	0.00	569.8
2488	0.2	-17.07	9.948	0.02	571.0
2491	0.2	-17.09	9.960	0.02	571.6
2494	0.0	-17.11	9.972	0.00	572.2
2497	0.2	-17.13	9.984	0.02	573.0
2500	0.0	-17.15	9.996	0.00	573.6
2503	0.0	-17.18	10.008	0.00	574.6
2506	0.4	-17.20	10.020	0.04	575.2
2509	0.0	-17.22	10.032	0.00	576.0
2512	-0.4	-17.24	10.044	-0.04	576.6
2515	0.2	-17.26	10.056	0.02	577.2
2518	0.2	-17.28	10.068	0.02	578.0
2521	-0.2	-17.30	10.080	-0.02	578.6
2524	-0.2	-17.32	10.092	-0.02	579.2
2527	0.0	-17.34	10.104	0.00	580.0
2530	0.0	-17.36	10.116	0.00	580.6
2533	0.0	-17.38	10.128	0.00	581.2
2536	0.0	-17.40	10.140	0.00	582.0
2539	0.0	-17.43	10.152	0.00	583.0
2542	-0.2	-17.45	10.164	-0.02	583.6
2545	-0.4	-17.47	10.176	-0.04	584.2
2548	0.0	-17.49	10.188	0.00	585.0
2551	-0.2	-17.51	10.200	-0.02	585.6
2554	0.0	-17.53	10.212	0.00	586.2
2557	0.0	-17.55	10.224	0.00	587.0
2560	0.0	-17.57	10.236	0.00	587.6
2563	-0.4	-17.59	10.248	-0.04	588.2
2566	0.2	-17.61	10.260	0.02	589.0
2569	-0.2	-17.63	10.272	-0.02	589.6
2572	0.0	-17.66	10.284	0.00	590.6
2575	0.0	-17.68	10.296	0.00	591.4
2578	0.0	-17.70	10.308	0.00	592.0
2581	0.0	-17.72	10.320	0.00	592.6
2584	0.0	-17.74	10.332	0.00	593.4
2587	0.0	-17.76	10.344	0.00	594.0
2590	0.0	-17.78	10.356	0.00	594.6
2593	0.0	-17.80	10.368	0.00	595.4
2596	0.2	-17.82	10.380	0.02	596.0
2599	0.0	-17.84	10.392	0.00	596.6
2602	0.2	-17.86	10.404	0.02	597.4
2605	0.0	-17.89	10.416	0.00	598.4
2608	0.2	-17.91	10.428	0.02	599.0
2611	0.0	-17.93	10.440	0.00	599.6
2614	-0.2	-17.95	10.452	-0.02	600.4
2617	0.0	-17.97	10.464	0.00	601.0
2620	-0.2	-17.99	10.476	-0.02	601.6
2623	0.0	-18.01	10.488	0.00	602.4
2626	0.0	-18.03	10.500	0.00	603.0
2629	-0.2	-18.05	10.512	-0.02	603.6
2632	0.0	-18.07	10.524	0.00	604.4
2635	0.0	-18.09	10.536	0.00	605.0
2638	0.0	-18.12	10.548	0.00	606.0
2641	0.0	-18.14	10.560	0.00	606.6
2644	0.2	-18.16	10.572	0.02	607.4
2647	-0.2	-18.18	10.584	-0.02	608.0
2650	-0.2	-18.20	10.596	-0.02	608.6
2653	0.0	-18.22	10.608	0.00	609.4
2656	0.0	-18.24	10.620	0.00	610.0
2659	-0.4	-18.26	10.632	-0.04	610.8
2662	-0.2	-18.28	10.644	-0.02	611.4
2665	0.0	-18.31	10.656	0.00	612.4
2668	0.0	-18.33	10.668	0.00	613.0
2671	0.0	-18.35	10.680	0.00	613.8
2674	0.0	-18.37	10.692	0.00	614.4
2677	0.2	-18.39	10.704	0.02	615.0
2680	0.0	-18.41	10.716	0.00	615.8
2683	0.0	-18.43	10.728	0.00	616.4
2686	0.0	-18.45	10.740	0.00	617.0
2689	0.0	-18.47	10.752	0.00	617.8
2692	0.0	-18.49	10.764	0.00	618.4
2695	0.0	-18.52	10.776	0.00	619.4
2698	0.0	-18.54	10.788	0.00	620.0
2701	0.0	-18.56	10.800	0.00	620.8
2704	0.2	-18.58	10.812	0.02	621.4
2707	-0.4	-18.60	10.824	-0.04	622.0
2710	0.0	-18.62	10.836	0.00	622.8
2713	0.0	-18.64	10.848	0.00	623.4
2716	0.0	-18.66	10.860	0.00	624.0
2719	-0.2	-18.68	10.872	-0.02	624.8
2722	0.2	-18.71	10.884	0.02	625.8
2725	0.0	-18.73	10.896	0.00	626.4
2728	0.0	-18.75	10.908	0.00	627.0
2731	0.0	-18.77	10.920	0.00	627.8
2734	-0.2	-18.79	10.932	-0.02	628.4
2737	0.0	-18.81	10.944	0.00	629.0
2740	-0.2	-18.83	10.956	-0.02	629.8
2743	0.0	-18.85	10.968	0.00	630.4
2746	-0.2	-18.88	10.980	-0.02	631.4
2749	0.2	-18.90	10.992	0.02	632.2
2752	0.0	-18.92	11.004	0.00	632.8
2755	0.0	-18.94	11.016	0.00	633.4
2758	0.2	-18.96	11.028	0.02	634.2
2761	0.0	-18.98	11.040	0.00	634.8
2764	0.0	-19.00	11.052	0.00	635.4
2767	0.0	-19.02	11.064	0.00	636.2
2770	0.0	-19.04	11.076	0.00	636.8
2773	0.2	-19.06	11.088	0.02	637.4
2776	0.2	-19.08	11.100	0.02	638.2
2779	0.0	-19.10	11.112	0.00	638.8
2782	0.2	-19.12	11.124	0.02	639.4
2785	0.0	-19.14	11.136	0.00	640.2
2788	-0.2	-19.16	11.148	-0.02	640.8
2791	0.0	-19.18	11.160	0.00	641.4
2794	0.0	-19.20	11.172	0.00	642.2
2797	0.0	-19.22	11.184	0.00	642.8
2800	0.2	-19.25	11.196	0.02	643.8
2803	-0.2	-19.27	11.208	-0.02	644.4
2806	0.2	-19.29	11.220	0.02	645.2
2809	0.0	-19.31	11.232	0.00	645.8
2812	0.8	-19.33	11.244	0.10	646.4
2815	0.0	-19.35	11.256	0.00	647.2
2818	-0.2	-19.37	11.268	-0.02	647.8
2821	0.0	-19.39	11.280	0.00	648.4
2824	0.0	-19.41	11.292	0.00	649.2
2827	0.2	-19.44	11.304	0.02	650.2
2830	0.4	-19.46	11.316	0.04	650.8
2833	0.6	-19.48	11.328	0.08	651.6
2836	1.2	-19.50	11.340	0.14	652.2
2839	2.8	-19.52	11.352	0.34	652.8
2842	5.0	-19.54	11.364	0.62	653.6
2845	8.6	-19.56	11.376	1.06	654.2
2848	12.8	-19.58	11.388	1.58	654.8
2851	17.0	-19.59	11.400	2.10	655.2
2854	22.2	-19.61	11.412	2.74	655.8
2857	27.6	-19.63	11.424	3.42	656.6
2860	37.0	-19.64	11.436	4.58	656.8
2863	51.0	-19.65	11.448	6.30	657.2
2866	60.8	-19.66	11.460	7.52	657.6
2869	65.4	-19.68	11.472	8.08	658.2
2872	67.2	-19.69	11.484	8.30	658.6
2875	68.8	-19.72	11.496	8.50	659.6
2878	69.0	-19.74	11.508	8.52	660.2
2881	68.2	-19.76	11.520	8.42	660.8
2884	68.4	-19.78	11.532	8.46	661.6
2887	67.2	-19.80	11.544	8.30	662.2
2890	66.8	-19.82	11.556	8.26	662.8
2893	65.4	-19.85	11.568	8.08	663.8
2896	65.2	-19.87	11.580	8.06	664.6
2899	64.2	-19.89	11.592	7.94	665.2
2902	62.6	-19.91	11.604	7.74	665.8
2905	61.2	-19.93	11.616	7.56	666.6
2908	60.2	-19.96	11.628	7.44	667.6
2911	59.2	-19.98	11.640	7.32	668.2
2914	57.2	-20.00	11.652	7.06	668.8
2917	55.8	-20.02	11.664	6.90	669.6
2920	49.8	-20.05	11.676	6.16	670.6
2923	46.6	-20.07	11.688	5.76	671.2
2926	49.4	-20.09	11.700	6.10	672.0
2929	51.4	-20.11	11.712	6.36	672.6
2932	54.0	-20.13	11.724	6.68	673.2
2935	55.4	-20.15	11.736	6.84	674.0
2938	57.2	-20.17	11.748	7.06	674.6
2941	57.8	-20.19	11.760	7.14	675.2
2944	59.0	-20.21	11.772	7.30	676.0
2947	57.6	-20.23	11.784	7.12	676.6
2950	57.4	-20.26	11.796	7.10	677.6
2953	56.4	-20.28	11.808	6.96	678.2
2956	56.0	-20.30	11.820	6.92	679.0
2959	55.8	-20.32	11.832	6.90	679.6
2962	55.4	-20.34	11.844	6.84	680.2
2965	55.2	-20.36	11.856	6.82	681.0
2968	54.0	-20.38	11.868	6.68	681.6
2971	52.8	-20.40	11.880	6.52	682.2
2974	52.4	-20.42	11.892	6.48	683.0
2977	51.8	-20.45	11.904	6.40	684.0
2980	50.2	-20.47	11.916	6.20	684.6
2983	49.8	-20.49	11.928	6.16	685.2
2986	48.8	-20.51	11.940	6.04	686.0
2989	48.2	-20.54	11.952	5.96	687.0
2992	47.6	-20.56	11.964	5.88	687.6
2995	46.8	-20.58	11.976	5.78	688.2
2998	47.2	-20.60	11.988	5.84	689.0
3001	46.0	-20.62	12.000	5.68	689.6
3004	45.2	-20.64	12.012	5.58	690.4
3007	44.6	-20.66	12.024	5.52	691.0
3010	44.0	-20.68	12.036	5.44	691.6
3013	43.8	-20.71	12.048	5.42	692.6
3016	42.8	-20.73	12.060	5.28	693.4
3019	42.8	-20.75	12.072	5.28	694.0
3022	42.2	-20.77	12.084	5.22	694.6
3025	42.4	-20.79	12.096	5.24	695.4
3028	41.8	-20.81	12.108	5.16	696.0
3031	41.8	-20.84	12.120	5.16	697.0
3034	41.8	-20.86	12.132	5.16	697.6
3037	42.0	-20.88	12.144	5.18	698.4
3040	42.2	-20.90	12.156	5.22	699.0
3043	42.2	-20.92	12.168	5.22	699.6
3046	42.0	-20.94	12.180	5.18	700.4
3049	42.0	-20.96	12.192	5.18	701.0
3052	42.4	-20.98	12.204	5.24	701.6
3055	42.8	-21.00	12.216	5.28	702.4
3058	43.6	-21.02	12.228	5.38	703.0
3061	44.4	-21.04	12.240	5.48	703.6
3064	45.0	-21.06	12.252	5.56	704.4
3067	45.6	-21.08	12.264	5.64	705.0
3070	47.4	-21.10	12.276	5.86	705.6
3073	48.4	-21.12	12.288	5.98	706.4
3076	48.6	-21.14	12.300	6.00	707.0
3079	49.4	-21.16	12.312	6.10	707.6
3082	49.6	-21.18	12.324	6.12	708.4
3085	49.0	-21.21	12.336	6.06	709.4
3088	45.4	-21.23	12.348	5.60	710.0
3091	44.4	-21.25	12.360	5.48	710.8
3094	46.8	-21.27	12.372	5.78	711.4
3097	41.2	-21.29	12.384	5.10	712.0
3100	42.8	-21.31	12.396	5.28	712.8
3103	44.8	-21.33	12.408	5.54	713.4
3106	47.4	-21.35	12.420	5.86	714.0
3109	49.2	-21.37	12.432	6.08	714.8
3112	50.4	-21.39	12.444	6.22	715.4
3115	46.4	-21.40	12.456	5.74	715.8
3118	42.0	-21.41	12.468	5.18	716.0
3121	39.6	-21.41	12.480	4.90	716.0
3124	38.4	-21.41	12.492	4.74	716.0
3127	37.6	-21.41	12.504	4.64	716.0
3130	37.0	-21.41	12.516	4.58	716.0
3133	36.4	-21.41	12.528	4.50	716.0
3136	35.8	-21.41	12.540	4.42	716.0
3139	35.6	-21.41	12.552	4.40	716.0
3142	35.2	-21.41	12.564	4.34	716.0
3145	35.0	-21.41	12.576	4.32	716.0
3148	34.8	-21.41	12.588	4.30	716.0
3151	34.6	-21.41	12.600	4.28	716.0
3154	34.4	-21.41	12.612	4.26	716.0
3157	34.2	-21.41	12.624	4.22	716.0
3160	34.0	-21.41	12.636	4.20	716.0
3163	34.0	-21.41	12.648	4.20	716.0