File: results/youngs-modulus/2025-04-15/inconclusive-data/pf06mt02.csv
sep=
pf06mt02

System Information:
IntelliMESUR Version: 2.2.1
Test Frame Model: F505
Test Frame Serial Number: 4418651
Test Frame Capacity: 500 lbF / 2.2 kN
Test Frame Firmware Version: 1.00.14
Force Sensor Model: FS05-100
Force Sensor Capacity: 500 N
Force Sensor Resolution: 0.2 N
Force Sensor Serial Number: 4425350
Calibration Date: Apr 29, 2024
Calibration Due Date: Apr 29, 2025

Reading	Load [N]	Distance [mm]	Time [s]	Stress [MPa]	Strain [%]
1	0.2	0.00	0.000	0.04	0.0
3	0.0	0.00	0.008	0.00	0.0
5	0.0	0.00	0.016	0.00	0.0
7	0.0	0.00	0.024	0.00	0.0
9	0.0	0.00	0.032	0.00	0.0
11	0.0	0.00	0.040	0.00	0.0
13	0.0	0.00	0.048	0.00	0.0
15	0.0	0.00	0.056	0.00	0.0
17	0.0	0.00	0.064	0.00	0.0
19	-0.2	0.00	0.072	-0.04	0.0
21	0.2	0.00	0.080	0.04	0.0
23	0.0	0.00	0.088	0.00	0.0
25	0.0	0.00	0.096	0.00	0.0
27	-0.2	0.00	0.104	-0.04	0.0
29	0.0	0.00	0.112	0.00	0.0
31	0.0	0.00	0.120	0.00	0.0
33	0.0	0.00	0.128	0.00	0.0
35	0.0	0.00	0.136	0.00	0.0
37	0.0	0.00	0.144	0.00	0.0
39	-0.2	0.00	0.152	-0.04	0.0
41	-0.2	0.00	0.160	-0.04	0.0
43	0.0	0.00	0.168	0.00	0.0
45	-0.2	0.00	0.176	-0.04	0.0
47	0.0	0.00	0.184	0.00	0.0
49	0.0	-0.01	0.192	0.00	0.4
51	0.0	-0.02	0.200	0.00	0.6
53	0.0	-0.05	0.208	0.00	1.6
55	0.0	-0.05	0.216	0.00	1.6
57	0.0	-0.07	0.224	0.00	2.2
59	0.0	-0.08	0.232	0.00	2.4
61	0.2	-0.09	0.240	0.04	2.8
63	0.2	-0.11	0.248	0.04	3.4
65	0.0	-0.12	0.256	0.00	3.8
67	0.0	-0.14	0.264	0.00	4.4
69	0.0	-0.15	0.272	0.00	4.6
71	0.0	-0.16	0.280	0.00	5.0
73	0.2	-0.18	0.288	0.04	5.6
75	0.0	-0.19	0.296	0.00	5.8
77	0.0	-0.21	0.304	0.00	6.6
79	0.0	-0.22	0.312	0.00	6.8
81	0.0	-0.23	0.320	0.00	7.2
83	0.0	-0.25	0.328	0.00	7.8
85	0.2	-0.26	0.336	0.04	8.0
87	0.2	-0.28	0.344	0.04	8.6
89	-0.4	-0.30	0.352	-0.08	9.2
91	0.0	-0.30	0.360	0.00	9.2
93	0.0	-0.32	0.368	0.00	10.0
95	-0.2	-0.33	0.376	-0.04	10.2
97	0.0	-0.35	0.384	0.00	10.8
99	-0.2	-0.37	0.392	-0.04	11.4
101	0.0	-0.37	0.400	0.00	11.4
103	0.0	-0.39	0.408	0.00	12.0
105	-0.2	-0.40	0.416	-0.04	12.4
107	0.0	-0.42	0.424	0.00	13.0
109	0.0	-0.44	0.432	0.00	13.6
111	0.0	-0.44	0.440	0.00	13.6
113	0.0	-0.46	0.448	0.00	14.2
115	0.0	-0.47	0.456	0.00	14.6
117	0.0	-0.49	0.464	0.00	15.2
119	0.0	-0.50	0.472	0.00	15.4
121	0.0	-0.51	0.480	0.00	15.8
123	-0.4	-0.53	0.488	-0.08	16.4
125	0.0	-0.54	0.496	0.00	16.8
127	-0.2	-0.55	0.504	-0.04	17.0
129	0.0	-0.57	0.512	0.00	17.6
131	0.0	-0.58	0.520	0.00	18.0
133	0.0	-0.60	0.528	0.00	18.6
135	0.0	-0.62	0.536	0.00	19.2
137	0.0	-0.62	0.544	0.00	19.2
139	0.2	-0.64	0.552	0.04	19.8
141	0.0	-0.65	0.560	0.00	20.2
143	0.0	-0.67	0.568	0.00	20.8
145	0.0	-0.69	0.576	0.00	21.4
147	0.0	-0.69	0.584	0.00	21.4
149	0.0	-0.71	0.592	0.00	22.0
151	0.0	-0.72	0.600	0.00	22.2
153	0.2	-0.74	0.608	0.04	23.0
155	0.2	-0.75	0.616	0.04	23.2
157	0.0	-0.77	0.624	0.00	23.8
159	0.0	-0.79	0.632	0.00	24.4
161	0.2	-0.80	0.640	0.04	24.8
163	0.0	-0.82	0.648	0.00	25.4
165	-0.4	-0.83	0.656	-0.08	25.6
167	0.0	-0.84	0.664	0.00	26.0
169	0.0	-0.86	0.672	0.00	26.6
171	0.0	-0.87	0.680	0.00	27.0
173	0.2	-0.89	0.688	0.04	27.6
175	-0.2	-0.90	0.696	-0.04	27.8
177	0.0	-0.91	0.704	0.00	28.2
179	0.0	-0.93	0.712	0.00	28.8
181	0.2	-0.94	0.720	0.04	29.2
183	0.0	-0.96	0.728	0.00	29.8
185	0.2	-0.97	0.736	0.04	30.0
187	0.2	-0.98	0.744	0.04	30.4
189	0.0	-1.00	0.752	0.00	31.0
191	0.0	-1.01	0.760	0.00	31.2
193	0.2	-1.03	0.768	0.04	31.8
195	0.0	-1.04	0.776	0.00	32.2
197	0.0	-1.05	0.784	0.00	32.6
199	0.0	-1.07	0.792	0.00	33.2
201	0.2	-1.08	0.800	0.04	33.4
203	0.0	-1.10	0.808	0.00	34.0
205	0.0	-1.11	0.816	0.00	34.4
207	0.0	-1.12	0.824	0.00	34.6
209	0.2	-1.14	0.832	0.04	35.2
211	0.0	-1.15	0.840	0.00	35.6
213	0.0	-1.16	0.848	0.00	36.0
215	0.0	-1.18	0.856	0.00	36.6
217	0.0	-1.19	0.864	0.00	36.8
219	0.0	-1.21	0.872	0.00	37.4
221	-0.2	-1.22	0.880	-0.04	37.8
223	0.0	-1.23	0.888	0.00	38.0
225	0.0	-1.25	0.896	0.00	38.6
227	0.0	-1.26	0.904	0.00	39.0
229	0.0	-1.28	0.912	0.00	39.6
231	-0.2	-1.29	0.920	-0.04	40.0
233	0.0	-1.30	0.928	0.00	40.2
235	-0.2	-1.32	0.936	-0.04	40.8
237	0.0	-1.33	0.944	0.00	41.2
239	-0.2	-1.34	0.952	-0.04	41.4
241	0.2	-1.36	0.960	0.04	42.2
243	0.0	-1.37	0.968	0.00	42.4
245	0.0	-1.39	0.976	0.00	43.0
247	-0.2	-1.40	0.984	-0.04	43.4
249	0.0	-1.41	0.992	0.00	43.6
251	0.0	-1.43	1.000	0.00	44.2
253	0.0	-1.44	1.008	0.00	44.6
255	0.0	-1.46	1.016	0.00	45.2
257	-0.2	-1.48	1.024	-0.04	45.8
259	0.2	-1.48	1.032	0.04	45.8
261	0.0	-1.50	1.040	0.00	46.4
263	0.0	-1.51	1.048	0.00	46.8
265	0.0	-1.53	1.056	0.00	47.4
267	-0.2	-1.55	1.064	-0.04	48.0
269	0.2	-1.55	1.072	0.04	48.0
271	0.0	-1.57	1.080	0.00	48.6
273	0.0	-1.58	1.088	0.00	49.0
275	-0.2	-1.60	1.096	-0.04	49.6
277	-0.2	-1.61	1.104	-0.04	49.8
279	-0.2	-1.62	1.112	-0.04	50.2
281	-0.2	-1.64	1.120	-0.04	50.8
283	0.0	-1.65	1.128	0.00	51.0
285	-0.2	-1.67	1.136	-0.04	51.8
287	0.0	-1.68	1.144	0.00	52.0
289	0.0	-1.69	1.152	0.00	52.4
291	0.2	-1.71	1.160	0.04	53.0
293	0.0	-1.72	1.168	0.00	53.2
295	0.0	-1.74	1.176	0.00	53.8
297	0.0	-1.75	1.184	0.00	54.2
299	0.0	-1.76	1.192	0.00	54.4
301	-0.2	-1.77	1.200	-0.04	54.8
303	0.2	-1.78	1.208	0.04	55.2
305	0.2	-1.80	1.216	0.04	55.8
307	0.2	-1.81	1.224	0.04	56.0
309	0.0	-1.82	1.232	0.00	56.4
311	0.0	-1.84	1.240	0.00	57.0
313	0.2	-1.85	1.248	0.04	57.2
315	0.2	-1.87	1.256	0.04	57.8
317	0.2	-1.88	1.264	0.04	58.2
319	-0.2	-1.89	1.272	-0.04	58.6
321	0.0	-1.91	1.280	0.00	59.2
323	-0.2	-1.92	1.288	-0.04	59.4
325	0.0	-1.94	1.296	0.00	60.0
327	0.0	-1.95	1.304	0.00	60.4
329	0.0	-1.96	1.312	0.00	60.6
331	-0.2	-1.97	1.320	-0.04	61.0
333	0.0	-1.99	1.328	0.00	61.6
335	0.0	-2.00	1.336	0.00	62.0
337	0.0	-2.02	1.344	0.00	62.6
339	0.2	-2.03	1.352	0.04	62.8
341	0.4	-2.04	1.360	0.08	63.2
343	0.0	-2.06	1.368	0.00	63.8
345	0.4	-2.07	1.376	0.08	64.0
347	-0.2	-2.09	1.384	-0.04	64.8
349	0.0	-2.10	1.392	0.00	65.0
351	0.0	-2.12	1.400	0.00	65.6
353	0.0	-2.13	1.408	0.00	66.0
355	0.2	-2.14	1.416	0.04	66.2
357	-0.2	-2.16	1.424	-0.04	66.8
359	-0.2	-2.17	1.432	-0.04	67.2
361	0.0	-2.19	1.440	0.00	67.8
363	0.0	-2.20	1.448	0.00	68.2
365	0.0	-2.21	1.456	0.00	68.4
367	0.0	-2.23	1.464	0.00	69.0
369	-0.2	-2.24	1.472	-0.04	69.4
371	0.0	-2.25	1.480	0.00	69.6
373	0.0	-2.27	1.488	0.00	70.2
375	0.2	-2.28	1.496	0.04	70.6
377	0.0	-2.30	1.504	0.00	71.2
379	-0.2	-2.31	1.512	-0.04	71.6
381	0.0	-2.32	1.520	0.00	71.8
383	0.0	-2.34	1.528	0.00	72.4
385	0.0	-2.35	1.536	0.00	72.8
387	0.2	-2.37	1.544	0.04	73.4
389	0.0	-2.39	1.552	0.00	74.0
391	0.0	-2.39	1.560	0.00	74.0
393	0.0	-2.41	1.568	0.00	74.6
395	0.0	-2.42	1.576	0.00	75.0
397	0.0	-2.44	1.584	0.00	75.6
399	0.0	-2.46	1.592	0.00	76.2
401	0.0	-2.46	1.600	0.00	76.2
403	-0.2	-2.48	1.608	-0.04	76.8
405	0.0	-2.49	1.616	0.00	77.0
407	0.0	-2.50	1.624	0.00	77.4
409	0.0	-2.53	1.632	0.00	78.4
411	0.2	-2.53	1.640	0.04	78.4
413	0.0	-2.55	1.648	0.00	79.0
415	0.0	-2.56	1.656	0.00	79.2
417	0.0	-2.57	1.664	0.00	79.6
419	0.0	-2.59	1.672	0.00	80.2
421	0.0	-2.60	1.680	0.00	80.4
423	0.0	-2.62	1.688	0.00	81.2
425	0.0	-2.64	1.696	0.00	81.8
427	0.0	-2.64	1.704	0.00	81.8
429	0.0	-2.66	1.712	0.00	82.4
431	0.0	-2.67	1.720	0.00	82.6
433	0.4	-2.69	1.728	0.08	83.2
435	-0.2	-2.70	1.736	-0.04	83.6
437	-0.2	-2.72	1.744	-0.04	84.2
439	0.0	-2.73	1.752	0.00	84.6
441	0.0	-2.74	1.760	0.00	84.8
443	0.0	-2.76	1.768	0.00	85.4
445	-0.4	-2.78	1.776	-0.08	86.0
447	0.0	-2.80	1.784	0.00	86.6
449	-0.2	-2.81	1.792	-0.04	87.0
451	-0.2	-2.82	1.800	-0.04	87.4
453	-0.4	-2.84	1.808	-0.08	88.0
455	-0.4	-2.85	1.816	-0.08	88.2
457	-0.4	-2.87	1.824	-0.08	88.8
459	0.2	-2.88	1.832	0.04	89.2
461	0.0	-2.89	1.840	0.00	89.4
463	0.0	-2.91	1.848	0.00	90.0
465	0.0	-2.92	1.856	0.00	90.4
467	0.0	-2.93	1.864	0.00	90.8
469	0.0	-2.95	1.872	0.00	91.4
471	0.0	-2.96	1.880	0.00	91.6
473	-0.6	-2.98	1.888	-0.12	92.2
475	0.0	-2.99	1.896	0.00	92.6
477	0.0	-3.00	1.904	0.00	92.8
479	0.0	-3.02	1.912	0.00	93.4
481	0.2	-3.03	1.920	0.04	93.8
483	-0.2	-3.05	1.928	-0.04	94.4
485	0.0	-3.06	1.936	0.00	94.8
487	-0.2	-3.07	1.944	-0.04	95.0
489	0.0	-3.09	1.952	0.00	95.6
491	0.2	-3.10	1.960	0.04	96.0
493	0.2	-3.12	1.968	0.04	96.6
495	0.0	-3.13	1.976	0.00	97.0
497	0.0	-3.15	1.984	0.00	97.6
499	0.0	-3.16	1.992	0.00	97.8
501	0.0	-3.17	2.000	0.00	98.2
503	0.0	-3.19	2.008	0.00	98.8
505	0.2	-3.20	2.016	0.04	99.0
507	0.0	-3.22	2.024	0.00	99.6
509	0.2	-3.23	2.032	0.04	100.0
511	-0.2	-3.24	2.040	-0.04	100.4
513	0.2	-3.26	2.048	0.04	101.0
515	0.0	-3.27	2.056	0.00	101.2
517	-0.4	-3.30	2.064	-0.08	102.2
519	-0.2	-3.30	2.072	-0.04	102.2
521	0.0	-3.31	2.080	0.00	102.4
523	0.0	-3.33	2.088	0.00	103.0
525	0.0	-3.34	2.096	0.00	103.4
527	0.0	-3.37	2.104	0.00	104.4
529	0.0	-3.37	2.112	0.00	104.4
531	0.4	-3.38	2.120	0.08	104.6
533	0.0	-3.40	2.128	0.00	105.2
535	0.4	-3.41	2.136	0.08	105.6
537	0.0	-3.44	2.144	0.00	106.6
539	0.0	-3.44	2.152	0.00	106.6
541	0.0	-3.45	2.160	0.00	106.8
543	0.2	-3.47	2.168	0.04	107.4
545	0.0	-3.48	2.176	0.00	107.8
547	0.0	-3.50	2.184	0.00	108.4
549	0.0	-3.51	2.192	0.00	108.6
551	0.0	-3.53	2.200	0.00	109.2
553	0.0	-3.54	2.208	0.00	109.6
555	0.0	-3.55	2.216	0.00	110.0
557	0.0	-3.57	2.224	0.00	110.6
559	0.0	-3.58	2.232	0.00	110.8
561	0.2	-3.60	2.240	0.04	111.4
563	0.0	-3.62	2.248	0.00	112.0
565	-0.2	-3.63	2.256	-0.04	112.4
567	0.0	-3.64	2.264	0.00	112.6
569	0.0	-3.65	2.272	0.00	113.0
571	-0.2	-3.67	2.280	-0.04	113.6
573	0.0	-3.69	2.288	0.00	114.2
575	0.0	-3.70	2.296	0.00	114.6
577	0.4	-3.71	2.304	0.08	114.8
579	0.0	-3.72	2.312	0.00	115.2
581	0.0	-3.74	2.320	0.00	115.8
583	0.0	-3.75	2.328	0.00	116.0
585	0.0	-3.77	2.336	0.00	116.8
587	-0.2	-3.78	2.344	-0.04	117.0
589	0.0	-3.79	2.352	0.00	117.4
591	-0.2	-3.82	2.360	-0.04	118.2
593	0.0	-3.82	2.368	0.00	118.2
595	0.0	-3.84	2.376	0.00	118.8
597	0.2	-3.85	2.384	0.04	119.2
599	0.0	-3.86	2.392	0.00	119.6
601	0.0	-3.88	2.400	0.00	120.2
603	-0.2	-3.89	2.408	-0.04	120.4
605	-0.2	-3.91	2.416	-0.04	121.0
607	0.0	-3.92	2.424	0.00	121.4
609	0.2	-3.94	2.432	0.04	122.0
611	0.0	-3.96	2.440	0.00	122.6
613	0.2	-3.96	2.448	0.04	122.6
615	0.2	-3.98	2.456	0.04	123.2
617	0.0	-3.99	2.464	0.00	123.6
619	0.0	-4.01	2.472	0.00	124.2
621	0.2	-4.02	2.480	0.04	124.4
623	0.0	-4.03	2.488	0.00	124.8
625	-0.4	-4.05	2.496	-0.08	125.4
627	0.2	-4.06	2.504	0.04	125.6
629	0.0	-4.08	2.512	0.00	126.4
631	0.0	-4.09	2.520	0.00	126.6
633	0.2	-4.10	2.528	0.04	127.0
635	-0.2	-4.12	2.536	-0.04	127.6
637	0.0	-4.13	2.544	0.00	127.8
639	-0.2	-4.15	2.552	-0.04	128.4
641	0.0	-4.16	2.560	0.00	128.8
643	0.0	-4.17	2.568	0.00	129.2
645	-0.4	-4.19	2.576	-0.08	129.8
647	0.6	-4.20	2.584	0.12	130.0
649	0.0	-4.22	2.592	0.00	130.6
651	0.0	-4.23	2.600	0.00	131.0
653	0.0	-4.24	2.608	0.00	131.2
655	0.0	-4.26	2.616	0.00	131.8
657	0.0	-4.28	2.624	0.00	132.6
659	0.0	-4.29	2.632	0.00	132.8
661	0.0	-4.30	2.640	0.00	133.2
663	-0.2	-4.32	2.648	-0.04	133.8
665	0.0	-4.33	2.656	0.00	134.0
667	0.2	-4.34	2.664	0.04	134.4
669	0.0	-4.36	2.672	0.00	135.0
671	0.0	-4.37	2.680	0.00	135.2
673	-0.2	-4.39	2.688	-0.04	136.0
675	0.2	-4.40	2.696	0.04	136.2
677	0.0	-4.41	2.704	0.00	136.6
679	-0.2	-4.43	2.712	-0.04	137.2
681	0.0	-4.44	2.720	0.00	137.4
683	0.0	-4.46	2.728	0.00	138.0
685	0.0	-4.48	2.736	0.00	138.6
687	0.0	-4.48	2.744	0.00	138.6
689	0.0	-4.50	2.752	0.00	139.4
691	0.2	-4.51	2.760	0.04	139.6
693	0.2	-4.53	2.768	0.04	140.2
695	0.0	-4.54	2.776	0.00	140.6
697	-0.2	-4.55	2.784	-0.04	140.8
699	0.0	-4.57	2.792	0.00	141.4
701	0.2	-4.58	2.800	0.04	141.8
703	0.0	-4.60	2.808	0.00	142.4
705	0.0	-4.61	2.816	0.00	142.8
707	0.0	-4.63	2.824	0.00	143.4
709	0.0	-4.64	2.832	0.00	143.6
711	0.0	-4.65	2.840	0.00	144.0
713	0.0	-4.67	2.848	0.00	144.6
715	0.0	-4.68	2.856	0.00	144.8
717	0.0	-4.70	2.864	0.00	145.6
719	0.0	-4.71	2.872	0.00	145.8
721	-0.2	-4.72	2.880	-0.04	146.2
723	0.2	-4.74	2.888	0.04	146.8
725	0.0	-4.75	2.896	0.00	147.0
727	0.0	-4.77	2.904	0.00	147.6
729	0.0	-4.78	2.912	0.00	148.0
731	0.0	-4.80	2.920	0.00	148.6
733	0.0	-4.81	2.928	0.00	149.0
735	0.0	-4.82	2.936	0.00	149.2
737	0.0	-4.84	2.944	0.00	149.8
739	-0.2	-4.85	2.952	-0.04	150.2
741	0.0	-4.87	2.960	0.00	150.8
743	-0.4	-4.88	2.968	-0.08	151.0
745	0.0	-4.89	2.976	0.00	151.4
747	-0.2	-4.91	2.984	-0.04	152.0
749	0.0	-4.92	2.992	0.00	152.4
751	0.0	-4.94	3.000	0.00	153.0
753	0.0	-4.95	3.008	0.00	153.2
755	0.0	-4.96	3.016	0.00	153.6
757	-0.2	-4.98	3.024	-0.04	154.2
759	0.0	-5.00	3.032	0.00	154.8
761	0.0	-5.00	3.040	0.00	154.8
763	-0.2	-5.02	3.048	-0.04	155.4
765	0.2	-5.03	3.056	0.04	155.8
767	0.2	-5.05	3.064	0.04	156.4
769	0.0	-5.06	3.072	0.00	156.6
771	-0.2	-5.08	3.080	-0.04	157.2
773	0.4	-5.09	3.088	0.08	157.6
775	0.2	-5.10	3.096	0.04	157.8
777	0.0	-5.12	3.104	0.00	158.6
779	0.0	-5.13	3.112	0.00	158.8
781	-0.2	-5.15	3.120	-0.04	159.4
783	0.0	-5.16	3.128	0.00	159.8
785	0.0	-5.17	3.136	0.00	160.0
787	0.0	-5.19	3.144	0.00	160.6
789	0.2	-5.20	3.152	0.04	161.0
791	0.0	-5.22	3.160	0.00	161.6
793	0.0	-5.23	3.168	0.00	162.0
795	0.0	-5.24	3.176	0.00	162.2
797	0.0	-5.26	3.184	0.00	162.8
799	0.4	-5.27	3.192	0.08	163.2
801	0.0	-5.28	3.200	0.00	163.4
803	0.0	-5.30	3.208	0.00	164.0
805	-0.2	-5.31	3.216	-0.04	164.4
807	0.0	-5.33	3.224	0.00	165.0
809	0.0	-5.34	3.232	0.00	165.4
811	0.0	-5.35	3.240	0.00	165.6
813	0.0	-5.37	3.248	0.00	166.2
815	0.0	-5.38	3.256	0.00	166.6
817	0.0	-5.40	3.264	0.00	167.2
819	0.0	-5.41	3.272	0.00	167.4
821	0.0	-5.42	3.280	0.00	167.8
823	0.4	-5.44	3.288	0.08	168.4
825	0.0	-5.46	3.296	0.00	169.0
827	-0.2	-5.46	3.304	-0.04	169.0
829	0.0	-5.48	3.312	0.00	169.6
831	0.0	-5.49	3.320	0.00	170.0
833	0.0	-5.51	3.328	0.00	170.6
835	-0.2	-5.52	3.336	-0.04	170.8
837	0.2	-5.53	3.344	0.04	171.2
839	-0.2	-5.55	3.352	-0.04	171.8
841	0.0	-5.56	3.360	0.00	172.2
843	-0.4	-5.58	3.368	-0.08	172.8
845	0.0	-5.59	3.376	0.00	173.0
847	0.0	-5.60	3.384	0.00	173.4
849	0.0	-5.62	3.392	0.00	174.0
851	0.4	-5.64	3.400	0.08	174.6
853	-0.2	-5.65	3.408	-0.04	175.0
855	-0.2	-5.66	3.416	-0.04	175.2
857	0.0	-5.68	3.424	0.00	175.8
859	0.2	-5.69	3.432	0.04	176.2
861	0.0	-5.70	3.440	0.00	176.4
863	0.0	-5.72	3.448	0.00	177.0
865	-0.2	-5.73	3.456	-0.04	177.4
867	0.2	-5.74	3.464	0.04	177.8
869	0.2	-5.76	3.472	0.04	178.4
871	0.0	-5.76	3.480	0.00	178.4
873	0.0	-5.78	3.488	0.00	179.0
875	0.0	-5.79	3.496	0.00	179.2
877	-0.2	-5.80	3.504	-0.04	179.6
879	0.0	-5.82	3.512	0.00	180.2
881	0.2	-5.83	3.520	0.04	180.4
883	0.0	-5.85	3.528	0.00	181.2
885	0.2	-5.86	3.536	0.04	181.4
887	0.0	-5.87	3.544	0.00	181.8
889	-0.2	-5.89	3.552	-0.04	182.4
891	0.0	-5.90	3.560	0.00	182.6
893	-0.2	-5.92	3.568	-0.04	183.2
895	0.0	-5.94	3.576	0.00	184.0
897	0.0	-5.94	3.584	0.00	184.0
899	0.0	-5.96	3.592	0.00	184.6
901	0.0	-5.97	3.600	0.00	184.8
903	0.0	-5.98	3.608	0.00	185.2
905	0.0	-6.00	3.616	0.00	185.8
907	0.0	-6.01	3.624	0.00	186.0
909	0.0	-6.03	3.632	0.00	186.6
911	0.0	-6.04	3.640	0.00	187.0
913	-0.2	-6.05	3.648	-0.04	187.4
915	0.2	-6.07	3.656	0.04	188.0
917	0.0	-6.08	3.664	0.00	188.2
919	-0.2	-6.10	3.672	-0.04	188.8
921	-0.2	-6.11	3.680	-0.04	189.2
923	0.0	-6.12	3.688	0.00	189.4
925	0.0	-6.14	3.696	0.00	190.0
927	0.2	-6.15	3.704	0.04	190.4
929	0.0	-6.16	3.712	0.00	190.8
931	-0.2	-6.18	3.720	-0.04	191.4
933	0.0	-6.19	3.728	0.00	191.6
935	-0.2	-6.21	3.736	-0.04	192.2
937	0.0	-6.22	3.744	0.00	192.6
939	0.0	-6.23	3.752	0.00	192.8
941	0.0	-6.25	3.760	0.00	193.4
943	0.0	-6.26	3.768	0.00	193.8
945	0.2	-6.28	3.776	0.04	194.4
947	0.2	-6.30	3.784	0.04	195.0
949	0.0	-6.30	3.792	0.00	195.0
951	0.0	-6.32	3.800	0.00	195.6
953	0.0	-6.33	3.808	0.00	196.0
955	0.0	-6.35	3.816	0.00	196.6
957	0.0	-6.37	3.824	0.00	197.2
959	-0.2	-6.37	3.832	-0.04	197.2
961	0.2	-6.39	3.840	0.04	197.8
963	0.0	-6.40	3.848	0.00	198.2
965	0.0	-6.42	3.856	0.00	198.8
967	0.0	-6.43	3.864	0.00	199.0
969	0.0	-6.44	3.872	0.00	199.4
971	0.0	-6.46	3.880	0.00	200.0
973	0.0	-6.48	3.888	0.00	200.6
975	0.0	-6.49	3.896	0.00	201.0
977	0.2	-6.50	3.904	0.04	201.2
979	0.0	-6.51	3.912	0.00	201.6
981	0.0	-6.53	3.920	0.00	202.2
983	0.0	-6.54	3.928	0.00	202.4
985	0.0	-6.55	3.936	0.00	202.8
987	0.0	-6.57	3.944	0.00	203.4
989	0.0	-6.58	3.952	0.00	203.8
991	0.0	-6.60	3.960	0.00	204.4
993	0.0	-6.62	3.968	0.00	205.0
995	0.0	-6.62	3.976	0.00	205.0
997	0.0	-6.64	3.984	0.00	205.6
999	0.0	-6.65	3.992	0.00	205.8
1001	0.0	-6.67	4.000	0.00	206.6
1003	0.2	-6.68	4.008	0.04	206.8
1005	0.0	-6.69	4.016	0.00	207.2
1007	0.0	-6.71	4.024	0.00	207.8
1009	0.0	-6.72	4.032	0.00	208.0
1011	0.0	-6.73	4.040	0.00	208.4
1013	0.0	-6.75	4.048	0.00	209.0
1015	0.2	-6.77	4.056	0.04	209.6
1017	0.0	-6.79	4.064	0.00	210.2
1019	0.2	-6.80	4.072	0.04	210.6
1021	0.2	-6.81	4.080	0.04	210.8
1023	0.0	-6.83	4.088	0.00	211.4
1025	0.0	-6.84	4.096	0.00	211.8
1027	-0.2	-6.86	4.104	-0.04	212.4
1029	-0.2	-6.87	4.112	-0.04	212.6
1031	-0.2	-6.88	4.120	-0.04	213.0
1033	0.0	-6.90	4.128	0.00	213.6
1035	0.0	-6.91	4.136	0.00	214.0
1037	0.0	-6.94	4.144	0.00	214.8
1039	0.0	-6.94	4.152	0.00	214.8
1041	-0.2	-6.95	4.160	-0.04	215.2
1043	-0.4	-6.97	4.168	-0.08	215.8
1045	0.0	-6.98	4.176	0.00	216.0
1047	0.2	-6.99	4.184	0.04	216.4
1049	-0.2	-7.01	4.192	-0.04	217.0
1051	-0.2	-7.02	4.200	-0.04	217.4
1053	-0.2	-7.04	4.208	-0.04	218.0
1055	0.0	-7.05	4.216	0.00	218.2
1057	0.0	-7.07	4.224	0.00	218.8
1059	0.0	-7.08	4.232	0.00	219.2
1061	0.0	-7.09	4.240	0.00	219.6
1063	0.0	-7.11	4.248	0.00	220.2
1065	0.0	-7.12	4.256	0.00	220.4
1067	-0.2	-7.14	4.264	-0.04	221.0
1069	0.0	-7.15	4.272	0.00	221.4
1071	-0.2	-7.16	4.280	-0.04	221.6
1073	0.0	-7.18	4.288	0.00	222.2
1075	0.2	-7.19	4.296	0.04	222.6
1077	0.0	-7.20	4.304	0.00	223.0
1079	0.0	-7.22	4.312	0.00	223.6
1081	0.0	-7.23	4.320	0.00	223.8
1083	0.0	-7.25	4.328	0.00	224.4
1085	0.0	-7.26	4.336	0.00	224.8
1087	0.0	-7.28	4.344	0.00	225.4
1089	0.0	-7.29	4.352	0.00	225.6
1091	0.0	-7.30	4.360	0.00	226.0
1093	0.0	-7.32	4.368	0.00	226.6
1095	-0.2	-7.34	4.376	-0.04	227.2
1097	-0.2	-7.34	4.384	-0.04	227.2
1099	0.2	-7.36	4.392	0.04	227.8
1101	0.0	-7.37	4.400	0.00	228.2
1103	0.0	-7.38	4.408	0.00	228.4
1105	0.0	-7.40	4.416	0.00	229.2
1107	0.0	-7.41	4.424	0.00	229.4
1109	0.0	-7.44	4.432	0.00	230.4
1111	0.0	-7.44	4.440	0.00	230.4
1113	0.0	-7.46	4.448	0.00	231.0
1115	0.0	-7.47	4.456	0.00	231.2
1117	0.0	-7.48	4.464	0.00	231.6
1119	0.0	-7.50	4.472	0.00	232.2
1121	0.0	-7.51	4.480	0.00	232.6
1123	0.0	-7.52	4.488	0.00	232.8
1125	0.0	-7.54	4.496	0.00	233.4
1127	0.0	-7.55	4.504	0.00	233.8
1129	0.2	-7.57	4.512	0.04	234.4
1131	-0.4	-7.58	4.520	-0.08	234.6
1133	0.0	-7.59	4.528	0.00	235.0
1135	0.0	-7.61	4.536	0.00	235.6
1137	0.0	-7.62	4.544	0.00	236.0
1139	0.0	-7.64	4.552	0.00	236.6
1141	-0.2	-7.65	4.560	-0.04	236.8
1143	0.0	-7.66	4.568	0.00	237.2
1145	0.0	-7.68	4.576	0.00	237.8
1147	0.0	-7.69	4.584	0.00	238.0
1149	0.0	-7.71	4.592	0.00	238.6
1151	-0.4	-7.72	4.600	-0.08	239.0
1153	0.0	-7.73	4.608	0.00	239.4
1155	-0.2	-7.75	4.616	-0.04	240.0
1157	0.0	-7.76	4.624	0.00	240.2
1159	0.2	-7.78	4.632	0.04	240.8
1161	0.0	-7.80	4.640	0.00	241.4
1163	0.0	-7.80	4.648	0.00	241.4
1165	0.2	-7.82	4.656	0.04	242.2
1167	-0.2	-7.83	4.664	-0.04	242.4
1169	0.0	-7.85	4.672	0.00	243.0
1171	0.0	-7.87	4.680	0.00	243.6
1173	0.0	-7.87	4.688	0.00	243.6
1175	0.0	-7.89	4.696	0.00	244.2
1177	0.0	-7.90	4.704	0.00	244.6
1179	-0.2	-7.92	4.712	-0.04	245.2
1181	0.0	-7.93	4.720	0.00	245.6
1183	0.0	-7.94	4.728	0.00	245.8
1185	-0.4	-7.96	4.736	-0.08	246.4
1187	0.0	-7.98	4.744	0.00	247.0
1189	-0.2	-7.99	4.752	-0.04	247.4
1191	0.0	-8.00	4.760	0.00	247.6
1193	0.0	-8.01	4.768	0.00	248.0
1195	-0.2	-8.03	4.776	-0.04	248.6
1197	0.2	-8.04	4.784	0.04	249.0
1199	0.0	-8.06	4.792	0.00	249.6
1201	0.0	-8.07	4.800	0.00	249.8
1203	0.0	-8.08	4.808	0.00	250.2
1205	0.0	-8.10	4.816	0.00	250.8
1207	0.0	-8.12	4.824	0.00	251.4
1209	0.0	-8.13	4.832	0.00	251.8
1211	0.0	-8.14	4.840	0.00	252.0
1213	0.0	-8.16	4.848	0.00	252.6
1215	-0.2	-8.17	4.856	-0.04	253.0
1217	0.0	-8.18	4.864	0.00	253.2
1219	-0.2	-8.20	4.872	-0.04	253.8
1221	0.0	-8.21	4.880	0.00	254.2
1223	0.2	-8.23	4.888	0.04	254.8
1225	0.2	-8.24	4.896	0.04	255.2
1227	-0.2	-8.25	4.904	-0.04	255.4
1229	0.0	-8.27	4.912	0.00	256.0
1231	0.2	-8.28	4.920	0.04	256.4
1233	0.0	-8.30	4.928	0.00	257.0
1235	0.0	-8.31	4.936	0.00	257.2
1237	-0.2	-8.32	4.944	-0.04	257.6
1239	0.0	-8.34	4.952	0.00	258.2
1241	0.0	-8.35	4.960	0.00	258.6
1243	-0.4	-8.37	4.968	-0.08	259.2
1245	0.0	-8.38	4.976	0.00	259.4
1247	0.2	-8.39	4.984	0.04	259.8
1249	0.0	-8.41	4.992	0.00	260.4
1251	0.0	-8.42	5.000	0.00	260.6
1253	0.0	-8.44	5.008	0.00	261.4
1255	-0.4	-8.45	5.016	-0.08	261.6
1257	0.0	-8.46	5.024	0.00	262.0
1259	0.0	-8.48	5.032	0.00	262.6
1261	0.0	-8.49	5.040	0.00	262.8
1263	-0.2	-8.51	5.048	-0.04	263.4
1265	0.0	-8.52	5.056	0.00	263.8
1267	0.0	-8.54	5.064	0.00	264.4
1269	0.0	-8.55	5.072	0.00	264.8
1271	0.2	-8.56	5.080	0.04	265.0
1273	0.2	-8.58	5.088	0.04	265.6
1275	-0.2	-8.59	5.096	-0.04	266.0
1277	0.2	-8.62	5.104	0.04	266.8
1279	0.0	-8.62	5.112	0.00	266.8
1281	0.0	-8.64	5.120	0.00	267.4
1283	0.0	-8.65	5.128	0.00	267.8
1285	0.2	-8.66	5.136	0.04	268.2
1287	0.0	-8.68	5.144	0.00	268.8
1289	0.2	-8.69	5.152	0.04	269.0
1291	0.0	-8.70	5.160	0.00	269.4
1293	-0.2	-8.72	5.168	-0.04	270.0
1295	0.0	-8.73	5.176	0.00	270.2
1297	0.0	-8.75	5.184	0.00	270.8
1299	-0.2	-8.76	5.192	-0.04	271.2
1301	0.0	-8.77	5.200	0.00	271.6
1303	0.0	-8.79	5.208	0.00	272.2
1305	0.0	-8.80	5.216	0.00	272.4
1307	-0.2	-8.82	5.224	-0.04	273.0
1309	0.0	-8.83	5.232	0.00	273.4
1311	-0.2	-8.84	5.240	-0.04	273.6
1313	0.0	-8.86	5.248	0.00	274.4
1315	0.2	-8.87	5.256	0.04	274.6
1317	0.0	-8.89	5.264	0.00	275.2
1319	0.2	-8.90	5.272	0.04	275.6
1321	0.0	-8.92	5.280	0.00	276.2
1323	0.2	-8.93	5.288	0.04	276.4
1325	-0.4	-8.94	5.296	-0.08	276.8
1327	0.0	-8.96	5.304	0.00	277.4
1329	0.0	-8.97	5.312	0.00	277.8
1331	0.0	-8.99	5.320	0.00	278.4
1333	0.4	-9.00	5.328	0.08	278.6
1335	0.2	-9.01	5.336	0.04	279.0
1337	-0.2	-9.03	5.344	-0.04	279.6
1339	0.0	-9.04	5.352	0.00	279.8
1341	0.0	-9.06	5.360	0.00	280.4
1343	-0.4	-9.07	5.368	-0.08	280.8
1345	-0.2	-9.08	5.376	-0.04	281.2
1347	-0.2	-9.10	5.384	-0.04	281.8
1349	0.0	-9.11	5.392	0.00	282.0
1351	0.0	-9.13	5.400	0.00	282.6
1353	-0.2	-9.14	5.408	-0.04	283.0
1355	0.0	-9.15	5.416	0.00	283.2
1357	0.0	-9.17	5.424	0.00	284.0
1359	0.0	-9.18	5.432	0.00	284.2
1361	0.0	-9.20	5.440	0.00	284.8
1363	0.0	-9.21	5.448	0.00	285.2
1365	0.2	-9.23	5.456	0.04	285.8
1367	0.0	-9.24	5.464	0.00	286.0
1369	0.0	-9.25	5.472	0.00	286.4
1371	0.0	-9.27	5.480	0.00	287.0
1373	0.0	-9.28	5.488	0.00	287.4
1375	0.0	-9.30	5.496	0.00	288.0
1377	0.0	-9.31	5.504	0.00	288.2
1379	0.0	-9.32	5.512	0.00	288.6
1381	0.0	-9.34	5.520	0.00	289.2
1383	-0.2	-9.35	5.528	-0.04	289.4
1385	0.0	-9.37	5.536	0.00	290.0
1387	0.2	-9.38	5.544	0.04	290.4
1389	0.0	-9.40	5.552	0.00	291.0
1391	0.0	-9.41	5.560	0.00	291.4
1393	0.2	-9.42	5.568	0.04	291.6
1395	0.2	-9.44	5.576	0.04	292.2
1397	0.2	-9.45	5.584	0.04	292.6
1399	0.0	-9.48	5.592	0.00	293.4
1401	0.2	-9.48	5.600	0.04	293.4
1403	0.2	-9.49	5.608	0.04	293.8
1405	0.0	-9.51	5.616	0.00	294.4
1407	0.0	-9.52	5.624	0.00	294.8
1409	-0.2	-9.54	5.632	-0.04	295.4
1411	-0.2	-9.55	5.640	-0.04	295.6
1413	-0.2	-9.56	5.648	-0.04	296.0
1415	-0.2	-9.58	5.656	-0.04	296.6
1417	-0.2	-9.59	5.664	-0.04	297.0
1419	0.0	-9.61	5.672	0.00	297.6
1421	0.0	-9.62	5.680	0.00	297.8
1423	0.0	-9.64	5.688	0.00	298.4
1425	0.2	-9.65	5.696	0.04	298.8
1427	0.0	-9.66	5.704	0.00	299.0
1429	-0.2	-9.68	5.712	-0.04	299.6
1431	0.0	-9.69	5.720	0.00	300.0
1433	-0.2	-9.71	5.728	-0.04	300.6
1435	0.0	-9.72	5.736	0.00	301.0
1437	-0.2	-9.73	5.744	-0.04	301.2
1439	-0.4	-9.75	5.752	-0.08	301.8
1441	0.0	-9.76	5.760	0.00	302.2
1443	0.0	-9.77	5.768	0.00	302.4
1445	0.0	-9.78	5.776	0.00	302.8
1447	0.0	-9.79	5.784	0.00	303.0
1449	0.2	-9.81	5.792	0.04	303.8
1451	-0.2	-9.82	5.800	-0.04	304.0
1453	0.0	-9.84	5.808	0.00	304.6
1455	-0.4	-9.85	5.816	-0.08	305.0
1457	-0.2	-9.86	5.824	-0.04	305.2
1459	0.2	-9.88	5.832	0.04	305.8
1461	0.0	-9.89	5.840	0.00	306.2
1463	0.2	-9.91	5.848	0.04	306.8
1465	0.0	-9.92	5.856	0.00	307.2
1467	-0.2	-9.93	5.864	-0.04	307.4
1469	0.0	-9.95	5.872	0.00	308.0
1471	0.0	-9.96	5.880	0.00	308.4
1473	0.0	-9.98	5.888	0.00	309.0
1475	0.0	-9.99	5.896	0.00	309.2
1477	-0.2	-10.00	5.904	-0.04	309.6
1479	0.0	-10.02	5.912	0.00	310.2
1481	0.0	-10.03	5.920	0.00	310.6
1483	0.0	-10.05	5.928	0.00	311.2
1485	0.2	-10.06	5.936	0.04	311.4
1487	0.0	-10.08	5.944	0.00	312.0
1489	0.0	-10.09	5.952	0.00	312.4
1491	0.0	-10.10	5.960	0.00	312.6
1493	-0.4	-10.12	5.968	-0.08	313.4
1495	0.0	-10.13	5.976	0.00	313.6
1497	0.0	-10.14	5.984	0.00	314.0
1499	0.0	-10.16	5.992	0.00	314.6
1501	0.0	-10.17	6.000	0.00	314.8
1503	-0.2	-10.19	6.008	-0.04	315.4
1505	0.0	-10.20	6.016	0.00	315.8
1507	0.2	-10.21	6.024	0.04	316.0
1509	0.0	-10.23	6.032	0.00	316.8
1511	0.0	-10.24	6.040	0.00	317.0
1513	0.0	-10.26	6.048	0.00	317.6
1515	0.0	-10.27	6.056	0.00	318.0
1517	-0.2	-10.28	6.064	-0.04	318.2
1519	0.0	-10.30	6.072	0.00	318.8
1521	0.0	-10.32	6.080	0.00	319.6
1523	0.0	-10.33	6.088	0.00	319.8
1525	-0.2	-10.34	6.096	-0.04	320.2
1527	0.0	-10.35	6.104	0.00	320.4
1529	0.0	-10.37	6.112	0.00	321.0
1531	0.0	-10.38	6.120	0.00	321.4
1533	0.0	-10.40	6.128	0.00	322.0
1535	0.0	-10.42	6.136	0.00	322.6
1537	0.0	-10.42	6.144	0.00	322.6
1539	0.0	-10.44	6.152	0.00	323.2
1541	-0.2	-10.45	6.160	-0.04	323.6
1543	0.0	-10.47	6.168	0.00	324.2
1545	-0.2	-10.48	6.176	-0.04	324.4
1547	-0.2	-10.49	6.184	-0.04	324.8
1549	0.0	-10.51	6.192	0.00	325.4
1551	0.0	-10.52	6.200	0.00	325.6
1553	0.0	-10.54	6.208	0.00	326.4
1555	-0.2	-10.55	6.216	-0.04	326.6
1557	0.2	-10.56	6.224	0.04	327.0
1559	0.0	-10.58	6.232	0.00	327.6
1561	0.0	-10.59	6.240	0.00	327.8
1563	0.0	-10.61	6.248	0.00	328.4
1565	0.0	-10.62	6.256	0.00	328.8
1567	0.0	-10.63	6.264	0.00	329.2
1569	0.2	-10.66	6.272	0.04	330.0
1571	0.0	-10.66	6.280	0.00	330.0
1573	0.0	-10.68	6.288	0.00	330.6
1575	0.0	-10.69	6.296	0.00	331.0
1577	0.0	-10.70	6.304	0.00	331.2
1579	0.0	-10.72	6.312	0.00	331.8
1581	0.0	-10.74	6.320	0.00	332.6
1583	0.0	-10.74	6.328	0.00	332.6
1585	0.0	-10.76	6.336	0.00	333.2
1587	0.0	-10.77	6.344	0.00	333.4
1589	0.0	-10.79	6.352	0.00	334.0
1591	0.0	-10.80	6.360	0.00	334.4
1593	0.0	-10.81	6.368	0.00	334.6
1595	0.0	-10.83	6.376	0.00	335.2
1597	0.0	-10.84	6.384	0.00	335.6
1599	0.0	-10.86	6.392	0.00	336.2
1601	-0.2	-10.87	6.400	-0.04	336.6
1603	0.0	-10.88	6.408	0.00	336.8
1605	0.0	-10.90	6.416	0.00	337.4
1607	0.0	-10.91	6.424	0.00	337.8
1609	-0.2	-10.93	6.432	-0.04	338.4
1611	0.0	-10.94	6.440	0.00	338.6
1613	0.0	-10.95	6.448	0.00	339.0
1615	-0.2	-10.98	6.456	-0.04	340.0
1617	0.0	-10.98	6.464	0.00	340.0
1619	-0.2	-11.00	6.472	-0.04	340.6
1621	0.2	-11.01	6.480	0.04	340.8
1623	-0.4	-11.02	6.488	-0.08	341.2
1625	0.0	-11.04	6.496	0.00	341.8
1627	0.0	-11.05	6.504	0.00	342.2
1629	0.2	-11.08	6.512	0.04	343.0
1631	0.2	-11.08	6.520	0.04	343.0
1633	-0.2	-11.09	6.528	-0.04	343.4
1635	0.0	-11.11	6.536	0.00	344.0
1637	0.0	-11.12	6.544	0.00	344.2
1639	0.0	-11.14	6.552	0.00	344.8
1641	0.0	-11.16	6.560	0.00	345.6
1643	0.2	-11.16	6.568	0.04	345.6
1645	0.0	-11.18	6.576	0.00	346.2
1647	-0.2	-11.19	6.584	-0.04	346.4
1649	0.0	-11.21	6.592	0.00	347.0
1651	0.0	-11.22	6.600	0.00	347.4
1653	0.0	-11.23	6.608	0.00	347.6
1655	-0.2	-11.25	6.616	-0.04	348.2
1657	-0.4	-11.26	6.624	-0.08	348.6
1659	0.0	-11.27	6.632	0.00	349.0
1661	-0.4	-11.29	6.640	-0.08	349.6
1663	0.0	-11.30	6.648	0.00	349.8
1665	-0.2	-11.32	6.656	-0.04	350.4
1667	0.0	-11.33	6.664	0.00	350.8
1669	0.0	-11.34	6.672	0.00	351.0
1671	0.0	-11.36	6.680	0.00	351.8
1673	0.0	-11.37	6.688	0.00	352.0
1675	-0.2	-11.40	6.696	-0.04	353.0
1677	0.0	-11.40	6.704	0.00	353.0
1679	0.2	-11.41	6.712	0.04	353.2
1681	0.2	-11.43	6.720	0.04	353.8
1683	0.0	-11.44	6.728	0.00	354.2
1685	0.0	-11.45	6.736	0.00	354.4
1687	0.0	-11.47	6.744	0.00	355.2
1689	0.0	-11.48	6.752	0.00	355.4
1691	0.0	-11.50	6.760	0.00	356.0
1693	0.0	-11.51	6.768	0.00	356.4
1695	0.0	-11.52	6.776	0.00	356.6
1697	0.0	-11.54	6.784	0.00	357.2
1699	0.2	-11.55	6.792	0.04	357.6
1701	0.0	-11.58	6.800	0.00	358.6
1703	-0.2	-11.58	6.808	-0.04	358.6
1705	0.0	-11.59	6.816	0.00	358.8
1707	-0.2	-11.61	6.824	-0.04	359.4
1709	0.0	-11.62	6.832	0.00	359.8
1711	-0.2	-11.64	6.840	-0.04	360.4
1713	0.2	-11.65	6.848	0.04	360.6
1715	0.0	-11.66	6.856	0.00	361.0
1717	0.0	-11.68	6.864	0.00	361.6
1719	-0.2	-11.69	6.872	-0.04	362.0
1721	0.2	-11.71	6.880	0.04	362.6
1723	0.0	-11.72	6.888	0.00	362.8
1725	0.0	-11.74	6.896	0.00	363.4
1727	0.2	-11.75	6.904	0.04	363.8
1729	0.0	-11.77	6.912	0.00	364.4
1731	0.0	-11.79	6.920	0.00	365.0
1733	0.0	-11.80	6.928	0.00	365.4
1735	0.0	-11.82	6.936	0.00	366.0
1737	0.0	-11.83	6.944	0.00	366.2
1739	0.2	-11.84	6.952	0.04	366.6
1741	0.0	-11.86	6.960	0.00	367.2
1743	0.2	-11.87	6.968	0.04	367.4
1745	0.0	-11.88	6.976	0.00	367.8
1747	0.2	-11.90	6.984	0.04	368.4
1749	-0.2	-11.92	6.992	-0.04	369.0
1751	0.0	-11.92	7.000	0.00	369.0
1753	0.2	-11.94	7.008	0.04	369.6
1755	0.0	-11.95	7.016	0.00	370.0
1757	0.0	-11.97	7.024	0.00	370.6
1759	0.2	-11.98	7.032	0.04	370.8
1761	-0.2	-11.99	7.040	-0.04	371.2
1763	-0.2	-12.01	7.048	-0.04	371.8
1765	-0.2	-12.02	7.056	-0.04	372.2
1767	0.2	-12.04	7.064	0.04	372.8
1769	-0.2	-12.05	7.072	-0.04	373.0
1771	0.0	-12.06	7.080	0.00	373.4
1773	0.0	-12.08	7.088	0.00	374.0
1775	0.0	-12.09	7.096	0.00	374.4
1777	0.0	-12.11	7.104	0.00	375.0
1779	0.2	-12.12	7.112	0.04	375.2
1781	0.2	-12.13	7.120	0.04	375.6
1783	0.0	-12.15	7.128	0.00	376.2
1785	-0.2	-12.16	7.136	-0.04	376.4
1787	0.0	-12.17	7.144	0.00	376.8
1789	0.0	-12.19	7.152	0.00	377.4
1791	-0.2	-12.20	7.160	-0.04	377.8
1793	-0.2	-12.22	7.168	-0.04	378.4
1795	0.0	-12.24	7.176	0.00	379.0
1797	-0.2	-12.24	7.184	-0.04	379.0
1799	-0.2	-12.26	7.192	-0.04	379.6
1801	0.2	-12.27	7.200	0.04	379.8
1803	0.0	-12.29	7.208	0.00	380.4
1805	0.0	-12.30	7.216	0.00	380.8
1807	0.0	-12.31	7.224	0.00	381.2
1809	0.0	-12.33	7.232	0.00	381.8
1811	0.0	-12.34	7.240	0.00	382.0
1813	-0.2	-12.36	7.248	-0.04	382.6
1815	0.0	-12.37	7.256	0.00	383.0
1817	0.2	-12.40	7.264	0.04	384.0
1819	0.0	-12.40	7.272	0.00	384.0
1821	-0.2	-12.41	7.280	-0.04	384.2
1823	-0.2	-12.43	7.288	-0.04	384.8
1825	0.0	-12.44	7.296	0.00	385.2
1827	0.0	-12.45	7.304	0.00	385.4
1829	0.2	-12.47	7.312	0.04	386.0
1831	0.0	-12.48	7.320	0.00	386.4
1833	0.0	-12.50	7.328	0.00	387.0
1835	0.0	-12.51	7.336	0.00	387.4
1837	0.0	-12.52	7.344	0.00	387.6
1839	0.0	-12.54	7.352	0.00	388.2
1841	-0.2	-12.55	7.360	-0.04	388.6
1843	0.0	-12.57	7.368	0.00	389.2
1845	0.0	-12.58	7.376	0.00	389.4
1847	0.0	-12.59	7.384	0.00	389.8
1849	0.0	-12.61	7.392	0.00	390.4
1851	0.0	-12.62	7.400	0.00	390.8
1853	0.2	-12.64	7.408	0.04	391.4
1855	0.2	-12.66	7.416	0.04	392.0
1857	0.2	-12.66	7.424	0.04	392.0
1859	0.0	-12.68	7.432	0.00	392.6
1861	-0.2	-12.69	7.440	-0.04	392.8
1863	0.0	-12.70	7.448	0.00	393.2
1865	0.2	-12.72	7.456	0.04	393.8
1867	0.0	-12.73	7.464	0.00	394.2
1869	0.0	-12.75	7.472	0.00	394.8
1871	0.0	-12.76	7.480	0.00	395.0
1873	-0.2	-12.77	7.488	-0.04	395.4
1875	0.0	-12.79	7.496	0.00	396.0
1877	0.0	-12.80	7.504	0.00	396.2
1879	-0.2	-12.82	7.512	-0.04	397.0
1881	-0.2	-12.83	7.520	-0.04	397.2
1883	0.0	-12.85	7.528	0.00	397.8
1885	0.0	-12.86	7.536	0.00	398.2
1887	0.0	-12.87	7.544	0.00	398.4
1889	0.0	-12.90	7.552	0.00	399.4
1891	0.0	-12.90	7.560	0.00	399.4
1893	-0.4	-12.92	7.568	-0.08	400.0
1895	0.2	-12.93	7.576	0.04	400.4
1897	-0.4	-12.94	7.584	-0.08	400.6
1899	0.2	-12.96	7.592	0.04	401.2
1901	0.2	-12.98	7.600	0.04	401.8
1903	0.0	-12.99	7.608	0.00	402.2
1905	0.2	-13.00	7.616	0.04	402.4
1907	0.0	-13.02	7.624	0.00	403.0
1909	0.0	-13.03	7.632	0.00	403.4
1911	0.0	-13.04	7.640	0.00	403.8
1913	0.0	-13.06	7.648	0.00	404.4
1915	-0.2	-13.08	7.656	-0.04	405.0
1917	0.0	-13.08	7.664	0.00	405.0
1919	-0.2	-13.10	7.672	-0.04	405.6
1921	0.0	-13.12	7.680	0.00	406.2
1923	0.0	-13.13	7.688	0.00	406.6
1925	0.0	-13.14	7.696	0.00	406.8
1927	-0.2	-13.16	7.704	-0.04	407.4
1929	-0.4	-13.17	7.712	-0.08	407.8
1931	0.0	-13.18	7.720	0.00	408.0
1933	0.0	-13.20	7.728	0.00	408.6
1935	0.4	-13.21	7.736	0.08	409.0
1937	0.0	-13.22	7.744	0.00	409.2
1939	0.0	-13.24	7.752	0.00	410.0
1941	0.0	-13.25	7.760	0.00	410.2
1943	0.0	-13.27	7.768	0.00	410.8
1945	-0.4	-13.28	7.776	-0.08	411.2
1947	0.0	-13.30	7.784	0.00	411.8
1949	0.0	-13.32	7.792	0.00	412.4
1951	0.0	-13.32	7.800	0.00	412.4
1953	0.2	-13.34	7.808	0.04	413.0
1955	0.0	-13.35	7.816	0.00	413.4
1957	-0.2	-13.37	7.824	-0.04	414.0
1959	-0.2	-13.38	7.832	-0.04	414.2
1961	0.0	-13.39	7.840	0.00	414.6
1963	0.0	-13.42	7.848	0.00	415.4
1965	-0.2	-13.42	7.856	-0.04	415.4
1967	0.0	-13.44	7.864	0.00	416.0
1969	0.2	-13.45	7.872	0.04	416.4
1971	0.0	-13.46	7.880	0.00	416.8
1973	0.0	-13.48	7.888	0.00	417.4
1975	0.0	-13.50	7.896	0.00	418.0
1977	0.0	-13.51	7.904	0.00	418.2
1979	0.0	-13.52	7.912	0.00	418.6
1981	-0.2	-13.53	7.920	-0.04	418.8
1983	-0.2	-13.55	7.928	-0.04	419.6
1985	0.0	-13.56	7.936	0.00	419.8
1987	0.0	-13.58	7.944	0.00	420.4
1989	0.0	-13.59	7.952	0.00	420.8
1991	0.0	-13.61	7.960	0.00	421.4
1993	0.2	-13.62	7.968	0.04	421.6
1995	0.0	-13.63	7.976	0.00	422.0
1997	0.2	-13.66	7.984	0.04	423.0
1999	0.2	-13.66	7.992	0.04	423.0
2001	0.0	-13.68	8.000	0.00	423.6
2003	0.0	-13.69	8.008	0.00	423.8
2005	-0.2	-13.71	8.016	-0.04	424.4
2007	-0.2	-13.72	8.024	-0.04	424.8
2009	-0.2	-13.74	8.032	-0.04	425.4
2011	0.0	-13.75	8.040	0.00	425.6
2013	0.0	-13.76	8.048	0.00	426.0
2015	0.0	-13.78	8.056	0.00	426.6
2017	0.0	-13.79	8.064	0.00	427.0
2019	-0.2	-13.80	8.072	-0.04	427.2
2021	-0.2	-13.82	8.080	-0.04	427.8
2023	0.0	-13.83	8.088	0.00	428.2
2025	0.0	-13.85	8.096	0.00	428.8
2027	0.0	-13.86	8.104	0.00	429.2
2029	0.0	-13.87	8.112	0.00	429.4
2031	-0.2	-13.90	8.120	-0.04	430.4
2033	0.0	-13.90	8.128	0.00	430.4
2035	0.0	-13.92	8.136	0.00	431.0
2037	0.0	-13.93	8.144	0.00	431.2
2039	0.0	-13.94	8.152	0.00	431.6
2041	0.0	-13.96	8.160	0.00	432.2
2043	0.2	-13.97	8.168	0.04	432.6
2045	0.0	-14.00	8.176	0.00	433.4
2047	0.0	-14.00	8.184	0.00	433.4
2049	0.0	-14.02	8.192	0.00	434.0
2051	0.0	-14.03	8.200	0.00	434.4
2053	0.0	-14.04	8.208	0.00	434.6
2055	0.2	-14.06	8.216	0.04	435.2
2057	-0.2	-14.07	8.224	-0.04	435.6
2059	0.2	-14.10	8.232	0.04	436.6
2061	0.2	-14.10	8.240	0.04	436.6
2063	0.0	-14.11	8.248	0.00	436.8
2065	0.0	-14.13	8.256	0.00	437.4
2067	-0.2	-14.14	8.264	-0.04	437.8
2069	-0.2	-14.16	8.272	-0.04	438.4
2071	0.0	-14.17	8.280	0.00	438.6
2073	-0.2	-14.18	8.288	-0.04	439.0
2075	0.0	-14.20	8.296	0.00	439.6
2077	-0.2	-14.21	8.304	-0.04	440.0
2079	0.0	-14.23	8.312	0.00	440.6
2081	0.0	-14.24	8.320	0.00	440.8
2083	-0.2	-14.25	8.328	-0.04	441.2
2085	-0.2	-14.27	8.336	-0.04	441.8
2087	-0.2	-14.28	8.344	-0.04	442.2
2089	-0.2	-14.30	8.352	-0.04	442.8
2091	0.0	-14.31	8.360	0.00	443.0
2093	0.4	-14.32	8.368	0.08	443.4
2095	0.0	-14.34	8.376	0.00	444.0
2097	0.0	-14.35	8.384	0.00	444.2
2099	0.0	-14.37	8.392	0.00	444.8
2101	-0.2	-14.38	8.400	-0.04	445.2
2103	0.0	-14.40	8.408	0.00	445.8
2105	0.0	-14.41	8.416	0.00	446.2
2107	-0.2	-14.42	8.424	-0.04	446.4
2109	0.0	-14.44	8.432	0.00	447.0
2111	-0.4	-14.45	8.440	-0.08	447.4
2113	0.0	-14.48	8.448	0.00	448.2
2115	0.0	-14.48	8.456	0.00	448.2
2117	0.0	-14.50	8.464	0.00	449.0
2119	0.0	-14.51	8.472	0.00	449.2
2121	0.2	-14.52	8.480	0.04	449.6
2123	0.2	-14.54	8.488	0.04	450.2
2125	0.2	-14.55	8.496	0.04	450.4
2127	0.0	-14.56	8.504	0.00	450.8
2129	0.0	-14.58	8.512	0.00	451.4
2131	0.0	-14.59	8.520	0.00	451.8
2133	0.0	-14.61	8.528	0.00	452.4
2135	0.0	-14.62	8.536	0.00	452.6
2137	0.0	-14.63	8.544	0.00	453.0
2139	0.0	-14.65	8.552	0.00	453.6
2141	0.2	-14.66	8.560	0.04	453.8
2143	0.0	-14.68	8.568	0.00	454.4
2145	0.0	-14.69	8.576	0.00	454.8
2147	0.2	-14.71	8.584	0.04	455.4
2149	0.0	-14.72	8.592	0.00	455.8
2151	-0.2	-14.74	8.600	-0.04	456.4
2153	0.2	-14.75	8.608	0.04	456.6
2155	0.0	-14.76	8.616	0.00	457.0
2157	0.2	-14.77	8.624	0.04	457.2
2159	0.0	-14.78	8.632	0.00	457.6
2161	0.0	-14.79	8.640	0.00	457.8
2163	0.0	-14.82	8.648	0.00	458.8
2165	0.0	-14.82	8.656	0.00	458.8
2167	-0.2	-14.84	8.664	-0.04	459.4
2169	0.0	-14.85	8.672	0.00	459.8
2171	0.0	-14.86	8.680	0.00	460.0
2173	0.0	-14.88	8.688	0.00	460.6
2175	0.0	-14.89	8.696	0.00	461.0
2177	0.2	-14.91	8.704	0.04	461.6
2179	0.2	-14.92	8.712	0.04	462.0
2181	0.0	-14.94	8.720	0.00	462.6
2183	0.0	-14.95	8.728	0.00	462.8
2185	0.0	-14.96	8.736	0.00	463.2
2187	-0.2	-14.98	8.744	-0.04	463.8
2189	0.0	-15.00	8.752	0.00	464.4
2191	-0.2	-15.00	8.760	-0.04	464.4
2193	0.0	-15.02	8.768	0.00	465.0
2195	0.0	-15.04	8.776	0.00	465.6
2197	0.0	-15.05	8.784	0.00	466.0
2199	0.0	-15.06	8.792	0.00	466.2
2201	0.0	-15.08	8.800	0.00	466.8
2203	0.2	-15.09	8.808	0.04	467.2
2205	0.2	-15.10	8.816	0.04	467.4
2207	0.2	-15.12	8.824	0.04	468.2
2209	-0.2	-15.14	8.832	-0.04	468.8
2211	0.2	-15.15	8.840	0.04	469.0
2213	0.0	-15.16	8.848	0.00	469.4
2215	0.0	-15.17	8.856	0.00	469.6
2217	0.2	-15.19	8.864	0.04	470.2
2219	0.0	-15.20	8.872	0.00	470.6
2221	0.0	-15.22	8.880	0.00	471.2
2223	0.0	-15.24	8.888	0.00	471.8
2225	0.4	-15.24	8.896	0.08	471.8
2227	-0.2	-15.26	8.904	-0.04	472.4
2229	0.2	-15.27	8.912	0.04	472.8
2231	-0.2	-15.29	8.920	-0.04	473.4
2233	-0.2	-15.30	8.928	-0.04	473.6
2235	0.0	-15.31	8.936	0.00	474.0
2237	0.0	-15.33	8.944	0.00	474.6
2239	0.0	-15.34	8.952	0.00	475.0
2241	0.0	-15.36	8.960	0.00	475.6
2243	0.0	-15.37	8.968	0.00	475.8
2245	0.0	-15.38	8.976	0.00	476.2
2247	0.2	-15.40	8.984	0.04	476.8
2249	0.0	-15.41	8.992	0.00	477.0
2251	0.0	-15.42	9.000	0.00	477.4
2253	0.0	-15.44	9.008	0.00	478.0
2255	0.0	-15.45	9.016	0.00	478.4
2257	0.2	-15.48	9.024	0.04	479.2
2259	0.0	-15.48	9.032	0.00	479.2
2261	0.0	-15.49	9.040	0.00	479.6
2263	-0.2	-15.51	9.048	-0.04	480.2
2265	0.0	-15.52	9.056	0.00	480.4
2267	0.0	-15.54	9.064	0.00	481.2
2269	0.2	-15.55	9.072	0.04	481.4
2271	0.6	-15.56	9.080	0.12	481.8
2273	0.2	-15.58	9.088	0.04	482.4
2275	0.0	-15.59	9.096	0.00	482.6
2277	0.0	-15.61	9.104	0.00	483.2
2279	0.2	-15.62	9.112	0.04	483.6
2281	0.4	-15.63	9.120	0.08	484.0
2283	0.0	-15.66	9.128	0.00	484.8
2285	0.2	-15.66	9.136	0.04	484.8
2287	0.0	-15.68	9.144	0.00	485.4
2289	0.0	-15.69	9.152	0.00	485.8
2291	0.0	-15.70	9.160	0.00	486.0
2293	0.2	-15.72	9.168	0.04	486.6
2295	0.0	-15.73	9.176	0.00	487.0
2297	0.2	-15.75	9.184	0.04	487.6
2299	0.0	-15.76	9.192	0.00	488.0
2301	0.6	-15.77	9.200	0.12	488.2
2303	0.2	-15.79	9.208	0.04	488.8
2305	0.0	-15.80	9.216	0.00	489.2
2307	0.0	-15.82	9.224	0.00	489.8
2309	0.0	-15.83	9.232	0.00	490.0
2311	0.0	-15.84	9.240	0.00	490.4
2313	0.0	-15.86	9.248	0.00	491.0
2315	0.0	-15.88	9.256	0.00	491.6
2317	-0.2	-15.88	9.264	-0.04	491.6
2319	0.0	-15.90	9.272	0.00	492.2
2321	0.0	-15.92	9.280	0.00	492.8
2323	0.2	-15.93	9.288	0.04	493.2
2325	0.0	-15.94	9.296	0.00	493.4
2327	-0.2	-15.95	9.304	-0.04	493.8
2329	0.2	-15.98	9.312	0.04	494.8
2331	0.0	-15.98	9.320	0.00	494.8
2333	0.0	-16.00	9.328	0.00	495.4
2335	0.4	-16.02	9.336	0.08	496.0
2337	-0.2	-16.02	9.344	-0.04	496.0
2339	0.0	-16.04	9.352	0.00	496.6
2341	0.2	-16.05	9.360	0.04	497.0
2343	0.2	-16.06	9.368	0.04	497.2
2345	-0.2	-16.08	9.376	-0.04	497.8
2347	0.2	-16.09	9.384	0.04	498.2
2349	0.0	-16.11	9.392	0.00	498.8
2351	-0.2	-16.12	9.400	-0.04	499.0
2353	0.0	-16.13	9.408	0.00	499.4
2355	0.0	-16.15	9.416	0.00	500.0
2357	0.0	-16.16	9.424	0.00	500.4
2359	0.0	-16.18	9.432	0.00	501.0
2361	0.2	-16.19	9.440	0.04	501.2
2363	-0.2	-16.20	9.448	-0.04	501.6
2365	-0.2	-16.22	9.456	-0.04	502.2
2367	-0.2	-16.23	9.464	-0.04	502.4
2369	0.0	-16.24	9.472	0.00	502.8
2371	0.0	-16.26	9.480	0.00	503.4
2373	0.0	-16.27	9.488	0.00	503.8
2375	0.0	-16.29	9.496	0.00	504.4
2377	-0.2	-16.30	9.504	-0.04	504.6
2379	-0.2	-16.31	9.512	-0.04	505.0
2381	0.0	-16.33	9.520	0.00	505.6
2383	0.2	-16.34	9.528	0.04	505.8
2385	0.2	-16.36	9.536	0.04	506.6
2387	0.0	-16.37	9.544	0.00	506.8
2389	-0.2	-16.38	9.552	-0.04	507.2
2391	0.0	-16.40	9.560	0.00	507.8
2393	-0.2	-16.41	9.568	-0.04	508.0
2395	0.0	-16.43	9.576	0.00	508.6
2397	0.0	-16.44	9.584	0.00	509.0
2399	0.0	-16.45	9.592	0.00	509.2
2401	0.0	-16.47	9.600	0.00	510.0
2403	0.0	-16.48	9.608	0.00	510.2
2405	0.0	-16.50	9.616	0.00	510.8
2407	0.4	-16.52	9.624	0.08	511.4
2409	0.0	-16.52	9.632	0.00	511.4
2411	0.0	-16.54	9.640	0.00	512.0
2413	-0.2	-16.55	9.648	-0.04	512.4
2415	0.0	-16.58	9.656	0.00	513.4
2417	0.0	-16.58	9.664	0.00	513.4
2419	0.0	-16.59	9.672	0.00	513.6
2421	0.0	-16.61	9.680	0.00	514.2
2423	-0.2	-16.62	9.688	-0.04	514.6
2425	0.2	-16.63	9.696	0.04	514.8
2427	0.0	-16.66	9.704	0.00	515.8
2429	0.0	-16.66	9.712	0.00	515.8
2431	0.0	-16.68	9.720	0.00	516.4
2433	0.0	-16.69	9.728	0.00	516.8
2435	0.0	-16.70	9.736	0.00	517.0
2437	-0.2	-16.72	9.744	-0.04	517.6
2439	0.0	-16.74	9.752	0.00	518.2
2441	0.0	-16.75	9.760	0.00	518.6
2443	0.0	-16.76	9.768	0.00	518.8
2445	0.0	-16.78	9.776	0.00	519.6
2447	-0.2	-16.80	9.784	-0.04	520.2
2449	0.0	-16.81	9.792	0.00	520.4
2451	-0.2	-16.82	9.800	-0.04	520.8
2453	0.0	-16.84	9.808	0.00	521.4
2455	0.0	-16.86	9.816	0.00	522.0
2457	0.2	-16.87	9.824	0.04	522.2
2459	0.2	-16.88	9.832	0.04	522.6
2461	-0.2	-16.90	9.840	-0.04	523.2
2463	-0.2	-16.91	9.848	-0.04	523.6
2465	0.0	-16.92	9.856	0.00	523.8
2467	0.0	-16.94	9.864	0.00	524.4
2469	0.0	-16.95	9.872	0.00	524.8
2471	0.0	-16.96	9.880	0.00	525.0
2473	0.0	-16.98	9.888	0.00	525.6
2475	0.0	-17.00	9.896	0.00	526.4
2477	-0.2	-17.01	9.904	-0.04	526.6
2479	0.0	-17.02	9.912	0.00	527.0
2481	0.0	-17.03	9.920	0.00	527.2
2483	0.0	-17.06	9.928	0.00	528.2
2485	0.2	-17.06	9.936	0.04	528.2
2487	0.0	-17.08	9.944	0.00	528.8
2489	0.0	-17.09	9.952	0.00	529.2
2491	0.0	-17.10	9.960	0.00	529.4
2493	0.0	-17.12	9.968	0.00	530.0
2495	0.0	-17.13	9.976	0.00	530.4
2497	0.0	-17.15	9.984	0.00	531.0
2499	0.2	-17.16	9.992	0.04	531.2
2501	0.0	-17.17	10.000	0.00	531.6
2503	0.0	-17.19	10.008	0.00	532.2
2505	0.0	-17.20	10.016	0.00	532.6
2507	0.2	-17.22	10.024	0.04	533.2
2509	-0.2	-17.24	10.032	-0.04	533.8
2511	-0.2	-17.24	10.040	-0.04	533.8
2513	0.2	-17.26	10.048	0.04	534.4
2515	0.0	-17.27	10.056	0.00	534.6
2517	0.0	-17.28	10.064	0.00	535.0
2519	0.0	-17.30	10.072	0.00	535.6
2521	0.0	-17.31	10.080	0.00	536.0
2523	0.0	-17.33	10.088	0.00	536.6
2525	0.0	-17.34	10.096	0.00	536.8
2527	0.2	-17.36	10.104	0.04	537.4
2529	0.0	-17.37	10.112	0.00	537.8
2531	0.0	-17.38	10.120	0.00	538.0
2533	0.0	-17.40	10.128	0.00	538.6
2535	0.0	-17.41	10.136	0.00	539.0
2537	0.2	-17.42	10.144	0.04	539.4
2539	0.0	-17.44	10.152	0.00	540.0
2541	0.0	-17.45	10.160	0.00	540.2
2543	-0.2	-17.47	10.168	-0.04	540.8
2545	-0.2	-17.48	10.176	-0.04	541.2
2547	-0.2	-17.50	10.184	-0.04	541.8
2549	0.0	-17.51	10.192	0.00	542.2
2551	0.0	-17.52	10.200	0.00	542.4
2553	-0.2	-17.53	10.208	-0.04	542.8
2555	0.0	-17.56	10.216	0.00	543.6
2557	-0.2	-17.56	10.224	-0.04	543.6
2559	0.0	-17.58	10.232	0.00	544.2
2561	0.0	-17.59	10.240	0.00	544.6
2563	0.0	-17.60	10.248	0.00	544.8
2565	0.0	-17.62	10.256	0.00	545.6
2567	0.0	-17.63	10.264	0.00	545.8
2569	0.2	-17.65	10.272	0.04	546.4
2571	0.0	-17.66	10.280	0.00	546.8
2573	0.2	-17.67	10.288	0.04	547.0
2575	-0.2	-17.70	10.296	-0.04	548.0
2577	0.2	-17.70	10.304	0.04	548.0
2579	-0.2	-17.72	10.312	-0.04	548.6
2581	0.0	-17.73	10.320	0.00	549.0
2583	0.0	-17.74	10.328	0.00	549.2
2585	0.0	-17.76	10.336	0.00	549.8
2587	0.0	-17.77	10.344	0.00	550.2
2589	-0.2	-17.79	10.352	-0.04	550.8
2591	0.0	-17.80	10.360	0.00	551.0
2593	0.0	-17.81	10.368	0.00	551.4
2595	0.0	-17.84	10.376	0.00	552.4
2597	0.0	-17.84	10.384	0.00	552.4
2599	0.2	-17.86	10.392	0.04	553.0
2601	0.0	-17.88	10.400	0.00	553.6
2603	0.0	-17.89	10.408	0.00	553.8
2605	0.4	-17.90	10.416	0.08	554.2
2607	0.0	-17.91	10.424	0.00	554.4
2609	0.0	-17.93	10.432	0.00	555.2
2611	0.0	-17.94	10.440	0.00	555.4
2613	0.0	-17.95	10.448	0.00	555.8
2615	-0.2	-17.97	10.456	-0.04	556.4
2617	-0.2	-17.98	10.464	-0.04	556.6
2619	0.0	-18.00	10.472	0.00	557.2
2621	-0.2	-18.01	10.480	-0.04	557.6
2623	0.2	-18.02	10.488	0.04	557.8
2625	0.0	-18.04	10.496	0.00	558.6
2627	0.2	-18.05	10.504	0.04	558.8
2629	0.0	-18.08	10.512	0.00	559.8
2631	0.0	-18.08	10.520	0.00	559.8
2633	0.0	-18.09	10.528	0.00	560.0
2635	0.0	-18.11	10.536	0.00	560.6
2637	0.2	-18.12	10.544	0.04	561.0
2639	-0.2	-18.14	10.552	-0.04	561.6
2641	0.2	-18.15	10.560	0.04	562.0
2643	0.0	-18.16	10.568	0.00	562.2
2645	0.0	-18.18	10.576	0.00	562.8
2647	0.0	-18.19	10.584	0.00	563.2
2649	-0.2	-18.22	10.592	-0.04	564.0
2651	0.0	-18.22	10.600	0.00	564.0
2653	0.4	-18.24	10.608	0.08	564.8
2655	0.0	-18.25	10.616	0.00	565.0
2657	0.0	-18.26	10.624	0.00	565.4
2659	0.4	-18.28	10.632	0.08	566.0
2661	0.2	-18.29	10.640	0.04	566.2
2663	0.0	-18.31	10.648	0.00	566.8
2665	0.0	-18.32	10.656	0.00	567.2
2667	0.4	-18.34	10.664	0.08	567.8
2669	0.4	-18.35	10.672	0.08	568.2
2671	0.0	-18.36	10.680	0.00	568.4
2673	-0.2	-18.38	10.688	-0.04	569.0
2675	-0.2	-18.40	10.696	-0.04	569.6
2677	0.0	-18.40	10.704	0.00	569.6
2679	0.0	-18.42	10.712	0.00	570.2
2681	0.2	-18.43	10.720	0.04	570.6
2683	-0.6	-18.45	10.728	-0.12	571.2
2685	0.0	-18.46	10.736	0.00	571.6
2687	0.2	-18.47	10.744	0.04	571.8
2689	0.0	-18.49	10.752	0.00	572.4
2691	0.2	-18.50	10.760	0.04	572.8
2693	0.0	-18.52	10.768	0.00	573.4
2695	-0.2	-18.54	10.776	-0.04	574.0
2697	0.0	-18.54	10.784	0.00	574.0
2699	0.0	-18.56	10.792	0.00	574.6
2701	-0.4	-18.57	10.800	-0.08	575.0
2703	-0.4	-18.59	10.808	-0.08	575.6
2705	0.0	-18.60	10.816	0.00	575.8
2707	0.2	-18.62	10.824	0.04	576.4
2709	0.2	-18.63	10.832	0.04	576.8
2711	0.2	-18.64	10.840	0.04	577.0
2713	0.0	-18.66	10.848	0.00	577.8
2715	0.0	-18.68	10.856	0.00	578.4
2717	-0.2	-18.69	10.864	-0.04	578.6
2719	0.0	-18.70	10.872	0.00	579.0
2721	0.2	-18.71	10.880	0.04	579.2
2723	0.0	-18.74	10.888	0.00	580.2
2725	0.0	-18.74	10.896	0.00	580.2
2727	0.0	-18.76	10.904	0.00	580.8
2729	0.0	-18.77	10.912	0.00	581.2
2731	-0.2	-18.77	10.920	-0.04	581.2
2733	0.0	-18.79	10.928	0.00	581.8
2735	0.0	-18.80	10.936	0.00	582.0
2737	-0.2	-18.82	10.944	-0.04	582.6
2739	0.0	-18.83	10.952	0.00	583.0
2741	0.0	-18.84	10.960	0.00	583.2
2743	-0.6	-18.86	10.968	-0.12	584.0
2745	0.0	-18.88	10.976	0.00	584.6
2747	0.0	-18.89	10.984	0.00	584.8
2749	0.6	-18.90	10.992	0.12	585.2
2751	1.0	-18.92	11.000	0.20	585.8
2753	1.8	-18.93	11.008	0.34	586.0
2755	2.8	-18.94	11.016	0.54	586.4
2757	4.2	-18.96	11.024	0.80	587.0
2759	6.0	-18.97	11.032	1.16	587.4
2761	8.6	-18.98	11.040	1.66	587.6
2763	10.8	-18.99	11.048	2.08	588.0
2765	13.0	-19.01	11.056	2.50	588.6
2767	15.4	-19.02	11.064	2.96	588.8
2769	18.0	-19.03	11.072	3.46	589.2
2771	20.8	-19.04	11.080	4.00	589.4
2773	23.0	-19.06	11.088	4.44	590.0
2775	26.4	-19.06	11.096	5.08	590.0
2777	30.2	-19.08	11.104	5.82	590.8
2779	34.6	-19.08	11.112	6.66	590.8
2781	39.4	-19.10	11.120	7.60	591.4
2783	44.6	-19.10	11.128	8.60	591.4
2785	52.4	-19.11	11.136	10.10	591.6
2787	61.6	-19.12	11.144	11.88	592.0
2789	70.6	-19.12	11.152	13.60	592.0
2791	79.6	-19.13	11.160	15.34	592.2
2793	86.2	-19.14	11.168	16.62	592.6
2795	91.2	-19.15	11.176	17.58	592.8
2797	95.8	-19.16	11.184	18.46	593.2
2799	99.0	-19.17	11.192	19.08	593.4
2801	101.4	-19.18	11.200	19.54	593.8
2803	101.4	-19.20	11.208	19.54	594.4
2805	101.8	-19.22	11.216	19.62	595.0
2807	102.8	-19.22	11.224	19.82	595.0
2809	102.4	-19.24	11.232	19.74	595.6
2811	101.8	-19.25	11.240	19.62	596.0
2813	101.0	-19.27	11.248	19.46	596.6
2815	99.8	-19.28	11.256	19.24	597.0
2817	99.8	-19.29	11.264	19.24	597.2
2819	99.0	-19.32	11.272	19.08	598.2
2821	96.0	-19.33	11.280	18.50	598.4
2823	95.6	-19.34	11.288	18.42	598.8
2825	94.8	-19.36	11.296	18.28	599.4
2827	93.8	-19.38	11.304	18.08	600.0
2829	93.0	-19.40	11.312	17.92	600.6
2831	92.0	-19.40	11.320	17.74	600.6
2833	90.8	-19.42	11.328	17.50	601.2
2835	89.6	-19.43	11.336	17.28	601.6
2837	88.2	-19.45	11.344	17.00	602.2
2839	87.0	-19.46	11.352	16.78	602.4
2841	86.6	-19.48	11.360	16.70	603.0
2843	85.2	-19.49	11.368	16.42	603.4
2845	84.2	-19.52	11.376	16.24	604.4
2847	83.2	-19.52	11.384	16.04	604.4
2849	81.8	-19.54	11.392	15.76	605.0
2851	80.6	-19.55	11.400	15.54	605.2
2853	79.2	-19.58	11.408	15.26	606.2
2855	78.0	-19.58	11.416	15.04	606.2
2857	77.0	-19.60	11.424	14.84	606.8
2859	72.8	-19.61	11.432	14.04	607.2
2861	68.8	-19.61	11.440	13.26	607.2
2863	66.4	-19.61	11.448	12.80	607.2
2865	64.6	-19.61	11.456	12.46	607.2
2867	63.4	-19.61	11.464	12.22	607.2
2869	62.6	-19.61	11.472	12.06	607.2
2871	62.0	-19.61	11.480	11.96	607.2
2873	61.2	-19.61	11.488	11.80	607.2
2875	60.8	-19.61	11.496	11.72	607.2
2877	60.0	-19.62	11.504	11.56	607.4
2879	59.6	-19.62	11.512	11.48	607.4
2881	59.4	-19.62	11.520	11.46	607.4
2883	59.2	-19.62	11.528	11.42	607.4
2885	58.8	-19.62	11.536	11.34	607.4
2886	58.6	-19.62	11.540	11.30	607.4