File: results/youngs-modulus/2025-04-21/inconclusive-data/pf08lt02.csv
sep=
pf08lt02

System Information:
IntelliMESUR Version: 2.2.1
Test Frame Model: F505
Test Frame Serial Number: 4418651
Test Frame Capacity: 500 lbF / 2.2 kN
Test Frame Firmware Version: 1.00.14
Force Sensor Model: FS05-100
Force Sensor Capacity: 500 N
Force Sensor Resolution: 0.2 N
Force Sensor Serial Number: 4425350
Calibration Date: Apr 29, 2024
Calibration Due Date: Apr 29, 2025

Reading	Load [N]	Distance [mm]	Time [s]	Stress [MPa]	Strain [%]
1	0.0	0.01	0.000	0.00	-0.2
4	0.2	0.01	0.012	0.02	-0.2
7	0.0	0.01	0.024	0.00	-0.2
10	0.0	0.01	0.036	0.00	-0.2
13	-0.2	0.01	0.048	-0.02	-0.2
16	0.0	0.01	0.060	0.00	-0.2
19	0.0	0.01	0.072	0.00	-0.2
22	0.0	0.01	0.084	0.00	-0.2
25	0.0	0.01	0.096	0.00	-0.2
28	0.0	0.01	0.108	0.00	-0.2
31	0.0	0.01	0.120	0.00	-0.2
34	-0.4	0.01	0.132	-0.04	-0.2
37	0.0	0.01	0.144	0.00	-0.2
40	0.0	0.01	0.156	0.00	-0.2
43	0.2	0.01	0.168	0.02	-0.2
46	0.0	0.01	0.180	0.00	-0.2
49	0.0	0.00	0.192	0.00	0.0
52	0.0	-0.03	0.204	0.00	0.8
55	0.0	-0.05	0.216	0.00	1.4
58	0.0	-0.07	0.228	0.00	2.0
61	0.0	-0.09	0.240	0.00	2.6
64	0.0	-0.11	0.252	0.00	3.2
67	0.0	-0.13	0.264	0.00	3.8
70	0.0	-0.15	0.276	0.00	4.4
73	-0.2	-0.18	0.288	-0.02	5.2
76	0.0	-0.19	0.300	0.00	5.6
79	-0.2	-0.21	0.312	-0.02	6.2
82	0.0	-0.23	0.324	0.00	6.6
85	-0.4	-0.25	0.336	-0.04	7.2
88	0.0	-0.27	0.348	0.00	7.8
91	0.0	-0.29	0.360	0.00	8.4
94	0.2	-0.31	0.372	0.02	9.0
97	0.0	-0.33	0.384	0.00	9.6
100	-0.2	-0.36	0.396	-0.02	10.4
103	0.0	-0.38	0.408	0.00	11.0
106	0.0	-0.40	0.420	0.00	11.6
109	0.6	-0.42	0.432	0.06	12.2
112	0.0	-0.44	0.444	0.00	12.8
115	-0.2	-0.46	0.456	-0.02	13.4
118	0.0	-0.48	0.468	0.00	14.0
121	-0.2	-0.50	0.480	-0.02	14.6
124	0.0	-0.52	0.492	0.00	15.2
127	-0.2	-0.55	0.504	-0.02	16.0
130	0.2	-0.56	0.516	0.02	16.2
133	-0.2	-0.59	0.528	-0.02	17.2
136	-0.2	-0.61	0.540	-0.02	17.8
139	0.2	-0.63	0.552	0.02	18.4
142	-0.2	-0.65	0.564	-0.02	18.8
145	-0.2	-0.67	0.576	-0.02	19.4
148	0.0	-0.69	0.588	0.00	20.0
151	-0.2	-0.71	0.600	-0.02	20.6
154	0.0	-0.73	0.612	0.00	21.2
157	0.2	-0.75	0.624	0.02	21.8
160	0.0	-0.78	0.636	0.00	22.6
163	-0.4	-0.80	0.648	-0.04	23.2
166	0.0	-0.82	0.660	0.00	23.8
169	0.0	-0.84	0.672	0.00	24.4
172	0.2	-0.86	0.684	0.02	25.0
175	-0.2	-0.88	0.696	-0.02	25.6
178	0.0	-0.90	0.708	0.00	26.2
181	0.0	-0.92	0.720	0.00	26.8
184	0.0	-0.94	0.732	0.00	27.4
187	0.0	-0.96	0.744	0.00	28.0
190	0.0	-0.98	0.756	0.00	28.4
193	0.2	-1.01	0.768	0.02	29.4
196	0.0	-1.03	0.780	0.00	30.0
199	0.2	-1.05	0.792	0.02	30.6
202	0.2	-1.07	0.804	0.02	31.2
205	0.0	-1.09	0.816	0.00	31.6
208	0.0	-1.11	0.828	0.00	32.2
211	0.0	-1.13	0.840	0.00	32.8
214	-0.2	-1.15	0.852	-0.02	33.4
217	0.0	-1.17	0.864	0.00	34.0
220	0.0	-1.20	0.876	0.00	34.8
223	0.0	-1.22	0.888	0.00	35.4
226	0.0	-1.25	0.900	0.00	36.4
229	0.2	-1.27	0.912	0.02	37.0
232	0.0	-1.29	0.924	0.00	37.6
235	0.0	-1.31	0.936	0.00	38.0
238	0.0	-1.33	0.948	0.00	38.6
241	0.0	-1.35	0.960	0.00	39.2
244	0.0	-1.37	0.972	0.00	39.8
247	0.0	-1.39	0.984	0.00	40.4
250	0.0	-1.41	0.996	0.00	41.0
253	0.0	-1.43	1.008	0.00	41.6
256	-0.4	-1.46	1.020	-0.04	42.4
259	-0.2	-1.48	1.032	-0.02	43.0
262	0.0	-1.50	1.044	0.00	43.6
265	0.0	-1.52	1.056	0.00	44.2
268	-0.2	-1.54	1.068	-0.02	44.8
271	0.0	-1.56	1.080	0.00	45.4
274	-0.2	-1.58	1.092	-0.02	46.0
277	-0.2	-1.60	1.104	-0.02	46.6
280	-0.2	-1.62	1.116	-0.02	47.0
283	0.0	-1.64	1.128	0.00	47.6
286	0.4	-1.66	1.140	0.04	48.2
289	0.0	-1.68	1.152	0.00	48.8
292	0.0	-1.70	1.164	0.00	49.4
295	-0.4	-1.73	1.176	-0.04	50.2
298	0.0	-1.75	1.188	0.00	50.8
301	0.2	-1.77	1.200	0.02	51.4
304	0.0	-1.79	1.212	0.00	52.0
307	0.2	-1.81	1.224	0.02	52.6
310	0.0	-1.83	1.236	0.00	53.2
313	0.0	-1.85	1.248	0.00	53.8
316	0.2	-1.87	1.260	0.02	54.4
319	0.0	-1.89	1.272	0.00	55.0
322	0.0	-1.91	1.284	0.00	55.6
325	0.0	-1.93	1.296	0.00	56.2
328	0.0	-1.96	1.308	0.00	57.0
331	-0.2	-1.98	1.320	-0.02	57.6
334	0.0	-2.00	1.332	0.00	58.2
337	0.0	-2.02	1.344	0.00	58.8
340	0.2	-2.04	1.356	0.02	59.4
343	0.0	-2.06	1.368	0.00	59.8
346	0.0	-2.08	1.380	0.00	60.4
349	0.0	-2.10	1.392	0.00	61.0
352	0.0	-2.12	1.404	0.00	61.6
355	0.0	-2.14	1.416	0.00	62.2
358	0.2	-2.16	1.428	0.02	62.8
361	0.0	-2.19	1.440	0.00	63.6
364	0.0	-2.20	1.452	0.00	64.0
367	0.2	-2.22	1.464	0.02	64.6
370	0.0	-2.24	1.476	0.00	65.2
373	0.0	-2.26	1.488	0.00	65.6
376	-0.2	-2.28	1.500	-0.02	66.2
379	0.2	-2.30	1.512	0.02	66.8
382	0.0	-2.32	1.524	0.00	67.4
385	-0.2	-2.34	1.536	-0.02	68.0
388	0.0	-2.36	1.548	0.00	68.6
391	0.0	-2.38	1.560	0.00	69.2
394	0.2	-2.40	1.572	0.02	69.8
397	-0.2	-2.43	1.584	-0.02	70.6
400	-0.2	-2.45	1.596	-0.02	71.2
403	0.0	-2.47	1.608	0.00	71.8
406	-0.2	-2.49	1.620	-0.02	72.4
409	-0.2	-2.51	1.632	-0.02	73.0
412	0.0	-2.53	1.644	0.00	73.6
415	0.2	-2.55	1.656	0.02	74.2
418	0.0	-2.57	1.668	0.00	74.8
421	0.0	-2.59	1.680	0.00	75.2
424	0.0	-2.61	1.692	0.00	75.8
427	0.0	-2.63	1.704	0.00	76.4
430	0.0	-2.66	1.716	0.00	77.4
433	0.0	-2.68	1.728	0.00	78.0
436	0.0	-2.70	1.740	0.00	78.4
439	0.0	-2.72	1.752	0.00	79.0
442	0.2	-2.74	1.764	0.02	79.6
445	0.0	-2.76	1.776	0.00	80.2
448	-0.2	-2.78	1.788	-0.02	80.8
451	0.2	-2.80	1.800	0.02	81.4
454	0.2	-2.82	1.812	0.02	82.0
457	0.0	-2.84	1.824	0.00	82.6
460	0.0	-2.86	1.836	0.00	83.2
463	0.0	-2.89	1.848	0.00	84.0
466	0.0	-2.91	1.860	0.00	84.6
469	0.0	-2.93	1.872	0.00	85.2
472	-0.2	-2.95	1.884	-0.02	85.8
475	-0.2	-2.97	1.896	-0.02	86.4
478	0.0	-2.99	1.908	0.00	87.0
481	0.2	-3.01	1.920	0.02	87.6
484	0.0	-3.03	1.932	0.00	88.0
487	0.0	-3.05	1.944	0.00	88.6
490	0.2	-3.07	1.956	0.02	89.2
493	-0.2	-3.10	1.968	-0.02	90.2
496	0.0	-3.12	1.980	0.00	90.6
499	0.0	-3.14	1.992	0.00	91.2
502	0.0	-3.16	2.004	0.00	91.8
505	0.0	-3.18	2.016	0.00	92.4
508	0.0	-3.21	2.028	0.00	93.4
511	-0.2	-3.23	2.040	-0.02	93.8
514	0.0	-3.25	2.052	0.00	94.4
517	0.0	-3.27	2.064	0.00	95.0
520	-0.2	-3.29	2.076	-0.02	95.6
523	0.0	-3.32	2.088	0.00	96.6
526	0.0	-3.34	2.100	0.00	97.0
529	0.0	-3.36	2.112	0.00	97.6
532	0.0	-3.38	2.124	0.00	98.2
535	-0.2	-3.40	2.136	-0.02	98.8
538	0.0	-3.42	2.148	0.00	99.4
541	0.2	-3.44	2.160	0.02	100.0
544	0.2	-3.46	2.172	0.02	100.6
547	-0.2	-3.48	2.184	-0.02	101.2
550	0.0	-3.50	2.196	0.00	101.8
553	-0.2	-3.53	2.208	-0.02	102.6
556	0.0	-3.55	2.220	0.00	103.2
559	0.0	-3.57	2.232	0.00	103.8
562	-0.2	-3.59	2.244	-0.02	104.4
565	0.0	-3.61	2.256	0.00	105.0
568	-0.2	-3.63	2.268	-0.02	105.6
571	0.0	-3.65	2.280	0.00	106.2
574	0.0	-3.67	2.292	0.00	106.6
577	0.0	-3.69	2.304	0.00	107.2
580	0.0	-3.72	2.316	0.00	108.2
583	0.0	-3.74	2.328	0.00	108.8
586	-0.2	-3.76	2.340	-0.02	109.4
589	-0.2	-3.78	2.352	-0.02	109.8
592	0.0	-3.80	2.364	0.00	110.4
595	0.0	-3.82	2.376	0.00	111.0
598	0.0	-3.84	2.388	0.00	111.6
601	0.0	-3.86	2.400	0.00	112.2
604	0.0	-3.88	2.412	0.00	112.8
607	0.0	-3.91	2.424	0.00	113.6
610	0.0	-3.93	2.436	0.00	114.2
613	0.0	-3.95	2.448	0.00	114.8
616	-0.2	-3.97	2.460	-0.02	115.4
619	0.0	-3.99	2.472	0.00	116.0
622	0.0	-4.01	2.484	0.00	116.6
625	0.0	-4.03	2.496	0.00	117.2
628	0.2	-4.05	2.508	0.02	117.8
631	0.0	-4.08	2.520	0.00	118.6
634	0.0	-4.10	2.532	0.00	119.2
637	0.0	-4.12	2.544	0.00	119.8
640	0.0	-4.14	2.556	0.00	120.4
643	0.0	-4.16	2.568	0.00	121.0
646	0.0	-4.18	2.580	0.00	121.6
649	0.0	-4.20	2.592	0.00	122.0
652	0.2	-4.22	2.604	0.02	122.6
655	0.0	-4.25	2.616	0.00	123.6
658	0.0	-4.27	2.628	0.00	124.2
661	-0.2	-4.29	2.640	-0.02	124.8
664	0.0	-4.31	2.652	0.00	125.2
667	0.0	-4.33	2.664	0.00	125.8
670	0.0	-4.35	2.676	0.00	126.4
673	0.0	-4.37	2.688	0.00	127.0
676	0.0	-4.39	2.700	0.00	127.6
679	0.0	-4.41	2.712	0.00	128.2
682	0.2	-4.43	2.724	0.02	128.8
685	0.0	-4.46	2.736	0.00	129.6
688	0.2	-4.48	2.748	0.02	130.2
691	-0.2	-4.50	2.760	-0.02	130.8
694	-0.4	-4.52	2.772	-0.04	131.4
697	0.0	-4.54	2.784	0.00	132.0
700	0.0	-4.56	2.796	0.00	132.6
703	0.2	-4.58	2.808	0.02	133.2
706	0.2	-4.60	2.820	0.02	133.8
709	0.2	-4.63	2.832	0.02	134.6
712	0.0	-4.65	2.844	0.00	135.2
715	0.2	-4.67	2.856	0.02	135.8
718	0.0	-4.69	2.868	0.00	136.4
721	0.2	-4.71	2.880	0.02	137.0
724	0.0	-4.73	2.892	0.00	137.6
727	0.0	-4.75	2.904	0.00	138.0
730	0.2	-4.77	2.916	0.02	138.6
733	0.0	-4.79	2.928	0.00	139.2
736	0.0	-4.82	2.940	0.00	140.2
739	0.0	-4.84	2.952	0.00	140.6
742	0.0	-4.86	2.964	0.00	141.2
745	0.0	-4.88	2.976	0.00	141.8
748	0.0	-4.90	2.988	0.00	142.4
751	-0.4	-4.92	3.000	-0.04	143.0
754	0.0	-4.94	3.012	0.00	143.6
757	0.0	-4.96	3.024	0.00	144.2
760	0.0	-4.98	3.036	0.00	144.8
763	-0.2	-5.01	3.048	-0.02	145.6
766	0.0	-5.03	3.060	0.00	146.2
769	0.0	-5.05	3.072	0.00	146.8
772	0.2	-5.07	3.084	0.02	147.4
775	0.0	-5.09	3.096	0.00	148.0
778	0.0	-5.11	3.108	0.00	148.6
781	0.0	-5.13	3.120	0.00	149.2
784	0.0	-5.15	3.132	0.00	149.8
787	0.0	-5.17	3.144	0.00	150.2
790	0.0	-5.20	3.156	0.00	151.2
793	-0.2	-5.22	3.168	-0.02	151.8
796	0.0	-5.24	3.180	0.00	152.4
799	0.0	-5.26	3.192	0.00	153.0
802	0.0	-5.28	3.204	0.00	153.4
805	0.2	-5.30	3.216	0.02	154.0
808	0.0	-5.32	3.228	0.00	154.6
811	0.2	-5.34	3.240	0.02	155.2
814	0.2	-5.36	3.252	0.02	155.8
817	-0.2	-5.39	3.264	-0.02	156.6
820	0.0	-5.41	3.276	0.00	157.2
823	0.0	-5.43	3.288	0.00	157.8
826	0.0	-5.45	3.300	0.00	158.4
829	0.0	-5.47	3.312	0.00	159.0
832	0.0	-5.49	3.324	0.00	159.6
835	0.0	-5.51	3.336	0.00	160.2
838	-0.2	-5.53	3.348	-0.02	160.8
841	0.0	-5.55	3.360	0.00	161.4
844	0.0	-5.57	3.372	0.00	162.0
847	0.0	-5.59	3.384	0.00	162.4
850	0.0	-5.62	3.396	0.00	163.4
853	-0.2	-5.64	3.408	-0.02	164.0
856	0.2	-5.66	3.420	0.02	164.6
859	-0.2	-5.68	3.432	-0.02	165.2
862	-0.2	-5.70	3.444	-0.02	165.6
865	-0.2	-5.72	3.456	-0.02	166.2
868	-0.2	-5.74	3.468	-0.02	166.8
871	-0.2	-5.76	3.480	-0.02	167.4
874	0.0	-5.78	3.492	0.00	168.0
877	-0.4	-5.81	3.504	-0.04	168.8
880	0.2	-5.82	3.516	0.02	169.2
883	0.0	-5.85	3.528	0.00	170.0
886	0.0	-5.87	3.540	0.00	170.6
889	0.0	-5.89	3.552	0.00	171.2
892	0.0	-5.91	3.564	0.00	171.8
895	-0.2	-5.93	3.576	-0.02	172.4
898	0.0	-5.95	3.588	0.00	173.0
901	0.0	-5.97	3.600	0.00	173.6
904	0.0	-5.99	3.612	0.00	174.2
907	-0.2	-6.01	3.624	-0.02	174.8
910	0.2	-6.03	3.636	0.02	175.2
913	0.0	-6.05	3.648	0.00	175.8
916	0.0	-6.08	3.660	0.00	176.8
919	-0.2	-6.10	3.672	-0.02	177.4
922	0.4	-6.12	3.684	0.04	178.0
925	0.0	-6.14	3.696	0.00	178.4
928	-0.2	-6.16	3.708	-0.02	179.0
931	-0.2	-6.18	3.720	-0.02	179.6
934	0.0	-6.19	3.732	0.00	180.0
937	0.0	-6.21	3.744	0.00	180.6
940	0.2	-6.23	3.756	0.02	181.2
943	0.2	-6.25	3.768	0.02	181.6
946	0.0	-6.28	3.780	0.00	182.6
949	0.0	-6.30	3.792	0.00	183.2
952	0.0	-6.32	3.804	0.00	183.8
955	0.0	-6.34	3.816	0.00	184.4
958	0.0	-6.36	3.828	0.00	184.8
961	0.0	-6.38	3.840	0.00	185.4
964	-0.6	-6.40	3.852	-0.06	186.0
967	0.0	-6.42	3.864	0.00	186.6
970	0.0	-6.44	3.876	0.00	187.2
973	0.2	-6.46	3.888	0.02	187.8
976	0.0	-6.48	3.900	0.00	188.4
979	0.0	-6.51	3.912	0.00	189.2
982	0.0	-6.52	3.924	0.00	189.6
985	0.0	-6.55	3.936	0.00	190.4
988	0.0	-6.57	3.948	0.00	191.0
991	0.2	-6.59	3.960	0.02	191.6
994	0.0	-6.61	3.972	0.00	192.2
997	0.0	-6.63	3.984	0.00	192.8
1000	-0.2	-6.65	3.996	-0.02	193.4
1003	-0.2	-6.67	4.008	-0.02	193.8
1006	0.0	-6.69	4.020	0.00	194.4
1009	0.0	-6.71	4.032	0.00	195.0
1012	0.0	-6.73	4.044	0.00	195.6
1015	0.0	-6.75	4.056	0.00	196.2
1018	0.0	-6.77	4.068	0.00	196.8
1021	-0.6	-6.80	4.080	-0.06	197.6
1024	0.0	-6.82	4.092	0.00	198.2
1027	-0.2	-6.84	4.104	-0.02	198.8
1030	0.2	-6.86	4.116	0.02	199.4
1033	0.0	-6.88	4.128	0.00	200.0
1036	0.0	-6.90	4.140	0.00	200.6
1039	0.0	-6.92	4.152	0.00	201.2
1042	0.0	-6.94	4.164	0.00	201.8
1045	0.0	-6.96	4.176	0.00	202.4
1048	-0.2	-6.98	4.188	-0.02	203.0
1051	-0.2	-7.00	4.200	-0.02	203.4
1054	-0.2	-7.03	4.212	-0.02	204.4
1057	0.2	-7.05	4.224	0.02	205.0
1060	0.0	-7.07	4.236	0.00	205.6
1063	0.2	-7.09	4.248	0.02	206.2
1066	0.0	-7.11	4.260	0.00	206.6
1069	0.2	-7.13	4.272	0.02	207.2
1072	0.0	-7.15	4.284	0.00	207.8
1075	0.0	-7.17	4.296	0.00	208.4
1078	0.0	-7.20	4.308	0.00	209.4
1081	0.0	-7.22	4.320	0.00	209.8
1084	0.0	-7.24	4.332	0.00	210.4
1087	-0.4	-7.27	4.344	-0.04	211.4
1090	0.0	-7.28	4.356	0.00	211.6
1093	0.0	-7.31	4.368	0.00	212.6
1096	0.0	-7.33	4.380	0.00	213.0
1099	0.0	-7.35	4.392	0.00	213.6
1102	0.0	-7.37	4.404	0.00	214.2
1105	0.0	-7.39	4.416	0.00	214.8
1108	-0.2	-7.41	4.428	-0.02	215.4
1111	0.0	-7.43	4.440	0.00	216.0
1114	-0.2	-7.45	4.452	-0.02	216.6
1117	0.0	-7.47	4.464	0.00	217.2
1120	0.2	-7.50	4.476	0.02	218.0
1123	-0.2	-7.51	4.488	-0.02	218.4
1126	0.2	-7.54	4.500	0.02	219.2
1129	0.0	-7.56	4.512	0.00	219.8
1132	0.0	-7.58	4.524	0.00	220.4
1135	0.0	-7.60	4.536	0.00	221.0
1138	0.0	-7.62	4.548	0.00	221.6
1141	0.0	-7.64	4.560	0.00	222.0
1144	0.0	-7.66	4.572	0.00	222.6
1147	-0.2	-7.68	4.584	-0.02	223.2
1150	0.0	-7.70	4.596	0.00	223.8
1153	0.0	-7.72	4.608	0.00	224.4
1156	0.2	-7.74	4.620	0.02	225.0
1159	-0.6	-7.77	4.632	-0.06	225.8
1162	0.0	-7.79	4.644	0.00	226.4
1165	0.0	-7.81	4.656	0.00	227.0
1168	0.2	-7.83	4.668	0.02	227.6
1171	0.2	-7.85	4.680	0.02	228.2
1174	0.2	-7.87	4.692	0.02	228.8
1177	0.0	-7.89	4.704	0.00	229.4
1180	0.0	-7.91	4.716	0.00	230.0
1183	0.0	-7.93	4.728	0.00	230.6
1186	-0.2	-7.95	4.740	-0.02	231.2
1189	-0.2	-7.97	4.752	-0.02	231.6
1192	-0.2	-7.99	4.764	-0.02	232.2
1195	-0.2	-8.02	4.776	-0.02	233.2
1198	0.0	-8.04	4.788	0.00	233.8
1201	0.0	-8.06	4.800	0.00	234.4
1204	0.0	-8.08	4.812	0.00	234.8
1207	0.0	-8.10	4.824	0.00	235.4
1210	0.0	-8.12	4.836	0.00	236.0
1213	0.0	-8.14	4.848	0.00	236.6
1216	0.0	-8.16	4.860	0.00	237.2
1219	0.4	-8.18	4.872	0.04	237.8
1222	0.0	-8.21	4.884	0.00	238.6
1225	-0.2	-8.23	4.896	-0.02	239.2
1228	0.0	-8.25	4.908	0.00	239.8
1231	0.2	-8.27	4.920	0.02	240.4
1234	0.0	-8.29	4.932	0.00	241.0
1237	0.0	-8.31	4.944	0.00	241.6
1240	-0.4	-8.33	4.956	-0.04	242.2
1243	0.0	-8.35	4.968	0.00	242.8
1246	0.0	-8.37	4.980	0.00	243.4
1249	0.0	-8.40	4.992	0.00	244.2
1252	0.2	-8.42	5.004	0.02	244.8
1255	0.0	-8.44	5.016	0.00	245.4
1258	0.0	-8.46	5.028	0.00	246.0
1261	-0.4	-8.48	5.040	-0.04	246.6
1264	0.0	-8.50	5.052	0.00	247.0
1267	-0.4	-8.52	5.064	-0.04	247.6
1270	0.2	-8.54	5.076	0.02	248.2
1273	0.0	-8.56	5.088	0.00	248.8
1276	0.0	-8.58	5.100	0.00	249.4
1279	0.0	-8.60	5.112	0.00	250.0
1282	0.0	-8.63	5.124	0.00	250.8
1285	0.0	-8.65	5.136	0.00	251.4
1288	0.0	-8.67	5.148	0.00	252.0
1291	0.0	-8.69	5.160	0.00	252.6
1294	0.0	-8.71	5.172	0.00	253.2
1297	0.0	-8.73	5.184	0.00	253.8
1300	-0.2	-8.75	5.196	-0.02	254.4
1303	-0.2	-8.77	5.208	-0.02	255.0
1306	0.0	-8.79	5.220	0.00	255.6
1309	0.0	-8.82	5.232	0.00	256.4
1312	0.0	-8.84	5.244	0.00	257.0
1315	0.2	-8.86	5.256	0.02	257.6
1318	0.0	-8.88	5.268	0.00	258.2
1321	-0.2	-8.90	5.280	-0.02	258.8
1324	0.0	-8.92	5.292	0.00	259.4
1327	0.0	-8.94	5.304	0.00	259.8
1330	0.0	-8.96	5.316	0.00	260.4
1333	0.2	-8.98	5.328	0.02	261.0
1336	0.0	-9.01	5.340	0.00	262.0
1339	0.0	-9.03	5.352	0.00	262.4
1342	0.0	-9.05	5.364	0.00	263.0
1345	0.0	-9.07	5.376	0.00	263.6
1348	0.0	-9.09	5.388	0.00	264.2
1351	-0.2	-9.11	5.400	-0.02	264.8
1354	0.0	-9.13	5.412	0.00	265.4
1357	0.2	-9.16	5.424	0.02	266.2
1360	0.0	-9.18	5.436	0.00	266.8
1363	0.0	-9.20	5.448	0.00	267.4
1366	0.0	-9.22	5.460	0.00	268.0
1369	0.0	-9.24	5.472	0.00	268.6
1372	0.0	-9.26	5.484	0.00	269.2
1375	0.0	-9.28	5.496	0.00	269.8
1378	0.0	-9.30	5.508	0.00	270.4
1381	0.2	-9.32	5.520	0.02	271.0
1384	0.2	-9.35	5.532	0.02	271.8
1387	0.0	-9.37	5.544	0.00	272.4
1390	0.2	-9.39	5.556	0.02	273.0
1393	0.0	-9.41	5.568	0.00	273.6
1396	0.0	-9.43	5.580	0.00	274.2
1399	-0.2	-9.45	5.592	-0.02	274.8
1402	0.0	-9.47	5.604	0.00	275.2
1405	0.0	-9.49	5.616	0.00	275.8
1408	0.0	-9.51	5.628	0.00	276.4
1411	0.0	-9.54	5.640	0.00	277.4
1414	-0.4	-9.56	5.652	-0.04	278.0
1417	0.0	-9.58	5.664	0.00	278.4
1420	0.2	-9.60	5.676	0.02	279.0
1423	0.0	-9.62	5.688	0.00	279.6
1426	0.0	-9.64	5.700	0.00	280.2
1429	-0.2	-9.66	5.712	-0.02	280.8
1432	-0.4	-9.68	5.724	-0.04	281.4
1435	0.0	-9.70	5.736	0.00	282.0
1438	0.0	-9.73	5.748	0.00	282.8
1441	0.0	-9.75	5.760	0.00	283.4
1444	0.2	-9.77	5.772	0.02	284.0
1447	0.4	-9.79	5.784	0.04	284.6
1450	0.2	-9.81	5.796	0.02	285.2
1453	0.0	-9.83	5.808	0.00	285.8
1456	0.0	-9.85	5.820	0.00	286.4
1459	-0.2	-9.88	5.832	-0.02	287.2
1462	0.0	-9.89	5.844	0.00	287.6
1465	0.0	-9.92	5.856	0.00	288.4
1468	-0.2	-9.94	5.868	-0.02	289.0
1471	0.0	-9.96	5.880	0.00	289.6
1474	0.2	-9.98	5.892	0.02	290.2
1477	0.0	-10.00	5.904	0.00	290.6
1480	0.0	-10.02	5.916	0.00	291.2
1483	0.0	-10.04	5.928	0.00	291.8
1486	-0.2	-10.06	5.940	-0.02	292.4
1489	0.0	-10.08	5.952	0.00	293.0
1492	0.0	-10.11	5.964	0.00	293.8
1495	0.0	-10.13	5.976	0.00	294.4
1498	0.0	-10.15	5.988	0.00	295.0
1501	0.0	-10.17	6.000	0.00	295.6
1504	0.0	-10.19	6.012	0.00	296.2
1507	0.2	-10.20	6.024	0.02	296.6
1510	-0.2	-10.22	6.036	-0.02	297.0
1513	0.0	-10.24	6.048	0.00	297.6
1516	0.0	-10.26	6.060	0.00	298.2
1519	0.0	-10.29	6.072	0.00	299.2
1522	0.2	-10.31	6.084	0.02	299.8
1525	0.0	-10.33	6.096	0.00	300.2
1528	-0.2	-10.35	6.108	-0.02	300.8
1531	0.0	-10.37	6.120	0.00	301.4
1534	0.0	-10.39	6.132	0.00	302.0
1537	0.0	-10.41	6.144	0.00	302.6
1540	-0.2	-10.43	6.156	-0.02	303.2
1543	0.0	-10.45	6.168	0.00	303.8
1546	0.0	-10.48	6.180	0.00	304.6
1549	0.0	-10.50	6.192	0.00	305.2
1552	0.2	-10.52	6.204	0.02	305.8
1555	0.0	-10.54	6.216	0.00	306.4
1558	0.2	-10.56	6.228	0.02	307.0
1561	0.0	-10.58	6.240	0.00	307.6
1564	0.0	-10.60	6.252	0.00	308.2
1567	-0.2	-10.62	6.264	-0.02	308.8
1570	0.0	-10.64	6.276	0.00	309.4
1573	-0.2	-10.67	6.288	-0.02	310.2
1576	0.0	-10.69	6.300	0.00	310.8
1579	0.0	-10.71	6.312	0.00	311.4
1582	0.2	-10.73	6.324	0.02	312.0
1585	0.0	-10.75	6.336	0.00	312.4
1588	-0.2	-10.77	6.348	-0.02	313.0
1591	-0.2	-10.79	6.360	-0.02	313.6
1594	-0.4	-10.81	6.372	-0.04	314.2
1597	0.0	-10.83	6.384	0.00	314.8
1600	0.0	-10.85	6.396	0.00	315.4
1603	0.0	-10.87	6.408	0.00	316.0
1606	0.0	-10.90	6.420	0.00	316.8
1609	-0.4	-10.92	6.432	-0.04	317.4
1612	0.0	-10.94	6.444	0.00	318.0
1615	0.0	-10.96	6.456	0.00	318.6
1618	-0.2	-10.98	6.468	-0.02	319.2
1621	-0.2	-11.00	6.480	-0.02	319.8
1624	0.0	-11.02	6.492	0.00	320.4
1627	0.0	-11.04	6.504	0.00	321.0
1630	0.0	-11.06	6.516	0.00	321.6
1633	0.2	-11.08	6.528	0.02	322.0
1636	0.0	-11.10	6.540	0.00	322.6
1639	0.2	-11.13	6.552	0.02	323.6
1642	0.0	-11.15	6.564	0.00	324.2
1645	0.0	-11.17	6.576	0.00	324.8
1648	0.2	-11.19	6.588	0.02	325.2
1651	0.0	-11.21	6.600	0.00	325.8
1654	0.0	-11.23	6.612	0.00	326.4
1657	0.0	-11.25	6.624	0.00	327.0
1660	0.0	-11.27	6.636	0.00	327.6
1663	-0.4	-11.29	6.648	-0.04	328.2
1666	0.2	-11.31	6.660	0.02	328.8
1669	0.4	-11.34	6.672	0.04	329.6
1672	0.0	-11.35	6.684	0.00	330.0
1675	0.0	-11.38	6.696	0.00	330.8
1678	0.0	-11.40	6.708	0.00	331.4
1681	0.2	-11.42	6.720	0.02	332.0
1684	0.0	-11.44	6.732	0.00	332.6
1687	0.0	-11.46	6.744	0.00	333.2
1690	0.0	-11.48	6.756	0.00	333.8
1693	-0.4	-11.50	6.768	-0.04	334.4
1696	0.0	-11.52	6.780	0.00	334.8
1699	0.0	-11.54	6.792	0.00	335.4
1702	0.0	-11.57	6.804	0.00	336.4
1705	0.2	-11.59	6.816	0.02	337.0
1708	0.0	-11.61	6.828	0.00	337.6
1711	0.0	-11.63	6.840	0.00	338.0
1714	-0.2	-11.65	6.852	-0.02	338.6
1717	0.4	-11.67	6.864	0.04	339.2
1720	0.0	-11.69	6.876	0.00	339.8
1723	-0.2	-11.71	6.888	-0.02	340.4
1726	0.0	-11.73	6.900	0.00	341.0
1729	-0.2	-11.75	6.912	-0.02	341.6
1732	-0.2	-11.77	6.924	-0.02	342.2
1735	0.0	-11.79	6.936	0.00	342.8
1738	-0.2	-11.81	6.948	-0.02	343.4
1741	0.2	-11.84	6.960	0.02	344.2
1744	0.0	-11.86	6.972	0.00	344.8
1747	0.0	-11.88	6.984	0.00	345.4
1750	0.2	-11.90	6.996	0.02	346.0
1753	0.0	-11.92	7.008	0.00	346.6
1756	0.0	-11.94	7.020	0.00	347.0
1759	-0.2	-11.96	7.032	-0.02	347.6
1762	0.2	-11.98	7.044	0.02	348.2
1765	-0.4	-12.00	7.056	-0.04	348.8
1768	0.2	-12.02	7.068	0.02	349.4
1771	0.0	-12.04	7.080	0.00	350.0
1774	0.0	-12.06	7.092	0.00	350.6
1777	0.0	-12.09	7.104	0.00	351.4
1780	0.0	-12.11	7.116	0.00	352.0
1783	-0.2	-12.13	7.128	-0.02	352.6
1786	-0.2	-12.15	7.140	-0.02	353.2
1789	0.0	-12.17	7.152	0.00	353.8
1792	0.0	-12.20	7.164	0.00	354.6
1795	0.0	-12.22	7.176	0.00	355.2
1798	-0.2	-12.24	7.188	-0.02	355.8
1801	0.4	-12.26	7.200	0.04	356.4
1804	0.0	-12.28	7.212	0.00	357.0
1807	0.0	-12.30	7.224	0.00	357.6
1810	0.0	-12.33	7.236	0.00	358.4
1813	0.2	-12.35	7.248	0.02	359.0
1816	0.2	-12.37	7.260	0.02	359.6
1819	0.0	-12.39	7.272	0.00	360.2
1822	0.0	-12.41	7.284	0.00	360.8
1825	0.0	-12.43	7.296	0.00	361.4
1828	0.2	-12.45	7.308	0.02	362.0
1831	-0.2	-12.47	7.320	-0.02	362.6
1834	0.0	-12.49	7.332	0.00	363.0
1837	0.0	-12.52	7.344	0.00	364.0
1840	-0.2	-12.53	7.356	-0.02	364.2
1843	0.0	-12.56	7.368	0.00	365.2
1846	0.0	-12.58	7.380	0.00	365.6
1849	0.0	-12.60	7.392	0.00	366.2
1852	0.2	-12.62	7.404	0.02	366.8
1855	0.2	-12.64	7.416	0.02	367.4
1858	0.4	-12.66	7.428	0.04	368.0
1861	0.0	-12.68	7.440	0.00	368.6
1864	0.0	-12.70	7.452	0.00	369.2
1867	-0.2	-12.72	7.464	-0.02	369.8
1870	0.0	-12.74	7.476	0.00	370.4
1873	0.2	-12.77	7.488	0.02	371.2
1876	-0.2	-12.79	7.500	-0.02	371.8
1879	0.0	-12.81	7.512	0.00	372.4
1882	-0.2	-12.83	7.524	-0.02	373.0
1885	0.2	-12.85	7.536	0.02	373.6
1888	0.0	-12.87	7.548	0.00	374.2
1891	-0.4	-12.89	7.560	-0.04	374.8
1894	0.0	-12.91	7.572	0.00	375.2
1897	0.2	-12.93	7.584	0.02	375.8
1900	-0.2	-12.95	7.596	-0.02	376.4
1903	0.2	-12.97	7.608	0.02	377.0
1906	0.0	-13.00	7.620	0.00	378.0
1909	-0.2	-13.02	7.632	-0.02	378.4
1912	0.2	-13.04	7.644	0.02	379.0
1915	0.0	-13.06	7.656	0.00	379.6
1918	0.2	-13.08	7.668	0.02	380.2
1921	0.0	-13.10	7.680	0.00	380.8
1924	-0.2	-13.12	7.692	-0.02	381.4
1927	-0.2	-13.14	7.704	-0.02	382.0
1930	0.0	-13.16	7.716	0.00	382.6
1933	0.2	-13.18	7.728	0.02	383.2
1936	0.0	-13.20	7.740	0.00	383.8
1939	0.0	-13.23	7.752	0.00	384.6
1942	0.0	-13.25	7.764	0.00	385.2
1945	-0.2	-13.27	7.776	-0.02	385.8
1948	0.0	-13.29	7.788	0.00	386.4
1951	0.0	-13.31	7.800	0.00	387.0
1954	0.2	-13.33	7.812	0.02	387.6
1957	0.2	-13.35	7.824	0.02	388.0
1960	0.0	-13.37	7.836	0.00	388.6
1963	-0.2	-13.39	7.848	-0.02	389.2
1966	-0.2	-13.42	7.860	-0.02	390.2
1969	0.2	-13.44	7.872	0.02	390.6
1972	-0.2	-13.46	7.884	-0.02	391.2
1975	0.0	-13.48	7.896	0.00	391.8
1978	0.0	-13.50	7.908	0.00	392.4
1981	0.0	-13.52	7.920	0.00	393.0
1984	0.2	-13.54	7.932	0.02	393.6
1987	-0.4	-13.56	7.944	-0.04	394.2
1990	-0.2	-13.58	7.956	-0.02	394.8
1993	0.2	-13.61	7.968	0.02	395.6
1996	0.0	-13.63	7.980	0.00	396.2
1999	-0.2	-13.65	7.992	-0.02	396.8
2002	0.0	-13.67	8.004	0.00	397.4
2005	0.4	-13.69	8.016	0.04	398.0
2008	0.2	-13.71	8.028	0.02	398.6
2011	0.2	-13.73	8.040	0.02	399.2
2014	-0.2	-13.75	8.052	-0.02	399.8
2017	0.0	-13.77	8.064	0.00	400.2
2020	0.0	-13.80	8.076	0.00	401.2
2023	-0.2	-13.82	8.088	-0.02	401.8
2026	0.0	-13.84	8.100	0.00	402.4
2029	0.0	-13.86	8.112	0.00	403.0
2032	0.2	-13.88	8.124	0.02	403.4
2035	-0.2	-13.90	8.136	-0.02	404.0
2038	-0.4	-13.92	8.148	-0.04	404.6
2041	-0.2	-13.94	8.160	-0.02	405.2
2044	0.0	-13.96	8.172	0.00	405.8
2047	0.0	-13.99	8.184	0.00	406.6
2050	0.0	-14.01	8.196	0.00	407.2
2053	0.2	-14.03	8.208	0.02	407.8
2056	-0.2	-14.05	8.220	-0.02	408.4
2059	0.0	-14.07	8.232	0.00	409.0
2062	-0.2	-14.09	8.244	-0.02	409.6
2065	0.0	-14.11	8.256	0.00	410.2
2068	0.2	-14.14	8.268	0.02	411.0
2071	-0.2	-14.16	8.280	-0.02	411.6
2074	0.4	-14.18	8.292	0.04	412.2
2077	0.2	-14.20	8.304	0.02	412.8
2080	0.2	-14.22	8.316	0.02	413.4
2083	0.0	-14.24	8.328	0.00	414.0
2086	-0.2	-14.26	8.340	-0.02	414.6
2089	0.6	-14.28	8.352	0.06	415.2
2092	0.0	-14.30	8.364	0.00	415.6
2095	-0.2	-14.33	8.376	-0.02	416.6
2098	0.0	-14.35	8.388	0.00	417.2
2101	0.0	-14.37	8.400	0.00	417.8
2104	0.2	-14.39	8.412	0.02	418.4
2107	0.4	-14.41	8.424	0.04	418.8
2110	0.2	-14.43	8.436	0.02	419.4
2113	0.0	-14.45	8.448	0.00	420.0
2116	-0.2	-14.47	8.460	-0.02	420.6
2119	0.0	-14.49	8.472	0.00	421.2
2122	-0.2	-14.52	8.484	-0.02	422.0
2125	-0.6	-14.54	8.496	-0.06	422.6
2128	0.0	-14.56	8.508	0.00	423.2
2131	0.0	-14.58	8.520	0.00	423.8
2134	0.0	-14.60	8.532	0.00	424.4
2137	0.2	-14.62	8.544	0.02	425.0
2140	0.0	-14.64	8.556	0.00	425.6
2143	0.0	-14.66	8.568	0.00	426.2
2146	0.2	-14.68	8.580	0.02	426.8
2149	0.0	-14.71	8.592	0.00	427.6
2152	0.2	-14.73	8.604	0.02	428.2
2155	0.0	-14.75	8.616	0.00	428.8
2158	0.0	-14.77	8.628	0.00	429.4
2161	0.0	-14.79	8.640	0.00	430.0
2164	-0.2	-14.81	8.652	-0.02	430.6
2167	0.0	-14.83	8.664	0.00	431.2
2170	0.0	-14.85	8.676	0.00	431.6
2173	0.0	-14.87	8.688	0.00	432.2
2176	0.2	-14.90	8.700	0.02	433.2
2179	0.0	-14.92	8.712	0.00	433.8
2182	0.4	-14.94	8.724	0.04	434.4
2185	0.0	-14.96	8.736	0.00	434.8
2188	0.0	-14.98	8.748	0.00	435.4
2191	-0.2	-15.00	8.760	-0.02	436.0
2194	-0.2	-15.02	8.772	-0.02	436.6
2197	0.2	-15.04	8.784	0.02	437.2
2200	0.0	-15.06	8.796	0.00	437.8
2203	0.2	-15.09	8.808	0.02	438.6
2206	0.0	-15.11	8.820	0.00	439.2
2209	-0.2	-15.13	8.832	-0.02	439.8
2212	0.0	-15.15	8.844	0.00	440.4
2215	0.0	-15.17	8.856	0.00	441.0
2218	-0.4	-15.18	8.868	-0.04	441.2
2221	0.0	-15.20	8.880	0.00	441.8
2224	0.0	-15.22	8.892	0.00	442.4
2227	-0.2	-15.24	8.904	-0.02	443.0
2230	0.0	-15.27	8.916	0.00	443.8
2233	-0.6	-15.29	8.928	-0.06	444.4
2236	0.0	-15.31	8.940	0.00	445.0
2239	0.0	-15.33	8.952	0.00	445.6
2242	0.0	-15.35	8.964	0.00	446.2
2245	-0.2	-15.37	8.976	-0.02	446.8
2248	0.0	-15.39	8.988	0.00	447.4
2251	0.0	-15.41	9.000	0.00	448.0
2254	0.2	-15.43	9.012	0.02	448.6
2257	0.2	-15.46	9.024	0.02	449.4
2260	0.2	-15.48	9.036	0.02	450.0
2263	0.2	-15.50	9.048	0.02	450.6
2266	0.0	-15.52	9.060	0.00	451.2
2269	0.0	-15.54	9.072	0.00	451.8
2272	-0.2	-15.56	9.084	-0.02	452.4
2275	0.0	-15.58	9.096	0.00	453.0
2278	-0.2	-15.60	9.108	-0.02	453.4
2281	0.4	-15.62	9.120	0.04	454.0
2284	0.0	-15.65	9.132	0.00	455.0
2287	0.0	-15.67	9.144	0.00	455.6
2290	0.0	-15.69	9.156	0.00	456.2
2293	0.0	-15.71	9.168	0.00	456.6
2296	0.0	-15.73	9.180	0.00	457.2
2299	0.0	-15.75	9.192	0.00	457.8
2302	0.0	-15.77	9.204	0.00	458.4
2305	-0.2	-15.79	9.216	-0.02	459.0
2308	-0.2	-15.81	9.228	-0.02	459.6
2311	0.0	-15.83	9.240	0.00	460.2
2314	0.2	-15.85	9.252	0.02	460.8
2317	0.0	-15.88	9.264	0.00	461.6
2320	-0.2	-15.90	9.276	-0.02	462.2
2323	0.0	-15.92	9.288	0.00	462.8
2326	0.0	-15.94	9.300	0.00	463.4
2329	0.0	-15.96	9.312	0.00	464.0
2332	0.0	-15.98	9.324	0.00	464.6
2335	0.0	-16.00	9.336	0.00	465.2
2338	-0.2	-16.02	9.348	-0.02	465.6
2341	0.2	-16.04	9.360	0.02	466.2
2344	0.0	-16.06	9.372	0.00	466.8
2347	0.0	-16.08	9.384	0.00	467.4
2350	0.0	-16.11	9.396	0.00	468.4
2353	-0.4	-16.13	9.408	-0.04	468.8
2356	0.0	-16.15	9.420	0.00	469.4
2359	0.0	-16.17	9.432	0.00	470.0
2362	0.2	-16.19	9.444	0.02	470.6
2365	0.2	-16.21	9.456	0.02	471.2
2368	0.2	-16.23	9.468	0.02	471.8
2371	0.4	-16.25	9.480	0.04	472.4
2374	0.6	-16.27	9.492	0.06	473.0
2377	0.8	-16.29	9.504	0.08	473.6
2380	1.0	-16.31	9.516	0.10	474.2
2383	1.6	-16.33	9.528	0.16	474.8
2386	1.6	-16.36	9.540	0.16	475.6
2389	2.2	-16.38	9.552	0.22	476.2
2392	1.6	-16.40	9.564	0.16	476.8
2395	2.0	-16.42	9.576	0.20	477.4
2398	2.2	-16.44	9.588	0.22	478.0
2401	2.4	-16.46	9.600	0.24	478.4
2404	2.2	-16.48	9.612	0.22	479.0
2407	2.6	-16.50	9.624	0.26	479.6
2410	2.6	-16.52	9.636	0.26	480.2
2413	2.6	-16.54	9.648	0.26	480.8
2416	2.8	-16.56	9.660	0.28	481.4
2419	3.0	-16.58	9.672	0.32	482.0
2422	3.2	-16.60	9.684	0.34	482.6
2425	3.0	-16.63	9.696	0.32	483.4
2428	3.2	-16.65	9.708	0.34	484.0
2431	3.2	-16.67	9.720	0.34	484.6
2434	3.2	-16.69	9.732	0.34	485.2
2437	3.4	-16.71	9.744	0.36	485.8
2440	3.4	-16.73	9.756	0.36	486.4
2443	3.4	-16.75	9.768	0.36	487.0
2446	3.8	-16.77	9.780	0.40	487.6
2449	3.4	-16.79	9.792	0.36	488.0
2452	3.6	-16.81	9.804	0.38	488.6
2455	3.8	-16.83	9.816	0.40	489.2
2458	3.8	-16.85	9.828	0.40	489.8
2461	4.2	-16.88	9.840	0.44	490.6
2464	4.2	-16.90	9.852	0.44	491.2
2467	4.4	-16.92	9.864	0.46	491.8
2470	4.2	-16.94	9.876	0.44	492.4
2473	4.6	-16.96	9.888	0.48	493.0
2476	4.8	-16.98	9.900	0.50	493.6
2479	5.0	-17.00	9.912	0.52	494.2
2482	5.2	-17.02	9.924	0.54	494.8
2485	5.2	-17.04	9.936	0.54	495.4
2488	5.2	-17.06	9.948	0.54	496.0
2491	5.6	-17.08	9.960	0.58	496.6
2494	5.6	-17.10	9.972	0.58	497.0
2497	5.4	-17.12	9.984	0.56	497.6
2500	6.0	-17.15	9.996	0.62	498.6
2503	6.0	-17.16	10.008	0.62	498.8
2506	6.4	-17.20	10.020	0.66	500.0
2509	6.6	-17.22	10.032	0.68	500.6
2512	7.0	-17.24	10.044	0.72	501.2
2515	7.2	-17.26	10.056	0.74	501.8
2518	7.4	-17.28	10.068	0.76	502.4
2521	8.0	-17.30	10.080	0.82	503.0
2524	7.8	-17.32	10.092	0.80	503.4
2527	8.2	-17.34	10.104	0.84	504.0
2530	8.6	-17.36	10.116	0.88	504.6
2533	9.0	-17.38	10.128	0.94	505.2
2536	9.4	-17.40	10.140	0.98	505.8
2539	9.6	-17.42	10.152	1.00	506.4
2542	10.4	-17.44	10.164	1.08	507.0
2545	10.6	-17.46	10.176	1.10	507.6
2548	11.2	-17.48	10.188	1.16	508.2
2551	11.2	-17.50	10.200	1.16	508.8
2554	11.8	-17.53	10.212	1.22	509.6
2557	12.2	-17.54	10.224	1.26	509.8
2560	12.8	-17.57	10.236	1.32	510.8
2563	13.4	-17.59	10.248	1.38	511.4
2566	13.8	-17.61	10.260	1.42	512.0
2569	14.4	-17.63	10.272	1.48	512.4
2572	14.8	-17.65	10.284	1.52	513.0
2575	15.4	-17.67	10.296	1.60	513.6
2578	15.8	-17.69	10.308	1.64	514.2
2581	16.8	-17.71	10.320	1.74	514.8
2584	17.0	-17.73	10.332	1.76	515.4
2587	17.6	-17.75	10.344	1.82	516.0
2590	18.2	-17.77	10.356	1.88	516.6
2593	19.0	-17.79	10.368	1.96	517.2
2596	19.2	-17.81	10.380	1.98	517.8
2599	19.6	-17.83	10.392	2.02	518.4
2602	19.4	-17.85	10.404	2.00	518.8
2605	18.4	-17.87	10.416	1.90	519.4
2608	17.0	-17.90	10.428	1.76	520.4
2611	3.6	-17.93	10.440	0.38	521.2
2614	0.0	-17.95	10.452	0.00	521.8
2617	0.0	-17.97	10.464	0.00	522.4
2620	0.0	-17.99	10.476	0.00	523.0
2623	-0.2	-18.01	10.488	-0.02	523.6
2626	-0.2	-18.03	10.500	-0.02	524.2
2629	-0.2	-18.06	10.512	-0.02	525.0
2632	0.0	-18.08	10.524	0.00	525.6
2635	-0.2	-18.10	10.536	-0.02	526.2
2638	0.0	-18.12	10.548	0.00	526.8
2641	-0.2	-18.14	10.560	-0.02	527.4
2644	0.0	-18.16	10.572	0.00	528.0
2647	0.0	-18.18	10.584	0.00	528.4
2650	0.0	-18.20	10.596	0.00	529.0
2653	-0.2	-18.22	10.608	-0.02	529.6
2656	0.0	-18.24	10.620	0.00	530.2
2659	0.0	-18.26	10.632	0.00	530.8
2662	0.0	-18.29	10.644	0.00	531.6
2665	-0.4	-18.31	10.656	-0.04	532.2
2668	0.2	-18.33	10.668	0.02	532.8
2671	0.0	-18.35	10.680	0.00	533.4
2674	0.0	-18.37	10.692	0.00	534.0
2677	0.0	-18.39	10.704	0.00	534.6
2680	0.0	-18.41	10.716	0.00	535.2
2683	0.4	-18.43	10.728	0.04	535.8
2686	0.0	-18.45	10.740	0.00	536.4
2689	0.2	-18.48	10.752	0.02	537.2
2692	0.4	-18.50	10.764	0.04	537.8
2695	0.8	-18.52	10.776	0.08	538.4
2698	0.6	-18.54	10.788	0.06	539.0
2701	0.8	-18.56	10.800	0.08	539.6
2704	0.8	-18.58	10.812	0.08	540.2
2707	0.6	-18.60	10.824	0.06	540.6
2710	0.8	-18.62	10.836	0.08	541.2
2713	1.2	-18.64	10.848	0.12	541.8
2716	1.4	-18.67	10.860	0.14	542.8
2719	1.4	-18.69	10.872	0.14	543.4
2722	2.0	-18.71	10.884	0.20	543.8
2725	2.0	-18.73	10.896	0.20	544.4
2728	2.8	-18.75	10.908	0.28	545.0
2731	3.0	-18.77	10.920	0.32	545.6
2734	3.6	-18.79	10.932	0.38	546.2
2737	4.2	-18.81	10.944	0.44	546.8
2740	4.6	-18.83	10.956	0.48	547.4
2743	5.0	-18.85	10.968	0.52	548.0
2746	5.6	-18.87	10.980	0.58	548.6
2749	6.0	-18.89	10.992	0.62	549.2
2752	6.6	-18.92	11.004	0.68	550.0
2755	6.8	-18.94	11.016	0.70	550.6
2758	7.4	-18.96	11.028	0.76	551.2
2761	8.0	-18.98	11.040	0.82	551.8
2764	8.6	-19.00	11.052	0.88	552.4
2767	8.8	-19.02	11.064	0.90	553.0
2770	9.4	-19.04	11.076	0.98	553.4
2773	10.2	-19.06	11.088	1.06	554.0
2776	11.0	-19.08	11.100	1.14	554.6
2779	11.4	-19.10	11.112	1.18	555.2
2782	12.2	-19.12	11.124	1.26	555.8
2785	12.8	-19.14	11.136	1.32	556.4
2788	13.8	-19.16	11.148	1.42	557.0
2791	14.4	-19.17	11.160	1.48	557.2
2794	14.8	-19.19	11.172	1.52	557.8
2797	15.4	-19.22	11.184	1.60	558.8
2800	16.0	-19.24	11.196	1.66	559.4
2803	16.2	-19.26	11.208	1.68	559.8
2806	16.6	-19.28	11.220	1.72	560.4
2809	16.6	-19.30	11.232	1.72	561.0
2812	17.2	-19.32	11.244	1.78	561.6
2815	17.2	-19.34	11.256	1.78	562.2
2818	17.6	-19.36	11.268	1.82	562.8
2821	17.4	-19.38	11.280	1.80	563.4
2824	17.6	-19.40	11.292	1.82	564.0
2827	17.6	-19.42	11.304	1.82	564.6
2830	18.0	-19.44	11.316	1.86	565.2
2833	18.0	-19.47	11.328	1.86	566.0
2836	18.4	-19.49	11.340	1.90	566.6
2839	18.6	-19.51	11.352	1.92	567.2
2842	18.6	-19.53	11.364	1.92	567.8
2845	19.0	-19.55	11.376	1.96	568.4
2848	19.6	-19.57	11.388	2.02	568.8
2851	20.6	-19.59	11.400	2.12	569.4
2854	22.8	-19.61	11.412	2.36	570.0
2857	24.6	-19.63	11.424	2.54	570.6
2860	28.0	-19.65	11.436	2.90	571.2
2863	30.0	-19.67	11.448	3.10	571.8
2866	32.0	-19.69	11.460	3.30	572.4
2869	34.4	-19.70	11.472	3.56	572.6
2872	36.0	-19.73	11.484	3.72	573.6
2875	37.6	-19.74	11.496	3.88	573.8
2878	39.0	-19.77	11.508	4.04	574.8
2881	40.6	-19.79	11.520	4.20	575.2
2884	41.2	-19.81	11.532	4.26	575.8
2887	42.4	-19.82	11.544	4.38	576.2
2890	43.8	-19.84	11.556	4.52	576.8
2893	45.2	-19.86	11.568	4.68	577.4
2896	46.4	-19.88	11.580	4.80	578.0
2899	47.8	-19.91	11.592	4.94	578.8
2902	48.8	-19.93	11.604	5.04	579.4
2905	50.4	-19.94	11.616	5.20	579.6
2908	51.6	-19.96	11.628	5.34	580.2
2911	52.8	-19.98	11.640	5.46	580.8
2914	54.2	-20.00	11.652	5.60	581.4
2917	55.4	-20.03	11.664	5.72	582.2
2920	57.0	-20.05	11.676	5.90	582.8
2923	58.0	-20.07	11.688	6.00	583.4
2926	60.2	-20.08	11.700	6.22	583.8
2929	61.8	-20.10	11.712	6.38	584.4
2932	63.4	-20.12	11.724	6.56	584.8
2935	65.2	-20.14	11.736	6.74	585.4
2938	66.8	-20.16	11.748	6.90	586.0
2941	69.0	-20.18	11.760	7.14	586.6
2944	70.6	-20.20	11.772	7.30	587.2
2947	73.0	-20.22	11.784	7.54	587.8
2950	74.4	-20.24	11.796	7.68	588.4
2953	76.2	-20.26	11.808	7.88	589.0
2956	77.6	-20.28	11.820	8.02	589.6
2959	78.2	-20.30	11.832	8.08	590.2
2962	80.2	-20.32	11.844	8.28	590.6
2965	81.0	-20.34	11.856	8.38	591.2
2968	82.4	-20.36	11.868	8.52	591.8
2971	82.4	-20.38	11.880	8.52	592.4
2974	83.2	-20.40	11.892	8.60	593.0
2977	84.0	-20.42	11.904	8.68	593.6
2980	85.0	-20.44	11.916	8.78	594.2
2983	85.6	-20.46	11.928	8.84	594.8
2986	85.6	-20.48	11.940	8.84	595.4
2989	86.6	-20.50	11.952	8.94	596.0
2992	88.0	-20.52	11.964	9.10	596.6
2995	90.0	-20.54	11.976	9.30	597.0
2998	92.0	-20.56	11.988	9.50	597.6
3001	94.8	-20.58	12.000	9.80	598.2
3004	96.8	-20.60	12.012	10.00	598.8
3007	99.6	-20.62	12.024	10.30	599.4
3010	101.4	-20.64	12.036	10.48	600.0
3013	103.8	-20.66	12.048	10.72	600.6
3016	106.0	-20.68	12.060	10.96	601.2
3019	107.6	-20.69	12.072	11.12	601.4
3022	109.8	-20.71	12.084	11.34	602.0
3025	110.6	-20.73	12.096	11.44	602.6
3028	112.4	-20.75	12.108	11.62	603.2
3031	113.6	-20.77	12.120	11.74	603.8
3034	115.6	-20.79	12.132	11.94	604.4
3037	117.8	-20.81	12.144	12.18	605.0
3040	120.2	-20.83	12.156	12.42	605.6
3043	121.8	-20.85	12.168	12.58	606.2
3046	123.6	-20.87	12.180	12.78	606.6
3049	124.8	-20.89	12.192	12.90	607.2
3052	126.0	-20.91	12.204	13.02	607.8
3055	127.6	-20.93	12.216	13.18	608.4
3058	128.2	-20.95	12.228	13.24	609.0
3061	129.6	-20.97	12.240	13.40	609.6
3064	131.0	-20.99	12.252	13.54	610.2
3067	132.0	-21.01	12.264	13.64	610.8
3070	133.6	-21.03	12.276	13.80	611.4
3073	134.4	-21.05	12.288	13.88	612.0
3076	136.0	-21.07	12.300	14.06	612.6
3079	137.2	-21.09	12.312	14.18	613.0
3082	139.4	-21.11	12.324	14.40	613.6
3085	140.6	-21.12	12.336	14.54	614.0
3088	142.0	-21.14	12.348	14.68	614.6
3091	144.4	-21.16	12.360	14.92	615.2
3094	146.8	-21.18	12.372	15.18	615.6
3097	150.0	-21.20	12.384	15.50	616.2
3100	152.0	-21.22	12.396	15.70	616.8
3103	154.8	-21.24	12.408	16.00	617.4
3106	157.0	-21.25	12.420	16.22	617.8
3109	160.4	-21.28	12.432	16.58	618.6
3112	162.6	-21.29	12.444	16.80	618.8
3115	165.8	-21.31	12.456	17.14	619.4
3118	168.6	-21.33	12.468	17.42	620.0
3121	171.6	-21.35	12.480	17.74	620.6
3124	175.8	-21.36	12.492	18.16	621.0
3127	179.2	-21.38	12.504	18.52	621.6
3130	184.2	-21.40	12.516	19.04	622.0
3133	188.4	-21.42	12.528	19.48	622.6
3136	189.0	-21.43	12.540	19.54	623.0
3139	181.0	-21.43	12.552	18.70	623.0
3142	175.4	-21.44	12.564	18.12	623.2
3145	172.0	-21.44	12.576	17.78	623.2
3148	169.2	-21.45	12.588	17.48	623.6
3151	167.2	-21.45	12.600	17.28	623.6
3154	165.2	-21.45	12.612	17.08	623.6
3157	163.8	-21.45	12.624	16.92	623.6
3160	162.4	-21.45	12.636	16.78	623.6
3163	161.2	-21.45	12.648	16.66	623.6
3166	160.2	-21.45	12.660	16.56	623.6
3169	159.4	-21.45	12.672	16.48	623.6
3172	158.6	-21.46	12.684	16.40	623.8
3175	157.8	-21.46	12.696	16.30	623.8
3178	156.8	-21.46	12.708	16.20	623.8
3181	191.0	-21.42	12.720	16.16	623.8