File: results/youngs-modulus/2025-04-21/inconclusive-data/pf11mt02.csv
sep=
pf11mt02

System Information:
IntelliMESUR Version: 2.2.1
Test Frame Model: F505
Test Frame Serial Number: 4418651
Test Frame Capacity: 500 lbF / 2.2 kN
Test Frame Firmware Version: 1.00.14
Force Sensor Model: FS05-100
Force Sensor Capacity: 500 N
Force Sensor Resolution: 0.2 N
Force Sensor Serial Number: 4425350
Calibration Date: Apr 29, 2024
Calibration Due Date: Apr 29, 2025

Reading	Load [N]	Distance [mm]	Time [s]	Stress [MPa]	Strain [%]
1	0.2	0.00	0.000	0.02	0.0
4	0.2	0.00	0.012	0.02	0.0
7	0.2	0.00	0.024	0.02	0.0
10	0.2	0.00	0.036	0.02	0.0
13	0.2	0.00	0.048	0.02	0.0
16	0.2	0.00	0.060	0.02	0.0
19	0.2	0.00	0.072	0.02	0.0
22	0.4	0.00	0.084	0.06	0.0
25	0.4	0.00	0.096	0.06	0.0
28	0.2	0.00	0.108	0.02	0.0
31	0.2	0.00	0.120	0.02	0.0
34	0.0	0.00	0.132	0.00	0.0
37	0.2	0.00	0.144	0.02	0.0
40	0.2	0.00	0.156	0.02	0.0
43	0.4	0.00	0.168	0.06	0.0
46	0.2	0.00	0.180	0.02	0.0
49	0.2	0.00	0.192	0.02	0.0
52	0.2	-0.03	0.204	0.02	1.0
55	0.0	-0.05	0.216	0.00	1.6
58	0.4	-0.07	0.228	0.06	2.2
61	0.2	-0.09	0.240	0.02	3.0
64	0.2	-0.11	0.252	0.02	3.6
67	0.2	-0.13	0.264	0.02	4.2
70	0.2	-0.15	0.276	0.02	4.8
73	0.4	-0.18	0.288	0.06	5.8
76	0.2	-0.20	0.300	0.02	6.4
79	0.2	-0.22	0.312	0.02	7.2
82	0.0	-0.24	0.324	0.00	7.8
85	0.4	-0.25	0.336	0.06	8.0
88	0.2	-0.27	0.348	0.02	8.8
91	0.2	-0.29	0.360	0.02	9.4
94	0.0	-0.31	0.372	0.00	10.0
97	0.2	-0.33	0.384	0.02	10.6
100	0.0	-0.36	0.396	0.00	11.6
103	0.4	-0.38	0.408	0.06	12.2
106	0.2	-0.40	0.420	0.02	13.0
109	0.0	-0.42	0.432	0.00	13.6
112	0.2	-0.44	0.444	0.02	14.2
115	0.0	-0.46	0.456	0.00	14.8
118	0.2	-0.48	0.468	0.02	15.6
121	0.2	-0.50	0.480	0.02	16.2
124	0.2	-0.52	0.492	0.02	16.8
127	0.2	-0.55	0.504	0.02	17.8
130	0.4	-0.57	0.516	0.06	18.4
133	0.2	-0.59	0.528	0.02	19.0
136	0.2	-0.61	0.540	0.02	19.8
139	0.2	-0.63	0.552	0.02	20.4
142	0.2	-0.65	0.564	0.02	21.0
145	0.2	-0.67	0.576	0.02	21.6
148	-0.2	-0.69	0.588	-0.02	22.4
151	0.4	-0.71	0.600	0.06	23.0
154	0.2	-0.73	0.612	0.02	23.6
157	0.8	-0.76	0.624	0.12	24.6
160	0.6	-0.78	0.636	0.08	25.2
163	0.2	-0.80	0.648	0.02	25.8
166	0.2	-0.82	0.660	0.02	26.6
169	0.2	-0.84	0.672	0.02	27.2
172	0.4	-0.86	0.684	0.06	27.8
175	0.2	-0.88	0.696	0.02	28.4
178	0.2	-0.90	0.708	0.02	29.2
181	0.4	-0.92	0.720	0.06	29.8
184	0.2	-0.94	0.732	0.02	30.4
187	0.2	-0.97	0.744	0.02	31.4
190	0.2	-0.99	0.756	0.02	32.0
193	0.2	-1.01	0.768	0.02	32.6
196	-0.4	-1.03	0.780	-0.06	33.4
199	0.2	-1.05	0.792	0.02	34.0
202	0.2	-1.07	0.804	0.02	34.6
205	0.0	-1.09	0.816	0.00	35.2
208	0.2	-1.11	0.828	0.02	36.0
211	0.2	-1.13	0.840	0.02	36.6
214	0.4	-1.15	0.852	0.06	37.2
217	0.2	-1.17	0.864	0.02	37.8
220	0.0	-1.19	0.876	0.00	38.6
223	0.2	-1.22	0.888	0.02	39.4
226	0.2	-1.25	0.900	0.02	40.4
229	0.2	-1.27	0.912	0.02	41.2
232	0.2	-1.29	0.924	0.02	41.8
235	0.4	-1.31	0.936	0.06	42.4
238	0.2	-1.33	0.948	0.02	43.0
241	-0.2	-1.35	0.960	-0.02	43.6
244	-0.2	-1.37	0.972	-0.02	44.4
247	0.2	-1.39	0.984	0.02	45.0
250	0.0	-1.42	0.996	0.00	46.0
253	0.2	-1.44	1.008	0.02	46.6
256	0.2	-1.46	1.020	0.02	47.2
259	0.2	-1.48	1.032	0.02	47.8
262	0.2	-1.50	1.044	0.02	48.6
265	0.2	-1.52	1.056	0.02	49.2
268	0.4	-1.54	1.068	0.06	49.8
271	0.4	-1.56	1.080	0.06	50.4
274	0.2	-1.58	1.092	0.02	51.2
277	0.2	-1.60	1.104	0.02	51.8
280	0.2	-1.62	1.116	0.02	52.4
283	0.2	-1.65	1.128	0.02	53.4
286	0.2	-1.66	1.140	0.02	53.8
289	0.2	-1.69	1.152	0.02	54.6
292	0.2	-1.71	1.164	0.02	55.4
295	0.2	-1.73	1.176	0.02	56.0
298	0.2	-1.75	1.188	0.02	56.6
301	0.4	-1.77	1.200	0.06	57.2
304	0.2	-1.79	1.212	0.02	58.0
307	0.0	-1.81	1.224	0.00	58.6
310	-0.2	-1.83	1.236	-0.02	59.2
313	0.4	-1.85	1.248	0.06	59.8
316	0.2	-1.87	1.260	0.02	60.6
319	0.2	-1.89	1.272	0.02	61.2
322	0.2	-1.92	1.284	0.02	62.2
325	0.0	-1.94	1.296	0.00	62.8
328	0.0	-1.96	1.308	0.00	63.4
331	0.2	-1.98	1.320	0.02	64.0
334	0.0	-2.00	1.332	0.00	64.8
337	0.2	-2.02	1.344	0.02	65.4
340	0.2	-2.04	1.356	0.02	66.0
343	0.2	-2.06	1.368	0.02	66.6
346	0.0	-2.08	1.380	0.00	67.4
349	0.2	-2.10	1.392	0.02	68.0
352	0.2	-2.12	1.404	0.02	68.6
355	0.2	-2.14	1.416	0.02	69.2
358	0.0	-2.17	1.428	0.00	70.2
361	0.2	-2.19	1.440	0.02	70.8
364	0.4	-2.21	1.452	0.06	71.6
367	0.2	-2.23	1.464	0.02	72.2
370	0.2	-2.24	1.476	0.02	72.4
373	0.2	-2.26	1.488	0.02	73.2
376	0.0	-2.28	1.500	0.00	73.8
379	0.4	-2.30	1.512	0.06	74.4
382	0.2	-2.32	1.524	0.02	75.0
385	0.0	-2.34	1.536	0.00	75.8
388	0.2	-2.36	1.548	0.02	76.4
391	0.2	-2.39	1.560	0.02	77.4
394	0.0	-2.41	1.572	0.00	78.0
397	0.4	-2.43	1.584	0.06	78.6
400	0.4	-2.45	1.596	0.06	79.2
403	0.4	-2.47	1.608	0.06	80.0
406	0.2	-2.49	1.620	0.02	80.6
409	0.2	-2.51	1.632	0.02	81.2
412	0.4	-2.53	1.644	0.06	81.8
415	0.2	-2.55	1.656	0.02	82.6
418	0.0	-2.57	1.668	0.00	83.2
421	0.0	-2.59	1.680	0.00	83.8
424	0.2	-2.62	1.692	0.02	84.8
427	0.0	-2.64	1.704	0.00	85.4
430	0.2	-2.66	1.716	0.02	86.0
433	0.4	-2.68	1.728	0.06	86.8
436	0.4	-2.70	1.740	0.06	87.4
439	0.2	-2.72	1.752	0.02	88.0
442	0.2	-2.74	1.764	0.02	88.6
445	0.0	-2.76	1.776	0.00	89.4
448	0.0	-2.78	1.788	0.00	90.0
451	-0.2	-2.80	1.800	-0.02	90.6
454	0.0	-2.82	1.812	0.00	91.2
457	0.2	-2.85	1.824	0.02	92.2
460	0.2	-2.87	1.836	0.02	92.8
463	0.2	-2.89	1.848	0.02	93.6
466	-0.2	-2.91	1.860	-0.02	94.2
469	0.2	-2.93	1.872	0.02	94.8
472	0.2	-2.95	1.884	0.02	95.4
475	0.2	-2.97	1.896	0.02	96.2
478	0.4	-2.99	1.908	0.06	96.8
481	0.0	-3.01	1.920	0.00	97.4
484	0.4	-3.03	1.932	0.06	98.0
487	0.2	-3.06	1.944	0.02	99.0
490	0.2	-3.08	1.956	0.02	99.6
493	0.0	-3.10	1.968	0.00	100.4
496	0.4	-3.12	1.980	0.06	101.0
499	0.2	-3.14	1.992	0.02	101.6
502	0.2	-3.16	2.004	0.02	102.2
505	0.2	-3.18	2.016	0.02	103.0
508	0.0	-3.20	2.028	0.00	103.6
511	0.2	-3.22	2.040	0.02	104.2
514	0.0	-3.25	2.052	0.00	105.2
517	0.2	-3.27	2.064	0.02	105.8
520	0.2	-3.30	2.076	0.02	106.8
523	0.2	-3.32	2.088	0.02	107.4
526	0.0	-3.34	2.100	0.00	108.0
529	0.4	-3.36	2.112	0.06	108.8
532	0.2	-3.38	2.124	0.02	109.4
535	0.2	-3.40	2.136	0.02	110.0
538	0.2	-3.42	2.148	0.02	110.6
541	0.2	-3.44	2.160	0.02	111.4
544	0.2	-3.46	2.172	0.02	112.0
547	0.2	-3.49	2.184	0.02	113.0
550	0.4	-3.51	2.196	0.06	113.6
553	0.0	-3.53	2.208	0.00	114.2
556	0.2	-3.55	2.220	0.02	114.8
559	0.0	-3.57	2.232	0.00	115.6
562	0.4	-3.59	2.244	0.06	116.2
565	0.0	-3.61	2.256	0.00	116.8
568	0.0	-3.63	2.268	0.00	117.4
571	0.2	-3.65	2.280	0.02	118.2
574	0.0	-3.68	2.292	0.00	119.0
577	0.2	-3.70	2.304	0.02	119.8
580	0.0	-3.72	2.316	0.00	120.4
583	0.0	-3.74	2.328	0.00	121.0
586	0.0	-3.76	2.340	0.00	121.6
589	0.2	-3.78	2.352	0.02	122.4
592	0.2	-3.80	2.364	0.02	123.0
595	0.0	-3.82	2.376	0.00	123.6
598	0.4	-3.84	2.388	0.06	124.2
601	0.2	-3.87	2.400	0.02	125.2
604	0.2	-3.89	2.412	0.02	125.8
607	0.2	-3.91	2.424	0.02	126.6
610	0.2	-3.93	2.436	0.02	127.2
613	0.2	-3.95	2.448	0.02	127.8
616	0.0	-3.97	2.460	0.00	128.4
619	0.2	-3.99	2.472	0.02	129.2
622	0.0	-4.01	2.484	0.00	129.8
625	0.2	-4.03	2.496	0.02	130.4
628	0.2	-4.06	2.508	0.02	131.4
631	0.4	-4.08	2.520	0.06	132.0
634	0.0	-4.10	2.532	0.00	132.6
637	0.4	-4.12	2.544	0.06	133.4
640	0.0	-4.14	2.556	0.00	134.0
643	0.2	-4.16	2.568	0.02	134.6
646	0.2	-4.18	2.580	0.02	135.2
649	0.2	-4.20	2.592	0.02	136.0
652	0.2	-4.22	2.604	0.02	136.6
655	0.4	-4.25	2.616	0.06	137.6
658	0.2	-4.27	2.628	0.02	138.2
661	-0.2	-4.29	2.640	-0.02	138.8
664	0.2	-4.31	2.652	0.02	139.4
667	0.2	-4.33	2.664	0.02	140.2
670	0.2	-4.35	2.676	0.02	140.8
673	0.2	-4.37	2.688	0.02	141.4
676	-0.2	-4.39	2.700	-0.02	142.0
679	0.2	-4.41	2.712	0.02	142.8
682	0.2	-4.44	2.724	0.02	143.6
685	0.4	-4.46	2.736	0.06	144.4
688	-0.2	-4.48	2.748	-0.02	145.0
691	0.2	-4.50	2.760	0.02	145.6
694	0.6	-4.52	2.772	0.08	146.2
697	0.2	-4.54	2.784	0.02	147.0
700	0.2	-4.56	2.796	0.02	147.6
703	0.4	-4.58	2.808	0.06	148.2
706	0.2	-4.60	2.820	0.02	148.8
709	0.2	-4.63	2.832	0.02	149.8
712	0.4	-4.65	2.844	0.06	150.4
715	0.0	-4.67	2.856	0.00	151.2
718	0.2	-4.69	2.868	0.02	151.8
721	0.2	-4.71	2.880	0.02	152.4
724	0.2	-4.73	2.892	0.02	153.0
727	0.2	-4.75	2.904	0.02	153.8
730	0.4	-4.77	2.916	0.06	154.4
733	0.4	-4.79	2.928	0.06	155.0
736	0.2	-4.82	2.940	0.02	156.0
739	0.2	-4.84	2.952	0.02	156.6
742	0.2	-4.86	2.964	0.02	157.2
745	0.2	-4.88	2.976	0.02	158.0
748	0.2	-4.90	2.988	0.02	158.6
751	0.0	-4.92	3.000	0.00	159.2
754	0.0	-4.94	3.012	0.00	159.8
757	0.0	-4.96	3.024	0.00	160.6
760	0.2	-4.98	3.036	0.02	161.2
763	0.2	-5.01	3.048	0.02	162.2
766	0.2	-5.03	3.060	0.02	162.8
769	0.4	-5.05	3.072	0.06	163.4
772	0.0	-5.07	3.084	0.00	164.0
775	0.4	-5.09	3.096	0.06	164.8
778	0.2	-5.11	3.108	0.02	165.4
781	0.2	-5.13	3.120	0.02	166.0
784	0.2	-5.15	3.132	0.02	166.6
787	0.0	-5.17	3.144	0.00	167.4
790	0.2	-5.20	3.156	0.02	168.2
793	0.0	-5.22	3.168	0.00	169.0
796	0.2	-5.24	3.180	0.02	169.6
799	0.0	-5.26	3.192	0.00	170.2
802	0.2	-5.28	3.204	0.02	170.8
805	0.2	-5.30	3.216	0.02	171.6
808	0.2	-5.32	3.228	0.02	172.2
811	0.2	-5.34	3.240	0.02	172.8
814	0.4	-5.36	3.252	0.06	173.4
817	0.2	-5.39	3.264	0.02	174.4
820	0.4	-5.41	3.276	0.06	175.0
823	0.2	-5.43	3.288	0.02	175.8
826	0.2	-5.45	3.300	0.02	176.4
829	0.4	-5.47	3.312	0.06	177.0
832	0.4	-5.49	3.324	0.06	177.6
835	0.2	-5.51	3.336	0.02	178.4
838	0.2	-5.53	3.348	0.02	179.0
841	0.2	-5.55	3.360	0.02	179.6
844	0.2	-5.58	3.372	0.02	180.6
847	0.4	-5.60	3.384	0.06	181.2
850	0.2	-5.62	3.396	0.02	181.8
853	0.2	-5.64	3.408	0.02	182.6
856	0.4	-5.66	3.420	0.06	183.2
859	0.2	-5.68	3.432	0.02	183.8
862	0.4	-5.70	3.444	0.06	184.4
865	0.2	-5.72	3.456	0.02	185.2
868	0.0	-5.74	3.468	0.00	185.8
871	0.4	-5.76	3.480	0.06	186.4
874	0.2	-5.78	3.492	0.02	187.0
877	0.2	-5.81	3.504	0.02	188.0
880	0.2	-5.83	3.516	0.02	188.6
883	0.2	-5.85	3.528	0.02	189.4
886	0.4	-5.87	3.540	0.06	190.0
889	0.2	-5.89	3.552	0.02	190.6
892	0.4	-5.91	3.564	0.06	191.2
895	0.2	-5.93	3.576	0.02	192.0
898	0.0	-5.95	3.588	0.00	192.6
901	0.2	-5.97	3.600	0.02	193.2
904	0.0	-5.99	3.612	0.00	193.8
907	0.2	-6.02	3.624	0.02	194.8
910	0.2	-6.04	3.636	0.02	195.4
913	0.2	-6.06	3.648	0.02	196.2
916	0.2	-6.08	3.660	0.02	196.8
919	0.2	-6.10	3.672	0.02	197.4
922	0.2	-6.12	3.684	0.02	198.0
925	0.2	-6.14	3.696	0.02	198.8
928	0.0	-6.16	3.708	0.00	199.4
931	0.4	-6.18	3.720	0.06	200.0
934	0.2	-6.20	3.732	0.02	200.6
937	0.2	-6.22	3.744	0.02	201.2
940	-0.2	-6.24	3.756	-0.02	202.0
943	0.2	-6.26	3.768	0.02	202.6
946	0.2	-6.28	3.780	0.02	203.2
949	0.2	-6.30	3.792	0.02	203.8
952	0.2	-6.32	3.804	0.02	204.6
955	0.2	-6.34	3.816	0.02	205.2
958	0.6	-6.36	3.828	0.08	205.8
961	0.2	-6.38	3.840	0.02	206.4
964	0.2	-6.40	3.852	0.02	207.2
967	0.0	-6.42	3.864	0.00	207.8
970	0.2	-6.44	3.876	0.02	208.4
973	0.2	-6.47	3.888	0.02	209.4
976	0.2	-6.48	3.900	0.02	209.8
979	0.2	-6.51	3.912	0.02	210.6
982	-0.2	-6.53	3.924	-0.02	211.4
985	0.2	-6.55	3.936	0.02	212.0
988	-0.2	-6.57	3.948	-0.02	212.6
991	0.2	-6.59	3.960	0.02	213.2
994	0.4	-6.61	3.972	0.06	214.0
997	0.2	-6.63	3.984	0.02	214.6
1000	0.0	-6.65	3.996	0.00	215.2
1003	0.2	-6.67	4.008	0.02	215.8
1006	0.2	-6.69	4.020	0.02	216.6
1009	0.2	-6.71	4.032	0.02	217.2
1012	0.2	-6.74	4.044	0.02	218.2
1015	0.0	-6.76	4.056	0.00	218.8
1018	0.2	-6.78	4.068	0.02	219.4
1021	0.2	-6.80	4.080	0.02	220.0
1024	0.0	-6.82	4.092	0.00	220.8
1027	0.2	-6.84	4.104	0.02	221.4
1030	0.2	-6.86	4.116	0.02	222.0
1033	0.2	-6.88	4.128	0.02	222.6
1036	0.2	-6.90	4.140	0.02	223.4
1039	0.6	-6.92	4.152	0.08	224.0
1042	0.0	-6.94	4.164	0.00	224.6
1045	0.2	-6.96	4.176	0.02	225.2
1048	0.2	-6.99	4.188	0.02	226.2
1051	0.2	-7.01	4.200	0.02	226.8
1054	0.2	-7.03	4.212	0.02	227.6
1057	0.2	-7.05	4.224	0.02	228.2
1060	0.4	-7.07	4.236	0.06	228.8
1063	0.2	-7.09	4.248	0.02	229.4
1066	0.2	-7.11	4.260	0.02	230.0
1069	0.0	-7.13	4.272	0.00	230.8
1072	0.2	-7.15	4.284	0.02	231.4
1075	0.0	-7.17	4.296	0.00	232.0
1078	0.0	-7.19	4.308	0.00	232.6
1081	0.4	-7.22	4.320	0.06	233.6
1084	0.2	-7.25	4.332	0.02	234.6
1087	0.2	-7.27	4.344	0.02	235.2
1090	0.0	-7.29	4.356	0.00	236.0
1093	0.2	-7.31	4.368	0.02	236.6
1096	0.2	-7.33	4.380	0.02	237.2
1099	0.2	-7.35	4.392	0.02	237.8
1102	0.0	-7.37	4.404	0.00	238.6
1105	0.2	-7.39	4.416	0.02	239.2
1108	0.2	-7.41	4.428	0.02	239.8
1111	0.2	-7.43	4.440	0.02	240.4
1114	0.0	-7.45	4.452	0.00	241.2
1117	0.0	-7.47	4.464	0.00	241.8
1120	0.2	-7.50	4.476	0.02	242.8
1123	0.2	-7.52	4.488	0.02	243.4
1126	0.4	-7.54	4.500	0.06	244.0
1129	0.2	-7.56	4.512	0.02	244.6
1132	0.2	-7.58	4.524	0.02	245.4
1135	0.0	-7.60	4.536	0.00	246.0
1138	0.4	-7.62	4.548	0.06	246.6
1141	0.2	-7.64	4.560	0.02	247.2
1144	0.0	-7.66	4.572	0.00	247.8
1147	0.2	-7.68	4.584	0.02	248.6
1150	0.2	-7.70	4.596	0.02	249.2
1153	0.2	-7.72	4.608	0.02	249.8
1156	0.2	-7.75	4.620	0.02	250.8
1159	0.2	-7.77	4.632	0.02	251.4
1162	0.2	-7.79	4.644	0.02	252.2
1165	0.2	-7.81	4.656	0.02	252.8
1168	0.2	-7.83	4.668	0.02	253.4
1171	0.2	-7.85	4.680	0.02	254.0
1174	0.2	-7.87	4.692	0.02	254.6
1177	0.0	-7.89	4.704	0.00	255.4
1180	0.4	-7.91	4.716	0.06	256.0
1183	0.2	-7.93	4.728	0.02	256.6
1186	0.0	-7.95	4.740	0.00	257.2
1189	0.2	-7.98	4.752	0.02	258.2
1192	0.2	-8.00	4.764	0.02	258.8
1195	0.0	-8.02	4.776	0.00	259.6
1198	0.2	-8.04	4.788	0.02	260.2
1201	0.2	-8.06	4.800	0.02	260.8
1204	0.2	-8.08	4.812	0.02	261.4
1207	0.2	-8.10	4.824	0.02	262.2
1210	0.4	-8.12	4.836	0.06	262.8
1213	0.2	-8.14	4.848	0.02	263.4
1216	0.2	-8.17	4.860	0.02	264.4
1219	0.2	-8.19	4.872	0.02	265.0
1222	0.2	-8.21	4.884	0.02	265.6
1225	0.2	-8.23	4.896	0.02	266.4
1228	0.2	-8.25	4.908	0.02	267.0
1231	0.2	-8.27	4.920	0.02	267.6
1234	0.2	-8.29	4.932	0.02	268.2
1237	0.2	-8.31	4.944	0.02	269.0
1240	0.0	-8.33	4.956	0.00	269.6
1243	0.2	-8.35	4.968	0.02	270.2
1246	0.2	-8.37	4.980	0.02	270.8
1249	0.2	-8.40	4.992	0.02	271.8
1252	0.2	-8.42	5.004	0.02	272.4
1255	0.4	-8.44	5.016	0.06	273.2
1258	0.2	-8.46	5.028	0.02	273.8
1261	0.2	-8.48	5.040	0.02	274.4
1264	0.2	-8.50	5.052	0.02	275.0
1267	0.0	-8.52	5.064	0.00	275.8
1270	0.2	-8.54	5.076	0.02	276.4
1273	0.2	-8.56	5.088	0.02	277.0
1276	0.2	-8.59	5.100	0.02	278.0
1279	0.4	-8.61	5.112	0.06	278.6
1282	0.0	-8.63	5.124	0.00	279.2
1285	0.0	-8.65	5.136	0.00	280.0
1288	0.4	-8.67	5.148	0.06	280.6
1291	0.0	-8.69	5.160	0.00	281.2
1294	0.2	-8.71	5.172	0.02	281.8
1297	0.2	-8.73	5.184	0.02	282.6
1300	0.2	-8.75	5.196	0.02	283.2
1303	0.2	-8.78	5.208	0.02	284.2
1306	-0.2	-8.80	5.220	-0.02	284.8
1309	0.2	-8.82	5.232	0.02	285.4
1312	0.2	-8.84	5.244	0.02	286.0
1315	0.4	-8.86	5.256	0.06	286.8
1318	0.2	-8.88	5.268	0.02	287.4
1321	0.2	-8.90	5.280	0.02	288.0
1324	0.0	-8.92	5.292	0.00	288.6
1327	0.2	-8.94	5.304	0.02	289.4
1330	0.2	-8.97	5.316	0.02	290.2
1333	0.2	-8.99	5.328	0.02	291.0
1336	0.2	-9.01	5.340	0.02	291.6
1339	0.2	-9.03	5.352	0.02	292.2
1342	0.2	-9.05	5.364	0.02	292.8
1345	0.2	-9.07	5.376	0.02	293.6
1348	0.2	-9.09	5.388	0.02	294.2
1351	0.2	-9.11	5.400	0.02	294.8
1354	0.2	-9.13	5.412	0.02	295.4
1357	0.2	-9.16	5.424	0.02	296.4
1360	0.0	-9.18	5.436	0.00	297.0
1363	0.2	-9.20	5.448	0.02	297.8
1366	0.2	-9.22	5.460	0.02	298.4
1369	0.2	-9.24	5.472	0.02	299.0
1372	0.2	-9.26	5.484	0.02	299.6
1375	0.0	-9.28	5.496	0.00	300.4
1378	0.0	-9.30	5.508	0.00	301.0
1381	0.4	-9.32	5.520	0.06	301.6
1384	0.2	-9.35	5.532	0.02	302.6
1387	0.2	-9.37	5.544	0.02	303.2
1390	0.2	-9.39	5.556	0.02	303.8
1393	0.0	-9.41	5.568	0.00	304.6
1396	0.0	-9.43	5.580	0.00	305.2
1399	0.2	-9.45	5.592	0.02	305.8
1402	0.2	-9.47	5.604	0.02	306.4
1405	0.4	-9.49	5.616	0.06	307.2
1408	0.0	-9.51	5.628	0.00	307.8
1411	0.2	-9.54	5.640	0.02	308.8
1414	0.0	-9.56	5.652	0.00	309.4
1417	0.2	-9.58	5.664	0.02	310.0
1420	0.2	-9.60	5.676	0.02	310.6
1423	0.2	-9.62	5.688	0.02	311.4
1426	0.2	-9.64	5.700	0.02	312.0
1429	0.2	-9.66	5.712	0.02	312.6
1432	0.2	-9.68	5.724	0.02	313.2
1435	0.2	-9.71	5.736	0.02	314.2
1438	0.2	-9.73	5.748	0.02	314.8
1441	0.2	-9.75	5.760	0.02	315.6
1444	0.4	-9.77	5.772	0.06	316.2
1447	0.2	-9.79	5.784	0.02	316.8
1450	0.4	-9.81	5.796	0.06	317.4
1453	0.0	-9.83	5.808	0.00	318.2
1456	0.2	-9.85	5.820	0.02	318.8
1459	0.2	-9.88	5.832	0.02	319.8
1462	0.0	-9.90	5.844	0.00	320.4
1465	0.4	-9.92	5.856	0.06	321.0
1468	0.4	-9.94	5.868	0.06	321.6
1471	0.2	-9.96	5.880	0.02	322.4
1474	0.2	-9.98	5.892	0.02	323.0
1477	0.0	-10.00	5.904	0.00	323.6
1480	0.0	-10.02	5.916	0.00	324.2
1483	0.2	-10.04	5.928	0.02	325.0
1486	0.0	-10.07	5.940	0.00	325.8
1489	0.2	-10.09	5.952	0.02	326.6
1492	0.0	-10.11	5.964	0.00	327.2
1495	0.2	-10.13	5.976	0.02	327.8
1498	0.2	-10.15	5.988	0.02	328.4
1501	0.4	-10.17	6.000	0.06	329.2
1504	0.2	-10.19	6.012	0.02	329.8
1507	-0.2	-10.21	6.024	-0.02	330.4
1510	0.4	-10.23	6.036	0.06	331.0
1513	0.2	-10.25	6.048	0.02	331.8
1516	0.0	-10.27	6.060	0.00	332.4
1519	0.0	-10.29	6.072	0.00	333.0
1522	0.2	-10.31	6.084	0.02	333.6
1525	0.2	-10.33	6.096	0.02	334.4
1528	0.2	-10.35	6.108	0.02	335.0
1531	0.2	-10.37	6.120	0.02	335.6
1534	0.4	-10.39	6.132	0.06	336.2
1537	0.0	-10.41	6.144	0.00	336.8
1540	0.2	-10.44	6.156	0.02	337.8
1543	0.4	-10.46	6.168	0.06	338.6
1546	0.2	-10.48	6.180	0.02	339.2
1549	0.2	-10.50	6.192	0.02	339.8
1552	0.4	-10.52	6.204	0.06	340.4
1555	0.2	-10.54	6.216	0.02	341.2
1558	0.2	-10.56	6.228	0.02	341.8
1561	0.2	-10.58	6.240	0.02	342.4
1564	0.2	-10.60	6.252	0.02	343.0
1567	0.2	-10.62	6.264	0.02	343.6
1570	0.0	-10.65	6.276	0.00	344.6
1573	0.2	-10.67	6.288	0.02	345.4
1576	0.2	-10.69	6.300	0.02	346.0
1579	0.2	-10.71	6.312	0.02	346.6
1582	0.2	-10.73	6.324	0.02	347.2
1585	0.2	-10.75	6.336	0.02	347.8
1588	0.2	-10.77	6.348	0.02	348.6
1591	0.2	-10.79	6.360	0.02	349.2
1594	0.4	-10.81	6.372	0.06	349.8
1597	0.0	-10.83	6.384	0.00	350.4
1600	0.2	-10.86	6.396	0.02	351.4
1603	0.2	-10.88	6.408	0.02	352.2
1606	0.0	-10.90	6.420	0.00	352.8
1609	0.2	-10.92	6.432	0.02	353.4
1612	0.2	-10.94	6.444	0.02	354.0
1615	0.2	-10.96	6.456	0.02	354.6
1618	0.2	-10.98	6.468	0.02	355.4
1621	0.2	-11.00	6.480	0.02	356.0
1624	0.2	-11.02	6.492	0.02	356.6
1627	-0.4	-11.04	6.504	-0.06	357.2
1630	0.2	-11.06	6.516	0.02	358.0
1633	0.2	-11.08	6.528	0.02	358.6
1636	0.4	-11.11	6.540	0.06	359.6
1639	0.2	-11.13	6.552	0.02	360.2
1642	0.4	-11.15	6.564	0.06	360.8
1645	0.2	-11.17	6.576	0.02	361.4
1648	0.2	-11.19	6.588	0.02	362.2
1651	0.2	-11.21	6.600	0.02	362.8
1654	0.2	-11.23	6.612	0.02	363.4
1657	0.4	-11.25	6.624	0.06	364.0
1660	0.0	-11.27	6.636	0.00	364.8
1663	0.6	-11.30	6.648	0.08	365.6
1666	0.2	-11.31	6.660	0.02	366.0
1669	0.0	-11.34	6.672	0.00	367.0
1672	0.2	-11.36	6.684	0.02	367.6
1675	0.2	-11.38	6.696	0.02	368.2
1678	0.2	-11.40	6.708	0.02	369.0
1681	0.0	-11.42	6.720	0.00	369.6
1684	0.2	-11.44	6.732	0.02	370.2
1687	0.4	-11.46	6.744	0.06	370.8
1690	0.0	-11.48	6.756	0.00	371.6
1693	0.4	-11.50	6.768	0.06	372.2
1696	0.2	-11.52	6.780	0.02	372.8
1699	-0.2	-11.55	6.792	-0.02	373.8
1702	0.2	-11.57	6.804	0.02	374.4
1705	0.0	-11.59	6.816	0.00	375.0
1708	0.2	-11.61	6.828	0.02	375.8
1711	0.2	-11.63	6.840	0.02	376.4
1714	0.2	-11.65	6.852	0.02	377.0
1717	0.2	-11.67	6.864	0.02	377.6
1720	0.0	-11.69	6.876	0.00	378.4
1723	0.0	-11.71	6.888	0.00	379.0
1726	0.0	-11.73	6.900	0.00	379.6
1729	0.2	-11.75	6.912	0.02	380.2
1732	0.2	-11.78	6.924	0.02	381.2
1735	0.2	-11.80	6.936	0.02	381.8
1738	0.2	-11.82	6.948	0.02	382.6
1741	0.2	-11.84	6.960	0.02	383.2
1744	0.0	-11.86	6.972	0.00	383.8
1747	0.2	-11.88	6.984	0.02	384.4
1750	0.2	-11.90	6.996	0.02	385.2
1753	0.2	-11.92	7.008	0.02	385.8
1756	0.2	-11.94	7.020	0.02	386.4
1759	0.2	-11.96	7.032	0.02	387.0
1762	0.2	-11.98	7.044	0.02	387.8
1765	0.2	-12.00	7.056	0.02	388.4
1768	0.2	-12.02	7.068	0.02	389.0
1771	-0.2	-12.05	7.080	-0.02	390.0
1774	0.2	-12.07	7.092	0.02	390.6
1777	0.2	-12.09	7.104	0.02	391.2
1780	0.0	-12.11	7.116	0.00	392.0
1783	0.2	-12.13	7.128	0.02	392.6
1786	0.2	-12.15	7.140	0.02	393.2
1789	0.2	-12.17	7.152	0.02	393.8
1792	0.2	-12.19	7.164	0.02	394.4
1795	0.2	-12.21	7.176	0.02	395.2
1798	0.0	-12.25	7.188	0.00	396.4
1801	0.2	-12.26	7.200	0.02	396.8
1804	0.2	-12.29	7.212	0.02	397.8
1807	0.2	-12.31	7.224	0.02	398.4
1810	0.2	-12.33	7.236	0.02	399.0
1813	0.2	-12.35	7.248	0.02	399.6
1816	0.2	-12.37	7.260	0.02	400.4
1819	0.4	-12.39	7.272	0.06	401.0
1822	0.2	-12.41	7.284	0.02	401.6
1825	0.0	-12.43	7.296	0.00	402.2
1828	0.2	-12.45	7.308	0.02	403.0
1831	0.2	-12.47	7.320	0.02	403.6
1834	0.0	-12.49	7.332	0.00	404.2
1837	0.2	-12.52	7.344	0.02	405.2
1840	0.4	-12.54	7.356	0.06	405.8
1843	0.2	-12.56	7.368	0.02	406.4
1846	0.0	-12.58	7.380	0.00	407.2
1849	0.2	-12.60	7.392	0.02	407.8
1852	0.2	-12.62	7.404	0.02	408.4
1855	0.2	-12.64	7.416	0.02	409.0
1858	0.2	-12.66	7.428	0.02	409.8
1861	0.0	-12.68	7.440	0.00	410.4
1864	0.2	-12.70	7.452	0.02	411.0
1867	0.4	-12.72	7.464	0.06	411.6
1870	0.2	-12.75	7.476	0.02	412.6
1873	0.2	-12.77	7.488	0.02	413.2
1876	0.2	-12.79	7.500	0.02	414.0
1879	0.2	-12.81	7.512	0.02	414.6
1882	0.2	-12.83	7.524	0.02	415.2
1885	0.0	-12.85	7.536	0.00	415.8
1888	0.2	-12.87	7.548	0.02	416.6
1891	0.4	-12.89	7.560	0.06	417.2
1894	0.0	-12.91	7.572	0.00	417.8
1897	0.4	-12.93	7.584	0.06	418.4
1900	0.2	-12.96	7.596	0.02	419.4
1903	0.2	-12.98	7.608	0.02	420.0
1906	0.2	-13.00	7.620	0.02	420.8
1909	0.2	-13.02	7.632	0.02	421.4
1912	0.4	-13.04	7.644	0.06	422.0
1915	0.0	-13.06	7.656	0.00	422.6
1918	0.2	-13.08	7.668	0.02	423.4
1921	0.2	-13.10	7.680	0.02	424.0
1924	0.0	-13.12	7.692	0.00	424.6
1927	0.2	-13.14	7.704	0.02	425.2
1930	0.2	-13.16	7.716	0.02	425.8
1933	0.2	-13.19	7.728	0.02	426.8
1936	0.0	-13.21	7.740	0.00	427.6
1939	0.4	-13.23	7.752	0.06	428.2
1942	0.2	-13.25	7.764	0.02	428.8
1945	0.4	-13.27	7.776	0.06	429.4
1948	0.2	-13.29	7.788	0.02	430.0
1951	0.2	-13.31	7.800	0.02	430.8
1954	0.2	-13.33	7.812	0.02	431.4
1957	0.2	-13.35	7.824	0.02	432.0
1960	0.2	-13.38	7.836	0.02	433.0
1963	0.4	-13.40	7.848	0.06	433.6
1966	0.0	-13.42	7.860	0.00	434.4
1969	-0.4	-13.44	7.872	-0.06	435.0
1972	0.2	-13.46	7.884	0.02	435.6
1975	0.2	-13.48	7.896	0.02	436.2
1978	0.2	-13.50	7.908	0.02	436.8
1981	0.0	-13.52	7.920	0.00	437.6
1984	0.2	-13.54	7.932	0.02	438.2
1987	0.2	-13.56	7.944	0.02	438.8
1990	0.2	-13.58	7.956	0.02	439.4
1993	0.2	-13.61	7.968	0.02	440.4
1996	0.2	-13.63	7.980	0.02	441.2
1999	0.2	-13.65	7.992	0.02	441.8
2002	0.4	-13.67	8.004	0.06	442.4
2005	0.2	-13.69	8.016	0.02	443.0
2008	0.2	-13.71	8.028	0.02	443.6
2011	0.2	-13.73	8.040	0.02	444.4
2014	0.0	-13.76	8.052	0.00	445.4
2017	0.4	-13.78	8.064	0.06	446.0
2020	0.2	-13.80	8.076	0.02	446.6
2023	0.6	-13.82	8.088	0.08	447.2
2026	0.2	-13.84	8.100	0.02	447.8
2029	0.2	-13.86	8.112	0.02	448.6
2032	0.2	-13.88	8.124	0.02	449.2
2035	0.2	-13.90	8.136	0.02	449.8
2038	0.2	-13.92	8.148	0.02	450.4
2041	0.2	-13.95	8.160	0.02	451.4
2044	0.2	-13.97	8.172	0.02	452.2
2047	0.2	-13.99	8.184	0.02	452.8
2050	0.2	-14.01	8.196	0.02	453.4
2053	0.0	-14.03	8.208	0.00	454.0
2056	0.2	-14.05	8.220	0.02	454.6
2059	0.2	-14.07	8.232	0.02	455.4
2062	0.4	-14.09	8.244	0.06	456.0
2065	0.2	-14.11	8.256	0.02	456.6
2068	0.2	-14.14	8.268	0.02	457.6
2071	0.2	-14.16	8.280	0.02	458.2
2074	0.2	-14.18	8.292	0.02	458.8
2077	0.4	-14.20	8.304	0.06	459.6
2080	0.4	-14.22	8.316	0.06	460.2
2083	0.2	-14.24	8.328	0.02	460.8
2086	-0.2	-14.26	8.340	-0.02	461.4
2089	0.2	-14.28	8.352	0.02	462.2
2092	0.2	-14.30	8.364	0.02	462.8
2095	0.2	-14.33	8.376	0.02	463.8
2098	0.2	-14.35	8.388	0.02	464.4
2101	0.2	-14.37	8.400	0.02	465.0
2104	0.2	-14.39	8.412	0.02	465.6
2107	0.2	-14.41	8.424	0.02	466.4
2110	0.2	-14.43	8.436	0.02	467.0
2113	0.2	-14.45	8.448	0.02	467.6
2116	0.2	-14.47	8.460	0.02	468.2
2119	0.2	-14.49	8.472	0.02	469.0
2122	0.2	-14.52	8.484	0.02	470.0
2125	0.2	-14.54	8.496	0.02	470.6
2128	0.2	-14.56	8.508	0.02	471.2
2131	0.2	-14.58	8.520	0.02	471.8
2134	0.2	-14.60	8.532	0.02	472.4
2137	0.4	-14.62	8.544	0.06	473.2
2140	0.2	-14.64	8.556	0.02	473.8
2143	0.2	-14.66	8.568	0.02	474.4
2146	0.0	-14.68	8.580	0.00	475.0
2149	0.2	-14.71	8.592	0.02	476.0
2152	0.2	-14.73	8.604	0.02	476.6
2155	0.2	-14.75	8.616	0.02	477.4
2158	0.2	-14.77	8.628	0.02	478.0
2161	0.2	-14.79	8.640	0.02	478.6
2164	0.2	-14.81	8.652	0.02	479.2
2167	0.2	-14.83	8.664	0.02	480.0
2170	0.2	-14.86	8.676	0.02	481.0
2173	0.2	-14.88	8.688	0.02	481.6
2176	0.2	-14.90	8.700	0.02	482.2
2179	0.2	-14.92	8.712	0.02	482.8
2182	0.2	-14.94	8.724	0.02	483.4
2185	0.2	-14.96	8.736	0.02	484.2
2188	0.4	-14.98	8.748	0.06	484.8
2191	0.2	-15.00	8.760	0.02	485.4
2194	0.2	-15.02	8.772	0.02	486.0
2197	0.2	-15.05	8.784	0.02	487.0
2200	0.2	-15.07	8.796	0.02	487.8
2203	0.2	-15.09	8.808	0.02	488.4
2206	0.0	-15.11	8.820	0.00	489.0
2209	0.2	-15.13	8.832	0.02	489.6
2212	0.2	-15.15	8.844	0.02	490.2
2215	0.2	-15.17	8.856	0.02	491.0
2218	0.0	-15.19	8.868	0.00	491.6
2221	0.2	-15.21	8.880	0.02	492.2
2224	0.2	-15.24	8.892	0.02	493.2
2227	0.2	-15.25	8.904	0.02	493.6
2230	0.2	-15.27	8.916	0.02	494.2
2233	0.2	-15.29	8.928	0.02	494.8
2236	0.0	-15.31	8.940	0.00	495.4
2239	0.2	-15.33	8.952	0.02	496.2
2242	0.4	-15.35	8.964	0.06	496.8
2245	0.2	-15.37	8.976	0.02	497.4
2248	0.0	-15.39	8.988	0.00	498.0
2251	0.2	-15.42	9.000	0.02	499.0
2254	0.2	-15.44	9.012	0.02	499.6
2257	0.2	-15.46	9.024	0.02	500.4
2260	0.2	-15.48	9.036	0.02	501.0
2263	0.2	-15.50	9.048	0.02	501.6
2266	0.4	-15.52	9.060	0.06	502.2
2269	0.2	-15.54	9.072	0.02	503.0
2272	0.2	-15.56	9.084	0.02	503.6
2275	0.2	-15.58	9.096	0.02	504.2
2278	-0.2	-15.60	9.108	-0.02	504.8
2281	0.2	-15.62	9.120	0.02	505.6
2284	0.2	-15.65	9.132	0.02	506.4
2287	0.2	-15.67	9.144	0.02	507.2
2290	0.2	-15.69	9.156	0.02	507.8
2293	0.2	-15.71	9.168	0.02	508.4
2296	0.2	-15.73	9.180	0.02	509.0
2299	0.2	-15.75	9.192	0.02	509.8
2302	0.2	-15.77	9.204	0.02	510.4
2305	0.2	-15.79	9.216	0.02	511.0
2308	0.0	-15.81	9.228	0.00	511.6
2311	0.2	-15.84	9.240	0.02	512.6
2314	0.0	-15.86	9.252	0.00	513.2
2317	0.2	-15.88	9.264	0.02	514.0
2320	0.2	-15.90	9.276	0.02	514.6
2323	0.2	-15.92	9.288	0.02	515.2
2326	0.2	-15.94	9.300	0.02	515.8
2329	0.2	-15.96	9.312	0.02	516.6
2332	0.4	-15.98	9.324	0.06	517.2
2335	0.2	-16.00	9.336	0.02	517.8
2338	0.0	-16.02	9.348	0.00	518.4
2341	0.2	-16.04	9.360	0.02	519.0
2344	0.2	-16.06	9.372	0.02	519.8
2347	0.4	-16.09	9.384	0.06	520.8
2350	0.0	-16.11	9.396	0.00	521.4
2353	-0.2	-16.13	9.408	-0.02	522.0
2356	0.2	-16.15	9.420	0.02	522.6
2359	0.4	-16.17	9.432	0.06	523.4
2362	0.2	-16.19	9.444	0.02	524.0
2365	0.2	-16.21	9.456	0.02	524.6
2368	0.2	-16.23	9.468	0.02	525.2
2371	0.2	-16.25	9.480	0.02	525.8
2374	0.0	-16.27	9.492	0.00	526.6
2377	0.0	-16.29	9.504	0.00	527.2
2380	0.2	-16.32	9.516	0.02	528.2
2383	0.2	-16.33	9.528	0.02	528.4
2386	0.2	-16.36	9.540	0.02	529.4
2389	0.2	-16.38	9.552	0.02	530.0
2392	0.2	-16.40	9.564	0.02	530.8
2395	0.2	-16.42	9.576	0.02	531.4
2398	0.0	-16.44	9.588	0.00	532.0
2401	0.2	-16.46	9.600	0.02	532.6
2404	0.4	-16.48	9.612	0.06	533.4
2407	0.2	-16.50	9.624	0.02	534.0
2410	0.2	-16.52	9.636	0.02	534.6
2413	0.2	-16.54	9.648	0.02	535.2
2416	0.2	-16.56	9.660	0.02	536.0
2419	0.2	-16.59	9.672	0.02	536.8
2422	0.2	-16.61	9.684	0.02	537.6
2425	-0.2	-16.63	9.696	-0.02	538.2
2428	0.2	-16.65	9.708	0.02	538.8
2431	0.0	-16.67	9.720	0.00	539.4
2434	0.2	-16.69	9.732	0.02	540.2
2437	0.4	-16.71	9.744	0.06	540.8
2440	0.4	-16.73	9.756	0.06	541.4
2443	-0.2	-16.75	9.768	-0.02	542.0
2446	0.2	-16.77	9.780	0.02	542.8
2449	0.4	-16.79	9.792	0.06	543.4
2452	0.4	-16.82	9.804	0.06	544.4
2455	0.2	-16.84	9.816	0.02	545.0
2458	0.2	-16.86	9.828	0.02	545.6
2461	0.2	-16.88	9.840	0.02	546.2
2464	0.2	-16.90	9.852	0.02	547.0
2467	0.0	-16.92	9.864	0.00	547.6
2470	0.0	-16.94	9.876	0.00	548.2
2473	0.0	-16.96	9.888	0.00	548.8
2476	0.2	-16.98	9.900	0.02	549.6
2479	0.0	-17.00	9.912	0.00	550.2
2482	0.2	-17.02	9.924	0.02	550.8
2485	0.2	-17.04	9.936	0.02	551.4
2488	0.4	-17.07	9.948	0.06	552.4
2491	0.2	-17.09	9.960	0.02	553.0
2494	0.2	-17.11	9.972	0.02	553.8
2497	0.4	-17.13	9.984	0.06	554.4
2500	0.2	-17.15	9.996	0.02	555.0
2503	0.2	-17.17	10.008	0.02	555.6
2506	0.0	-17.19	10.020	0.00	556.4
2509	0.2	-17.21	10.032	0.02	557.0
2512	0.2	-17.24	10.044	0.02	558.0
2515	0.4	-17.26	10.056	0.06	558.6
2518	0.2	-17.28	10.068	0.02	559.2
2521	0.2	-17.31	10.080	0.02	560.2
2524	0.2	-17.33	10.092	0.02	560.8
2527	0.2	-17.35	10.104	0.02	561.4
2530	0.0	-17.37	10.116	0.00	562.2
2533	-0.4	-17.39	10.128	-0.06	562.8
2536	0.2	-17.41	10.140	0.02	563.4
2539	0.2	-17.43	10.152	0.02	564.0
2542	0.2	-17.45	10.164	0.02	564.8
2545	0.2	-17.47	10.176	0.02	565.4
2548	0.2	-17.49	10.188	0.02	566.0
2551	0.4	-17.51	10.200	0.06	566.6
2554	0.2	-17.54	10.212	0.02	567.6
2557	0.2	-17.56	10.224	0.02	568.2
2560	0.4	-17.58	10.236	0.06	569.0
2563	0.2	-17.60	10.248	0.02	569.6
2566	0.2	-17.62	10.260	0.02	570.2
2569	0.2	-17.64	10.272	0.02	570.8
2572	0.2	-17.66	10.284	0.02	571.6
2575	0.2	-17.68	10.296	0.02	572.2
2578	0.2	-17.70	10.308	0.02	572.8
2581	0.4	-17.72	10.320	0.06	573.4
2584	0.0	-17.74	10.332	0.00	574.2
2587	0.2	-17.76	10.344	0.02	574.8
2590	0.6	-17.79	10.356	0.08	575.8
2593	0.2	-17.81	10.368	0.02	576.4
2596	0.2	-17.83	10.380	0.02	577.0
2599	0.2	-17.85	10.392	0.02	577.6
2602	0.4	-17.87	10.404	0.06	578.4
2605	0.2	-17.89	10.416	0.02	579.0
2608	0.0	-17.91	10.428	0.00	579.6
2611	0.2	-17.93	10.440	0.02	580.2
2614	0.2	-17.95	10.452	0.02	581.0
2617	0.4	-17.97	10.464	0.06	581.6
2620	0.2	-17.99	10.476	0.02	582.2
2623	0.0	-18.02	10.488	0.00	583.2
2626	0.2	-18.03	10.500	0.02	583.4
2629	0.2	-18.06	10.512	0.02	584.4
2632	0.4	-18.08	10.524	0.06	585.2
2635	0.0	-18.10	10.536	0.00	585.8
2638	0.4	-18.12	10.548	0.06	586.4
2641	0.4	-18.14	10.560	0.06	587.0
2644	0.0	-18.16	10.572	0.00	587.8
2647	0.2	-18.18	10.584	0.02	588.4
2650	0.2	-18.20	10.596	0.02	589.0
2653	0.2	-18.22	10.608	0.02	589.6
2656	0.4	-18.25	10.620	0.06	590.6
2659	0.2	-18.27	10.632	0.02	591.2
2662	0.2	-18.29	10.644	0.02	592.0
2665	0.2	-18.31	10.656	0.02	592.6
2668	0.0	-18.33	10.668	0.00	593.2
2671	0.4	-18.35	10.680	0.06	593.8
2674	0.2	-18.37	10.692	0.02	594.4
2677	0.2	-18.39	10.704	0.02	595.2
2680	0.2	-18.41	10.716	0.02	595.8
2683	0.4	-18.43	10.728	0.06	596.4
2686	0.2	-18.46	10.740	0.02	597.4
2689	0.2	-18.48	10.752	0.02	598.0
2692	0.2	-18.50	10.764	0.02	598.8
2695	0.2	-18.52	10.776	0.02	599.4
2698	0.4	-18.54	10.788	0.06	600.0
2701	0.0	-18.56	10.800	0.00	600.6
2704	0.2	-18.58	10.812	0.02	601.2
2707	0.0	-18.60	10.824	0.00	602.0
2710	0.2	-18.62	10.836	0.02	602.6
2713	0.0	-18.65	10.848	0.00	603.6
2716	0.2	-18.67	10.860	0.02	604.2
2719	0.4	-18.69	10.872	0.06	604.8
2722	0.2	-18.71	10.884	0.02	605.6
2725	0.0	-18.73	10.896	0.00	606.2
2728	0.4	-18.75	10.908	0.06	606.8
2731	0.2	-18.77	10.920	0.02	607.4
2734	0.2	-18.79	10.932	0.02	608.0
2737	0.2	-18.81	10.944	0.02	608.8
2740	0.2	-18.83	10.956	0.02	609.4
2743	0.2	-18.86	10.968	0.02	610.4
2746	0.2	-18.88	10.980	0.02	611.0
2749	0.4	-18.90	10.992	0.06	611.6
2752	0.0	-18.92	11.004	0.00	612.2
2755	0.2	-18.94	11.016	0.02	613.0
2758	0.2	-18.96	11.028	0.02	613.6
2761	0.0	-18.98	11.040	0.00	614.2
2764	0.4	-19.00	11.052	0.06	614.8
2767	0.2	-19.02	11.064	0.02	615.6
2770	0.2	-19.05	11.076	0.02	616.6
2773	0.2	-19.07	11.088	0.02	617.2
2776	0.2	-19.09	11.100	0.02	617.8
2779	0.2	-19.11	11.112	0.02	618.4
2782	0.2	-19.13	11.124	0.02	619.0
2785	0.2	-19.15	11.136	0.02	619.8
2788	0.4	-19.17	11.148	0.06	620.4
2791	0.4	-19.19	11.160	0.06	621.0
2794	0.0	-19.21	11.172	0.00	621.6
2797	0.2	-19.24	11.184	0.02	622.6
2800	0.2	-19.25	11.196	0.02	623.0
2803	0.2	-19.27	11.208	0.02	623.6
2806	0.2	-19.29	11.220	0.02	624.2
2809	0.2	-19.31	11.232	0.02	625.0
2812	0.2	-19.33	11.244	0.02	625.6
2815	0.2	-19.35	11.256	0.02	626.2
2818	-0.2	-19.38	11.268	-0.02	627.2
2821	0.2	-19.40	11.280	0.02	627.8
2824	0.2	-19.42	11.292	0.02	628.4
2827	0.2	-19.44	11.304	0.02	629.2
2830	0.4	-19.46	11.316	0.06	629.8
2833	0.6	-19.48	11.328	0.08	630.4
2836	1.0	-19.50	11.340	0.14	631.0
2839	2.0	-19.52	11.352	0.30	631.8
2842	3.2	-19.54	11.364	0.48	632.4
2845	5.6	-19.56	11.376	0.84	633.0
2848	7.6	-19.58	11.388	1.12	633.6
2851	9.6	-19.60	11.400	1.42	634.4
2854	12.4	-19.62	11.412	1.84	635.0
2857	15.0	-19.64	11.424	2.22	635.6
2860	18.2	-19.66	11.436	2.70	636.2
2863	22.2	-19.67	11.448	3.30	636.6
2866	30.6	-19.69	11.460	4.54	637.2
2869	43.8	-19.70	11.472	6.50	637.6
2872	53.4	-19.71	11.484	7.92	637.8
2875	59.0	-19.73	11.496	8.76	638.6
2878	64.0	-19.74	11.508	9.50	638.8
2881	68.4	-19.76	11.520	10.14	639.4
2884	70.8	-19.78	11.532	10.50	640.2
2887	72.6	-19.80	11.544	10.76	640.8
2890	72.8	-19.82	11.556	10.80	641.4
2893	72.8	-19.84	11.568	10.80	642.0
2896	72.2	-19.86	11.580	10.70	642.8
2899	71.6	-19.89	11.592	10.62	643.6
2902	70.8	-19.91	11.604	10.50	644.4
2905	69.4	-19.93	11.616	10.30	645.0
2908	68.4	-19.95	11.628	10.14	645.6
2911	67.0	-19.97	11.640	9.94	646.2
2914	66.2	-20.00	11.652	9.82	647.2
2917	64.6	-20.02	11.664	9.58	647.8
2920	63.2	-20.04	11.676	9.38	648.6
2923	60.8	-20.06	11.688	9.02	649.2
2926	57.8	-20.09	11.700	8.58	650.2
2929	55.4	-20.11	11.712	8.22	650.8
2932	52.0	-20.13	11.724	7.72	651.4
2935	55.0	-20.15	11.736	8.16	652.2
2938	62.2	-20.17	11.748	9.22	652.8
2941	66.4	-20.19	11.760	9.84	653.4
2944	63.4	-20.21	11.772	9.40	654.0
2947	52.2	-20.24	11.784	7.74	655.0
2950	49.2	-20.26	11.796	7.30	655.6
2953	48.6	-20.29	11.808	7.20	656.6
2956	48.4	-20.31	11.820	7.18	657.2
2959	48.0	-20.33	11.832	7.12	658.0
2962	47.2	-20.35	11.844	7.00	658.6
2965	44.4	-20.37	11.856	6.58	659.2
2968	41.4	-20.40	11.868	6.14	660.2
2971	37.2	-20.42	11.880	5.52	660.8
2974	35.8	-20.44	11.892	5.30	661.4
2977	36.0	-20.46	11.904	5.34	662.2
2980	35.6	-20.49	11.916	5.28	663.2
2983	35.2	-20.51	11.928	5.22	663.8
2986	35.0	-20.53	11.940	5.20	664.4
2989	34.4	-20.55	11.952	5.10	665.0
2992	33.6	-20.57	11.964	4.98	665.6
2995	33.0	-20.59	11.976	4.90	666.4
2998	32.2	-20.62	11.988	4.78	667.4
3001	31.8	-20.64	12.000	4.72	668.0
3004	32.0	-20.66	12.012	4.74	668.6
3007	32.4	-20.68	12.024	4.80	669.2
3010	32.6	-20.70	12.036	4.84	670.0
3013	32.6	-20.72	12.048	4.84	670.6
3016	33.8	-20.74	12.060	5.02	671.2
3019	34.2	-20.76	12.072	5.08	671.8
3022	34.8	-20.78	12.084	5.16	672.4
3025	35.4	-20.80	12.096	5.26	673.2
3028	36.0	-20.82	12.108	5.34	673.8
3031	36.6	-20.84	12.120	5.42	674.4
3034	37.4	-20.86	12.132	5.54	675.0
3037	38.0	-20.88	12.144	5.64	675.8
3040	38.4	-20.90	12.156	5.70	676.4
3043	38.8	-20.92	12.168	5.76	677.0
3046	39.0	-20.94	12.180	5.78	677.6
3049	39.4	-20.97	12.192	5.84	678.6
3052	39.2	-20.99	12.204	5.82	679.2
3055	39.4	-21.01	12.216	5.84	680.0
3058	40.0	-21.03	12.228	5.94	680.6
3061	41.2	-21.05	12.240	6.12	681.2
3064	42.4	-21.07	12.252	6.28	681.8
3067	43.4	-21.09	12.264	6.44	682.6
3070	45.2	-21.11	12.276	6.70	683.2
3073	45.4	-21.13	12.288	6.74	683.8
3076	47.0	-21.15	12.300	6.98	684.4
3079	47.8	-21.17	12.312	7.08	685.2
3082	48.6	-21.19	12.324	7.20	685.8
3085	49.0	-21.21	12.336	7.26	686.4
3088	49.8	-21.23	12.348	7.38	687.0
3091	51.0	-21.25	12.360	7.56	687.8
3094	52.2	-21.27	12.372	7.74	688.4
3097	53.4	-21.29	12.384	7.92	689.0
3100	54.2	-21.31	12.396	8.04	689.6
3103	55.8	-21.33	12.408	8.28	690.2
3106	56.8	-21.35	12.420	8.42	691.0
3109	58.0	-21.37	12.432	8.60	691.6
3112	59.6	-21.39	12.444	8.84	692.2
3115	60.4	-21.41	12.456	8.96	692.8
3118	62.0	-21.43	12.468	9.20	693.6
3121	62.8	-21.45	12.480	9.32	694.2
3124	65.0	-21.47	12.492	9.64	694.8
3127	65.2	-21.49	12.504	9.66	695.4
3130	64.2	-21.51	12.516	9.52	696.2
3133	65.6	-21.53	12.528	9.72	696.8
3136	65.8	-21.55	12.540	9.76	697.4
3139	62.8	-21.56	12.552	9.32	697.8
3142	57.4	-21.57	12.564	8.52	698.0
3145	54.6	-21.57	12.576	8.10	698.0
3148	52.8	-21.57	12.588	7.84	698.0
3151	51.6	-21.57	12.600	7.66	698.0
3154	50.8	-21.57	12.612	7.54	698.0
3157	50.2	-21.57	12.624	7.44	698.0
3160	49.6	-21.57	12.636	7.36	698.0
3163	49.2	-21.57	12.648	7.30	698.0
3166	48.6	-21.57	12.660	7.20	698.0
3169	48.2	-21.57	12.672	7.14	698.0
3172	47.8	-21.57	12.684	7.08	698.0
3175	47.4	-21.57	12.696	7.02	698.0
3178	73.0	-19.82	12.708	7.00	698.4