File: results/youngs-modulus/2025-04-21/inconclusive-data/pf12lt01.csv
sep=
pf12lt01

System Information:
IntelliMESUR Version: 2.2.1
Test Frame Model: F505
Test Frame Serial Number: 4418651
Test Frame Capacity: 500 lbF / 2.2 kN
Test Frame Firmware Version: 1.00.14
Force Sensor Model: FS05-100
Force Sensor Capacity: 500 N
Force Sensor Resolution: 0.2 N
Force Sensor Serial Number: 4425350
Calibration Date: Apr 29, 2024
Calibration Due Date: Apr 29, 2025

Reading	Load [N]	Distance [mm]	Time [s]	Stress [MPa]	Strain [%]
1	0.0	0.00	0.000	0.00	0.0
4	-0.2	0.00	0.012	-0.04	0.0
7	0.0	0.00	0.024	0.00	0.0
10	0.2	0.00	0.036	0.04	0.0
13	0.0	0.00	0.048	0.00	0.0
16	0.0	0.00	0.060	0.00	0.0
19	-0.2	0.00	0.072	-0.04	0.0
22	0.0	0.00	0.084	0.00	0.0
25	0.0	0.00	0.096	0.00	0.0
28	0.0	0.00	0.108	0.00	0.0
31	0.0	0.00	0.120	0.00	0.0
34	0.0	0.00	0.132	0.00	0.0
37	0.0	0.00	0.144	0.00	0.0
40	-0.2	0.00	0.156	-0.04	0.0
43	0.0	0.00	0.168	0.00	0.0
46	0.0	0.00	0.180	0.00	0.0
49	0.0	-0.01	0.192	0.00	0.4
52	0.2	-0.03	0.204	0.04	1.0
55	-0.2	-0.05	0.216	-0.04	1.8
58	0.0	-0.08	0.228	0.00	2.8
61	0.0	-0.10	0.240	0.00	3.4
64	0.0	-0.12	0.252	0.00	4.2
67	-0.2	-0.14	0.264	-0.04	4.8
70	0.0	-0.16	0.276	0.00	5.6
73	0.0	-0.18	0.288	0.00	6.2
76	-0.2	-0.20	0.300	-0.04	7.0
79	0.4	-0.22	0.312	0.06	7.6
82	0.4	-0.24	0.324	0.06	8.4
85	0.0	-0.27	0.336	0.00	9.4
88	0.0	-0.28	0.348	0.00	9.6
91	0.0	-0.30	0.360	0.00	10.4
94	0.0	-0.32	0.372	0.00	11.0
97	0.0	-0.34	0.384	0.00	11.8
100	-0.2	-0.36	0.396	-0.04	12.4
103	0.0	-0.38	0.408	0.00	13.2
106	0.0	-0.40	0.420	0.00	13.8
109	0.2	-0.42	0.432	0.04	14.6
112	0.2	-0.45	0.444	0.04	15.6
115	-0.2	-0.47	0.456	-0.04	16.2
118	0.0	-0.49	0.468	0.00	17.0
121	0.0	-0.51	0.480	0.00	17.6
124	0.0	-0.53	0.492	0.00	18.4
127	0.0	-0.55	0.504	0.00	19.0
130	0.0	-0.57	0.516	0.00	19.8
133	-0.2	-0.59	0.528	-0.04	20.4
136	-0.2	-0.61	0.540	-0.04	21.2
139	0.0	-0.63	0.552	0.00	21.8
142	0.2	-0.66	0.564	0.04	22.8
145	0.0	-0.68	0.576	0.00	23.6
148	0.0	-0.70	0.588	0.00	24.2
151	-0.2	-0.72	0.600	-0.04	25.0
154	0.0	-0.74	0.612	0.00	25.6
157	0.0	-0.76	0.624	0.00	26.2
160	0.0	-0.78	0.636	0.00	27.0
163	0.0	-0.80	0.648	0.00	27.6
166	0.0	-0.82	0.660	0.00	28.4
169	-0.2	-0.85	0.672	-0.04	29.4
172	0.0	-0.87	0.684	0.00	30.2
175	0.0	-0.89	0.696	0.00	30.8
178	0.0	-0.91	0.708	0.00	31.4
181	-0.2	-0.93	0.720	-0.04	32.2
184	-0.2	-0.95	0.732	-0.04	32.8
187	0.4	-0.97	0.744	0.06	33.6
190	0.0	-0.99	0.756	0.00	34.2
193	0.0	-1.01	0.768	0.00	35.0
196	-0.2	-1.03	0.780	-0.04	35.6
199	0.0	-1.05	0.792	0.00	36.4
202	-0.2	-1.08	0.804	-0.04	37.4
205	0.0	-1.10	0.816	0.00	38.0
208	0.0	-1.12	0.828	0.00	38.8
211	0.0	-1.14	0.840	0.00	39.4
214	0.0	-1.16	0.852	0.00	40.2
217	0.0	-1.18	0.864	0.00	40.8
220	0.0	-1.20	0.876	0.00	41.6
223	-0.4	-1.22	0.888	-0.06	42.2
226	0.2	-1.24	0.900	0.04	43.0
229	0.0	-1.27	0.912	0.00	44.0
232	0.0	-1.29	0.924	0.00	44.6
235	0.0	-1.32	0.936	0.00	45.6
238	0.0	-1.34	0.948	0.00	46.4
241	0.0	-1.36	0.960	0.00	47.0
244	0.0	-1.38	0.972	0.00	47.8
247	-0.2	-1.40	0.984	-0.04	48.4
250	0.0	-1.42	0.996	0.00	49.2
253	0.0	-1.44	1.008	0.00	49.8
256	0.0	-1.46	1.020	0.00	50.6
259	-0.2	-1.48	1.032	-0.04	51.2
262	0.0	-1.50	1.044	0.00	52.0
265	-0.2	-1.52	1.056	-0.04	52.6
268	0.0	-1.55	1.068	0.00	53.6
271	0.0	-1.57	1.080	0.00	54.4
274	0.2	-1.59	1.092	0.04	55.0
277	0.0	-1.61	1.104	0.00	55.8
280	0.0	-1.63	1.116	0.00	56.4
283	0.0	-1.65	1.128	0.00	57.0
286	-0.2	-1.67	1.140	-0.04	57.8
289	-0.4	-1.69	1.152	-0.06	58.4
292	0.0	-1.71	1.164	0.00	59.2
295	0.2	-1.73	1.176	0.04	59.8
298	0.0	-1.75	1.188	0.00	60.6
301	0.0	-1.77	1.200	0.00	61.2
304	0.0	-1.80	1.212	0.00	62.2
307	0.0	-1.82	1.224	0.00	63.0
310	0.0	-1.84	1.236	0.00	63.6
313	-0.6	-1.86	1.248	-0.10	64.4
316	-0.2	-1.88	1.260	-0.04	65.0
319	0.0	-1.90	1.272	0.00	65.8
322	0.0	-1.92	1.284	0.00	66.4
325	-0.4	-1.94	1.296	-0.06	67.2
328	0.2	-1.96	1.308	0.04	67.8
331	0.0	-1.98	1.320	0.00	68.6
334	0.0	-2.00	1.332	0.00	69.2
337	-0.2	-2.03	1.344	-0.04	70.2
340	-0.2	-2.05	1.356	-0.04	71.0
343	0.0	-2.07	1.368	0.00	71.6
346	0.0	-2.09	1.380	0.00	72.4
349	0.2	-2.11	1.392	0.04	73.0
352	-0.2	-2.13	1.404	-0.04	73.8
355	0.0	-2.15	1.416	0.00	74.4
358	-0.2	-2.17	1.428	-0.04	75.0
361	0.0	-2.19	1.440	0.00	75.8
364	-0.2	-2.21	1.452	-0.04	76.4
367	0.0	-2.23	1.464	0.00	77.2
370	0.2	-2.26	1.476	0.04	78.2
373	0.0	-2.27	1.488	0.00	78.6
376	0.0	-2.29	1.500	0.00	79.2
379	0.0	-2.31	1.512	0.00	80.0
382	0.0	-2.33	1.524	0.00	80.6
385	0.2	-2.35	1.536	0.04	81.4
388	0.0	-2.37	1.548	0.00	82.0
391	0.0	-2.39	1.560	0.00	82.6
394	0.0	-2.41	1.572	0.00	83.4
397	0.2	-2.43	1.584	0.04	84.0
400	0.0	-2.45	1.596	0.00	84.8
403	0.0	-2.47	1.608	0.00	85.4
406	0.0	-2.50	1.620	0.00	86.6
409	0.2	-2.52	1.632	0.04	87.2
412	0.0	-2.54	1.644	0.00	87.8
415	0.0	-2.56	1.656	0.00	88.6
418	0.0	-2.58	1.668	0.00	89.2
421	0.0	-2.60	1.680	0.00	90.0
424	0.0	-2.62	1.692	0.00	90.6
427	0.0	-2.64	1.704	0.00	91.4
430	0.0	-2.66	1.716	0.00	92.0
433	0.0	-2.68	1.728	0.00	92.8
436	0.2	-2.70	1.740	0.04	93.4
439	-0.2	-2.73	1.752	-0.04	94.4
442	0.2	-2.75	1.764	0.04	95.2
445	0.2	-2.77	1.776	0.04	95.8
448	0.0	-2.79	1.788	0.00	96.6
451	0.0	-2.81	1.800	0.00	97.2
454	0.0	-2.83	1.812	0.00	98.0
457	0.0	-2.85	1.824	0.00	98.6
460	-0.2	-2.87	1.836	-0.04	99.4
463	0.0	-2.89	1.848	0.00	100.0
466	0.0	-2.91	1.860	0.00	100.6
469	-0.2	-2.93	1.872	-0.04	101.4
472	0.0	-2.96	1.884	0.00	102.4
475	0.0	-2.98	1.896	0.00	103.2
478	0.2	-3.00	1.908	0.04	103.8
481	0.0	-3.02	1.920	0.00	104.4
484	0.2	-3.04	1.932	0.04	105.2
487	0.0	-3.06	1.944	0.00	105.8
490	0.0	-3.08	1.956	0.00	106.6
493	0.0	-3.10	1.968	0.00	107.2
496	0.0	-3.12	1.980	0.00	108.0
499	0.0	-3.14	1.992	0.00	108.6
502	0.0	-3.16	2.004	0.00	109.4
505	0.2	-3.19	2.016	0.04	110.4
508	0.0	-3.21	2.028	0.00	111.0
511	0.0	-3.23	2.040	0.00	111.8
514	0.0	-3.25	2.052	0.00	112.4
517	0.0	-3.28	2.064	0.00	113.4
520	0.0	-3.30	2.076	0.00	114.2
523	0.4	-3.32	2.088	0.06	114.8
526	-0.2	-3.34	2.100	-0.04	115.6
529	0.0	-3.36	2.112	0.00	116.2
532	0.0	-3.39	2.124	0.00	117.4
535	0.0	-3.41	2.136	0.00	118.0
538	0.2	-3.43	2.148	0.04	118.6
541	0.0	-3.45	2.160	0.00	119.4
544	0.0	-3.47	2.172	0.00	120.0
547	0.0	-3.49	2.184	0.00	120.8
550	0.0	-3.51	2.196	0.00	121.4
553	0.0	-3.53	2.208	0.00	122.2
556	-0.2	-3.55	2.220	-0.04	122.8
559	0.0	-3.58	2.232	0.00	123.8
562	0.0	-3.60	2.244	0.00	124.6
565	0.0	-3.62	2.256	0.00	125.2
568	0.0	-3.64	2.268	0.00	126.0
571	0.0	-3.66	2.280	0.00	126.6
574	-0.2	-3.68	2.292	-0.04	127.4
577	-0.2	-3.70	2.304	-0.04	128.0
580	-0.2	-3.72	2.316	-0.04	128.8
583	0.2	-3.74	2.328	0.04	129.4
586	0.2	-3.76	2.340	0.04	130.2
589	0.0	-3.79	2.352	0.00	131.2
592	0.0	-3.81	2.364	0.00	131.8
595	0.0	-3.83	2.376	0.00	132.6
598	0.0	-3.85	2.388	0.00	133.2
601	0.2	-3.87	2.400	0.04	134.0
604	-0.2	-3.89	2.412	-0.04	134.6
607	0.0	-3.91	2.424	0.00	135.2
610	0.0	-3.93	2.436	0.00	136.0
613	0.2	-3.96	2.448	0.04	137.0
616	0.0	-3.98	2.460	0.00	137.8
619	0.0	-4.00	2.472	0.00	138.4
622	0.0	-4.02	2.484	0.00	139.2
625	0.0	-4.04	2.496	0.00	139.8
628	-0.2	-4.06	2.508	-0.04	140.4
631	0.0	-4.08	2.520	0.00	141.2
634	0.2	-4.10	2.532	0.04	141.8
637	-0.2	-4.12	2.544	-0.04	142.6
640	0.0	-4.15	2.556	0.00	143.6
643	0.0	-4.17	2.568	0.00	144.2
646	-0.2	-4.19	2.580	-0.04	145.0
649	0.0	-4.21	2.592	0.00	145.6
652	0.0	-4.23	2.604	0.00	146.4
655	0.0	-4.25	2.616	0.00	147.0
658	0.0	-4.27	2.628	0.00	147.8
661	0.4	-4.29	2.640	0.06	148.4
664	-0.2	-4.31	2.652	-0.04	149.2
667	0.0	-4.34	2.664	0.00	150.2
670	0.0	-4.36	2.676	0.00	150.8
673	0.0	-4.38	2.688	0.00	151.6
676	0.0	-4.40	2.700	0.00	152.2
679	0.0	-4.42	2.712	0.00	153.0
682	0.0	-4.44	2.724	0.00	153.6
685	0.2	-4.46	2.736	0.04	154.4
688	0.0	-4.48	2.748	0.00	155.0
691	0.0	-4.50	2.760	0.00	155.8
694	0.0	-4.53	2.772	0.00	156.8
697	-0.2	-4.55	2.784	-0.04	157.4
700	0.2	-4.57	2.796	0.04	158.2
703	0.0	-4.59	2.808	0.00	158.8
706	0.2	-4.61	2.820	0.04	159.6
709	0.2	-4.63	2.832	0.04	160.2
712	0.0	-4.65	2.844	0.00	160.8
715	0.2	-4.67	2.856	0.04	161.6
718	0.0	-4.69	2.868	0.00	162.2
721	-0.2	-4.72	2.880	-0.04	163.4
724	0.0	-4.74	2.892	0.00	164.0
727	0.0	-4.76	2.904	0.00	164.8
730	-0.2	-4.78	2.916	-0.04	165.4
733	0.0	-4.80	2.928	0.00	166.0
736	-0.2	-4.82	2.940	-0.04	166.8
739	0.0	-4.84	2.952	0.00	167.4
742	-0.2	-4.86	2.964	-0.04	168.2
745	0.0	-4.88	2.976	0.00	168.8
748	-0.2	-4.91	2.988	-0.04	169.8
751	0.0	-4.93	3.000	0.00	170.6
754	0.0	-4.95	3.012	0.00	171.2
757	0.2	-4.97	3.024	0.04	172.0
760	0.0	-4.99	3.036	0.00	172.6
763	0.0	-5.01	3.048	0.00	173.4
766	0.2	-5.03	3.060	0.04	174.0
769	-0.2	-5.05	3.072	-0.04	174.8
772	0.0	-5.07	3.084	0.00	175.4
775	0.2	-5.10	3.096	0.04	176.4
778	0.0	-5.12	3.108	0.00	177.2
781	0.0	-5.14	3.120	0.00	177.8
784	0.0	-5.16	3.132	0.00	178.6
787	0.2	-5.18	3.144	0.04	179.2
790	-0.2	-5.20	3.156	-0.04	180.0
793	-0.2	-5.22	3.168	-0.04	180.6
796	0.0	-5.24	3.180	0.00	181.4
799	0.2	-5.26	3.192	0.04	182.0
802	0.0	-5.29	3.204	0.00	183.0
805	-0.2	-5.31	3.216	-0.04	183.8
808	0.0	-5.33	3.228	0.00	184.4
811	0.0	-5.35	3.240	0.00	185.2
814	0.0	-5.37	3.252	0.00	185.8
817	0.0	-5.39	3.264	0.00	186.6
820	0.0	-5.41	3.276	0.00	187.2
823	-0.2	-5.43	3.288	-0.04	187.8
826	0.2	-5.45	3.300	0.04	188.6
829	0.0	-5.48	3.312	0.00	189.6
832	0.0	-5.50	3.324	0.00	190.4
835	0.2	-5.52	3.336	0.04	191.0
838	0.0	-5.54	3.348	0.00	191.6
841	0.2	-5.56	3.360	0.04	192.4
844	0.0	-5.58	3.372	0.00	193.0
847	0.4	-5.60	3.384	0.06	193.8
850	-0.2	-5.62	3.396	-0.04	194.4
853	0.2	-5.64	3.408	0.04	195.2
856	0.2	-5.67	3.420	0.04	196.2
859	0.0	-5.69	3.432	0.00	196.8
862	0.0	-5.71	3.444	0.00	197.6
865	0.2	-5.73	3.456	0.04	198.2
868	0.2	-5.75	3.468	0.04	199.0
871	-0.2	-5.77	3.480	-0.04	199.6
874	-0.2	-5.79	3.492	-0.04	200.4
877	0.2	-5.81	3.504	0.04	201.0
880	0.2	-5.83	3.516	0.04	201.8
883	0.0	-5.85	3.528	0.00	202.4
886	0.0	-5.87	3.540	0.00	203.2
889	0.0	-5.89	3.552	0.00	203.8
892	-0.2	-5.92	3.564	-0.04	204.8
895	0.0	-5.94	3.576	0.00	205.6
898	-0.2	-5.96	3.588	-0.04	206.2
901	0.0	-5.98	3.600	0.00	207.0
904	0.0	-6.00	3.612	0.00	207.6
907	0.0	-6.02	3.624	0.00	208.4
910	0.0	-6.04	3.636	0.00	209.0
913	0.0	-6.06	3.648	0.00	209.6
916	0.2	-6.08	3.660	0.04	210.4
919	0.0	-6.10	3.672	0.00	211.0
922	0.0	-6.12	3.684	0.00	211.8
925	-0.2	-6.15	3.696	-0.04	212.8
928	0.6	-6.17	3.708	0.10	213.4
931	0.0	-6.19	3.720	0.00	214.2
934	-0.2	-6.21	3.732	-0.04	214.8
937	0.0	-6.23	3.744	0.00	215.6
940	0.0	-6.25	3.756	0.00	216.2
943	0.0	-6.27	3.768	0.00	217.0
946	0.0	-6.28	3.780	0.00	217.4
949	0.0	-6.30	3.792	0.00	218.0
952	0.2	-6.32	3.804	0.04	218.6
955	-0.2	-6.34	3.816	-0.04	219.4
958	0.0	-6.37	3.828	0.00	220.4
961	0.0	-6.39	3.840	0.00	221.2
964	0.0	-6.41	3.852	0.00	221.8
967	-0.2	-6.43	3.864	-0.04	222.4
970	0.0	-6.45	3.876	0.00	223.2
973	0.0	-6.47	3.888	0.00	223.8
976	-0.2	-6.49	3.900	-0.04	224.6
979	0.2	-6.51	3.912	0.04	225.2
982	0.0	-6.53	3.924	0.00	226.0
985	0.0	-6.55	3.936	0.00	226.6
988	0.0	-6.57	3.948	0.00	227.4
991	0.2	-6.60	3.960	0.04	228.4
994	0.2	-6.62	3.972	0.04	229.0
997	0.0	-6.64	3.984	0.00	229.8
1000	0.0	-6.66	3.996	0.00	230.4
1003	0.0	-6.68	4.008	0.00	231.2
1006	0.0	-6.70	4.020	0.00	231.8
1009	-0.2	-6.72	4.032	-0.04	232.6
1012	0.0	-6.74	4.044	0.00	233.2
1015	0.0	-6.76	4.056	0.00	234.0
1018	0.0	-6.78	4.068	0.00	234.6
1021	-0.2	-6.80	4.080	-0.04	235.2
1024	0.0	-6.82	4.092	0.00	236.0
1027	0.2	-6.84	4.104	0.04	236.6
1030	0.0	-6.86	4.116	0.00	237.4
1033	-0.2	-6.89	4.128	-0.04	238.4
1036	0.0	-6.91	4.140	0.00	239.2
1039	0.0	-6.93	4.152	0.00	239.8
1042	0.0	-6.95	4.164	0.00	240.4
1045	-0.2	-6.97	4.176	-0.04	241.2
1048	0.0	-6.99	4.188	0.00	241.8
1051	0.4	-7.01	4.200	0.06	242.6
1054	-0.4	-7.03	4.212	-0.06	243.2
1057	0.0	-7.05	4.224	0.00	244.0
1060	0.0	-7.07	4.236	0.00	244.6
1063	0.0	-7.09	4.248	0.00	245.4
1066	0.4	-7.12	4.260	0.06	246.4
1069	-0.2	-7.14	4.272	-0.04	247.0
1072	0.0	-7.16	4.284	0.00	247.8
1075	0.0	-7.18	4.296	0.00	248.4
1078	-0.2	-7.20	4.308	-0.04	249.2
1081	0.0	-7.22	4.320	0.00	249.8
1084	0.0	-7.24	4.332	0.00	250.6
1087	0.0	-7.27	4.344	0.00	251.6
1090	0.0	-7.29	4.356	0.00	252.2
1093	-0.2	-7.31	4.368	-0.04	253.0
1096	-0.2	-7.33	4.380	-0.04	253.6
1099	0.0	-7.36	4.392	0.00	254.6
1102	0.0	-7.38	4.404	0.00	255.4
1105	0.0	-7.40	4.416	0.00	256.0
1108	0.0	-7.42	4.428	0.00	256.8
1111	0.0	-7.44	4.440	0.00	257.4
1114	0.2	-7.46	4.452	0.04	258.2
1117	0.0	-7.48	4.464	0.00	258.8
1120	0.0	-7.50	4.476	0.00	259.6
1123	-0.2	-7.52	4.488	-0.04	260.2
1126	0.2	-7.54	4.500	0.04	260.8
1129	0.0	-7.56	4.512	0.00	261.6
1132	0.2	-7.58	4.524	0.04	262.2
1135	0.0	-7.61	4.536	0.00	263.4
1138	0.0	-7.63	4.548	0.00	264.0
1141	-0.2	-7.65	4.560	-0.04	264.8
1144	0.0	-7.67	4.572	0.00	265.4
1147	0.0	-7.69	4.584	0.00	266.0
1150	0.0	-7.71	4.596	0.00	266.8
1153	0.2	-7.73	4.608	0.04	267.4
1156	0.0	-7.75	4.620	0.00	268.2
1159	0.2	-7.77	4.632	0.04	268.8
1162	0.0	-7.79	4.644	0.00	269.6
1165	0.0	-7.81	4.656	0.00	270.2
1168	0.2	-7.84	4.668	0.04	271.2
1171	-0.2	-7.86	4.680	-0.04	272.0
1174	0.0	-7.88	4.692	0.00	272.6
1177	0.0	-7.90	4.704	0.00	273.4
1180	0.0	-7.92	4.716	0.00	274.0
1183	0.0	-7.94	4.728	0.00	274.8
1186	-0.2	-7.96	4.740	-0.04	275.4
1189	0.0	-7.98	4.752	0.00	276.2
1192	0.0	-8.00	4.764	0.00	276.8
1195	0.2	-8.02	4.776	0.04	277.6
1198	-0.2	-8.04	4.788	-0.04	278.2
1201	0.0	-8.07	4.800	0.00	279.2
1204	0.0	-8.09	4.812	0.00	280.0
1207	0.2	-8.11	4.824	0.04	280.6
1210	0.0	-8.13	4.836	0.00	281.4
1213	0.2	-8.15	4.848	0.04	282.0
1216	0.0	-8.17	4.860	0.00	282.6
1219	0.2	-8.19	4.872	0.04	283.4
1222	0.0	-8.21	4.884	0.00	284.0
1225	0.0	-8.23	4.896	0.00	284.8
1228	0.0	-8.25	4.908	0.00	285.4
1231	-0.2	-8.27	4.920	-0.04	286.2
1234	0.2	-8.30	4.932	0.04	287.2
1237	-0.2	-8.32	4.944	-0.04	287.8
1240	0.0	-8.34	4.956	0.00	288.6
1243	0.2	-8.36	4.968	0.04	289.2
1246	0.2	-8.38	4.980	0.04	290.0
1249	0.0	-8.40	4.992	0.00	290.6
1252	0.0	-8.42	5.004	0.00	291.4
1255	0.0	-8.44	5.016	0.00	292.0
1258	-0.2	-8.46	5.028	-0.04	292.8
1261	-0.2	-8.49	5.040	-0.04	293.8
1264	0.0	-8.51	5.052	0.00	294.4
1267	0.0	-8.53	5.064	0.00	295.2
1270	-0.2	-8.55	5.076	-0.04	295.8
1273	0.2	-8.57	5.088	0.04	296.6
1276	0.0	-8.59	5.100	0.00	297.2
1279	0.0	-8.61	5.112	0.00	298.0
1282	0.0	-8.63	5.124	0.00	298.6
1285	0.0	-8.65	5.136	0.00	299.4
1288	-0.2	-8.67	5.148	-0.04	300.0
1291	-0.2	-8.70	5.160	-0.04	301.0
1294	0.0	-8.72	5.172	0.00	301.8
1297	0.2	-8.74	5.184	0.04	302.4
1300	0.0	-8.76	5.196	0.00	303.2
1303	-0.2	-8.78	5.208	-0.04	303.8
1306	0.0	-8.80	5.220	0.00	304.4
1309	0.0	-8.82	5.232	0.00	305.2
1312	-0.2	-8.84	5.244	-0.04	305.8
1315	0.0	-8.86	5.256	0.00	306.6
1318	0.2	-8.89	5.268	0.04	307.6
1321	0.2	-8.91	5.280	0.04	308.4
1324	0.0	-8.93	5.292	0.00	309.0
1327	0.0	-8.95	5.304	0.00	309.6
1330	-0.4	-8.97	5.316	-0.06	310.4
1333	0.0	-8.99	5.328	0.00	311.0
1336	0.0	-9.01	5.340	0.00	311.8
1339	-0.2	-9.03	5.352	-0.04	312.4
1342	0.0	-9.05	5.364	0.00	313.2
1345	-0.2	-9.08	5.376	-0.04	314.2
1348	0.0	-9.10	5.388	0.00	314.8
1351	0.0	-9.12	5.400	0.00	315.6
1354	0.0	-9.14	5.412	0.00	316.2
1357	-0.4	-9.16	5.424	-0.06	317.0
1360	0.0	-9.18	5.436	0.00	317.6
1363	0.0	-9.20	5.448	0.00	318.4
1366	0.2	-9.22	5.460	0.04	319.0
1369	0.2	-9.25	5.472	0.04	320.0
1372	0.0	-9.27	5.484	0.00	320.8
1375	0.0	-9.29	5.496	0.00	321.4
1378	0.0	-9.31	5.508	0.00	322.2
1381	0.0	-9.33	5.520	0.00	322.8
1384	0.0	-9.35	5.532	0.00	323.6
1387	0.0	-9.37	5.544	0.00	324.2
1390	0.2	-9.39	5.556	0.04	325.0
1393	0.0	-9.41	5.568	0.00	325.6
1396	0.0	-9.44	5.580	0.00	326.6
1399	0.0	-9.46	5.592	0.00	327.4
1402	0.0	-9.48	5.604	0.00	328.0
1405	0.0	-9.50	5.616	0.00	328.8
1408	0.0	-9.52	5.628	0.00	329.4
1411	0.0	-9.54	5.640	0.00	330.2
1414	0.0	-9.56	5.652	0.00	330.8
1417	0.0	-9.58	5.664	0.00	331.4
1420	0.4	-9.61	5.676	0.06	332.6
1423	0.0	-9.63	5.688	0.00	333.2
1426	-0.2	-9.65	5.700	-0.04	334.0
1429	0.2	-9.67	5.712	0.04	334.6
1432	0.0	-9.69	5.724	0.00	335.2
1435	0.4	-9.71	5.736	0.06	336.0
1438	0.0	-9.73	5.748	0.00	336.6
1441	0.0	-9.75	5.760	0.00	337.4
1444	0.0	-9.77	5.772	0.00	338.0
1447	0.0	-9.80	5.784	0.00	339.2
1450	0.0	-9.82	5.796	0.00	339.8
1453	0.0	-9.84	5.808	0.00	340.4
1456	0.0	-9.86	5.820	0.00	341.2
1459	0.0	-9.88	5.832	0.00	341.8
1462	0.0	-9.90	5.844	0.00	342.6
1465	0.2	-9.92	5.856	0.04	343.2
1468	0.4	-9.94	5.868	0.06	344.0
1471	0.2	-9.96	5.880	0.04	344.6
1474	0.0	-9.99	5.892	0.00	345.6
1477	0.0	-10.01	5.904	0.00	346.4
1480	0.0	-10.03	5.916	0.00	347.0
1483	-0.2	-10.05	5.928	-0.04	347.8
1486	-0.2	-10.07	5.940	-0.04	348.4
1489	0.0	-10.09	5.952	0.00	349.2
1492	-0.2	-10.11	5.964	-0.04	349.8
1495	-0.2	-10.13	5.976	-0.04	350.6
1498	0.0	-10.15	5.988	0.00	351.2
1501	-0.2	-10.18	6.000	-0.04	352.2
1504	0.0	-10.20	6.012	0.00	353.0
1507	-0.2	-10.22	6.024	-0.04	353.6
1510	0.2	-10.24	6.036	0.04	354.4
1513	0.2	-10.26	6.048	0.04	355.0
1516	0.2	-10.27	6.060	0.04	355.4
1519	-0.2	-10.29	6.072	-0.04	356.0
1522	0.0	-10.31	6.084	0.00	356.8
1525	0.0	-10.33	6.096	0.00	357.4
1528	0.4	-10.36	6.108	0.06	358.4
1531	0.0	-10.38	6.120	0.00	359.2
1534	-0.4	-10.40	6.132	-0.06	359.8
1537	0.0	-10.42	6.144	0.00	360.6
1540	-0.2	-10.44	6.156	-0.04	361.2
1543	-0.2	-10.46	6.168	-0.04	362.0
1546	0.2	-10.48	6.180	0.04	362.6
1549	0.0	-10.50	6.192	0.00	363.4
1552	0.0	-10.52	6.204	0.00	364.0
1555	-0.2	-10.55	6.216	-0.04	365.0
1558	0.0	-10.57	6.228	0.00	365.8
1561	0.4	-10.59	6.240	0.06	366.4
1564	0.0	-10.61	6.252	0.00	367.2
1567	0.0	-10.63	6.264	0.00	367.8
1570	0.0	-10.65	6.276	0.00	368.6
1573	0.0	-10.67	6.288	0.00	369.2
1576	-0.4	-10.69	6.300	-0.06	369.8
1579	-0.4	-10.71	6.312	-0.06	370.6
1582	-0.4	-10.74	6.324	-0.06	371.6
1585	0.2	-10.76	6.336	0.04	372.4
1588	0.2	-10.78	6.348	0.04	373.0
1591	0.0	-10.80	6.360	0.00	373.8
1594	0.0	-10.82	6.372	0.00	374.4
1597	0.0	-10.84	6.384	0.00	375.0
1600	0.0	-10.86	6.396	0.00	375.8
1603	0.0	-10.88	6.408	0.00	376.4
1606	0.2	-10.90	6.420	0.04	377.2
1609	0.0	-10.92	6.432	0.00	377.8
1612	0.2	-10.94	6.444	0.04	378.6
1615	0.0	-10.97	6.456	0.00	379.6
1618	0.0	-10.99	6.468	0.00	380.2
1621	-0.4	-11.01	6.480	-0.06	381.0
1624	0.2	-11.03	6.492	0.04	381.6
1627	0.0	-11.05	6.504	0.00	382.4
1630	0.0	-11.07	6.516	0.00	383.0
1633	0.2	-11.09	6.528	0.04	383.8
1636	0.0	-11.11	6.540	0.00	384.4
1639	-0.2	-11.13	6.552	-0.04	385.2
1642	0.0	-11.15	6.564	0.00	385.8
1645	0.0	-11.17	6.576	0.00	386.6
1648	-0.2	-11.20	6.588	-0.04	387.6
1651	0.0	-11.22	6.600	0.00	388.2
1654	0.0	-11.24	6.612	0.00	389.0
1657	-0.2	-11.26	6.624	-0.04	389.6
1660	0.2	-11.28	6.636	0.04	390.4
1663	0.2	-11.30	6.648	0.04	391.0
1666	0.0	-11.32	6.660	0.00	391.6
1669	0.0	-11.34	6.672	0.00	392.4
1672	0.2	-11.36	6.684	0.04	393.0
1675	0.0	-11.38	6.696	0.00	393.8
1678	0.0	-11.40	6.708	0.00	394.4
1681	0.0	-11.43	6.720	0.00	395.6
1684	0.0	-11.45	6.732	0.00	396.2
1687	0.0	-11.47	6.744	0.00	396.8
1690	0.0	-11.49	6.756	0.00	397.6
1693	0.0	-11.51	6.768	0.00	398.2
1696	-0.2	-11.53	6.780	-0.04	399.0
1699	0.0	-11.55	6.792	0.00	399.6
1702	0.2	-11.57	6.804	0.04	400.4
1705	0.2	-11.59	6.816	0.04	401.0
1708	-0.2	-11.61	6.828	-0.04	401.8
1711	0.0	-11.63	6.840	0.00	402.4
1714	0.0	-11.65	6.852	0.00	403.2
1717	-0.2	-11.68	6.864	-0.04	404.2
1720	0.0	-11.70	6.876	0.00	404.8
1723	-0.4	-11.72	6.888	-0.06	405.6
1726	0.2	-11.74	6.900	0.04	406.2
1729	0.0	-11.76	6.912	0.00	407.0
1732	-0.2	-11.78	6.924	-0.04	407.6
1735	0.0	-11.80	6.936	0.00	408.4
1738	0.0	-11.82	6.948	0.00	409.0
1741	0.0	-11.84	6.960	0.00	409.6
1744	0.2	-11.86	6.972	0.04	410.4
1747	0.2	-11.88	6.984	0.04	411.0
1750	0.0	-11.91	6.996	0.00	412.2
1753	0.2	-11.93	7.008	0.04	412.8
1756	0.0	-11.95	7.020	0.00	413.4
1759	0.0	-11.97	7.032	0.00	414.2
1762	0.2	-11.99	7.044	0.04	414.8
1765	0.0	-12.01	7.056	0.00	415.6
1768	0.0	-12.03	7.068	0.00	416.2
1771	0.2	-12.05	7.080	0.04	417.0
1774	0.2	-12.07	7.092	0.04	417.6
1777	0.0	-12.09	7.104	0.00	418.4
1780	0.0	-12.11	7.116	0.00	419.0
1783	0.0	-12.14	7.128	0.00	420.0
1786	-0.4	-12.16	7.140	-0.06	420.8
1789	0.0	-12.18	7.152	0.00	421.4
1792	0.0	-12.20	7.164	0.00	422.2
1795	0.0	-12.22	7.176	0.00	422.8
1798	0.2	-12.24	7.188	0.04	423.6
1801	0.2	-12.26	7.200	0.04	424.2
1804	0.0	-12.29	7.212	0.00	425.2
1807	0.0	-12.31	7.224	0.00	426.0
1810	0.4	-12.33	7.236	0.06	426.6
1813	-0.2	-12.35	7.248	-0.04	427.4
1816	0.0	-12.38	7.260	0.00	428.4
1819	-0.2	-12.40	7.272	-0.04	429.0
1822	0.0	-12.42	7.284	0.00	429.8
1825	-0.2	-12.44	7.296	-0.04	430.4
1828	0.0	-12.46	7.308	0.00	431.2
1831	0.0	-12.48	7.320	0.00	431.8
1834	0.0	-12.50	7.332	0.00	432.6
1837	0.0	-12.52	7.344	0.00	433.2
1840	-0.2	-12.54	7.356	-0.04	434.0
1843	0.0	-12.56	7.368	0.00	434.6
1846	0.0	-12.58	7.380	0.00	435.2
1849	0.2	-12.60	7.392	0.04	436.0
1852	0.0	-12.63	7.404	0.00	437.0
1855	0.0	-12.65	7.416	0.00	437.8
1858	0.4	-12.67	7.428	0.06	438.4
1861	-0.2	-12.69	7.440	-0.04	439.2
1864	0.0	-12.71	7.452	0.00	439.8
1867	-0.2	-12.73	7.464	-0.04	440.4
1870	0.2	-12.75	7.476	0.04	441.2
1873	0.0	-12.77	7.488	0.00	441.8
1876	0.0	-12.79	7.500	0.00	442.6
1879	0.0	-12.81	7.512	0.00	443.2
1882	-0.2	-12.83	7.524	-0.04	444.0
1885	0.2	-12.86	7.536	0.04	445.0
1888	0.0	-12.88	7.548	0.00	445.6
1891	-0.2	-12.90	7.560	-0.04	446.4
1894	-0.2	-12.92	7.572	-0.04	447.0
1897	0.0	-12.94	7.584	0.00	447.8
1900	0.0	-12.96	7.596	0.00	448.4
1903	-0.2	-12.98	7.608	-0.04	449.2
1906	0.0	-13.00	7.620	0.00	449.8
1909	0.2	-13.02	7.632	0.04	450.6
1912	-0.2	-13.04	7.644	-0.04	451.2
1915	0.0	-13.06	7.656	0.00	452.0
1918	0.2	-13.09	7.668	0.04	453.0
1921	0.0	-13.11	7.680	0.00	453.6
1924	0.0	-13.13	7.692	0.00	454.4
1927	0.2	-13.15	7.704	0.04	455.0
1930	0.0	-13.17	7.716	0.00	455.8
1933	-0.2	-13.19	7.728	-0.04	456.4
1936	0.0	-13.21	7.740	0.00	457.0
1939	-0.4	-13.23	7.752	-0.06	457.8
1942	-0.2	-13.25	7.764	-0.04	458.4
1945	0.0	-13.27	7.776	0.00	459.2
1948	0.0	-13.30	7.788	0.00	460.2
1951	0.0	-13.32	7.800	0.00	460.8
1954	0.2	-13.34	7.812	0.04	461.6
1957	0.2	-13.36	7.824	0.04	462.2
1960	0.0	-13.38	7.836	0.00	463.0
1963	0.0	-13.40	7.848	0.00	463.6
1966	0.0	-13.42	7.860	0.00	464.4
1969	0.0	-13.44	7.872	0.00	465.0
1972	-0.2	-13.46	7.884	-0.04	465.8
1975	0.0	-13.49	7.896	0.00	466.8
1978	0.2	-13.51	7.908	0.04	467.4
1981	0.0	-13.53	7.920	0.00	468.2
1984	0.0	-13.55	7.932	0.00	468.8
1987	0.0	-13.57	7.944	0.00	469.6
1990	0.2	-13.59	7.956	0.04	470.2
1993	-0.4	-13.61	7.968	-0.06	471.0
1996	0.0	-13.63	7.980	0.00	471.6
1999	0.0	-13.65	7.992	0.00	472.4
2002	-0.2	-13.68	8.004	-0.04	473.4
2005	0.0	-13.70	8.016	0.00	474.0
2008	0.0	-13.72	8.028	0.00	474.8
2011	0.0	-13.74	8.040	0.00	475.4
2014	0.0	-13.76	8.052	0.00	476.2
2017	0.0	-13.78	8.064	0.00	476.8
2020	0.0	-13.80	8.076	0.00	477.6
2023	0.0	-13.82	8.088	0.00	478.2
2026	0.0	-13.84	8.100	0.00	478.8
2029	-0.2	-13.87	8.112	-0.04	480.0
2032	0.0	-13.89	8.124	0.00	480.6
2035	0.2	-13.91	8.136	0.04	481.4
2038	0.0	-13.93	8.148	0.00	482.0
2041	0.2	-13.95	8.160	0.04	482.6
2044	0.0	-13.97	8.172	0.00	483.4
2047	0.0	-13.99	8.184	0.00	484.0
2050	-0.2	-14.01	8.196	-0.04	484.8
2053	0.2	-14.03	8.208	0.04	485.4
2056	0.0	-14.06	8.220	0.00	486.6
2059	0.0	-14.08	8.232	0.00	487.2
2062	0.0	-14.10	8.244	0.00	487.8
2065	0.0	-14.12	8.256	0.00	488.6
2068	0.0	-14.14	8.268	0.00	489.2
2071	0.0	-14.16	8.280	0.00	490.0
2074	0.0	-14.18	8.292	0.00	490.6
2077	0.0	-14.20	8.304	0.00	491.4
2080	-0.2	-14.23	8.316	-0.04	492.4
2083	0.2	-14.25	8.328	0.04	493.0
2086	0.0	-14.27	8.340	0.00	493.8
2089	0.0	-14.29	8.352	0.00	494.4
2092	0.0	-14.31	8.364	0.00	495.2
2095	-0.2	-14.33	8.376	-0.04	495.8
2098	-0.2	-14.35	8.388	-0.04	496.6
2101	0.0	-14.37	8.400	0.00	497.2
2104	-0.2	-14.39	8.412	-0.04	498.0
2107	0.0	-14.42	8.424	0.00	499.0
2110	0.0	-14.44	8.436	0.00	499.6
2113	0.2	-14.46	8.448	0.04	500.4
2116	0.0	-14.48	8.460	0.00	501.0
2119	0.2	-14.50	8.472	0.04	501.8
2122	0.0	-14.52	8.484	0.00	502.4
2125	0.0	-14.54	8.496	0.00	503.2
2128	-0.2	-14.56	8.508	-0.04	503.8
2131	0.0	-14.58	8.520	0.00	504.4
2134	0.2	-14.61	8.532	0.04	505.6
2137	-0.2	-14.63	8.544	-0.04	506.2
2140	0.0	-14.65	8.556	0.00	507.0
2143	0.0	-14.67	8.568	0.00	507.6
2146	-0.2	-14.69	8.580	-0.04	508.4
2149	0.2	-14.71	8.592	0.04	509.0
2152	0.0	-14.73	8.604	0.00	509.6
2155	-0.2	-14.75	8.616	-0.04	510.4
2158	0.2	-14.77	8.628	0.04	511.0
2161	0.4	-14.80	8.640	0.06	512.2
2164	0.0	-14.82	8.652	0.00	512.8
2167	-0.4	-14.84	8.664	-0.06	513.4
2170	0.0	-14.86	8.676	0.00	514.2
2173	0.0	-14.88	8.688	0.00	514.8
2176	0.0	-14.90	8.700	0.00	515.6
2179	0.0	-14.92	8.712	0.00	516.2
2182	0.2	-14.94	8.724	0.04	517.0
2185	0.0	-14.96	8.736	0.00	517.6
2188	0.0	-14.99	8.748	0.00	518.6
2191	0.0	-15.01	8.760	0.00	519.4
2194	0.0	-15.03	8.772	0.00	520.0
2197	-0.2	-15.05	8.784	-0.04	520.8
2200	0.0	-15.07	8.796	0.00	521.4
2203	0.0	-15.09	8.808	0.00	522.2
2206	0.0	-15.11	8.820	0.00	522.8
2209	0.0	-15.13	8.832	0.00	523.6
2212	0.0	-15.16	8.844	0.00	524.6
2215	0.0	-15.18	8.856	0.00	525.2
2218	0.0	-15.20	8.868	0.00	526.0
2221	0.2	-15.22	8.880	0.04	526.6
2224	0.0	-15.24	8.892	0.00	527.4
2227	0.0	-15.26	8.904	0.00	528.0
2230	-0.2	-15.27	8.916	-0.04	528.4
2233	0.0	-15.29	8.928	0.00	529.0
2236	0.0	-15.31	8.940	0.00	529.8
2239	0.2	-15.34	8.952	0.04	530.8
2242	0.0	-15.36	8.964	0.00	531.4
2245	0.0	-15.38	8.976	0.00	532.2
2248	0.0	-15.40	8.988	0.00	532.8
2251	0.0	-15.42	9.000	0.00	533.6
2254	0.0	-15.44	9.012	0.00	534.2
2257	-0.2	-15.46	9.024	-0.04	535.0
2260	0.2	-15.48	9.036	0.04	535.6
2263	0.0	-15.50	9.048	0.00	536.4
2266	-0.2	-15.52	9.060	-0.04	537.0
2269	0.0	-15.55	9.072	0.00	538.0
2272	-0.2	-15.57	9.084	-0.04	538.8
2275	0.0	-15.59	9.096	0.00	539.4
2278	-0.2	-15.61	9.108	-0.04	540.2
2281	-0.2	-15.63	9.120	-0.04	540.8
2284	0.2	-15.65	9.132	0.04	541.6
2287	0.0	-15.67	9.144	0.00	542.2
2290	-0.2	-15.69	9.156	-0.04	543.0
2293	0.0	-15.71	9.168	0.00	543.6
2296	0.0	-15.74	9.180	0.00	544.6
2299	0.0	-15.76	9.192	0.00	545.4
2302	0.0	-15.78	9.204	0.00	546.0
2305	-0.2	-15.80	9.216	-0.04	546.8
2308	0.0	-15.82	9.228	0.00	547.4
2311	0.0	-15.84	9.240	0.00	548.0
2314	0.0	-15.86	9.252	0.00	548.8
2317	0.0	-15.88	9.264	0.00	549.4
2320	0.0	-15.90	9.276	0.00	550.2
2323	0.2	-15.92	9.288	0.04	550.8
2326	0.2	-15.95	9.300	0.04	552.0
2329	0.0	-15.97	9.312	0.00	552.6
2332	-0.2	-15.99	9.324	-0.04	553.2
2335	0.0	-16.01	9.336	0.00	554.0
2338	0.0	-16.03	9.348	0.00	554.6
2341	-0.2	-16.05	9.360	-0.04	555.4
2344	0.0	-16.07	9.372	0.00	556.0
2347	0.2	-16.09	9.384	0.04	556.8
2350	0.2	-16.11	9.396	0.04	557.4
2353	-0.2	-16.13	9.408	-0.04	558.2
2356	0.0	-16.15	9.420	0.00	558.8
2359	0.0	-16.18	9.432	0.00	559.8
2362	0.2	-16.19	9.444	0.04	560.2
2365	0.0	-16.22	9.456	0.00	561.2
2368	0.0	-16.24	9.468	0.00	562.0
2371	0.0	-16.26	9.480	0.00	562.6
2374	0.0	-16.28	9.492	0.00	563.4
2377	0.0	-16.30	9.504	0.00	564.0
2380	-0.2	-16.32	9.516	-0.04	564.8
2383	0.2	-16.34	9.528	0.04	565.4
2386	0.0	-16.36	9.540	0.00	566.0
2389	0.0	-16.38	9.552	0.00	566.8
2392	-0.2	-16.40	9.564	-0.04	567.4
2395	-0.2	-16.42	9.576	-0.04	568.2
2398	0.2	-16.45	9.588	0.04	569.2
2401	0.2	-16.47	9.600	0.04	569.8
2404	-0.2	-16.49	9.612	-0.04	570.6
2407	0.0	-16.51	9.624	0.00	571.2
2410	0.0	-16.53	9.636	0.00	572.0
2413	0.0	-16.55	9.648	0.00	572.6
2416	0.0	-16.57	9.660	0.00	573.4
2419	0.0	-16.59	9.672	0.00	574.0
2422	-0.2	-16.61	9.684	-0.04	574.8
2425	0.0	-16.63	9.696	0.00	575.4
2428	-0.2	-16.65	9.708	-0.04	576.2
2431	0.0	-16.67	9.720	0.00	576.8
2434	0.0	-16.70	9.732	0.00	577.8
2437	0.0	-16.72	9.744	0.00	578.6
2440	0.0	-16.74	9.756	0.00	579.2
2443	-0.2	-16.76	9.768	-0.04	580.0
2446	0.0	-16.78	9.780	0.00	580.6
2449	0.0	-16.80	9.792	0.00	581.4
2452	-0.2	-16.82	9.804	-0.04	582.0
2455	0.0	-16.84	9.816	0.00	582.6
2458	-0.2	-16.86	9.828	-0.04	583.4
2461	0.0	-16.88	9.840	0.00	584.0
2464	0.0	-16.90	9.852	0.00	584.8
2467	0.0	-16.93	9.864	0.00	585.8
2470	0.0	-16.95	9.876	0.00	586.6
2473	0.0	-16.97	9.888	0.00	587.2
2476	0.2	-16.99	9.900	0.04	587.8
2479	-0.2	-17.01	9.912	-0.04	588.6
2482	0.0	-17.03	9.924	0.00	589.2
2485	0.2	-17.05	9.936	0.04	590.0
2488	0.2	-17.07	9.948	0.04	590.6
2491	0.2	-17.09	9.960	0.04	591.4
2494	-0.4	-17.11	9.972	-0.06	592.0
2497	0.0	-17.13	9.984	0.00	592.8
2500	0.0	-17.15	9.996	0.00	593.4
2503	0.0	-17.17	10.008	0.00	594.2
2506	0.6	-17.20	10.020	0.10	595.2
2509	0.0	-17.22	10.032	0.00	595.8
2512	0.0	-17.24	10.044	0.00	596.6
2515	0.0	-17.26	10.056	0.00	597.2
2518	0.0	-17.29	10.068	0.00	598.2
2521	0.0	-17.31	10.080	0.00	599.0
2524	-0.2	-17.33	10.092	-0.04	599.6
2527	0.0	-17.35	10.104	0.00	600.4
2530	-0.2	-17.37	10.116	-0.04	601.0
2533	0.0	-17.39	10.128	0.00	601.8
2536	0.0	-17.41	10.140	0.00	602.4
2539	-0.2	-17.44	10.152	-0.04	603.4
2542	0.0	-17.46	10.164	0.00	604.2
2545	0.0	-17.48	10.176	0.00	604.8
2548	-0.2	-17.50	10.188	-0.04	605.6
2551	0.0	-17.52	10.200	0.00	606.2
2554	0.4	-17.54	10.212	0.06	607.0
2557	0.0	-17.56	10.224	0.00	607.6
2560	0.0	-17.58	10.236	0.00	608.4
2563	0.0	-17.60	10.248	0.00	609.0
2566	-0.2	-17.62	10.260	-0.04	609.6
2569	0.4	-17.64	10.272	0.06	610.4
2572	0.0	-17.66	10.284	0.00	611.0
2575	0.0	-17.69	10.296	0.00	612.2
2578	0.0	-17.71	10.308	0.00	612.8
2581	-0.6	-17.73	10.320	-0.10	613.4
2584	-0.2	-17.75	10.332	-0.04	614.2
2587	0.0	-17.77	10.344	0.00	614.8
2590	-0.4	-17.79	10.356	-0.06	615.6
2593	0.0	-17.81	10.368	0.00	616.2
2596	-0.4	-17.83	10.380	-0.06	617.0
2599	0.0	-17.85	10.392	0.00	617.6
2602	0.0	-17.87	10.404	0.00	618.4
2605	0.0	-17.89	10.416	0.00	619.0
2608	0.0	-17.92	10.428	0.00	620.0
2611	-0.2	-17.94	10.440	-0.04	620.8
2614	0.0	-17.96	10.452	0.00	621.4
2617	0.0	-17.98	10.464	0.00	622.2
2620	-0.4	-18.00	10.476	-0.06	622.8
2623	0.0	-18.02	10.488	0.00	623.6
2626	0.4	-18.04	10.500	0.06	624.2
2629	0.0	-18.06	10.512	0.00	625.0
2632	0.2	-18.08	10.524	0.04	625.6
2635	0.0	-18.10	10.536	0.00	626.2
2638	0.0	-18.12	10.548	0.00	627.0
2641	0.0	-18.15	10.560	0.00	628.0
2644	-0.2	-18.17	10.572	-0.04	628.8
2647	0.0	-18.19	10.584	0.00	629.4
2650	-0.2	-18.21	10.596	-0.04	630.2
2653	0.0	-18.23	10.608	0.00	630.8
2656	0.0	-18.25	10.620	0.00	631.4
2659	0.0	-18.27	10.632	0.00	632.2
2662	0.0	-18.29	10.644	0.00	632.8
2665	0.2	-18.31	10.656	0.04	633.6
2668	0.2	-18.33	10.668	0.04	634.2
2671	0.0	-18.36	10.680	0.00	635.2
2674	0.0	-18.38	10.692	0.00	636.0
2677	0.2	-18.40	10.704	0.04	636.6
2680	0.0	-18.42	10.716	0.00	637.4
2683	0.0	-18.44	10.728	0.00	638.0
2686	0.2	-18.46	10.740	0.04	638.8
2689	0.0	-18.48	10.752	0.00	639.4
2692	0.0	-18.50	10.764	0.00	640.2
2695	0.2	-18.52	10.776	0.04	640.8
2698	0.2	-18.55	10.788	0.04	641.8
2701	0.2	-18.57	10.800	0.04	642.6
2704	0.0	-18.59	10.812	0.00	643.2
2707	0.2	-18.61	10.824	0.04	644.0
2710	0.4	-18.63	10.836	0.06	644.6
2713	0.0	-18.65	10.848	0.00	645.4
2716	0.2	-18.67	10.860	0.04	646.0
2719	0.0	-18.69	10.872	0.00	646.8
2722	0.0	-18.71	10.884	0.00	647.4
2725	-0.2	-18.73	10.896	-0.04	648.0
2728	0.0	-18.76	10.908	0.00	649.2
2731	0.0	-18.78	10.920	0.00	649.8
2734	-0.2	-18.80	10.932	-0.04	650.6
2737	0.0	-18.82	10.944	0.00	651.2
2740	-0.2	-18.84	10.956	-0.04	652.0
2743	0.0	-18.86	10.968	0.00	652.6
2746	0.0	-18.88	10.980	0.00	653.2
2749	-0.4	-18.90	10.992	-0.06	654.0
2752	0.0	-18.92	11.004	0.00	654.6
2755	0.0	-18.94	11.016	0.00	655.4
2758	0.0	-18.97	11.028	0.00	656.4
2761	0.2	-18.99	11.040	0.04	657.0
2764	0.0	-19.01	11.052	0.00	657.8
2767	0.0	-19.03	11.064	0.00	658.4
2770	0.0	-19.05	11.076	0.00	659.2
2773	0.0	-19.07	11.088	0.00	659.8
2776	0.2	-19.09	11.100	0.04	660.6
2779	0.0	-19.11	11.112	0.00	661.2
2782	0.0	-19.14	11.124	0.00	662.2
2785	0.0	-19.16	11.136	0.00	663.0
2788	0.2	-19.18	11.148	0.04	663.6
2791	0.0	-19.20	11.160	0.00	664.4
2794	0.0	-19.22	11.172	0.00	665.0
2797	0.0	-19.24	11.184	0.00	665.8
2800	0.2	-19.26	11.196	0.04	666.4
2803	0.0	-19.27	11.208	0.00	666.8
2806	0.0	-19.30	11.220	0.00	667.8
2809	0.0	-19.32	11.232	0.00	668.6
2812	-0.4	-19.34	11.244	-0.06	669.2
2815	-0.2	-19.36	11.256	-0.04	669.8
2818	0.4	-19.38	11.268	0.06	670.6
2821	0.2	-19.40	11.280	0.04	671.2
2824	0.0	-19.42	11.292	0.00	672.0
2827	-0.2	-19.44	11.304	-0.04	672.6
2830	0.2	-19.46	11.316	0.04	673.4
2833	0.0	-19.49	11.328	0.00	674.4
2836	0.0	-19.51	11.340	0.00	675.0
2839	0.0	-19.53	11.352	0.00	675.8
2842	0.0	-19.55	11.364	0.00	676.4
2845	-0.2	-19.57	11.376	-0.04	677.2
2848	0.0	-19.59	11.388	0.00	677.8
2851	0.0	-19.61	11.400	0.00	678.6
2854	0.0	-19.63	11.412	0.00	679.2
2857	-0.2	-19.65	11.424	-0.04	680.0
2860	0.0	-19.68	11.436	0.00	681.0
2863	0.0	-19.70	11.448	0.00	681.6
2866	-0.2	-19.72	11.460	-0.04	682.4
2869	0.0	-19.74	11.472	0.00	683.0
2872	0.6	-19.76	11.484	0.10	683.8
2875	0.4	-19.78	11.496	0.06	684.4
2878	0.8	-19.80	11.508	0.12	685.2
2881	1.2	-19.82	11.520	0.20	685.8
2884	2.6	-19.84	11.532	0.42	686.6
2887	4.6	-19.86	11.544	0.74	687.2
2890	8.0	-19.88	11.556	1.28	687.8
2893	12.4	-19.90	11.568	2.00	688.6
2896	18.0	-19.91	11.580	2.90	689.0
2899	25.2	-19.93	11.592	4.06	689.6
2902	36.8	-19.94	11.604	5.94	690.0
2905	48.0	-19.95	11.616	7.74	690.4
2908	55.2	-19.97	11.628	8.90	691.0
2911	59.2	-19.98	11.640	9.54	691.4
2914	62.4	-20.00	11.652	10.06	692.0
2917	64.0	-20.02	11.664	10.32	692.8
2920	64.6	-20.05	11.676	10.42	693.8
2923	64.6	-20.07	11.688	10.42	694.4
2926	64.2	-20.09	11.700	10.36	695.2
2929	63.4	-20.11	11.712	10.22	695.8
2932	62.4	-20.13	11.724	10.06	696.6
2935	61.2	-20.15	11.736	9.86	697.2
2938	59.6	-20.17	11.748	9.62	698.0
2941	57.8	-20.20	11.760	9.32	699.0
2944	34.2	-20.24	11.772	5.52	700.4
2947	34.4	-20.26	11.784	5.54	701.0
2950	35.0	-20.28	11.796	5.64	701.8
2953	35.4	-20.30	11.808	5.70	702.4
2956	35.8	-20.32	11.820	5.78	703.2
2959	35.0	-20.34	11.832	5.64	703.8
2962	34.2	-20.37	11.844	5.52	704.8
2965	34.8	-20.39	11.856	5.62	705.6
2968	37.2	-20.41	11.868	6.00	706.2
2971	41.2	-20.42	11.880	6.64	706.6
2974	40.4	-20.45	11.892	6.52	707.6
2977	38.4	-20.47	11.904	6.20	708.4
2980	37.6	-20.49	11.916	6.06	709.0
2983	37.6	-20.51	11.928	6.06	709.6
2986	37.2	-20.53	11.940	6.00	710.4
2989	34.6	-20.55	11.952	5.58	711.0
2992	32.4	-20.58	11.964	5.22	712.2
2995	27.6	-20.60	11.976	4.46	712.8
2998	24.8	-20.63	11.988	4.00	713.8
3001	25.0	-20.65	12.000	4.04	714.6
3004	24.8	-20.67	12.012	4.00	715.2
3007	25.0	-20.69	12.024	4.04	716.0
3010	24.8	-20.71	12.036	4.00	716.6
3013	24.8	-20.73	12.048	4.00	717.4
3016	24.4	-20.75	12.060	3.94	718.0
3019	24.2	-20.77	12.072	3.90	718.6
3022	24.6	-20.80	12.084	3.96	719.8
3025	24.0	-20.82	12.096	3.86	720.4
3028	24.4	-20.84	12.108	3.94	721.2
3031	24.4	-20.86	12.120	3.94	721.8
3034	24.8	-20.88	12.132	4.00	722.4
3037	24.6	-20.90	12.144	3.96	723.2
3040	25.0	-20.92	12.156	4.04	723.8
3043	26.0	-20.94	12.168	4.20	724.6
3046	26.2	-20.96	12.180	4.22	725.2
3049	26.6	-20.98	12.192	4.28	726.0
3052	27.2	-21.00	12.204	4.38	726.6
3055	27.8	-21.02	12.216	4.48	727.4
3058	28.6	-21.04	12.228	4.62	728.0
3061	29.6	-21.06	12.240	4.78	728.8
3064	30.6	-21.08	12.252	4.94	729.4
3067	31.6	-21.10	12.264	5.10	730.2
3070	33.6	-21.12	12.276	5.42	730.8
3073	34.4	-21.14	12.288	5.54	731.4
3076	36.6	-21.16	12.300	5.90	732.2
3079	38.0	-21.18	12.312	6.12	732.8
3082	40.4	-21.20	12.324	6.52	733.6
3085	42.6	-21.22	12.336	6.86	734.2
3088	44.2	-21.24	12.348	7.12	735.0
3091	45.6	-21.26	12.360	7.36	735.6
3094	46.6	-21.28	12.372	7.52	736.4
3097	48.4	-21.30	12.384	7.80	737.0
3100	49.2	-21.32	12.396	7.94	737.8
3103	50.0	-21.34	12.408	8.06	738.4
3106	51.4	-21.36	12.420	8.28	739.2
3109	52.2	-21.38	12.432	8.42	739.8
3112	53.6	-21.40	12.444	8.64	740.4
3115	54.0	-21.42	12.456	8.70	741.2
3118	54.8	-21.44	12.468	8.84	741.8
3121	55.2	-21.46	12.480	8.90	742.6
3124	55.8	-21.48	12.492	9.00	743.2
3127	55.8	-21.50	12.504	9.00	744.0
3130	56.2	-21.52	12.516	9.06	744.6
3133	55.6	-21.54	12.528	8.96	745.4
3136	55.8	-21.56	12.540	9.00	746.0
3139	55.6	-21.58	12.552	8.96	746.8
3142	52.4	-21.59	12.564	8.44	747.0
3145	49.0	-21.60	12.576	7.90	747.4
3148	46.8	-21.60	12.588	7.54	747.4
3151	45.8	-21.60	12.600	7.38	747.4
3154	44.8	-21.60	12.612	7.22	747.4
3157	44.2	-21.60	12.624	7.12	747.4
3160	43.6	-21.60	12.636	7.04	747.4
3163	43.0	-21.60	12.648	6.94	747.4
3166	42.8	-21.60	12.660	6.90	747.4
3169	42.6	-21.60	12.672	6.86	747.4
3172	42.2	-21.60	12.684	6.80	747.4
3174	64.8	-20.08	12.692	6.74	747.4