File: results/youngs-modulus/2025-04-21/inconclusive-data/pf13lt02.csv
Axial Compression Test-Jun-21-2024-09-34-39-AM.log,,,,,
,,,,,
System Information:,,,,,
IntelliMESUR Version: 2.2.1,,,,,
Test Frame Model: F505,,,,,
Test Frame Serial Number: 4418651,,,,,
Test Frame Capacity: 500 lbF / 2.2 kN,,,,,
Test Frame Firmware Version: 1.00.14,,,,,
Force Sensor Model: FS05-100,,,,,
Force Sensor Capacity: 500 N,,,,,
Force Sensor Resolution: 0.2 N,,,,,
Force Sensor Serial Number: 4425350,,,,,
"Calibration Date: Apr 29, 2024",,,,,
"Calibration Due Date: Apr 29, 2025",,,,,
,,,,,
Reading,Load [N],Distance [mm],Time [s],Stress [MPa],Strain [%]
1,0.2,-0.02,0,0.1,1
4,0,-0.02,0.012,0,1
7,0.2,-0.02,0.024,0.1,1
10,0.4,-0.02,0.036,0.2,1
13,0.2,-0.02,0.048,0.1,1
16,-0.2,-0.02,0.06,-0.1,1
19,0.2,-0.02,0.072,0.1,1
22,0.2,-0.02,0.084,0.1,1
25,0.2,-0.02,0.096,0.1,1
28,0.4,-0.02,0.108,0.2,1
31,0.2,-0.02,0.12,0.1,1
34,0.2,-0.02,0.132,0.1,1
37,0.2,-0.02,0.144,0.1,1
40,0,-0.02,0.156,0,1
43,0.2,-0.02,0.168,0.1,1
46,0.2,-0.02,0.18,0.1,1
49,0.4,-0.03,0.192,0.2,2
52,0.2,-0.05,0.204,0.1,3
55,0.2,-0.07,0.216,0.1,4
58,0,-0.09,0.228,0,5.5
61,0.2,-0.11,0.24,0.1,6.5
64,-0.2,-0.13,0.252,-0.1,7.5
67,0.2,-0.15,0.264,0.1,9
70,0.2,-0.18,0.276,0.1,10.5
73,0.2,-0.2,0.288,0.1,11.5
76,0.4,-0.22,0.3,0.2,13
79,0.2,-0.24,0.312,0.1,14
82,0.2,-0.26,0.324,0.1,15
85,0.2,-0.28,0.336,0.1,16.5
88,0.4,-0.3,0.348,0.2,17.5
91,-0.2,-0.32,0.36,-0.1,18.5
94,0.2,-0.34,0.372,0.1,20
97,0.2,-0.37,0.384,0.1,21.5
100,0.2,-0.38,0.396,0.1,22
103,0.2,-0.4,0.408,0.1,23.5
106,0.2,-0.42,0.42,0.1,24.5
109,0.4,-0.44,0.432,0.2,25.5
112,0.2,-0.46,0.444,0.1,27
115,0.2,-0.48,0.456,0.1,28
118,0.2,-0.51,0.468,0.1,30
121,0.2,-0.52,0.48,0.1,30.5
124,0.2,-0.55,0.492,0.1,32
127,-0.2,-0.57,0.504,-0.1,33.5
130,-0.2,-0.59,0.516,-0.1,34.5
133,0.2,-0.61,0.528,0.1,35.5
136,0.2,-0.63,0.54,0.1,37
139,0.2,-0.65,0.552,0.1,38
142,0.4,-0.67,0.564,0.2,39
145,0.2,-0.69,0.576,0.1,40.5
148,0.2,-0.71,0.588,0.1,41.5
151,0.4,-0.74,0.6,0.2,43.5
154,0,-0.76,0.612,0,44.5
157,0.2,-0.78,0.624,0.1,45.5
160,0.2,-0.8,0.636,0.1,47
163,0.2,-0.82,0.648,0.1,48
166,0.4,-0.84,0.66,0.2,49
169,0.2,-0.86,0.672,0.1,50.5
172,0.2,-0.88,0.684,0.1,51.5
175,0.2,-0.9,0.696,0.1,52.5
178,0.2,-0.92,0.708,0.1,54
181,0.2,-0.94,0.72,0.1,55
184,0.2,-0.97,0.732,0.1,56.5
187,0.4,-0.99,0.744,0.2,58
190,0.2,-1.01,0.756,0.1,59
193,0.2,-1.03,0.768,0.1,60
196,0.2,-1.05,0.78,0.1,61.5
199,0.2,-1.07,0.792,0.1,62.5
202,0.2,-1.09,0.804,0.1,63.5
205,0.2,-1.11,0.816,0.1,65
208,0.2,-1.13,0.828,0.1,66
211,0.2,-1.15,0.84,0.1,67.5
214,0,-1.18,0.852,0,69
217,0.2,-1.2,0.864,0.1,70
220,0.2,-1.22,0.876,0.1,71.5
223,0.2,-1.24,0.888,0.1,72.5
226,0,-1.26,0.9,0,73.5
229,-0.2,-1.28,0.912,-0.1,75
232,0.2,-1.3,0.924,0.1,76
235,0.2,-1.32,0.936,0.1,77
238,0.2,-1.34,0.948,0.1,78.5
241,0.2,-1.37,0.96,0.1,80
244,0.2,-1.39,0.972,0.1,81.5
247,0,-1.42,0.984,0,83
250,0.2,-1.44,0.996,0.1,84
253,0.2,-1.46,1.008,0.1,85.5
256,0.2,-1.48,1.02,0.1,86.5
259,0.4,-1.5,1.032,0.2,87.5
262,0.2,-1.52,1.044,0.1,89
265,0.2,-1.54,1.056,0.1,90
268,0.2,-1.56,1.068,0.1,91
271,0.2,-1.58,1.08,0.1,92.5
274,0.2,-1.6,1.092,0.1,93.5
277,0.2,-1.62,1.104,0.1,94.5
280,0.2,-1.65,1.116,0.1,96.5
283,0.2,-1.67,1.128,0.1,97.5
286,0.2,-1.69,1.14,0.1,99
289,0,-1.71,1.152,0,100
292,0.2,-1.73,1.164,0.1,101
295,0.2,-1.75,1.176,0.1,102.5
298,0.2,-1.77,1.188,0.1,103.5
301,0.4,-1.79,1.2,0.2,104.5
304,0.2,-1.81,1.212,0.1,106
307,0.4,-1.83,1.224,0.2,107
310,0.2,-1.85,1.236,0.1,108
313,0.4,-1.88,1.248,0.2,110
316,0.2,-1.9,1.26,0.1,111
319,0.2,-1.92,1.272,0.1,112.5
322,0.2,-1.94,1.284,0.1,113.5
325,0.2,-1.96,1.296,0.1,114.5
328,0.4,-1.98,1.308,0.2,116
331,0.2,-2,1.32,0.1,117
334,0.2,-2.02,1.332,0.1,118
337,0,-2.04,1.344,0,119.5
340,0.2,-2.06,1.356,0.1,120.5
343,0.2,-2.08,1.368,0.1,121.5
346,0.2,-2.1,1.38,0.1,123
349,0,-2.13,1.392,0,124.5
352,0.2,-2.15,1.404,0.1,125.5
355,-0.2,-2.17,1.416,-0.1,127
358,0.2,-2.19,1.428,0.1,128
361,0.2,-2.21,1.44,0.1,129
364,0.2,-2.23,1.452,0.1,130.5
367,0.2,-2.25,1.464,0.1,131.5
370,0.2,-2.27,1.476,0.1,132.5
373,-0.2,-2.29,1.488,-0.1,134
376,0.2,-2.31,1.5,0.1,135
379,0.2,-2.33,1.512,0.1,136.5
382,0.2,-2.36,1.524,0.1,138
385,0.4,-2.37,1.536,0.2,138.5
388,0.6,-2.39,1.548,0.3,140
391,0,-2.41,1.56,0,141
394,0.2,-2.43,1.572,0.1,142
397,0.2,-2.45,1.584,0.1,143.5
400,0.2,-2.47,1.596,0.1,144.5
403,0.2,-2.49,1.608,0.1,145.5
406,0.2,-2.51,1.62,0.1,147
409,0.2,-2.53,1.632,0.1,148
412,0.2,-2.55,1.644,0.1,149
415,0,-2.58,1.656,0,151
418,-0.2,-2.6,1.668,-0.1,152
421,0.2,-2.62,1.68,0.1,153
424,0.2,-2.64,1.692,0.1,154.5
427,0.2,-2.66,1.704,0.1,155.5
430,-0.2,-2.68,1.716,-0.1,156.5
433,0.2,-2.7,1.728,0.1,158
436,0.2,-2.72,1.74,0.1,159
439,0.4,-2.74,1.752,0.2,160
442,0.2,-2.76,1.764,0.1,161.5
445,0.2,-2.78,1.776,0.1,162.5
448,0.2,-2.81,1.788,0.1,164.5
451,0.2,-2.83,1.8,0.1,165.5
454,0.2,-2.85,1.812,0.1,166.5
457,0.2,-2.87,1.824,0.1,168
460,0.2,-2.89,1.836,0.1,169
463,0.4,-2.91,1.848,0.2,170
466,0,-2.93,1.86,0,171.5
469,0.2,-2.95,1.872,0.1,172.5
472,0.4,-2.97,1.884,0.2,173.5
475,0.2,-2.99,1.896,0.1,175
478,0.2,-3.01,1.908,0.1,176
481,0.2,-3.03,1.92,0.1,177
484,0.2,-3.06,1.932,0.1,179
487,0.2,-3.08,1.944,0.1,180
490,0.2,-3.1,1.956,0.1,181.5
493,0.2,-3.12,1.968,0.1,182.5
496,0.2,-3.14,1.98,0.1,183.5
499,0,-3.16,1.992,0,185
502,0.2,-3.18,2.004,0.1,186
505,0.2,-3.2,2.016,0.1,187
508,0.2,-3.22,2.028,0.1,188.5
511,0.4,-3.25,2.04,0.2,190
514,0,-3.26,2.052,0,190.5
517,0.2,-3.29,2.064,0.1,192.5
520,0.2,-3.31,2.076,0.1,193.5
523,0.2,-3.33,2.088,0.1,194.5
526,0.2,-3.35,2.1,0.1,196
529,0.2,-3.38,2.112,0.1,197.5
532,0.4,-3.4,2.124,0.2,199
535,0.2,-3.42,2.136,0.1,200
538,0,-3.44,2.148,0,201
541,0.2,-3.46,2.16,0.1,202.5
544,0.2,-3.49,2.172,0.1,204
547,0.4,-3.51,2.184,0.2,205.5
550,0,-3.53,2.196,0,206.5
553,0.2,-3.55,2.208,0.1,207.5
556,0.2,-3.57,2.22,0.1,209
559,0.2,-3.59,2.232,0.1,210
562,0.2,-3.61,2.244,0.1,211
565,-0.2,-3.63,2.256,-0.1,212.5
568,0.2,-3.65,2.268,0.1,213.5
571,0.2,-3.68,2.28,0.1,215
574,0.2,-3.7,2.292,0.1,216.5
577,0.2,-3.72,2.304,0.1,217.5
580,0,-3.74,2.316,0,218.5
583,0.2,-3.76,2.328,0.1,220
586,0.2,-3.78,2.34,0.1,221
589,0.2,-3.8,2.352,0.1,222
592,0,-3.82,2.364,0,223.5
595,0.2,-3.84,2.376,0.1,224.5
598,0.2,-3.87,2.388,0.1,226.5
601,0,-3.88,2.4,0,227
604,0.2,-3.91,2.412,0.1,228.5
607,0.2,-3.93,2.424,0.1,230
610,0.2,-3.95,2.436,0.1,231
613,0,-3.97,2.448,0,232
616,-0.2,-3.99,2.46,-0.1,233.5
619,0,-4.01,2.472,0,234.5
622,-0.2,-4.03,2.484,-0.1,235.5
625,0.2,-4.06,2.496,0.1,237.5
628,0,-4.08,2.508,0,238.5
631,0.2,-4.1,2.52,0.1,240
634,0.2,-4.12,2.532,0.1,241
637,0,-4.14,2.544,0,242
640,0.2,-4.16,2.556,0.1,243.5
643,0,-4.18,2.568,0,244.5
646,0.2,-4.2,2.58,0.1,245.5
649,0.2,-4.22,2.592,0.1,247
652,0.2,-4.25,2.604,0.1,248.5
655,0,-4.27,2.616,0,249.5
658,0.2,-4.29,2.628,0.1,251
661,0.2,-4.31,2.64,0.1,252
664,0.4,-4.33,2.652,0.2,253
667,0.2,-4.35,2.664,0.1,254.5
670,0.2,-4.37,2.676,0.1,255.5
673,-0.2,-4.39,2.688,-0.1,256.5
676,0.2,-4.41,2.7,0.1,258
679,0.2,-4.44,2.712,0.1,259.5
682,0.2,-4.46,2.724,0.1,261
685,0.4,-4.48,2.736,0.2,262
688,0.2,-4.5,2.748,0.1,263
691,0.2,-4.52,2.76,0.1,264.5
694,0,-4.54,2.772,0,265.5
697,0.2,-4.56,2.784,0.1,266.5
700,0.2,-4.58,2.796,0.1,268
703,0,-4.6,2.808,0,269
706,0.4,-4.63,2.82,0.2,271
709,0.2,-4.65,2.832,0.1,272
712,0.2,-4.67,2.844,0.1,273
715,0.2,-4.69,2.856,0.1,274.5
718,0.2,-4.71,2.868,0.1,275.5
721,0,-4.73,2.88,0,276.5
724,0.2,-4.75,2.892,0.1,278
727,0.2,-4.77,2.904,0.1,279
730,0.4,-4.79,2.916,0.2,280
733,0.2,-4.82,2.928,0.1,282
736,0,-4.84,2.94,0,283
739,0,-4.86,2.952,0,284
742,0.2,-4.88,2.964,0.1,285.5
745,0.2,-4.9,2.976,0.1,286.5
748,0.2,-4.92,2.988,0.1,287.5
751,0.2,-4.94,3,0.1,289
754,0.4,-4.96,3.012,0.2,290
757,0.2,-4.98,3.024,0.1,291
760,0,-5.01,3.036,0,293
763,0.2,-5.03,3.048,0.1,294
766,0.2,-5.05,3.06,0.1,295.5
769,0.2,-5.07,3.072,0.1,296.5
772,0.2,-5.09,3.084,0.1,297.5
775,0.4,-5.11,3.096,0.2,299
778,0.4,-5.13,3.108,0.2,300
781,0,-5.16,3.12,0,302
784,0.2,-5.17,3.132,0.1,302.5
787,0.2,-5.2,3.144,0.1,304
790,0.2,-5.22,3.156,0.1,305.5
793,0.2,-5.24,3.168,0.1,306.5
796,-0.2,-5.26,3.18,-0.1,307.5
799,0.2,-5.28,3.192,0.1,309
802,0.2,-5.3,3.204,0.1,310
805,0.4,-5.32,3.216,0.2,311
808,0.2,-5.35,3.228,0.1,313
811,0.2,-5.36,3.24,0.1,313.5
814,0.2,-5.39,3.252,0.1,315
817,0.4,-5.41,3.264,0.2,316.5
820,0.4,-5.43,3.276,0.2,317.5
823,-0.2,-5.45,3.288,-0.1,318.5
826,0.4,-5.47,3.3,0.2,320
829,0,-5.49,3.312,0,321
832,0.2,-5.51,3.324,0.1,322
835,0,-5.53,3.336,0,323.5
838,0.2,-5.55,3.348,0.1,324.5
841,0.2,-5.58,3.36,0.1,326.5
844,0.2,-5.6,3.372,0.1,327.5
847,0.2,-5.62,3.384,0.1,328.5
850,0.2,-5.64,3.396,0.1,330
853,0.6,-5.66,3.408,0.3,331
856,0.2,-5.68,3.42,0.1,332
859,0.4,-5.7,3.432,0.2,333.5
862,-0.2,-5.72,3.444,-0.1,334.5
865,0.2,-5.74,3.456,0.1,335.5
868,0.2,-5.77,3.468,0.1,337.5
871,0.2,-5.79,3.48,0.1,338.5
874,0.4,-5.81,3.492,0.2,340
877,0,-5.83,3.504,0,341
880,-0.2,-5.85,3.516,-0.1,342
883,0.2,-5.87,3.528,0.1,343.5
886,0.2,-5.89,3.54,0.1,344.5
889,0,-5.91,3.552,0,345.5
892,0.2,-5.93,3.564,0.1,347
895,0.2,-5.96,3.576,0.1,348.5
898,0.2,-5.97,3.588,0.1,349
901,0.4,-6,3.6,0.2,351
904,0.2,-6.02,3.612,0.1,352
907,0,-6.04,3.624,0,353
910,0.2,-6.06,3.636,0.1,354.5
913,0.2,-6.08,3.648,0.1,355.5
916,0.4,-6.1,3.66,0.2,356.5
919,0.2,-6.12,3.672,0.1,358
922,0.2,-6.14,3.684,0.1,359
925,0.2,-6.16,3.696,0.1,360
928,0.2,-6.18,3.708,0.1,361.5
931,0.2,-6.2,3.72,0.1,362.5
934,0.2,-6.22,3.732,0.1,363.5
937,0.2,-6.25,3.744,0.1,365.5
940,0.2,-6.27,3.756,0.1,366.5
943,0.2,-6.29,3.768,0.1,368
946,0.2,-6.31,3.78,0.1,369
949,0.2,-6.33,3.792,0.1,370
952,0.2,-6.35,3.804,0.1,371.5
955,0.2,-6.36,3.816,0.1,372
958,0,-6.38,3.828,0,373
961,-0.2,-6.4,3.84,-0.1,374.5
964,0.2,-6.43,3.852,0.1,376
967,0.4,-6.44,3.864,0.2,376.5
970,0.2,-6.47,3.876,0.1,378.5
973,-0.2,-6.49,3.888,-0.1,379.5
976,0.2,-6.51,3.9,0.1,380.5
979,0.2,-6.53,3.912,0.1,382
982,0.2,-6.55,3.924,0.1,383
985,0.2,-6.57,3.936,0.1,384
988,0.4,-6.59,3.948,0.2,385.5
991,0.2,-6.61,3.96,0.1,386.5
994,0.2,-6.63,3.972,0.1,387.5
997,0,-6.65,3.984,0,389
1000,0.2,-6.67,3.996,0.1,390
1003,0.4,-6.7,4.008,0.2,392
1006,0,-6.72,4.02,0,393
1009,0.2,-6.74,4.032,0.1,394
1012,0,-6.76,4.044,0,395.5
1015,0,-6.78,4.056,0,396.5
1018,-0.2,-6.8,4.068,-0.1,397.5
1021,0.4,-6.82,4.08,0.2,399
1024,0.2,-6.84,4.092,0.1,400
1027,0.2,-6.86,4.104,0.1,401
1030,0.2,-6.88,4.116,0.1,402.5
1033,0.2,-6.9,4.128,0.1,403.5
1036,0.2,-6.92,4.14,0.1,404.5
1039,0.2,-6.95,4.152,0.1,406.5
1042,0.2,-6.97,4.164,0.1,407.5
1045,0.2,-6.99,4.176,0.1,409
1048,0.2,-7.01,4.188,0.1,410
1051,0.2,-7.03,4.2,0.1,411
1054,0,-7.05,4.212,0,412.5
1057,0,-7.07,4.224,0,413.5
1060,-0.2,-7.09,4.236,-0.1,414.5
1063,0.4,-7.11,4.248,0.2,416
1066,0.2,-7.13,4.26,0.1,417
1069,0.2,-7.15,4.272,0.1,418
1072,0.4,-7.18,4.284,0.2,420
1075,0.2,-7.19,4.296,0.1,420.5
1078,0.4,-7.22,4.308,0.2,422
1081,0.2,-7.24,4.32,0.1,423.5
1084,0.2,-7.26,4.332,0.1,424.5
1087,0.2,-7.28,4.344,0.1,425.5
1090,0.4,-7.3,4.356,0.2,427
1093,0.2,-7.32,4.368,0.1,428
1096,0.2,-7.34,4.38,0.1,429
1099,0.2,-7.37,4.392,0.1,431
1102,0.2,-7.39,4.404,0.1,432
1105,0.2,-7.42,4.416,0.1,434
1108,0,-7.43,4.428,0,434.5
1111,0.2,-7.46,4.44,0.1,436.5
1114,0.2,-7.48,4.452,0.1,437.5
1117,0.2,-7.5,4.464,0.1,438.5
1120,0.2,-7.52,4.476,0.1,440
1123,0,-7.54,4.488,0,441
1126,0.2,-7.56,4.5,0.1,442
1129,0.2,-7.58,4.512,0.1,443.5
1132,0.2,-7.6,4.524,0.1,444.5
1135,0,-7.62,4.536,0,445.5
1138,0.2,-7.64,4.548,0.1,447
1141,0.2,-7.67,4.56,0.1,448.5
1144,0.2,-7.69,4.572,0.1,449.5
1147,0.2,-7.71,4.584,0.1,451
1150,0.2,-7.73,4.596,0.1,452
1153,0.2,-7.75,4.608,0.1,453
1156,0,-7.77,4.62,0,454.5
1159,0.2,-7.79,4.632,0.1,455.5
1162,0.2,-7.81,4.644,0.1,456.5
1165,0.2,-7.83,4.656,0.1,458
1168,0.2,-7.85,4.668,0.1,459
1171,0.2,-7.87,4.68,0.1,460
1174,0.2,-7.89,4.692,0.1,461.5
1177,0.2,-7.91,4.704,0.1,462.5
1180,0.2,-7.94,4.716,0.1,464.5
1183,0,-7.96,4.728,0,465.5
1186,0.2,-7.98,4.74,0.1,466.5
1189,0.2,-8,4.752,0.1,468
1192,0.2,-8.02,4.764,0.1,469
1195,0.2,-8.04,4.776,0.1,470
1198,0.2,-8.06,4.788,0.1,471.5
1201,0.2,-8.08,4.8,0.1,472.5
1204,0.2,-8.1,4.812,0.1,473.5
1207,0.4,-8.13,4.824,0.2,475.5
1210,0.4,-8.14,4.836,0.2,476
1213,0.4,-8.17,4.848,0.2,478
1216,0,-8.19,4.86,0,479
1219,0.2,-8.21,4.872,0.1,480
1222,0,-8.23,4.884,0,481.5
1225,0.2,-8.25,4.896,0.1,482.5
1228,0.2,-8.27,4.908,0.1,483.5
1231,0.2,-8.29,4.92,0.1,485
1234,0.2,-8.31,4.932,0.1,486
1237,0,-8.33,4.944,0,487
1240,0.4,-8.36,4.956,0.2,489
1243,0.4,-8.38,4.968,0.2,490
1246,0.2,-8.4,4.98,0.1,491
1249,-0.2,-8.42,4.992,-0.1,492.5
1252,0.2,-8.44,5.004,0.1,493.5
1255,0,-8.46,5.016,0,494.5
1258,0.2,-8.48,5.028,0.1,496
1261,0.4,-8.5,5.04,0.2,497
1264,0,-8.52,5.052,0,498
1267,0.2,-8.54,5.064,0.1,499.5
1270,0,-8.56,5.076,0,500.5
1273,0.2,-8.59,5.088,0.1,502.5
1276,0.2,-8.61,5.1,0.1,503.5
1279,0.2,-8.63,5.112,0.1,504.5
1282,0,-8.65,5.124,0,506
1285,0.2,-8.67,5.136,0.1,507
1288,0.2,-8.69,5.148,0.1,508
1291,0.2,-8.71,5.16,0.1,509.5
1294,0.2,-8.73,5.172,0.1,510.5
1297,0,-8.75,5.184,0,511.5
1300,0.4,-8.78,5.196,0.2,513.5
1303,0.2,-8.8,5.208,0.1,514.5
1306,0.4,-8.82,5.22,0.2,516
1309,0,-8.84,5.232,0,517
1312,-0.2,-8.86,5.244,-0.1,518
1315,0.2,-8.88,5.256,0.1,519.5
1318,0.4,-8.9,5.268,0.2,520.5
1321,0,-8.92,5.28,0,521.5
1324,0.2,-8.94,5.292,0.1,523
1327,0,-8.97,5.304,0,524.5
1330,0,-8.99,5.316,0,525.5
1333,0.2,-9.01,5.328,0.1,527
1336,0,-9.03,5.34,0,528
1339,0.2,-9.05,5.352,0.1,529
1342,0,-9.07,5.364,0,530.5
1345,0.2,-9.09,5.376,0.1,531.5
1348,0.2,-9.11,5.388,0.1,532.5
1351,0.2,-9.13,5.4,0.1,534
1354,0.2,-9.16,5.412,0.1,535.5
1357,0.2,-9.18,5.424,0.1,537
1360,0.2,-9.2,5.436,0.1,538
1363,0.4,-9.22,5.448,0.2,539
1366,0.2,-9.24,5.46,0.1,540.5
1369,0.2,-9.26,5.472,0.1,541.5
1372,0.2,-9.28,5.484,0.1,542.5
1375,0.4,-9.3,5.496,0.2,544
1378,0.2,-9.32,5.508,0.1,545
1381,0.2,-9.35,5.52,0.1,547
1384,-0.2,-9.37,5.532,-0.1,548
1387,0.2,-9.39,5.544,0.1,549
1390,0,-9.41,5.556,0,550.5
1393,0.2,-9.43,5.568,0.1,551.5
1396,0,-9.45,5.58,0,552.5
1399,0.2,-9.47,5.592,0.1,554
1402,0,-9.49,5.604,0,555
1405,0.4,-9.51,5.616,0.2,556
1408,0.4,-9.54,5.628,0.2,558
1411,-0.2,-9.56,5.64,-0.1,559
1414,0.4,-9.58,5.652,0.2,560
1417,0.2,-9.6,5.664,0.1,561.5
1420,0,-9.62,5.676,0,562.5
1423,0.2,-9.64,5.688,0.1,563.5
1426,0.4,-9.66,5.7,0.2,565
1429,0.2,-9.69,5.712,0.1,566.5
1432,0.2,-9.71,5.724,0.1,568
1435,0.2,-9.73,5.736,0.1,569
1438,0.2,-9.75,5.748,0.1,570
1441,0.4,-9.77,5.76,0.2,571.5
1444,0,-9.79,5.772,0,572.5
1447,0.4,-9.81,5.784,0.2,573.5
1450,0.2,-9.83,5.796,0.1,575
1453,0.2,-9.85,5.808,0.1,576
1456,0.4,-9.88,5.82,0.2,578
1459,0.2,-9.9,5.832,0.1,579
1462,0.2,-9.92,5.844,0.1,580
1465,0.2,-9.94,5.856,0.1,581.5
1468,0.2,-9.96,5.868,0.1,582.5
1471,0.2,-9.98,5.88,0.1,583.5
1474,0.2,-10,5.892,0.1,585
1477,0.2,-10.02,5.904,0.1,586
1480,0.2,-10.04,5.916,0.1,587
1483,0.2,-10.07,5.928,0.1,589
1486,0.2,-10.09,5.94,0.1,590
1489,0.2,-10.11,5.952,0.1,591
1492,0,-10.13,5.964,0,592.5
1495,0.4,-10.15,5.976,0.2,593.5
1498,0,-10.17,5.988,0,594.5
1501,0.2,-10.19,6,0.1,596
1504,0,-10.21,6.012,0,597
1507,0.2,-10.23,6.024,0.1,598
1510,0.2,-10.26,6.036,0.1,600
1513,0.2,-10.28,6.048,0.1,601
1516,0.2,-10.3,6.06,0.1,602.5
1519,0.2,-10.32,6.072,0.1,603.5
1522,0.2,-10.34,6.084,0.1,604.5
1525,0.4,-10.36,6.096,0.2,606
1528,0.2,-10.37,6.108,0.1,606.5
1531,0.2,-10.39,6.12,0.1,607.5
1534,0,-10.41,6.132,0,609
1537,0.4,-10.44,6.144,0.2,610.5
1540,0.2,-10.46,6.156,0.1,611.5
1543,0.4,-10.48,6.168,0.2,613
1546,0,-10.5,6.18,0,614
1549,0.4,-10.52,6.192,0.2,615
1552,0.4,-10.54,6.204,0.2,616.5
1555,0.2,-10.56,6.216,0.1,617.5
1558,0.2,-10.58,6.228,0.1,618.5
1561,0.2,-10.6,6.24,0.1,620
1564,0.4,-10.63,6.252,0.2,621.5
1567,0.2,-10.65,6.264,0.1,623
1570,0.4,-10.67,6.276,0.2,624
1573,0.2,-10.69,6.288,0.1,625
1576,0.2,-10.71,6.3,0.1,626.5
1579,0.4,-10.73,6.312,0.2,627.5
1582,0.2,-10.75,6.324,0.1,628.5
1585,0,-10.77,6.336,0,630
1588,0.2,-10.79,6.348,0.1,631
1591,0,-10.82,6.36,0,632.5
1594,0,-10.84,6.372,0,634
1597,0.4,-10.86,6.384,0.2,635
1600,0,-10.88,6.396,0,636.5
1603,0,-10.9,6.408,0,637.5
1606,0,-10.92,6.42,0,638.5
1609,0.2,-10.94,6.432,0.1,640
1612,0.2,-10.96,6.444,0.1,641
1615,0.2,-10.98,6.456,0.1,642
1618,0.4,-11,6.468,0.2,643.5
1621,0,-11.02,6.48,0,644.5
1624,0.2,-11.04,6.492,0.1,645.5
1627,0,-11.07,6.504,0,647.5
1630,0.4,-11.09,6.516,0.2,648.5
1633,0.2,-11.11,6.528,0.1,649.5
1636,0,-11.13,6.54,0,651
1639,0,-11.15,6.552,0,652
1642,0.2,-11.17,6.564,0.1,653
1645,0,-11.19,6.576,0,654.5
1648,0,-11.21,6.588,0,655.5
1651,0.2,-11.23,6.6,0.1,656.5
1654,0.2,-11.26,6.612,0.1,658.5
1657,0.2,-11.27,6.624,0.1,659
1660,0.2,-11.3,6.636,0.1,661
1663,0.2,-11.32,6.648,0.1,662
1666,0.2,-11.34,6.66,0.1,663
1669,0.2,-11.36,6.672,0.1,664.5
1672,0.2,-11.38,6.684,0.1,665.5
1675,0.2,-11.4,6.696,0.1,666.5
1678,0.2,-11.42,6.708,0.1,668
1681,0.4,-11.44,6.72,0.2,669
1684,0.4,-11.46,6.732,0.2,670
1687,0.2,-11.48,6.744,0.1,671.5
1690,0.2,-11.5,6.756,0.1,672.5
1693,0.2,-11.53,6.768,0.1,674.5
1696,0.4,-11.55,6.78,0.2,675.5
1699,0.2,-11.57,6.792,0.1,676.5
1702,0,-11.59,6.804,0,678
1705,0,-11.61,6.816,0,679
1708,0.2,-11.63,6.828,0.1,680
1711,0.2,-11.65,6.84,0.1,681.5
1714,-0.2,-11.67,6.852,-0.1,682.5
1717,0.2,-11.69,6.864,0.1,683.5
1720,0.8,-11.72,6.876,0.35,685.5
1723,0.2,-11.73,6.888,0.1,686
1726,0,-11.76,6.9,0,687.5
1729,0.2,-11.78,6.912,0.1,689
1732,0.2,-11.8,6.924,0.1,690
1735,0.2,-11.82,6.936,0.1,691
1738,0.2,-11.84,6.948,0.1,692.5
1741,0.2,-11.86,6.96,0.1,693.5
1744,0.2,-11.88,6.972,0.1,694.5
1747,0.2,-11.9,6.984,0.1,696
1750,0.2,-11.92,6.996,0.1,697
1753,0.2,-11.94,7.008,0.1,698
1756,0.2,-11.96,7.02,0.1,699.5
1759,0.2,-11.98,7.032,0.1,700.5
1762,0.2,-12.01,7.044,0.1,702.5
1765,0.4,-12.03,7.056,0.2,703.5
1768,0.2,-12.05,7.068,0.1,704.5
1771,0.4,-12.07,7.08,0.2,706
1774,0.4,-12.09,7.092,0.2,707
1777,0.2,-12.11,7.104,0.1,708
1780,0,-12.13,7.116,0,709.5
1783,0.2,-12.15,7.128,0.1,710.5
1786,0.2,-12.17,7.14,0.1,711.5
1789,0.2,-12.19,7.152,0.1,713
1792,0.2,-12.21,7.164,0.1,714
1795,0.2,-12.24,7.176,0.1,716
1798,0,-12.26,7.188,0,717
1801,0,-12.28,7.2,0,718
1804,0.2,-12.3,7.212,0.1,719.5
1807,0.2,-12.32,7.224,0.1,720.5
1810,0,-12.34,7.236,0,721.5
1813,0.2,-12.36,7.248,0.1,723
1816,0,-12.39,7.26,0,724.5
1819,0.4,-12.41,7.272,0.2,725.5
1822,0.4,-12.43,7.284,0.2,727
1825,0.2,-12.45,7.296,0.1,728
1828,0.2,-12.48,7.308,0.1,730
1831,0.2,-12.5,7.32,0.1,731
1834,0.2,-12.52,7.332,0.1,732
1837,0.2,-12.54,7.344,0.1,733.5
1840,0.2,-12.56,7.356,0.1,734.5
1843,0.4,-12.58,7.368,0.2,735.5
1846,0.4,-12.6,7.38,0.2,737
1849,0,-12.62,7.392,0,738
1852,0.2,-12.64,7.404,0.1,739
1855,0.2,-12.66,7.416,0.1,740.5
1858,0,-12.68,7.428,0,741.5
1861,0.4,-12.71,7.44,0.2,743.5
1864,0.2,-12.73,7.452,0.1,744.5
1867,0.2,-12.75,7.464,0.1,745.5
1870,0.2,-12.77,7.476,0.1,747
1873,0.2,-12.79,7.488,0.1,748
1876,0.6,-12.81,7.5,0.3,749
1879,0.2,-12.83,7.512,0.1,750.5
1882,0,-12.85,7.524,0,751.5
1885,0.2,-12.87,7.536,0.1,752.5
1888,0.2,-12.89,7.548,0.1,754
1891,0.2,-12.92,7.56,0.1,755.5
1894,0.2,-12.94,7.572,0.1,756.5
1897,0,-12.96,7.584,0,758
1900,0.2,-12.98,7.596,0.1,759
1903,-0.2,-13,7.608,-0.1,760
1906,0.4,-13.02,7.62,0.2,761.5
1909,0.2,-13.04,7.632,0.1,762.5
1912,0.2,-13.06,7.644,0.1,763.5
1915,0.2,-13.08,7.656,0.1,765
1918,0.2,-13.1,7.668,0.1,766
1921,0.2,-13.12,7.68,0.1,767.5
1924,0.2,-13.15,7.692,0.1,769
1927,0,-13.16,7.704,0,769.5
1930,0.2,-13.19,7.716,0.1,771.5
1933,0.2,-13.21,7.728,0.1,772.5
1936,0.2,-13.23,7.74,0.1,773.5
1939,-0.2,-13.25,7.752,-0.1,775
1942,0.4,-13.27,7.764,0.2,776
1945,0,-13.29,7.776,0,777
1948,0.2,-13.31,7.788,0.1,778.5
1951,0,-13.33,7.8,0,779.5
1954,-0.2,-13.35,7.812,-0.1,780.5
1957,0.2,-13.38,7.824,0.1,782.5
1960,0.2,-13.4,7.836,0.1,783.5
1963,0.4,-13.42,7.848,0.2,785
1966,0.2,-13.44,7.86,0.1,786
1969,0.2,-13.46,7.872,0.1,787
1972,0.2,-13.48,7.884,0.1,788.5
1975,0.2,-13.5,7.896,0.1,789.5
1978,0.2,-13.52,7.908,0.1,790.5
1981,0,-13.54,7.92,0,792
1984,0.2,-13.57,7.932,0.1,793.5
1987,0.2,-13.59,7.944,0.1,794.5
1990,0.6,-13.61,7.956,0.3,796
1993,0.2,-13.63,7.968,0.1,797
1996,0,-13.65,7.98,0,798
1999,0,-13.67,7.992,0,799.5
2002,0.2,-13.69,8.004,0.1,800.5
2005,0.2,-13.71,8.016,0.1,802
2008,0.2,-13.73,8.028,0.1,803
2011,0.4,-13.76,8.04,0.2,804.5
2014,0.2,-13.77,8.052,0.1,805.5
2017,0.2,-13.8,8.064,0.1,807
2020,0.2,-13.82,8.076,0.1,808
2023,0.4,-13.84,8.088,0.2,809.5
2026,0.2,-13.86,8.1,0.1,810.5
2029,0.2,-13.88,8.112,0.1,811.5
2032,0.2,-13.9,8.124,0.1,813
2035,0.2,-13.92,8.136,0.1,814
2038,0.2,-13.95,8.148,0.1,816
2041,0.2,-13.97,8.16,0.1,817
2044,0,-13.99,8.172,0,818
2047,-0.2,-14.01,8.184,-0.1,819.5
2050,0.4,-14.03,8.196,0.2,820.5
2053,0,-14.05,8.208,0,821.5
2056,0.2,-14.07,8.22,0.1,823
2059,0.4,-14.09,8.232,0.2,824
2062,0.2,-14.11,8.244,0.1,825
2065,0.2,-14.14,8.256,0.1,827
2068,0.2,-14.16,8.268,0.1,828
2071,0.2,-14.18,8.28,0.1,829
2074,-0.2,-14.2,8.292,-0.1,830.5
2077,0.2,-14.22,8.304,0.1,831.5
2080,-0.2,-14.24,8.316,-0.1,832.5
2083,0.2,-14.26,8.328,0.1,834
2086,0,-14.28,8.34,0,835
2089,0,-14.3,8.352,0,836.5
2092,0.2,-14.33,8.364,0.1,838
2095,0,-14.35,8.376,0,839
2098,0.2,-14.37,8.388,0.1,840.5
2101,0.2,-14.39,8.4,0.1,841.5
2104,0.2,-14.41,8.412,0.1,842.5
2107,0.2,-14.43,8.424,0.1,844
2110,0.2,-14.45,8.436,0.1,845
2113,0.2,-14.47,8.448,0.1,846
2116,0.2,-14.49,8.46,0.1,847.5
2119,0.2,-14.52,8.472,0.1,849
2122,0.2,-14.54,8.484,0.1,850.5
2125,0.2,-14.56,8.496,0.1,851.5
2128,0.2,-14.58,8.508,0.1,852.5
2131,0.2,-14.6,8.52,0.1,854
2134,0.6,-14.62,8.532,0.3,855
2137,0.4,-14.64,8.544,0.2,856
2140,0.2,-14.66,8.556,0.1,857.5
2143,0.4,-14.68,8.568,0.2,858.5
2146,0.4,-14.71,8.58,0.2,860
2149,0,-14.73,8.592,0,861.5
2152,0,-14.75,8.604,0,862.5
2155,-0.2,-14.77,8.616,-0.1,863.5
2158,-0.2,-14.79,8.628,-0.1,865
2161,0.2,-14.81,8.64,0.1,866
2164,0.2,-14.83,8.652,0.1,867.5
2167,-0.2,-14.86,8.664,-0.1,869
2170,0.2,-14.87,8.676,0.1,869.5
2173,0.2,-14.9,8.688,0.1,871.5
2176,0.2,-14.92,8.7,0.1,872.5
2179,0.2,-14.94,8.712,0.1,873.5
2182,0.2,-14.96,8.724,0.1,875
2185,0.8,-14.98,8.736,0.35,876
2188,0.4,-15,8.748,0.2,877
2191,0.2,-15.02,8.76,0.1,878.5
2194,0,-15.05,8.772,0,880
2197,0.2,-15.06,8.784,0.1,880.5
2200,0.2,-15.09,8.796,0.1,882.5
2203,0,-15.11,8.808,0,883.5
2206,0.2,-15.13,8.82,0.1,885
2209,0.2,-15.15,8.832,0.1,886
2212,0.2,-15.17,8.844,0.1,887
2215,0.2,-15.19,8.856,0.1,888.5
2218,0.2,-15.21,8.868,0.1,889.5
2221,0,-15.24,8.88,0,891
2224,0.4,-15.25,8.892,0.2,892
2227,0,-15.28,8.904,0,893.5
2230,0.2,-15.3,8.916,0.1,894.5
2233,0.2,-15.32,8.928,0.1,896
2236,0.2,-15.34,8.94,0.1,897
2239,0.4,-15.36,8.952,0.2,898
2242,-0.2,-15.37,8.964,-0.1,899
2245,0.2,-15.39,8.976,0.1,900
2248,-0.2,-15.42,8.988,-0.1,902
2251,0.2,-15.43,9,0.1,902.5
2254,0.2,-15.46,9.012,0.1,904
2257,0,-15.48,9.024,0,905.5
2260,0.2,-15.5,9.036,0.1,906.5
2263,0.4,-15.52,9.048,0.2,907.5
2266,0.4,-15.54,9.06,0.2,909
2269,0.2,-15.56,9.072,0.1,910
2272,0,-15.58,9.084,0,911
2275,0.6,-15.61,9.096,0.3,913
2278,0.2,-15.62,9.108,0.1,913.5
2281,0.2,-15.65,9.12,0.1,915
2284,0.2,-15.67,9.132,0.1,916.5
2287,0.2,-15.69,9.144,0.1,917.5
2290,0.4,-15.71,9.156,0.2,918.5
2293,0.2,-15.73,9.168,0.1,920
2296,0.2,-15.75,9.18,0.1,921
2299,0.2,-15.77,9.192,0.1,922
2302,0.2,-15.79,9.204,0.1,923.5
2305,0.4,-15.81,9.216,0.2,924.5
2308,0.4,-15.84,9.228,0.2,926.5
2311,0.6,-15.86,9.24,0.3,927.5
2314,0.6,-15.88,9.252,0.3,928.5
2317,0,-15.9,9.264,0,930
2320,0.2,-15.92,9.276,0.1,931
2323,0.2,-15.94,9.288,0.1,932
2326,0,-15.96,9.3,0,933.5
2329,0.2,-15.98,9.312,0.1,934.5
2332,0.2,-16,9.324,0.1,935.5
2335,0,-16.02,9.336,0,937
2338,0.2,-16.05,9.348,0.1,938.5
2341,0.4,-16.07,9.36,0.2,940
2344,0,-16.09,9.372,0,941
2347,0.2,-16.11,9.384,0.1,942
2350,0.4,-16.13,9.396,0.2,943.5
2353,0.2,-16.15,9.408,0.1,944.5
2356,0.2,-16.17,9.42,0.1,945.5
2359,0.2,-16.19,9.432,0.1,947
2362,0.2,-16.21,9.444,0.1,948
2365,0,-16.23,9.456,0,949
2368,0.2,-16.25,9.468,0.1,950.5
2371,0.2,-16.28,9.48,0.1,952
2374,0.2,-16.29,9.492,0.1,952.5
2377,0,-16.32,9.504,0,954.5
2380,0.2,-16.34,9.516,0.1,955.5
2383,0.2,-16.36,9.528,0.1,956.5
2386,0,-16.38,9.54,0,958
2389,0.2,-16.4,9.552,0.1,959
2392,0.2,-16.42,9.564,0.1,960
2395,0.4,-16.44,9.576,0.2,961.5
2398,0.2,-16.46,9.588,0.1,962.5
2401,0,-16.48,9.6,0,963.5
2404,0.2,-16.51,9.612,0.1,965.5
2407,0.4,-16.52,9.624,0.2,966
2410,0.4,-16.55,9.636,0.2,968
2413,0.2,-16.57,9.648,0.1,969
2416,0.2,-16.59,9.66,0.1,970
2419,0.2,-16.61,9.672,0.1,971.5
2422,0.4,-16.63,9.684,0.2,972.5
2425,0.2,-16.65,9.696,0.1,973.5
2428,0.4,-16.67,9.708,0.2,975
2431,0.2,-16.69,9.72,0.1,976
2434,0.2,-16.71,9.732,0.1,977
2437,0.2,-16.73,9.744,0.1,978.5
2440,-0.2,-16.75,9.756,-0.1,979.5
2443,0.2,-16.78,9.768,0.1,981.5
2446,0.2,-16.8,9.78,0.1,982.5
2449,0.2,-16.82,9.792,0.1,983.5
2452,0,-16.84,9.804,0,985
2455,0.2,-16.86,9.816,0.1,986
2458,0.2,-16.88,9.828,0.1,987
2461,0.2,-16.9,9.84,0.1,988.5
2464,0.2,-16.92,9.852,0.1,989.5
2467,0,-16.94,9.864,0,990.5
2470,-0.2,-16.96,9.876,-0.1,992
2473,0.2,-16.98,9.888,0.1,993
2476,0.4,-17,9.9,0.2,994
2479,0,-17.03,9.912,0,996
2482,0.2,-17.05,9.924,0.1,997
2485,0,-17.07,9.936,0,998
2488,0.2,-17.09,9.948,0.1,999.5
2491,0.6,-17.11,9.96,0.3,1000.5
2494,0,-17.13,9.972,0,1002
2497,0.2,-17.15,9.984,0.1,1003
2500,0,-17.17,9.996,0,1004
2503,0.4,-17.19,10.008,0.2,1005.5
2506,0,-17.21,10.02,0,1006.5
2509,0.2,-17.23,10.032,0.1,1007.5
2512,0.2,-17.26,10.044,0.1,1009.5
2515,0.2,-17.27,10.056,0.1,1010
2518,0.2,-17.3,10.068,0.1,1011.5
2521,0.2,-17.32,10.08,0.1,1013
2524,0,-17.34,10.092,0,1014
2527,0.2,-17.36,10.104,0.1,1015
2530,0.2,-17.39,10.116,0.1,1017
2533,0.2,-17.41,10.128,0.1,1018
2536,0.4,-17.43,10.14,0.2,1019.5
2539,0.4,-17.45,10.152,0.2,1020.5
2542,0.2,-17.47,10.164,0.1,1021.5
2545,0,-17.5,10.176,0,1023.5
2548,0.2,-17.52,10.188,0.1,1024.5
2551,0.2,-17.54,10.2,0.1,1025.5
2554,0.2,-17.56,10.212,0.1,1027
2557,0.2,-17.58,10.224,0.1,1028
2560,0,-17.6,10.236,0,1029
2563,0.2,-17.62,10.248,0.1,1030.5
2566,0,-17.64,10.26,0,1031.5
2569,0.2,-17.66,10.272,0.1,1032.5
2572,0.2,-17.68,10.284,0.1,1034
2575,0.2,-17.7,10.296,0.1,1035
2578,0.2,-17.72,10.308,0.1,1036.5
2581,0.6,-17.75,10.32,0.3,1038
2584,0.2,-17.77,10.332,0.1,1039
2587,0.2,-17.79,10.344,0.1,1040.5
2590,0.4,-17.81,10.356,0.2,1041.5
2593,0.2,-17.83,10.368,0.1,1042.5
2596,0.2,-17.85,10.38,0.1,1044
2599,0.2,-17.87,10.392,0.1,1045
2602,0.2,-17.89,10.404,0.1,1046
2605,0.2,-17.91,10.416,0.1,1047.5
2608,0,-17.93,10.428,0,1048.5
2611,0.2,-17.95,10.44,0.1,1049.5
2614,0.2,-17.98,10.452,0.1,1051.5
2617,0.2,-17.99,10.464,0.1,1052
2620,0,-18.02,10.476,0,1054
2623,0,-18.04,10.488,0,1055
2626,0.2,-18.06,10.5,0.1,1056
2629,0.2,-18.08,10.512,0.1,1057.5
2632,0.2,-18.1,10.524,0.1,1058.5
2635,0.2,-18.12,10.536,0.1,1059.5
2638,0.2,-18.14,10.548,0.1,1061
2641,0.2,-18.16,10.56,0.1,1062
2644,0.2,-18.18,10.572,0.1,1063
2647,0.4,-18.21,10.584,0.2,1065
2650,0.2,-18.22,10.596,0.1,1065.5
2653,0.2,-18.25,10.608,0.1,1067.5
2656,0.2,-18.27,10.62,0.1,1068.5
2659,0.4,-18.29,10.632,0.2,1069.5
2662,0,-18.31,10.644,0,1071
2665,0.2,-18.33,10.656,0.1,1072
2668,0.4,-18.35,10.668,0.2,1073
2671,0.2,-18.37,10.68,0.1,1074.5
2674,0.6,-18.39,10.692,0.3,1075.5
2677,0.2,-18.41,10.704,0.1,1076.5
2680,0.4,-18.44,10.716,0.2,1078.5
2683,0.4,-18.46,10.728,0.2,1079.5
2686,0.4,-18.48,10.74,0.2,1080.5
2689,0.2,-18.5,10.752,0.1,1082
2692,0.2,-18.52,10.764,0.1,1083
2695,0,-18.54,10.776,0,1084
2698,0.2,-18.56,10.788,0.1,1085.5
2701,0.2,-18.58,10.8,0.1,1086.5
2704,0,-18.6,10.812,0,1087.5
2707,0.2,-18.63,10.824,0.1,1089.5
2710,0,-18.65,10.836,0,1090.5
2713,0.2,-18.67,10.848,0.1,1092
2716,0.2,-18.69,10.86,0.1,1093
2719,0.2,-18.71,10.872,0.1,1094
2722,0,-18.73,10.884,0,1095.5
2725,0.2,-18.75,10.896,0.1,1096.5
2728,0.2,-18.77,10.908,0.1,1097.5
2731,0.4,-18.79,10.92,0.2,1099
2734,0.2,-18.81,10.932,0.1,1100
2737,0.2,-18.83,10.944,0.1,1101
2740,0.4,-18.86,10.956,0.2,1103
2743,0.2,-18.88,10.968,0.1,1104
2746,0,-18.9,10.98,0,1105.5
2749,0.2,-18.92,10.992,0.1,1106.5
2752,0.2,-18.94,11.004,0.1,1107.5
2755,-0.2,-18.96,11.016,-0.1,1109
2758,0.2,-18.98,11.028,0.1,1110
2761,0.6,-19,11.04,0.3,1111
2764,0.2,-19.02,11.052,0.1,1112.5
2767,0.4,-19.05,11.064,0.2,1114
2770,0,-19.07,11.076,0,1115
2773,0.2,-19.09,11.088,0.1,1116.5
2776,0.6,-19.11,11.1,0.3,1117.5
2779,0.2,-19.13,11.112,0.1,1118.5
2782,0.2,-19.15,11.124,0.1,1120
2785,0.2,-19.17,11.136,0.1,1121
2788,0,-19.19,11.148,0,1122
2791,0.2,-19.22,11.16,0.1,1124
2794,0.2,-19.24,11.172,0.1,1125
2797,0.2,-19.26,11.184,0.1,1126.5
2800,0.2,-19.28,11.196,0.1,1127.5
2803,0,-19.3,11.208,0,1128.5
2806,0.2,-19.32,11.22,0.1,1130
2809,0.2,-19.34,11.232,0.1,1131
2812,0.2,-19.36,11.244,0.1,1132
2815,0.2,-19.38,11.256,0.1,1133.5
2818,0.2,-19.4,11.268,0.1,1134.5
2821,0.2,-19.42,11.28,0.1,1135.5
2824,0.2,-19.44,11.292,0.1,1137
2827,-0.2,-19.46,11.304,-0.1,1138
2830,0,-19.48,11.316,0,1139
2833,0.2,-19.5,11.328,0.1,1140.5
2836,0.2,-19.52,11.34,0.1,1141.5
2839,0.2,-19.54,11.352,0.1,1142.5
2842,0.2,-19.57,11.364,0.1,1144.5
2845,0.2,-19.59,11.376,0.1,1145.5
2848,-0.2,-19.61,11.388,-0.1,1147
2851,0.2,-19.63,11.4,0.1,1148
2854,0.2,-19.65,11.412,0.1,1149
2857,0,-19.67,11.424,0,1150.5
2860,0.2,-19.69,11.436,0.1,1151.5
2863,0.2,-19.71,11.448,0.1,1152.5
2866,0.2,-19.73,11.46,0.1,1154
2869,0.2,-19.76,11.472,0.1,1155.5
2872,0,-19.78,11.484,0,1156.5
2875,0.4,-19.8,11.496,0.2,1158
2878,0,-19.82,11.508,0,1159
2881,0.2,-19.84,11.52,0.1,1160
2884,0.2,-19.86,11.532,0.1,1161.5
2887,0.2,-19.88,11.544,0.1,1162.5
2890,0.2,-19.9,11.556,0.1,1163.5
2893,0.2,-19.92,11.568,0.1,1165
2896,0.2,-19.95,11.58,0.1,1166.5
2899,0.2,-19.97,11.592,0.1,1168
2902,0.2,-19.99,11.604,0.1,1169
2905,0.2,-20.01,11.616,0.1,1170
2908,0.2,-20.03,11.628,0.1,1171.5
2911,0,-20.05,11.64,0,1172.5
2914,0.2,-20.07,11.652,0.1,1173.5
2917,0.2,-20.09,11.664,0.1,1175
2920,0.2,-20.11,11.676,0.1,1176
2923,0.2,-20.14,11.688,0.1,1178
2926,0.2,-20.16,11.7,0.1,1179
2929,0.4,-20.18,11.712,0.2,1180
2932,0.2,-20.2,11.724,0.1,1181.5
2935,0.2,-20.22,11.736,0.1,1182.5
2938,0.2,-20.24,11.748,0.1,1183.5
2941,0.2,-20.26,11.76,0.1,1185
2944,0.4,-20.28,11.772,0.2,1186
2947,0,-20.3,11.784,0,1187
2950,0.2,-20.33,11.796,0.1,1189
2953,0.4,-20.35,11.808,0.2,1190
2956,0.2,-20.37,11.82,0.1,1191
2959,-0.2,-20.39,11.832,-0.1,1192.5
2962,-0.2,-20.41,11.844,-0.1,1193.5
2965,0.2,-20.43,11.856,0.1,1194.5
2968,0.4,-20.45,11.868,0.2,1196
2971,0.4,-20.47,11.88,0.2,1197
2974,0,-20.49,11.892,0,1198
2977,0.2,-20.52,11.904,0.1,1200
2980,0.4,-20.54,11.916,0.2,1201
2983,0.2,-20.56,11.928,0.1,1202.5
2986,0,-20.58,11.94,0,1203.5
2989,0.2,-20.6,11.952,0.1,1204.5
2992,0.2,-20.62,11.964,0.1,1206
2995,0.2,-20.64,11.976,0.1,1207
2998,0.4,-20.66,11.988,0.2,1208
3001,0.2,-20.68,12,0.1,1209.5
3004,0.4,-20.7,12.012,0.2,1210.5
3007,0.2,-20.73,12.024,0.1,1212.5
3010,0.2,-20.75,12.036,0.1,1213.5
3013,0.2,-20.77,12.048,0.1,1214.5
3016,0.2,-20.79,12.06,0.1,1216
3019,0.2,-20.81,12.072,0.1,1217
3022,0.2,-20.83,12.084,0.1,1218
3025,0.6,-20.85,12.096,0.3,1219.5
3028,0,-20.87,12.108,0,1220.5
3031,0.2,-20.89,12.12,0.1,1221.5
3034,0,-20.91,12.132,0,1223
3037,0.2,-20.94,12.144,0.1,1224.5
3040,-0.4,-20.96,12.156,-0.2,1225.5
3043,0.2,-20.98,12.168,0.1,1227
3046,0.2,-21,12.18,0.1,1228
3049,0.2,-21.02,12.192,0.1,1229
3052,0.2,-21.04,12.204,0.1,1230.5
3055,0.2,-21.06,12.216,0.1,1231.5
3058,0.2,-21.08,12.228,0.1,1232.5
3061,0.2,-21.1,12.24,0.1,1234
3064,0,-21.12,12.252,0,1235
3067,0.4,-21.15,12.264,0.2,1237
3070,0.2,-21.17,12.276,0.1,1238
3073,0.2,-21.19,12.288,0.1,1239
3076,0.4,-21.21,12.3,0.2,1240.5
3079,0.6,-21.23,12.312,0.3,1241.5
3082,0.6,-21.25,12.324,0.3,1242.5
3085,1,-21.27,12.336,0.45,1244
3088,1.2,-21.29,12.348,0.55,1245
3091,1.4,-21.31,12.36,0.65,1246
3094,1.4,-21.33,12.372,0.65,1247.5
3097,1.6,-21.35,12.384,0.75,1248.5
3100,2.2,-21.38,12.396,1.05,1250.5
3103,2.4,-21.4,12.408,1.1,1251.5
3106,3.6,-21.42,12.42,1.7,1252.5
3109,4.2,-21.44,12.432,1.95,1254
3112,4.4,-21.46,12.444,2.05,1255
3115,5.2,-21.48,12.456,2.45,1256
3118,5,-21.5,12.468,2.35,1257.5
3121,4.6,-21.52,12.48,2.15,1258.5
3124,5,-21.54,12.492,2.35,1259.5
3127,5.8,-21.56,12.504,2.7,1261
3130,7.8,-21.58,12.516,3.65,1262
3133,9,-21.6,12.528,4.2,1263
3136,10,-21.62,12.54,4.7,1264.5
3139,10.6,-21.64,12.552,4.95,1265.5
3142,11.4,-21.66,12.564,5.35,1266.5
3145,11.4,-21.68,12.576,5.35,1268
3148,10.2,-21.68,12.588,4.75,1268
3151,9.8,-21.68,12.6,4.6,1268
3154,9.6,-21.68,12.612,4.5,1268
3157,9.4,-21.68,12.624,4.4,1268
3160,9.4,-21.68,12.636,4.4,1268
3163,9.2,-21.68,12.648,4.3,1268
3166,11.8,-21.67,12.66,4.2,1268