File: results/youngs-modulus/2025-04-21/inconclusive-data/pf13lt03.csv
Axial Compression Test-Jun-21-2024-09-38-58-AM.log,,,,,
,,,,,
System Information:,,,,,
IntelliMESUR Version: 2.2.1,,,,,
Test Frame Model: F505,,,,,
Test Frame Serial Number: 4418651,,,,,
Test Frame Capacity: 500 lbF / 2.2 kN,,,,,
Test Frame Firmware Version: 1.00.14,,,,,
Force Sensor Model: FS05-100,,,,,
Force Sensor Capacity: 500 N,,,,,
Force Sensor Resolution: 0.2 N,,,,,
Force Sensor Serial Number: 4425350,,,,,
"Calibration Date: Apr 29, 2024",,,,,
"Calibration Due Date: Apr 29, 2025",,,,,
,,,,,
Reading,Load [N],Distance [mm],Time [s],Stress [MPa],Strain [%]
1,0,-0.01,0,0,0.5
4,0,-0.01,0.012,0,0.5
7,0,-0.01,0.024,0,0.5
10,-0.2,-0.01,0.036,-0.1,0.5
13,0,-0.01,0.048,0,0.5
16,0,-0.01,0.06,0,0.5
19,0.2,-0.01,0.072,0.1,0.5
22,0,-0.01,0.084,0,0.5
25,0,-0.01,0.096,0,0.5
28,0,-0.01,0.108,0,0.5
31,0,-0.01,0.12,0,0.5
34,0,-0.01,0.132,0,0.5
37,-0.2,-0.01,0.144,-0.1,0.5
40,0.2,-0.01,0.156,0.1,0.5
43,0,-0.01,0.168,0,0.5
46,-0.2,-0.01,0.18,-0.1,0.5
49,0,-0.02,0.192,0,1.5
52,0.2,-0.04,0.204,0.1,2.5
55,0.2,-0.06,0.216,0.1,4
58,0.2,-0.08,0.228,0.1,5
61,-0.2,-0.1,0.24,-0.1,6.5
64,0,-0.12,0.252,0,7.5
67,0.2,-0.15,0.264,0.1,9.5
70,0,-0.17,0.276,0,11
73,0,-0.19,0.288,0,12
76,0,-0.21,0.3,0,13.5
79,0,-0.23,0.312,0,14.5
82,0.2,-0.25,0.324,0.1,16
85,0.2,-0.27,0.336,0.1,17
88,0,-0.29,0.348,0,18.5
91,0,-0.31,0.36,0,19.5
94,-0.2,-0.34,0.372,-0.1,21.5
97,0,-0.36,0.384,0,23
100,0.2,-0.38,0.396,0.1,24
103,-0.2,-0.4,0.408,-0.1,25.5
106,-0.4,-0.41,0.42,-0.2,26
109,0.2,-0.43,0.432,0.1,27
112,-0.2,-0.45,0.444,-0.1,28.5
115,0.2,-0.47,0.456,0.1,29.5
118,0,-0.49,0.468,0,31
121,0.6,-0.52,0.48,0.3,33
124,0,-0.54,0.492,0,34
127,-0.2,-0.56,0.504,-0.1,35.5
130,0,-0.58,0.516,0,36.5
133,0,-0.6,0.528,0,38
136,0.2,-0.62,0.54,0.1,39
139,-0.2,-0.64,0.552,-0.1,40.5
142,0.2,-0.66,0.564,0.1,42
145,0,-0.68,0.576,0,43
148,0,-0.7,0.588,0,44.5
151,0,-0.73,0.6,0,46
154,0,-0.75,0.612,0,47.5
157,0,-0.77,0.624,0,48.5
160,-0.2,-0.79,0.636,-0.1,50
163,0,-0.81,0.648,0,51.5
166,0,-0.83,0.66,0,52.5
169,0,-0.85,0.672,0,54
172,0,-0.87,0.684,0,55
175,0.2,-0.89,0.696,0.1,56.5
178,0,-0.91,0.708,0,57.5
181,0,-0.94,0.72,0,59.5
184,0,-0.96,0.732,0,61
187,0,-0.98,0.744,0,62
190,0.2,-1,0.756,0.1,63.5
193,0,-1.02,0.768,0,64.5
196,0.4,-1.04,0.78,0.2,66
199,0,-1.06,0.792,0,67
202,0,-1.08,0.804,0,68.5
205,-0.2,-1.1,0.816,-0.1,69.5
208,0,-1.12,0.828,0,71
211,-0.2,-1.15,0.84,-0.1,73
214,0,-1.16,0.852,0,73.5
217,0,-1.19,0.864,0,75.5
220,0,-1.21,0.876,0,76.5
223,0,-1.23,0.888,0,78
226,0,-1.25,0.9,0,79
229,-0.2,-1.27,0.912,-0.1,80.5
232,-0.2,-1.29,0.924,-0.1,81.5
235,0,-1.31,0.936,0,83
238,0,-1.33,0.948,0,84
241,0,-1.35,0.96,0,85.5
244,-0.2,-1.38,0.972,-0.1,87.5
247,0,-1.41,0.984,0,89
250,0.2,-1.43,0.996,0.1,90.5
253,0,-1.45,1.008,0,92
256,0,-1.47,1.02,0,93
259,0,-1.49,1.032,0,94.5
262,0,-1.51,1.044,0,95.5
265,-0.4,-1.53,1.056,-0.2,97
268,0,-1.55,1.068,0,98
271,-0.2,-1.57,1.08,-0.1,99.5
274,0,-1.59,1.092,0,100.5
277,-0.2,-1.62,1.104,-0.1,102.5
280,0,-1.64,1.116,0,104
283,0,-1.66,1.128,0,105
286,-0.2,-1.68,1.14,-0.1,106.5
289,0.2,-1.7,1.152,0.1,107.5
292,-0.2,-1.72,1.164,-0.1,109
295,0,-1.74,1.176,0,110
298,0,-1.76,1.188,0,111.5
301,0,-1.78,1.2,0,112.5
304,0,-1.8,1.212,0,114
307,-0.2,-1.82,1.224,-0.1,115
310,0,-1.85,1.236,0,117
313,0,-1.87,1.248,0,118.5
316,0,-1.89,1.26,0,119.5
319,0,-1.91,1.272,0,121
322,0,-1.93,1.284,0,122
325,0,-1.95,1.296,0,123.5
328,0,-1.97,1.308,0,124.5
331,-0.2,-1.99,1.32,-0.1,126
334,0,-2.01,1.332,0,127
337,0,-2.03,1.344,0,128.5
340,-0.4,-2.05,1.356,-0.2,129.5
343,0,-2.07,1.368,0,131
346,-0.2,-2.1,1.38,-0.1,133
349,0,-2.12,1.392,0,134
352,0,-2.14,1.404,0,135.5
355,0,-2.16,1.416,0,136.5
358,-0.2,-2.18,1.428,-0.1,138
361,-0.2,-2.2,1.44,-0.1,139
364,0,-2.22,1.452,0,140.5
367,0,-2.24,1.464,0,142
370,0.2,-2.26,1.476,0.1,143
373,0,-2.28,1.488,0,144.5
376,0,-2.3,1.5,0,145.5
379,-0.4,-2.33,1.512,-0.2,147.5
382,0,-2.35,1.524,0,148.5
385,0.2,-2.37,1.536,0.1,150
388,-0.2,-2.39,1.548,-0.1,151.5
391,0,-2.4,1.56,0,152
394,0,-2.42,1.572,0,153
397,0.2,-2.44,1.584,0.1,154.5
400,0,-2.46,1.596,0,155.5
403,0,-2.48,1.608,0,157
406,0,-2.5,1.62,0,158
409,0,-2.52,1.632,0,159.5
412,0,-2.55,1.644,0,161.5
415,-0.2,-2.57,1.656,-0.1,162.5
418,0.2,-2.59,1.668,0.1,164
421,-0.2,-2.61,1.68,-0.1,165
424,0,-2.63,1.692,0,166.5
427,-0.2,-2.65,1.704,-0.1,167.5
430,-0.2,-2.67,1.716,-0.1,169
433,-0.2,-2.69,1.728,-0.1,170.5
436,0,-2.71,1.74,0,171.5
439,0.2,-2.73,1.752,0.1,173
442,0,-2.75,1.764,0,174
445,0.2,-2.77,1.776,0.1,175.5
448,0,-2.8,1.788,0,177
451,-0.2,-2.82,1.8,-0.1,178.5
454,0,-2.84,1.812,0,179.5
457,0,-2.86,1.824,0,181
460,0,-2.88,1.836,0,182.5
463,0.2,-2.9,1.848,0.1,183.5
466,0.2,-2.92,1.86,0.1,185
469,0,-2.94,1.872,0,186
472,0,-2.96,1.884,0,187.5
475,-0.2,-2.98,1.896,-0.1,188.5
478,-0.4,-3,1.908,-0.2,190
481,0,-3.03,1.92,0,192
484,0.2,-3.05,1.932,0.1,193
487,0,-3.07,1.944,0,194.5
490,0,-3.09,1.956,0,195.5
493,0.2,-3.11,1.968,0.1,197
496,0,-3.13,1.98,0,198
499,0,-3.15,1.992,0,199.5
502,-0.2,-3.17,2.004,-0.1,200.5
505,0,-3.19,2.016,0,202
508,-0.2,-3.22,2.028,-0.1,204
511,0.2,-3.23,2.04,0.1,204.5
514,0,-3.26,2.052,0,206.5
517,0,-3.28,2.064,0,207.5
520,0,-3.3,2.076,0,209
523,0,-3.32,2.088,0,210
526,0,-3.34,2.1,0,211.5
529,0,-3.36,2.112,0,212.5
532,0,-3.38,2.124,0,214
535,0,-3.41,2.136,0,216
538,0,-3.43,2.148,0,217
541,0,-3.46,2.16,0,219
544,0,-3.48,2.172,0,220.5
547,0,-3.5,2.184,0,221.5
550,0,-3.52,2.196,0,223
553,0,-3.54,2.208,0,224
556,0,-3.56,2.22,0,225.5
559,0.2,-3.58,2.232,0.1,226.5
562,0,-3.6,2.244,0,228
565,0,-3.62,2.256,0,229
568,0,-3.65,2.268,0,231
571,0,-3.66,2.28,0,231.5
574,0,-3.69,2.292,0,233.5
577,0,-3.71,2.304,0,235
580,0.2,-3.73,2.316,0.1,236
583,0.4,-3.75,2.328,0.2,237.5
586,0,-3.77,2.34,0,238.5
589,0,-3.79,2.352,0,240
592,-0.2,-3.81,2.364,-0.1,241
595,0,-3.83,2.376,0,242.5
598,-0.2,-3.85,2.388,-0.1,243.5
601,0,-3.88,2.4,0,245.5
604,-0.2,-3.9,2.412,-0.1,247
607,0,-3.92,2.424,0,248
610,0,-3.94,2.436,0,249.5
613,0.2,-3.96,2.448,0.1,250.5
616,0,-3.98,2.46,0,252
619,0,-4,2.472,0,253
622,0,-4.02,2.484,0,254.5
625,0,-4.04,2.496,0,255.5
628,0,-4.07,2.508,0,257.5
631,0,-4.09,2.52,0,259
634,0,-4.11,2.532,0,260
637,0,-4.13,2.544,0,261.5
640,0,-4.15,2.556,0,262.5
643,0,-4.17,2.568,0,264
646,0,-4.19,2.58,0,265
649,0,-4.22,2.592,0,267
652,0,-4.24,2.604,0,268.5
655,0,-4.26,2.616,0,269.5
658,-0.2,-4.28,2.628,-0.1,271
661,-0.2,-4.3,2.64,-0.1,272
664,0.2,-4.32,2.652,0.1,273.5
667,0,-4.34,2.664,0,274.5
670,-0.4,-4.36,2.676,-0.2,276
673,0,-4.38,2.688,0,277
676,0,-4.41,2.7,0,279
679,0,-4.43,2.712,0,280.5
682,0.2,-4.45,2.724,0.1,281.5
685,0,-4.47,2.736,0,283
688,-0.2,-4.49,2.748,-0.1,284
691,0.2,-4.51,2.76,0.1,285.5
694,0.2,-4.53,2.772,0.1,286.5
697,0,-4.55,2.784,0,288
700,-0.2,-4.57,2.796,-0.1,289
703,0.2,-4.6,2.808,0.1,291
706,-0.2,-4.62,2.82,-0.1,292.5
709,0.2,-4.64,2.832,0.1,293.5
712,-0.2,-4.66,2.844,-0.1,295
715,0,-4.68,2.856,0,296
718,0,-4.7,2.868,0,297.5
721,0,-4.72,2.88,0,298.5
724,-0.2,-4.74,2.892,-0.1,300
727,0,-4.76,2.904,0,301.5
730,0,-4.79,2.916,0,303
733,0,-4.81,2.928,0,304.5
736,0.4,-4.83,2.94,0.2,305.5
739,0,-4.85,2.952,0,307
742,0,-4.87,2.964,0,308
745,-0.2,-4.89,2.976,-0.1,309.5
748,0,-4.91,2.988,0,311
751,0.2,-4.93,3,0.1,312
754,0,-4.95,3.012,0,313.5
757,0,-4.98,3.024,0,315
760,0,-5,3.036,0,316.5
763,-0.2,-5.02,3.048,-0.1,317.5
766,-0.2,-5.04,3.06,-0.1,319
769,0,-5.06,3.072,0,320.5
772,-0.2,-5.08,3.084,-0.1,321.5
775,0,-5.1,3.096,0,323
778,0,-5.12,3.108,0,324
781,0.2,-5.14,3.12,0.1,325.5
784,0,-5.17,3.132,0,327
787,0,-5.19,3.144,0,328.5
790,0,-5.21,3.156,0,329.5
793,0,-5.23,3.168,0,331
796,0,-5.25,3.18,0,332.5
799,-0.2,-5.27,3.192,-0.1,333.5
802,0,-5.29,3.204,0,335
805,0,-5.31,3.216,0,336
808,0.2,-5.33,3.228,0.1,337.5
811,0,-5.36,3.24,0,339
814,0,-5.38,3.252,0,340.5
817,0,-5.4,3.264,0,342
820,-0.2,-5.42,3.276,-0.1,343
823,0,-5.44,3.288,0,344.5
826,-0.2,-5.46,3.3,-0.1,345.5
829,0,-5.48,3.312,0,347
832,0,-5.5,3.324,0,348
835,0,-5.52,3.336,0,349.5
838,0.2,-5.55,3.348,0.1,351.5
841,0,-5.57,3.36,0,352.5
844,0.2,-5.59,3.372,0.1,354
847,-0.4,-5.61,3.384,-0.2,355
850,0,-5.63,3.396,0,356.5
853,0,-5.65,3.408,0,357.5
856,0,-5.67,3.42,0,359
859,-0.2,-5.69,3.432,-0.1,360
862,0.2,-5.71,3.444,0.1,361.5
865,0,-5.74,3.456,0,363.5
868,0,-5.76,3.468,0,364.5
871,0,-5.78,3.48,0,366
874,-0.4,-5.8,3.492,-0.2,367
877,-0.2,-5.82,3.504,-0.1,368.5
880,0,-5.84,3.516,0,369.5
883,0,-5.86,3.528,0,371
886,0,-5.88,3.54,0,372
889,0,-5.9,3.552,0,373.5
892,0.2,-5.92,3.564,0.1,374.5
895,0.2,-5.94,3.576,0.1,376
898,0.2,-5.97,3.588,0.1,378
901,-0.2,-5.99,3.6,-0.1,379
904,0,-6.01,3.612,0,380.5
907,0,-6.03,3.624,0,381.5
910,0,-6.05,3.636,0,383
913,0.2,-6.07,3.648,0.1,384
916,0.2,-6.09,3.66,0.1,385.5
919,0,-6.11,3.672,0,386.5
922,0,-6.13,3.684,0,388
925,0.2,-6.15,3.696,0.1,389
928,0,-6.17,3.708,0,390.5
931,-0.2,-6.19,3.72,-0.1,392
934,0,-6.22,3.732,0,393.5
937,0,-6.24,3.744,0,395
940,0.2,-6.26,3.756,0.1,396
943,0,-6.28,3.768,0,397.5
946,0,-6.3,3.78,0,398.5
949,0,-6.32,3.792,0,400
952,0.2,-6.34,3.804,0.1,401.5
955,-0.2,-6.36,3.816,-0.1,402.5
958,0,-6.38,3.828,0,404
961,-0.2,-6.39,3.84,-0.1,404.5
964,0.2,-6.41,3.852,0.1,405.5
967,0,-6.44,3.864,0,407.5
970,-0.2,-6.46,3.876,-0.1,409
973,0,-6.48,3.888,0,410
976,0,-6.5,3.9,0,411.5
979,0,-6.52,3.912,0,412.5
982,-0.2,-6.54,3.924,-0.1,414
985,0,-6.56,3.936,0,415
988,0.2,-6.58,3.948,0.1,416.5
991,0,-6.6,3.96,0,417.5
994,0.2,-6.62,3.972,0.1,419
997,-0.2,-6.64,3.984,-0.1,420.5
1000,0.2,-6.67,3.996,0.1,422
1003,-0.2,-6.69,4.008,-0.1,423.5
1006,-0.2,-6.71,4.02,-0.1,424.5
1009,0,-6.73,4.032,0,426
1012,0.2,-6.75,4.044,0.1,427
1015,0,-6.77,4.056,0,428.5
1018,0.2,-6.79,4.068,0.1,429.5
1021,0,-6.81,4.08,0,431
1024,-0.2,-6.83,4.092,-0.1,432.5
1027,0.4,-6.85,4.104,0.2,433.5
1030,-0.2,-6.87,4.116,-0.1,435
1033,0,-6.89,4.128,0,436
1036,0,-6.92,4.14,0,438
1039,0,-6.94,4.152,0,439
1042,0.2,-6.96,4.164,0.1,440.5
1045,-0.2,-6.98,4.176,-0.1,442
1048,0,-7,4.188,0,443
1051,0,-7.02,4.2,0,444.5
1054,0,-7.04,4.212,0,445.5
1057,0,-7.06,4.224,0,447
1060,0.2,-7.08,4.236,0.1,448
1063,0.2,-7.1,4.248,0.1,449.5
1066,-0.2,-7.12,4.26,-0.1,450.5
1069,-0.2,-7.15,4.272,-0.1,452.5
1072,0,-7.16,4.284,0,453
1075,0,-7.19,4.296,0,455
1078,0,-7.21,4.308,0,456.5
1081,0,-7.23,4.32,0,457.5
1084,0,-7.25,4.332,0,459
1087,-0.6,-7.27,4.344,-0.3,460
1090,0.2,-7.29,4.356,0.1,461.5
1093,0.2,-7.31,4.368,0.1,462.5
1096,-0.2,-7.33,4.38,-0.1,464
1099,0,-7.35,4.392,0,465
1102,0,-7.38,4.404,0,467
1105,0,-7.4,4.416,0,468.5
1108,0.2,-7.43,4.428,0.1,470.5
1111,-0.2,-7.45,4.44,-0.1,471.5
1114,0,-7.47,4.452,0,473
1117,0,-7.49,4.464,0,474
1120,-0.2,-7.51,4.476,-0.1,475.5
1123,0,-7.53,4.488,0,476.5
1126,0,-7.55,4.5,0,478
1129,0.4,-7.57,4.512,0.2,479
1132,-0.2,-7.59,4.524,-0.1,480.5
1135,0,-7.61,4.536,0,481.5
1138,0,-7.64,4.548,0,483.5
1141,0.4,-7.66,4.56,0.2,485
1144,0,-7.68,4.572,0,486
1147,0,-7.7,4.584,0,487.5
1150,0,-7.72,4.596,0,488.5
1153,0,-7.74,4.608,0,490
1156,0,-7.76,4.62,0,491
1159,0,-7.78,4.632,0,492.5
1162,0,-7.8,4.644,0,493.5
1165,0,-7.82,4.656,0,495
1168,0,-7.84,4.668,0,496
1171,0.2,-7.87,4.68,0.1,498
1174,0,-7.88,4.692,0,498.5
1177,0,-7.91,4.704,0,500.5
1180,0.2,-7.93,4.716,0.1,502
1183,0,-7.95,4.728,0,503
1186,0.2,-7.97,4.74,0.1,504.5
1189,-0.2,-7.99,4.752,-0.1,505.5
1192,-0.2,-8.01,4.764,-0.1,507
1195,0.2,-8.03,4.776,0.1,508
1198,-0.2,-8.05,4.788,-0.1,509.5
1201,0,-8.07,4.8,0,511
1204,0,-8.09,4.812,0,512
1207,0,-8.11,4.824,0,513.5
1210,0,-8.14,4.836,0,515
1213,0.2,-8.16,4.848,0.1,516.5
1216,0,-8.18,4.86,0,517.5
1219,0,-8.2,4.872,0,519
1222,-0.2,-8.22,4.884,-0.1,520.5
1225,0,-8.24,4.896,0,521.5
1228,0,-8.26,4.908,0,523
1231,0,-8.28,4.92,0,524
1234,0,-8.3,4.932,0,525.5
1237,0,-8.33,4.944,0,527
1240,0,-8.35,4.956,0,528.5
1243,0.2,-8.37,4.968,0.1,529.5
1246,-0.2,-8.39,4.98,-0.1,531
1249,0,-8.41,4.992,0,532.5
1252,0,-8.43,5.004,0,533.5
1255,0.2,-8.45,5.016,0.1,535
1258,0.2,-8.47,5.028,0.1,536
1261,0.2,-8.49,5.04,0.1,537.5
1264,0,-8.51,5.052,0,538.5
1267,-0.2,-8.53,5.064,-0.1,540
1270,0,-8.56,5.076,0,542
1273,-0.2,-8.58,5.088,-0.1,543
1276,0,-8.6,5.1,0,544.5
1279,0,-8.62,5.112,0,545.5
1282,0,-8.64,5.124,0,547
1285,-0.2,-8.66,5.136,-0.1,548
1288,-0.2,-8.68,5.148,-0.1,549.5
1291,0,-8.7,5.16,0,550.5
1294,0,-8.72,5.172,0,552
1297,0,-8.74,5.184,0,553
1300,-0.4,-8.77,5.196,-0.2,555
1303,0,-8.79,5.208,0,556.5
1306,0,-8.81,5.22,0,557.5
1309,0,-8.83,5.232,0,559
1312,0.2,-8.85,5.244,0.1,560
1315,0.2,-8.87,5.256,0.1,561.5
1318,0,-8.89,5.268,0,562.5
1321,0,-8.91,5.28,0,564
1324,0.2,-8.93,5.292,0.1,565
1327,0,-8.96,5.304,0,567
1330,-0.2,-8.98,5.316,-0.1,568.5
1333,0.2,-9,5.328,0.1,569.5
1336,-0.2,-9.02,5.34,-0.1,571
1339,0.2,-9.04,5.352,0.1,572
1342,-0.2,-9.06,5.364,-0.1,573.5
1345,0,-9.08,5.376,0,574.5
1348,0,-9.1,5.388,0,576
1351,0,-9.13,5.4,0,578
1354,0,-9.15,5.412,0,579
1357,0,-9.17,5.424,0,580.5
1360,0,-9.19,5.436,0,581.5
1363,0,-9.21,5.448,0,583
1366,0,-9.23,5.46,0,584
1369,0,-9.25,5.472,0,585.5
1372,0,-9.27,5.484,0,586.5
1375,-0.4,-9.29,5.496,-0.2,588
1378,0.4,-9.32,5.508,0.2,590
1381,0,-9.34,5.52,0,591
1384,0,-9.36,5.532,0,592.5
1387,0,-9.38,5.544,0,593.5
1390,0,-9.4,5.556,0,595
1393,0,-9.42,5.568,0,596
1396,0,-9.44,5.58,0,597.5
1399,0,-9.46,5.592,0,598.5
1402,0.2,-9.48,5.604,0.1,600
1405,0,-9.51,5.616,0,602
1408,0,-9.53,5.628,0,603
1411,0,-9.55,5.64,0,604.5
1414,0,-9.57,5.652,0,605.5
1417,0,-9.59,5.664,0,607
1420,0,-9.61,5.676,0,608
1423,0.2,-9.63,5.688,0.1,609.5
1426,0.2,-9.65,5.7,0.1,611
1429,-0.2,-9.67,5.712,-0.1,612
1432,0.2,-9.7,5.724,0.1,614
1435,0,-9.72,5.736,0,615
1438,-0.2,-9.74,5.748,-0.1,616.5
1441,0.2,-9.76,5.76,0.1,617.5
1444,-0.2,-9.78,5.772,-0.1,619
1447,-0.4,-9.8,5.784,-0.2,620.5
1450,0,-9.82,5.796,0,621.5
1453,0.2,-9.84,5.808,0.1,623
1456,0,-9.87,5.82,0,624.5
1459,-0.2,-9.89,5.832,-0.1,626
1462,0,-9.91,5.844,0,627
1465,0,-9.93,5.856,0,628.5
1468,-0.2,-9.95,5.868,-0.1,629.5
1471,0.2,-9.97,5.88,0.1,631
1474,0,-9.99,5.892,0,632.5
1477,0,-10.01,5.904,0,633.5
1480,0,-10.04,5.916,0,635.5
1483,0,-10.06,5.928,0,636.5
1486,0,-10.08,5.94,0,638
1489,0,-10.1,5.952,0,639
1492,0,-10.12,5.964,0,640.5
1495,0,-10.14,5.976,0,642
1498,0.2,-10.16,5.988,0.1,643
1501,-0.2,-10.18,6,-0.1,644.5
1504,0,-10.2,6.012,0,645.5
1507,0,-10.23,6.024,0,647.5
1510,0,-10.25,6.036,0,648.5
1513,0,-10.27,6.048,0,650
1516,0,-10.29,6.06,0,651.5
1519,0,-10.31,6.072,0,652.5
1522,-0.4,-10.33,6.084,-0.2,654
1525,0,-10.35,6.096,0,655
1528,0.4,-10.37,6.108,0.2,656.5
1531,0.2,-10.39,6.12,0.1,657.5
1534,0.4,-10.41,6.132,0.2,659
1537,0,-10.43,6.144,0,660
1540,0,-10.45,6.156,0,661.5
1543,-0.2,-10.47,6.168,-0.1,662.5
1546,0,-10.49,6.18,0,664
1549,0,-10.51,6.192,0,665
1552,0,-10.53,6.204,0,666.5
1555,0,-10.55,6.216,0,667.5
1558,-0.2,-10.57,6.228,-0.1,669
1561,0.2,-10.59,6.24,0.1,670.5
1564,0,-10.62,6.252,0,672
1567,0,-10.64,6.264,0,673.5
1570,0,-10.66,6.276,0,674.5
1573,0,-10.68,6.288,0,676
1576,0,-10.7,6.3,0,677
1579,-0.2,-10.72,6.312,-0.1,678.5
1582,0,-10.74,6.324,0,679.5
1585,0,-10.76,6.336,0,681
1588,-0.2,-10.78,6.348,-0.1,682.5
1591,0.2,-10.81,6.36,0.1,684
1594,-0.2,-10.83,6.372,-0.1,685.5
1597,-0.4,-10.85,6.384,-0.2,686.5
1600,0,-10.87,6.396,0,688
1603,-0.2,-10.89,6.408,-0.1,689
1606,0,-10.91,6.42,0,690.5
1609,0.2,-10.93,6.432,0.1,692
1612,-0.2,-10.95,6.444,-0.1,693
1615,0.2,-10.97,6.456,0.1,694.5
1618,-0.2,-10.99,6.468,-0.1,695.5
1621,0,-11.01,6.48,0,697
1624,0,-11.04,6.492,0,698.5
1627,0.2,-11.06,6.504,0.1,700
1630,0,-11.08,6.516,0,701.5
1633,-0.2,-11.1,6.528,-0.1,702.5
1636,0,-11.12,6.54,0,704
1639,0,-11.14,6.552,0,705
1642,0,-11.16,6.564,0,706.5
1645,0,-11.18,6.576,0,707.5
1648,0,-11.2,6.588,0,709
1651,-0.2,-11.22,6.6,-0.1,710
1654,0,-11.24,6.612,0,711.5
1657,0,-11.27,6.624,0,713.5
1660,-0.2,-11.29,6.636,-0.1,714.5
1663,0,-11.31,6.648,0,716
1666,0,-11.33,6.66,0,717
1669,0,-11.35,6.672,0,718.5
1672,-0.2,-11.37,6.684,-0.1,719.5
1675,0,-11.39,6.696,0,721
1678,-0.2,-11.41,6.708,-0.1,722
1681,0,-11.43,6.72,0,723.5
1684,0.2,-11.46,6.732,0.1,725.5
1687,0,-11.47,6.744,0,726
1690,0,-11.5,6.756,0,728
1693,0,-11.52,6.768,0,729
1696,-0.2,-11.54,6.78,-0.1,730.5
1699,0,-11.56,6.792,0,731.5
1702,0,-11.58,6.804,0,733
1705,-0.2,-11.6,6.816,-0.1,734
1708,0,-11.62,6.828,0,735.5
1711,-0.4,-11.64,6.84,-0.2,736.5
1714,-0.4,-11.66,6.852,-0.2,738
1717,0.2,-11.68,6.864,0.1,739
1720,0,-11.7,6.876,0,740.5
1723,0.2,-11.73,6.888,0.1,742.5
1726,0,-11.75,6.9,0,743.5
1729,0,-11.77,6.912,0,745
1732,0.2,-11.79,6.924,0.1,746
1735,-0.2,-11.81,6.936,-0.1,747.5
1738,0,-11.83,6.948,0,748.5
1741,0.2,-11.85,6.96,0.1,750
1744,0,-11.87,6.972,0,751.5
1747,0,-11.89,6.984,0,752.5
1750,0,-11.91,6.996,0,754
1753,0,-11.93,7.008,0,755
1756,0.2,-11.95,7.02,0.1,756.5
1759,0,-11.98,7.032,0,758
1762,0,-12,7.044,0,759.5
1765,-0.2,-12.02,7.056,-0.1,761
1768,-0.6,-12.04,7.068,-0.3,762
1771,0,-12.06,7.08,0,763.5
1774,0,-12.08,7.092,0,764.5
1777,0,-12.1,7.104,0,766
1780,0,-12.12,7.116,0,767
1783,0,-12.14,7.128,0,768.5
1786,0,-12.16,7.14,0,769.5
1789,0.2,-12.18,7.152,0.1,771
1792,0.4,-12.21,7.164,0.2,773
1795,0,-12.23,7.176,0,774
1798,0,-12.25,7.188,0,775.5
1801,0,-12.27,7.2,0,776.5
1804,0.2,-12.29,7.212,0.1,778
1807,0,-12.31,7.224,0,779
1810,-0.2,-12.33,7.236,-0.1,780.5
1813,-0.2,-12.35,7.248,-0.1,781.5
1816,0,-12.37,7.26,0,783
1819,-0.2,-12.4,7.272,-0.1,785
1822,0.2,-12.42,7.284,0.1,786
1825,0,-12.45,7.296,0,788
1828,0.2,-12.47,7.308,0.1,789
1831,0,-12.49,7.32,0,790.5
1834,0.2,-12.51,7.332,0.1,792
1837,0,-12.53,7.344,0,793
1840,0,-12.55,7.356,0,794.5
1843,0,-12.57,7.368,0,795.5
1846,0,-12.59,7.38,0,797
1849,0,-12.61,7.392,0,798
1852,0,-12.63,7.404,0,799.5
1855,0,-12.65,7.416,0,800.5
1858,-0.4,-12.68,7.428,-0.2,802.5
1861,-0.2,-12.7,7.44,-0.1,804
1864,0,-12.72,7.452,0,805
1867,0.2,-12.74,7.464,0.1,806.5
1870,0.2,-12.76,7.476,0.1,807.5
1873,0.2,-12.78,7.488,0.1,809
1876,-0.4,-12.8,7.5,-0.2,810
1879,0.2,-12.82,7.512,0.1,811.5
1882,0,-12.84,7.524,0,812.5
1885,0,-12.86,7.536,0,814
1888,0,-12.89,7.548,0,816
1891,0,-12.9,7.56,0,816.5
1894,0,-12.93,7.572,0,818.5
1897,0,-12.95,7.584,0,819.5
1900,0,-12.97,7.596,0,821
1903,0,-12.99,7.608,0,822
1906,0,-13.01,7.62,0,823.5
1909,0,-13.03,7.632,0,824.5
1912,-0.4,-13.05,7.644,-0.2,826
1915,0,-13.07,7.656,0,827
1918,0,-13.09,7.668,0,828.5
1921,-0.2,-13.12,7.68,-0.1,830.5
1924,0,-13.13,7.692,0,831
1927,0,-13.16,7.704,0,833
1930,0,-13.18,7.716,0,834
1933,0,-13.2,7.728,0,835.5
1936,-0.2,-13.22,7.74,-0.1,836.5
1939,0.2,-13.24,7.752,0.1,838
1942,-0.2,-13.26,7.764,-0.1,839
1945,0,-13.28,7.776,0,840.5
1948,0,-13.3,7.788,0,842
1951,0.2,-13.32,7.8,0.1,843
1954,0.2,-13.35,7.812,0.1,845
1957,0,-13.37,7.824,0,846
1960,0,-13.39,7.836,0,847.5
1963,-0.2,-13.41,7.848,-0.1,848.5
1966,0,-13.43,7.86,0,850
1969,-0.2,-13.45,7.872,-0.1,851.5
1972,0,-13.47,7.884,0,852.5
1975,0.2,-13.49,7.896,0.1,854
1978,0,-13.51,7.908,0,855
1981,0,-13.53,7.92,0,856.5
1984,0,-13.55,7.932,0,857.5
1987,-0.2,-13.58,7.944,-0.1,859.5
1990,0,-13.6,7.956,0,861
1993,0,-13.62,7.968,0,862
1996,-0.2,-13.64,7.98,-0.1,863.5
1999,0,-13.66,7.992,0,864.5
2002,0.2,-13.68,8.004,0.1,866
2005,0,-13.7,8.016,0,867
2008,0,-13.72,8.028,0,868.5
2011,-0.2,-13.74,8.04,-0.1,869.5
2014,0.2,-13.77,8.052,0.1,871.5
2017,0,-13.79,8.064,0,873
2020,0,-13.81,8.076,0,874
2023,0,-13.83,8.088,0,875.5
2026,0.4,-13.85,8.1,0.2,876.5
2029,0,-13.87,8.112,0,878
2032,0,-13.89,8.124,0,879
2035,0,-13.91,8.136,0,880.5
2038,0,-13.93,8.148,0,881.5
2041,0,-13.96,8.16,0,883.5
2044,0,-13.98,8.172,0,885
2047,0,-14,8.184,0,886
2050,-0.4,-14.02,8.196,-0.2,887.5
2053,0,-14.04,8.208,0,888.5
2056,0,-14.06,8.22,0,890
2059,-0.2,-14.08,8.232,-0.1,891
2062,0,-14.1,8.244,0,892.5
2065,0.2,-14.13,8.256,0.1,894.5
2068,0,-14.15,8.268,0,895.5
2071,0,-14.17,8.28,0,897
2074,0,-14.19,8.292,0,898
2077,-0.2,-14.21,8.304,-0.1,899.5
2080,0.4,-14.23,8.316,0.2,900.5
2083,-0.2,-14.25,8.328,-0.1,902
2086,0,-14.27,8.34,0,903
2089,0,-14.3,8.352,0,905
2092,-0.2,-14.32,8.364,-0.1,906.5
2095,0,-14.34,8.376,0,907.5
2098,0,-14.36,8.388,0,909
2101,0,-14.38,8.4,0,910
2104,0.4,-14.4,8.412,0.2,911.5
2107,0.2,-14.42,8.424,0.1,912.5
2110,0,-14.44,8.436,0,914
2113,-0.2,-14.46,8.448,-0.1,915
2116,-0.2,-14.49,8.46,-0.1,917
2119,0,-14.51,8.472,0,918.5
2122,0,-14.53,8.484,0,919.5
2125,0,-14.55,8.496,0,921
2128,0,-14.57,8.508,0,922
2131,0,-14.59,8.52,0,923.5
2134,-0.2,-14.61,8.532,-0.1,924.5
2137,-0.2,-14.63,8.544,-0.1,926
2140,0,-14.65,8.556,0,927
2143,0,-14.68,8.568,0,929
2146,0,-14.7,8.58,0,930.5
2149,0,-14.72,8.592,0,931.5
2152,-0.4,-14.74,8.604,-0.2,933
2155,0.2,-14.76,8.616,0.1,934
2158,0,-14.78,8.628,0,935.5
2161,0,-14.8,8.64,0,936.5
2164,-0.2,-14.82,8.652,-0.1,938
2167,0,-14.84,8.664,0,939
2170,-0.2,-14.87,8.676,-0.1,941
2173,0,-14.89,8.688,0,942.5
2176,0.2,-14.91,8.7,0.1,943.5
2179,-0.2,-14.93,8.712,-0.1,945
2182,-0.4,-14.95,8.724,-0.2,946
2185,0,-14.97,8.736,0,947.5
2188,0,-14.99,8.748,0,948.5
2191,0,-15.01,8.76,0,950
2194,0,-15.03,8.772,0,951.5
2197,0.2,-15.06,8.784,0.1,953
2200,0,-15.08,8.796,0,954.5
2203,0,-15.1,8.808,0,955.5
2206,0,-15.12,8.82,0,957
2209,0,-15.14,8.832,0,958
2212,0,-15.16,8.844,0,959.5
2215,0.2,-15.18,8.856,0.1,961
2218,0,-15.2,8.868,0,962
2221,0,-15.22,8.88,0,963.5
2224,0,-15.25,8.892,0,965
2227,0,-15.27,8.904,0,966.5
2230,0,-15.29,8.916,0,967.5
2233,0.2,-15.31,8.928,0.1,969
2236,0,-15.33,8.94,0,970.5
2239,0,-15.35,8.952,0,971.5
2242,-0.2,-15.37,8.964,-0.1,973
2245,-0.2,-15.39,8.976,-0.1,974
2248,-0.2,-15.4,8.988,-0.1,974.5
2251,0,-15.43,9,0,976.5
2254,0.2,-15.45,9.012,0.1,978
2257,0.2,-15.47,9.024,0.1,979
2260,0,-15.49,9.036,0,980.5
2263,0.6,-15.51,9.048,0.3,981.5
2266,-0.2,-15.53,9.06,-0.1,983
2269,0.2,-15.55,9.072,0.1,984
2272,0,-15.57,9.084,0,985.5
2275,0,-15.59,9.096,0,986.5
2278,0,-15.62,9.108,0,988.5
2281,0,-15.64,9.12,0,990
2284,-0.4,-15.66,9.132,-0.2,991
2287,0,-15.68,9.144,0,992.5
2290,0,-15.7,9.156,0,993.5
2293,0,-15.72,9.168,0,995
2296,0,-15.74,9.18,0,996
2299,0,-15.76,9.192,0,997.5
2302,0,-15.78,9.204,0,998.5
2305,0.4,-15.81,9.216,0.2,1000.5
2308,0,-15.83,9.228,0,1002
2311,0.4,-15.85,9.24,0.2,1003
2314,0,-15.87,9.252,0,1004.5
2317,0,-15.89,9.264,0,1005.5
2320,0,-15.91,9.276,0,1007
2323,0,-15.93,9.288,0,1008
2326,0.4,-15.95,9.3,0.2,1009.5
2329,0,-15.97,9.312,0,1011
2332,0.2,-15.99,9.324,0.1,1012
2335,0.2,-16.02,9.336,0.1,1014
2338,0,-16.04,9.348,0,1015
2341,0,-16.06,9.36,0,1016.5
2344,-0.2,-16.08,9.372,-0.1,1017.5
2347,-0.2,-16.1,9.384,-0.1,1019
2350,0,-16.12,9.396,0,1020.5
2353,0.4,-16.14,9.408,0.2,1021.5
2356,0.2,-16.16,9.42,0.1,1023
2359,0,-16.18,9.432,0,1024
2362,0,-16.2,9.444,0,1025.5
2365,0,-16.22,9.456,0,1026.5
2368,-0.4,-16.25,9.468,-0.2,1028.5
2371,0,-16.27,9.48,0,1029.5
2374,0,-16.29,9.492,0,1031
2377,0,-16.31,9.504,0,1032.5
2380,0,-16.33,9.516,0,1033.5
2383,0,-16.35,9.528,0,1035
2386,0.2,-16.37,9.54,0.1,1036
2389,-0.2,-16.39,9.552,-0.1,1037.5
2392,0,-16.41,9.564,0,1038.5
2395,0,-16.43,9.576,0,1040
2398,0,-16.45,9.588,0,1041
2401,0,-16.48,9.6,0,1043
2404,0,-16.49,9.612,0,1043.5
2407,-0.2,-16.52,9.624,-0.1,1045.5
2410,0,-16.54,9.636,0,1047
2413,-0.6,-16.56,9.648,-0.3,1048
2416,0,-16.58,9.66,0,1049.5
2419,0.4,-16.6,9.672,0.2,1050.5
2422,0,-16.62,9.684,0,1052
2425,0.2,-16.64,9.696,0.1,1053
2428,0,-16.66,9.708,0,1054.5
2431,0,-16.68,9.72,0,1055.5
2434,0.4,-16.7,9.732,0.2,1057
2437,-0.4,-16.72,9.744,-0.2,1058
2440,0.2,-16.75,9.756,0.1,1060
2443,-0.2,-16.77,9.768,-0.1,1061.5
2446,0,-16.79,9.78,0,1062.5
2449,0,-16.81,9.792,0,1064
2452,0.2,-16.83,9.804,0.1,1065
2455,0,-16.85,9.816,0,1066.5
2458,0.2,-16.87,9.828,0.1,1067.5
2461,0,-16.89,9.84,0,1069
2464,0,-16.91,9.852,0,1070.5
2467,0,-16.93,9.864,0,1071.5
2470,0,-16.95,9.876,0,1073
2473,0,-16.97,9.888,0,1074
2476,0,-17,9.9,0,1076
2479,0.2,-17.02,9.912,0.1,1077
2482,0.2,-17.04,9.924,0.1,1078.5
2485,0,-17.06,9.936,0,1079.5
2488,0,-17.08,9.948,0,1081
2491,0,-17.1,9.96,0,1082.5
2494,0.4,-17.12,9.972,0.2,1083.5
2497,0,-17.14,9.984,0,1085
2500,0,-17.16,9.996,0,1086
2503,-0.4,-17.18,10.008,-0.2,1087.5
2506,-0.2,-17.2,10.02,-0.1,1088.5
2509,0,-17.23,10.032,0,1090.5
2512,0,-17.24,10.044,0,1091
2515,0,-17.27,10.056,0,1093
2518,0,-17.29,10.068,0,1094.5
2521,0.2,-17.31,10.08,0.1,1095.5
2524,0,-17.33,10.092,0,1097
2527,0.2,-17.35,10.104,0.1,1098
2530,0,-17.37,10.116,0,1099.5
2533,0,-17.39,10.128,0,1100.5
2536,0,-17.42,10.14,0,1102.5
2539,0.2,-17.44,10.152,0.1,1104
2542,0,-17.46,10.164,0,1105
2545,0,-17.48,10.176,0,1106.5
2548,0,-17.51,10.188,0,1108
2551,-0.2,-17.53,10.2,-0.1,1109.5
2554,0.2,-17.55,10.212,0.1,1111
2557,0,-17.57,10.224,0,1112
2560,0,-17.59,10.236,0,1113.5
2563,-0.2,-17.61,10.248,-0.1,1114.5
2566,0,-17.63,10.26,0,1116
2569,-0.2,-17.65,10.272,-0.1,1117
2572,-0.4,-17.67,10.284,-0.2,1118.5
2575,0,-17.69,10.296,0,1119.5
2578,-0.2,-17.72,10.308,-0.1,1121.5
2581,0,-17.73,10.32,0,1122
2584,0,-17.76,10.332,0,1124
2587,-0.2,-17.78,10.344,-0.1,1125.5
2590,0,-17.8,10.356,0,1126.5
2593,0,-17.82,10.368,0,1128
2596,-0.2,-17.84,10.38,-0.1,1129
2599,-0.2,-17.86,10.392,-0.1,1130.5
2602,0.2,-17.88,10.404,0.1,1131.5
2605,0,-17.9,10.416,0,1133
2608,-0.4,-17.92,10.428,-0.2,1134
2611,-0.2,-17.95,10.44,-0.1,1136
2614,-0.2,-17.96,10.452,-0.1,1136.5
2617,0,-17.99,10.464,0,1138.5
2620,0.2,-18.01,10.476,0.1,1140
2623,0,-18.03,10.488,0,1141
2626,0,-18.05,10.5,0,1142.5
2629,0.2,-18.07,10.512,0.1,1143.5
2632,0,-18.09,10.524,0,1145
2635,0.2,-18.11,10.536,0.1,1146
2638,-0.2,-18.13,10.548,-0.1,1147.5
2641,-0.4,-18.15,10.56,-0.2,1148.5
2644,0,-18.18,10.572,0,1150.5
2647,-0.2,-18.19,10.584,-0.1,1151.5
2650,0,-18.22,10.596,0,1153
2653,0,-18.24,10.608,0,1154.5
2656,-0.2,-18.26,10.62,-0.1,1155.5
2659,-0.2,-18.28,10.632,-0.1,1157
2662,0,-18.3,10.644,0,1158
2665,0.2,-18.32,10.656,0.1,1159.5
2668,-0.2,-18.34,10.668,-0.1,1161
2671,0,-18.36,10.68,0,1162
2674,0,-18.38,10.692,0,1163.5
2677,0.4,-18.4,10.704,0.2,1164.5
2680,-0.2,-18.43,10.716,-0.1,1166.5
2683,0,-18.45,10.728,0,1167.5
2686,0,-18.47,10.74,0,1169
2689,-0.2,-18.49,10.752,-0.1,1170.5
2692,0,-18.51,10.764,0,1171.5
2695,0.2,-18.53,10.776,0.1,1173
2698,-0.2,-18.55,10.788,-0.1,1174
2701,0,-18.57,10.8,0,1175.5
2704,0,-18.59,10.812,0,1176.5
2707,0,-18.62,10.824,0,1178.5
2710,0,-18.64,10.836,0,1179.5
2713,0,-18.66,10.848,0,1181
2716,0.2,-18.68,10.86,0.1,1182.5
2719,0,-18.7,10.872,0,1183.5
2722,0.2,-18.72,10.884,0.1,1185
2725,0,-18.74,10.896,0,1186
2728,0,-18.76,10.908,0,1187.5
2731,-0.2,-18.78,10.92,-0.1,1188.5
2734,-0.2,-18.8,10.932,-0.1,1190
2737,0,-18.83,10.944,0,1192
2740,0.4,-18.85,10.956,0.2,1193
2743,0,-18.87,10.968,0,1194.5
2746,0,-18.89,10.98,0,1195.5
2749,0,-18.91,10.992,0,1197
2752,0,-18.93,11.004,0,1198
2755,0,-18.95,11.016,0,1199.5
2758,-0.2,-18.97,11.028,-0.1,1200.5
2761,0,-18.99,11.04,0,1202
2764,0,-19.02,11.052,0,1204
2767,0.2,-19.04,11.064,0.1,1205
2770,0,-19.06,11.076,0,1206.5
2773,0,-19.08,11.088,0,1207.5
2776,0,-19.1,11.1,0,1209
2779,0,-19.12,11.112,0,1210
2782,0,-19.14,11.124,0,1211.5
2785,0,-19.16,11.136,0,1212.5
2788,0,-19.18,11.148,0,1214
2791,0,-19.21,11.16,0,1216
2794,-0.2,-19.23,11.172,-0.1,1217
2797,0,-19.25,11.184,0,1218.5
2800,0,-19.27,11.196,0,1219.5
2803,0,-19.29,11.208,0,1221
2806,0.6,-19.31,11.22,0.3,1222
2809,-0.2,-19.33,11.232,-0.1,1223.5
2812,0.2,-19.35,11.244,0.1,1224.5
2815,-0.4,-19.37,11.256,-0.2,1226
2818,0,-19.4,11.268,0,1228
2821,-0.2,-19.41,11.28,-0.1,1228.5
2824,0.2,-19.43,11.292,0.1,1229.5
2827,0.2,-19.45,11.304,0.1,1231
2830,-0.2,-19.47,11.316,-0.1,1232.5
2833,0.2,-19.49,11.328,0.1,1233.5
2836,0,-19.51,11.34,0,1235
2839,0.2,-19.53,11.352,0.1,1236
2842,0,-19.56,11.364,0,1238
2845,0,-19.58,11.376,0,1239
2848,-0.2,-19.6,11.388,-0.1,1240.5
2851,0,-19.62,11.4,0,1242
2854,0.4,-19.64,11.412,0.2,1243
2857,0,-19.66,11.424,0,1244.5
2860,0.2,-19.68,11.436,0.1,1245.5
2863,-0.2,-19.7,11.448,-0.1,1247
2866,0,-19.72,11.46,0,1248
2869,-0.2,-19.75,11.472,-0.1,1250
2872,0,-19.77,11.484,0,1251.5
2875,0.2,-19.79,11.496,0.1,1252.5
2878,0,-19.81,11.508,0,1254
2881,-0.2,-19.83,11.52,-0.1,1255
2884,0.2,-19.85,11.532,0.1,1256.5
2887,0.2,-19.87,11.544,0.1,1257.5
2890,0,-19.89,11.556,0,1259
2893,0.2,-19.91,11.568,0.1,1260
2896,-0.2,-19.94,11.58,-0.1,1262
2899,0,-19.96,11.592,0,1263.5
2902,-0.4,-19.98,11.604,-0.2,1264.5
2905,0,-20,11.616,0,1266
2908,-0.2,-20.02,11.628,-0.1,1267
2911,0,-20.04,11.64,0,1268.5
2914,0,-20.06,11.652,0,1269.5
2917,0,-20.08,11.664,0,1271
2920,0.2,-20.1,11.676,0.1,1272
2923,0,-20.13,11.688,0,1274
2926,0,-20.15,11.7,0,1275.5
2929,0.2,-20.17,11.712,0.1,1276.5
2932,-0.2,-20.19,11.724,-0.1,1278
2935,0.2,-20.21,11.736,0.1,1279
2938,0,-20.23,11.748,0,1280.5
2941,0.2,-20.25,11.76,0.1,1281.5
2944,0,-20.27,11.772,0,1283
2947,-0.4,-20.29,11.784,-0.2,1284
2950,-0.2,-20.32,11.796,-0.1,1286
2953,0,-20.34,11.808,0,1287.5
2956,0,-20.36,11.82,0,1288.5
2959,-0.2,-20.38,11.832,-0.1,1290
2962,0,-20.4,11.844,0,1291
2965,0,-20.42,11.856,0,1292.5
2968,-0.2,-20.44,11.868,-0.1,1293.5
2971,0,-20.46,11.88,0,1295
2974,-0.2,-20.48,11.892,-0.1,1296
2977,0.2,-20.51,11.904,0.1,1298
2980,0,-20.53,11.916,0,1299.5
2983,-0.2,-20.55,11.928,-0.1,1300.5
2986,0,-20.57,11.94,0,1302
2989,0,-20.59,11.952,0,1303
2992,0,-20.61,11.964,0,1304.5
2995,0.2,-20.63,11.976,0.1,1305.5
2998,-0.2,-20.65,11.988,-0.1,1307
3001,0,-20.67,12,0,1308
3004,0,-20.7,12.012,0,1310
3007,0,-20.72,12.024,0,1311.5
3010,0,-20.74,12.036,0,1312.5
3013,0.2,-20.76,12.048,0.1,1314
3016,0,-20.78,12.06,0,1315
3019,0,-20.8,12.072,0,1316.5
3022,0,-20.82,12.084,0,1317.5
3025,-0.2,-20.84,12.096,-0.1,1319
3028,0,-20.86,12.108,0,1320.5
3031,0.2,-20.88,12.12,0.1,1321.5
3034,0.2,-20.9,12.132,0.1,1323
3037,0,-20.93,12.144,0,1324.5
3040,0,-20.95,12.156,0,1326
3043,-0.2,-20.97,12.168,-0.1,1327
3046,0,-20.99,12.18,0,1328.5
3049,0,-21.01,12.192,0,1329.5
3052,0,-21.03,12.204,0,1331
3055,0.2,-21.05,12.216,0.1,1332.5
3058,0,-21.07,12.228,0,1333.5
3061,0,-21.09,12.24,0,1335
3064,0,-21.12,12.252,0,1336.5
3067,-0.2,-21.14,12.264,-0.1,1338
3070,0,-21.16,12.276,0,1339
3073,-0.4,-21.18,12.288,-0.2,1340.5
3076,-0.2,-21.2,12.3,-0.1,1342
3079,-0.2,-21.22,12.312,-0.1,1343
3082,0.2,-21.24,12.324,0.1,1344.5
3085,0,-21.26,12.336,0,1345.5
3088,0,-21.28,12.348,0,1347
3091,0,-21.31,12.36,0,1348.5
3094,0.2,-21.32,12.372,0.1,1349.5
3097,0.6,-21.35,12.384,0.3,1351.5
3100,0.8,-21.37,12.396,0.4,1352.5
3103,1,-21.39,12.408,0.5,1354
3106,1.8,-21.41,12.42,0.85,1355
3109,2.8,-21.43,12.432,1.35,1356.5
3112,3.8,-21.45,12.444,1.8,1357.5
3115,4,-21.47,12.456,1.9,1359
3118,5.6,-21.49,12.468,2.7,1360
3121,7.2,-21.51,12.48,3.45,1361.5
3124,8.6,-21.53,12.492,4.1,1362.5
3127,9.6,-21.55,12.504,4.6,1364
3130,10.4,-21.57,12.516,5,1365
3133,10.8,-21.59,12.528,5.2,1366.5
3136,10.8,-21.61,12.54,5.2,1367.5
3139,11,-21.63,12.552,5.25,1369
3142,11.2,-21.65,12.564,5.35,1370.5
3145,11.6,-21.67,12.576,5.55,1371.5
3148,11.2,-21.69,12.588,5.35,1373
3151,11,-21.71,12.6,5.25,1374
3154,10,-21.72,12.612,4.8,1374.5
3157,9.2,-21.72,12.624,4.4,1374.5
3160,9,-21.72,12.636,4.3,1374.5
3163,8.8,-21.72,12.648,4.2,1374.5
3166,8.6,-21.72,12.66,4.1,1374.5
3169,8.6,-21.72,12.672,4.1,1374.5
3172,8.4,-21.72,12.684,4.05,1374.5
3175,8.4,-21.72,12.696,4.05,1374.5
3178,8.4,-21.72,12.708,4.05,1374.5
3181,8.2,-21.72,12.72,3.95,1374.5
3184,8,-21.72,12.732,3.85,1374.5
3187,8,-21.72,12.744,3.85,1374.5
3189,11.6,-21.65,12.752,3.85,1374.5