File: results/youngs-modulus/2025-04-21/inconclusive-data/pf18mt03.csv
sep=
pf18mt03

System Information:
IntelliMESUR Version: 2.2.1
Test Frame Model: F505
Test Frame Serial Number: 4418651
Test Frame Capacity: 500 lbF / 2.2 kN
Test Frame Firmware Version: 1.00.14
Force Sensor Model: FS05-100
Force Sensor Capacity: 500 N
Force Sensor Resolution: 0.2 N
Force Sensor Serial Number: 4425350
Calibration Date: Apr 29, 2024
Calibration Due Date: Apr 29, 2025

Reading	Load [N]	Distance [mm]	Time [s]	Stress [MPa]	Strain [%]
1	0.0	0.00	0.000	0.00	0.0
4	0.0	0.00	0.012	0.00	0.0
7	0.0	0.00	0.024	0.00	0.0
10	0.0	0.00	0.036	0.00	0.0
13	0.0	0.00	0.048	0.00	0.0
16	0.0	0.00	0.060	0.00	0.0
19	0.0	0.00	0.072	0.00	0.0
22	-0.2	0.00	0.084	-0.04	0.0
25	-0.2	0.00	0.096	-0.04	0.0
28	0.0	0.00	0.108	0.00	0.0
31	0.0	0.00	0.120	0.00	0.0
34	0.0	0.00	0.132	0.00	0.0
37	0.0	0.00	0.144	0.00	0.0
40	0.0	0.00	0.156	0.00	0.0
43	0.2	0.00	0.168	0.04	0.0
46	-0.2	0.00	0.180	-0.04	0.0
49	-0.2	-0.01	0.192	-0.04	0.4
52	0.0	-0.03	0.204	0.00	1.0
55	0.0	-0.06	0.216	0.00	2.0
58	0.6	-0.08	0.228	0.12	2.8
61	-0.2	-0.10	0.240	-0.04	3.4
64	0.0	-0.12	0.252	0.00	4.2
67	-0.2	-0.14	0.264	-0.04	4.8
70	0.0	-0.16	0.276	0.00	5.4
73	0.0	-0.18	0.288	0.00	6.2
76	0.0	-0.20	0.300	0.00	6.8
79	0.2	-0.22	0.312	0.04	7.6
82	0.0	-0.24	0.324	0.00	8.2
85	0.0	-0.26	0.336	0.00	9.0
88	0.2	-0.29	0.348	0.04	10.0
91	0.0	-0.31	0.360	0.00	10.6
94	0.2	-0.33	0.372	0.04	11.4
97	0.0	-0.35	0.384	0.00	12.0
100	-0.2	-0.37	0.396	-0.04	12.6
103	-0.2	-0.39	0.408	-0.04	13.4
106	-0.2	-0.41	0.420	-0.04	14.0
109	0.2	-0.43	0.432	0.04	14.8
112	0.0	-0.45	0.444	0.00	15.4
115	0.0	-0.47	0.456	0.00	16.0
118	0.0	-0.49	0.468	0.00	16.8
121	0.0	-0.52	0.480	0.00	17.8
124	0.0	-0.54	0.492	0.00	18.4
127	0.0	-0.56	0.504	0.00	19.2
130	0.0	-0.58	0.516	0.00	19.8
133	0.2	-0.60	0.528	0.04	20.6
136	0.0	-0.62	0.540	0.00	21.2
139	0.0	-0.64	0.552	0.00	22.0
142	-0.2	-0.66	0.564	-0.04	22.6
145	0.0	-0.68	0.576	0.00	23.2
148	0.0	-0.71	0.588	0.00	24.4
151	0.0	-0.73	0.600	0.00	25.0
154	0.0	-0.75	0.612	0.00	25.6
157	-0.2	-0.77	0.624	-0.04	26.4
160	0.0	-0.80	0.636	0.00	27.4
163	0.0	-0.82	0.648	0.00	28.0
166	-0.2	-0.84	0.660	-0.04	28.8
169	0.0	-0.86	0.672	0.00	29.4
172	0.0	-0.88	0.684	0.00	30.2
175	-0.2	-0.90	0.696	-0.04	30.8
178	-0.2	-0.92	0.708	-0.04	31.6
181	0.0	-0.94	0.720	0.00	32.2
184	0.0	-0.97	0.732	0.00	33.2
187	0.2	-0.99	0.744	0.04	34.0
190	-0.2	-1.01	0.756	-0.04	34.6
193	-0.4	-1.03	0.768	-0.08	35.2
196	0.0	-1.05	0.780	0.00	36.0
199	0.0	-1.07	0.792	0.00	36.6
202	0.2	-1.09	0.804	0.04	37.4
205	0.0	-1.11	0.816	0.00	38.0
208	0.0	-1.13	0.828	0.00	38.6
211	-0.2	-1.15	0.840	-0.04	39.4
214	0.0	-1.17	0.852	0.00	40.0
217	0.2	-1.20	0.864	0.04	41.0
220	0.0	-1.22	0.876	0.00	41.8
223	0.2	-1.24	0.888	0.04	42.4
226	-0.2	-1.26	0.900	-0.04	43.2
229	0.0	-1.28	0.912	0.00	43.8
232	0.0	-1.30	0.924	0.00	44.6
235	0.0	-1.32	0.936	0.00	45.2
238	0.0	-1.34	0.948	0.00	45.8
241	0.2	-1.36	0.960	0.04	46.6
244	0.0	-1.38	0.972	0.00	47.2
247	0.0	-1.40	0.984	0.00	48.0
250	0.2	-1.43	0.996	0.04	49.0
253	-0.2	-1.44	1.008	-0.04	49.4
256	0.2	-1.47	1.020	0.04	50.4
259	0.2	-1.49	1.032	0.04	51.0
262	0.2	-1.51	1.044	0.04	51.8
265	0.0	-1.53	1.056	0.00	52.4
268	0.2	-1.55	1.068	0.04	53.0
271	0.0	-1.57	1.080	0.00	53.8
274	0.2	-1.59	1.092	0.04	54.4
277	0.0	-1.61	1.104	0.00	55.2
280	0.2	-1.63	1.116	0.04	55.8
283	0.0	-1.65	1.128	0.00	56.6
286	0.2	-1.68	1.140	0.04	57.6
289	0.0	-1.70	1.152	0.00	58.2
292	0.2	-1.72	1.164	0.04	59.0
295	0.0	-1.74	1.176	0.00	59.6
298	-0.2	-1.76	1.188	-0.04	60.2
301	0.2	-1.78	1.200	0.04	61.0
304	0.0	-1.79	1.212	0.00	61.4
307	-0.2	-1.81	1.224	-0.04	62.0
310	0.0	-1.83	1.236	0.00	62.6
313	0.2	-1.85	1.248	0.04	63.4
316	0.0	-1.87	1.260	0.00	64.0
319	0.2	-1.90	1.272	0.04	65.0
322	0.2	-1.92	1.284	0.04	65.8
325	0.0	-1.94	1.296	0.00	66.4
328	0.0	-1.96	1.308	0.00	67.2
331	0.0	-1.98	1.320	0.00	67.8
334	0.0	-2.00	1.332	0.00	68.4
337	0.0	-2.02	1.344	0.00	69.2
340	0.0	-2.04	1.356	0.00	69.8
343	0.0	-2.06	1.368	0.00	70.6
346	-0.2	-2.08	1.380	-0.04	71.2
349	0.0	-2.10	1.392	0.00	72.0
352	-0.2	-2.12	1.404	-0.04	72.6
355	0.0	-2.14	1.416	0.00	73.2
358	0.0	-2.17	1.428	0.00	74.4
361	0.0	-2.19	1.440	0.00	75.0
364	-0.2	-2.21	1.452	-0.04	75.6
367	-0.2	-2.23	1.464	-0.04	76.4
370	0.0	-2.25	1.476	0.00	77.0
373	0.2	-2.27	1.488	0.04	77.8
376	0.2	-2.29	1.500	0.04	78.4
379	0.0	-2.31	1.512	0.00	79.2
382	0.0	-2.33	1.524	0.00	79.8
385	-0.4	-2.35	1.536	-0.08	80.4
388	-0.2	-2.38	1.548	-0.04	81.6
391	0.0	-2.40	1.560	0.00	82.2
394	-0.2	-2.42	1.572	-0.04	82.8
397	0.0	-2.44	1.584	0.00	83.6
400	0.0	-2.46	1.596	0.00	84.2
403	0.2	-2.48	1.608	0.04	85.0
406	0.0	-2.50	1.620	0.00	85.6
409	0.2	-2.52	1.632	0.04	86.4
412	0.0	-2.54	1.644	0.00	87.0
415	0.0	-2.56	1.656	0.00	87.6
418	0.2	-2.59	1.668	0.04	88.6
421	0.0	-2.61	1.680	0.00	89.4
424	0.0	-2.63	1.692	0.00	90.0
427	0.0	-2.65	1.704	0.00	90.8
430	0.0	-2.67	1.716	0.00	91.4
433	0.0	-2.69	1.728	0.00	92.2
436	0.0	-2.71	1.740	0.00	92.8
439	-0.2	-2.73	1.752	-0.04	93.4
442	0.0	-2.75	1.764	0.00	94.2
445	0.0	-2.77	1.776	0.00	94.8
448	0.0	-2.80	1.788	0.00	95.8
451	0.0	-2.83	1.800	0.00	97.0
454	0.0	-2.85	1.812	0.00	97.6
457	0.0	-2.87	1.824	0.00	98.2
460	0.0	-2.89	1.836	0.00	99.0
463	-0.2	-2.91	1.848	-0.04	99.6
466	0.0	-2.93	1.860	0.00	100.4
469	-0.2	-2.95	1.872	-0.04	101.0
472	0.4	-2.97	1.884	0.08	101.8
475	0.0	-2.99	1.896	0.00	102.4
478	0.0	-3.02	1.908	0.00	103.4
481	0.0	-3.04	1.920	0.00	104.2
484	0.4	-3.06	1.932	0.08	104.8
487	-0.2	-3.08	1.944	-0.04	105.4
490	0.2	-3.10	1.956	0.04	106.2
493	0.0	-3.12	1.968	0.00	106.8
496	0.0	-3.14	1.980	0.00	107.6
499	0.0	-3.16	1.992	0.00	108.2
502	0.0	-3.18	2.004	0.00	109.0
505	0.0	-3.20	2.016	0.00	109.6
508	0.0	-3.23	2.028	0.00	110.6
511	-0.2	-3.25	2.040	-0.04	111.4
514	0.0	-3.27	2.052	0.00	112.0
517	0.0	-3.29	2.064	0.00	112.6
520	0.2	-3.31	2.076	0.04	113.4
523	0.2	-3.33	2.088	0.04	114.0
526	0.0	-3.35	2.100	0.00	114.8
529	0.0	-3.37	2.112	0.00	115.4
532	0.2	-3.39	2.124	0.04	116.0
535	0.0	-3.42	2.136	0.00	117.2
538	0.2	-3.44	2.148	0.04	117.8
541	0.2	-3.46	2.160	0.04	118.4
544	-0.2	-3.48	2.172	-0.04	119.2
547	0.0	-3.50	2.184	0.00	119.8
550	0.2	-3.52	2.196	0.04	120.6
553	0.0	-3.54	2.208	0.00	121.2
556	0.0	-3.56	2.220	0.00	122.0
559	0.0	-3.58	2.232	0.00	122.6
562	0.0	-3.61	2.244	0.00	123.6
565	0.0	-3.63	2.256	0.00	124.4
568	-0.2	-3.65	2.268	-0.04	125.0
571	0.2	-3.67	2.280	0.04	125.6
574	-0.2	-3.69	2.292	-0.04	126.4
577	0.0	-3.71	2.304	0.00	127.0
580	0.0	-3.73	2.316	0.00	127.8
583	0.2	-3.75	2.328	0.04	128.4
586	0.0	-3.78	2.340	0.00	129.4
589	0.0	-3.80	2.352	0.00	130.2
592	0.0	-3.82	2.364	0.00	130.8
595	0.0	-3.84	2.376	0.00	131.6
598	0.0	-3.86	2.388	0.00	132.2
601	0.0	-3.88	2.400	0.00	132.8
604	0.0	-3.90	2.412	0.00	133.6
607	0.0	-3.92	2.424	0.00	134.2
610	0.0	-3.95	2.436	0.00	135.2
613	0.0	-3.97	2.448	0.00	136.0
616	0.0	-3.99	2.460	0.00	136.6
619	0.2	-4.01	2.472	0.04	137.4
622	-0.2	-4.03	2.484	-0.04	138.0
625	-0.2	-4.05	2.496	-0.04	138.6
628	0.0	-4.07	2.508	0.00	139.4
631	0.0	-4.09	2.520	0.00	140.0
634	0.0	-4.11	2.532	0.00	140.8
637	0.0	-4.14	2.544	0.00	141.8
640	0.0	-4.16	2.556	0.00	142.4
643	0.0	-4.18	2.568	0.00	143.2
646	-0.4	-4.20	2.580	-0.08	143.8
649	-0.2	-4.22	2.592	-0.04	144.6
652	0.0	-4.24	2.604	0.00	145.2
655	0.0	-4.26	2.616	0.00	145.8
658	-0.4	-4.28	2.628	-0.08	146.6
661	0.0	-4.30	2.640	0.00	147.2
664	0.0	-4.33	2.652	0.00	148.2
667	0.0	-4.35	2.664	0.00	149.0
670	0.0	-4.37	2.676	0.00	149.6
673	0.0	-4.39	2.688	0.00	150.4
676	0.4	-4.41	2.700	0.08	151.0
679	0.0	-4.43	2.712	0.00	151.8
682	0.0	-4.45	2.724	0.00	152.4
685	0.0	-4.47	2.736	0.00	153.0
688	-0.2	-4.49	2.748	-0.04	153.8
691	0.0	-4.52	2.760	0.00	154.8
694	-0.2	-4.54	2.772	-0.04	155.4
697	-0.2	-4.56	2.784	-0.04	156.2
700	0.0	-4.58	2.796	0.00	156.8
703	0.0	-4.60	2.808	0.00	157.6
706	0.0	-4.62	2.820	0.00	158.2
709	0.0	-4.64	2.832	0.00	159.0
712	0.0	-4.66	2.844	0.00	159.6
715	0.0	-4.68	2.856	0.00	160.2
718	0.0	-4.71	2.868	0.00	161.4
721	-0.2	-4.73	2.880	-0.04	162.0
724	0.2	-4.75	2.892	0.04	162.6
727	0.0	-4.77	2.904	0.00	163.4
730	0.0	-4.79	2.916	0.00	164.0
733	0.2	-4.81	2.928	0.04	164.8
736	-0.2	-4.83	2.940	-0.04	165.4
739	0.0	-4.85	2.952	0.00	166.0
742	0.0	-4.87	2.964	0.00	166.8
745	0.2	-4.90	2.976	0.04	167.8
748	0.2	-4.92	2.988	0.04	168.4
751	0.0	-4.94	3.000	0.00	169.2
754	0.2	-4.96	3.012	0.04	169.8
757	0.0	-4.98	3.024	0.00	170.6
760	-0.2	-5.00	3.036	-0.04	171.2
763	-0.2	-5.02	3.048	-0.04	172.0
766	0.0	-5.04	3.060	0.00	172.6
769	0.0	-5.06	3.072	0.00	173.2
772	-0.2	-5.09	3.084	-0.04	174.4
775	0.2	-5.11	3.096	0.04	175.0
778	0.0	-5.13	3.108	0.00	175.6
781	0.0	-5.15	3.120	0.00	176.4
784	0.0	-5.17	3.132	0.00	177.0
787	0.0	-5.19	3.144	0.00	177.8
790	0.2	-5.21	3.156	0.04	178.4
793	0.0	-5.23	3.168	0.00	179.2
796	0.0	-5.25	3.180	0.00	179.8
799	-0.2	-5.27	3.192	-0.04	180.4
802	0.2	-5.29	3.204	0.04	181.2
805	0.0	-5.32	3.216	0.00	182.2
808	0.0	-5.34	3.228	0.00	182.8
811	-0.2	-5.36	3.240	-0.04	183.6
814	0.0	-5.38	3.252	0.00	184.2
817	0.2	-5.40	3.264	0.04	185.0
820	0.0	-5.42	3.276	0.00	185.6
823	0.2	-5.44	3.288	0.04	186.4
826	0.0	-5.46	3.300	0.00	187.0
829	0.0	-5.48	3.312	0.00	187.6
832	-0.2	-5.50	3.324	-0.04	188.4
835	-0.2	-5.52	3.336	-0.04	189.0
838	0.0	-5.55	3.348	0.00	190.0
841	0.0	-5.57	3.360	0.00	190.8
844	0.0	-5.59	3.372	0.00	191.4
847	-0.2	-5.61	3.384	-0.04	192.2
850	0.0	-5.63	3.396	0.00	192.8
853	0.2	-5.65	3.408	0.04	193.4
856	0.0	-5.67	3.420	0.00	194.2
859	0.0	-5.69	3.432	0.00	194.8
862	0.0	-5.71	3.444	0.00	195.6
865	0.0	-5.73	3.456	0.00	196.2
868	0.0	-5.75	3.468	0.00	197.0
871	0.0	-5.78	3.480	0.00	198.0
874	0.0	-5.79	3.492	0.00	198.2
877	0.0	-5.81	3.504	0.00	199.0
880	0.0	-5.83	3.516	0.00	199.6
883	-0.4	-5.85	3.528	-0.08	200.4
886	0.0	-5.87	3.540	0.00	201.0
889	0.0	-5.89	3.552	0.00	201.8
892	0.0	-5.91	3.564	0.00	202.4
895	0.2	-5.93	3.576	0.04	203.0
898	0.0	-5.95	3.588	0.00	203.8
901	0.0	-5.97	3.600	0.00	204.4
904	0.2	-5.99	3.612	0.04	205.2
907	0.0	-6.02	3.624	0.00	206.2
910	0.2	-6.04	3.636	0.04	206.8
913	0.0	-6.06	3.648	0.00	207.6
916	0.0	-6.08	3.660	0.00	208.2
919	0.0	-6.10	3.672	0.00	209.0
922	0.2	-6.12	3.684	0.04	209.6
925	0.2	-6.14	3.696	0.04	210.2
928	-0.2	-6.16	3.708	-0.04	211.0
931	0.0	-6.18	3.720	0.00	211.6
934	-0.2	-6.20	3.732	-0.04	212.4
937	0.0	-6.22	3.744	0.00	213.0
940	0.2	-6.25	3.756	0.04	214.0
943	-0.2	-6.26	3.768	-0.04	214.4
946	0.2	-6.29	3.780	0.04	215.4
949	0.0	-6.31	3.792	0.00	216.0
952	0.0	-6.33	3.804	0.00	216.8
955	0.0	-6.35	3.816	0.00	217.4
958	0.0	-6.37	3.828	0.00	218.2
961	-0.2	-6.39	3.840	-0.04	218.8
964	-0.2	-6.41	3.852	-0.04	219.6
967	-0.2	-6.43	3.864	-0.04	220.2
970	0.0	-6.45	3.876	0.00	220.8
973	0.0	-6.47	3.888	0.00	221.6
976	0.0	-6.49	3.900	0.00	222.2
979	0.2	-6.52	3.912	0.04	223.2
982	0.0	-6.54	3.924	0.00	224.0
985	0.0	-6.56	3.936	0.00	224.6
988	-0.2	-6.58	3.948	-0.04	225.4
991	0.0	-6.60	3.960	0.00	226.0
994	0.2	-6.62	3.972	0.04	226.8
997	0.2	-6.64	3.984	0.04	227.4
1000	-0.2	-6.66	3.996	-0.04	228.0
1003	-0.2	-6.68	4.008	-0.04	228.8
1006	0.0	-6.70	4.020	0.00	229.4
1009	0.0	-6.72	4.032	0.00	230.2
1012	0.0	-6.74	4.044	0.00	230.8
1015	0.0	-6.77	4.056	0.00	231.8
1018	0.0	-6.80	4.068	0.00	232.8
1021	0.0	-6.82	4.080	0.00	233.6
1024	0.0	-6.84	4.092	0.00	234.2
1027	0.0	-6.86	4.104	0.00	235.0
1030	0.0	-6.88	4.116	0.00	235.6
1033	0.0	-6.90	4.128	0.00	236.4
1036	0.2	-6.92	4.140	0.04	237.0
1039	0.0	-6.94	4.152	0.00	237.6
1042	0.0	-6.96	4.164	0.00	238.4
1045	-0.2	-6.98	4.176	-0.04	239.0
1048	0.0	-7.01	4.188	0.00	240.0
1051	0.2	-7.03	4.200	0.04	240.8
1054	0.0	-7.05	4.212	0.00	241.4
1057	0.0	-7.07	4.224	0.00	242.2
1060	0.2	-7.09	4.236	0.04	242.8
1063	0.0	-7.11	4.248	0.00	243.4
1066	0.2	-7.13	4.260	0.04	244.2
1069	-0.2	-7.15	4.272	-0.04	244.8
1072	0.2	-7.17	4.284	0.04	245.6
1075	0.0	-7.19	4.296	0.00	246.2
1078	0.0	-7.21	4.308	0.00	247.0
1081	0.0	-7.24	4.320	0.00	248.0
1084	0.0	-7.26	4.332	0.00	248.6
1087	0.0	-7.28	4.344	0.00	249.4
1090	0.0	-7.30	4.356	0.00	250.0
1093	0.0	-7.32	4.368	0.00	250.6
1096	0.2	-7.34	4.380	0.04	251.4
1099	0.0	-7.36	4.392	0.00	252.0
1102	-0.2	-7.38	4.404	-0.04	252.8
1105	0.0	-7.40	4.416	0.00	253.4
1108	0.0	-7.42	4.428	0.00	254.2
1111	-0.2	-7.44	4.440	-0.04	254.8
1114	0.0	-7.46	4.452	0.00	255.4
1117	0.2	-7.49	4.464	0.04	256.6
1120	0.2	-7.51	4.476	0.04	257.2
1123	0.0	-7.53	4.488	0.00	257.8
1126	-0.2	-7.55	4.500	-0.04	258.6
1129	0.2	-7.57	4.512	0.04	259.2
1132	-0.2	-7.59	4.524	-0.04	260.0
1135	0.0	-7.61	4.536	0.00	260.6
1138	0.0	-7.63	4.548	0.00	261.4
1141	0.0	-7.65	4.560	0.00	262.0
1144	0.0	-7.67	4.572	0.00	262.6
1147	0.0	-7.69	4.584	0.00	263.4
1150	0.0	-7.72	4.596	0.00	264.4
1153	0.2	-7.74	4.608	0.04	265.0
1156	-0.4	-7.76	4.620	-0.08	265.8
1159	-0.4	-7.78	4.632	-0.08	266.4
1162	0.2	-7.80	4.644	0.04	267.2
1165	0.0	-7.82	4.656	0.00	267.8
1168	0.0	-7.84	4.668	0.00	268.4
1171	-0.2	-7.86	4.680	-0.04	269.2
1174	-0.2	-7.88	4.692	-0.04	269.8
1177	-0.2	-7.91	4.704	-0.04	270.8
1180	0.0	-7.93	4.716	0.00	271.6
1183	0.2	-7.95	4.728	0.04	272.2
1186	-0.2	-7.97	4.740	-0.04	273.0
1189	0.0	-7.99	4.752	0.00	273.6
1192	-0.2	-8.01	4.764	-0.04	274.4
1195	0.0	-8.03	4.776	0.00	275.0
1198	0.0	-8.05	4.788	0.00	275.6
1201	0.0	-8.07	4.800	0.00	276.4
1204	0.0	-8.09	4.812	0.00	277.0
1207	0.2	-8.11	4.824	0.04	277.8
1210	-0.2	-8.14	4.836	-0.04	278.8
1213	-0.2	-8.16	4.848	-0.04	279.4
1216	0.0	-8.18	4.860	0.00	280.2
1219	-0.4	-8.20	4.872	-0.08	280.8
1222	0.2	-8.22	4.884	0.04	281.6
1225	0.2	-8.24	4.896	0.04	282.2
1228	0.0	-8.26	4.908	0.00	282.8
1231	0.0	-8.28	4.920	0.00	283.6
1234	0.0	-8.30	4.932	0.00	284.2
1237	0.0	-8.33	4.944	0.00	285.2
1240	0.0	-8.35	4.956	0.00	286.0
1243	0.2	-8.37	4.968	0.04	286.6
1246	0.0	-8.39	4.980	0.00	287.4
1249	0.2	-8.41	4.992	0.04	288.0
1252	-0.2	-8.43	5.004	-0.04	288.6
1255	0.0	-8.45	5.016	0.00	289.4
1258	0.0	-8.48	5.028	0.00	290.4
1261	0.2	-8.49	5.040	0.04	290.8
1264	0.0	-8.52	5.052	0.00	291.8
1267	0.0	-8.54	5.064	0.00	292.4
1270	0.0	-8.56	5.076	0.00	293.2
1273	-0.2	-8.58	5.088	-0.04	293.8
1276	0.2	-8.60	5.100	0.04	294.6
1279	-0.2	-8.62	5.112	-0.04	295.2
1282	0.0	-8.64	5.124	0.00	295.8
1285	0.0	-8.67	5.136	0.00	297.0
1288	0.0	-8.69	5.148	0.00	297.6
1291	0.2	-8.71	5.160	0.04	298.2
1294	0.0	-8.73	5.172	0.00	299.0
1297	0.2	-8.75	5.184	0.04	299.6
1300	-0.2	-8.77	5.196	-0.04	300.4
1303	0.0	-8.79	5.208	0.00	301.0
1306	-0.2	-8.81	5.220	-0.04	301.8
1309	0.0	-8.83	5.232	0.00	302.4
1312	0.2	-8.86	5.244	0.04	303.4
1315	0.0	-8.88	5.256	0.00	304.2
1318	0.0	-8.90	5.268	0.00	304.8
1321	-0.2	-8.92	5.280	-0.04	305.4
1324	0.0	-8.94	5.292	0.00	306.2
1327	0.0	-8.96	5.304	0.00	306.8
1330	0.0	-8.98	5.316	0.00	307.6
1333	-0.2	-9.00	5.328	-0.04	308.2
1336	0.0	-9.02	5.340	0.00	309.0
1339	0.0	-9.05	5.352	0.00	310.0
1342	0.2	-9.07	5.364	0.04	310.6
1345	0.0	-9.09	5.376	0.00	311.4
1348	-0.2	-9.11	5.388	-0.04	312.0
1351	0.4	-9.13	5.400	0.08	312.6
1354	0.0	-9.15	5.412	0.00	313.4
1357	0.0	-9.17	5.424	0.00	314.0
1360	0.2	-9.19	5.436	0.04	314.8
1363	0.2	-9.21	5.448	0.04	315.4
1366	-0.2	-9.24	5.460	-0.04	316.4
1369	-0.2	-9.26	5.472	-0.04	317.2
1372	-0.2	-9.28	5.484	-0.04	317.8
1375	0.0	-9.30	5.496	0.00	318.4
1378	0.0	-9.32	5.508	0.00	319.2
1381	0.0	-9.34	5.520	0.00	319.8
1384	0.0	-9.36	5.532	0.00	320.6
1387	0.0	-9.38	5.544	0.00	321.2
1390	0.0	-9.40	5.556	0.00	322.0
1393	0.2	-9.43	5.568	0.04	323.0
1396	0.0	-9.45	5.580	0.00	323.6
1399	0.0	-9.47	5.592	0.00	324.4
1402	0.2	-9.49	5.604	0.04	325.0
1405	0.2	-9.51	5.616	0.04	325.6
1408	0.0	-9.53	5.628	0.00	326.4
1411	0.0	-9.55	5.640	0.00	327.0
1414	0.0	-9.58	5.652	0.00	328.0
1417	0.0	-9.60	5.664	0.00	328.8
1420	-0.2	-9.62	5.676	-0.04	329.4
1423	0.0	-9.64	5.688	0.00	330.2
1426	-0.2	-9.66	5.700	-0.04	330.8
1429	0.0	-9.68	5.712	0.00	331.6
1432	0.0	-9.70	5.724	0.00	332.2
1435	0.0	-9.72	5.736	0.00	332.8
1438	0.0	-9.74	5.748	0.00	333.6
1441	0.2	-9.77	5.760	0.04	334.6
1444	0.0	-9.79	5.772	0.00	335.2
1447	-0.2	-9.80	5.784	-0.04	335.6
1450	0.0	-9.82	5.796	0.00	336.4
1453	0.0	-9.84	5.808	0.00	337.0
1456	0.2	-9.86	5.820	0.04	337.6
1459	0.2	-9.88	5.832	0.04	338.4
1462	0.2	-9.90	5.844	0.04	339.0
1465	0.0	-9.92	5.856	0.00	339.8
1468	-0.2	-9.94	5.868	-0.04	340.4
1471	0.2	-9.96	5.880	0.04	341.0
1474	0.0	-9.99	5.892	0.00	342.2
1477	0.2	-10.01	5.904	0.04	342.8
1480	0.0	-10.03	5.916	0.00	343.4
1483	-0.2	-10.05	5.928	-0.04	344.2
1486	0.2	-10.07	5.940	0.04	344.8
1489	0.0	-10.09	5.952	0.00	345.6
1492	0.2	-10.11	5.964	0.04	346.2
1495	0.0	-10.13	5.976	0.00	347.0
1498	0.0	-10.15	5.988	0.00	347.6
1501	0.0	-10.18	6.000	0.00	348.6
1504	-0.2	-10.20	6.012	-0.04	349.4
1507	0.0	-10.22	6.024	0.00	350.0
1510	0.2	-10.24	6.036	0.04	350.6
1513	-0.2	-10.26	6.048	-0.04	351.4
1516	0.0	-10.28	6.060	0.00	352.0
1519	-0.2	-10.30	6.072	-0.04	352.8
1522	0.0	-10.32	6.084	0.00	353.4
1525	-0.4	-10.34	6.096	-0.08	354.2
1528	0.0	-10.37	6.108	0.00	355.2
1531	0.0	-10.39	6.120	0.00	355.8
1534	-0.2	-10.41	6.132	-0.04	356.6
1537	0.0	-10.43	6.144	0.00	357.2
1540	-0.2	-10.45	6.156	-0.04	357.8
1543	-0.2	-10.47	6.168	-0.04	358.6
1546	0.0	-10.49	6.180	0.00	359.2
1549	-0.2	-10.51	6.192	-0.04	360.0
1552	0.0	-10.53	6.204	0.00	360.6
1555	-0.2	-10.55	6.216	-0.04	361.4
1558	0.0	-10.57	6.228	0.00	362.0
1561	0.0	-10.59	6.240	0.00	362.6
1564	0.0	-10.62	6.252	0.00	363.6
1567	0.2	-10.64	6.264	0.04	364.4
1570	0.0	-10.66	6.276	0.00	365.0
1573	-0.4	-10.68	6.288	-0.08	365.8
1576	0.0	-10.70	6.300	0.00	366.4
1579	0.0	-10.72	6.312	0.00	367.2
1582	0.0	-10.74	6.324	0.00	367.8
1585	-0.2	-10.76	6.336	-0.04	368.4
1588	0.2	-10.78	6.348	0.04	369.2
1591	0.0	-10.80	6.360	0.00	369.8
1594	0.4	-10.83	6.372	0.08	370.8
1597	0.0	-10.85	6.384	0.00	371.6
1600	0.0	-10.87	6.396	0.00	372.2
1603	0.0	-10.89	6.408	0.00	373.0
1606	0.0	-10.91	6.420	0.00	373.6
1609	-0.2	-10.93	6.432	-0.04	374.4
1612	-0.2	-10.95	6.444	-0.04	375.0
1615	0.2	-10.97	6.456	0.04	375.6
1618	0.0	-10.99	6.468	0.00	376.4
1621	0.0	-11.01	6.480	0.00	377.0
1624	-0.2	-11.03	6.492	-0.04	377.8
1627	-0.2	-11.05	6.504	-0.04	378.4
1630	0.0	-11.08	6.516	0.00	379.4
1633	0.2	-11.10	6.528	0.04	380.2
1636	-0.2	-11.12	6.540	-0.04	380.8
1639	0.0	-11.14	6.552	0.00	381.6
1642	0.0	-11.16	6.564	0.00	382.2
1645	0.0	-11.18	6.576	0.00	382.8
1648	0.0	-11.20	6.588	0.00	383.6
1651	0.0	-11.22	6.600	0.00	384.2
1654	0.0	-11.24	6.612	0.00	385.0
1657	0.2	-11.26	6.624	0.04	385.6
1660	0.0	-11.28	6.636	0.00	386.4
1663	0.4	-11.31	6.648	0.08	387.4
1666	0.4	-11.33	6.660	0.08	388.0
1669	0.0	-11.35	6.672	0.00	388.6
1672	0.0	-11.37	6.684	0.00	389.4
1675	0.0	-11.39	6.696	0.00	390.0
1678	-0.2	-11.41	6.708	-0.04	390.8
1681	0.0	-11.43	6.720	0.00	391.4
1684	0.0	-11.45	6.732	0.00	392.2
1687	0.0	-11.47	6.744	0.00	392.8
1690	-0.2	-11.49	6.756	-0.04	393.4
1693	0.0	-11.51	6.768	0.00	394.2
1696	0.0	-11.53	6.780	0.00	394.8
1699	0.0	-11.56	6.792	0.00	395.8
1702	0.0	-11.58	6.804	0.00	396.6
1705	0.2	-11.60	6.816	0.04	397.2
1708	0.0	-11.62	6.828	0.00	398.0
1711	0.0	-11.64	6.840	0.00	398.6
1714	-0.2	-11.66	6.852	-0.04	399.4
1717	0.0	-11.68	6.864	0.00	400.0
1720	0.0	-11.70	6.876	0.00	400.6
1723	0.2	-11.72	6.888	0.04	401.4
1726	-0.2	-11.74	6.900	-0.04	402.0
1729	0.0	-11.76	6.912	0.00	402.8
1732	0.0	-11.80	6.924	0.00	404.2
1735	0.0	-11.82	6.936	0.00	404.8
1738	-0.2	-11.84	6.948	-0.04	405.4
1741	0.0	-11.86	6.960	0.00	406.2
1744	0.0	-11.88	6.972	0.00	406.8
1747	-0.2	-11.90	6.984	-0.04	407.6
1750	0.0	-11.92	6.996	0.00	408.2
1753	0.0	-11.94	7.008	0.00	409.0
1756	-0.2	-11.96	7.020	-0.04	409.6
1759	-0.2	-11.98	7.032	-0.04	410.2
1762	0.0	-12.00	7.044	0.00	411.0
1765	0.2	-12.03	7.056	0.04	412.0
1768	0.0	-12.05	7.068	0.00	412.6
1771	0.0	-12.07	7.080	0.00	413.4
1774	-0.2	-12.09	7.092	-0.04	414.0
1777	0.2	-12.11	7.104	0.04	414.8
1780	0.0	-12.13	7.116	0.00	415.4
1783	0.0	-12.15	7.128	0.00	416.0
1786	0.0	-12.17	7.140	0.00	416.8
1789	0.2	-12.19	7.152	0.04	417.4
1792	0.0	-12.21	7.164	0.00	418.2
1795	0.0	-12.23	7.176	0.00	418.8
1798	0.0	-12.26	7.188	0.00	419.8
1801	0.0	-12.28	7.200	0.00	420.6
1804	-0.2	-12.30	7.212	-0.04	421.2
1807	0.0	-12.32	7.224	0.00	422.0
1810	0.0	-12.34	7.236	0.00	422.6
1813	0.2	-12.36	7.248	0.04	423.2
1816	0.0	-12.38	7.260	0.00	424.0
1819	0.0	-12.40	7.272	0.00	424.6
1822	0.0	-12.42	7.284	0.00	425.4
1825	0.2	-12.44	7.296	0.04	426.0
1828	-0.2	-12.46	7.308	-0.04	426.8
1831	0.2	-12.48	7.320	0.04	427.4
1834	-0.2	-12.51	7.332	-0.04	428.4
1837	-0.2	-12.53	7.344	-0.04	429.2
1840	-0.4	-12.55	7.356	-0.08	429.8
1843	0.0	-12.57	7.368	0.00	430.4
1846	0.0	-12.59	7.380	0.00	431.2
1849	0.0	-12.61	7.392	0.00	431.8
1852	0.0	-12.63	7.404	0.00	432.6
1855	-0.4	-12.65	7.416	-0.08	433.2
1858	0.0	-12.67	7.428	0.00	434.0
1861	-0.2	-12.69	7.440	-0.04	434.6
1864	0.0	-12.72	7.452	0.00	435.6
1867	0.0	-12.74	7.464	0.00	436.4
1870	0.2	-12.76	7.476	0.04	437.0
1873	0.0	-12.78	7.488	0.00	437.6
1876	0.2	-12.80	7.500	0.04	438.4
1879	0.0	-12.82	7.512	0.00	439.0
1882	0.0	-12.84	7.524	0.00	439.8
1885	0.0	-12.86	7.536	0.00	440.4
1888	0.0	-12.88	7.548	0.00	441.0
1891	0.2	-12.90	7.560	0.04	441.8
1894	0.0	-12.93	7.572	0.00	442.8
1897	-0.2	-12.95	7.584	-0.04	443.4
1900	0.0	-12.97	7.596	0.00	444.2
1903	-0.2	-12.99	7.608	-0.04	444.8
1906	0.0	-13.01	7.620	0.00	445.6
1909	0.0	-13.03	7.632	0.00	446.2
1912	0.2	-13.05	7.644	0.04	447.0
1915	-0.2	-13.07	7.656	-0.04	447.6
1918	0.0	-13.09	7.668	0.00	448.2
1921	0.0	-13.12	7.680	0.00	449.4
1924	0.0	-13.14	7.692	0.00	450.0
1927	0.0	-13.16	7.704	0.00	450.6
1930	-0.2	-13.18	7.716	-0.04	451.4
1933	0.0	-13.20	7.728	0.00	452.0
1936	0.0	-13.22	7.740	0.00	452.8
1939	0.0	-13.24	7.752	0.00	453.4
1942	0.0	-13.26	7.764	0.00	454.2
1945	0.0	-13.28	7.776	0.00	454.8
1948	0.0	-13.31	7.788	0.00	455.8
1951	0.0	-13.33	7.800	0.00	456.6
1954	0.0	-13.35	7.812	0.00	457.2
1957	-0.2	-13.37	7.824	-0.04	457.8
1960	0.0	-13.39	7.836	0.00	458.6
1963	0.0	-13.41	7.848	0.00	459.2
1966	0.2	-13.43	7.860	0.04	460.0
1969	0.0	-13.45	7.872	0.00	460.6
1972	0.2	-13.47	7.884	0.04	461.4
1975	-0.4	-13.50	7.896	-0.08	462.4
1978	0.0	-13.52	7.908	0.00	463.0
1981	-0.2	-13.54	7.920	-0.04	463.6
1984	0.0	-13.56	7.932	0.00	464.4
1987	0.0	-13.58	7.944	0.00	465.0
1990	-0.2	-13.60	7.956	-0.04	465.8
1993	0.2	-13.62	7.968	0.04	466.4
1996	0.2	-13.64	7.980	0.04	467.2
1999	0.0	-13.67	7.992	0.00	468.2
2002	0.0	-13.69	8.004	0.00	468.8
2005	0.0	-13.71	8.016	0.00	469.6
2008	0.0	-13.73	8.028	0.00	470.2
2011	-0.2	-13.75	8.040	-0.04	470.8
2014	0.0	-13.77	8.052	0.00	471.6
2017	0.0	-13.79	8.064	0.00	472.2
2020	0.2	-13.81	8.076	0.04	473.0
2023	0.2	-13.84	8.088	0.04	474.0
2026	0.0	-13.86	8.100	0.00	474.6
2029	-0.2	-13.88	8.112	-0.04	475.4
2032	0.0	-13.90	8.124	0.00	476.0
2035	0.0	-13.92	8.136	0.00	476.8
2038	0.0	-13.94	8.148	0.00	477.4
2041	0.0	-13.96	8.160	0.00	478.0
2044	0.0	-13.98	8.172	0.00	478.8
2047	0.0	-14.00	8.184	0.00	479.4
2050	0.2	-14.03	8.196	0.04	480.4
2053	0.0	-14.05	8.208	0.00	481.2
2056	0.0	-14.07	8.220	0.00	481.8
2059	0.0	-14.09	8.232	0.00	482.6
2062	0.0	-14.11	8.244	0.00	483.2
2065	0.0	-14.13	8.256	0.00	484.0
2068	0.0	-14.15	8.268	0.00	484.6
2071	-0.2	-14.17	8.280	-0.04	485.2
2074	-0.2	-14.19	8.292	-0.04	486.0
2077	0.2	-14.22	8.304	0.04	487.0
2080	0.0	-14.24	8.316	0.00	487.6
2083	0.0	-14.26	8.328	0.00	488.4
2086	0.0	-14.28	8.340	0.00	489.0
2089	0.0	-14.30	8.352	0.00	489.8
2092	0.0	-14.32	8.364	0.00	490.4
2095	0.0	-14.34	8.376	0.00	491.0
2098	0.0	-14.36	8.388	0.00	491.8
2101	-0.2	-14.38	8.400	-0.04	492.4
2104	-0.2	-14.41	8.412	-0.04	493.4
2107	0.0	-14.43	8.424	0.00	494.2
2110	0.0	-14.45	8.436	0.00	494.8
2113	0.0	-14.47	8.448	0.00	495.6
2116	0.0	-14.49	8.460	0.00	496.2
2119	0.0	-14.51	8.472	0.00	497.0
2122	0.0	-14.53	8.484	0.00	497.6
2125	0.0	-14.55	8.496	0.00	498.2
2128	0.2	-14.57	8.508	0.04	499.0
2131	0.0	-14.60	8.520	0.00	500.0
2134	0.2	-14.62	8.532	0.04	500.6
2137	0.0	-14.64	8.544	0.00	501.4
2140	0.0	-14.66	8.556	0.00	502.0
2143	0.0	-14.68	8.568	0.00	502.8
2146	0.0	-14.70	8.580	0.00	503.4
2149	0.0	-14.72	8.592	0.00	504.2
2152	0.0	-14.74	8.604	0.00	504.8
2155	0.0	-14.76	8.616	0.00	505.4
2158	0.0	-14.79	8.628	0.00	506.6
2161	0.0	-14.80	8.640	0.00	506.8
2164	0.0	-14.82	8.652	0.00	507.6
2167	0.0	-14.84	8.664	0.00	508.2
2170	0.0	-14.86	8.676	0.00	509.0
2173	0.0	-14.88	8.688	0.00	509.6
2176	0.2	-14.90	8.700	0.04	510.2
2179	0.0	-14.92	8.712	0.00	511.0
2182	0.2	-14.94	8.724	0.04	511.6
2185	0.2	-14.97	8.736	0.04	512.6
2188	0.2	-14.99	8.748	0.04	513.4
2191	0.0	-15.01	8.760	0.00	514.0
2194	0.0	-15.03	8.772	0.00	514.8
2197	0.2	-15.05	8.784	0.04	515.4
2200	0.0	-15.07	8.796	0.00	516.0
2203	0.0	-15.09	8.808	0.00	516.8
2206	0.0	-15.11	8.820	0.00	517.4
2209	0.0	-15.13	8.832	0.00	518.2
2212	-0.2	-15.16	8.844	-0.04	519.2
2215	0.2	-15.18	8.856	0.04	519.8
2218	0.0	-15.20	8.868	0.00	520.6
2221	0.0	-15.22	8.880	0.00	521.2
2224	0.0	-15.24	8.892	0.00	522.0
2227	0.0	-15.26	8.904	0.00	522.6
2230	0.0	-15.28	8.916	0.00	523.2
2233	0.0	-15.30	8.928	0.00	524.0
2236	0.0	-15.32	8.940	0.00	524.6
2239	0.0	-15.34	8.952	0.00	525.4
2242	0.0	-15.36	8.964	0.00	526.0
2245	0.0	-15.39	8.976	0.00	527.0
2248	0.0	-15.41	8.988	0.00	527.8
2251	0.0	-15.43	9.000	0.00	528.4
2254	0.0	-15.45	9.012	0.00	529.2
2257	0.0	-15.47	9.024	0.00	529.8
2260	0.0	-15.49	9.036	0.00	530.4
2263	0.2	-15.51	9.048	0.04	531.2
2266	0.0	-15.53	9.060	0.00	531.8
2269	0.4	-15.55	9.072	0.08	532.6
2272	0.2	-15.57	9.084	0.04	533.2
2275	0.0	-15.59	9.096	0.00	534.0
2278	-0.2	-15.62	9.108	-0.04	535.0
2281	-0.2	-15.64	9.120	-0.04	535.6
2284	0.0	-15.66	9.132	0.00	536.4
2287	-0.2	-15.68	9.144	-0.04	537.0
2290	0.0	-15.70	9.156	0.00	537.6
2293	0.0	-15.72	9.168	0.00	538.4
2296	-0.2	-15.74	9.180	-0.04	539.0
2299	0.0	-15.76	9.192	0.00	539.8
2302	0.0	-15.78	9.204	0.00	540.4
2305	0.0	-15.80	9.216	0.00	541.0
2308	-0.2	-15.82	9.228	-0.04	541.8
2311	0.0	-15.85	9.240	0.00	542.8
2314	0.0	-15.87	9.252	0.00	543.4
2317	0.0	-15.89	9.264	0.00	544.2
2320	0.0	-15.91	9.276	0.00	544.8
2323	-0.6	-15.93	9.288	-0.12	545.6
2326	0.0	-15.95	9.300	0.00	546.2
2329	0.0	-15.97	9.312	0.00	547.0
2332	0.0	-15.99	9.324	0.00	547.6
2335	0.0	-16.01	9.336	0.00	548.2
2338	0.4	-16.03	9.348	0.08	549.0
2341	0.0	-16.05	9.360	0.00	549.6
2344	0.0	-16.07	9.372	0.00	550.4
2347	0.0	-16.10	9.384	0.00	551.4
2350	0.0	-16.12	9.396	0.00	552.0
2353	0.2	-16.14	9.408	0.04	552.8
2356	-0.2	-16.16	9.420	-0.04	553.4
2359	0.2	-16.18	9.432	0.04	554.2
2362	0.0	-16.20	9.444	0.00	554.8
2365	0.0	-16.22	9.456	0.00	555.4
2368	0.0	-16.24	9.468	0.00	556.2
2371	-0.2	-16.26	9.480	-0.04	556.8
2374	-0.2	-16.28	9.492	-0.04	557.6
2377	0.0	-16.30	9.504	0.00	558.2
2380	0.0	-16.33	9.516	0.00	559.2
2383	0.2	-16.35	9.528	0.04	560.0
2386	0.0	-16.37	9.540	0.00	560.6
2389	0.0	-16.39	9.552	0.00	561.4
2392	0.0	-16.41	9.564	0.00	562.0
2395	0.0	-16.43	9.576	0.00	562.6
2398	0.2	-16.45	9.588	0.04	563.4
2401	0.0	-16.47	9.600	0.00	564.0
2404	-0.2	-16.49	9.612	-0.04	564.8
2407	-0.4	-16.51	9.624	-0.08	565.4
2410	0.0	-16.53	9.636	0.00	566.0
2413	0.0	-16.55	9.648	0.00	566.8
2416	0.0	-16.57	9.660	0.00	567.4
2419	0.2	-16.60	9.672	0.04	568.4
2422	0.0	-16.62	9.684	0.00	569.2
2425	0.0	-16.64	9.696	0.00	569.8
2428	0.0	-16.66	9.708	0.00	570.6
2431	0.0	-16.68	9.720	0.00	571.2
2434	0.0	-16.70	9.732	0.00	572.0
2437	-0.2	-16.72	9.744	-0.04	572.6
2440	0.0	-16.74	9.756	0.00	573.2
2443	-0.2	-16.76	9.768	-0.04	574.0
2446	0.0	-16.79	9.780	0.00	575.0
2449	-0.2	-16.81	9.792	-0.04	575.6
2452	-0.2	-16.83	9.804	-0.04	576.4
2455	0.2	-16.86	9.816	0.04	577.4
2458	0.0	-16.88	9.828	0.00	578.0
2461	0.0	-16.90	9.840	0.00	578.8
2464	0.0	-16.92	9.852	0.00	579.4
2467	0.0	-16.94	9.864	0.00	580.2
2470	-0.2	-16.96	9.876	-0.04	580.8
2473	0.4	-16.98	9.888	0.08	581.6
2476	0.0	-17.00	9.900	0.00	582.2
2479	0.2	-17.02	9.912	0.04	582.8
2482	0.0	-17.04	9.924	0.00	583.6
2485	0.0	-17.06	9.936	0.00	584.2
2488	0.0	-17.09	9.948	0.00	585.2
2491	0.0	-17.11	9.960	0.00	586.0
2494	0.0	-17.13	9.972	0.00	586.6
2497	0.2	-17.15	9.984	0.04	587.4
2500	0.0	-17.17	9.996	0.00	588.0
2503	-0.2	-17.19	10.008	-0.04	588.6
2506	0.0	-17.21	10.020	0.00	589.4
2509	-0.2	-17.23	10.032	-0.04	590.0
2512	0.0	-17.25	10.044	0.00	590.8
2515	0.0	-17.27	10.056	0.00	591.4
2518	-0.2	-17.29	10.068	-0.04	592.2
2521	0.0	-17.32	10.080	0.00	593.2
2524	0.4	-17.34	10.092	0.08	593.8
2527	0.0	-17.36	10.104	0.00	594.6
2530	0.0	-17.38	10.116	0.00	595.2
2533	0.0	-17.40	10.128	0.00	595.8
2536	-0.2	-17.42	10.140	-0.04	596.6
2539	0.2	-17.44	10.152	0.04	597.2
2542	0.0	-17.46	10.164	0.00	598.0
2545	0.0	-17.48	10.176	0.00	598.6
2548	0.2	-17.50	10.188	0.04	599.4
2551	-0.4	-17.52	10.200	-0.08	600.0
2554	-0.2	-17.54	10.212	-0.04	600.6
2557	-0.2	-17.57	10.224	-0.04	601.8
2560	0.0	-17.59	10.236	0.00	602.4
2563	0.0	-17.61	10.248	0.00	603.0
2566	0.0	-17.63	10.260	0.00	603.8
2569	0.0	-17.65	10.272	0.00	604.4
2572	0.2	-17.67	10.284	0.04	605.2
2575	0.0	-17.69	10.296	0.00	605.8
2578	0.0	-17.71	10.308	0.00	606.6
2581	0.0	-17.73	10.320	0.00	607.2
2584	0.0	-17.75	10.332	0.00	607.8
2587	0.0	-17.77	10.344	0.00	608.6
2590	-0.2	-17.80	10.356	-0.04	609.6
2593	0.2	-17.82	10.368	0.04	610.2
2596	0.2	-17.84	10.380	0.04	611.0
2599	0.2	-17.86	10.392	0.04	611.6
2602	0.0	-17.88	10.404	0.00	612.4
2605	-0.2	-17.90	10.416	-0.04	613.0
2608	-0.2	-17.92	10.428	-0.04	613.6
2611	0.0	-17.94	10.440	0.00	614.4
2614	0.0	-17.96	10.452	0.00	615.0
2617	-0.2	-17.99	10.464	-0.04	616.0
2620	0.2	-18.01	10.476	0.04	616.8
2623	0.2	-18.03	10.488	0.04	617.4
2626	0.2	-18.05	10.500	0.04	618.2
2629	0.0	-18.07	10.512	0.00	618.8
2632	0.0	-18.09	10.524	0.00	619.6
2635	0.0	-18.11	10.536	0.00	620.2
2638	0.0	-18.13	10.548	0.00	620.8
2641	0.2	-18.15	10.560	0.04	621.6
2644	0.0	-18.18	10.572	0.00	622.6
2647	0.0	-18.20	10.584	0.00	623.2
2650	0.2	-18.22	10.596	0.04	624.0
2653	0.2	-18.24	10.608	0.04	624.6
2656	-0.2	-18.26	10.620	-0.04	625.4
2659	0.2	-18.28	10.632	0.04	626.0
2662	0.0	-18.30	10.644	0.00	626.8
2665	0.0	-18.32	10.656	0.00	627.4
2668	0.0	-18.34	10.668	0.00	628.0
2671	0.0	-18.37	10.680	0.00	629.2
2674	0.6	-18.39	10.692	0.12	629.8
2677	0.0	-18.41	10.704	0.00	630.4
2680	-0.2	-18.43	10.716	-0.04	631.2
2683	0.0	-18.45	10.728	0.00	631.8
2686	-0.2	-18.47	10.740	-0.04	632.6
2689	-0.2	-18.49	10.752	-0.04	633.2
2692	-0.2	-18.51	10.764	-0.04	634.0
2695	-0.2	-18.53	10.776	-0.04	634.6
2698	0.0	-18.56	10.788	0.00	635.6
2701	0.2	-18.58	10.800	0.04	636.4
2704	0.2	-18.60	10.812	0.04	637.0
2707	-0.4	-18.62	10.824	-0.08	637.6
2710	-0.2	-18.64	10.836	-0.04	638.4
2713	0.0	-18.66	10.848	0.00	639.0
2716	0.2	-18.68	10.860	0.04	639.8
2719	-0.2	-18.70	10.872	-0.04	640.4
2722	0.0	-18.72	10.884	0.00	641.0
2725	0.2	-18.75	10.896	0.04	642.2
2728	0.0	-18.77	10.908	0.00	642.8
2731	-0.4	-18.79	10.920	-0.08	643.4
2734	0.2	-18.80	10.932	0.04	643.8
2737	0.0	-18.82	10.944	0.00	644.6
2740	0.2	-18.84	10.956	0.04	645.2
2743	0.0	-18.86	10.968	0.00	645.8
2746	0.0	-18.88	10.980	0.00	646.6
2749	0.0	-18.90	10.992	0.00	647.2
2752	0.0	-18.93	11.004	0.00	648.2
2755	0.2	-18.95	11.016	0.04	649.0
2758	0.0	-18.97	11.028	0.00	649.6
2761	0.0	-18.99	11.040	0.00	650.4
2764	-0.2	-19.01	11.052	-0.04	651.0
2767	0.0	-19.03	11.064	0.00	651.8
2770	0.0	-19.05	11.076	0.00	652.4
2773	0.0	-19.07	11.088	0.00	653.0
2776	-0.2	-19.09	11.100	-0.04	653.8
2779	-0.2	-19.12	11.112	-0.04	654.8
2782	0.0	-19.14	11.124	0.00	655.4
2785	-0.2	-19.16	11.136	-0.04	656.2
2788	-0.2	-19.18	11.148	-0.04	656.8
2791	0.2	-19.20	11.160	0.04	657.6
2794	0.6	-19.22	11.172	0.12	658.2
2797	1.4	-19.24	11.184	0.26	659.0
2800	3.4	-19.27	11.196	0.62	660.0
2803	5.8	-19.28	11.208	1.06	660.2
2806	9.2	-19.30	11.220	1.70	661.0
2809	13.8	-19.32	11.232	2.54	661.6
2812	23.2	-19.33	11.244	4.28	662.0
2815	38.2	-19.34	11.256	7.04	662.4
2818	51.6	-19.35	11.268	9.50	662.6
2821	56.2	-19.37	11.280	10.34	663.4
2824	64.0	-19.38	11.292	11.78	663.6
2827	71.2	-19.40	11.304	13.10	664.4
2830	76.0	-19.41	11.316	13.98	664.8
2833	79.8	-19.43	11.328	14.68	665.4
2836	81.2	-19.45	11.340	14.94	666.0
2839	79.6	-19.47	11.352	14.66	666.8
2842	79.6	-19.49	11.364	14.66	667.4
2845	79.4	-19.51	11.376	14.62	668.2
2848	78.4	-19.54	11.388	14.44	669.2
2851	77.2	-19.56	11.400	14.22	669.8
2854	76.4	-19.58	11.412	14.06	670.6
2857	74.8	-19.60	11.424	13.76	671.2
2860	72.8	-19.63	11.436	13.40	672.2
2863	71.6	-19.65	11.448	13.18	673.0
2866	70.0	-19.67	11.460	12.88	673.6
2869	68.4	-19.69	11.472	12.60	674.4
2872	66.6	-19.71	11.484	12.26	675.0
2875	66.0	-19.74	11.496	12.14	676.0
2878	65.6	-19.76	11.508	12.08	676.8
2881	64.2	-19.78	11.520	11.82	677.4
2884	61.2	-19.80	11.532	11.26	678.0
2887	59.4	-19.83	11.544	10.94	679.2
2890	60.0	-19.85	11.556	11.04	679.8
2893	61.0	-19.87	11.568	11.22	680.4
2896	62.2	-19.89	11.580	11.44	681.2
2899	62.2	-19.91	11.592	11.44	681.8
2902	62.8	-19.93	11.604	11.56	682.6
2905	63.6	-19.95	11.616	11.70	683.2
2908	65.4	-19.97	11.628	12.04	684.0
2911	66.6	-19.99	11.640	12.26	684.6
2914	67.4	-20.01	11.652	12.40	685.2
2917	67.6	-20.03	11.664	12.44	686.0
2920	66.6	-20.05	11.676	12.26	686.6
2923	66.6	-20.07	11.688	12.26	687.4
2926	65.4	-20.10	11.700	12.04	688.4
2929	65.0	-20.12	11.712	11.96	689.0
2932	64.2	-20.14	11.724	11.82	689.8
2935	63.6	-20.16	11.736	11.70	690.4
2938	62.8	-20.18	11.748	11.56	691.0
2941	62.2	-20.20	11.760	11.44	691.8
2944	61.6	-20.22	11.772	11.34	692.4
2947	60.8	-20.25	11.784	11.20	693.4
2950	59.4	-20.27	11.796	10.94	694.2
2953	56.8	-20.29	11.808	10.46	694.8
2956	55.0	-20.32	11.820	10.12	695.8
2959	53.6	-20.34	11.832	9.86	696.6
2962	53.4	-20.36	11.844	9.82	697.2
2965	52.8	-20.38	11.856	9.72	698.0
2968	52.2	-20.40	11.868	9.60	698.6
2971	51.6	-20.42	11.880	9.50	699.4
2974	51.8	-20.44	11.892	9.54	700.0
2977	51.4	-20.46	11.904	9.46	700.6
2980	51.2	-20.48	11.916	9.42	701.4
2983	51.8	-20.51	11.928	9.54	702.4
2986	52.0	-20.53	11.940	9.58	703.0
2989	52.8	-20.55	11.952	9.72	703.8
2992	53.8	-20.57	11.964	9.90	704.4
2995	54.6	-20.59	11.976	10.06	705.2
2998	55.8	-20.61	11.988	10.28	705.8
3001	57.0	-20.63	12.000	10.50	706.6
3004	58.0	-20.65	12.012	10.68	707.2
3007	58.4	-20.67	12.024	10.76	707.8
3010	59.4	-20.69	12.036	10.94	708.6
3013	59.8	-20.71	12.048	11.00	709.2
3016	61.0	-20.73	12.060	11.22	710.0
3019	55.4	-20.75	12.072	10.20	710.6
3022	40.4	-20.79	12.084	7.44	712.0
3025	38.4	-20.81	12.096	7.06	712.6
3028	37.8	-20.83	12.108	6.96	713.4
3031	36.8	-20.85	12.120	6.78	714.0
3034	36.6	-20.87	12.132	6.74	714.8
3037	37.2	-20.89	12.144	6.84	715.4
3040	37.4	-20.91	12.156	6.88	716.0
3043	37.8	-20.94	12.168	6.96	717.2
3046	37.2	-20.96	12.180	6.84	717.8
3049	37.0	-20.98	12.192	6.82	718.4
3052	37.0	-21.00	12.204	6.82	719.2
3055	37.0	-21.02	12.216	6.82	719.8
3058	36.6	-21.04	12.228	6.74	720.6
3061	36.2	-21.06	12.240	6.66	721.2
3064	36.6	-21.08	12.252	6.74	722.0
3067	36.8	-21.10	12.264	6.78	722.6
3070	37.2	-21.12	12.276	6.84	723.2
3073	38.0	-21.14	12.288	7.00	724.0
3076	35.6	-21.15	12.300	6.56	724.4
3079	33.2	-21.15	12.312	6.12	724.4
3082	31.8	-21.16	12.324	5.86	724.6
3085	31.4	-21.16	12.336	5.78	724.6
3088	30.6	-21.16	12.348	5.64	724.6
3091	30.4	-21.16	12.360	5.60	724.6