File: results/youngs-modulus/2025-04-21/inconclusive-data/pf19mt03.csv
sep=
pf19mt03

System Information:
IntelliMESUR Version: 2.2.1
Test Frame Model: F505
Test Frame Serial Number: 4418651
Test Frame Capacity: 500 lbF / 2.2 kN
Test Frame Firmware Version: 1.00.14
Force Sensor Model: FS05-100
Force Sensor Capacity: 500 N
Force Sensor Resolution: 0.2 N
Force Sensor Serial Number: 4425350
Calibration Date: Apr 29, 2024
Calibration Due Date: Apr 29, 2025

Reading	Load [N]	Distance [mm]	Time [s]	Stress [MPa]	Strain [%]
1	-0.2	0.00	0.000	-0.04	0.0
4	0.0	0.00	0.012	0.00	0.0
7	0.0	0.00	0.024	0.00	0.0
10	0.0	0.00	0.036	0.00	0.0
13	-0.2	0.00	0.048	-0.04	0.0
16	0.0	0.00	0.060	0.00	0.0
19	0.0	0.00	0.072	0.00	0.0
22	0.0	0.00	0.084	0.00	0.0
25	0.0	0.00	0.096	0.00	0.0
28	-0.2	0.00	0.108	-0.04	0.0
31	0.0	0.00	0.120	0.00	0.0
34	0.0	0.00	0.132	0.00	0.0
37	0.0	0.00	0.144	0.00	0.0
40	0.0	0.00	0.156	0.00	0.0
43	0.0	0.00	0.168	0.00	0.0
46	0.0	0.00	0.180	0.00	0.0
49	0.0	-0.01	0.192	0.00	0.4
52	0.0	-0.03	0.204	0.00	1.2
55	0.2	-0.06	0.216	0.04	2.2
58	0.0	-0.08	0.228	0.00	3.0
61	-0.2	-0.10	0.240	-0.04	3.6
64	0.0	-0.12	0.252	0.00	4.4
67	0.0	-0.14	0.264	0.00	5.2
70	-0.2	-0.16	0.276	-0.04	6.0
73	-0.2	-0.18	0.288	-0.04	6.6
76	0.2	-0.20	0.300	0.04	7.4
79	0.0	-0.22	0.312	0.00	8.2
82	0.0	-0.25	0.324	0.00	9.2
85	-0.2	-0.27	0.336	-0.04	10.0
88	0.0	-0.29	0.348	0.00	10.8
91	0.0	-0.31	0.360	0.00	11.4
94	0.0	-0.33	0.372	0.00	12.2
97	0.2	-0.35	0.384	0.04	13.0
100	0.0	-0.37	0.396	0.00	13.6
103	0.2	-0.39	0.408	0.04	14.4
106	-0.2	-0.41	0.420	-0.04	15.2
109	0.2	-0.43	0.432	0.04	15.8
112	0.4	-0.46	0.444	0.08	17.0
115	0.0	-0.48	0.456	0.00	17.8
118	0.0	-0.50	0.468	0.00	18.4
121	0.0	-0.52	0.480	0.00	19.2
124	0.0	-0.54	0.492	0.00	20.0
127	0.0	-0.56	0.504	0.00	20.6
130	0.0	-0.58	0.516	0.00	21.4
133	0.2	-0.60	0.528	0.04	22.2
136	0.2	-0.62	0.540	0.04	22.8
139	0.0	-0.64	0.552	0.00	23.6
142	0.2	-0.66	0.564	0.04	24.4
145	0.0	-0.69	0.576	0.00	25.4
148	-0.2	-0.71	0.588	-0.04	26.2
151	-0.2	-0.73	0.600	-0.04	27.0
154	0.0	-0.75	0.612	0.00	27.6
157	0.0	-0.77	0.624	0.00	28.4
160	0.2	-0.79	0.636	0.04	29.2
163	0.0	-0.81	0.648	0.00	29.8
166	0.0	-0.83	0.660	0.00	30.6
169	0.2	-0.85	0.672	0.04	31.4
172	0.0	-0.87	0.684	0.00	32.2
175	0.0	-0.89	0.696	0.00	32.8
178	0.0	-0.92	0.708	0.00	34.0
181	0.0	-0.95	0.720	0.00	35.0
184	-0.2	-0.97	0.732	-0.04	35.8
187	-0.2	-0.99	0.744	-0.04	36.6
190	0.0	-1.01	0.756	0.00	37.2
193	0.2	-1.03	0.768	0.04	38.0
196	0.2	-1.05	0.780	0.04	38.8
199	-0.4	-1.07	0.792	-0.08	39.4
202	0.2	-1.09	0.804	0.04	40.2
205	0.2	-1.11	0.816	0.04	41.0
208	0.0	-1.13	0.828	0.00	41.6
211	0.2	-1.16	0.840	0.04	42.8
214	0.0	-1.18	0.852	0.00	43.6
217	0.0	-1.20	0.864	0.00	44.2
220	0.0	-1.22	0.876	0.00	45.0
223	-0.2	-1.24	0.888	-0.04	45.8
226	0.0	-1.26	0.900	0.00	46.4
229	-0.2	-1.28	0.912	-0.04	47.2
232	-0.2	-1.30	0.924	-0.04	48.0
235	0.0	-1.32	0.936	0.00	48.8
238	0.0	-1.34	0.948	0.00	49.4
241	0.2	-1.36	0.960	0.04	50.2
244	0.2	-1.39	0.972	0.04	51.2
247	-0.2	-1.41	0.984	-0.04	52.0
250	0.0	-1.43	0.996	0.00	52.8
253	-0.6	-1.45	1.008	-0.12	53.6
256	0.0	-1.47	1.020	0.00	54.2
259	-0.4	-1.49	1.032	-0.08	55.0
262	0.0	-1.51	1.044	0.00	55.8
265	0.0	-1.53	1.056	0.00	56.4
268	0.0	-1.55	1.068	0.00	57.2
271	0.0	-1.57	1.080	0.00	58.0
274	0.0	-1.59	1.092	0.00	58.6
277	0.0	-1.61	1.104	0.00	59.4
280	0.2	-1.64	1.116	0.04	60.6
283	0.2	-1.66	1.128	0.04	61.2
286	0.0	-1.68	1.140	0.00	62.0
289	0.0	-1.70	1.152	0.00	62.8
292	0.0	-1.72	1.164	0.00	63.4
295	-0.2	-1.74	1.176	-0.04	64.2
298	0.2	-1.76	1.188	0.04	65.0
301	0.0	-1.78	1.200	0.00	65.6
304	0.0	-1.80	1.212	0.00	66.4
307	0.0	-1.82	1.224	0.00	67.2
310	0.0	-1.84	1.236	0.00	67.8
313	-0.2	-1.87	1.248	-0.04	69.0
316	0.0	-1.89	1.260	0.00	69.8
319	0.0	-1.91	1.272	0.00	70.4
322	0.0	-1.93	1.284	0.00	71.2
325	0.0	-1.94	1.296	0.00	71.6
328	-0.2	-1.96	1.308	-0.04	72.4
331	0.0	-1.98	1.320	0.00	73.0
334	0.0	-2.00	1.332	0.00	73.8
337	0.0	-2.02	1.344	0.00	74.6
340	0.0	-2.04	1.356	0.00	75.2
343	0.0	-2.06	1.368	0.00	76.0
346	0.2	-2.09	1.380	0.04	77.2
349	-0.2	-2.11	1.392	-0.04	77.8
352	0.0	-2.13	1.404	0.00	78.6
355	0.0	-2.15	1.416	0.00	79.4
358	0.0	-2.17	1.428	0.00	80.0
361	0.0	-2.19	1.440	0.00	80.8
364	-0.2	-2.21	1.452	-0.04	81.6
367	0.0	-2.23	1.464	0.00	82.2
370	0.2	-2.25	1.476	0.04	83.0
373	0.0	-2.27	1.488	0.00	83.8
376	-0.2	-2.29	1.500	-0.04	84.6
379	0.0	-2.31	1.512	0.00	85.2
382	0.0	-2.34	1.524	0.00	86.4
385	0.0	-2.36	1.536	0.00	87.0
388	0.0	-2.38	1.548	0.00	87.8
391	0.0	-2.40	1.560	0.00	88.6
394	0.0	-2.42	1.572	0.00	89.2
397	0.0	-2.44	1.584	0.00	90.0
400	0.0	-2.46	1.596	0.00	90.8
403	0.0	-2.48	1.608	0.00	91.6
406	0.0	-2.50	1.620	0.00	92.2
409	0.0	-2.52	1.632	0.00	93.0
412	0.2	-2.54	1.644	0.04	93.8
415	0.2	-2.57	1.656	0.04	94.8
418	0.2	-2.59	1.668	0.04	95.6
421	-0.2	-2.61	1.680	-0.04	96.4
424	-0.4	-2.63	1.692	-0.08	97.0
427	0.0	-2.65	1.704	0.00	97.8
430	0.0	-2.67	1.716	0.00	98.6
433	0.0	-2.69	1.728	0.00	99.2
436	0.0	-2.71	1.740	0.00	100.0
439	0.0	-2.73	1.752	0.00	100.8
442	0.2	-2.75	1.764	0.04	101.4
445	0.0	-2.77	1.776	0.00	102.2
448	0.0	-2.80	1.788	0.00	103.4
451	0.0	-2.82	1.800	0.00	104.0
454	0.2	-2.84	1.812	0.04	104.8
457	0.2	-2.86	1.824	0.04	105.6
460	0.2	-2.88	1.836	0.04	106.2
463	0.0	-2.90	1.848	0.00	107.0
466	0.0	-2.92	1.860	0.00	107.8
469	0.0	-2.95	1.872	0.00	108.8
472	0.0	-2.97	1.884	0.00	109.6
475	0.0	-3.00	1.896	0.00	110.8
478	0.2	-3.02	1.908	0.04	111.4
481	0.0	-3.04	1.920	0.00	112.2
484	0.0	-3.06	1.932	0.00	113.0
487	-0.2	-3.08	1.944	-0.04	113.6
490	0.0	-3.10	1.956	0.00	114.4
493	0.2	-3.12	1.968	0.04	115.2
496	0.0	-3.14	1.980	0.00	115.8
499	0.2	-3.16	1.992	0.04	116.6
502	-0.2	-3.19	2.004	-0.04	117.8
505	-0.2	-3.21	2.016	-0.04	118.4
508	0.2	-3.23	2.028	0.04	119.2
511	0.0	-3.25	2.040	0.00	120.0
514	-0.2	-3.27	2.052	-0.04	120.6
517	0.0	-3.29	2.064	0.00	121.4
520	0.2	-3.31	2.076	0.04	122.2
523	0.0	-3.33	2.088	0.00	122.8
526	0.0	-3.35	2.100	0.00	123.6
529	-0.2	-3.37	2.112	-0.04	124.4
532	-0.2	-3.39	2.124	-0.04	125.0
535	-0.2	-3.42	2.136	-0.04	126.2
538	0.2	-3.44	2.148	0.04	127.0
541	0.0	-3.46	2.160	0.00	127.6
544	0.2	-3.48	2.172	0.04	128.4
547	0.2	-3.50	2.184	0.04	129.2
550	0.0	-3.52	2.196	0.00	129.8
553	0.0	-3.54	2.208	0.00	130.6
556	0.2	-3.56	2.220	0.04	131.4
559	0.0	-3.58	2.232	0.00	132.2
562	0.0	-3.61	2.244	0.00	133.2
565	0.0	-3.63	2.256	0.00	134.0
568	-0.2	-3.65	2.268	-0.04	134.6
571	0.0	-3.67	2.280	0.00	135.4
574	0.0	-3.69	2.292	0.00	136.2
577	0.0	-3.71	2.304	0.00	137.0
580	-0.4	-3.73	2.316	-0.08	137.6
583	-0.2	-3.76	2.328	-0.04	138.8
586	0.0	-3.78	2.340	0.00	139.4
589	-0.4	-3.80	2.352	-0.08	140.2
592	0.0	-3.82	2.364	0.00	141.0
595	0.0	-3.84	2.376	0.00	141.6
598	0.0	-3.86	2.388	0.00	142.4
601	0.4	-3.88	2.400	0.08	143.2
604	-0.2	-3.90	2.412	-0.04	144.0
607	0.0	-3.92	2.424	0.00	144.6
610	0.0	-3.95	2.436	0.00	145.8
613	0.0	-3.97	2.448	0.00	146.4
616	0.0	-3.99	2.460	0.00	147.2
619	0.2	-4.01	2.472	0.04	148.0
622	0.0	-4.03	2.484	0.00	148.8
625	0.0	-4.05	2.496	0.00	149.4
628	0.0	-4.07	2.508	0.00	150.2
631	-0.2	-4.09	2.520	-0.04	151.0
634	0.2	-4.11	2.532	0.04	151.6
637	0.0	-4.14	2.544	0.00	152.8
640	0.2	-4.16	2.556	0.04	153.6
643	0.2	-4.18	2.568	0.04	154.2
646	-0.2	-4.20	2.580	-0.04	155.0
649	0.0	-4.22	2.592	0.00	155.8
652	0.0	-4.24	2.604	0.00	156.4
655	0.0	-4.26	2.616	0.00	157.2
658	0.0	-4.28	2.628	0.00	158.0
661	0.0	-4.30	2.640	0.00	158.6
664	-0.2	-4.33	2.652	-0.04	159.8
667	0.0	-4.35	2.664	0.00	160.6
670	0.0	-4.37	2.676	0.00	161.2
673	0.2	-4.39	2.688	0.04	162.0
676	0.2	-4.41	2.700	0.04	162.8
679	0.0	-4.43	2.712	0.00	163.4
682	0.0	-4.45	2.724	0.00	164.2
685	-0.2	-4.47	2.736	-0.04	165.0
688	0.0	-4.49	2.748	0.00	165.6
691	0.0	-4.52	2.760	0.00	166.8
694	0.0	-4.54	2.772	0.00	167.6
697	0.0	-4.56	2.784	0.00	168.2
700	0.0	-4.58	2.796	0.00	169.0
703	0.2	-4.60	2.808	0.04	169.8
706	0.0	-4.62	2.820	0.00	170.4
709	-0.2	-4.64	2.832	-0.04	171.2
712	0.0	-4.66	2.844	0.00	172.0
715	0.0	-4.68	2.856	0.00	172.6
718	0.0	-4.71	2.868	0.00	173.8
721	0.0	-4.73	2.880	0.00	174.6
724	0.0	-4.75	2.892	0.00	175.2
727	0.0	-4.77	2.904	0.00	176.0
730	0.0	-4.79	2.916	0.00	176.8
733	0.0	-4.81	2.928	0.00	177.4
736	0.0	-4.83	2.940	0.00	178.2
739	0.0	-4.85	2.952	0.00	179.0
742	0.0	-4.87	2.964	0.00	179.8
745	0.0	-4.90	2.976	0.00	180.8
748	0.0	-4.92	2.988	0.00	181.6
751	0.0	-4.94	3.000	0.00	182.2
754	0.0	-4.96	3.012	0.00	183.0
757	0.0	-4.98	3.024	0.00	183.8
760	0.0	-5.00	3.036	0.00	184.6
763	-0.2	-5.02	3.048	-0.04	185.2
766	0.0	-5.04	3.060	0.00	186.0
769	0.0	-5.06	3.072	0.00	186.8
772	0.0	-5.09	3.084	0.00	187.8
775	0.0	-5.11	3.096	0.00	188.6
778	0.0	-5.13	3.108	0.00	189.2
781	0.0	-5.15	3.120	0.00	190.0
784	0.0	-5.17	3.132	0.00	190.8
787	-0.2	-5.19	3.144	-0.04	191.6
790	0.2	-5.21	3.156	0.04	192.2
793	0.0	-5.23	3.168	0.00	193.0
796	0.0	-5.25	3.180	0.00	193.8
799	0.2	-5.28	3.192	0.04	194.8
802	0.0	-5.30	3.204	0.00	195.6
805	0.2	-5.32	3.216	0.04	196.4
808	0.0	-5.34	3.228	0.00	197.0
811	-0.2	-5.36	3.240	-0.04	197.8
814	0.0	-5.38	3.252	0.00	198.6
817	0.0	-5.40	3.264	0.00	199.2
820	0.0	-5.42	3.276	0.00	200.0
823	0.2	-5.44	3.288	0.04	200.8
826	0.0	-5.46	3.300	0.00	201.4
829	-0.2	-5.48	3.312	-0.04	202.2
832	-0.2	-5.51	3.324	-0.04	203.4
835	0.0	-5.53	3.336	0.00	204.0
838	0.0	-5.55	3.348	0.00	204.8
841	0.0	-5.57	3.360	0.00	205.6
844	0.0	-5.59	3.372	0.00	206.2
847	0.0	-5.61	3.384	0.00	207.0
850	0.0	-5.63	3.396	0.00	207.8
853	0.0	-5.65	3.408	0.00	208.4
856	0.0	-5.67	3.420	0.00	209.2
859	0.2	-5.69	3.432	0.04	210.0
862	0.0	-5.71	3.444	0.00	210.8
865	-0.2	-5.73	3.456	-0.04	211.4
868	0.0	-5.76	3.468	0.00	212.6
871	0.0	-5.78	3.480	0.00	213.2
874	-0.2	-5.80	3.492	-0.04	214.0
877	0.0	-5.82	3.504	0.00	214.8
880	0.2	-5.84	3.516	0.04	215.4
883	0.0	-5.86	3.528	0.00	216.2
886	0.0	-5.88	3.540	0.00	217.0
889	-0.4	-5.90	3.552	-0.08	217.8
892	0.0	-5.92	3.564	0.00	218.4
895	-0.2	-5.93	3.576	-0.04	218.8
898	-0.2	-5.95	3.588	-0.04	219.6
901	0.0	-5.98	3.600	0.00	220.6
904	0.0	-6.00	3.612	0.00	221.4
907	0.0	-6.02	3.624	0.00	222.2
910	0.0	-6.04	3.636	0.00	222.8
913	0.0	-6.06	3.648	0.00	223.6
916	0.0	-6.08	3.660	0.00	224.4
919	0.0	-6.10	3.672	0.00	225.0
922	0.0	-6.12	3.684	0.00	225.8
925	0.0	-6.14	3.696	0.00	226.6
928	0.0	-6.16	3.708	0.00	227.4
931	-0.2	-6.18	3.720	-0.04	228.0
934	0.2	-6.21	3.732	0.04	229.2
937	0.0	-6.23	3.744	0.00	229.8
940	0.4	-6.25	3.756	0.08	230.6
943	0.2	-6.27	3.768	0.04	231.4
946	0.0	-6.29	3.780	0.00	232.2
949	0.4	-6.31	3.792	0.08	232.8
952	0.0	-6.33	3.804	0.00	233.6
955	0.0	-6.35	3.816	0.00	234.4
958	0.0	-6.37	3.828	0.00	235.0
961	0.2	-6.39	3.840	0.04	235.8
964	0.0	-6.41	3.852	0.00	236.6
967	0.0	-6.43	3.864	0.00	237.2
970	0.4	-6.46	3.876	0.08	238.4
973	0.0	-6.48	3.888	0.00	239.2
976	-0.2	-6.50	3.900	-0.04	239.8
979	0.2	-6.52	3.912	0.04	240.6
982	0.0	-6.54	3.924	0.00	241.4
985	-0.2	-6.56	3.936	-0.04	242.0
988	0.0	-6.58	3.948	0.00	242.8
991	0.0	-6.60	3.960	0.00	243.6
994	0.0	-6.62	3.972	0.00	244.2
997	-0.2	-6.64	3.984	-0.04	245.0
1000	0.0	-6.66	3.996	0.00	245.8
1003	-0.2	-6.68	4.008	-0.04	246.4
1006	0.0	-6.70	4.020	0.00	247.2
1009	0.0	-6.73	4.032	0.00	248.4
1012	0.0	-6.75	4.044	0.00	249.0
1015	0.0	-6.77	4.056	0.00	249.8
1018	0.0	-6.79	4.068	0.00	250.6
1021	0.0	-6.81	4.080	0.00	251.2
1024	0.0	-6.83	4.092	0.00	252.0
1027	0.2	-6.85	4.104	0.04	252.8
1030	0.0	-6.87	4.116	0.00	253.6
1033	0.0	-6.89	4.128	0.00	254.2
1036	0.0	-6.91	4.140	0.00	255.0
1039	-0.2	-6.94	4.152	-0.04	256.0
1042	0.0	-6.97	4.164	0.00	257.2
1045	0.0	-6.99	4.176	0.00	258.0
1048	0.2	-7.01	4.188	0.04	258.6
1051	0.0	-7.03	4.200	0.00	259.4
1054	0.0	-7.05	4.212	0.00	260.2
1057	0.0	-7.07	4.224	0.00	260.8
1060	0.0	-7.09	4.236	0.00	261.6
1063	0.0	-7.11	4.248	0.00	262.4
1066	0.0	-7.13	4.260	0.00	263.0
1069	-0.2	-7.15	4.272	-0.04	263.8
1072	-0.2	-7.17	4.284	-0.04	264.6
1075	0.0	-7.19	4.296	0.00	265.4
1078	0.0	-7.22	4.308	0.00	266.4
1081	0.0	-7.24	4.320	0.00	267.2
1084	-0.2	-7.26	4.332	-0.04	267.8
1087	0.0	-7.28	4.344	0.00	268.6
1090	0.0	-7.30	4.356	0.00	269.4
1093	0.2	-7.32	4.368	0.04	270.2
1096	0.2	-7.34	4.380	0.04	270.8
1099	0.0	-7.36	4.392	0.00	271.6
1102	0.2	-7.38	4.404	0.04	272.4
1105	0.0	-7.40	4.416	0.00	273.0
1108	0.0	-7.42	4.428	0.00	273.8
1111	-0.2	-7.45	4.440	-0.04	275.0
1114	0.0	-7.47	4.452	0.00	275.6
1117	-0.2	-7.49	4.464	-0.04	276.4
1120	0.0	-7.51	4.476	0.00	277.2
1123	0.0	-7.53	4.488	0.00	277.8
1126	-0.4	-7.55	4.500	-0.08	278.6
1129	-0.4	-7.57	4.512	-0.08	279.4
1132	0.2	-7.59	4.524	0.04	280.0
1135	0.0	-7.61	4.536	0.00	280.8
1138	0.0	-7.63	4.548	0.00	281.6
1141	0.0	-7.65	4.560	0.00	282.2
1144	0.0	-7.68	4.572	0.00	283.4
1147	0.0	-7.70	4.584	0.00	284.2
1150	-0.2	-7.72	4.596	-0.04	284.8
1153	0.0	-7.74	4.608	0.00	285.6
1156	0.0	-7.76	4.620	0.00	286.4
1159	0.0	-7.78	4.632	0.00	287.0
1162	0.0	-7.80	4.644	0.00	287.8
1165	0.4	-7.82	4.656	0.08	288.6
1168	0.0	-7.84	4.668	0.00	289.2
1171	0.0	-7.86	4.680	0.00	290.0
1174	0.0	-7.88	4.692	0.00	290.8
1177	0.0	-7.91	4.704	0.00	291.8
1180	-0.2	-7.93	4.716	-0.04	292.6
1183	-0.2	-7.95	4.728	-0.04	293.4
1186	0.0	-7.97	4.740	0.00	294.0
1189	0.0	-7.99	4.752	0.00	294.8
1192	0.0	-8.01	4.764	0.00	295.6
1195	0.0	-8.03	4.776	0.00	296.4
1198	0.0	-8.05	4.788	0.00	297.0
1201	0.0	-8.07	4.800	0.00	297.8
1204	0.2	-8.10	4.812	0.04	298.8
1207	0.0	-8.12	4.824	0.00	299.6
1210	0.0	-8.14	4.836	0.00	300.4
1213	0.0	-8.16	4.848	0.00	301.2
1216	0.0	-8.18	4.860	0.00	301.8
1219	-0.2	-8.20	4.872	-0.04	302.6
1222	-0.2	-8.22	4.884	-0.04	303.4
1225	0.0	-8.24	4.896	0.00	304.0
1228	-0.2	-8.26	4.908	-0.04	304.8
1231	-0.2	-8.28	4.920	-0.04	305.6
1234	0.0	-8.31	4.932	0.00	306.6
1237	0.0	-8.33	4.944	0.00	307.4
1240	0.2	-8.35	4.956	0.04	308.2
1243	0.0	-8.37	4.968	0.00	308.8
1246	-0.2	-8.39	4.980	-0.04	309.6
1249	0.0	-8.41	4.992	0.00	310.4
1252	0.2	-8.43	5.004	0.04	311.0
1255	-0.6	-8.45	5.016	-0.12	311.8
1258	0.2	-8.47	5.028	0.04	312.6
1261	0.2	-8.50	5.040	0.04	313.6
1264	0.0	-8.52	5.052	0.00	314.4
1267	0.0	-8.54	5.064	0.00	315.2
1270	0.0	-8.56	5.076	0.00	315.8
1273	0.0	-8.58	5.088	0.00	316.6
1276	0.0	-8.60	5.100	0.00	317.4
1279	0.2	-8.62	5.112	0.04	318.0
1282	0.0	-8.64	5.124	0.00	318.8
1285	0.0	-8.66	5.136	0.00	319.6
1288	0.0	-8.69	5.148	0.00	320.6
1291	0.0	-8.71	5.160	0.00	321.4
1294	0.0	-8.73	5.172	0.00	322.2
1297	0.0	-8.75	5.184	0.00	322.8
1300	-0.2	-8.77	5.196	-0.04	323.6
1303	0.0	-8.79	5.208	0.00	324.4
1306	0.0	-8.81	5.220	0.00	325.0
1309	0.0	-8.83	5.232	0.00	325.8
1312	0.0	-8.86	5.244	0.00	327.0
1315	-0.2	-8.88	5.256	-0.04	327.6
1318	0.2	-8.90	5.268	0.04	328.4
1321	0.0	-8.92	5.280	0.00	329.2
1324	0.0	-8.94	5.292	0.00	329.8
1327	0.0	-8.96	5.304	0.00	330.6
1330	0.0	-8.98	5.316	0.00	331.4
1333	0.2	-9.00	5.328	0.04	332.2
1336	0.0	-9.02	5.340	0.00	332.8
1339	-0.2	-9.05	5.352	-0.04	334.0
1342	0.0	-9.07	5.364	0.00	334.6
1345	0.2	-9.09	5.376	0.04	335.4
1348	0.0	-9.11	5.388	0.00	336.2
1351	0.0	-9.13	5.400	0.00	337.0
1354	-0.2	-9.15	5.412	-0.04	337.6
1357	-0.4	-9.17	5.424	-0.08	338.4
1360	0.0	-9.19	5.436	0.00	339.2
1363	0.0	-9.21	5.448	0.00	339.8
1366	0.4	-9.24	5.460	0.08	341.0
1369	0.0	-9.26	5.472	0.00	341.6
1372	-0.2	-9.28	5.484	-0.04	342.4
1375	0.0	-9.30	5.496	0.00	343.2
1378	0.0	-9.32	5.508	0.00	344.0
1381	0.0	-9.34	5.520	0.00	344.6
1384	-0.2	-9.36	5.532	-0.04	345.4
1387	0.0	-9.38	5.544	0.00	346.2
1390	0.0	-9.41	5.556	0.00	347.2
1393	0.0	-9.43	5.568	0.00	348.0
1396	0.0	-9.45	5.580	0.00	348.8
1399	0.2	-9.47	5.592	0.04	349.4
1402	-0.2	-9.49	5.604	-0.04	350.2
1405	0.0	-9.51	5.616	0.00	351.0
1408	0.0	-9.53	5.628	0.00	351.6
1411	0.2	-9.55	5.640	0.04	352.4
1414	0.0	-9.58	5.652	0.00	353.6
1417	-0.2	-9.60	5.664	-0.04	354.2
1420	0.0	-9.62	5.676	0.00	355.0
1423	-0.2	-9.64	5.688	-0.04	355.8
1426	0.0	-9.66	5.700	0.00	356.4
1429	0.0	-9.68	5.712	0.00	357.2
1432	0.2	-9.70	5.724	0.04	358.0
1435	-0.2	-9.72	5.736	-0.04	358.6
1438	-0.4	-9.74	5.748	-0.08	359.4
1441	0.0	-9.77	5.760	0.00	360.6
1444	0.0	-9.79	5.772	0.00	361.2
1447	0.0	-9.81	5.784	0.00	362.0
1450	0.0	-9.83	5.796	0.00	362.8
1453	0.0	-9.85	5.808	0.00	363.4
1456	0.0	-9.87	5.820	0.00	364.2
1459	0.0	-9.89	5.832	0.00	365.0
1462	0.2	-9.91	5.844	0.04	365.6
1465	0.0	-9.93	5.856	0.00	366.4
1468	0.2	-9.95	5.868	0.04	367.2
1471	0.0	-9.97	5.880	0.00	367.8
1474	0.2	-9.99	5.892	0.04	368.6
1477	-0.2	-10.01	5.904	-0.04	369.4
1480	-0.2	-10.03	5.916	-0.04	370.2
1483	0.0	-10.05	5.928	0.00	370.8
1486	0.0	-10.07	5.940	0.00	371.6
1489	0.2	-10.09	5.952	0.04	372.4
1492	-0.2	-10.11	5.964	-0.04	373.0
1495	0.2	-10.13	5.976	0.04	373.8
1498	0.0	-10.16	5.988	0.00	375.0
1501	0.0	-10.18	6.000	0.00	375.6
1504	-0.2	-10.20	6.012	-0.04	376.4
1507	0.0	-10.22	6.024	0.00	377.2
1510	-0.2	-10.24	6.036	-0.04	377.8
1513	0.0	-10.26	6.048	0.00	378.6
1516	0.0	-10.28	6.060	0.00	379.4
1519	-0.2	-10.30	6.072	-0.04	380.0
1522	0.0	-10.32	6.084	0.00	380.8
1525	0.2	-10.35	6.096	0.04	382.0
1528	0.0	-10.37	6.108	0.00	382.6
1531	-0.2	-10.39	6.120	-0.04	383.4
1534	0.0	-10.41	6.132	0.00	384.2
1537	0.0	-10.43	6.144	0.00	384.8
1540	0.0	-10.45	6.156	0.00	385.6
1543	0.6	-10.47	6.168	0.12	386.4
1546	0.0	-10.49	6.180	0.00	387.0
1549	0.0	-10.51	6.192	0.00	387.8
1552	0.0	-10.53	6.204	0.00	388.6
1555	0.0	-10.55	6.216	0.00	389.2
1558	-0.2	-10.58	6.228	-0.04	390.4
1561	0.0	-10.60	6.240	0.00	391.2
1564	0.0	-10.62	6.252	0.00	391.8
1567	0.0	-10.64	6.264	0.00	392.6
1570	-0.4	-10.66	6.276	-0.08	393.4
1573	0.0	-10.68	6.288	0.00	394.0
1576	0.0	-10.70	6.300	0.00	394.8
1579	0.0	-10.72	6.312	0.00	395.6
1582	0.2	-10.74	6.324	0.04	396.4
1585	0.0	-10.76	6.336	0.00	397.0
1588	-0.2	-10.78	6.348	-0.04	397.8
1591	0.0	-10.81	6.360	0.00	398.8
1594	0.0	-10.83	6.372	0.00	399.6
1597	0.0	-10.85	6.384	0.00	400.4
1600	0.0	-10.87	6.396	0.00	401.2
1603	0.2	-10.89	6.408	0.04	401.8
1606	0.0	-10.91	6.420	0.00	402.6
1609	0.0	-10.93	6.432	0.00	403.4
1612	0.0	-10.95	6.444	0.00	404.0
1615	0.2	-10.97	6.456	0.04	404.8
1618	0.0	-10.99	6.468	0.00	405.6
1621	0.0	-11.01	6.480	0.00	406.2
1624	0.0	-11.04	6.492	0.00	407.4
1627	0.0	-11.06	6.504	0.00	408.2
1630	0.0	-11.08	6.516	0.00	408.8
1633	0.0	-11.10	6.528	0.00	409.6
1636	0.0	-11.12	6.540	0.00	410.4
1639	-0.2	-11.14	6.552	-0.04	411.0
1642	0.0	-11.16	6.564	0.00	411.8
1645	-0.2	-11.18	6.576	-0.04	412.6
1648	0.0	-11.20	6.588	0.00	413.2
1651	0.0	-11.22	6.600	0.00	414.0
1654	-0.4	-11.24	6.612	-0.08	414.8
1657	0.0	-11.27	6.624	0.00	415.8
1660	0.0	-11.29	6.636	0.00	416.6
1663	0.0	-11.31	6.648	0.00	417.4
1666	0.0	-11.33	6.660	0.00	418.0
1669	-0.2	-11.35	6.672	-0.04	418.8
1672	0.0	-11.37	6.684	0.00	419.6
1675	0.2	-11.39	6.696	0.04	420.2
1678	0.2	-11.41	6.708	0.04	421.0
1681	0.0	-11.43	6.720	0.00	421.8
1684	0.0	-11.45	6.732	0.00	422.6
1687	0.0	-11.47	6.744	0.00	423.2
1690	0.0	-11.49	6.756	0.00	424.0
1693	0.4	-11.52	6.768	0.08	425.0
1696	0.0	-11.54	6.780	0.00	425.8
1699	0.0	-11.56	6.792	0.00	426.6
1702	0.0	-11.58	6.804	0.00	427.4
1705	0.0	-11.60	6.816	0.00	428.0
1708	0.0	-11.62	6.828	0.00	428.8
1711	0.2	-11.64	6.840	0.04	429.6
1714	0.0	-11.66	6.852	0.00	430.2
1717	-0.2	-11.68	6.864	-0.04	431.0
1720	0.0	-11.70	6.876	0.00	431.8
1723	0.0	-11.72	6.888	0.00	432.4
1726	0.4	-11.75	6.900	0.08	433.6
1729	0.0	-11.77	6.912	0.00	434.4
1732	0.2	-11.79	6.924	0.04	435.0
1735	0.0	-11.81	6.936	0.00	435.8
1738	0.0	-11.83	6.948	0.00	436.6
1741	-0.2	-11.85	6.960	-0.04	437.2
1744	0.0	-11.87	6.972	0.00	438.0
1747	0.0	-11.89	6.984	0.00	438.8
1750	0.0	-11.91	6.996	0.00	439.4
1753	0.0	-11.94	7.008	0.00	440.6
1756	0.0	-11.96	7.020	0.00	441.4
1759	0.0	-11.99	7.032	0.00	442.4
1762	0.0	-12.01	7.044	0.00	443.2
1765	0.0	-12.03	7.056	0.00	444.0
1768	0.0	-12.05	7.068	0.00	444.6
1771	0.0	-12.07	7.080	0.00	445.4
1774	0.0	-12.09	7.092	0.00	446.2
1777	0.2	-12.11	7.104	0.04	446.8
1780	0.0	-12.13	7.116	0.00	447.6
1783	0.0	-12.15	7.128	0.00	448.4
1786	0.0	-12.17	7.140	0.00	449.0
1789	0.0	-12.19	7.152	0.00	449.8
1792	0.0	-12.21	7.164	0.00	450.6
1795	-0.2	-12.24	7.176	-0.04	451.6
1798	0.2	-12.26	7.188	0.04	452.4
1801	0.0	-12.28	7.200	0.00	453.2
1804	-0.2	-12.30	7.212	-0.04	453.8
1807	0.0	-12.32	7.224	0.00	454.6
1810	0.4	-12.34	7.236	0.08	455.4
1813	0.0	-12.36	7.248	0.00	456.0
1816	0.0	-12.38	7.260	0.00	456.8
1819	-0.2	-12.40	7.272	-0.04	457.6
1822	-0.2	-12.42	7.284	-0.04	458.4
1825	0.0	-12.44	7.296	0.00	459.0
1828	0.0	-12.47	7.308	0.00	460.2
1831	0.0	-12.49	7.320	0.00	460.8
1834	0.0	-12.51	7.332	0.00	461.6
1837	-0.2	-12.53	7.344	-0.04	462.4
1840	0.4	-12.55	7.356	0.08	463.0
1843	0.0	-12.57	7.368	0.00	463.8
1846	0.2	-12.59	7.380	0.04	464.6
1849	0.0	-12.61	7.392	0.00	465.4
1852	0.0	-12.63	7.404	0.00	466.0
1855	0.4	-12.65	7.416	0.08	466.8
1858	0.0	-12.67	7.428	0.00	467.6
1861	0.2	-12.70	7.440	0.04	468.6
1864	0.0	-12.72	7.452	0.00	469.4
1867	0.0	-12.74	7.464	0.00	470.2
1870	0.0	-12.76	7.476	0.00	470.8
1873	0.0	-12.78	7.488	0.00	471.6
1876	0.2	-12.80	7.500	0.04	472.4
1879	0.0	-12.82	7.512	0.00	473.0
1882	0.0	-12.84	7.524	0.00	473.8
1885	-0.2	-12.86	7.536	-0.04	474.6
1888	0.2	-12.88	7.548	0.04	475.2
1891	0.0	-12.91	7.560	0.00	476.4
1894	0.0	-12.93	7.572	0.00	477.2
1897	-0.2	-12.95	7.584	-0.04	477.8
1900	0.0	-12.97	7.596	0.00	478.6
1903	0.0	-12.99	7.608	0.00	479.4
1906	0.0	-13.01	7.620	0.00	480.0
1909	0.0	-13.03	7.632	0.00	480.8
1912	0.0	-13.05	7.644	0.00	481.6
1915	0.0	-13.07	7.656	0.00	482.2
1918	0.0	-13.10	7.668	0.00	483.4
1921	0.2	-13.12	7.680	0.04	484.2
1924	-0.2	-13.14	7.692	-0.04	484.8
1927	0.0	-13.16	7.704	0.00	485.6
1930	0.0	-13.18	7.716	0.00	486.4
1933	0.0	-13.20	7.728	0.00	487.0
1936	0.0	-13.22	7.740	0.00	487.8
1939	0.0	-13.24	7.752	0.00	488.6
1942	0.0	-13.26	7.764	0.00	489.2
1945	0.2	-13.28	7.776	0.04	490.0
1948	0.0	-13.31	7.788	0.00	491.2
1951	0.0	-13.33	7.800	0.00	491.8
1954	0.0	-13.35	7.812	0.00	492.6
1957	0.0	-13.37	7.824	0.00	493.4
1960	0.2	-13.39	7.836	0.04	494.0
1963	-0.2	-13.41	7.848	-0.04	494.8
1966	-0.2	-13.43	7.860	-0.04	495.6
1969	0.0	-13.45	7.872	0.00	496.4
1972	0.0	-13.47	7.884	0.00	497.0
1975	-0.2	-13.50	7.896	-0.04	498.2
1978	0.4	-13.52	7.908	0.08	498.8
1981	0.0	-13.54	7.920	0.00	499.6
1984	0.0	-13.56	7.932	0.00	500.4
1987	-0.2	-13.58	7.944	-0.04	501.2
1990	0.0	-13.60	7.956	0.00	501.8
1993	0.0	-13.62	7.968	0.00	502.6
1996	-0.2	-13.64	7.980	-0.04	503.4
1999	0.0	-13.67	7.992	0.00	504.4
2002	0.0	-13.69	8.004	0.00	505.2
2005	0.0	-13.71	8.016	0.00	506.0
2008	0.0	-13.73	8.028	0.00	506.6
2011	0.0	-13.75	8.040	0.00	507.4
2014	-0.4	-13.77	8.052	-0.08	508.2
2017	-0.6	-13.79	8.064	-0.12	508.8
2020	0.0	-13.81	8.076	0.00	509.6
2023	0.0	-13.84	8.088	0.00	510.8
2026	0.0	-13.86	8.100	0.00	511.4
2029	0.0	-13.88	8.112	0.00	512.2
2032	-0.2	-13.90	8.124	-0.04	513.0
2035	0.0	-13.92	8.136	0.00	513.6
2038	-0.2	-13.94	8.148	-0.04	514.4
2041	0.2	-13.96	8.160	0.04	515.2
2044	-0.6	-13.98	8.172	-0.12	515.8
2047	0.0	-14.00	8.184	0.00	516.6
2050	0.0	-14.03	8.196	0.00	517.8
2053	0.0	-14.05	8.208	0.00	518.4
2056	0.0	-14.07	8.220	0.00	519.2
2059	-0.2	-14.09	8.232	-0.04	520.0
2062	0.2	-14.11	8.244	0.04	520.6
2065	-0.2	-14.13	8.256	-0.04	521.4
2068	0.0	-14.15	8.268	0.00	522.2
2071	-0.2	-14.17	8.280	-0.04	522.8
2074	0.0	-14.19	8.292	0.00	523.6
2077	0.2	-14.22	8.304	0.04	524.8
2080	0.2	-14.24	8.316	0.04	525.4
2083	0.2	-14.26	8.328	0.04	526.2
2086	0.0	-14.28	8.340	0.00	527.0
2089	0.0	-14.30	8.352	0.00	527.6
2092	0.0	-14.32	8.364	0.00	528.4
2095	-0.2	-14.34	8.376	-0.04	529.2
2098	0.2	-14.36	8.388	0.04	529.8
2101	0.0	-14.38	8.400	0.00	530.6
2104	0.0	-14.41	8.412	0.00	531.8
2107	0.0	-14.43	8.424	0.00	532.4
2110	-0.2	-14.45	8.436	-0.04	533.2
2113	0.2	-14.47	8.448	0.04	534.0
2116	0.0	-14.49	8.460	0.00	534.6
2119	0.0	-14.51	8.472	0.00	535.4
2122	0.0	-14.53	8.484	0.00	536.2
2125	0.0	-14.55	8.496	0.00	537.0
2128	0.2	-14.57	8.508	0.04	537.6
2131	0.0	-14.60	8.520	0.00	538.8
2134	0.2	-14.62	8.532	0.04	539.4
2137	0.4	-14.64	8.544	0.08	540.2
2140	-0.2	-14.66	8.556	-0.04	541.0
2143	0.2	-14.68	8.568	0.04	541.6
2146	0.0	-14.70	8.580	0.00	542.4
2149	0.0	-14.72	8.592	0.00	543.2
2152	0.0	-14.74	8.604	0.00	544.0
2155	-0.2	-14.77	8.616	-0.04	545.0
2158	-0.2	-14.79	8.628	-0.04	545.8
2161	-0.2	-14.81	8.640	-0.04	546.4
2164	0.0	-14.83	8.652	0.00	547.2
2167	0.0	-14.85	8.664	0.00	548.0
2170	0.4	-14.87	8.676	0.08	548.8
2173	0.0	-14.89	8.688	0.00	549.4
2176	0.2	-14.91	8.700	0.04	550.2
2179	0.0	-14.93	8.712	0.00	551.0
2182	0.0	-14.95	8.724	0.00	551.6
2185	0.2	-14.97	8.736	0.04	552.4
2188	0.0	-14.99	8.748	0.00	553.2
2191	0.2	-15.01	8.760	0.04	553.8
2194	0.0	-15.03	8.772	0.00	554.6
2197	0.0	-15.05	8.784	0.00	555.4
2200	0.0	-15.07	8.796	0.00	556.0
2203	0.0	-15.09	8.808	0.00	556.8
2206	0.0	-15.11	8.820	0.00	557.6
2209	0.0	-15.13	8.832	0.00	558.4
2212	0.0	-15.16	8.844	0.00	559.4
2215	0.0	-15.18	8.856	0.00	560.2
2218	0.0	-15.20	8.868	0.00	560.8
2221	0.2	-15.22	8.880	0.04	561.6
2224	0.0	-15.24	8.892	0.00	562.4
2227	-0.4	-15.26	8.904	-0.08	563.0
2230	0.0	-15.28	8.916	0.00	563.8
2233	0.0	-15.30	8.928	0.00	564.6
2236	0.0	-15.32	8.940	0.00	565.4
2239	-0.2	-15.35	8.952	-0.04	566.4
2242	0.0	-15.37	8.964	0.00	567.2
2245	0.0	-15.39	8.976	0.00	567.8
2248	-0.2	-15.41	8.988	-0.04	568.6
2251	0.0	-15.43	9.000	0.00	569.4
2254	-0.2	-15.45	9.012	-0.04	570.2
2257	0.0	-15.47	9.024	0.00	570.8
2260	0.0	-15.49	9.036	0.00	571.6
2263	0.2	-15.51	9.048	0.04	572.4
2266	0.0	-15.53	9.060	0.00	573.0
2269	0.0	-15.56	9.072	0.00	574.2
2272	0.0	-15.58	9.084	0.00	575.0
2275	0.0	-15.60	9.096	0.00	575.6
2278	0.0	-15.62	9.108	0.00	576.4
2281	-0.2	-15.64	9.120	-0.04	577.2
2284	0.0	-15.66	9.132	0.00	577.8
2287	0.0	-15.68	9.144	0.00	578.6
2290	0.0	-15.70	9.156	0.00	579.4
2293	0.0	-15.72	9.168	0.00	580.0
2296	0.0	-15.74	9.180	0.00	580.8
2299	0.0	-15.76	9.192	0.00	581.6
2302	0.0	-15.79	9.204	0.00	582.6
2305	0.0	-15.81	9.216	0.00	583.4
2308	-0.4	-15.83	9.228	-0.08	584.2
2311	0.0	-15.85	9.240	0.00	584.8
2314	0.2	-15.87	9.252	0.04	585.6
2317	0.0	-15.89	9.264	0.00	586.4
2320	0.0	-15.91	9.276	0.00	587.0
2323	0.0	-15.93	9.288	0.00	587.8
2326	0.0	-15.95	9.300	0.00	588.6
2329	0.0	-15.97	9.312	0.00	589.2
2332	-0.2	-15.99	9.324	-0.04	590.0
2335	-0.2	-16.02	9.336	-0.04	591.2
2338	0.2	-16.03	9.348	0.04	591.6
2341	-0.2	-16.06	9.360	-0.04	592.6
2344	0.0	-16.08	9.372	0.00	593.4
2347	0.0	-16.10	9.384	0.00	594.0
2350	0.0	-16.12	9.396	0.00	594.8
2353	0.0	-16.14	9.408	0.00	595.6
2356	0.2	-16.16	9.420	0.04	596.4
2359	0.0	-16.18	9.432	0.00	597.0
2362	0.2	-16.20	9.444	0.04	597.8
2365	0.0	-16.22	9.456	0.00	598.6
2368	0.0	-16.24	9.468	0.00	599.2
2371	-0.2	-16.26	9.480	-0.04	600.0
2374	0.2	-16.29	9.492	0.04	601.2
2377	-0.2	-16.31	9.504	-0.04	601.8
2380	0.0	-16.33	9.516	0.00	602.6
2383	0.2	-16.35	9.528	0.04	603.4
2386	-0.4	-16.37	9.540	-0.08	604.0
2389	0.0	-16.39	9.552	0.00	604.8
2392	0.0	-16.41	9.564	0.00	605.6
2395	0.6	-16.43	9.576	0.12	606.2
2398	0.0	-16.45	9.588	0.00	607.0
2401	0.0	-16.47	9.600	0.00	607.8
2404	0.0	-16.49	9.612	0.00	608.4
2407	0.0	-16.51	9.624	0.00	609.2
2410	0.0	-16.54	9.636	0.00	610.4
2413	0.0	-16.56	9.648	0.00	611.0
2416	0.0	-16.58	9.660	0.00	611.8
2419	0.0	-16.60	9.672	0.00	612.6
2422	0.0	-16.62	9.684	0.00	613.2
2425	0.0	-16.64	9.696	0.00	614.0
2428	0.0	-16.66	9.708	0.00	614.8
2431	0.2	-16.68	9.720	0.04	615.4
2434	0.2	-16.70	9.732	0.04	616.2
2437	0.2	-16.72	9.744	0.04	617.0
2440	0.0	-16.74	9.756	0.00	617.8
2443	0.0	-16.77	9.768	0.00	618.8
2446	0.0	-16.79	9.780	0.00	619.6
2449	0.2	-16.81	9.792	0.04	620.2
2452	0.0	-16.83	9.804	0.00	621.0
2455	-0.2	-16.85	9.816	-0.04	621.8
2458	0.0	-16.87	9.828	0.00	622.6
2461	0.2	-16.89	9.840	0.04	623.2
2464	0.0	-16.91	9.852	0.00	624.0
2467	0.0	-16.93	9.864	0.00	624.8
2470	0.0	-16.96	9.876	0.00	625.8
2473	0.0	-16.98	9.888	0.00	626.6
2476	0.0	-17.00	9.900	0.00	627.4
2479	0.0	-17.02	9.912	0.00	628.0
2482	0.0	-17.05	9.924	0.00	629.2
2485	0.0	-17.07	9.936	0.00	629.8
2488	0.0	-17.09	9.948	0.00	630.6
2491	-0.2	-17.11	9.960	-0.04	631.4
2494	0.0	-17.13	9.972	0.00	632.2
2497	-0.2	-17.15	9.984	-0.04	632.8
2500	0.0	-17.17	9.996	0.00	633.6
2503	0.0	-17.19	10.008	0.00	634.4
2506	0.0	-17.21	10.020	0.00	635.0
2509	0.0	-17.23	10.032	0.00	635.8
2512	0.4	-17.26	10.044	0.08	637.0
2515	-0.2	-17.28	10.056	-0.04	637.6
2518	-0.2	-17.30	10.068	-0.04	638.4
2521	0.2	-17.32	10.080	0.04	639.2
2524	0.0	-17.34	10.092	0.00	639.8
2527	0.0	-17.36	10.104	0.00	640.6
2530	0.2	-17.38	10.116	0.04	641.4
2533	-0.2	-17.40	10.128	-0.04	642.0
2536	0.2	-17.42	10.140	0.04	642.8
2539	0.0	-17.44	10.152	0.00	643.6
2542	0.0	-17.46	10.164	0.00	644.2
2545	0.0	-17.49	10.176	0.00	645.4
2548	0.0	-17.50	10.188	0.00	645.8
2551	0.4	-17.53	10.200	0.08	646.8
2554	0.0	-17.55	10.212	0.00	647.6
2557	0.0	-17.57	10.224	0.00	648.4
2560	0.2	-17.59	10.236	0.04	649.0
2563	0.0	-17.61	10.248	0.00	649.8
2566	0.4	-17.63	10.260	0.08	650.6
2569	0.2	-17.65	10.272	0.04	651.2
2572	0.0	-17.67	10.284	0.00	652.0
2575	-0.2	-17.69	10.296	-0.04	652.8
2578	0.2	-17.71	10.308	0.04	653.6
2581	0.0	-17.73	10.320	0.00	654.2
2584	0.4	-17.76	10.332	0.08	655.4
2587	0.2	-17.78	10.344	0.04	656.0
2590	0.2	-17.80	10.356	0.04	656.8
2593	-0.2	-17.82	10.368	-0.04	657.6
2596	-0.2	-17.84	10.380	-0.04	658.4
2599	0.2	-17.86	10.392	0.04	659.0
2602	0.0	-17.88	10.404	0.00	659.8
2605	-0.6	-17.90	10.416	-0.12	660.6
2608	0.0	-17.92	10.428	0.00	661.2
2611	0.0	-17.94	10.440	0.00	662.0
2614	0.0	-17.97	10.452	0.00	663.0
2617	0.0	-17.99	10.464	0.00	663.8
2620	0.2	-18.01	10.476	0.04	664.6
2623	-0.4	-18.03	10.488	-0.08	665.4
2626	0.0	-18.05	10.500	0.00	666.0
2629	-0.2	-18.07	10.512	-0.04	666.8
2632	0.0	-18.09	10.524	0.00	667.6
2635	0.0	-18.11	10.536	0.00	668.2
2638	-0.2	-18.13	10.548	-0.04	669.0
2641	0.0	-18.16	10.560	0.00	670.2
2644	0.2	-18.18	10.572	0.04	670.8
2647	0.0	-18.20	10.584	0.00	671.6
2650	-0.4	-18.22	10.596	-0.08	672.4
2653	0.0	-18.24	10.608	0.00	673.0
2656	0.0	-18.26	10.620	0.00	673.8
2659	0.0	-18.28	10.632	0.00	674.6
2662	0.0	-18.30	10.644	0.00	675.2
2665	0.0	-18.32	10.656	0.00	676.0
2668	-0.2	-18.34	10.668	-0.04	676.8
2671	0.2	-18.37	10.680	0.04	677.8
2674	0.0	-18.39	10.692	0.00	678.6
2677	0.0	-18.41	10.704	0.00	679.4
2680	0.0	-18.43	10.716	0.00	680.0
2683	0.0	-18.45	10.728	0.00	680.8
2686	0.0	-18.47	10.740	0.00	681.6
2689	0.0	-18.49	10.752	0.00	682.2
2692	0.2	-18.51	10.764	0.04	683.0
2695	0.0	-18.53	10.776	0.00	683.8
2698	0.4	-18.56	10.788	0.08	684.8
2701	-0.4	-18.58	10.800	-0.08	685.6
2704	0.0	-18.60	10.812	0.00	686.4
2707	0.0	-18.62	10.824	0.00	687.0
2710	0.2	-18.64	10.836	0.04	687.8
2713	-0.4	-18.66	10.848	-0.08	688.6
2716	0.0	-18.68	10.860	0.00	689.2
2719	0.0	-18.70	10.872	0.00	690.0
2722	0.0	-18.72	10.884	0.00	690.8
2725	0.0	-18.75	10.896	0.00	691.8
2728	0.0	-18.77	10.908	0.00	692.6
2731	-0.2	-18.79	10.920	-0.04	693.4
2734	-0.2	-18.81	10.932	-0.04	694.0
2737	0.0	-18.83	10.944	0.00	694.8
2740	0.0	-18.85	10.956	0.00	695.6
2743	0.0	-18.87	10.968	0.00	696.4
2746	0.2	-18.89	10.980	0.04	697.0
2749	0.0	-18.91	10.992	0.00	697.8
2752	0.0	-18.94	11.004	0.00	698.8
2755	0.0	-18.95	11.016	0.00	699.2
2758	-0.4	-18.97	11.028	-0.08	700.0
2761	0.0	-18.99	11.040	0.00	700.8
2764	-0.2	-19.01	11.052	-0.04	701.4
2767	0.0	-19.03	11.064	0.00	702.2
2770	0.0	-19.05	11.076	0.00	703.0
2773	-0.2	-19.07	11.088	-0.04	703.6
2776	0.0	-19.10	11.100	0.00	704.8
2779	-0.4	-19.12	11.112	-0.08	705.6
2782	0.0	-19.14	11.124	0.00	706.2
2785	0.0	-19.16	11.136	0.00	707.0
2788	0.0	-19.18	11.148	0.00	707.8
2791	-0.2	-19.20	11.160	-0.04	708.4
2794	0.0	-19.22	11.172	0.00	709.2
2797	0.0	-19.24	11.184	0.00	710.0
2800	-0.2	-19.26	11.196	-0.04	710.8
2803	-0.2	-19.29	11.208	-0.04	711.8
2806	0.0	-19.31	11.220	0.00	712.6
2809	0.0	-19.33	11.232	0.00	713.2
2812	0.0	-19.35	11.244	0.00	714.0
2815	0.2	-19.37	11.256	0.04	714.8
2818	0.2	-19.39	11.268	0.04	715.4
2821	0.0	-19.41	11.280	0.00	716.2
2824	0.0	-19.43	11.292	0.00	717.0
2827	0.0	-19.45	11.304	0.00	717.8
2830	0.0	-19.48	11.316	0.00	718.8
2833	0.0	-19.50	11.328	0.00	719.6
2836	0.0	-19.52	11.340	0.00	720.2
2839	0.0	-19.54	11.352	0.00	721.0
2842	0.2	-19.56	11.364	0.04	721.8
2845	0.2	-19.58	11.376	0.04	722.6
2848	0.4	-19.60	11.388	0.08	723.2
2851	0.6	-19.62	11.400	0.12	724.0
2854	1.0	-19.64	11.412	0.22	724.8
2857	2.0	-19.67	11.424	0.42	725.8
2860	2.6	-19.69	11.436	0.54	726.6
2863	4.6	-19.71	11.448	0.96	727.4
2866	6.8	-19.73	11.460	1.44	728.0
2869	10.0	-19.74	11.472	2.10	728.4
2872	13.0	-19.76	11.484	2.74	729.2
2875	17.0	-19.78	11.496	3.58	729.8
2878	22.2	-19.80	11.508	4.68	730.6
2881	29.4	-19.81	11.520	6.18	731.0
2884	41.2	-19.82	11.532	8.66	731.4
2887	52.0	-19.83	11.544	10.94	731.8
2890	59.0	-19.85	11.556	12.42	732.4
2893	57.2	-19.87	11.568	12.04	733.2
2896	59.0	-19.89	11.580	12.42	734.0
2899	59.6	-19.91	11.592	12.54	734.6
2902	58.4	-19.93	11.604	12.28	735.4
2905	56.8	-19.96	11.616	11.96	736.6
2908	54.6	-19.98	11.628	11.48	737.2
2911	53.4	-20.00	11.640	11.24	738.0
2914	51.2	-20.02	11.652	10.78	738.8
2917	50.4	-20.05	11.664	10.60	739.8
2920	50.2	-20.07	11.676	10.56	740.6
2923	51.2	-20.09	11.688	10.78	741.4
2926	50.4	-20.11	11.700	10.60	742.0
2929	48.6	-20.13	11.712	10.22	742.8
2932	47.4	-20.15	11.724	9.98	743.6
2935	45.8	-20.18	11.736	9.64	744.6
2938	41.2	-20.20	11.748	8.66	745.4
2941	40.8	-20.22	11.760	8.58	746.2
2944	41.2	-20.24	11.772	8.66	746.8
2947	42.0	-20.26	11.784	8.84	747.6
2950	40.4	-20.29	11.796	8.50	748.8
2953	37.2	-20.31	11.808	7.82	749.4
2956	36.2	-20.33	11.820	7.62	750.2
2959	36.4	-20.35	11.832	7.66	751.0
2962	36.2	-20.37	11.844	7.62	751.6
2965	36.4	-20.39	11.856	7.66	752.4
2968	37.0	-20.41	11.868	7.78	753.2
2971	37.8	-20.44	11.880	7.96	754.2
2974	37.6	-20.46	11.892	7.92	755.0
2977	38.0	-20.48	11.904	8.00	755.8
2980	37.4	-20.50	11.916	7.86	756.4
2983	37.8	-20.52	11.928	7.96	757.2
2986	37.2	-20.54	11.940	7.82	758.0
2989	36.6	-20.56	11.952	7.70	758.6
2992	36.2	-20.58	11.964	7.62	759.4
2995	36.0	-20.60	11.976	7.58	760.2
2998	35.8	-20.63	11.988	7.54	761.2
3001	35.0	-20.65	12.000	7.36	762.0
3004	34.4	-20.67	12.012	7.24	762.8
3007	33.8	-20.69	12.024	7.12	763.4
3010	33.0	-20.71	12.036	6.94	764.2
3013	32.4	-20.73	12.048	6.82	765.0
3016	31.6	-20.76	12.060	6.64	766.0
3019	31.2	-20.78	12.072	6.56	766.8
3022	30.6	-20.80	12.084	6.44	767.6
3025	30.0	-20.82	12.096	6.32	768.2
3028	29.2	-20.84	12.108	6.14	769.0
3031	29.4	-20.86	12.120	6.18	769.8
3034	30.2	-20.88	12.132	6.36	770.4
3037	29.6	-20.90	12.144	6.22	771.2
3040	30.2	-20.92	12.156	6.36	772.0
3043	30.4	-20.94	12.168	6.40	772.6
3046	31.4	-20.97	12.180	6.60	773.8
3049	32.2	-20.98	12.192	6.78	774.2
3052	33.8	-21.01	12.204	7.12	775.2
3055	34.8	-21.02	12.216	7.32	775.6
3058	36.2	-21.04	12.228	7.62	776.4
3061	37.2	-21.06	12.240	7.82	777.2
3064	38.2	-21.08	12.252	8.04	777.8
3067	39.2	-21.10	12.264	8.24	778.6
3070	39.4	-21.12	12.276	8.28	779.4
3073	40.2	-21.15	12.288	8.46	780.4
3076	40.8	-21.17	12.300	8.58	781.2
3079	41.8	-21.19	12.312	8.80	782.0
3082	42.4	-21.20	12.324	8.92	782.2
3085	43.0	-21.23	12.336	9.04	783.4
3088	44.8	-21.24	12.348	9.42	783.8
3091	46.2	-21.26	12.360	9.72	784.6
3094	48.4	-21.28	12.372	10.18	785.2
3097	46.4	-21.29	12.384	9.76	785.6
3100	43.0	-21.29	12.396	9.04	785.6
3103	41.2	-21.30	12.408	8.66	786.0
3106	40.0	-21.30	12.420	8.42	786.0
3109	39.4	-21.30	12.432	8.28	786.0
3112	38.8	-21.30	12.444	8.16	786.0
3114	38.2	-21.30	12.452	8.04	786.0